{
  "xsize": 16,
  "zsize": 16,
  "refpalette": "infinite_domain:wasteland_highway",
  "meta": [
    {
      "key": "support",
      "char": "v"
    }
  ],
  "slices": [
    [
      "vRRRRRRRRRRRRRRv",
      "RRRRRRRRRRRRRRRR",
      "RRRRRRRRRRRRRRRR",
      "RRRRRRRRRRRRRRRR",
      "RRRRRRRRRRRRRRRR",
      "RRRRRRRRRRRRRRRR",
      "RRRRRRRRRRRRRRRR",
      "uuuuuuuuuRRRRRRR",
      "uuuuuuuuuRRRRRRR",
      "RRRRRRRuuRRRRRRR",
      "RRRRRRRuuRRRRRRR",
      "RRRRRRRuuRRRRRRR",
      "RRRRRRRuuRRRRRRR",
      "RRRRRRRuuRRRRRRR",
      "RRRRRRRuuRRRRRRR",
      "vRRRRRRuuRRRRRRv"
    ],
    [
      "v::::::::::::::v",
      "~~~~~~~~~~~~~~~:",
      "~~~~~~~~~~~~~~~:",
      "~~~~~~~~~~~~~~~:",
      "~~~~~~~~~~~~~~~:",
      "~~~~~~~~~~~~~~~:",
      "~~~~~~~~~~~~~~~:",
      "~~~~~~~~~~~~~~~:",
      "~~~~~~~~~~~~~~~:",
      "~~~~~~~~~~~~~~~:",
      "~~~~~~~~~~~~~~~:",
      "~~~~~~~~~~~~~~~:",
      "~~~~~~~~~~~~~~~:",
      "~~~~~~~~~~~~~~~:",
      "~~~~~~~~~~~~~~~:",
      "v~~~~~~~~~~~~~~:"
    ],
    [
      "w~~~~~~~~~~~~~~w",
      "~~~~~~~~~~~~~~~~",
      "~~~~~~~~~~~~~~~~",
      "~~~~~~~~~~~~~~~~",
      "~~~~~~~~~~~~~~~~",
      "~~~~~~~~~~~~~~~~",
      "~~~~~~~~~~~~~~~~",
      "~~~~~~~~~~~~~~~~",
      "~~~~~~~~~~~~~~~~",
      "~~~~~~~~~~~~~~~~",
      "~~~~~~~~~~~~~~~~",
      "~~~~~~~~~~~~~~~~",
      "~~~~~~~~~~~~~~~~",
      "~~~~~~~~~~~~~~~~",
      "~~~~~~~~~~~~~~~~",
      "w~~~~~~~~~~~~~~~"
    ],
    [
      "w~~~~~~~~~~~~~~w",
      "~~~~~~~~~~~~~~~~",
      "~~~~~~~~~~~~~~~~",
      "~~~~~~~~~~~~~~~~",
      "~~~~~~~~~~~~~~~~",
      "~~~~~~~~~~~~~~~~",
      "~~~~~~~~~~~~~~~~",
      "~~~~~~~~~~~~~~~~",
      "~~~~~~~~~~~~~~~~",
      "~~~~~~~~~~~~~~~~",
      "~~~~~~~~~~~~~~~~",
      "~~~~~~~~~~~~~~~~",
      "~~~~~~~~~~~~~~~~",
      "~~~~~~~~~~~~~~~~",
      "~~~~~~~~~~~~~~~~",
      "w~~~~~~~~~~~~~~~"
    ],
    [
      "w~~~~~~~~~~~~~~w",
      "~~~~~~~~~~~~~~~~",
      "~~~~~~~~~~~~~~~~",
      "~~~~~~~~~~~~~~~~",
      "~~~~~~~~~~~~~~~~",
      "~~~~~~~~~~~~~~~~",
      "~~~~~~~~~~~~~~~~",
      "~~~~~~~~~~~~~~~~",
      "~~~~~~~~~~~~~~~~",
      "~~~~~~~~~~~~~~~~",
      "~~~~~~~~~~~~~~~~",
      "~~~~~~~~~~~~~~~~",
      "~~~~~~~~~~~~~~~~",
      "~~~~~~~~~~~~~~~~",
      "~~~~~~~~~~~~~~~~",
      "w~~~~~~~~~~~~~~~"
    ],
    [
      "w~~~~~~~~~~~~~~w",
      "~~~~~~~~~~~~~~~~",
      "~~~~~~~~~~~~~~~~",
      "~~~~~~~~~~~~~~~~",
      "~~~~~~~~~~~~~~~~",
      "~~~~~~~~~~~~~~~~",
      "~~~~~~~~~~~~~~~~",
      "~~~~~~~~~~~~~~~~",
      "~~~~~~~~~~~~~~~~",
      "~~~~~~~~~~~~~~~~",
      "~~~~~~~~~~~~~~~~",
      "~~~~~~~~~~~~~~~~",
      "~~~~~~~~~~~~~~~~",
      "~~~~~~~~~~~~~~~~",
      "~~~~~~~~~~~~~~~~",
      "w~~~~~~~~~~~~~~~"
    ],
    [
      "w~~~~~~~~~~~~~~w",
      "~~~~~~~~~~~~~~~~",
      "~~~~~~~~~~~~~~~~",
      "~~~~~~~~~~~~~~~~",
      "~~~~~~~~~~~~~~~~",
      "~~~~~~~~~~~~~~~~",
      "~~~~~~~~~~~~~~~~",
      "~~~~~~~~~~~~~~~~",
      "~~~~~~~~~~~~~~~~",
      "~~~~~~~~~~~~~~~~",
      "~~~~~~~~~~~~~~~~",
      "~~~~~~~~~~~~~~~~",
      "~~~~~~~~~~~~~~~~",
      "~~~~~~~~~~~~~~~~",
      "~~~~~~~~~~~~~~~~",
      "w~~~~~~~~~~~~~~~"
    ],
    [
      "w~~~~~~~~~~~~~~w",
      "~~~~~~~~~~~~~~~~",
      "~~~~~~~~~~~~~~~~",
      "~~~~~~~~~~~~~~~~",
      "~~~~~~~~~~~~~~~~",
      "~~~~~~~~~~~~~~~~",
      "~~~~~~~~~~~~~~~~",
      "~~~~~~~~~~~~~~~~",
      "~~~~~~~~~~~~~~~~",
      "~~~~~~~~~~~~~~~~",
      "~~~~~~~~~~~~~~~~",
      "~~~~~~~~~~~~~~~~",
      "~~~~~~~~~~~~~~~~",
      "~~~~~~~~~~~~~~~~",
      "~~~~~~~~~~~~~~~~",
      "w~~~~~~~~~~~~~~~"
    ],
    [
      "wwwwwwwwwwwwwwww",
      "w~~~~~~~~~~~~~~w",
      "w~~~~~~~~~~~~~~w",
      "w~~~~~~~~~~~~~~w",
      "w~~~~~~~~~~~~~~w",
      "w~~~~~~~~~~~~~~w",
      "w~~~~~~~~~~~~~~w",
      "w~~~~~~~~~~~~~~w",
      "w~~~~~~~~~~~~~~w",
      "w~~~~~~~~~~~~~~w",
      "w~~~~~~~~~~~~~~w",
      "w~~~~~~~~~~~~~~w",
      "w~~~~~~~~~~~~~~w",
      "w~~~~~~~~~~~~~~w",
      "w~~~~~~~~~~~~~~w",
      "w~~~~~~~~~~~~~~w"
    ]
  ]
}
