{
  "xsize": 16,
  "zsize": 16,
  "refpalette": "rails",
  "slices": [
    [
      "B              B",
      "B              B",
      "B              B",
      "BBBBBBBBBBBBBBBB",
      "BBBBBBBBBBBBBBBB",
      "BBBBBBBBBBBBBBBB",
      "BBBBBBBBBBBBBBBB",
      "BBBBBBBBBBBBBBBB",
      "BBBBBBBBBBBBBBBB",
      "BBBBBBBBBBBBBBBB",
      "BBBBBBBBBBBBBBBB",
      "BBBBBBBBBBBBBBBB",
      "B              B",
      "B              B",
      "B              B",
      "B               "
    ],
    [
      "B              B",
      "B              B",
      "B              B",
      "BBBBBBBBBBBBBBBB",
      "BBBBBBBBBBBBBBBB",
      "eeeeeeefeeeBBBBe",
      "BBBBBBBgBBBBBBBB",
      "eeeeeeefeeeBBBBe",
      "BBBBBBBgBBBBBBBB",
      "eeeeeeefeeeBBBBe",
      "BBBBBBBBBBBBBBBB",
      "BBBBBBBBBBBBBBBB",
      "B              B",
      "B              B",
      "B              B",
      "B               "
    ],
    [
      "B              B",
      "B              B",
      "B              B",
      "BBBBBBBBBBBBBBBB",
      "~~~~~~~~~~~~~~~B",
      "~~~~~~~~~~~~~~~B",
      "~~~~~~~~~~~~~~~B",
      "~~~~~~~~~~~~~~~B",
      "~~~~~~~~~~~~~~~B",
      "~~~~~~~~~~~~~~~B",
      "~~~~~~~~~~~~~~~B",
      "BBBBBBBBBBBBBBBB",
      "B              B",
      "B              B",
      "B              B",
      "B               "
    ],
    [
      "B              B",
      "B              B",
      "B              B",
      "BBBBBBBBBBBBBBBB",
      "~~~~~~~~~~~~~~~B",
      "~~~~~~~~~~~~~~~B",
      "~~~~~~~~~~~~~~~B",
      "~~~~~~~~~~~~~~~B",
      "~~~~~~~~~~~~~~~B",
      "~~~~~~~~~~~~~~~B",
      "~~~~~~~~~~~~~~~B",
      "BBBBBBBBBBBBBBBB",
      "B              B",
      "B              B",
      "B              B",
      "B               "
    ],
    [
      "B              B",
      "B              B",
      "B              B",
      "BBBBBBBBBBBBBBBB",
      "~~~~~~~~T~~~~~~B",
      "~~~~~~~~~~~~~~~B",
      "~~~~~~~~~~~~~~~B",
      "~~~~~~~~~~~~~~~B",
      "~~~~~~~~~~~~~~~B",
      "~~~~~~~~~~~~~~~B",
      "~~~~~~~~~~~~~~~B",
      "BBBBBBBBBBBBBBBB",
      "B              B",
      "B              B",
      "B              B",
      "B               "
    ],
    [
      "B              B",
      "B              B",
      "B              B",
      "BBBBBBBBBBBBBBBB",
      "BBBBBBBBBBBBBBBB",
      "BBBBBBBBBBBBBBBB",
      "BBBBBBBBBBBBBBBB",
      "BBBBBBBBBBBBBBBB",
      "BBBBBBBBBBBBBBBB",
      "BBBBBBBBBBBBBBBB",
      "BBBBBBBBBBBBBBBB",
      "BBBBBBBBBBBBBBBB",
      "B              B",
      "B              B",
      "B              B",
      "B               "
    ]
  ]
}
