{
  "xsize": 16,
  "zsize": 16,
  "slices": [
    [
      "))))))))))))))))",
      "%))))%))))%))))%",
      "))))))))))))))))",
      "))))))))))))))))",
      "))))))))))))))))",
      "))))))))))))))))",
      "))))))))))))))))",
      "))))))))))))))))",
      "))))))))))))))))",
      ")))))%%$))))))))",
      ")))%%$))))))))))",
      ")%%$))))))))))))",
      "%$))))))))))))))",
      "))))))))))))))))",
      "))))))))))))))%%",
      "))))))))))))%%$)"
    ],
    [
      "                ",
      "                ",
      "                ",
      "          '''   ",
      "          '''   ",
      "          '''   ",
      "                ",
      "                ",
      "                ",
      "'               ",
      " (((((((((((((((",
      " (((((((((((((((",
      " (((((((((((((((",
      " (((((((((((((((",
      " (((((((((((((((",
      " ((((((((((((((("
    ],
    [
      "                ",
      "                ",
      "                ",
      "          '''   ",
      "          '''   ",
      "          '''   ",
      "                ",
      "                ",
      "                ",
      "'               ",
      "                ",
      "                ",
      "                ",
      "    !!!    !!!  ",
      "    !!!    !!!  ",
      "    !!!    !!!  "
    ],
    [
      "                ",
      "                ",
      "                ",
      "          '''   ",
      "          '''   ",
      "          '''   ",
      "                ",
      "                ",
      "                ",
      "'               ",
      "                ",
      "                ",
      "                ",
      "    !!!    !!!  ",
      "    !!!    !!!  ",
      "    !!!    !!!  "
    ],
    [
      "                ",
      "                ",
      "                ",
      "          '''   ",
      "          '''   ",
      "          '''   ",
      "                ",
      "                ",
      "                ",
      "'               ",
      "                ",
      "                ",
      "     &      &   ",
      "    !!!    !!!  ",
      "    !!!    !!!  ",
      "    !!!    !!!  "
    ],
    [
      "                ",
      "                ",
      "                ",
      "          '''   ",
      "          '''   ",
      "          '''   ",
      "                ",
      "                ",
      "                ",
      "'               ",
      "                ",
      "                ",
      "                ",
      "    !!!    !!!  ",
      "    !!!    !!!  ",
      "    !!!    !!!  "
    ]
  ],
  "palette": {
    "palette": [
      {
        "char": "!",
        "block": "immersiveengineering:sheetmetal_steel"
      },
      {
        "char": "$",
        "block": "minecraft:coarse_dirt"
      },
      {
        "char": "%",
        "block": "minecraft:gravel"
      },
      {
        "char": "&",
        "block": "minecraft:lever[face=wall,facing=north,powered=false]"
      },
      {
        "char": "'",
        "block": "minecraft:polished_blackstone_bricks"
      },
      {
        "char": "(",
        "block": "minecraft:smooth_stone"
      },
      {
        "char": ")",
        "block": "tfmg:asphalt"
      }
    ]
  }
}
