{
  "xsize": 16,
  "zsize": 16,
  "slices": [
    [
      "4444444444444444",
      "4444444444444444",
      "4444444444444444",
      "4444444444444444",
      "44444444444444''",
      "444444444444''%4",
      "4444444444''%444",
      "44444444''%44444",
      "444444''%4444444",
      "4444''%444444444",
      "44''%44444444444",
      "''%4444444444444",
      "%444444444444444",
      "444444444444444'",
      "4444444444444''%",
      "44444444444''%44"
    ],
    [
      ".........       ",
      ".........       ",
      ".........       ",
      ".........       ",
      ".........       ",
      ".........       ",
      ".........       ",
      ".........       ",
      ".........       ",
      ".........       ",
      ".........       ",
      ".........       ",
      ".........       ",
      ".........       ",
      ".........       ",
      "''''.....       "
    ],
    [
      "000000000       ",
      "        0       ",
      "        0       ",
      "  &&&   0       ",
      "      5 0       ",
      "$       0       ",
      "   /    0       ",
      "        0       ",
      ",11111110       ",
      "  1     0       ",
      "  1     0       ",
      "  *     0       ",
      "  1 2 ) 0       ",
      "  1     0       ",
      "  1     0       ",
      "0,0000000       "
    ],
    [
      "000000000       ",
      "        0       ",
      "        0       ",
      "        0       ",
      "      3 0       ",
      "3       0       ",
      "        0       ",
      "        0       ",
      "-11111110       ",
      "  1     0       ",
      "  1     0       ",
      "  +     !       ",
      "  1     !       ",
      "  1   ( 0       ",
      "  1     0       ",
      "0-000!!00       "
    ],
    [
      "000000000       ",
      "        0       ",
      "        0       ",
      "        0       ",
      "        0       ",
      "        0       ",
      "        0       ",
      "        0       ",
      "111111110       ",
      "  1     0       ",
      "  1     0       ",
      "  1     !       ",
      "  1     !       ",
      "  1     0       ",
      "  1     0       ",
      "00000!!00       "
    ],
    [
      "000000000       ",
      "        0       ",
      "        0       ",
      "        0       ",
      "        0       ",
      "        0       ",
      "        0       ",
      "        0       ",
      "111111110       ",
      "  1     0       ",
      "  1     0       ",
      "  1     0       ",
      "  1     0       ",
      "  1     0       ",
      "  1     0       ",
      "000000000       "
    ]
  ],
  "palette": {
    "palette": [
      {
        "char": "!",
        "block": "create:framed_glass"
      },
      {
        "char": "$",
        "block": "minecraft:barrel[facing=up,open=false]"
      },
      {
        "char": "%",
        "block": "minecraft:coarse_dirt"
      },
      {
        "char": "&",
        "block": "minecraft:dark_oak_stairs[facing=south,half=bottom,shape=straight,waterlogged=false]"
      },
      {
        "char": "'",
        "block": "minecraft:gravel"
      },
      {
        "char": "(",
        "block": "minecraft:lever[face=wall,facing=south,powered=false]"
      },
      {
        "char": ")",
        "block": "minecraft:quartz_stairs[facing=north,half=bottom,shape=straight,waterlogged=false]"
      },
      {
        "char": "*",
        "block": "minecraft:spruce_door[facing=east,half=lower,hinge=left,open=false,powered=false]"
      },
      {
        "char": "+",
        "block": "minecraft:spruce_door[facing=east,half=upper,hinge=left,open=false,powered=false]"
      },
      {
        "char": ",",
        "block": "minecraft:spruce_door[facing=south,half=lower,hinge=left,open=false,powered=false]"
      },
      {
        "char": "-",
        "block": "minecraft:spruce_door[facing=south,half=upper,hinge=left,open=false,powered=false]"
      },
      {
        "char": ".",
        "block": "minecraft:spruce_planks"
      },
      {
        "char": "/",
        "block": "minecraft:spruce_slab[type=bottom,waterlogged=false]"
      },
      {
        "char": "0",
        "block": "minecraft:stone_bricks"
      },
      {
        "char": "1",
        "block": "minecraft:stripped_spruce_wood"
      },
      {
        "char": "2",
        "block": "kubejs:ruined_cauldron"
      },
      {
        "char": "3",
        "block": "supplementaries:item_shelf"
      },
      {
        "char": "4",
        "block": "tfmg:asphalt"
      },
      {
        "char": "5",
        "block": "the_wasteland_reworked:radio"
      }
    ]
  }
}
