{
  "xsize": 16,
  "zsize": 16,
  "slices": [
    [
      " ...$$!.........",
      " .$$!...........",
      " $!.............",
      " ...............",
      " ..............$",
      " !...........$$!",
      " ..........$$!..",
      " ........$$!....",
      " ......$$!......",
      " ....$$!........",
      " ..$$!..........",
      " !$!............",
      " !..............",
      " ...............",
      " ...............",
      " ...........$$.."
    ],
    [
      "     +++++++++++",
      "     +++++++++++",
      "     +++++++++++",
      "     +++++++++++",
      "     +++++++++++",
      "                ",
      "                ",
      "                ",
      "                ",
      "                ",
      "            ((( ",
      "            ((( ",
      "            ((( ",
      "                ",
      "                ",
      "                "
    ],
    [
      "     ' &     )  ",
      "     ' %     , -",
      "     '       ,  ",
      "     '       ,  ",
      "     '''''''''''",
      "                ",
      "                ",
      "                ",
      "                ",
      "                ",
      "            ((( ",
      "            ((( ",
      "            ((( ",
      "                ",
      "                ",
      "                "
    ],
    [
      "     '       *  ",
      "     '       ,  ",
      "     '       ,  ",
      "     '       ,  ",
      "     '''''''''''",
      "                ",
      "                ",
      "                ",
      "                ",
      "                ",
      "                ",
      "                ",
      "                ",
      "                ",
      "                ",
      "                "
    ],
    [
      "     '       ,  ",
      "     '       ,  ",
      "     '       ,  ",
      "     '       ,  ",
      "     '''''''''''",
      "                ",
      "                ",
      "                ",
      "                ",
      "                ",
      "                ",
      "                ",
      "                ",
      "                ",
      "                ",
      "                "
    ],
    [
      "     '       ,  ",
      "     '       ,  ",
      "     '       ,  ",
      "     '       ,  ",
      "     '''''''''''",
      "                ",
      "                ",
      "                ",
      "                ",
      "                ",
      "                ",
      "                ",
      "                ",
      "                ",
      "                ",
      "                "
    ]
  ],
  "palette": {
    "palette": [
      {
        "char": "!",
        "block": "minecraft:coarse_dirt"
      },
      {
        "char": "$",
        "block": "minecraft:gravel"
      },
      {
        "char": "%",
        "block": "minecraft:gray_bed[facing=north,occupied=false,part=foot]"
      },
      {
        "char": "&",
        "block": "minecraft:gray_bed[facing=north,occupied=false,part=head]"
      },
      {
        "char": "'",
        "block": "minecraft:mud_bricks"
      },
      {
        "char": "(",
        "block": "minecraft:oxidized_copper"
      },
      {
        "char": ")",
        "block": "minecraft:spruce_door[facing=east,half=lower,hinge=left,open=false,powered=false]"
      },
      {
        "char": "*",
        "block": "minecraft:spruce_door[facing=east,half=upper,hinge=left,open=false,powered=false]"
      },
      {
        "char": "+",
        "block": "minecraft:spruce_planks"
      },
      {
        "char": ",",
        "block": "minecraft:stripped_spruce_wood"
      },
      {
        "char": "-",
        "block": "minecraft:water_cauldron[level=2]"
      },
      {
        "char": ".",
        "block": "tfmg:asphalt"
      }
    ]
  }
}
