{
  "xsize": 16,
  "zsize": 16,
  "slices": [
    [
      "!!!!!!''''''''''",
      "!!!!!!''''''''%'",
      "!!!!!!''''''%%!'",
      "!!!!!!''''%%!'''",
      "!!!!!!''%%!'''''",
      "!!!!!!%%!'''''''",
      "''''%%!'''''''''",
      "''%%!'''''''''''",
      "%%!'''''''''''''",
      "!'''''''''''''''",
      "''''''''''''''''",
      "''''''''''''''''",
      "''''''''''''''''",
      "''''''''''''''''",
      "''''''''''''''''",
      "''''''''''''''''"
    ],
    [
      "                ",
      " $              ",
      "                ",
      "                ",
      "                ",
      "                ",
      "                ",
      "                ",
      "                ",
      "                ",
      "                ",
      "                ",
      "                ",
      "           &&&  ",
      "           &&&  ",
      "           &&&  "
    ],
    [
      "                ",
      " $              ",
      "                ",
      "                ",
      "                ",
      "                ",
      "                ",
      "                ",
      "                ",
      "                ",
      "                ",
      "                ",
      "                ",
      "           &&&  ",
      "           &&&  ",
      "           &&&  "
    ],
    [
      "                ",
      " $              ",
      "                ",
      "                ",
      "                ",
      "                ",
      "                ",
      "                ",
      "                ",
      "                ",
      "                ",
      "                ",
      "                ",
      "                ",
      "                ",
      "                "
    ],
    [
      "                ",
      " $              ",
      "                ",
      "                ",
      "                ",
      "                ",
      "                ",
      "                ",
      "                ",
      "                ",
      "                ",
      "                ",
      "                ",
      "                ",
      "                ",
      "                "
    ],
    [
      "                ",
      " $              ",
      "                ",
      "                ",
      "                ",
      "                ",
      "                ",
      "                ",
      "                ",
      "                ",
      "                ",
      "                ",
      "                ",
      "                ",
      "                ",
      "                "
    ]
  ],
  "palette": {
    "palette": [
      {
        "char": "!",
        "block": "minecraft:coarse_dirt"
      },
      {
        "char": "$",
        "block": "minecraft:dead_bush"
      },
      {
        "char": "%",
        "block": "minecraft:gravel"
      },
      {
        "char": "&",
        "block": "minecraft:oxidized_copper"
      },
      {
        "char": "'",
        "block": "tfmg:asphalt"
      }
    ]
  }
}
