{
  "xsize": 16,
  "zsize": 16,
  "slices": [
    [
      "0000000000(($000",
      "00000000(($00000",
      "000000(($0000000",
      "0000(($000000000",
      "00(($00000000000",
      "                ",
      "                ",
      "                ",
      "                ",
      "                ",
      "                ",
      "                ",
      "                ",
      "                ",
      "                ",
      "                "
    ],
    [
      "  ))(())(())(***",
      "  ())(())(())***",
      "  (())(())(()-  ",
      "  )(())(())1(   ",
      "  ))(())(()) -  ",
      "                ",
      "                ",
      "                ",
      "                ",
      "                ",
      "                ",
      "                ",
      "                ",
      "                ",
      "                ",
      "                "
    ],
    [
      "  ))(())(())(.  ",
      "  ())(())(())))%",
      "   ,,,,,,,(()-  ",
      "    ())(())     ",
      "     ())(()  -  ",
      "                ",
      "                ",
      "                ",
      "                ",
      "                ",
      "                ",
      "                ",
      "                ",
      "                ",
      "                ",
      "                "
    ],
    [
      "  ))(())(()) .  ",
      "   ))(())(()///&",
      "   )))(())   -  ",
      "     ))(()      ",
      "      ))+    -  ",
      "                ",
      "                ",
      "                ",
      "                ",
      "                ",
      "                ",
      "                ",
      "                ",
      "                ",
      "                ",
      "                "
    ],
    [
      "   / ())(()  .  ",
      "   //!())/!!/// ",
      "   )   ()+   -  ",
      "          '     ",
      "         +   -  ",
      "                ",
      "                ",
      "                ",
      "                ",
      "                ",
      "                ",
      "                ",
      "                ",
      "                ",
      "                ",
      "                "
    ],
    [
      "   /  )).    .  ",
      "   ////)////////",
      "   )    ) +  -  ",
      "           '    ",
      "          +  -  ",
      "                ",
      "                ",
      "                ",
      "                ",
      "                ",
      "                ",
      "                ",
      "                ",
      "                ",
      "                ",
      "                "
    ]
  ],
  "palette": {
    "palette": [
      {
        "char": "!",
        "block": "create:framed_glass"
      },
      {
        "char": "$",
        "block": "minecraft:coarse_dirt"
      },
      {
        "char": "%",
        "block": "minecraft:dark_oak_door[facing=south,half=lower,hinge=left,open=false,powered=false]"
      },
      {
        "char": "&",
        "block": "minecraft:dark_oak_door[facing=south,half=upper,hinge=left,open=false,powered=false]"
      },
      {
        "char": "'",
        "block": "minecraft:dark_oak_stairs[facing=east,half=bottom,shape=straight,waterlogged=false]"
      },
      {
        "char": "(",
        "block": "minecraft:gravel"
      },
      {
        "char": ")",
        "block": "minecraft:mud_bricks"
      },
      {
        "char": "*",
        "block": "minecraft:oak_planks"
      },
      {
        "char": "+",
        "block": "minecraft:stripped_dark_oak_log"
      },
      {
        "char": ",",
        "block": "minecraft:stripped_dark_oak_log[axis=x]"
      },
      {
        "char": "-",
        "block": "minecraft:stripped_dark_oak_log[axis=y]"
      },
      {
        "char": ".",
        "block": "minecraft:stripped_oak_wood"
      },
      {
        "char": "/",
        "block": "minecraft:yellow_terracotta"
      },
      {
        "char": "0",
        "block": "tfmg:asphalt"
      },
      {
        "char": "1",
        "block": "wastelands:scrap_pile"
      }
    ]
  }
}
