{
  "xsize": 16,
  "zsize": 16,
  "slices": [
    [
      "$$$$$$    !     ",
      "$$$$$$    !     ",
      "$$$$$$    !     ",
      "$$$$$$    !     ",
      "$$$$$$    !     ",
      "          !     ",
      "$$$$$$    !     ",
      "$$$$$$    !     ",
      "$$$$$$    !     ",
      "$$$$$$    !     ",
      "$$$$$$    !     ",
      "          !     ",
      "$$$$$$    !     ",
      "$$$$$$    !     ",
      "$$$$$$    !!!!!!",
      "$$$$$$          "
    ],
    [
      "$$$$$$    !     ",
      "$$$$$$    !     ",
      "$$$$$$    !     ",
      "$$$$$$    !     ",
      "$$$$$$    !     ",
      "          !     ",
      "$$$$$$    !     ",
      "$$$$$$    !     ",
      "$$$$$$    !     ",
      "$$$$$$    !     ",
      "$$$$$$    !     ",
      "          !     ",
      "$$$$$$    !     ",
      "$$$$$$    !     ",
      "$$$$$$    !!!!!!",
      "$$$$$$          "
    ],
    [
      "$$$$$$    !     ",
      "$$$$$$    !     ",
      "$$$$$$    !     ",
      "$$$$$$    !     ",
      "$$$$$$    !     ",
      "          !     ",
      "$$$$$$    !     ",
      "$$$$$$    !     ",
      "$$$$$$    !     ",
      "$$$$$$    !     ",
      "$$$$$$    !     ",
      "          !     ",
      "$$$$$$    !     ",
      "$$$$$$    !     ",
      "$$$$$$    !!!!!!",
      "$$$$$$          "
    ],
    [
      "          !     ",
      "          !     ",
      "          !     ",
      "          !     ",
      "          !     ",
      "          !     ",
      "          !     ",
      "          !     ",
      "          !     ",
      "          !     ",
      "          !     ",
      "          !     ",
      "          !     ",
      "          !     ",
      "          !!!!!!",
      "                "
    ],
    [
      "          !     ",
      "          !     ",
      "          !     ",
      "          !     ",
      "          !     ",
      "          !     ",
      "          !     ",
      "          !     ",
      "          !     ",
      "          !     ",
      "          !     ",
      "          !     ",
      "          !     ",
      "          !     ",
      "          !!!!!!",
      "                "
    ],
    [
      "          !     ",
      "          !     ",
      "          !     ",
      "          !     ",
      "          !     ",
      "          !     ",
      "          !     ",
      "          !     ",
      "          !     ",
      "          !     ",
      "          !     ",
      "          !     ",
      "          !     ",
      "          !     ",
      "          !!!!!!",
      "                "
    ]
  ],
  "palette": {
    "palette": [
      {
        "char": "!",
        "block": "minecraft:bricks"
      },
      {
        "char": "$",
        "block": "minecraft:oak_leaves[distance=1,persistent=true]"
      }
    ]
  }
}
