{
  "xsize": 16,
  "zsize": 16,
  "slices": [
    [
      "                ",
      "      &&&&      ",
      "      &&&&      ",
      "      &&&&      ",
      "      &&&&      ",
      "      &&&&      ",
      "                ",
      "            !!! ",
      "           !   !",
      "           !   !",
      "           !   !",
      "%%%%%       !!! ",
      "%%%%%           ",
      "%%%%%           ",
      "                ",
      "                "
    ],
    [
      "                ",
      "      &&&&      ",
      "      &&&&      ",
      "      &&&&      ",
      "      &&&&      ",
      "      &&&&      ",
      "                ",
      "            !!! ",
      "           !   !",
      "           !   !",
      "           !   !",
      "%%%%%       !!! ",
      "%%%%%           ",
      "%%%%%           ",
      "                ",
      "                "
    ],
    [
      "                ",
      "      &&&&      ",
      "      &&&&      ",
      "      &&&&      ",
      "      &&&&      ",
      "      &&&&      ",
      "                ",
      "            !!! ",
      "           !   !",
      "           !   !",
      "           !   !",
      "            !!! ",
      "  $             ",
      "                ",
      "                ",
      "                "
    ],
    [
      "                ",
      "      &&&&      ",
      "      &&&&      ",
      "      &&&&      ",
      "      &&&&      ",
      "      &&&&      ",
      "                ",
      "            !!! ",
      "           !   !",
      "           !   !",
      "           !   !",
      "            !!! ",
      "  $             ",
      "                ",
      "                ",
      "                "
    ],
    [
      "                ",
      "                ",
      "      $$$$$$$$$$",
      "      $$$$$$$$$$",
      "      $$$$$$$$$$",
      "                ",
      "                ",
      "            !!! ",
      "           !   !",
      "           !   !",
      "           !   !",
      "            !!! ",
      "  $    $$$      ",
      "                ",
      "                ",
      "                "
    ],
    [
      "                ",
      "                ",
      "      $$$$$$$$$$",
      "      $$$$$$$$$$",
      "      $$$$$$$$$$",
      "                ",
      "                ",
      "            !!! ",
      "           !   !",
      "           !   !",
      "           !   !",
      "            !!! ",
      "  $    $$$      ",
      "                ",
      "                ",
      "                "
    ]
  ],
  "palette": {
    "palette": [
      {
        "char": "!",
        "block": "immersiveengineering:sheetmetal_steel"
      },
      {
        "char": "$",
        "block": "minecraft:polished_blackstone"
      },
      {
        "char": "%",
        "block": "minecraft:yellow_concrete"
      },
      {
        "char": "&",
        "block": "tfmg:steel_block"
      }
    ]
  }
}
