{
  "xsize": 16,
  "zsize": 16,
  "slices": [
    [
      "+++++++&&$++++++",
      "+++++&&$++++++++",
      "+++&&$++++++++++",
      "+&&$++++++++++++",
      "&$++++++++++++++",
      "++++++++++++++++",
      "++++++++++++++&&",
      "++++++++++++&&$+",
      "++++++++++&&$+++",
      "++++++++&&$+++++",
      "++++++&&$+++++++",
      "++++&&$+++++++++",
      "++&&$+++++++++++",
      "&&$+++++++++++++",
      "$+++++++++++++++",
      "+++++++++++++++&"
    ],
    [
      "   %      ------",
      "          ------",
      "          ------",
      "          ------",
      "          ------",
      "          ------",
      "   %      ------",
      "          ------",
      "          ------",
      "          ------",
      "          ------",
      "          ------",
      "   %      ------",
      "          ------",
      "          ------",
      "          ------"
    ],
    [
      "   %      !*****",
      "          !     ",
      "          !     ",
      "          !     ",
      "          !     ",
      "          !  )  ",
      "   %      !!!   ",
      "          !     ",
      "          !     ",
      "          !     ",
      "          !  (  ",
      "          !     ",
      "   %      !     ",
      "          !     ",
      "          !     ",
      "          !,,,,,"
    ],
    [
      "   %      !*****",
      "          !     ",
      "          !     ",
      "          !     ",
      "          !     ",
      "          !     ",
      "   %      !!!   ",
      "          !     ",
      "          !     ",
      "          !     ",
      "          !     ",
      "          !     ",
      "   %      !     ",
      "          !     ",
      "          !     ",
      "          !,,,,,"
    ],
    [
      "   %      !*****",
      "          !     ",
      "          !     ",
      "          !     ",
      "          !     ",
      "          !     ",
      "   %      !!!   ",
      "          !     ",
      "          !     ",
      "          !     ",
      "          !     ",
      "          !     ",
      "   %      !     ",
      "          !     ",
      "          !     ",
      "          !,,,,,"
    ],
    [
      "''''''    !     ",
      "''''''    !     ",
      "''''''    !     ",
      "          !     ",
      "''''''    !     ",
      "''''''    !     ",
      "''''''    !!!   ",
      "''''''    !     ",
      "''''''    !     ",
      "          !     ",
      "''''''    !     ",
      "''''''    !     ",
      "''''''    !     ",
      "''''''    !     ",
      "''''''    !     ",
      "          !,,,,,"
    ]
  ],
  "palette": {
    "palette": [
      {
        "char": "!",
        "block": "minecraft:bricks"
      },
      {
        "char": "$",
        "block": "minecraft:coarse_dirt"
      },
      {
        "char": "%",
        "block": "minecraft:dark_oak_log[axis=y]"
      },
      {
        "char": "&",
        "block": "minecraft:gravel"
      },
      {
        "char": "'",
        "block": "minecraft:oak_leaves[distance=1,persistent=true]"
      },
      {
        "char": "(",
        "block": "kubejs:ruined_smoker[facing=south]"
      },
      {
        "char": ")",
        "block": "kubejs:ruined_cauldron"
      },
      {
        "char": "*",
        "block": "quark:apple_crate"
      },
      {
        "char": "+",
        "block": "tfmg:asphalt"
      },
      {
        "char": ",",
        "block": "tfmg:cinder_block"
      },
      {
        "char": "-",
        "block": "tfmg:factory_floor"
      }
    ]
  }
}
