{
  "xsize": 16,
  "zsize": 16,
  "slices": [
    [
      "%%%%%%%%%       ",
      "        %       ",
      "        %       ",
      "        %       ",
      "        %       ",
      "        %       ",
      "        %       ",
      "        %       ",
      "        %       ",
      "        %       ",
      "        %       ",
      "        %       ",
      "        %       ",
      "        %       ",
      "        %       ",
      "%%%%%%%%%       "
    ],
    [
      "%%%%%%%%%       ",
      "        %       ",
      "        %       ",
      "        %       ",
      "        %       ",
      "        %       ",
      "        %       ",
      "        %       ",
      "        %       ",
      "        %       ",
      "        %       ",
      "        %       ",
      "        %       ",
      "        %       ",
      "        %       ",
      "%%%%%%%%%       "
    ],
    [
      "%%%%%%%%%       ",
      "        %       ",
      "        %       ",
      "        %       ",
      "        %       ",
      "        %       ",
      "        %       ",
      "        %       ",
      "        %       ",
      "        %       ",
      "      ! %       ",
      "        %       ",
      "        %       ",
      "        %       ",
      "        %       ",
      "%%%%%%%%%       "
    ],
    [
      "%%%%%%%%$       ",
      "&&&&&&&&$       ",
      "&&&&&&&&$       ",
      "&&&&&&&&$       ",
      "&&&&&&&&$       ",
      "&&&&&&&&$       ",
      "&&&&&&&&$       ",
      "&&&&&&&&$       ",
      "&&&&&&&&$       ",
      "&&&&&&&&$       ",
      "&&&&&&!&$       ",
      "&&&&&&&&$       ",
      "&&&&&&&&$       ",
      "&&&&&&&&$       ",
      "&&&&&&&&$       ",
      "%%%%%%%%$       "
    ],
    [
      "%%%%%%%$        ",
      "       $        ",
      "       $        ",
      "       $        ",
      "       $        ",
      "       $        ",
      "       $        ",
      "       $        ",
      "       $        ",
      "       $        ",
      "      !$        ",
      "       $        ",
      "       $        ",
      "       $        ",
      "       $        ",
      "%%%%%%%$        "
    ],
    [
      "%%%%%%$         ",
      "      $         ",
      "      $         ",
      "      $         ",
      "      $         ",
      "      $         ",
      "      $         ",
      "      $         ",
      "      $         ",
      "      $         ",
      "      !         ",
      "      $         ",
      "      $         ",
      "      $         ",
      "      $         ",
      "%%%%%%$         "
    ]
  ],
  "palette": {
    "palette": [
      {
        "char": "!",
        "block": "minecraft:bricks"
      },
      {
        "char": "$",
        "block": "minecraft:dark_oak_stairs[facing=west,half=bottom,shape=straight,waterlogged=false]"
      },
      {
        "char": "%",
        "block": "minecraft:stone_bricks"
      },
      {
        "char": "&",
        "block": "minecraft:weathered_cut_copper"
      }
    ]
  }
}
