{
  "xsize": 16,
  "zsize": 16,
  "slices": [
    [
      "$$&&&&&!!!!!%%%%",
      "****************",
      "****************",
      "****************",
      "****************",
      "****************",
      "****************",
      "****************",
      "!!$$$$$!!!!!$$$$",
      "!!$$$$$!!!!!$$$$",
      "%%&&&&&!!!!!!!!!",
      "$$$$$$$$$$$$$$$!",
      "$$$$$$$$$$$$$$$!",
      "$$$$$$$$$$$$$$$!",
      "$$$$$$$$$$$$$$$!",
      "$$$$$$$$$$$$$$$&"
    ],
    [
      "                ",
      "                ",
      "                ",
      "                ",
      ")      )      ) ",
      "                ",
      "                ",
      "                ",
      "((((((((((((((  ",
      "((((((((((((((  ",
      "((((((((((((((  ",
      "((((((((((((((  ",
      "((((((((((((((  ",
      "((((((((((((((  ",
      "((((((((((((((  ",
      "(('(((('(((('(  "
    ],
    [
      "                ",
      "                ",
      "                ",
      "                ",
      "                ",
      "                ",
      "                ",
      "                ",
      "                ",
      "                ",
      "                ",
      "                ",
      "                ",
      "                ",
      "                ",
      "                "
    ],
    [
      "                ",
      "                ",
      "                ",
      "                ",
      "                ",
      "                ",
      "                ",
      "                ",
      "                ",
      "                ",
      "                ",
      "                ",
      "                ",
      "                ",
      "                ",
      "                "
    ],
    [
      "                ",
      "                ",
      "                ",
      "                ",
      "                ",
      "                ",
      "                ",
      "                ",
      "                ",
      "                ",
      "                ",
      "                ",
      "                ",
      "                ",
      "                ",
      "                "
    ],
    [
      "                ",
      "                ",
      "                ",
      "                ",
      "                ",
      "                ",
      "                ",
      "                ",
      "                ",
      "                ",
      "                ",
      "                ",
      "                ",
      "                ",
      "                ",
      "                "
    ]
  ],
  "palette": {
    "palette": [
      {
        "char": "!",
        "block": "minecraft:coarse_dirt"
      },
      {
        "char": "$",
        "block": "minecraft:gravel"
      },
      {
        "char": "%",
        "block": "minecraft:gray_concrete"
      },
      {
        "char": "&",
        "block": "minecraft:polished_andesite"
      },
      {
        "char": "'",
        "block": "minecraft:polished_blackstone"
      },
      {
        "char": "(",
        "block": "minecraft:smooth_stone"
      },
      {
        "char": ")",
        "block": "minecraft:yellow_concrete"
      },
      {
        "char": "*",
        "block": "tfmg:asphalt"
      }
    ]
  }
}
