{
  "xsize": 16,
  "zsize": 16,
  "slices": [
    [
      "!!!!!!!!!!!!!!!$",
      "!!!!!!!!!!!!!!!$",
      "!!!!!!!!!!!!!!!$",
      "!!!!!!!!!!!!!!!$",
      "!!!!!!!!!!!!!!!$",
      "!!!!!!!!!!!!!!!$",
      "!!!!!!!!!!!!!!!$",
      "!!!!!!!!!!!!!!!$",
      "!!!!!!!!!!!!!!!$",
      "               !",
      "               !",
      "               !",
      "               !",
      "               !",
      "               $",
      "               $"
    ],
    [
      "&&%&&&&%&&&&%&  ",
      "&&%&&&&%&&&&%&  ",
      "  %    %    %   ",
      "  %    %    %   ",
      "  %    %    %   ",
      "  %    %    %   ",
      "  %    %    %   ",
      "  %    %    %   ",
      "  %    %    %   ",
      "                ",
      "                ",
      "                ",
      "                ",
      "                ",
      "                ",
      "                "
    ],
    [
      "                ",
      "                ",
      "                ",
      "                ",
      "                ",
      "                ",
      "                ",
      "                ",
      "                ",
      "                ",
      "                ",
      "                ",
      "                ",
      "                ",
      "                ",
      "                "
    ],
    [
      "                ",
      "                ",
      "                ",
      "                ",
      "                ",
      "                ",
      "                ",
      "                ",
      "                ",
      "                ",
      "                ",
      "                ",
      "                ",
      "                ",
      "                ",
      "                "
    ],
    [
      "                ",
      "                ",
      "                ",
      "                ",
      "                ",
      "                ",
      "                ",
      "                ",
      "                ",
      "                ",
      "                ",
      "                ",
      "                ",
      "                ",
      "                ",
      "                "
    ],
    [
      "                ",
      "                ",
      "                ",
      "                ",
      "                ",
      "                ",
      "                ",
      "                ",
      "                ",
      "                ",
      "                ",
      "                ",
      "                ",
      "                ",
      "                ",
      "                "
    ]
  ],
  "palette": {
    "palette": [
      {
        "char": "!",
        "block": "minecraft:gravel"
      },
      {
        "char": "$",
        "block": "minecraft:polished_andesite"
      },
      {
        "char": "%",
        "block": "minecraft:polished_blackstone"
      },
      {
        "char": "&",
        "block": "minecraft:smooth_stone"
      }
    ]
  }
}
