{
  "xsize": 16,
  "zsize": 16,
  "slices": [
    [
      "2222222''&222222",
      "22222''&22222222",
      "222''&2222222222",
      "2''&222222222222",
      "'&22222222222222",
      "2222222222222222",
      "22222222222222''",
      "222222222222''&2",
      "2222222222''&222",
      "22222222''&22222",
      "222222''&2222222",
      "2222''&222222222",
      "2222&22222222222",
      "2222222222222222",
      "2222222222222222",
      "222222222222222'"
    ],
    [
      "4444444444444444",
      "4444444444444444",
      "4444444444444444",
      "4444444444444444",
      "4444444444444444",
      "'444444444444444",
      "'444444444444444",
      "'444444444444444",
      "'444444444444444",
      "'444444444444444",
      "'444444444444444",
      "'444444444444444",
      "'444444444444444",
      "'444444444444444",
      "'444444444444444",
      "'444444444444444"
    ],
    [
      "        )   )  $",
      "        ) * )  $",
      "//      )   )  $",
      "0              $",
      "6666666        $",
      "'              $",
      "'-333333333-333$",
      "'   3    3     $",
      "'   3    3 ))) $",
      "'   31   31))) $",
      "'   +    + ))) $",
      "'   3    3 ))) $",
      "'   3    3 )%) $",
      "' 5 3(   3())) $",
      "'   3    3 ))) $",
      "'   3    3     $"
    ],
    [
      "        )   )  $",
      "        )   )  $",
      "        )   )  !",
      "               !",
      "               $",
      "'              $",
      "'.333333333.333$",
      "'   3    3     $",
      "'   3    3 ))) $",
      "'   3    3 ))) $",
      "'   ,    , ))) !",
      "'   3    3 ))) !",
      "'   3    3 ))) $",
      "'   3    3 ))) $",
      "'   3    3 ))) $",
      "'   3    3     $"
    ],
    [
      "        )   )  $",
      "        )   )  $",
      "        )   )  !",
      "               !",
      "               $",
      "'              $",
      "'33333333333333$",
      "'   3    3     $",
      "'   3    3 ))) $",
      "'   3    3 ))) $",
      "'   3    3 ))) !",
      "'   3    3 ))) !",
      "'   3    3 ))) $",
      "'   3    3 ))) $",
      "'   3    3 ))) $",
      "'   3    3     $"
    ],
    [
      "               $",
      "               $",
      "               $",
      "               $",
      "               $",
      "'              $",
      "'33333333333333$",
      "'   3    3     $",
      "'   3    3     $",
      "'   3    3     $",
      "'   3    3     $",
      "'   3    3     $",
      "'   3    3     $",
      "'   3    3     $",
      "'   3    3     $",
      "'   3    3     $"
    ]
  ],
  "palette": {
    "palette": [
      {
        "char": "!",
        "block": "create:framed_glass"
      },
      {
        "char": "$",
        "block": "minecraft:bricks"
      },
      {
        "char": "%",
        "block": "minecraft:chest[facing=south,type=single,waterlogged=false]",
        "tag": {
          "id": "minecraft:chest",
          "LootTable": "infinite_domain:chests/wasteland_roadside"
        }
      },
      {
        "char": "&",
        "block": "minecraft:coarse_dirt"
      },
      {
        "char": "'",
        "block": "minecraft:gravel"
      },
      {
        "char": "(",
        "block": "minecraft:quartz_stairs[facing=south,half=bottom,shape=straight,waterlogged=false]"
      },
      {
        "char": ")",
        "block": "minecraft:scaffolding"
      },
      {
        "char": "*",
        "block": "minecraft:spawner",
        "tag": {
          "id": "minecraft:mob_spawner",
          "Delay": 200,
          "MinSpawnDelay": 240,
          "MaxSpawnDelay": 720,
          "SpawnCount": 2,
          "MaxNearbyEntities": 6,
          "RequiredPlayerRange": 14,
          "SpawnRange": 4,
          "SpawnData": {
            "entity": {
              "id": "minecraft:zombie"
            }
          },
          "SpawnPotentials": [
            {
              "weight": 1,
              "data": {
                "entity": {
                  "id": "minecraft:zombie"
                }
              }
            }
          ]
        }
      },
      {
        "char": "+",
        "block": "minecraft:spruce_door[facing=east,half=lower,hinge=left,open=false,powered=false]"
      },
      {
        "char": ",",
        "block": "minecraft:spruce_door[facing=east,half=upper,hinge=left,open=false,powered=false]"
      },
      {
        "char": "-",
        "block": "minecraft:spruce_door[facing=south,half=lower,hinge=left,open=false,powered=false]"
      },
      {
        "char": ".",
        "block": "minecraft:spruce_door[facing=south,half=upper,hinge=left,open=false,powered=false]"
      },
      {
        "char": "/",
        "block": "minecraft:spruce_slab[type=bottom,waterlogged=false]"
      },
      {
        "char": "0",
        "block": "minecraft:spruce_stairs[facing=north,half=bottom,shape=straight,waterlogged=false]"
      },
      {
        "char": "1",
        "block": "minecraft:water_cauldron[level=2]"
      },
      {
        "char": "2",
        "block": "tfmg:asphalt"
      },
      {
        "char": "3",
        "block": "tfmg:cinder_block"
      },
      {
        "char": "4",
        "block": "tfmg:factory_floor"
      },
      {
        "char": "5",
        "block": "the_wasteland_reworked:garbage_bag"
      },
      {
        "char": "6",
        "block": "zvhouses:spruce_countertop"
      }
    ]
  }
}
