{
  "xsize": 16,
  "zsize": 16,
  "slices": [
    [
      "++++++++++++++++",
      "++&++++&++++&+++",
      "++++++++++++++++",
      "+%++++++++++++++",
      "++++++++++++++++",
      "++++++++++++++++",
      "++++++++++++++++",
      "++++++++++++++++",
      "++++++++++++++++",
      " %++++++++++++++",
      " +++++++++++++++",
      " +++++++++++++&&",
      " +++++++++++&&%+",
      " +++++++++&&%+++",
      " +++++++&&%+++++",
      " %++++&&%+++++++"
    ],
    [
      "                ",
      "                ",
      "                ",
      "                ",
      "                ",
      "            ((((",
      "            ((((",
      "            ((((",
      "   ,,,,,,,,,((((",
      "   ,,,,,,,,,((((",
      "   ,,,,,,,,,,,,,",
      "   ,,,,,,,,,,,,,",
      "   ,,,,,,,,,,,,,",
      "   ,,,,,,,,,,,,,",
      "   ,,,,,,,,,,,,,",
      "   ,,,,,,,,,,,,,"
    ],
    [
      "                ",
      "                ",
      "                ",
      "                ",
      "                ",
      "            ****",
      "            *   ",
      "   '      ' *   ",
      "   '$$$$$$'$*   ",
      "   $        ****",
      "   $            ",
      "   $            ",
      "   $   )   )    ",
      "   $   )   )    ",
      "   $   )   )    ",
      "   $   )   )    "
    ],
    [
      "                ",
      "                ",
      "                ",
      "                ",
      "                ",
      "            ****",
      "            *   ",
      "   '      ' *   ",
      "   '$!!$!!'$*   ",
      "   $        ****",
      "   $            ",
      "   $            ",
      "   !   )   )    ",
      "   !   )   )    ",
      "   $   )   )    ",
      "   $   )   )    "
    ],
    [
      "                ",
      "                ",
      "                ",
      "                ",
      "                ",
      "            ****",
      "            *   ",
      "   '      ' *   ",
      "   '$!!$!!'$*   ",
      "   $        ****",
      "   $            ",
      "   $            ",
      "   !   )   )    ",
      "   !   )   )    ",
      "   $   )   )    ",
      "   $   )   )    "
    ],
    [
      "                ",
      "                ",
      "                ",
      "                ",
      "                ",
      "            ****",
      "            *   ",
      "   '      ' *   ",
      "   '$$$$$$'$*   ",
      "   $        ****",
      "   $            ",
      "   $            ",
      "   $            ",
      "   $            ",
      "   $            ",
      "   $            "
    ]
  ],
  "palette": {
    "palette": [
      {
        "char": "!",
        "block": "create:framed_glass"
      },
      {
        "char": "$",
        "block": "minecraft:bricks"
      },
      {
        "char": "%",
        "block": "minecraft:coarse_dirt"
      },
      {
        "char": "&",
        "block": "minecraft:gravel"
      },
      {
        "char": "'",
        "block": "minecraft:mud_bricks"
      },
      {
        "char": "(",
        "block": "minecraft:polished_andesite"
      },
      {
        "char": ")",
        "block": "minecraft:scaffolding"
      },
      {
        "char": "*",
        "block": "minecraft:smooth_stone"
      },
      {
        "char": "+",
        "block": "tfmg:asphalt"
      },
      {
        "char": ",",
        "block": "tfmg:factory_floor"
      }
    ]
  }
}
