{
  "xsize": 16,
  "zsize": 16,
  "slices": [
    [
      "   0    /    /  ",
      "   0    /    /  ",
      "   0    /    /  ",
      "   0    /    /  ",
      "   0            ",
      "   0            ",
      "   0            ",
      "   0            ",
      "   0            ",
      "   0    /    /  ",
      "   0    /    /  ",
      "   0    /    /  ",
      "   0    /    /  ",
      "   0    /    /  ",
      "   0    /    /  ",
      "   0    /    /  "
    ],
    [
      "  *0++++++++++++",
      "  *0++++++++++++",
      "  *0++++++++++++",
      "  *0++++++++++++",
      "  *0++++++++++++",
      "  *0++++++++++++",
      "  *0++++++++++++",
      "  *0++++++++++++",
      "  *0++++++++++++",
      "  *        +++++",
      "  *        +++++",
      "  *        +++++",
      "  *        +++++",
      "  *        +++++",
      "  *        +++++",
      "  *        +++++"
    ],
    [
      "   0//-////-//  ",
      "   0 %  / %  /  ",
      "   0 $ !/ $ !/  ",
      "   0    /    /  ",
      "   0//-////-//  ",
      "   0//          ",
      "   0!&          ",
      "   0//          ",
      "   0//-////-// (",
      "             /  ",
      "            !/  ",
      "             /! ",
      "             /  ",
      "           -//  ",
      "             /  ",
      "            ,/  "
    ],
    [
      "   0//.////.//  ",
      "   0    /    /  ",
      "   0    /    /  ",
      "   0    /    /  ",
      "   0//.////.//  ",
      "   01/          ",
      "   0/'          ",
      "   0//          ",
      "   0//.////.// )",
      "             /  ",
      "             /  ",
      "             /  ",
      "             /  ",
      "           .//  ",
      "             /  ",
      "             /  "
    ],
    [
      "   0//////////  ",
      "   0    /    /  ",
      "   0    /    /  ",
      "   0    /    /  ",
      "   0//////////  ",
      "   0//          ",
      "   0//          ",
      "   0//          ",
      "   0//////////  ",
      "             /  ",
      "             /  ",
      "             /  ",
      "             /  ",
      "           ///  ",
      "             /  ",
      "             /  "
    ],
    [
      "   0//////////  ",
      "   0    /    /  ",
      "   0    /    /  ",
      "   0    /    /  ",
      "   0//////////  ",
      "   0//          ",
      "   0//          ",
      "   0//          ",
      "   0//////////  ",
      "             /  ",
      "             /  ",
      "             /  ",
      "             /  ",
      "           ///  ",
      "             /  ",
      "             /  "
    ]
  ],
  "palette": {
    "palette": [
      {
        "char": "!",
        "block": "minecraft:barrel[facing=up,open=false]"
      },
      {
        "char": "$",
        "block": "minecraft:brown_bed[facing=north,occupied=false,part=foot]"
      },
      {
        "char": "%",
        "block": "minecraft:brown_bed[facing=north,occupied=false,part=head]"
      },
      {
        "char": "&",
        "block": "minecraft:dark_oak_door[facing=east,half=lower,hinge=left,open=false,powered=false]"
      },
      {
        "char": "'",
        "block": "minecraft:dark_oak_door[facing=east,half=upper,hinge=left,open=false,powered=false]"
      },
      {
        "char": "(",
        "block": "minecraft:dark_oak_door[facing=south,half=lower,hinge=left,open=false,powered=false]"
      },
      {
        "char": ")",
        "block": "minecraft:dark_oak_door[facing=south,half=upper,hinge=left,open=false,powered=false]"
      },
      {
        "char": "*",
        "block": "minecraft:dark_oak_slab[type=bottom,waterlogged=false]"
      },
      {
        "char": "+",
        "block": "minecraft:oak_planks"
      },
      {
        "char": ",",
        "block": "minecraft:quartz_stairs[facing=south,half=bottom,shape=straight,waterlogged=false]"
      },
      {
        "char": "-",
        "block": "minecraft:spruce_door[facing=south,half=lower,hinge=left,open=false,powered=false]"
      },
      {
        "char": ".",
        "block": "minecraft:spruce_door[facing=south,half=upper,hinge=left,open=false,powered=false]"
      },
      {
        "char": "/",
        "block": "minecraft:stripped_oak_wood"
      },
      {
        "char": "0",
        "block": "minecraft:yellow_terracotta"
      },
      {
        "char": "1",
        "block": "supplementaries:item_shelf"
      }
    ]
  }
}
