{
  "xsize": 16,
  "zsize": 16,
  "slices": [
    [
      "%:::::::::::::::",
      ":::::::::::::::(",
      ":::::::::::::((%",
      ":::::::::::((%::",
      ":::::::::((%::::",
      "::::)))))%::::::",
      "::::))))):::::::",
      ":::())))):::::::",
      ":((%))))):::::::",
      "(%::))))):::::::",
      "::::::::::::::::",
      "::::::::::::::((",
      "::::::::::::((%:",
      "::::::::::((%:::",
      "::::::::((%:::::",
      "::::::((%:::::::"
    ],
    [
      "              --",
      "          4   --",
      "              --",
      "              --",
      "   ------- +++++",
      "   -77777- +++++",
      "   -77777- +++++",
      "   -77777- +++++",
      "   -77777- +++++",
      "   -77777- +++++",
      "   ------- +++++",
      "           +++++",
      "   +++++++++++++",
      "   +++++++++++++",
      "   +++++++++++++",
      "   +++++++++++++"
    ],
    [
      "                ",
      "          4     ",
      "                ",
      "                ",
      "           99994",
      "           9   4",
      "           9 '  ",
      "           9   '",
      "           9 &&&",
      "           9 5  ",
      "           90.  ",
      "   * 00 * 0025$ ",
      "   **********5**",
      "   9    5    5  ",
      "   9 8 ,5 8 ,5  ",
      "   9    5    5  "
    ],
    [
      "                ",
      "          4     ",
      "                ",
      "                ",
      "           99994",
      "           9   4",
      "           9    ",
      "           9    ",
      "           9  ;'",
      "           9 5  ",
      "           9 /  ",
      "   *    *  9 5  ",
      "   96!!696!!6599",
      "   9    5    5  ",
      "   9    5    5  ",
      "   9    5    5  "
    ],
    [
      "                ",
      "          4     ",
      "                ",
      "                ",
      "           99994",
      "           9   4",
      "           9    ",
      "           9    ",
      "           9    ",
      "           9 5 '",
      "           9 5  ",
      "   *    *  9 5  ",
      "   96!!696!!6599",
      "   9    5    5  ",
      "   9    5    5  ",
      "   9    5    5  "
    ],
    [
      "                ",
      "          4     ",
      "                ",
      "                ",
      "           99993",
      "           9   3",
      "           9    ",
      "           9    ",
      "           9    ",
      "           9 5  ",
      "           9 5 '",
      "   * 11 * 11 5  ",
      "   9999999999599",
      "   9    5    5  ",
      "   9    5    5  ",
      "   9    5    5  "
    ]
  ],
  "palette": {
    "palette": [
      {
        "char": "!",
        "block": "create:framed_glass"
      },
      {
        "char": "$",
        "block": "minecraft:barrel[facing=up,open=false]"
      },
      {
        "char": "%",
        "block": "minecraft:coarse_dirt"
      },
      {
        "char": "&",
        "block": "minecraft:dark_oak_slab[type=bottom,waterlogged=false]"
      },
      {
        "char": "'",
        "block": "minecraft:dark_oak_stairs[facing=south,half=bottom,shape=straight,waterlogged=false]"
      },
      {
        "char": "(",
        "block": "minecraft:gravel"
      },
      {
        "char": ")",
        "block": "minecraft:light_blue_concrete"
      },
      {
        "char": "*",
        "block": "minecraft:mud_bricks"
      },
      {
        "char": "+",
        "block": "minecraft:oak_planks"
      },
      {
        "char": ",",
        "block": "minecraft:quartz_stairs[facing=north,half=bottom,shape=straight,waterlogged=false]"
      },
      {
        "char": "-",
        "block": "minecraft:smooth_stone"
      },
      {
        "char": ".",
        "block": "minecraft:spruce_door[facing=east,half=lower,hinge=left,open=false,powered=false]"
      },
      {
        "char": "/",
        "block": "minecraft:spruce_door[facing=east,half=upper,hinge=left,open=false,powered=false]"
      },
      {
        "char": "0",
        "block": "minecraft:spruce_slab[type=bottom,waterlogged=false]"
      },
      {
        "char": "1",
        "block": "minecraft:spruce_slab[type=top,waterlogged=false]"
      },
      {
        "char": "2",
        "block": "minecraft:spruce_stairs[facing=north,half=bottom,shape=straight,waterlogged=false]"
      },
      {
        "char": "3",
        "block": "minecraft:stripped_dark_oak_log[axis=x]"
      },
      {
        "char": "4",
        "block": "minecraft:stripped_dark_oak_log[axis=y]"
      },
      {
        "char": "5",
        "block": "minecraft:stripped_oak_wood"
      },
      {
        "char": "6",
        "block": "minecraft:stripped_spruce_log[axis=y]"
      },
      {
        "char": "7",
        "block": "minecraft:water"
      },
      {
        "char": "8",
        "block": "kubejs:ruined_cauldron"
      },
      {
        "char": "9",
        "block": "minecraft:yellow_terracotta"
      },
      {
        "char": ":",
        "block": "tfmg:asphalt"
      },
      {
        "char": ";",
        "block": "the_wasteland_reworked:radio"
      }
    ]
  }
}
