{
  "xsize": 16,
  "zsize": 16,
  "slices": [
    [
      ".......**)......",
      ".....**)........",
      "...**)..........",
      ".**)............",
      "*)..............",
      "................",
      "..............**",
      "............**).",
      "..........**)...",
      "........**).....",
      "......**).......",
      "....**).........",
      "..**)...........",
      "**).............",
      ")...............",
      "...............*"
    ],
    [
      "0000000000000000",
      "0000000000000000",
      "0000000000000000",
      "0000000000000000",
      "0000000000000000",
      "0000000000000000",
      "0000000000000000",
      "0000000000000000",
      "0000000000000000",
      "0000000000000000",
      "0000000000000000",
      "0000000000000000",
      "0000000000000000",
      "0000000000000000",
      "0000000000000000",
      "0000000000000000"
    ],
    [
      "!!!!  $$$$$$$/  ",
      "             /  ",
      "    1       1/  ",
      "&  &  &  &  &/  ",
      "!  !  !  !  !/  ",
      "             +  ",
      "             /  ",
      "  222  222  2/2 ",
      "  222  222  2/22",
      "  222  222  2/22",
      "  222  222  2/22",
      "  222  222  2/2 ",
      "  222  222  2/2 ",
      "             ///",
      " ((((((    (((((",
      " ((((((    ((((("
    ],
    [
      "             /  ",
      "             /  ",
      "    1       1/  ",
      "             /  ",
      "             /  ",
      "             ,  ",
      "             /  ",
      "             /  ",
      "   '    '    /  ",
      "             /  ",
      "             /  ",
      "   %    %    /  ",
      "             /  ",
      "             ///",
      "                ",
      "                "
    ],
    [
      "             /  ",
      "             /  ",
      "    1       1/  ",
      "             /  ",
      "             /  ",
      "             /  ",
      "---          /  ",
      "             /  ",
      "             /  ",
      "             /  ",
      "             /  ",
      "             /  ",
      "             /  ",
      "             ///",
      "                ",
      "                "
    ],
    [
      "             /  ",
      "             /  ",
      "    1       1/  ",
      "             /  ",
      "             /  ",
      "             /  ",
      "             /  ",
      "             /  ",
      "             /  ",
      "             /  ",
      "             /  ",
      "             /  ",
      "             /  ",
      "             ///",
      "                ",
      "                "
    ]
  ],
  "palette": {
    "palette": [
      {
        "char": "!",
        "block": "create:andesite_casing"
      },
      {
        "char": "$",
        "block": "create:brass_casing"
      },
      {
        "char": "%",
        "block": "create:cardboard_block"
      },
      {
        "char": "&",
        "block": "create:depot"
      },
      {
        "char": "'",
        "block": "create:mechanical_press"
      },
      {
        "char": "(",
        "block": "jaffabricate:pallet_full"
      },
      {
        "char": ")",
        "block": "minecraft:coarse_dirt"
      },
      {
        "char": "*",
        "block": "minecraft:gravel"
      },
      {
        "char": "+",
        "block": "minecraft:spruce_door[facing=east,half=lower,hinge=left,open=false,powered=false]"
      },
      {
        "char": ",",
        "block": "minecraft:spruce_door[facing=east,half=upper,hinge=left,open=false,powered=false]"
      },
      {
        "char": "-",
        "block": "minecraft:weathered_cut_copper"
      },
      {
        "char": ".",
        "block": "tfmg:asphalt"
      },
      {
        "char": "/",
        "block": "tfmg:cinder_block"
      },
      {
        "char": "0",
        "block": "tfmg:factory_floor"
      },
      {
        "char": "1",
        "block": "tfmg:steel_block"
      },
      {
        "char": "2",
        "block": "zvhouses:stone_brick_countertop"
      }
    ]
  }
}
