{
  "xsize": 16,
  "zsize": 16,
  "slices": [
    [
      "))))))))))      ",
      "))))))))))      ",
      ")))))))))&      ",
      ")))))))&&%      ",
      ")))))&&%))      ",
      ")))&&%)))&      ",
      ")&&%))))))      ",
      "&%))))))))      ",
      "))))))))))      ",
      "))))))))))      ",
      "))))))))))      ",
      ")))))))))&      ",
      "))))))))&&      ",
      "))))))&&%)      ",
      "))))&&%)))      ",
      "))&&%)))))      "
    ],
    [
      "++++++++        ",
      "++++++++        ",
      "++++++++        ",
      "++++++++        ",
      "++++++++        ",
      "++++++++        ",
      "++++++++        ",
      "++++++++        ",
      "++++++++        ",
      "++++$$$$        ",
      "++++$$$$        ",
      "++++$$$$        ",
      "++++$$$$        ",
      "&&&&&&&&&&&     ",
      "&&&&&&&&&&&     ",
      "&&&&&&&&&&&     "
    ],
    [
      "       $        ",
      "       $        ",
      "       $        ",
      "       $        ",
      "       $        ",
      " (     $        ",
      "       $        ",
      "$$$$$$$$        ",
      "       $        ",
      "    $$$$        ",
      " '  $  $        ",
      "    $  $        ",
      "    $$$$        ",
      "&&&&&&&&&&&     ",
      "&&&&&&&&&&&     ",
      "&&&&&&&&&&&     "
    ],
    [
      "       $        ",
      "       $        ",
      "       $        ",
      "       $        ",
      "       $        ",
      "       $        ",
      "       $        ",
      "$$$$$$$$        ",
      "       $        ",
      "    $$$$        ",
      "    $  $        ",
      "    $  $        ",
      "    $$$$        ",
      "&&&&&&&&&&&     ",
      "&&&&&&&&&&&     ",
      "&&&&&&&&&&&     "
    ],
    [
      "       $        ",
      "       $        ",
      "       $        ",
      "       $        ",
      "       $        ",
      "       $        ",
      "       $        ",
      "$$$$$$$$        ",
      "       $        ",
      "    $$$$        ",
      "    $  $        ",
      "    $  $        ",
      "    $$$$        ",
      "&&&&&&&&&&&     ",
      "&&&&&&&&&&&     ",
      "&&&&&&&&&&&     "
    ],
    [
      "       $        ",
      "       $        ",
      "       $        ",
      "       $        ",
      "       $        ",
      "       $        ",
      "       $        ",
      "$$$$$$$$        ",
      "       !        ",
      "    $$$$        ",
      "    $  $        ",
      "    $  $        ",
      "    $$$$        ",
      "       $        ",
      "       $        ",
      "*******$        "
    ]
  ],
  "palette": {
    "palette": [
      {
        "char": "!",
        "block": "create:framed_glass"
      },
      {
        "char": "$",
        "block": "minecraft:bricks"
      },
      {
        "char": "%",
        "block": "minecraft:coarse_dirt"
      },
      {
        "char": "&",
        "block": "minecraft:gravel"
      },
      {
        "char": "'",
        "block": "minecraft:smoker[facing=south,lit=false]"
      },
      {
        "char": "(",
        "block": "minecraft:water_cauldron[level=3]"
      },
      {
        "char": ")",
        "block": "tfmg:asphalt"
      },
      {
        "char": "*",
        "block": "tfmg:cinder_block"
      },
      {
        "char": "+",
        "block": "tfmg:factory_floor"
      }
    ]
  }
}
