{
  "xsize": 16,
  "zsize": 16,
  "slices": [
    [
      "A//$AAAAAAAAAAAA",
      "/$AAAAAAAAAAAAAA",
      "AAAAAAAAAAAAAAAA",
      "AAAAAAAAAAAAAA//",
      "AAAAAAAAAAAA//$A",
      "AAAAAAAAAA//$AAA",
      "AAAAAAAA//$AAAAA",
      "AAAAAA//$AAAAAAA",
      "AAAA//$AAAAAAAAA",
      "AA//$AAAAAAAAAAA",
      "//$AAAAAAAAAAAAA",
      "$AAAAAAAAAAAAAAA",
      "AAAAAAAAAAAAAAA/",
      "AAAAAAAAAAAAA//$",
      "AAAAAAAAAAA//$AA",
      "AAAAAAAAA//$AAAA"
    ],
    [
      "33333           ",
      "33333   :       ",
      "33333           ",
      "33333           ",
      "11111111 >  >  >",
      "11111111 >  >  >",
      "11111111 >  >  >",
      "11111111 >  >  >",
      "11111111 >  >  >",
      "11111111 >  >  >",
      "11111111 >88>88>",
      "11111111        ",
      "1111111111111111",
      "1111111111111111",
      "1111111111111111",
      "1111111111111111"
    ],
    [
      "                ",
      "        :       ",
      "                ",
      "                ",
      "  :?????        ",
      "%&:    ?        ",
      ".  .   ?        ",
      ".      ?        ",
      "----   ?        ",
      "    ;  ?        ",
      "    4  ?        ",
      "  0 6620 66 0  0",
      ")*00;00000000000",
      "  ;    ;    ;  ?",
      "  ; = 2; = 2;  ?",
      "  ;    ;    ;  ?"
    ],
    [
      "                ",
      "        :       ",
      "                ",
      "                ",
      "  :?????        ",
      "'(:    ?        ",
      "       ?        ",
      "       ?        ",
      ". @    ?        ",
      "    ;  ?        ",
      "    5  ?        ",
      "  0 ;  0    0  0",
      "+,?<!!<?<!!<????",
      "  ;    ;    ;  ?",
      "  ;    ;    ;  ?",
      "  ;    ;    ;  ?"
    ],
    [
      "                ",
      "        :       ",
      "                ",
      "                ",
      "  :?????        ",
      "  :    ?        ",
      "       ?        ",
      "       ?        ",
      "       ?        ",
      ".   ;  ?        ",
      "    ;  ?        ",
      "  0 ;  0    0  0",
      "  ?<!!<?<!!<????",
      "  ;    ;    ;  ?",
      "  ;    ;    ;  ?",
      "  ;    ;    ;  ?"
    ],
    [
      "                ",
      "        :       ",
      "                ",
      "                ",
      "999?????        ",
      "999    ?        ",
      "       ?        ",
      "       ?        ",
      "       ?        ",
      "    ;  ?        ",
      ".   ;  ?        ",
      "  0 77 0 77 0  0",
      "????;???????????",
      "  ;    ;    ;  ?",
      "  ;    ;    ;  ?",
      "  ;    ;    ;  ?"
    ]
  ],
  "palette": {
    "palette": [
      {
        "char": "!",
        "block": "create:framed_glass"
      },
      {
        "char": "$",
        "block": "minecraft:coarse_dirt"
      },
      {
        "char": "%",
        "block": "minecraft:dark_oak_door[facing=north,half=lower,hinge=left,open=false,powered=false]"
      },
      {
        "char": "&",
        "block": "minecraft:dark_oak_door[facing=north,half=lower,hinge=right,open=false,powered=false]"
      },
      {
        "char": "'",
        "block": "minecraft:dark_oak_door[facing=north,half=upper,hinge=left,open=false,powered=false]"
      },
      {
        "char": "(",
        "block": "minecraft:dark_oak_door[facing=north,half=upper,hinge=right,open=false,powered=false]"
      },
      {
        "char": ")",
        "block": "minecraft:dark_oak_door[facing=south,half=lower,hinge=left,open=false,powered=false]"
      },
      {
        "char": "*",
        "block": "minecraft:dark_oak_door[facing=south,half=lower,hinge=right,open=false,powered=false]"
      },
      {
        "char": "+",
        "block": "minecraft:dark_oak_door[facing=south,half=upper,hinge=left,open=false,powered=false]"
      },
      {
        "char": ",",
        "block": "minecraft:dark_oak_door[facing=south,half=upper,hinge=right,open=false,powered=false]"
      },
      {
        "char": "-",
        "block": "minecraft:dark_oak_slab[type=bottom,waterlogged=false]"
      },
      {
        "char": ".",
        "block": "minecraft:dark_oak_stairs[facing=south,half=bottom,shape=straight,waterlogged=false]"
      },
      {
        "char": "/",
        "block": "minecraft:gravel"
      },
      {
        "char": "0",
        "block": "minecraft:mud_bricks"
      },
      {
        "char": "1",
        "block": "minecraft:oak_planks"
      },
      {
        "char": "2",
        "block": "minecraft:quartz_stairs[facing=north,half=bottom,shape=straight,waterlogged=false]"
      },
      {
        "char": "3",
        "block": "minecraft:smooth_stone"
      },
      {
        "char": "4",
        "block": "minecraft:spruce_door[facing=east,half=lower,hinge=left,open=false,powered=false]"
      },
      {
        "char": "5",
        "block": "minecraft:spruce_door[facing=east,half=upper,hinge=left,open=false,powered=false]"
      },
      {
        "char": "6",
        "block": "minecraft:spruce_slab[type=bottom,waterlogged=false]"
      },
      {
        "char": "7",
        "block": "minecraft:spruce_slab[type=top,waterlogged=false]"
      },
      {
        "char": "8",
        "block": "minecraft:stone_bricks"
      },
      {
        "char": "9",
        "block": "minecraft:stripped_dark_oak_log[axis=x]"
      },
      {
        "char": ":",
        "block": "minecraft:stripped_dark_oak_log[axis=y]"
      },
      {
        "char": ";",
        "block": "minecraft:stripped_oak_wood"
      },
      {
        "char": "<",
        "block": "minecraft:stripped_spruce_log[axis=y]"
      },
      {
        "char": "=",
        "block": "minecraft:water_cauldron[level=1]"
      },
      {
        "char": ">",
        "block": "minecraft:white_concrete"
      },
      {
        "char": "?",
        "block": "minecraft:yellow_terracotta"
      },
      {
        "char": "@",
        "block": "supplementaries:item_shelf"
      },
      {
        "char": "A",
        "block": "tfmg:asphalt"
      }
    ]
  }
}
