{
  "xsize": 16,
  "zsize": 16,
  "slices": [
    [
      "'''''''''''''!!!",
      "'''''''''''$$!!!",
      "'''''''''$$!'!!!",
      "'''''''$$!'''!!!",
      "'''''$$!'''''!!!",
      "''''$!'''''''!!!",
      "''''''''''''''''",
      "''''''''''''''''",
      "''''''''''''''''",
      "''''''''''''''$$",
      "''''''''''''$$!'",
      "''''''''''$$!'''",
      "'''''''''$!'''''",
      "''''''''''''''''",
      "''''''''''''''''",
      "''$'''''''''''''"
    ],
    [
      "                ",
      "                ",
      "                ",
      "                ",
      "                ",
      "                ",
      "                ",
      "                ",
      "                ",
      "                ",
      "                ",
      "                ",
      "                ",
      "&&&             ",
      "&&& %%%         ",
      "&&& %%%         "
    ],
    [
      "                ",
      "                ",
      "                ",
      "                ",
      "                ",
      "                ",
      "                ",
      "                ",
      "                ",
      "                ",
      "                ",
      "                ",
      "                ",
      "(((             ",
      "  ( %%%         ",
      "  ( %%%         "
    ],
    [
      "                ",
      "                ",
      "                ",
      "                ",
      "                ",
      "                ",
      "                ",
      "                ",
      "                ",
      "                ",
      "                ",
      "                ",
      "                ",
      "(((             ",
      "  (             ",
      "  (             "
    ],
    [
      "                ",
      "                ",
      "                ",
      "                ",
      "                ",
      "                ",
      "                ",
      "                ",
      "                ",
      "                ",
      "                ",
      "                ",
      "                ",
      "(((             ",
      "  (             ",
      "  (             "
    ],
    [
      "                ",
      "                ",
      "                ",
      "                ",
      "                ",
      "                ",
      "                ",
      "                ",
      "                ",
      "                ",
      "                ",
      "                ",
      "                ",
      "(((             ",
      "  (             ",
      "  (             "
    ]
  ],
  "palette": {
    "palette": [
      {
        "char": "!",
        "block": "minecraft:coarse_dirt"
      },
      {
        "char": "$",
        "block": "minecraft:gravel"
      },
      {
        "char": "%",
        "block": "minecraft:oxidized_copper"
      },
      {
        "char": "&",
        "block": "minecraft:spruce_planks"
      },
      {
        "char": "'",
        "block": "tfmg:asphalt"
      },
      {
        "char": "(",
        "block": "the_wasteland_reworked:decayed_planks"
      }
    ]
  }
}
