{
  "xsize": 16,
  "zsize": 16,
  "slices": [
    [
      "(((((((((($$!(((",
      "(((((((($$!(((((",
      "(((((($$!(((((((",
      "(((($$!(((((((((",
      "(($$!(((((((((((",
      "$$!(((((((((((((",
      "!(((((((((((((((",
      "((((((((((((((($",
      "((((((((((((($$!",
      "((((((((((($$!((",
      "((((((((($$!((((",
      "((((((($$(((((((",
      "(((((($!((((((((",
      "((((((((((((((((",
      "((((((((((((((((",
      "(((((((((((((((("
    ],
    [
      " &&&&&&&&&&&&&&&",
      " &&&&&&&&&&&&&&&",
      " &&&&&&&&&&&&&&&",
      " &&&&&&&&&&&&&&&",
      " &&&&&&&&&&&&&&&",
      " &&&&&&&&&&&&&&&",
      " &&&&&&&&&&&&&&&",
      " &&&&&&&&&&&&&&&",
      "%               ",
      "                ",
      "                ",
      "                ",
      "                ",
      "'        '      ",
      "'        '      ",
      "'        '      "
    ],
    [
      "                ",
      "                ",
      "                ",
      "                ",
      "                ",
      "                ",
      "                ",
      "                ",
      "%               ",
      "                ",
      "                ",
      "                ",
      "                ",
      "                ",
      "                ",
      "                "
    ],
    [
      "                ",
      "                ",
      "                ",
      "                ",
      "                ",
      "                ",
      "                ",
      "                ",
      "%               ",
      "                ",
      "                ",
      "                ",
      "                ",
      "                ",
      "                ",
      "                "
    ],
    [
      "                ",
      "                ",
      "                ",
      "                ",
      "                ",
      "                ",
      "                ",
      "                ",
      "%               ",
      "                ",
      "                ",
      "                ",
      "                ",
      "                ",
      "                ",
      "                "
    ],
    [
      "                ",
      "                ",
      "                ",
      "                ",
      "                ",
      "                ",
      "                ",
      "                ",
      "%               ",
      "                ",
      "                ",
      "                ",
      "                ",
      "                ",
      "                ",
      "                "
    ]
  ],
  "palette": {
    "palette": [
      {
        "char": "!",
        "block": "minecraft:coarse_dirt"
      },
      {
        "char": "$",
        "block": "minecraft:gravel"
      },
      {
        "char": "%",
        "block": "minecraft:polished_blackstone_bricks"
      },
      {
        "char": "&",
        "block": "minecraft:smooth_stone"
      },
      {
        "char": "'",
        "block": "minecraft:white_concrete"
      },
      {
        "char": "(",
        "block": "tfmg:asphalt"
      }
    ]
  }
}
