{
  "xsize": 16,
  "zsize": 16,
  "slices": [
    [
      "1111111''&111111",
      "11111''&11111111",
      "111''&1111111111",
      "1''&111111111111",
      "'&11111111111111",
      "1111111111111111",
      "11111111111111''",
      "111111111111''&1",
      "1111111111''&111",
      "11111111''&11111",
      "111111''&1111111",
      "1111''&111111111",
      "1111&11111111111",
      "1111111111111111",
      "1111111111111111",
      "111111111111111'"
    ],
    [
      "3333333333333333",
      "3333333333333333",
      "3333333333333333",
      "3333333333333333",
      "3333333333333333",
      "3333333333333333",
      "3333333333333333",
      "3333333333333333",
      "3333333333333333",
      "3333333333333333",
      "3333333333333333",
      "3333333333333333",
      "3333333333333333",
      "3333333333333333",
      "3333333333333333",
      "3333333333333333"
    ],
    [
      "        )   )  $",
      "        )   )  $",
      "..      )   )  $",
      "/              $",
      "4444444        $",
      "               $",
      "2,222222222,222$",
      "    2    2     $",
      "    2    2 ))) $",
      "0   20   20))) $",
      "    *    * ))) $",
      "    2    2 ))) $",
      "    2    2 )%) $",
      "(   2(   2())) $",
      "    2    2 ))) $",
      "    2    2     $"
    ],
    [
      "        )   )  $",
      "        )   )  $",
      "        )   )  !",
      "               !",
      "               $",
      "               $",
      "2-222222222-222$",
      "    2    2     $",
      "    2    2 ))) $",
      "    2    2 ))) $",
      "    +    + ))) !",
      "    2    2 ))) !",
      "    2    2 ))) $",
      "    2    2 ))) $",
      "    2    2 ))) $",
      "    2    2     $"
    ],
    [
      "        )   )  $",
      "        )   )  $",
      "        )   )  !",
      "               !",
      "               $",
      "               $",
      "222222222222222$",
      "    2    2     $",
      "    2    2 ))) $",
      "    2    2 ))) $",
      "    2    2 ))) !",
      "    2    2 ))) !",
      "    2    2 ))) $",
      "    2    2 ))) $",
      "    2    2 ))) $",
      "    2    2     $"
    ],
    [
      "               $",
      "               $",
      "               $",
      "               $",
      "               $",
      "               $",
      "222222222222222$",
      "    2    2     $",
      "    2    2     $",
      "    2    2     $",
      "    2    2     $",
      "    2    2     $",
      "    2    2     $",
      "    2    2     $",
      "    2    2     $",
      "    2    2     $"
    ]
  ],
  "palette": {
    "palette": [
      {
        "char": "!",
        "block": "create:framed_glass"
      },
      {
        "char": "$",
        "block": "minecraft:bricks"
      },
      {
        "char": "%",
        "block": "minecraft:chest[facing=south,type=single,waterlogged=false]",
        "tag": {
          "id": "minecraft:chest",
          "LootTable": "infinite_domain:chests/wasteland_roadside"
        }
      },
      {
        "char": "&",
        "block": "minecraft:coarse_dirt"
      },
      {
        "char": "'",
        "block": "minecraft:gravel"
      },
      {
        "char": "(",
        "block": "minecraft:quartz_stairs[facing=south,half=bottom,shape=straight,waterlogged=false]"
      },
      {
        "char": ")",
        "block": "minecraft:scaffolding"
      },
      {
        "char": "*",
        "block": "minecraft:spruce_door[facing=east,half=lower,hinge=left,open=false,powered=false]"
      },
      {
        "char": "+",
        "block": "minecraft:spruce_door[facing=east,half=upper,hinge=left,open=false,powered=false]"
      },
      {
        "char": ",",
        "block": "minecraft:spruce_door[facing=south,half=lower,hinge=left,open=false,powered=false]"
      },
      {
        "char": "-",
        "block": "minecraft:spruce_door[facing=south,half=upper,hinge=left,open=false,powered=false]"
      },
      {
        "char": ".",
        "block": "minecraft:spruce_slab[type=bottom,waterlogged=false]"
      },
      {
        "char": "/",
        "block": "minecraft:spruce_stairs[facing=north,half=bottom,shape=straight,waterlogged=false]"
      },
      {
        "char": "0",
        "block": "kubejs:ruined_cauldron"
      },
      {
        "char": "1",
        "block": "tfmg:asphalt"
      },
      {
        "char": "2",
        "block": "tfmg:cinder_block"
      },
      {
        "char": "3",
        "block": "tfmg:factory_floor"
      },
      {
        "char": "4",
        "block": "zvhouses:spruce_countertop"
      }
    ]
  }
}
