{
  "xsize": 16,
  "zsize": 16,
  "slices": [
    [
      ",,,,,,(,,,,,,,,,",
      ",,,,,,,,,,,,,,,,",
      ",,,,,,,,,,,,,,,,",
      ",,,,,,,,,,,,,,,,",
      ",,,,,,,,,,,,,,,)",
      ",,,,,,,,,,,,,))(",
      ",,,,,,,,,,,))(,,",
      ",,,,,,,,,))(,,,,",
      ",,,,,,,))(,,,,,,",
      ",,,,,,)(,,,,,,,,",
      ",,,,,,,,,,,,,,,,",
      ",,,,,,,,,,,,,,,,",
      ",,,,,,,,,,,,,,,,",
      ",,,,,,,,,,,,,,,,",
      ",,,,,,,,,,,,,,))",
      ",,,,,,,,,,,,))(,"
    ],
    [
      " )))))))))))))))",
      " )))))))))))))))",
      " )))))))))))))))",
      " )))))))))))))))",
      " )))))))))))))))",
      " )))))))))))))))",
      " )))))))))))))))",
      "  ))))))))))))))",
      "  ))))))))))))))",
      " ))&)))))))))))&",
      "  ***-----------",
      "  ***-----------",
      "  ***-----------",
      "  ***-----------",
      "   -------------",
      "   -------------"
    ],
    [
      " )))))))))))))))",
      " )))))))))))))))",
      " ))))))))))0))))",
      " )))))))))))))))",
      " ))))))))))))))&",
      " &&)))))))))))& ",
      " & %)))))))))&  ",
      "   )))))))))&/11",
      "   )&&)))))& 111",
      "    & ')))&''111",
      "      ''' '''111",
      "      ''' '''111",
      "             111",
      "      ''' '''   ",
      "   %  '''''''   ",
      "   %  '''''''   "
    ],
    [
      " )))))))))))))))",
      "  ))))))))))))))",
      "  ))))))))))))))",
      " ))&)))))))))))&",
      "  && )))))))))& ",
      "   % ))))))))&  ",
      "   %))&)))))&   ",
      "   % && )))&    ",
      "   %    ))&   $ ",
      "      '))&'''   ",
      "      ''' '''   ",
      "      ''' ''' ! ",
      "                ",
      "      ''' '''   ",
      "   %  ''' '''   ",
      "   %  ''' '''   "
    ],
    [
      " & %)))))))))&  ",
      "   )))))))))&   ",
      "   )&&)))))&.   ",
      "   %&  )))&     ",
      "   %  )))&      ",
      "   %  )&&       ",
      "   %   &++++++++",
      "   %            ",
      "   %            ",
      "      ''' '''   ",
      "      ''' '''   ",
      "      ''' '''   ",
      "                ",
      "      ''' '''   ",
      "   %  ''' '''   ",
      "   %  ''' '''   "
    ],
    [
      "    ))&)))))&   ",
      "     && )))&    ",
      "        ))& .   ",
      "   %   ))&      ",
      "   %    &       ",
      "   %            ",
      "   %            ",
      "   %            ",
      "   %            ",
      "                ",
      "                ",
      "                ",
      "                ",
      "                ",
      "   %            ",
      "   %            "
    ]
  ],
  "palette": {
    "palette": [
      {
        "char": "!",
        "block": "create:cardboard_block"
      },
      {
        "char": "$",
        "block": "create:mechanical_press"
      },
      {
        "char": "%",
        "block": "immersiveengineering:concrete_brick"
      },
      {
        "char": "&",
        "block": "immersiveengineering:concrete_brick_cracked"
      },
      {
        "char": "'",
        "block": "jaffabricate:pallet_full"
      },
      {
        "char": "(",
        "block": "minecraft:coarse_dirt"
      },
      {
        "char": ")",
        "block": "minecraft:gravel"
      },
      {
        "char": "*",
        "block": "minecraft:smooth_stone"
      },
      {
        "char": "+",
        "block": "minecraft:weathered_cut_copper"
      },
      {
        "char": ",",
        "block": "tfmg:asphalt"
      },
      {
        "char": "-",
        "block": "tfmg:factory_floor"
      },
      {
        "char": ".",
        "block": "tfmg:steel_block"
      },
      {
        "char": "/",
        "block": "the_wasteland_reworked:garbage_bag"
      },
      {
        "char": "0",
        "block": "wastelands:scrap_pile"
      },
      {
        "char": "1",
        "block": "zvhouses:stone_brick_countertop"
      }
    ]
  }
}
