{
  "xsize": 16,
  "zsize": 16,
  "slices": [
    [
      "                ",
      "+++++++++       ",
      "+++++++++       ",
      "+++++++++       ",
      "+++++++++       ",
      "+++++++++       ",
      "       1        ",
      "       1        ",
      "       1        ",
      "       1        ",
      "       1        ",
      "& '    '    '  '",
      "1111111111111111",
      "  .    .    .  1",
      "  .    .    .  1",
      "  .    .    .  1"
    ],
    [
      "                ",
      "                ",
      "                ",
      "'''''           ",
      "11111111        ",
      "       1        ",
      "       1        ",
      "       1        ",
      "       1        ",
      "       1        ",
      "       1        ",
      " %'%%%%'%%%%'%%'",
      "&111111111111111",
      "(((((((((((((((1",
      "(((((((((((((((1",
      "(((((((((((((((1"
    ],
    [
      "                ",
      "                ",
      "****            ",
      "'''''           ",
      "$$$$$$$$        ",
      "$$$$$$$$        ",
      "$$$$$$$$        ",
      "$$$$$$$$        ",
      "$$$$$$$$        ",
      "$$$$$$$$        ",
      "$$$$$$$$        ",
      ",$'$,,$' ,, '  '",
      " 111111111111111",
      "  .    .    .  1",
      "  . 0 ). 0 ).  1",
      "  .    .    .  1"
    ],
    [
      "                ",
      "                ",
      "****            ",
      "'''''           ",
      "                ",
      "                ",
      "                ",
      "                ",
      "                ",
      "                ",
      "                ",
      "  '    '    '  '",
      "!/1/!!/1/!!/1111",
      "  .    .    .  1",
      "  .    .    .  1",
      "  .    .    .  1"
    ],
    [
      "                ",
      "                ",
      "                ",
      "'''''           ",
      "                ",
      "                ",
      "                ",
      "                ",
      "                ",
      "                ",
      "                ",
      "  '    '    '  '",
      "!/1/!!/1/!!/1111",
      "  .    .    .  1",
      "  .    .    .  1",
      "  .    .    .  1"
    ],
    [
      "                ",
      "                ",
      "                ",
      "                ",
      "                ",
      "                ",
      "                ",
      "                ",
      "                ",
      "                ",
      "                ",
      "- ' -- ' -- '  '",
      "1111111111111111",
      "  .    .    .  1",
      "  .    .    .  1",
      "  .    .    .  1"
    ]
  ],
  "palette": {
    "palette": [
      {
        "char": "!",
        "block": "create:framed_glass"
      },
      {
        "char": "$",
        "block": "minecraft:dark_oak_planks"
      },
      {
        "char": "%",
        "block": "minecraft:dark_oak_slab[type=bottom,waterlogged=false]"
      },
      {
        "char": "&",
        "block": "minecraft:dark_oak_stairs[facing=south,half=bottom,shape=straight,waterlogged=false]"
      },
      {
        "char": "'",
        "block": "minecraft:mud_bricks"
      },
      {
        "char": "(",
        "block": "minecraft:oak_planks"
      },
      {
        "char": ")",
        "block": "minecraft:quartz_stairs[facing=north,half=bottom,shape=straight,waterlogged=false]"
      },
      {
        "char": "*",
        "block": "minecraft:red_terracotta"
      },
      {
        "char": "+",
        "block": "minecraft:smooth_stone_slab[type=top,waterlogged=false]"
      },
      {
        "char": ",",
        "block": "minecraft:spruce_slab[type=bottom,waterlogged=false]"
      },
      {
        "char": "-",
        "block": "minecraft:spruce_slab[type=top,waterlogged=false]"
      },
      {
        "char": ".",
        "block": "minecraft:stripped_oak_wood"
      },
      {
        "char": "/",
        "block": "minecraft:stripped_spruce_log[axis=y]"
      },
      {
        "char": "0",
        "block": "kubejs:ruined_cauldron"
      },
      {
        "char": "1",
        "block": "minecraft:yellow_terracotta"
      }
    ]
  }
}
