{
  "xsize": 16,
  "zsize": 16,
  "slices": [
    [
      "777777777777777 ",
      "777777777777777 ",
      "777777777777777 ",
      "777777777777777 ",
      "77..+7777777777 ",
      "..+777777777777 ",
      "+77777777777777 ",
      "777777777777777 ",
      "7777777777777.. ",
      "77777777777..+7 ",
      "777777777..+777 ",
      "7777777..+77777 ",
      "77777..+7777777 ",
      "777..+777777777 ",
      "7..+77777777777 ",
      ".+7777777777777 "
    ],
    [
      "9990000000000   ",
      "9990000000000   ",
      "9990000000000   ",
      "9990000000000   ",
      "9999999999999   ",
      "9999999999999   ",
      "9999999999999   ",
      "9999999999999   ",
      "9999999999999   ",
      "9999999999999   ",
      "9999999999999   ",
      "9999999999999   ",
      "9999999999999   ",
      "9999999999999   ",
      "9999999999999   ",
      "9999999999999   "
    ],
    [
      "   )    1   )   ",
      "   ,    8 5 )   ",
      "  :)  ( 8   )   ",
      "   )    8   )   ",
      "   8888888888   ",
      "   8        8   ",
      "   8 $$  $$ 8   ",
      "   8 $$  $$ 8   ",
      ";; 8 $$  $$ 8   ",
      "*; 8        8   ",
      ";; 8        8   ",
      "   ,        8   ",
      "   8 $$  $$ 8   ",
      "8838 $$  $$ 8   ",
      "'  8 $$  $$ 8   ",
      "'  8&&&&&&&&8   "
    ],
    [
      "   )    2   )   ",
      "   -    8   )   ",
      "  :)    8   )   ",
      "   )    8   )   ",
      "   8888888888   ",
      "   8        8   ",
      "   8 $$  $$ 8   ",
      "   8 $$  $$ 8   ",
      "   8 $$  $$ 8   ",
      " 6 8        8   ",
      "   8        8   ",
      "   -        8   ",
      "   8 $$  $$ 8   ",
      "8848 $$  $$ 8   ",
      "   8 $$  $$ 8   ",
      "   8 /  !  %8   "
    ],
    [
      "   )    8   )   ",
      "        8   )   ",
      "  :)    8   )   ",
      "   )    8   )   ",
      "   8888888888   ",
      "   8        8   ",
      "   8 $$  $$ 8   ",
      "   8 $$  $$ 8   ",
      "   8 $$  $$ 8   ",
      "   8        8   ",
      "   8        8   ",
      "            8   ",
      "   8 $$  $$ 8   ",
      "8888 $$  $$ 8   ",
      "   8 $$  $$ 8   ",
      "   8        8   "
    ],
    [
      "   )    8   )   ",
      "   )    8   )   ",
      "  :)    8   )   ",
      "   )    8   )   ",
      "   8888888888   ",
      "   8        8   ",
      "   8 $$  $$ 8   ",
      "   8 $$  $$ 8   ",
      "   8 $$  $$ 8   ",
      "   8        8   ",
      "   8        8   ",
      "   8        8   ",
      "   8 $$  $$ 8   ",
      "8888 $$  $$ 8   ",
      "   8 $$  $$ 8   ",
      "   8        8   "
    ]
  ],
  "palette": {
    "palette": [
      {
        "char": "!",
        "block": "create:controls"
      },
      {
        "char": "$",
        "block": "create:fluid_tank"
      },
      {
        "char": "%",
        "block": "create:red_nixie_tube"
      },
      {
        "char": "&",
        "block": "immersiveengineering:sheetmetal_steel"
      },
      {
        "char": "'",
        "block": "jaffabricate:pallet_full"
      },
      {
        "char": "(",
        "block": "minecraft:barrel[facing=up,open=false]"
      },
      {
        "char": ")",
        "block": "minecraft:bricks"
      },
      {
        "char": "*",
        "block": "minecraft:chest[facing=west,type=single,waterlogged=false]",
        "tag": {
          "id": "minecraft:chest",
          "LootTable": "infinite_domain:chests/wasteland_industrial"
        }
      },
      {
        "char": "+",
        "block": "minecraft:coarse_dirt"
      },
      {
        "char": ",",
        "block": "minecraft:dark_oak_door[facing=east,half=lower,hinge=left,open=false,powered=false]"
      },
      {
        "char": "-",
        "block": "minecraft:dark_oak_door[facing=east,half=upper,hinge=left,open=false,powered=false]"
      },
      {
        "char": ".",
        "block": "minecraft:gravel"
      },
      {
        "char": "/",
        "block": "minecraft:lever[face=wall,facing=south,powered=false]"
      },
      {
        "char": "0",
        "block": "minecraft:polished_andesite"
      },
      {
        "char": "1",
        "block": "minecraft:spruce_door[facing=east,half=lower,hinge=left,open=false,powered=false]"
      },
      {
        "char": "2",
        "block": "minecraft:spruce_door[facing=east,half=upper,hinge=left,open=false,powered=false]"
      },
      {
        "char": "3",
        "block": "minecraft:spruce_door[facing=south,half=lower,hinge=left,open=false,powered=false]"
      },
      {
        "char": "4",
        "block": "minecraft:spruce_door[facing=south,half=upper,hinge=left,open=false,powered=false]"
      },
      {
        "char": "5",
        "block": "minecraft:water_cauldron[level=1]"
      },
      {
        "char": "6",
        "block": "supplementaries:item_shelf"
      },
      {
        "char": "7",
        "block": "tfmg:asphalt"
      },
      {
        "char": "8",
        "block": "tfmg:cinder_block"
      },
      {
        "char": "9",
        "block": "tfmg:factory_floor"
      },
      {
        "char": ":",
        "block": "tfmg:steel_block"
      },
      {
        "char": ";",
        "block": "zvhouses:stone_brick_countertop"
      }
    ]
  }
}
