{
  "xsize": 16,
  "zsize": 16,
  "slices": [
    [
      "    !!!!!!      ",
      "    !!!!!!      ",
      "    !!!!!!      ",
      "    !!!!!!      ",
      "    !!!!!!      ",
      "    !!!!!!      ",
      "    !!!!!!      ",
      "    !!!!!!      ",
      "    !!!!!!      ",
      "    !!!!!!      ",
      "    !!!!!!      ",
      "    !!!!!!      ",
      "    !!!!!!      ",
      "    !!!!!!      ",
      "!!!!!!!!!!      ",
      "!!!!!!!!!!      "
    ],
    [
      "                ",
      "                ",
      "                ",
      "                ",
      "                ",
      "                ",
      "                ",
      "                ",
      "                ",
      "                ",
      "                ",
      "                ",
      "                ",
      "                ",
      "!!!!!!!!!!      ",
      "!!!!!!!!!!      "
    ],
    [
      "                ",
      "                ",
      "                ",
      "                ",
      "                ",
      "                ",
      "                ",
      "                ",
      "                ",
      "                ",
      "                ",
      "                ",
      "                ",
      "                ",
      "!!!!!!!!!!      ",
      "!!!!!!!!!!      "
    ],
    [
      "          $$$$$ ",
      "          $$$$$ ",
      "          $$$$$ ",
      "          $$$$$ ",
      "          $$$$$ ",
      "          $$$$$ ",
      "          $$$$$ ",
      "          $$$$$ ",
      "          $$$$$ ",
      "          $$$$$ ",
      "          $$$$$ ",
      "          $$$$$ ",
      "          $$$$$ ",
      "          $$$$$ ",
      "!!!!!!!!!!$$$$$ ",
      "!!!!!!!!!!$$$$$ "
    ],
    [
      "                ",
      "                ",
      "                ",
      "                ",
      "                ",
      "                ",
      "                ",
      "                ",
      "                ",
      "                ",
      "                ",
      "                ",
      "                ",
      "                ",
      "                ",
      "                "
    ],
    [
      "                ",
      "                ",
      "                ",
      "                ",
      "                ",
      "                ",
      "                ",
      "                ",
      "                ",
      "                ",
      "                ",
      "                ",
      "                ",
      "                ",
      "                ",
      "                "
    ]
  ],
  "palette": {
    "palette": [
      {
        "char": "!",
        "block": "minecraft:andesite"
      },
      {
        "char": "$",
        "block": "minecraft:stone"
      }
    ]
  }
}
