{
  "xsize": 16,
  "zsize": 16,
  "slices": [
    [
      " 555555555555555",
      " 5555555555555''",
      " 55555555555''%5",
      " %55555555''%555",
      " 5555555''%55555",
      " 55555''%5555555",
      " 555''%555555555",
      " 5''%55555555555",
      " '%5555555555555",
      " %55555555555555",
      " 55555555555555'",
      " 555555555555''%",
      " 5555555555''%55",
      " 55555555''%5555",
      " 555555''%555555",
      " %555''%55555555"
    ],
    [
      "    ////////////",
      "    ////////////",
      "    ////////////",
      "    ////////////",
      "    ////////////",
      "    ////////////",
      "    ////////////",
      "    ////////////",
      "    ////////////",
      "    ////////////",
      "    ////////////",
      "    ////////////",
      "    /////'''''//",
      "         '''''  ",
      "         '''''  ",
      "         '''''  "
    ],
    [
      "    6       &&& ",
      "    6           ",
      "    6 $$$$$     ",
      "    6 * 2    0  ",
      "    6           ",
      "    611111-11111",
      "    6       1   ",
      "    6       1   ",
      "    6 )     +   ",
      "    6 (     1 3 ",
      "    6       1   ",
      "    6       1   ",
      "    6666666-6666",
      "                ",
      "                ",
      "                "
    ],
    [
      "    6           ",
      "    6           ",
      "    !     4     ",
      "    !           ",
      "    6           ",
      "    611111.11111",
      "    6       1   ",
      "    6       1   ",
      "    6       ,   ",
      "    6       1   ",
      "    6       1   ",
      "    6       1   ",
      "    666!!66.666!",
      "                ",
      "                ",
      "                "
    ],
    [
      "    6           ",
      "    6           ",
      "    !           ",
      "    !           ",
      "    6           ",
      "    611111111111",
      "    6       1   ",
      "    6       1   ",
      "    6       1   ",
      "    6       1   ",
      "    6       1   ",
      "    6       1   ",
      "    666!!666666!",
      "                ",
      "                ",
      "                "
    ],
    [
      "    6           ",
      "    6           ",
      "    6           ",
      "    6           ",
      "    6           ",
      "    611111111111",
      "    6       1   ",
      "    6       1   ",
      "    6       1   ",
      "    6       1   ",
      "    6       1   ",
      "    6       1   ",
      "    666666666666",
      "                ",
      "                ",
      "                "
    ]
  ],
  "palette": {
    "palette": [
      {
        "char": "!",
        "block": "create:framed_glass"
      },
      {
        "char": "$",
        "block": "minecraft:barrel[facing=up,open=false]"
      },
      {
        "char": "%",
        "block": "minecraft:coarse_dirt"
      },
      {
        "char": "&",
        "block": "minecraft:dark_oak_stairs[facing=south,half=bottom,shape=straight,waterlogged=false]"
      },
      {
        "char": "'",
        "block": "minecraft:gravel"
      },
      {
        "char": "(",
        "block": "minecraft:gray_bed[facing=north,occupied=false,part=foot]"
      },
      {
        "char": ")",
        "block": "minecraft:gray_bed[facing=north,occupied=false,part=head]"
      },
      {
        "char": "*",
        "block": "minecraft:smoker[facing=north,lit=false]"
      },
      {
        "char": "+",
        "block": "minecraft:spruce_door[facing=east,half=lower,hinge=left,open=false,powered=false]"
      },
      {
        "char": ",",
        "block": "minecraft:spruce_door[facing=east,half=upper,hinge=left,open=false,powered=false]"
      },
      {
        "char": "-",
        "block": "minecraft:spruce_door[facing=south,half=lower,hinge=left,open=false,powered=false]"
      },
      {
        "char": ".",
        "block": "minecraft:spruce_door[facing=south,half=upper,hinge=left,open=false,powered=false]"
      },
      {
        "char": "/",
        "block": "minecraft:spruce_planks"
      },
      {
        "char": "0",
        "block": "minecraft:spruce_slab[type=bottom,waterlogged=false]"
      },
      {
        "char": "1",
        "block": "minecraft:stripped_spruce_wood"
      },
      {
        "char": "2",
        "block": "minecraft:water_cauldron[level=1]"
      },
      {
        "char": "3",
        "block": "minecraft:water_cauldron[level=2]"
      },
      {
        "char": "4",
        "block": "supplementaries:item_shelf"
      },
      {
        "char": "5",
        "block": "tfmg:asphalt"
      },
      {
        "char": "6",
        "block": "the_wasteland_reworked:decayed_planks"
      }
    ]
  }
}
