{
  "xsize": 16,
  "zsize": 16,
  "slices": [
    [
      "6666++&666666666",
      "66++&66666666666",
      "++&6666666666666",
      "&666666666666666",
      "666666666666666+",
      "6666666666666++&",
      "66666666666++&66",
      "666666666++&6666",
      "6666666++&666666",
      "66666++&66666666",
      "666++&6666666666",
      "6++&666666666666",
      "+&66666666666666",
      "6666666666666666",
      "66666666666666++",
      "666666666666++&6"
    ],
    [
      "   /////////////",
      "   /////////////",
      "   /////////////",
      "   /////////////",
      "   /////////////",
      "   /////////////",
      "   /////////////",
      "   /////////////",
      "   /////////////",
      "   /////////////",
      "   /////////////",
      "   /+..++../////",
      "  ..++..++..////",
      "  +..++..++..///",
      "  7+..++..++.///",
      "  .++..++..++///"
    ],
    [
      "   43303333033  ",
      "   4 %  3 %  3  ",
      "   4 $ !3 $ !3  ",
      "   4    3    3  ",
      "   43303333033  ",
      "   433          ",
      "   4!'      7   ",
      "   433          ",
      "   43303333033 )",
      "   4    3    3  ",
      "   4 , !3 , !3  ",
      "   4 ..++.-  3! ",
      "   4 +..++.  3  ",
      "   ..++..++033  ",
      "   +..++..++.3  ",
      "  .++..++..++3  "
    ],
    [
      "   43313333133  ",
      "   4    3    3  ",
      "   4    3    3  ",
      "   4    3    3  ",
      "   43313333133  ",
      "   453          ",
      "   43(          ",
      "   433          ",
      "   43313333133 *",
      "   4    3    3  ",
      "   4    3    3  ",
      "   4    3    3  ",
      "   4  ..3    3  ",
      "   433+..33133  ",
      "   4..++..   3  ",
      "   4+..++..  3  "
    ],
    [
      "   43333333333  ",
      "   4    3    3  ",
      "   4    3    3  ",
      "   4    3    3  ",
      "   43333333333  ",
      "   433          ",
      "   433          ",
      "   433          ",
      "   43333333333  ",
      "   4    3    3  ",
      "   4    3    3  ",
      "   4    3    3  ",
      "   42222222  3  ",
      "   4333.333333  ",
      "   4   +.    3  ",
      "   4 ..++.   3  "
    ],
    [
      "   43333333333  ",
      "   4    3    3  ",
      "   4    3    3  ",
      "   4    3    3  ",
      "   43333333333  ",
      "   433          ",
      "   433          ",
      "   433          ",
      "   43333333333  ",
      "   4    3    3  ",
      "   4    3    3  ",
      "   4    3    3  ",
      "   4    3    3  ",
      "   43333333333  ",
      "   4    3    3  ",
      "   4    3    3  "
    ]
  ],
  "palette": {
    "palette": [
      {
        "char": "!",
        "block": "minecraft:barrel[facing=up,open=false]"
      },
      {
        "char": "$",
        "block": "minecraft:brown_bed[facing=north,occupied=false,part=foot]"
      },
      {
        "char": "%",
        "block": "minecraft:brown_bed[facing=north,occupied=false,part=head]"
      },
      {
        "char": "&",
        "block": "minecraft:coarse_dirt"
      },
      {
        "char": "'",
        "block": "minecraft:dark_oak_door[facing=east,half=lower,hinge=left,open=false,powered=false]"
      },
      {
        "char": "(",
        "block": "minecraft:dark_oak_door[facing=east,half=upper,hinge=left,open=false,powered=false]"
      },
      {
        "char": ")",
        "block": "minecraft:dark_oak_door[facing=south,half=lower,hinge=left,open=false,powered=false]"
      },
      {
        "char": "*",
        "block": "minecraft:dark_oak_door[facing=south,half=upper,hinge=left,open=false,powered=false]"
      },
      {
        "char": "+",
        "block": "minecraft:gravel"
      },
      {
        "char": ",",
        "block": "minecraft:gray_bed[facing=south,occupied=false,part=foot]"
      },
      {
        "char": "-",
        "block": "minecraft:gray_bed[facing=south,occupied=false,part=head]"
      },
      {
        "char": ".",
        "block": "minecraft:mud_bricks"
      },
      {
        "char": "/",
        "block": "minecraft:oak_planks"
      },
      {
        "char": "0",
        "block": "minecraft:spruce_door[facing=south,half=lower,hinge=left,open=false,powered=false]"
      },
      {
        "char": "1",
        "block": "minecraft:spruce_door[facing=south,half=upper,hinge=left,open=false,powered=false]"
      },
      {
        "char": "2",
        "block": "minecraft:stripped_dark_oak_log[axis=x]"
      },
      {
        "char": "3",
        "block": "minecraft:stripped_oak_wood"
      },
      {
        "char": "4",
        "block": "minecraft:yellow_terracotta"
      },
      {
        "char": "5",
        "block": "supplementaries:item_shelf"
      },
      {
        "char": "6",
        "block": "tfmg:asphalt"
      },
      {
        "char": "7",
        "block": "the_wasteland_reworked:garbage_bag"
      }
    ]
  }
}
