{
  "xsize": 16,
  "zsize": 16,
  "slices": [
    [
      " 000((%000000000",
      " 0((%00000000000",
      " (%0000000000000",
      " 000000000000000",
      " 00000000000000(",
      " %00000000000((%",
      " 0000000000((%00",
      " 00000000((%0000",
      " 000000((%000000",
      " 0000((%00000000",
      " 00((%0000000000",
      " %(%000000000000",
      " %00000000000000",
      " 000000000000000",
      " 000000000000000",
      " 00000000000((00"
    ],
    [
      "   2222222222222",
      "   2222222222222",
      "   2222222222222",
      "   2222222222222",
      "   2222222222222",
      "   2222222222222",
      "   2222222222222",
      "   2222222222222",
      "   2222222222222",
      "   2222222222222",
      "   2222222222222",
      "   2222222222222",
      "   2222222222222",
      "   2222222222222",
      "   2222222222222",
      "   2222222222222"
    ],
    [
      "   $   *   *    ",
      "   $   *   *    ",
      "   $   *   *    ",
      "   $            ",
      "   $          33",
      "   $            ",
      "   $1111-1111111",
      "   $       1    ",
      "   $       1    ",
      "   $ & '& '1 /  ",
      "   $       +    ",
      "   $       1    ",
      "   $       1    ",
      "   $       1 )  ",
      "   $       1    ",
      "   $       1    "
    ],
    [
      "   $   *   *    ",
      "   $   *   *    ",
      "   !   *   *    ",
      "   !            ",
      "   $            ",
      "   $            ",
      "   $1111.1111111",
      "   $       1    ",
      "   $       1    ",
      "   $       1    ",
      "   !       ,    ",
      "   !       1    ",
      "   $       1    ",
      "   $       1    ",
      "   $       1    ",
      "   $       1    "
    ],
    [
      "   $   *   *    ",
      "   $   *   *    ",
      "   !   *   *    ",
      "   !            ",
      "   $            ",
      "   $            ",
      "   $111111111111",
      "   $       1    ",
      "   $       1    ",
      "   $       1    ",
      "   !       1    ",
      "   !       1    ",
      "   $       1    ",
      "   $       1    ",
      "   $       1    ",
      "   $       1    "
    ],
    [
      "   $            ",
      "   $            ",
      "   $            ",
      "   $            ",
      "   $            ",
      "   $            ",
      "   $111111111111",
      "   $       1    ",
      "   $       1    ",
      "   $       1    ",
      "   $       1    ",
      "   $       1    ",
      "   $       1    ",
      "   $       1    ",
      "   $       1    ",
      "   $       1    "
    ]
  ],
  "palette": {
    "palette": [
      {
        "char": "!",
        "block": "create:framed_glass"
      },
      {
        "char": "$",
        "block": "minecraft:bricks"
      },
      {
        "char": "%",
        "block": "minecraft:coarse_dirt"
      },
      {
        "char": "&",
        "block": "minecraft:dark_oak_stairs[facing=east,half=bottom,shape=straight,waterlogged=false]"
      },
      {
        "char": "'",
        "block": "minecraft:dark_oak_stairs[facing=west,half=bottom,shape=straight,waterlogged=false]"
      },
      {
        "char": "(",
        "block": "minecraft:gravel"
      },
      {
        "char": ")",
        "block": "minecraft:quartz_stairs[facing=south,half=bottom,shape=straight,waterlogged=false]"
      },
      {
        "char": "*",
        "block": "minecraft:scaffolding"
      },
      {
        "char": "+",
        "block": "minecraft:spruce_door[facing=east,half=lower,hinge=left,open=false,powered=false]"
      },
      {
        "char": ",",
        "block": "minecraft:spruce_door[facing=east,half=upper,hinge=left,open=false,powered=false]"
      },
      {
        "char": "-",
        "block": "minecraft:spruce_door[facing=south,half=lower,hinge=left,open=false,powered=false]"
      },
      {
        "char": ".",
        "block": "minecraft:spruce_door[facing=south,half=upper,hinge=left,open=false,powered=false]"
      },
      {
        "char": "/",
        "block": "kubejs:ruined_cauldron"
      },
      {
        "char": "0",
        "block": "tfmg:asphalt"
      },
      {
        "char": "1",
        "block": "tfmg:cinder_block"
      },
      {
        "char": "2",
        "block": "tfmg:factory_floor"
      },
      {
        "char": "3",
        "block": "zvhouses:spruce_countertop"
      }
    ]
  }
}
