{
  "xsize": 16,
  "zsize": 16,
  "slices": [
    [
      "++++++++++++++++",
      "++++++++++++++++",
      "++++++++++++++++",
      "++++++++++++++++",
      "++++++++++++++++",
      "+++++++(('++++++",
      "+++++(('++++++++",
      "+++(('++++++++++",
      "++++++++++++++++",
      "++++++++++++++++",
      "++++++++++++++++",
      "++++++++++++++((",
      "++++++++++++(('+",
      "++++++++++(('+++",
      "++++++++(('+++++",
      "++++++(('+++++++"
    ],
    [
      "                ",
      "                ",
      "                ",
      "                ",
      "                ",
      "                ",
      "  ((((((((((((((",
      " ((((((((((((((%",
      " (((((((((((((((",
      " (((((((((((((((",
      " (((((((((((((((",
      " (((((((((((((((",
      " (((((((((((((((",
      " (((((((((((((((",
      " (((((((((((((((",
      " ((((((((((((((("
    ],
    [
      "                ",
      "                ",
      "                ",
      "                ",
      "                ",
      "                ",
      "   (%%(((((%    ",
      "  (%%((((((()(()",
      " (%%((((((((((%%",
      " %%(((((((((((% ",
      " %(((((((((((((!",
      " (((((((((((((((",
      " (((((((((((((((",
      " (((((((((((((((",
      " (((((((((((((((",
      " ((((((((((((((("
    ],
    [
      "                ",
      "                ",
      "                ",
      "                ",
      "                ",
      "                ",
      "   )    ((%     ",
      "   )$$$((%%$$$$$",
      "   $  ((((  (   ",
      "   $ ((((((((%  ",
      "   $((((((((%%  ",
      "   ((((((((((  (",
      "  ((((((((((((((",
      " ((((((((((((((%",
      " (((((((((((((((",
      " ((((((((((((((("
    ],
    [
      "                ",
      "                ",
      "                ",
      "                ",
      "                ",
      "                ",
      "   )      )     ",
      "   )$$$$($)$$$$$",
      "   $   (%%      ",
      "   $  (%%       ",
      "   $ (%%( ((&   ",
      "    (%%((((%%   ",
      "   (%%(((((%&   ",
      "  (%%((((((( (( ",
      " (%%((((((((((%%",
      " %%(((((((((((% "
    ],
    [
      "                ",
      "                ",
      "                ",
      "                ",
      "                ",
      "                ",
      "   ) **** ) ****",
      "   )$$$$$$)$$$$$",
      "   $            ",
      "   $            ",
      "                ",
      "         (      ",
      "        ((%     ",
      "       ((%%     ",
      "      ((((  (   ",
      "     ((((((((%  "
    ]
  ],
  "palette": {
    "palette": [
      {
        "char": "!",
        "block": "create:andesite_casing"
      },
      {
        "char": "$",
        "block": "immersiveengineering:concrete_brick"
      },
      {
        "char": "%",
        "block": "immersiveengineering:concrete_brick_cracked"
      },
      {
        "char": "&",
        "block": "jaffabricate:pallet_full"
      },
      {
        "char": "'",
        "block": "minecraft:coarse_dirt"
      },
      {
        "char": "(",
        "block": "minecraft:gravel"
      },
      {
        "char": ")",
        "block": "minecraft:mud_bricks"
      },
      {
        "char": "*",
        "block": "minecraft:spruce_slab[type=bottom,waterlogged=false]"
      },
      {
        "char": "+",
        "block": "tfmg:asphalt"
      }
    ]
  }
}
