{
  "xsize": 16,
  "zsize": 16,
  "slices": [
    [
      "&&%2222222222222",
      "%222222222222222",
      "2222222222222222",
      "2222222222222222",
      "2222222222222222",
      "222222222&&%2222",
      "2222222&&%222222",
      "22222&&%22222222",
      "222&&%2222222222",
      "2&&%222222222222",
      "&%22222222222222",
      "2222222222222222",
      "22222222222222&&",
      "222222222222&&%2",
      "2222222222&&%222",
      "22222222&&%22222"
    ],
    [
      "--- ***   ------",
      "---       ------",
      "---       ------",
      "---       ------",
      "---       ------",
      "---       ------",
      "---       ------",
      "---       ------",
      "---       ------",
      "---       ------",
      "---       ------",
      "---       ------",
      "---       ------",
      "          ------",
      "          ------",
      "          -----&"
    ],
    [
      "  3 ***   ......",
      "4 3       .     ",
      "  3       .     ",
      "  3       .     ",
      "  3       .     ",
      "//3       . $$$$",
      "  3       . , 0 ",
      "  3       .     ",
      "  3       ./////",
      "+ 3       .     ",
      "  3       .     ",
      "  3       . (   ",
      "333       . '   ",
      "          .     ",
      "          .     ",
      "          ......"
    ],
    [
      "  3       ......",
      "1 3       .     ",
      "  3       .     ",
      "  3       .     ",
      "  3       .     ",
      "//3       !     ",
      "  3       !     ",
      "  3       .     ",
      "  !       ./////",
      "  !       .     ",
      ") 3       .     ",
      "  3       .     ",
      "!33       .     ",
      "          .     ",
      "          .     ",
      "          ...!!."
    ],
    [
      "  3       ......",
      "  3       .     ",
      "  3       .     ",
      "  3       .     ",
      "  3       .     ",
      "//3       !     ",
      "  3       !     ",
      "  3       .     ",
      "  !       ./////",
      "  !       .     ",
      "  3       .     ",
      "  3       .     ",
      "!33       .     ",
      "          .     ",
      "          .     ",
      "          ...!!."
    ],
    [
      "  3       ......",
      "  3       .     ",
      "  3       .     ",
      "  3       .     ",
      "  3       .     ",
      "//3       .     ",
      "  3       .     ",
      "  3       .     ",
      "  3       ./////",
      "  3       .     ",
      "  3       .     ",
      "  3       .     ",
      "333       .     ",
      "          .     ",
      "          .     ",
      "          ......"
    ]
  ],
  "palette": {
    "palette": [
      {
        "char": "!",
        "block": "create:framed_glass"
      },
      {
        "char": "$",
        "block": "minecraft:barrel[facing=up,open=false]"
      },
      {
        "char": "%",
        "block": "minecraft:coarse_dirt"
      },
      {
        "char": "&",
        "block": "minecraft:gravel"
      },
      {
        "char": "'",
        "block": "minecraft:gray_bed[facing=north,occupied=false,part=foot]"
      },
      {
        "char": "(",
        "block": "minecraft:gray_bed[facing=north,occupied=false,part=head]"
      },
      {
        "char": ")",
        "block": "minecraft:lever[face=wall,facing=south,powered=false]"
      },
      {
        "char": "*",
        "block": "minecraft:oxidized_copper"
      },
      {
        "char": "+",
        "block": "minecraft:quartz_stairs[facing=north,half=bottom,shape=straight,waterlogged=false]"
      },
      {
        "char": ",",
        "block": "kubejs:ruined_smoker[facing=north]"
      },
      {
        "char": "-",
        "block": "minecraft:spruce_planks"
      },
      {
        "char": ".",
        "block": "minecraft:stone_bricks"
      },
      {
        "char": "/",
        "block": "minecraft:stripped_spruce_wood"
      },
      {
        "char": "0",
        "block": "kubejs:ruined_cauldron"
      },
      {
        "char": "1",
        "block": "supplementaries:item_shelf"
      },
      {
        "char": "2",
        "block": "tfmg:asphalt"
      },
      {
        "char": "3",
        "block": "the_wasteland_reworked:decayed_planks"
      },
      {
        "char": "4",
        "block": "the_wasteland_reworked:radio"
      }
    ]
  }
}
