{
  "xsize": 16,
  "zsize": 16,
  "slices": [
    [
      "(((((           ",
      "(((((&((((&((((&",
      "((((((((((((((((",
      "((((((((((((((((",
      "(((((((((((((((&",
      "(((((((((((((&&%",
      "(((((((((((&&%((",
      "(((((((((&&%((((",
      "(((((((&&%((((((",
      "(((((&&%((((((((",
      "(((((%((((((((((",
      "((((((((((((((((",
      "((((((((((((((((",
      "((((((((((((((((",
      "((((((((((((((&&",
      "((((((((((((&&%("
    ],
    [
      "                ",
      "                ",
      "                ",
      "                ",
      "                ",
      "               '",
      "               '",
      "               '",
      "               '",
      "               '",
      "               '",
      "               '",
      "               '",
      "               '",
      "               '",
      "               '"
    ],
    [
      "                ",
      "                ",
      "                ",
      "                ",
      "                ",
      "               $",
      "               $",
      "               $",
      "               $",
      "               $",
      "               $",
      "               $",
      "               $",
      "               $",
      "               $",
      "               $"
    ],
    [
      "                ",
      "                ",
      "                ",
      "                ",
      "                ",
      "               $",
      "               $",
      "               $",
      "               $",
      "               $",
      "               !",
      "               !",
      "               $",
      "               $",
      "               $",
      "               $"
    ],
    [
      "                ",
      "                ",
      "                ",
      "                ",
      "                ",
      "               $",
      "               $",
      "               $",
      "               $",
      "               $",
      "               !",
      "               !",
      "               $",
      "               $",
      "               $",
      "               $"
    ],
    [
      "                ",
      "                ",
      "                ",
      "                ",
      "                ",
      "               $",
      "               $",
      "               $",
      "               $",
      "               $",
      "               $",
      "               $",
      "               $",
      "               $",
      "               $",
      "               $"
    ]
  ],
  "palette": {
    "palette": [
      {
        "char": "!",
        "block": "create:framed_glass"
      },
      {
        "char": "$",
        "block": "minecraft:bricks"
      },
      {
        "char": "%",
        "block": "minecraft:coarse_dirt"
      },
      {
        "char": "&",
        "block": "minecraft:gravel"
      },
      {
        "char": "'",
        "block": "minecraft:spruce_planks"
      },
      {
        "char": "(",
        "block": "tfmg:asphalt"
      }
    ]
  }
}
