{
  "xsize": 16,
  "zsize": 16,
  "slices": [
    [
      "                ",
      "3333(((&3(3333(3",
      "333((&3333333333",
      "3((&333333333333",
      "(&33333333333333",
      "3333333333333333",
      "33333333333333((",
      "333333333333((&3",
      "3333333333((&333",
      "33333333((&33333",
      "333333((&3333333",
      "3333((&333333333",
      "33((&33333333333",
      "((&3333333333333",
      "&333333333333333",
      "333333333333333("
    ],
    [
      "                ",
      "                ",
      "    (((((       ",
      "    (((((       ",
      "    (((((       ",
      "....(((((.....  ",
      "..............  ",
      "..............  ",
      "..............  ",
      "..............  ",
      "..............  ",
      "..............  ",
      "..............  ",
      "..............  ",
      "..............  ",
      "..............  "
    ],
    [
      "                ",
      "                ",
      "                ",
      "                ",
      "                ",
      "%%%%%%*%%%%%%%  ",
      "             %  ",
      "             %  ",
      "       '''   %  ",
      "           4 %  ",
      " $$$$$       %  ",
      " ) 1    /    %  ",
      "             %  ",
      "00000,0000000%  ",
      "        0    %  ",
      "        0    %  "
    ],
    [
      "                ",
      "                ",
      "                ",
      "                ",
      "                ",
      "%%!!%%+%%%!!%%  ",
      "             %  ",
      "             %  ",
      "             %  ",
      "           2 %  ",
      "     2       %  ",
      "             %  ",
      "             %  ",
      "00000-0000000%  ",
      "        0    %  ",
      "        0    %  "
    ],
    [
      "                ",
      "                ",
      "                ",
      "                ",
      "                ",
      "%%!!%%%%%%!!%%  ",
      "             %  ",
      "             %  ",
      "             %  ",
      "             %  ",
      "             %  ",
      "             %  ",
      "             %  ",
      "0000000000000%  ",
      "        0    %  ",
      "        0    %  "
    ],
    [
      "                ",
      "                ",
      "                ",
      "                ",
      "                ",
      "%%%%%%%%%%%%%%  ",
      "             %  ",
      "             %  ",
      "             %  ",
      "             %  ",
      "             %  ",
      "             %  ",
      "             %  ",
      "0000000000000%  ",
      "        0    %  ",
      "        0    %  "
    ]
  ],
  "palette": {
    "palette": [
      {
        "char": "!",
        "block": "create:framed_glass"
      },
      {
        "char": "$",
        "block": "minecraft:barrel[facing=up,open=false]"
      },
      {
        "char": "%",
        "block": "minecraft:bricks"
      },
      {
        "char": "&",
        "block": "minecraft:coarse_dirt"
      },
      {
        "char": "'",
        "block": "minecraft:dark_oak_stairs[facing=south,half=bottom,shape=straight,waterlogged=false]"
      },
      {
        "char": "(",
        "block": "minecraft:gravel"
      },
      {
        "char": ")",
        "block": "minecraft:smoker[facing=north,lit=false]"
      },
      {
        "char": "*",
        "block": "minecraft:spruce_door[facing=north,half=lower,hinge=left,open=false,powered=false]"
      },
      {
        "char": "+",
        "block": "minecraft:spruce_door[facing=north,half=upper,hinge=left,open=false,powered=false]"
      },
      {
        "char": ",",
        "block": "minecraft:spruce_door[facing=south,half=lower,hinge=left,open=false,powered=false]"
      },
      {
        "char": "-",
        "block": "minecraft:spruce_door[facing=south,half=upper,hinge=left,open=false,powered=false]"
      },
      {
        "char": ".",
        "block": "minecraft:spruce_planks"
      },
      {
        "char": "/",
        "block": "minecraft:spruce_slab[type=bottom,waterlogged=false]"
      },
      {
        "char": "0",
        "block": "minecraft:stripped_spruce_wood"
      },
      {
        "char": "1",
        "block": "minecraft:water_cauldron[level=1]"
      },
      {
        "char": "2",
        "block": "supplementaries:item_shelf"
      },
      {
        "char": "3",
        "block": "tfmg:asphalt"
      },
      {
        "char": "4",
        "block": "the_wasteland_reworked:radio"
      }
    ]
  }
}
