{
  "xsize": 16,
  "zsize": 16,
  "slices": [
    [
      "*************''%",
      "***********''%**",
      "*********''%****",
      "*******''%******",
      "*****''%********",
      "***''%**********",
      "*''%************",
      "'%**************",
      "****************",
      "**************''",
      "************''%*",
      "**********''%***",
      "********''%*****",
      "******''%*******",
      "****''%*********",
      "**''%***********"
    ],
    [
      "          ++++++",
      "          ++++++",
      "   &      ++++++",
      "          ++++++",
      "          ++++++",
      "          ++++++",
      "          ++++++",
      "          ++++++",
      "   &      ++++++",
      "          ++++++",
      "          ++++++",
      "          ++++++",
      "          ++++++",
      "          ++++++",
      "   &      ++++++",
      "                "
    ],
    [
      "          $     ",
      "          $     ",
      "   &      $  !  ",
      "          $     ",
      "          $     ",
      "          $     ",
      "          $  )  ",
      "          $  )  ",
      "   &      $  )  ",
      "          $  )  ",
      "          $  )  ",
      "          $  )  ",
      "          $     ",
      "          $     ",
      "   &      $$$$$$",
      "                "
    ],
    [
      "          $     ",
      "          $     ",
      "   &      $     ",
      "          $     ",
      "          $     ",
      "          $     ",
      "          $  )  ",
      "          $  )  ",
      "   &      $  )  ",
      "          $  )  ",
      "          $  )  ",
      "          $  )  ",
      "          $     ",
      "          $     ",
      "   &      $$$$$$",
      "                "
    ],
    [
      "          $     ",
      "          $     ",
      "   &      $     ",
      "          $     ",
      "          $     ",
      "          $     ",
      "          $  )  ",
      "          $  )  ",
      "   &      $  )  ",
      "          $  )  ",
      "          $  )  ",
      "          $  )  ",
      "          $     ",
      "          $     ",
      "   &      $$$$$$",
      "                "
    ],
    [
      "((((((    $     ",
      "((((((    $     ",
      "((((((    $     ",
      "((((((    $     ",
      "((((((    $     ",
      "          $     ",
      "((((((    $     ",
      "((((((    $     ",
      "((((((    $     ",
      "((((((    $     ",
      "((((((    $     ",
      "          $     ",
      "((((((    $     ",
      "((((((    $     ",
      "((((((    $$$$$$",
      "((((((          "
    ]
  ],
  "palette": {
    "palette": [
      {
        "char": "!",
        "block": "create:mechanical_press"
      },
      {
        "char": "$",
        "block": "minecraft:bricks"
      },
      {
        "char": "%",
        "block": "minecraft:coarse_dirt"
      },
      {
        "char": "&",
        "block": "minecraft:dark_oak_log[axis=y]"
      },
      {
        "char": "'",
        "block": "minecraft:gravel"
      },
      {
        "char": "(",
        "block": "minecraft:oak_leaves[distance=1,persistent=true]"
      },
      {
        "char": ")",
        "block": "minecraft:scaffolding"
      },
      {
        "char": "*",
        "block": "tfmg:asphalt"
      },
      {
        "char": "+",
        "block": "tfmg:factory_floor"
      }
    ]
  }
}
