{
  "xsize": 16,
  "zsize": 16,
  "slices": [
    [
      "**********%%$***",
      "********%%$*****",
      "******%%$*******",
      "****%%$*********",
      "**%%$***********",
      "%%$*************",
      "$***************",
      "***************%",
      "*************%%$",
      "***********%%$**",
      "*********%%$****",
      "*******%%$******",
      "*****%%$********",
      "***%%$**********",
      "*%%$************",
      "%$**************"
    ],
    [
      ",,,,,,,,,,,,,,,,",
      ",,,,,,,,,,,,,,,,",
      ",,,,,,,,,,,,,,,,",
      ",,,,,,,,,,,,,,,,",
      ",,,,,,,,,,,,,,,,",
      ",,,,,,,,,,,,,,,,",
      ",,,,,,,,,,,,,,,,",
      ",,,,,,,,,,,,,,,,",
      ",,,,,,,,,,,,,,,,",
      ",,,,,,,,,,,,,,,,",
      ",,,,,,,,,,,,,,,,",
      ",,,,,,,,,,,,,,,,",
      ",,,,,,,,,,,,,,,,",
      ",,,,,,,,,,,,,,,,",
      ",,,,,,,,,,,,,,,,",
      ",,,,,,,,,,,,,,,,"
    ],
    [
      "  +             ",
      "  +             ",
      "  +             ",
      "  +             ",
      "  +             ",
      "  )    )  !!)   ",
      "        !!!!    ",
      "           !!!!!",
      "                ",
      "                ",
      "  &    &    &   ",
      "                ",
      "                ",
      "                ",
      "                ",
      "'++++++++'++++++"
    ],
    [
      "  +             ",
      "  +             ",
      "  +             ",
      "  +             ",
      "  +             ",
      "  +       !!    ",
      "        !!!!    ",
      "           !!!!!",
      "                ",
      "                ",
      "                ",
      "                ",
      "                ",
      "                ",
      "                ",
      "(++++++++(++++++"
    ],
    [
      "  +             ",
      "  +             ",
      "  +             ",
      "  +             ",
      "  +             ",
      "  +       !!    ",
      "        !!!!    ",
      "           !!!!!",
      "                ",
      "                ",
      "                ",
      "                ",
      "                ",
      "                ",
      "                ",
      "++++++++++++++++"
    ],
    [
      "  +             ",
      "  +             ",
      "  +             ",
      "  +             ",
      "  +             ",
      "  +       !!    ",
      "        !!!!    ",
      "           !!!!!",
      "                ",
      "                ",
      "                ",
      "                ",
      "                ",
      "                ",
      "                ",
      "++++++++++++++++"
    ]
  ],
  "palette": {
    "palette": [
      {
        "char": "!",
        "block": "minecraft:bricks"
      },
      {
        "char": "$",
        "block": "minecraft:coarse_dirt"
      },
      {
        "char": "%",
        "block": "minecraft:gravel"
      },
      {
        "char": "&",
        "block": "kubejs:ruined_smoker[facing=south]"
      },
      {
        "char": "'",
        "block": "minecraft:spruce_door[facing=south,half=lower,hinge=left,open=false,powered=false]"
      },
      {
        "char": "(",
        "block": "minecraft:spruce_door[facing=south,half=upper,hinge=left,open=false,powered=false]"
      },
      {
        "char": ")",
        "block": "kubejs:ruined_cauldron"
      },
      {
        "char": "*",
        "block": "tfmg:asphalt"
      },
      {
        "char": "+",
        "block": "tfmg:cinder_block"
      },
      {
        "char": ",",
        "block": "tfmg:factory_floor"
      }
    ]
  }
}
