{
  "xsize": 16,
  "zsize": 16,
  "slices": [
    [
      "1111111111111(('",
      "11111111111(('11",
      "111111111(('1111",
      "1111111(('111111",
      "11111(('11111111",
      "111(('1111111111",
      "11('111111111111",
      "1111111111111111",
      "1111111111111111",
      "11111111111111((",
      "111111111111(('1",
      "1111111111(('111",
      "11111111(('11111",
      "111111(('1111111",
      "11111('111111111",
      "1111111111111111"
    ],
    [
      "..............  ",
      "..............  ",
      "..............  ",
      "..............  ",
      "..............  ",
      "                ",
      "                ",
      "                ",
      "                ",
      "                ",
      "                ",
      "                ",
      "   ***          ",
      "   ***          ",
      "   ***          ",
      "                "
    ],
    [
      " &      ,    $  ",
      " %      /0 + $  ",
      "        /    $  ",
      "        /    $  ",
      "$$$$$$$$$$$$$$  ",
      "                ",
      "                ",
      "                ",
      "                ",
      "                ",
      "                ",
      "                ",
      "   ***          ",
      "   ***          ",
      "   ***          ",
      "                "
    ],
    [
      "        -    !  ",
      "        /    !  ",
      "        /  ) $  ",
      "        /    $  ",
      "$$$$$$$$$$$$$$  ",
      "                ",
      "                ",
      "                ",
      "                ",
      "                ",
      "                ",
      "                ",
      "                ",
      "                ",
      "                ",
      "                "
    ],
    [
      "        /    !  ",
      "        /    !  ",
      "        /    $  ",
      "        /    $  ",
      "$$$$$$$$$$$$$$  ",
      "                ",
      "                ",
      "                ",
      "                ",
      "                ",
      "                ",
      "                ",
      "                ",
      "                ",
      "                ",
      "                "
    ],
    [
      "        /    $  ",
      "        /    $  ",
      "        /    $  ",
      "        /    $  ",
      "$$$$$$$$$$$$$$  ",
      "                ",
      "                ",
      "                ",
      "                ",
      "                ",
      "                ",
      "                ",
      "                ",
      "                ",
      "                ",
      "                "
    ]
  ],
  "palette": {
    "palette": [
      {
        "char": "!",
        "block": "create:framed_glass"
      },
      {
        "char": "$",
        "block": "minecraft:bricks"
      },
      {
        "char": "%",
        "block": "minecraft:brown_bed[facing=north,occupied=false,part=foot]"
      },
      {
        "char": "&",
        "block": "minecraft:brown_bed[facing=north,occupied=false,part=head]"
      },
      {
        "char": "'",
        "block": "minecraft:coarse_dirt"
      },
      {
        "char": "(",
        "block": "minecraft:gravel"
      },
      {
        "char": ")",
        "block": "minecraft:lever[face=wall,facing=south,powered=false]"
      },
      {
        "char": "*",
        "block": "minecraft:oxidized_copper"
      },
      {
        "char": "+",
        "block": "minecraft:quartz_stairs[facing=north,half=bottom,shape=straight,waterlogged=false]"
      },
      {
        "char": ",",
        "block": "minecraft:spruce_door[facing=east,half=lower,hinge=left,open=false,powered=false]"
      },
      {
        "char": "-",
        "block": "minecraft:spruce_door[facing=east,half=upper,hinge=left,open=false,powered=false]"
      },
      {
        "char": ".",
        "block": "minecraft:spruce_planks"
      },
      {
        "char": "/",
        "block": "minecraft:stripped_spruce_wood"
      },
      {
        "char": "0",
        "block": "kubejs:ruined_cauldron"
      },
      {
        "char": "1",
        "block": "tfmg:asphalt"
      }
    ]
  }
}
