{
  "xsize": 16,
  "zsize": 16,
  "slices": [
    [
      "              **",
      "%%****%****%****",
      "****************",
      "****************",
      "************%%**",
      "**********%%$***",
      "********%%$*****",
      "******%%$*******",
      "****%%$*********",
      "**%%$***********",
      "%%$*************",
      "$***************",
      "****************",
      "*************%**",
      "****************",
      "****************"
    ],
    [
      "                ",
      "                ",
      "                ",
      "                ",
      "                ",
      "''''            ",
      "''''            ",
      "''''            ",
      "''''            ",
      "''''            ",
      "''''            ",
      "''''            ",
      "''''            ",
      "''''            ",
      "''''            ",
      "''''            "
    ],
    [
      "                ",
      "                ",
      "                ",
      "                ",
      "                ",
      "&&&&            ",
      "   &            ",
      "   &            ",
      "   &            ",
      " + &            ",
      "   &            ",
      "   &            ",
      "   &            ",
      "(((&            ",
      "   &            ",
      "   &            "
    ],
    [
      "                ",
      "                ",
      "                ",
      "                ",
      "                ",
      "!!&&            ",
      "   &            ",
      "   &            ",
      "   &            ",
      " ) &            ",
      "   &            ",
      "   &            ",
      "   &            ",
      "(((&            ",
      "   &            ",
      "   &            "
    ],
    [
      "                ",
      "                ",
      "                ",
      "                ",
      "                ",
      "!!&&            ",
      "   &            ",
      "   &            ",
      "   &            ",
      "   &            ",
      "   &            ",
      "   &            ",
      "   &            ",
      "(((&            ",
      "   &            ",
      "   &            "
    ],
    [
      "                ",
      "                ",
      "                ",
      "                ",
      "                ",
      "&&&&            ",
      "   &            ",
      "   &            ",
      "   &            ",
      "   &            ",
      "   &            ",
      "   &            ",
      "   &            ",
      "(((&            ",
      "   &            ",
      "   &            "
    ]
  ],
  "palette": {
    "palette": [
      {
        "char": "!",
        "block": "create:framed_glass"
      },
      {
        "char": "$",
        "block": "minecraft:coarse_dirt"
      },
      {
        "char": "%",
        "block": "minecraft:gravel"
      },
      {
        "char": "&",
        "block": "minecraft:mud_bricks"
      },
      {
        "char": "'",
        "block": "minecraft:spruce_planks"
      },
      {
        "char": "(",
        "block": "minecraft:stripped_spruce_wood"
      },
      {
        "char": ")",
        "block": "supplementaries:item_shelf"
      },
      {
        "char": "*",
        "block": "tfmg:asphalt"
      },
      {
        "char": "+",
        "block": "the_wasteland_reworked:radio"
      }
    ]
  }
}
