{
  "xsize": 16,
  "zsize": 16,
  "slices": [
    [
      "888888))'8888888",
      "8888))'888888888",
      "88))'88888888888",
      "))'8888888888888",
      "'888888888888888",
      "888888888888888)",
      "8888888888888))'",
      "88888888888))'88",
      "888888888))'8888",
      "8888888))'888888",
      "88888))'88888888",
      "888))'8888888888",
      "8))'888888888888",
      ")'88888888888888",
      "8888888888888888",
      "88888888888888))"
    ],
    [
      "111111111111111 ",
      "111111111111111 ",
      "111111111111111 ",
      "111111111111111 ",
      "111111111111111 ",
      "111111111111111 ",
      "111111111111111 ",
      "111111111111111 ",
      "111111111111111 ",
      "111111111111111 ",
      "111111111111111 ",
      "111111111111111 ",
      "11111)))))11111 ",
      "     )))))      ",
      "     )))))      ",
      "     )))))      "
    ],
    [
      "6       (((   6 ",
      "6           9 6 ",
      "6 $$$$$       6 ",
      "6 , 4    2    6 ",
      "6             6 ",
      "633333/33333336 ",
      "6        3    6 ",
      "6        3    6 ",
      "6 &      -    6 ",
      "6 %      35 + 6 ",
      "6        3    6 ",
      "6        3    6 ",
      "6666666/6666666 ",
      "                ",
      "                ",
      "                "
    ],
    [
      "6             6 ",
      "6           7 6 ",
      "!     7       6 ",
      "!             6 ",
      "6             6 ",
      "633333033333336 ",
      "6        3    6 ",
      "6        3    6 ",
      "6        .    ! ",
      "6        3    ! ",
      "6        3  * 6 ",
      "6        3    6 ",
      "666!!660666!!66 ",
      "                ",
      "                ",
      "                "
    ],
    [
      "6             6 ",
      "6             6 ",
      "!             6 ",
      "!             6 ",
      "6             6 ",
      "633333333333336 ",
      "6        3    6 ",
      "6        3    6 ",
      "6        3    ! ",
      "6        3    ! ",
      "6        3    6 ",
      "6        3    6 ",
      "666!!666666!!66 ",
      "                ",
      "                ",
      "                "
    ],
    [
      "6             6 ",
      "6             6 ",
      "6             6 ",
      "6             6 ",
      "6             6 ",
      "633333333333336 ",
      "6        3    6 ",
      "6        3    6 ",
      "6        3    6 ",
      "6        3    6 ",
      "6        3    6 ",
      "6        3    6 ",
      "666666666666666 ",
      "                ",
      "                ",
      "                "
    ]
  ],
  "palette": {
    "palette": [
      {
        "char": "!",
        "block": "create:framed_glass"
      },
      {
        "char": "$",
        "block": "minecraft:barrel[facing=up,open=false]"
      },
      {
        "char": "%",
        "block": "minecraft:brown_bed[facing=north,occupied=false,part=foot]"
      },
      {
        "char": "&",
        "block": "minecraft:brown_bed[facing=north,occupied=false,part=head]"
      },
      {
        "char": "'",
        "block": "minecraft:coarse_dirt"
      },
      {
        "char": "(",
        "block": "minecraft:dark_oak_stairs[facing=south,half=bottom,shape=straight,waterlogged=false]"
      },
      {
        "char": ")",
        "block": "minecraft:gravel"
      },
      {
        "char": "*",
        "block": "minecraft:lever[face=wall,facing=south,powered=false]"
      },
      {
        "char": "+",
        "block": "minecraft:quartz_stairs[facing=north,half=bottom,shape=straight,waterlogged=false]"
      },
      {
        "char": ",",
        "block": "minecraft:smoker[facing=north,lit=false]"
      },
      {
        "char": "-",
        "block": "minecraft:spruce_door[facing=east,half=lower,hinge=left,open=false,powered=false]"
      },
      {
        "char": ".",
        "block": "minecraft:spruce_door[facing=east,half=upper,hinge=left,open=false,powered=false]"
      },
      {
        "char": "/",
        "block": "minecraft:spruce_door[facing=south,half=lower,hinge=left,open=false,powered=false]"
      },
      {
        "char": "0",
        "block": "minecraft:spruce_door[facing=south,half=upper,hinge=left,open=false,powered=false]"
      },
      {
        "char": "1",
        "block": "minecraft:spruce_planks"
      },
      {
        "char": "2",
        "block": "minecraft:spruce_slab[type=bottom,waterlogged=false]"
      },
      {
        "char": "3",
        "block": "minecraft:stripped_spruce_wood"
      },
      {
        "char": "4",
        "block": "minecraft:water_cauldron[level=1]"
      },
      {
        "char": "5",
        "block": "minecraft:water_cauldron[level=2]"
      },
      {
        "char": "6",
        "block": "minecraft:yellow_terracotta"
      },
      {
        "char": "7",
        "block": "supplementaries:item_shelf"
      },
      {
        "char": "8",
        "block": "tfmg:asphalt"
      },
      {
        "char": "9",
        "block": "the_wasteland_reworked:radio"
      }
    ]
  }
}
