{
  "xsize": 16,
  "zsize": 16,
  "slices": [
    [
      "$$$    $$$!     ",
      "$$$    $$$!     ",
      "$$$    $$$!     ",
      "$$$    $$$!     ",
      "$$$    $$$!     ",
      "$$$    $$$!     ",
      "$$$    $$$!     ",
      "$$$    $$$!     ",
      "$$$    $$$!     ",
      "$$$    $$$!     ",
      "$$$    $$$!     ",
      "$$$    $$$!     ",
      "$$$    $$$!     ",
      "$$$    $$$!     ",
      "$$$    $$$!     ",
      "          !     "
    ],
    [
      "$$$    $$$!     ",
      "$$$    $$$!     ",
      "$$$    $$$!     ",
      "$$$    $$$!     ",
      "$$$    $$$!     ",
      "$$$    $$$!     ",
      "$$$    $$$!     ",
      "$$$    $$$!     ",
      "$$$    $$$!     ",
      "$$$    $$$!     ",
      "$$$    $$$!     ",
      "$$$    $$$!     ",
      "$$$    $$$!     ",
      "$$$    $$$!     ",
      "$$$    $$$!     ",
      "          !     "
    ],
    [
      "$$$    $$$!     ",
      "$$$    $$$!     ",
      "$$$    $$$!     ",
      "$$$    $$$!     ",
      "$$$    $$$!     ",
      "$$$    $$$!     ",
      "$$$    $$$!     ",
      "$$$    $$$!     ",
      "$$$    $$$!     ",
      "$$$    $$$!     ",
      "$$$    $$$!     ",
      "$$$    $$$!     ",
      "$$$    $$$!     ",
      "$$$    $$$!     ",
      "$$$    $$$!     ",
      "          !     "
    ],
    [
      "$$$    $$$!     ",
      "$$$    $$$!     ",
      "$$$    $$$!     ",
      "$$$    $$$!     ",
      "$$$    $$$!     ",
      "$$$    $$$!     ",
      "$$$    $$$!     ",
      "$$$    $$$!     ",
      "$$$    $$$!     ",
      "$$$    $$$!     ",
      "$$$    $$$!     ",
      "$$$    $$$!     ",
      "$$$    $$$!     ",
      "$$$    $$$!     ",
      "$$$    $$$!     ",
      "          !     "
    ],
    [
      "          !     ",
      "          !     ",
      "          !     ",
      "          !     ",
      "          !     ",
      "          !     ",
      "          !     ",
      "          !     ",
      "          !     ",
      "          !     ",
      "          !     ",
      "          !     ",
      "          !     ",
      "          !     ",
      "          !     ",
      "          !     "
    ],
    [
      "          !     ",
      "          !     ",
      "          !     ",
      "          !     ",
      "          !     ",
      "          !     ",
      "          !     ",
      "          !     ",
      "          !     ",
      "          !     ",
      "          !     ",
      "          !     ",
      "          !     ",
      "          !     ",
      "          !     ",
      "          !     "
    ]
  ],
  "palette": {
    "palette": [
      {
        "char": "!",
        "block": "minecraft:polished_deepslate"
      },
      {
        "char": "$",
        "block": "minecraft:scaffolding"
      }
    ]
  }
}
