{
  "xsize": 16,
  "zsize": 16,
  "slices": [
    [
      "       %   $$$$$",
      "       %   $$$$$",
      "       %        ",
      "       %        ",
      "       %        ",
      "       %        ",
      "       %        ",
      "       %        ",
      "       %        ",
      "&&&&&&&%        ",
      "       %        ",
      "       %%%%%%%%%",
      "                ",
      "      !!!!!!!   ",
      "      !!!!!!!   ",
      "      !!!!!!!   "
    ],
    [
      "       %   $$$$$",
      "       %   $$$$$",
      "       %        ",
      "       %        ",
      "       %        ",
      "       %        ",
      "       %        ",
      "       %        ",
      "       %        ",
      "&&&&&&&%        ",
      "       %        ",
      "       %%%%%%%%%",
      "''''''''''''''''",
      "''''''''''''''''",
      "''''''''''''''''",
      "''''''''''''''''"
    ],
    [
      "       %        ",
      "       %        ",
      "       %        ",
      "       %        ",
      "       %        ",
      "       %        ",
      "       %        ",
      "       %        ",
      "       %        ",
      "&&&&&&&%        ",
      "       %        ",
      "       %%%%%%%%%",
      "''''''''''''''''",
      "''''''''''''''''",
      "''''''''''''''''",
      "''''''''''''''''"
    ],
    [
      "       '''''''''",
      "       '''''''''",
      "       '''''''''",
      "       '''''''''",
      "       '''''''''",
      "       '''''''''",
      "       '''''''''",
      "       '''''''''",
      "       '''''''''",
      "&&&&&&&'''''''''",
      "       '''''''''",
      "       '''''''''",
      "                ",
      "                ",
      "                ",
      "                "
    ],
    [
      "                ",
      "                ",
      "                ",
      "                ",
      "                ",
      "                ",
      "                ",
      "                ",
      "                ",
      "&&&&&&&&&&&&&&&&",
      "                ",
      "                ",
      "                ",
      "                ",
      "                ",
      "                "
    ],
    [
      "                ",
      "                ",
      "                ",
      "                ",
      "                ",
      "                ",
      "                ",
      "                ",
      "                ",
      "&&&&&&&&&&&&&&&&",
      "                ",
      "                ",
      "                ",
      "                ",
      "                ",
      "                "
    ]
  ],
  "palette": {
    "palette": [
      {
        "char": "!",
        "block": "ae2:controller"
      },
      {
        "char": "$",
        "block": "immersiveengineering:capacitor_hv"
      },
      {
        "char": "%",
        "block": "minecraft:bricks"
      },
      {
        "char": "&",
        "block": "minecraft:polished_deepslate"
      },
      {
        "char": "'",
        "block": "minecraft:smooth_stone"
      }
    ]
  }
}
