{
  "xsize": 16,
  "zsize": 16,
  "slices": [
    [
      "$ & %%%    %%%  ",
      "$   %%%    %%%  ",
      "$   %%%    %%%  ",
      "$   %%%    %%%  ",
      "$   %%%    %%%  ",
      "$   %%%    %%%  ",
      "$   %%%    %%%  ",
      "$   %%%    %%%  ",
      "$   %%%    %%%  ",
      "$   %%%    %%%  ",
      "!!!!!!!!!  %%%  ",
      "!!!!!!!!!  %%%  ",
      "!!!!!!!!!  %%%  ",
      "!!!!!!!!!  %%%  ",
      "!!!!!!!!!  %%%  ",
      "!!!!!!!!!       "
    ],
    [
      "$   %%%    %%%  ",
      "$ & %%%    %%%  ",
      "$   %%%    %%%  ",
      "$   %%%    %%%  ",
      "$   %%%    %%%  ",
      "$   %%%    %%%  ",
      "$   %%%    %%%  ",
      "$   %%%    %%%  ",
      "$   %%%    %%%  ",
      "$   %%%    %%%  ",
      "$   %%%    %%%  ",
      "$   %%%    %%%  ",
      "$   %%%    %%%  ",
      "$   %%%    %%%  ",
      "$   %%%    %%%  ",
      "$               "
    ],
    [
      "$   %%%    %%%  ",
      "$   %%%    %%%  ",
      "$ & %%%    %%%  ",
      "$   %%%    %%%  ",
      "$   %%%    %%%  ",
      "$   %%%    %%%  ",
      "$   %%%    %%%  ",
      "$   %%%    %%%  ",
      "$   %%%    %%%  ",
      "$   %%%    %%%  ",
      "$   %%%    %%%  ",
      "$   %%%    %%%  ",
      "$   %%%    %%%  ",
      "$   %%%    %%%  ",
      "$   %%%    %%%  ",
      "$               "
    ],
    [
      "$   %%%    %%%  ",
      "$   %%%    %%%  ",
      "$   %%%    %%%  ",
      "$ & %%%    %%%  ",
      "$   %%%    %%%  ",
      "$   %%%    %%%  ",
      "$   %%%    %%%  ",
      "$   %%%    %%%  ",
      "$   %%%    %%%  ",
      "$   %%%    %%%  ",
      "$   %%%    %%%  ",
      "$   %%%    %%%  ",
      "$   %%%    %%%  ",
      "$   %%%    %%%  ",
      "$   %%%    %%%  ",
      "$               "
    ],
    [
      "$               ",
      "$               ",
      "$               ",
      "$               ",
      "$ &             ",
      "$               ",
      "$               ",
      "$               ",
      "$               ",
      "$               ",
      "$               ",
      "$               ",
      "$               ",
      "$               ",
      "$               ",
      "$               "
    ],
    [
      "$               ",
      "$               ",
      "$               ",
      "$               ",
      "$               ",
      "$ &             ",
      "$               ",
      "$               ",
      "$               ",
      "$               ",
      "$               ",
      "$               ",
      "$               ",
      "$               ",
      "$               ",
      "$               "
    ]
  ],
  "palette": {
    "palette": [
      {
        "char": "!",
        "block": "minecraft:gravel"
      },
      {
        "char": "$",
        "block": "minecraft:polished_deepslate"
      },
      {
        "char": "%",
        "block": "minecraft:scaffolding"
      },
      {
        "char": "&",
        "block": "minecraft:stone_brick_stairs[facing=south,half=bottom,shape=straight,waterlogged=false]"
      }
    ]
  }
}
