{
  "xsize": 16,
  "zsize": 16,
  "slices": [
    [
      "  %%% !     !   ",
      "  %%% !     !   ",
      "  %%% !     !   ",
      "  %%% !     !   ",
      "  %%% !     !   ",
      "  %%% !     !   ",
      "  %%% !     !   ",
      "  %%% !     !   ",
      "  %%% !     !   ",
      "  %%% !     !   ",
      "  %%% !     !   ",
      "  %%% !     !   ",
      "  %%% !     !   ",
      "  %%% !     !   ",
      "  %%% !!!!!!!   ",
      "      !!!!!!!   "
    ],
    [
      "  %%% !$$$$$!   ",
      "  %%% !$$$$$!   ",
      "  %%% !$$$$$!   ",
      "  %%% !$$$$$!   ",
      "  %%% !$$$$$!   ",
      "  %%% !$$$$$!   ",
      "  %%% !$$$$$!   ",
      "  %%% !$$$$$!   ",
      "  %%% !$$$$$!   ",
      "  %%% !$$$$$!   ",
      "  %%% !$$$$$!   ",
      "  %%% !$$$$$!   ",
      "  %%% !$$$$$!   ",
      "  %%% !$$$$$!   ",
      "  %%% !!!!!!!   ",
      "      !!!!!!!   "
    ],
    [
      "  %%% !     !   ",
      "  %%% !     !   ",
      "  %%% !     !   ",
      "  %%% !     !   ",
      "  %%% !     !   ",
      "  %%% !     !   ",
      "  %%% !     !   ",
      "  %%% !     !   ",
      "  %%% !     !   ",
      "  %%% !     !   ",
      "  %%% !     !   ",
      "  %%% !     !   ",
      "  %%% !     !   ",
      "  %%% !     !   ",
      "  %%% !!!!!!!   ",
      "      !!!!!!!   "
    ],
    [
      "  %%% !     !   ",
      "  %%% !     !   ",
      "  %%% !     !   ",
      "  %%% !     !   ",
      "  %%% !     !   ",
      "  %%% !     !   ",
      "  %%% !     !   ",
      "  %%% !     !   ",
      "  %%% !     !   ",
      "  %%% !     !   ",
      "  %%% !     !   ",
      "  %%% !     !   ",
      "  %%% !     !   ",
      "  %%% !     !   ",
      "  %%% !!!!!!!   ",
      "      !!!!!!!   "
    ],
    [
      "      !     !   ",
      "      !     !   ",
      "      !     !   ",
      "      !     !   ",
      "      !     !   ",
      "      !     !   ",
      "      !     !   ",
      "      !     !   ",
      "      !     !   ",
      "      !     !   ",
      "      !     !   ",
      "      !     !   ",
      "      !     !   ",
      "      !     !   ",
      "      !!!!!!!   ",
      "      !!!!!!!   "
    ],
    [
      "      !$$$$$!   ",
      "      !$$$$$!   ",
      "      !$$$$$!   ",
      "      !$$$$$!   ",
      "      !$$$$$!   ",
      "      !$$$$$!   ",
      "      !$$$$$!   ",
      "      !$$$$$!   ",
      "      !$$$$$!   ",
      "      !$$$$$!   ",
      "      !$$$$$!   ",
      "      !$$$$$!   ",
      "      !$$$$$!   ",
      "      !$$$$$!   ",
      "      !!!!!!!   ",
      "      !!!!!!!   "
    ]
  ],
  "palette": {
    "palette": [
      {
        "char": "!",
        "block": "ae2:controller"
      },
      {
        "char": "$",
        "block": "ae2:drive"
      },
      {
        "char": "%",
        "block": "minecraft:scaffolding"
      }
    ]
  }
}
