{
  "xsize": 16,
  "zsize": 16,
  "slices": [
    [
      "((((((((((((((((",
      "(%((((%((((%((((",
      "((((((((((((((((",
      "((((((((((((((((",
      "((((((((((((((((",
      "((((((((((((((((",
      "((((((((((((((((",
      "((((((((((((((((",
      "((((%%$(((((((((",
      "((%%$(((((((((((",
      "%%$(((((((((((((",
      "$(((((((((((((((",
      "(((((((((((((((%",
      "(((((((((((((%%$",
      "(((((((((((%%$((",
      "(((((((((%%$(((("
    ],
    [
      "                ",
      "                ",
      "                ",
      "                ",
      "                ",
      "                ",
      "                ",
      "                ",
      "     &          ",
      "                ",
      "''''''''''''''  ",
      "''''''''''''''  ",
      "''''''''''''''  ",
      "''''''''''''''  ",
      "''''''''''''''  ",
      "''''''''''''''  "
    ],
    [
      "                ",
      "                ",
      "                ",
      "                ",
      "                ",
      "                ",
      "                ",
      "                ",
      "     &          ",
      "                ",
      "!!!!!!!!!!!!!!  ",
      "             !  ",
      "             !  ",
      "             !  ",
      "         )   !  ",
      "             !  "
    ],
    [
      "                ",
      "                ",
      "                ",
      "                ",
      "                ",
      "                ",
      "                ",
      "                ",
      "     &          ",
      "                ",
      "!!!!!!!!!!!!!!  ",
      "             !  ",
      "             !  ",
      "             !  ",
      "             !  ",
      "             !  "
    ],
    [
      "                ",
      "                ",
      "                ",
      "                ",
      "                ",
      "                ",
      "                ",
      "                ",
      "     &          ",
      "                ",
      "!!!!!!!!!!!!!!  ",
      "             !  ",
      "             !  ",
      "             !  ",
      "             !  ",
      "             !  "
    ],
    [
      "                ",
      "                ",
      "                ",
      "                ",
      "                ",
      "                ",
      "                ",
      "                ",
      "     &          ",
      "                ",
      "!!!!!!!!!!!!!!  ",
      "             !  ",
      "             !  ",
      "             !  ",
      "             !  ",
      "             !  "
    ]
  ],
  "palette": {
    "palette": [
      {
        "char": "!",
        "block": "minecraft:bricks"
      },
      {
        "char": "$",
        "block": "minecraft:coarse_dirt"
      },
      {
        "char": "%",
        "block": "minecraft:gravel"
      },
      {
        "char": "&",
        "block": "minecraft:polished_deepslate"
      },
      {
        "char": "'",
        "block": "minecraft:smooth_stone"
      },
      {
        "char": "(",
        "block": "tfmg:asphalt"
      },
      {
        "char": ")",
        "block": "the_wasteland_reworked:radio"
      }
    ]
  }
}
