{
  "xsize": 16,
  "zsize": 16,
  "slices": [
    [
      "          !     ",
      "          !     ",
      "          !     ",
      "          !     ",
      "          !     ",
      "          !     ",
      "          !     ",
      "          !     ",
      "          !     ",
      "          !     ",
      "          !     ",
      "          !     ",
      "          !     ",
      "          !     ",
      "          !     ",
      "          !     "
    ],
    [
      "$$$$$$$$$$!     ",
      "$$$$$$$$$$!     ",
      "$$$$$$$$$$!     ",
      "$$$$$$$$$$!     ",
      "$$$$$$$$$$!     ",
      "$$$$$$$$$$!     ",
      "$$$$$$$$$$!     ",
      "$$$$$$$$$$!     ",
      "$$$$$$$$$$!     ",
      "$$$$$$$$$$!     ",
      "$$$$$$$$$$!     ",
      "$$$$$$$$$$!     ",
      "$$$$$$$$$$!     ",
      "$$$$$$$$$$!     ",
      "$$$$$$$$$$!     ",
      "$$$$$$$$$$!     "
    ],
    [
      "$%%$$$$$$$!     ",
      "$&$$$$$$$$!     ",
      "$$$$$$$$$$!     ",
      "$$$$$$$$$$!     ",
      "$$$$$$$$$$!     ",
      "$$$$$$$$$$!     ",
      "$$$$$$$$$$!     ",
      "$$$$$$$$$$!     ",
      "$$$$$$$$$$!     ",
      "$$$$$$$$$$!     ",
      "$$$$$$$$$$!     ",
      "$$$$$$$$$$!     ",
      "$$$$$$$$$$!     ",
      "$$$$$$$$$$!     ",
      "$$$$$$$$$$!     ",
      "$$$$$$$$$$!     "
    ],
    [
      "          !     ",
      "          !     ",
      "          !     ",
      "          !     ",
      "          !     ",
      "          !     ",
      "          !     ",
      "          !     ",
      "          !     ",
      "          !     ",
      "          !     ",
      "          !     ",
      "          !     ",
      "          !     ",
      "          !     ",
      "          !     "
    ],
    [
      "          !     ",
      "          !     ",
      "          !     ",
      "          !     ",
      "          !     ",
      "          !     ",
      "          !     ",
      "          !     ",
      "          !     ",
      "          !     ",
      "          !     ",
      "          !     ",
      "          !     ",
      "          !     ",
      "          !     ",
      "          !     "
    ],
    [
      "          !     ",
      "          !     ",
      "          !     ",
      "          !     ",
      "          !     ",
      "          !     ",
      "          !     ",
      "          !     ",
      "          !     ",
      "          !     ",
      "          !     ",
      "          !     ",
      "          !     ",
      "          !     ",
      "          !     ",
      "          !     "
    ]
  ],
  "palette": {
    "palette": [
      {
        "char": "!",
        "block": "minecraft:polished_deepslate"
      },
      {
        "char": "$",
        "block": "minecraft:smooth_stone"
      },
      {
        "char": "%",
        "block": "minecraft:spruce_slab[type=bottom,waterlogged=false]"
      },
      {
        "char": "&",
        "block": "minecraft:spruce_stairs[facing=north,half=bottom,shape=straight,waterlogged=false]"
      }
    ]
  }
}
