{
  "xsize": 16,
  "zsize": 16,
  "slices": [
    [
      " +++''&+++++++++",
      " +''&+++++++++++",
      " '&+++++++++++++",
      " +++++++++++++++",
      " ++++++++++++++'",
      " &+++++++++++''&",
      " ++++++++++''&++",
      " ++++++++''&++++",
      " ++++++''&++++++",
      " ++++''&++++++++",
      " ++''&++++++++++",
      " &'&++++++++++++",
      " &++++++++++++++",
      " +++++++++++++++",
      " +++++++++++++''",
      " +++++++++++''&+"
    ],
    [
      "     (((((((((((",
      "     (((((((((((",
      "     (((((((((((",
      "     (((((((((((",
      "     (((((((((((",
      "     (((((((((((",
      "     (((((((((((",
      "     (((((((((((",
      "     (((((((((((",
      "     (((((((((((",
      "     (((((((((((",
      "     (((((((((((",
      "     (((((((((((",
      "     (((((((((((",
      "     (((((((((((",
      "     ((((((((((("
    ],
    [
      "     %          ",
      "     %          ",
      "     %  $$$$$$$$",
      "     %  $$$$$$$$",
      "     %          ",
      "     %,,,,),,,,,",
      "     %          ",
      "     %          ",
      "     %  !!!!  !!",
      "     %  !!!!  !!",
      "     %  !!!!  !!",
      "     %  !!!!  !!",
      "     %  !!!!  !!",
      "     %  !!!!  !!",
      "     %          ",
      "     %%%%%%%%%%%"
    ],
    [
      "     %          ",
      "     %          ",
      "     %  $$$$$$$$",
      "     %  $$$$$$$$",
      "     %          ",
      "     %,,,,*,,,,,",
      "     %          ",
      "     %          ",
      "     %  !!!!  !!",
      "     %  !!!!  !!",
      "     %  !!!!  !!",
      "     %  !!!!  !!",
      "     %  !!!!  !!",
      "     %  !!!!  !!",
      "     %          ",
      "     %%%%%%%%%%%"
    ],
    [
      "     %          ",
      "     %          ",
      "     %          ",
      "     %          ",
      "     %          ",
      "     %,,,,,,,,,,",
      "     %          ",
      "     %          ",
      "     %  !!!!  !!",
      "     %  !!!!  !!",
      "     %  !!!!  !!",
      "     %  !!!!  !!",
      "     %  !!!!  !!",
      "     %  !!!!  !!",
      "     %          ",
      "     %%%%%%%%%%%"
    ],
    [
      "     %          ",
      "     %          ",
      "     %          ",
      "     %          ",
      "     %          ",
      "     %,,,,,,,,,,",
      "     %          ",
      "     %          ",
      "     %  !!!!  !!",
      "     %  !!!!  !!",
      "     %  !!!!  !!",
      "     %  !!!!  !!",
      "     %  !!!!  !!",
      "     %  !!!!  !!",
      "     %          ",
      "     %%%%%%%%%%%"
    ]
  ],
  "palette": {
    "palette": [
      {
        "char": "!",
        "block": "ae2:quartz_glass"
      },
      {
        "char": "$",
        "block": "minecraft:barrel[facing=up,open=false]"
      },
      {
        "char": "%",
        "block": "minecraft:bricks"
      },
      {
        "char": "&",
        "block": "minecraft:coarse_dirt"
      },
      {
        "char": "'",
        "block": "minecraft:gravel"
      },
      {
        "char": "(",
        "block": "minecraft:smooth_stone"
      },
      {
        "char": ")",
        "block": "minecraft:spruce_door[facing=south,half=lower,hinge=left,open=false,powered=false]"
      },
      {
        "char": "*",
        "block": "minecraft:spruce_door[facing=south,half=upper,hinge=left,open=false,powered=false]"
      },
      {
        "char": "+",
        "block": "tfmg:asphalt"
      },
      {
        "char": ",",
        "block": "tfmg:cinder_block"
      }
    ]
  }
}
