{
  "xsize": 16,
  "zsize": 16,
  "slices": [
    [
      ".......''&......",
      ".....''&........",
      "...''&..........",
      ".''&............",
      "'&..............",
      "................",
      "..............''",
      "............''&.",
      "..........''&...",
      "........''&.....",
      "......''&.......",
      "....''&.........",
      "..''&...........",
      "''&.............",
      "&...............",
      "...............'"
    ],
    [
      "**************  ",
      "**************  ",
      "**************  ",
      "**************  ",
      "**************  ",
      "**************  ",
      "**************  ",
      "**************  ",
      "**************  ",
      "0000000000000000",
      "0000000000000000",
      "0000000000000000",
      "0000000000000000",
      "0000000000000000",
      "0000000000000000",
      "0000000000000000"
    ],
    [
      "             %  ",
      "             %  ",
      "$$$$$$$$$$   %  ",
      "$$$$$$$$$$   %  ",
      "             %  ",
      "//+//////+///%  ",
      "             %  ",
      "             %  ",
      "!!   !!!!    %  ",
      "!!   !!!!   ((((",
      "!!   !!!!       ",
      "!!   !!!!       ",
      "!!-  !!!!       ",
      "!!   !!!!       ",
      "(               ",
      "(   )))    )))  "
    ],
    [
      "             %  ",
      "             %  ",
      "$$$$$$$$$$   %  ",
      "$$$$$$$$$$   %  ",
      "             %  ",
      "//,//////,///%  ",
      "             %  ",
      "             %  ",
      "!!   !!!!    %  ",
      "!!   !!!!   ((((",
      "!!   !!!!       ",
      "!!   !!!!       ",
      "!!   !!!!       ",
      "!!-  !!!!       ",
      "(               ",
      "(   )))    )))  "
    ],
    [
      "             %  ",
      "             %  ",
      "             %  ",
      "             %  ",
      "             %  ",
      "/////////////%  ",
      "             %  ",
      "             %  ",
      "!!   !!!!    %  ",
      "!!   !!!!   ((((",
      "!!   !!!!       ",
      "!!   !!!!       ",
      "!!   !!!!       ",
      "!!   !!!!       ",
      "( -             ",
      "(   )))    )))  "
    ],
    [
      "             %  ",
      "             %  ",
      "             %  ",
      "             %  ",
      "             %  ",
      "/////////////%  ",
      "             %  ",
      "             %  ",
      "!!   !!!!    %  ",
      "!!   !!!!   ((((",
      "!!   !!!!       ",
      "!!   !!!!       ",
      "!!   !!!!       ",
      "!!   !!!!       ",
      "(               ",
      "( - )))    )))  "
    ]
  ],
  "palette": {
    "palette": [
      {
        "char": "!",
        "block": "ae2:quartz_glass"
      },
      {
        "char": "$",
        "block": "minecraft:barrel[facing=up,open=false]"
      },
      {
        "char": "%",
        "block": "minecraft:bricks"
      },
      {
        "char": "&",
        "block": "minecraft:coarse_dirt"
      },
      {
        "char": "'",
        "block": "minecraft:gravel"
      },
      {
        "char": "(",
        "block": "minecraft:polished_deepslate"
      },
      {
        "char": ")",
        "block": "minecraft:scaffolding"
      },
      {
        "char": "*",
        "block": "minecraft:smooth_stone"
      },
      {
        "char": "+",
        "block": "minecraft:spruce_door[facing=south,half=lower,hinge=left,open=false,powered=false]"
      },
      {
        "char": ",",
        "block": "minecraft:spruce_door[facing=south,half=upper,hinge=left,open=false,powered=false]"
      },
      {
        "char": "-",
        "block": "minecraft:stone_brick_stairs[facing=south,half=bottom,shape=straight,waterlogged=false]"
      },
      {
        "char": ".",
        "block": "tfmg:asphalt"
      },
      {
        "char": "/",
        "block": "tfmg:cinder_block"
      },
      {
        "char": "0",
        "block": "tfmg:factory_floor"
      }
    ]
  }
}
