{
  "xsize": 16,
  "zsize": 16,
  "slices": [
    [
      ",,,,,,,,,,((',,,",
      ",,,,,,,,((',,,,,",
      ",,,,,,((',,,,,,,",
      ",,,,((',,,,,,,,,",
      ",,((',,,,,,,,,,,",
      "((',,,,,,,,,,,,,",
      "',,,,,,,,,,,,,,,",
      ",,,,,,,,,,,,,,,(",
      ",,,,,,,,,,,,,(('",
      ",,,,,,,,,,,((',,",
      ",,,,,,,,,((',,,,",
      ",,,,,,,((',,,,,,",
      ",,,,,((',,,,,,,,",
      ",,,((',,,,,,,,,,",
      ",((',,,,,,,,,,,,",
      "(',,,,,,,,,,,,,,"
    ],
    [
      "       +++++++++",
      "       +++++++++",
      "       +++++++++",
      "       +++++++++",
      "       +++++++++",
      "       +++++++++",
      "       +++++++++",
      "       +++++++++",
      "       +++++++++",
      "-------+++++++++",
      "-------+++++++++",
      "-------+++++++++",
      "----------------",
      "----------------",
      "----------------",
      "----------------"
    ],
    [
      "       &  $$$$$$",
      "       &  $$$$$$",
      "       &  $$$$$$",
      "       &        ",
      "       &        ",
      "       &        ",
      "       &        ",
      "       &        ",
      "       &        ",
      ")))))))&        ",
      "       &        ",
      "       &   &&&&&",
      "                ",
      "      !!!!!!!   ",
      "      !!!!!!!   ",
      "  *** !!!!!!!   "
    ],
    [
      "       &  $$$$$$",
      "       &  $$$$$$",
      "       &  $$$$$$",
      "       &        ",
      "       &        ",
      "       &        ",
      "       &        ",
      "       &        ",
      "       &        ",
      ")))))))&        ",
      "       &        ",
      "       &   &&&&&",
      "                ",
      "      !!!!!!!   ",
      "      !!!!!!!   ",
      "  *** !%%%%%!   "
    ],
    [
      "       &  $$$$$$",
      "       &  $$$$$$",
      "       &  $$$$$$",
      "       &        ",
      "       &        ",
      "       &        ",
      "       &        ",
      "       &        ",
      "       &        ",
      ")))))))&        ",
      "       &        ",
      "       &   &&&&&",
      "                ",
      "      !!!!!!!   ",
      "      !!!!!!!   ",
      "  *** !     !   "
    ],
    [
      "       &  $$$$$$",
      "       &  $$$$$$",
      "       &  $$$$$$",
      "       &        ",
      "       &        ",
      "       &        ",
      "       &        ",
      "       &        ",
      "       &        ",
      ")))))))&        ",
      "       &        ",
      "       &   &&&&&",
      "                ",
      "      !!!!!!!   ",
      "      !!!!!!!   ",
      "  *** !     !   "
    ]
  ],
  "palette": {
    "palette": [
      {
        "char": "!",
        "block": "ae2:controller"
      },
      {
        "char": "$",
        "block": "ae2:dense_energy_cell"
      },
      {
        "char": "%",
        "block": "ae2:drive"
      },
      {
        "char": "&",
        "block": "minecraft:bricks"
      },
      {
        "char": "'",
        "block": "minecraft:coarse_dirt"
      },
      {
        "char": "(",
        "block": "minecraft:gravel"
      },
      {
        "char": ")",
        "block": "minecraft:polished_deepslate"
      },
      {
        "char": "*",
        "block": "minecraft:scaffolding"
      },
      {
        "char": "+",
        "block": "minecraft:smooth_stone"
      },
      {
        "char": ",",
        "block": "tfmg:asphalt"
      },
      {
        "char": "-",
        "block": "tfmg:factory_floor"
      }
    ]
  }
}
