{
  "xsize": 16,
  "zsize": 16,
  "slices": [
    [
      "                ",
      "''))))')        ",
      "))))))))        ",
      ")))))))'        ",
      "))))))))        ",
      "))))))))        ",
      "))))))))        ",
      "))))))''        ",
      "))))''&)        ",
      "))''&))'        ",
      "''&)))))        ",
      "&)))))))        ",
      "))))))))        ",
      "))))))))        ",
      "))))))))        ",
      ")&))))&)        "
    ],
    [
      "                ",
      "                ",
      "$$              ",
      "$$              ",
      "$$              ",
      "                ",
      "                ",
      "                ",
      "                ",
      "                ",
      "                ",
      "                ",
      "$$              ",
      "$$              ",
      "$$              ",
      "                "
    ],
    [
      "                ",
      "                ",
      "$$              ",
      "$$              ",
      "$$              ",
      "                ",
      "                ",
      "                ",
      "                ",
      "  !!!!!!        ",
      "  !!!!!!        ",
      "  !!!!!!        ",
      "$$              ",
      "$$              ",
      "$$              ",
      "                "
    ],
    [
      "                ",
      "                ",
      "$$              ",
      "$$              ",
      "$$              ",
      "                ",
      "                ",
      "                ",
      "                ",
      "  !!!!!!        ",
      "  !!!!!!        ",
      "  !!!!!!        ",
      "$$              ",
      "$$              ",
      "$$              ",
      "                "
    ],
    [
      "                ",
      "                ",
      "$$              ",
      "$$              ",
      "((((            ",
      "((((            ",
      "((((            ",
      "((((            ",
      "((((            ",
      "((((            ",
      "((((            ",
      "((((            ",
      "((((            ",
      "$$              ",
      "$$              ",
      "                "
    ],
    [
      "                ",
      "                ",
      "                ",
      "                ",
      "((((            ",
      "((((            ",
      " (((            ",
      " (((            ",
      "%(((            ",
      " (((            ",
      " (((            ",
      "((((            ",
      "((((            ",
      "                ",
      "                ",
      "                "
    ]
  ],
  "palette": {
    "palette": [
      {
        "char": "!",
        "block": "immersiveengineering:sheetmetal_steel"
      },
      {
        "char": "$",
        "block": "minecraft:blackstone"
      },
      {
        "char": "%",
        "block": "minecraft:chest[facing=east,type=single,waterlogged=false]",
        "tag": {
          "id": "minecraft:chest",
          "LootTable": "infinite_domain:chests/wasteland_military"
        }
      },
      {
        "char": "&",
        "block": "minecraft:coarse_dirt"
      },
      {
        "char": "'",
        "block": "minecraft:gravel"
      },
      {
        "char": "(",
        "block": "minecraft:green_terracotta"
      },
      {
        "char": ")",
        "block": "tfmg:asphalt"
      }
    ]
  }
}
