{
  "xsize": 16,
  "zsize": 16,
  "slices": [
    [
      "                ",
      "                ",
      "                ",
      "                ",
      "         %%&%%%%",
      "         %% %%%%",
      "                ",
      "                ",
      "                ",
      "   %%))         ",
      "   %%))         ",
      "   %%%%%%%%%%%%%",
      "   %%%%%%%%%%%%%",
      "                ",
      "                ",
      "                "
    ],
    [
      "                ",
      "                ",
      "                ",
      "                ",
      "                ",
      "         $$$$$$$",
      "                ",
      "                ",
      "                ",
      "     $$         ",
      "     $$         ",
      "     $$$$$$$$$$$",
      "                ",
      "                ",
      "                ",
      "                "
    ],
    [
      "                ",
      "                ",
      "                ",
      "                ",
      "                ",
      "         $$$$$$$",
      "         $$$$$$$",
      "         $$$$$$$",
      "         $$$$$$$",
      "     $$$$$$$$$$$",
      "     $$$$$$$$$$$",
      "     $$$$$$$$$$$",
      "                ",
      "                ",
      "                ",
      "                "
    ],
    [
      "                ",
      "                ",
      "                ",
      "                ",
      "                ",
      "                ",
      "         (((((((",
      "         ((    (",
      "         ((    (",
      "         ((    (",
      "         (((((((",
      "                ",
      "                ",
      "                ",
      "                ",
      "                "
    ],
    [
      "                ",
      "                ",
      "                ",
      "                ",
      "                ",
      "                ",
      "         (((((((",
      "         ((((((!",
      "         ((((((!",
      "         ((((((!",
      "         (((((((",
      "                ",
      "                ",
      "                ",
      "                ",
      "                "
    ],
    [
      "                ",
      "                ",
      "                ",
      "                ",
      "                ",
      "                ",
      "                ",
      "                ",
      "            '   ",
      "                ",
      "                ",
      "                ",
      "                ",
      "                ",
      "                ",
      "                "
    ]
  ],
  "palette": {
    "palette": [
      {
        "char": "!",
        "block": "immersiveengineering:sheetmetal_steel"
      },
      {
        "char": "$",
        "block": "minecraft:green_concrete"
      },
      {
        "char": "%",
        "block": "minecraft:green_terracotta"
      },
      {
        "char": "&",
        "block": "minecraft:iron_door[facing=north,half=upper,hinge=left,open=false,powered=false]"
      },
      {
        "char": "'",
        "block": "minecraft:iron_trapdoor[facing=north,half=top,open=false,powered=false,waterlogged=false]"
      },
      {
        "char": "(",
        "block": "minecraft:mossy_stone_bricks"
      },
      {
        "char": ")",
        "block": "minecraft:oxidized_copper"
      }
    ]
  }
}
