{
  "xsize": 16,
  "zsize": 16,
  "slices": [
    [
      "                ",
      " *&****&****&**&",
      " ************&&$",
      " $*********&&$**",
      " ********&&$****",
      " ******&&$******",
      " ****&&$********",
      " **&&$**********",
      " &&$************",
      " $**************",
      " ***************",
      " *************&&",
      " ***********&&$*",
      " *********&&$***",
      " *******&&$*****",
      " *$***&$$***$***"
    ],
    [
      "                ",
      "                ",
      "    !!!!!!!!!!!!",
      "  &&&&&&&!!!!!!!",
      "  &&&&&&&!!!!!!!",
      "  &&&&&&&       ",
      "  &&&&&&&       ",
      "  &&&&&&&       ",
      "  &&&&&&&       ",
      "                ",
      "                ",
      "                ",
      "    !!!!!!!!!!!!",
      "    !!!!!!!!!!!!",
      "    !!!!!!!!!!!!",
      "                "
    ],
    [
      "                ",
      "                ",
      "    !!!!!!!!!!!!",
      "  &&&&&&&!!!!!!!",
      "  &&&&&&&!!!!!!!",
      "  &&&&&&&       ",
      "  &&&&&&&       ",
      "  &&&&&&&       ",
      "  &&&&&&&       ",
      "                ",
      "                ",
      "                ",
      "    !!!!!!!!!!!!",
      "    !!!!!!!!!!!!",
      "    !!!!!!!!!!!!",
      "                "
    ],
    [
      "                ",
      "                ",
      "    !!!!!!!!!!!!",
      "  &&&&&&&!!!!!!!",
      "  &&&&&&&!!!!!!!",
      "  &&&&&&&       ",
      "  &&&&&&&       ",
      "  &&&&&&&       ",
      "  &&&&&&&       ",
      "                ",
      "                ",
      "                ",
      "    !!!!!!!!!!!!",
      "    !!!!!!!!!!!!",
      "    !!!!!!!!!!!!",
      "                "
    ],
    [
      "                ",
      "                ",
      "    !!!!!!!!!!!!",
      "         !!!!!!!",
      "         '''''''",
      "         '''''''",
      "         '''''''",
      "         '''''''",
      "         '''''''",
      "   '''''''''''''",
      "   '''''''''''''",
      "   '''',''''''''",
      "   '''''''''''''",
      "    !!!!!!!!!!!!",
      "    !!!!!!!!!!!!",
      "                "
    ],
    [
      "                ",
      "                ",
      "                ",
      "                ",
      "         ''(''''",
      "         '' ''''",
      "                ",
      "             %  ",
      "            )   ",
      "   '''' +    %  ",
      "   ''''         ",
      "   '''''''''''''",
      "   '''''''''''''",
      "                ",
      "                ",
      "                "
    ]
  ],
  "palette": {
    "palette": [
      {
        "char": "!",
        "block": "minecraft:blackstone"
      },
      {
        "char": "$",
        "block": "minecraft:coarse_dirt"
      },
      {
        "char": "%",
        "block": "minecraft:dark_oak_stairs[facing=west,half=bottom,shape=straight,waterlogged=false]"
      },
      {
        "char": "&",
        "block": "minecraft:gravel"
      },
      {
        "char": "'",
        "block": "minecraft:green_terracotta"
      },
      {
        "char": "(",
        "block": "minecraft:iron_door[facing=north,half=lower,hinge=left,open=false,powered=false]"
      },
      {
        "char": ")",
        "block": "minecraft:spawner",
        "tag": {
          "id": "minecraft:mob_spawner",
          "Delay": 360,
          "MinSpawnDelay": 240,
          "MaxSpawnDelay": 720,
          "SpawnCount": 1,
          "MaxNearbyEntities": 2,
          "RequiredPlayerRange": 14,
          "SpawnRange": 4,
          "SpawnData": {
            "entity": {
              "id": "mutantmonsters:mutant_zombie"
            }
          },
          "SpawnPotentials": [
            {
              "weight": 1,
              "data": {
                "entity": {
                  "id": "mutantmonsters:mutant_zombie"
                }
              }
            }
          ]
        }
      },
      {
        "char": "*",
        "block": "tfmg:asphalt"
      },
      {
        "char": "+",
        "block": "the_wasteland_reworked:radio"
      },
      {
        "char": ",",
        "block": "the_wasteland_reworked:rusted_barrel"
      }
    ]
  }
}
