{
  "xsize": 16,
  "zsize": 16,
  "slices": [
    [
      "                ",
      " )'))))'))))'))'",
      " ))))))))))))''%",
      " %)))))))))''%))",
      " ))))))))''%))))",
      " ))))))''%))))))",
      " ))))''%))))))))",
      " ))''%))))))))))",
      " ''%))))))))))))",
      " %))))))))))))))",
      " )))))))))))))))",
      " )))))))))))))''",
      " )))))))))))''%)",
      " )))))))))''%)))",
      " )))))))''%)))))",
      " )%)))'%%)))%)))"
    ],
    [
      "                ",
      "                ",
      "                ",
      "                ",
      "                ",
      "                ",
      "                ",
      "                ",
      "                ",
      "                ",
      "                ",
      "                ",
      "                ",
      "                ",
      "                ",
      "                "
    ],
    [
      "                ",
      "                ",
      "    !!!!!!!!!!!!",
      "    !!!!!!!!!!!!",
      "    !!!!!!!!!!!!",
      "                ",
      "                ",
      "                ",
      "                ",
      "                ",
      "                ",
      "                ",
      "    !!!!!!!!!!!!",
      "    !!!!!!!!!!!!",
      "    !!!!!!!!!!!!",
      "                "
    ],
    [
      "                ",
      "                ",
      "    !!!!!!!!!!!!",
      "    !!!!!!!!!!!!",
      "    !!!!!!!!!!!!",
      "                ",
      "                ",
      "                ",
      "                ",
      "                ",
      "                ",
      "                ",
      "    !!!!!!!!!!!!",
      "    !!!!!!!!!!!!",
      "    !!!!!!!!!!!!",
      "                "
    ],
    [
      "                ",
      "                ",
      "    !!!!!!!!!!!!",
      "    !!!!!!!!!!!!",
      "   (((((((((((((",
      "   (((((((((((((",
      "   (((((((((((((",
      "   (((((((((((((",
      "   (((((((((((((",
      "   (((((((((((((",
      "   (((((((((((((",
      "   (((((((((((((",
      "   (((((((((((((",
      "    !!!!!!!!!!!!",
      "    !!!!!!!!!!!!",
      "                "
    ],
    [
      "                ",
      "                ",
      "                ",
      "                ",
      "   (((((((((((((",
      "   (((((((((((((",
      "   ((((         ",
      "   (((( $    &  ",
      "   ((((         ",
      "   (((( *    &  ",
      "   ((((         ",
      "   (((((((((((((",
      "   (((((((((((((",
      "                ",
      "                ",
      "                "
    ]
  ],
  "palette": {
    "palette": [
      {
        "char": "!",
        "block": "minecraft:blackstone"
      },
      {
        "char": "$",
        "block": "minecraft:blast_furnace[facing=east,lit=false]"
      },
      {
        "char": "%",
        "block": "minecraft:coarse_dirt"
      },
      {
        "char": "&",
        "block": "minecraft:dark_oak_stairs[facing=west,half=bottom,shape=straight,waterlogged=false]"
      },
      {
        "char": "'",
        "block": "minecraft:gravel"
      },
      {
        "char": "(",
        "block": "minecraft:green_terracotta"
      },
      {
        "char": ")",
        "block": "tfmg:asphalt"
      },
      {
        "char": "*",
        "block": "the_wasteland_reworked:radio"
      }
    ]
  }
}
