{
  "xsize": 16,
  "zsize": 16,
  "slices": [
    [
      "                ",
      "                ",
      "                ",
      "                ",
      "    &&--   --  -",
      "    &&%%%%%%%%%%",
      "    &&          ",
      "    %           ",
      "    %           ",
      "    %           ",
      "    %           ",
      "    %           ",
      "    %           ",
      "    %           ",
      "    %           ",
      "    %           "
    ],
    [
      "                ",
      "                ",
      "                ",
      "                ",
      "    &&          ",
      "    &&%%%%%%%%%%",
      "    &&          ",
      "    %           ",
      "    %           ",
      "    %           ",
      "    %           ",
      "    %           ",
      "    %           ",
      "    %           ",
      "    %           ",
      "    %           "
    ],
    [
      "                ",
      "                ",
      "                ",
      "                ",
      "    &&          ",
      "    &&%%%%%%%%%%",
      "    &&          ",
      "    %           ",
      "  (((           ",
      "  (((           ",
      "  (((           ",
      "  (((           ",
      "  (((           ",
      "  (((           ",
      "  (((           ",
      "    %           "
    ],
    [
      "                ",
      "                ",
      "                ",
      "                ",
      "   +&&++++++++++",
      "   +&&++++++++++",
      "   +&&''''''''''",
      "   ++'''''''''''",
      "  .++'''''''''''",
      "   ++'''''''''''",
      "   ++'''''''''''",
      "   ++'''''''''''",
      "   ++'''''''''''",
      "   ++'''''''''''",
      "  .++'''''''''''",
      "   ++'''''''''''"
    ],
    [
      "                ",
      "                ",
      "                ",
      "                ",
      "    &&,,   ,,  ,",
      "    &&%%%%%%%%%%",
      "    &&          ",
      "    %           ",
      "    % * $       ",
      "    %           ",
      "    %           ",
      "    %      )    ",
      "    %           ",
      "    %           ",
      "    %           ",
      "    %           "
    ],
    [
      "                ",
      "                ",
      "                ",
      "                ",
      "    &&          ",
      "    &&!!/%/!!//!",
      "    &&          ",
      "    %           ",
      "    %           ",
      "    !           ",
      "    !           ",
      "    %           ",
      "    %           ",
      "    %           ",
      "    %           ",
      "    %           "
    ]
  ],
  "palette": {
    "palette": [
      {
        "char": "!",
        "block": "create:framed_glass"
      },
      {
        "char": "$",
        "block": "minecraft:barrel[facing=up,open=false]"
      },
      {
        "char": "%",
        "block": "minecraft:bricks"
      },
      {
        "char": "&",
        "block": "minecraft:mud_bricks"
      },
      {
        "char": "'",
        "block": "minecraft:oak_planks"
      },
      {
        "char": "(",
        "block": "minecraft:oak_slab[type=top,waterlogged=false]"
      },
      {
        "char": ")",
        "block": "minecraft:oak_stairs[facing=east,half=bottom,shape=straight,waterlogged=false]"
      },
      {
        "char": "*",
        "block": "kubejs:ruined_smoker[facing=south]"
      },
      {
        "char": "+",
        "block": "minecraft:smooth_stone_slab[type=top,waterlogged=false]"
      },
      {
        "char": ",",
        "block": "minecraft:spruce_slab[type=bottom,waterlogged=false]"
      },
      {
        "char": "-",
        "block": "minecraft:spruce_slab[type=top,waterlogged=false]"
      },
      {
        "char": ".",
        "block": "minecraft:stripped_oak_log[axis=y]"
      },
      {
        "char": "/",
        "block": "minecraft:stripped_spruce_log[axis=y]"
      }
    ]
  }
}
