{
  "xsize": 16,
  "zsize": 16,
  "slices": [
    [
      "       % '      ",
      "       % '      ",
      "       % '      ",
      "       % '      ",
      "       % '      ",
      "       % '      ",
      "       % '      ",
      "       % '      ",
      "       % '      ",
      "       % '      ",
      "       % '''''''",
      "       % '      ",
      "       % '      ",
      "       % '      ",
      "       % '      ",
      "       % '      "
    ],
    [
      "       %        ",
      "       %        ",
      "       %        ",
      "       %        ",
      "       %        ",
      "       %        ",
      "       %        ",
      "       %        ",
      "       %        ",
      "       %        ",
      "       %        ",
      "       %        ",
      "       %        ",
      "       %        ",
      "       %        ",
      "       %        "
    ],
    [
      "       &&&&&&   ",
      "       &&&&&&   ",
      "       &&&&&&&&&",
      "       &&&&&&&&&",
      "       &&&&&&&&&",
      "       &&&&&&&&&",
      "       &&&&&&&&&",
      "       &&&&&&&&&",
      "       &&&&&&&&&",
      "       &&&&&&&&&",
      "       &&&&&&&&&",
      "       &&&&&&&&&",
      "       &&&&&&&&&",
      "       &&&&&&&&&",
      "       &&&&&&&&&",
      "       &&&&&&&&&"
    ],
    [
      "       % '(     ",
      "       % '      ",
      "       % '      ",
      "       % ' )    ",
      "       % '      ",
      "       % '      ",
      "       % '      ",
      "       % '   $  ",
      "       % '      ",
      "       % '      ",
      "       % '''''''",
      "       % '      ",
      "       % '      ",
      "       % '   $  ",
      "       % '      ",
      "       % '      "
    ],
    [
      "       % '((((  ",
      "       % '      ",
      "       ! '      ",
      "       ! '      ",
      "       % '      ",
      "       % '      ",
      "       % '      ",
      "       % '      ",
      "       % '      ",
      "       % '      ",
      "       % '''''''",
      "       % '      ",
      "       % '      ",
      "       ! '      ",
      "       ! '      ",
      "       % '      "
    ],
    [
      "       % '((    ",
      "       % '      ",
      "       ! '      ",
      "       ! '      ",
      "       % '      ",
      "       % '      ",
      "       % '      ",
      "       % '      ",
      "       % '      ",
      "       % '      ",
      "       % '''''''",
      "       % '      ",
      "       % '      ",
      "       ! '      ",
      "       ! '      ",
      "       % '      "
    ]
  ],
  "palette": {
    "palette": [
      {
        "char": "!",
        "block": "create:framed_glass"
      },
      {
        "char": "$",
        "block": "minecraft:barrel[facing=up,open=false]"
      },
      {
        "char": "%",
        "block": "minecraft:mud_bricks"
      },
      {
        "char": "&",
        "block": "minecraft:oak_planks"
      },
      {
        "char": "'",
        "block": "minecraft:stripped_oak_wood"
      },
      {
        "char": "(",
        "block": "minecraft:stripped_spruce_wood"
      },
      {
        "char": ")",
        "block": "minecraft:water_cauldron[level=3]"
      }
    ]
  }
}
