{
  "xsize": 16,
  "zsize": 16,
  "slices": [
    [
      "       & (      ",
      "       & (      ",
      "       & (      ",
      "       & (      ",
      "&&&&&&&& (      ",
      "         ())))))",
      "         (      ",
      "         (      ",
      "       % %      ",
      "         (      ",
      "         (      ",
      "         (      ",
      "         (      ",
      "         (      ",
      "         &&     ",
      "$$$$$$$$$&&!!$$$"
    ],
    [
      "       & (      ",
      "       & (      ",
      "       & (      ",
      "       & (      ",
      "&&&&&&&& (      ",
      "         ())))))",
      "         (      ",
      "         (      ",
      "         (      ",
      "         (      ",
      "         (      ",
      "         (      ",
      "         (      ",
      "         (      ",
      "         &&     ",
      "$$$$$$$$$&&!!$$$"
    ],
    [
      "       & (      ",
      "       & (      ",
      "       & (      ",
      "       & (      ",
      "&&&&&&&& (      ",
      "         ())))))",
      "         (      ",
      "         (      ",
      "         (      ",
      "         (      ",
      "         (      ",
      "         (      ",
      "         (      ",
      "         (      ",
      "         &&     ",
      "$$$$$$$$$&&$$$$$"
    ],
    [
      "       & (      ",
      "       & (      ",
      "       & (      ",
      "       & (      ",
      "&&&&&&&& (      ",
      "         (      ",
      "         (      ",
      "         (      ",
      "         (      ",
      "         (      ",
      "         (      ",
      "         (      ",
      "         (      ",
      "         (      ",
      "         &&     ",
      "$$$$$$$$$&&$$$$$"
    ],
    [
      "       &        ",
      "       &        ",
      "       &        ",
      "       &        ",
      "&&&&&&&&        ",
      "                ",
      "                ",
      "                ",
      "                ",
      "                ",
      "                ",
      "                ",
      "                ",
      "                ",
      "         &&     ",
      "$$$$$$$$$&&$$$$$"
    ],
    [
      "       *********",
      "       *********",
      "       *********",
      "       *********",
      "****************",
      "****************",
      "****************",
      "****************",
      "****************",
      "****************",
      "****************",
      "****************",
      "****************",
      "****************",
      "****************",
      "''''''''''''''''"
    ]
  ],
  "palette": {
    "palette": [
      {
        "char": "!",
        "block": "create:framed_glass"
      },
      {
        "char": "$",
        "block": "minecraft:bricks"
      },
      {
        "char": "%",
        "block": "minecraft:dark_oak_door[facing=west,half=upper,hinge=left,open=false,powered=false]"
      },
      {
        "char": "&",
        "block": "minecraft:mud_bricks"
      },
      {
        "char": "'",
        "block": "minecraft:smooth_stone_slab[type=top,waterlogged=false]"
      },
      {
        "char": "(",
        "block": "minecraft:stripped_oak_wood"
      },
      {
        "char": ")",
        "block": "minecraft:stripped_spruce_wood"
      },
      {
        "char": "*",
        "block": "minecraft:weathered_cut_copper"
      }
    ]
  }
}
