{
  "xsize": 16,
  "zsize": 16,
  "slices": [
    [
      "        %       ",
      "        %       ",
      "        %       ",
      "        %       ",
      "        %       ",
      "        %       ",
      "        %       ",
      "        %       ",
      "        %       ",
      "        %       ",
      "        %       ",
      "        %       ",
      "        %       ",
      "        %       ",
      "        ''      ",
      "%%%%%%%%''      "
    ],
    [
      "        %       ",
      "        %       ",
      "        %       ",
      "        %       ",
      "        %       ",
      "        %       ",
      "        )))     ",
      "        )))     ",
      "        )))     ",
      "        )))     ",
      "        )))     ",
      "        )))     ",
      "        )))     ",
      "        %       ",
      "        ''      ",
      "%%%%%%%%''      "
    ],
    [
      "((((((((++      ",
      "((((((((++      ",
      "((((((((++      ",
      "((((((((++      ",
      "((((((((++      ",
      "((((((((++      ",
      "((((((((++0     ",
      "((((((((++      ",
      "((((((((++      ",
      "((((((((++      ",
      "((((((((++      ",
      "((((((((++      ",
      "((((((((++0     ",
      "((((((((++      ",
      "((((((((''      ",
      "++++++++''      "
    ],
    [
      " ,  &   %       ",
      " 1      %       ",
      " 1      %       ",
      " 1      %       ",
      " 1      %       ",
      "11.11111%       ",
      "        %       ",
      "        %       ",
      "        %       ",
      "        %       ",
      "        %       ",
      "        %       ",
      "    $ * %       ",
      "        %       ",
      "        ''      ",
      "%%%%%%%%''      "
    ],
    [
      " -      !       ",
      " 1      %       ",
      " 1      %       ",
      " 1      %       ",
      " 1      %       ",
      "11/11111%       ",
      "        %       ",
      "        %       ",
      "        %       ",
      "        %       ",
      "        %       ",
      "        !       ",
      "        !       ",
      "        %       ",
      "        ''      ",
      "!!%%!!%%''      "
    ],
    [
      " 1      !       ",
      " 1      %       ",
      " 1      %       ",
      " 1      %       ",
      " 1      %       ",
      "11111111%       ",
      "        %       ",
      "        %       ",
      "        %       ",
      "        %       ",
      "        %       ",
      "        !       ",
      "        !       ",
      "        %       ",
      "        ''      ",
      "!!%%!!%%''      "
    ]
  ],
  "palette": {
    "palette": [
      {
        "char": "!",
        "block": "create:framed_glass"
      },
      {
        "char": "$",
        "block": "minecraft:barrel[facing=up,open=false]"
      },
      {
        "char": "%",
        "block": "minecraft:bricks"
      },
      {
        "char": "&",
        "block": "minecraft:chest[facing=west,type=single,waterlogged=false]",
        "tag": {
          "id": "minecraft:chest",
          "LootTable": "infinite_domain:chests/wasteland_home"
        }
      },
      {
        "char": "'",
        "block": "minecraft:mud_bricks"
      },
      {
        "char": "(",
        "block": "minecraft:oak_planks"
      },
      {
        "char": ")",
        "block": "minecraft:oak_slab[type=top,waterlogged=false]"
      },
      {
        "char": "*",
        "block": "minecraft:smoker[facing=north,lit=false]"
      },
      {
        "char": "+",
        "block": "minecraft:smooth_stone_slab[type=top,waterlogged=false]"
      },
      {
        "char": ",",
        "block": "minecraft:spruce_door[facing=east,half=lower,hinge=left,open=false,powered=false]"
      },
      {
        "char": "-",
        "block": "minecraft:spruce_door[facing=east,half=upper,hinge=left,open=false,powered=false]"
      },
      {
        "char": ".",
        "block": "minecraft:spruce_door[facing=south,half=lower,hinge=left,open=false,powered=false]"
      },
      {
        "char": "/",
        "block": "minecraft:spruce_door[facing=south,half=upper,hinge=left,open=false,powered=false]"
      },
      {
        "char": "0",
        "block": "minecraft:stripped_oak_log[axis=y]"
      },
      {
        "char": "1",
        "block": "minecraft:stripped_spruce_wood"
      }
    ]
  }
}
