{
  "xsize": 16,
  "zsize": 16,
  "slices": [
    [
      "2222222222''&222",
      "22222222''&22222",
      "222222''&2222222",
      "2222''&222222222",
      "22''&22222222222",
      "''&2222222222222",
      "&222222222222222",
      "222222222222222'",
      "2222222222222''&",
      "22222222222''&22",
      "222222222''&2222",
      "2222222''&222222",
      "22222''&22222222",
      "222''&2222222222",
      "2''&222222222222",
      "'&22222222222222"
    ],
    [
      "    ))))))))))))",
      "    ))))))))))))",
      "    ))))))))))))",
      "    ))))))))))))",
      "    ))))))))))))",
      "    ))))))))))))",
      "    ))))))))))))",
      "    ))))))))))))",
      "    ))))))))))))",
      "    ))))))))))))",
      "    ))))))))))))",
      "    ))))))))))))",
      "    ))))))))))))",
      "    ))))))))))))",
      "    ))))))))))))",
      "    ))))))))))))"
    ],
    [
      "    %        ,  ",
      "    %        0  ",
      "    %        0 1",
      "    %        0  ",
      "    %        0  ",
      "    %00000.00000",
      "    %           ",
      "    %           ",
      "    %           ",
      "    %      *    ",
      "    %           ",
      "    %           ",
      "    % + $       ",
      "    %           ",
      "    ((          ",
      "    ((%%%%%%%%%%"
    ],
    [
      "    !        -  ",
      "    %        0  ",
      "    %        0  ",
      "    %        0  ",
      "    %        0  ",
      "    %00000/00000",
      "    %           ",
      "    %           ",
      "    %           ",
      "    %           ",
      "    %           ",
      "    !           ",
      "    !           ",
      "    %           ",
      "    ((          ",
      "    ((!!%%%!!%%!"
    ],
    [
      "    !        0  ",
      "    %        0  ",
      "    %        0  ",
      "    %        0  ",
      "    %        0  ",
      "    %00000000000",
      "    %           ",
      "    %           ",
      "    %           ",
      "    %           ",
      "    %           ",
      "    !           ",
      "    !           ",
      "    %           ",
      "    ((          ",
      "    ((!!%%%!!%%!"
    ],
    [
      "    %        0  ",
      "    %        0  ",
      "    %        0  ",
      "    %        0  ",
      "    %        0  ",
      "    %00000000000",
      "    %           ",
      "    %           ",
      "    %           ",
      "    %           ",
      "    %           ",
      "    %           ",
      "    %           ",
      "    %           ",
      "    ((          ",
      "    ((%%%%%%%%%%"
    ]
  ],
  "palette": {
    "palette": [
      {
        "char": "!",
        "block": "create:framed_glass"
      },
      {
        "char": "$",
        "block": "minecraft:barrel[facing=up,open=false]"
      },
      {
        "char": "%",
        "block": "minecraft:bricks"
      },
      {
        "char": "&",
        "block": "minecraft:coarse_dirt"
      },
      {
        "char": "'",
        "block": "minecraft:gravel"
      },
      {
        "char": "(",
        "block": "minecraft:mud_bricks"
      },
      {
        "char": ")",
        "block": "minecraft:oak_planks"
      },
      {
        "char": "*",
        "block": "minecraft:oak_stairs[facing=east,half=bottom,shape=straight,waterlogged=false]"
      },
      {
        "char": "+",
        "block": "minecraft:smoker[facing=north,lit=false]"
      },
      {
        "char": ",",
        "block": "minecraft:spruce_door[facing=east,half=lower,hinge=left,open=false,powered=false]"
      },
      {
        "char": "-",
        "block": "minecraft:spruce_door[facing=east,half=upper,hinge=left,open=false,powered=false]"
      },
      {
        "char": ".",
        "block": "minecraft:spruce_door[facing=south,half=lower,hinge=left,open=false,powered=false]"
      },
      {
        "char": "/",
        "block": "minecraft:spruce_door[facing=south,half=upper,hinge=left,open=false,powered=false]"
      },
      {
        "char": "0",
        "block": "minecraft:stripped_spruce_wood"
      },
      {
        "char": "1",
        "block": "minecraft:water_cauldron[level=3]"
      },
      {
        "char": "2",
        "block": "tfmg:asphalt"
      }
    ]
  }
}
