{
  "xsize": 16,
  "zsize": 16,
  "slices": [
    [
      " 0      %       ",
      " 0      %       ",
      " 0      %       ",
      " 0      %       ",
      " 0      %       ",
      "00000000%       ",
      "        %       ",
      "        %       ",
      "        %       ",
      "        %       ",
      "        %       ",
      "        %       ",
      "        %       ",
      "        %       ",
      "        &&      ",
      "%%%%%%%%&&      "
    ],
    [
      "        %       ",
      "        %       ",
      "        %       ",
      "        %       ",
      "        %       ",
      "        %       ",
      "        %       ",
      "        %       ",
      "        %       ",
      "        %       ",
      "        %       ",
      "        %       ",
      "        %       ",
      "        %       ",
      "        &&      ",
      "%%%%%%%%&&      "
    ],
    [
      "        %       ",
      "        %       ",
      "        %       ",
      "        %       ",
      "        %       ",
      "        %       ",
      "        (((     ",
      "        (((     ",
      "        (((     ",
      "        (((     ",
      "        (((     ",
      "        (((     ",
      "        (((     ",
      "        %       ",
      "        &&      ",
      "%%%%%%%%&&      "
    ],
    [
      "''''''''**      ",
      "''''''''**      ",
      "''''''''**      ",
      "''''''''**      ",
      "''''''''**      ",
      "''''''''**      ",
      "''''''''**/     ",
      "''''''''**      ",
      "''''''''**      ",
      "''''''''**      ",
      "''''''''**      ",
      "''''''''**      ",
      "''''''''**/     ",
      "''''''''**      ",
      "''''''''&&      ",
      "********&&      "
    ],
    [
      " +      %       ",
      " 0      %       ",
      " 0      %       ",
      " 0      %       ",
      " 0      %       ",
      "00-00000%       ",
      "        %       ",
      "        %       ",
      "        %       ",
      "        %       ",
      "        %       ",
      "        %       ",
      "    $ ) %       ",
      "        %       ",
      "        &&      ",
      "%%%%%%%%&&      "
    ],
    [
      " ,      !       ",
      " 0      %       ",
      " 0      %       ",
      " 0      %       ",
      " 0      %       ",
      "00.00000%       ",
      "        %       ",
      "        %       ",
      "        %       ",
      "        %       ",
      "        %       ",
      "        !       ",
      "        !       ",
      "        %       ",
      "        &&      ",
      "!!%%!!%%&&      "
    ]
  ],
  "palette": {
    "palette": [
      {
        "char": "!",
        "block": "create:framed_glass"
      },
      {
        "char": "$",
        "block": "minecraft:barrel[facing=up,open=false]"
      },
      {
        "char": "%",
        "block": "minecraft:bricks"
      },
      {
        "char": "&",
        "block": "minecraft:mud_bricks"
      },
      {
        "char": "'",
        "block": "minecraft:oak_planks"
      },
      {
        "char": "(",
        "block": "minecraft:oak_slab[type=top,waterlogged=false]"
      },
      {
        "char": ")",
        "block": "minecraft:smoker[facing=north,lit=false]"
      },
      {
        "char": "*",
        "block": "minecraft:smooth_stone_slab[type=top,waterlogged=false]"
      },
      {
        "char": "+",
        "block": "minecraft:spruce_door[facing=east,half=lower,hinge=left,open=false,powered=false]"
      },
      {
        "char": ",",
        "block": "minecraft:spruce_door[facing=east,half=upper,hinge=left,open=false,powered=false]"
      },
      {
        "char": "-",
        "block": "minecraft:spruce_door[facing=south,half=lower,hinge=left,open=false,powered=false]"
      },
      {
        "char": ".",
        "block": "minecraft:spruce_door[facing=south,half=upper,hinge=left,open=false,powered=false]"
      },
      {
        "char": "/",
        "block": "minecraft:stripped_oak_log[axis=y]"
      },
      {
        "char": "0",
        "block": "minecraft:stripped_spruce_wood"
      }
    ]
  }
}
