{
  "xsize": 16,
  "zsize": 16,
  "slices": [
    [
      ".............   ",
      ".............   ",
      ".............   ",
      ".............   ",
      ".............   ",
      ".............   ",
      ".............   ",
      "............'   ",
      "..........''&   ",
      "........''&..   ",
      "......''&....   ",
      "....''&......   ",
      "..''&........   ",
      "''&..........   ",
      "&............   ",
      ".............   "
    ],
    [
      "                ",
      "                ",
      "                ",
      "                ",
      "                ",
      ")))))))))       ",
      ")))))))))       ",
      ")))))))))       ",
      ")))))))))       ",
      ")))))))))       ",
      ")))))))))       ",
      ")))))))))       ",
      ")))))))))       ",
      ")))))))))       ",
      ")))))))))       ",
      ")))))))))       "
    ],
    [
      "                ",
      "                ",
      "                ",
      "                ",
      "++  ++  ((      ",
      "%%%%%%%%((      ",
      "        ((      ",
      "        %       ",
      "    $ * %       ",
      "        %       ",
      "        %       ",
      "        %       ",
      "        %       ",
      "        %       ",
      "        %       ",
      "        %       "
    ],
    [
      "                ",
      "                ",
      "                ",
      "                ",
      "        ((      ",
      "!!--!!-%((      ",
      "        ((      ",
      "        %       ",
      "        %       ",
      "        !       ",
      "        !       ",
      "        %       ",
      "        %       ",
      "        %       ",
      "        %       ",
      "        %       "
    ],
    [
      "                ",
      "                ",
      "                ",
      "                ",
      "        ((      ",
      "!!--!!-%((      ",
      "        ((      ",
      "        %       ",
      "        %       ",
      "        !       ",
      "        !       ",
      "        %       ",
      "        %       ",
      "        %       ",
      "        %       ",
      "        %       "
    ],
    [
      "                ",
      "                ",
      "                ",
      "                ",
      ",,  ,,  ((      ",
      "%%%%%%%%((      ",
      "        ((      ",
      "        %       ",
      "        %       ",
      "        %       ",
      "        %       ",
      "        %       ",
      "        %       ",
      "        %       ",
      "        %       ",
      "        %       "
    ]
  ],
  "palette": {
    "palette": [
      {
        "char": "!",
        "block": "create:framed_glass"
      },
      {
        "char": "$",
        "block": "minecraft:barrel[facing=up,open=false]"
      },
      {
        "char": "%",
        "block": "minecraft:bricks"
      },
      {
        "char": "&",
        "block": "minecraft:coarse_dirt"
      },
      {
        "char": "'",
        "block": "minecraft:gravel"
      },
      {
        "char": "(",
        "block": "minecraft:mud_bricks"
      },
      {
        "char": ")",
        "block": "minecraft:oak_planks"
      },
      {
        "char": "*",
        "block": "kubejs:ruined_smoker[facing=south]"
      },
      {
        "char": "+",
        "block": "minecraft:spruce_slab[type=bottom,waterlogged=false]"
      },
      {
        "char": ",",
        "block": "minecraft:spruce_slab[type=top,waterlogged=false]"
      },
      {
        "char": "-",
        "block": "minecraft:stripped_spruce_log[axis=y]"
      },
      {
        "char": ".",
        "block": "tfmg:asphalt"
      }
    ]
  }
}
