{
  "xsize": 16,
  "zsize": 16,
  "slices": [
    [
      "2222222222222222",
      "2222222222222222",
      "2222222222222222",
      "----222222222222",
      "----222222222222",
      "----222222222))&",
      "----2222222))&22",
      "----22222))&2222",
      "2222222))&222222",
      "22222))&22222222",
      "222))&2222222222",
      "2))&222222222222",
      ")&22222222222222",
      "2222222222222222",
      "22222222222222))",
      "&&&&&&&22222))&2"
    ],
    [
      "                ",
      "                ",
      "    ,           ",
      "                ",
      "                ",
      "++++++++++++++++",
      "++++++++++++++++",
      "++++++++++++++++",
      "++++++++++++++++",
      "++++++++++++++++",
      "++++++++++)))+++",
      "++++++++++)))+++",
      "++++++++++)))+++",
      "++++++++++++++))",
      "++++++++++++++))",
      "       +++++++))"
    ],
    [
      "                ",
      "                ",
      "    ,           ",
      "                ",
      "         **..   ",
      "$$$$$$$$$**$$$$ ",
      "         **     ",
      "         0      ",
      " %       0      ",
      "         0      ",
      "         0)))   ",
      "         0)))   ",
      "       ' ')))   ",
      "         0    ))",
      "******** 0    ))",
      "       * 0    ))"
    ],
    [
      "                ",
      "                ",
      "    ,           ",
      "                ",
      "         **     ",
      "$$$$$$$$$**!!   ",
      "         **     ",
      "         0      ",
      "         0      ",
      "         0      ",
      "         0)))   ",
      "         0)))   ",
      "       ( ()))   ",
      "         0    ))",
      "******** 0    ))",
      "       * 0    ))"
    ],
    [
      "                ",
      "                ",
      "    ,           ",
      "                ",
      "         **     ",
      "$$$$$$$$$**!!1$1",
      "         **     ",
      "         0      ",
      "         0      ",
      "         0      ",
      "         0      ",
      "         0 $    ",
      "         0      ",
      "         0    ))",
      "******** 0    ))",
      "       * 0    ))"
    ],
    [
      "                ",
      "                ",
      "    ,           ",
      "                ",
      "         **//   ",
      "$$$$$$$$$**$$$  ",
      "         **     ",
      "         0      ",
      "         0      ",
      "         0      ",
      "         0      ",
      "         0      ",
      "         0      ",
      "         0    ))",
      "******** 0    ))",
      "       * 0    ))"
    ]
  ],
  "palette": {
    "palette": [
      {
        "char": "!",
        "block": "create:framed_glass"
      },
      {
        "char": "$",
        "block": "minecraft:bricks"
      },
      {
        "char": "%",
        "block": "minecraft:cartography_table"
      },
      {
        "char": "&",
        "block": "minecraft:coarse_dirt"
      },
      {
        "char": "'",
        "block": "minecraft:dark_oak_door[facing=west,half=lower,hinge=left,open=false,powered=false]"
      },
      {
        "char": "(",
        "block": "minecraft:dark_oak_door[facing=west,half=upper,hinge=left,open=false,powered=false]"
      },
      {
        "char": ")",
        "block": "minecraft:gravel"
      },
      {
        "char": "*",
        "block": "minecraft:mud_bricks"
      },
      {
        "char": "+",
        "block": "minecraft:oak_planks"
      },
      {
        "char": ",",
        "block": "minecraft:polished_deepslate"
      },
      {
        "char": "-",
        "block": "minecraft:smooth_stone"
      },
      {
        "char": ".",
        "block": "minecraft:spruce_slab[type=bottom,waterlogged=false]"
      },
      {
        "char": "/",
        "block": "minecraft:spruce_slab[type=top,waterlogged=false]"
      },
      {
        "char": "0",
        "block": "minecraft:stripped_oak_wood"
      },
      {
        "char": "1",
        "block": "minecraft:stripped_spruce_log[axis=y]"
      },
      {
        "char": "2",
        "block": "tfmg:asphalt"
      }
    ]
  }
}
