{
  "xsize": 16,
  "zsize": 16,
  "slices": [
    [
      "''&0000000000   ",
      "&000000000000   ",
      "0000000000000   ",
      "0000000000000   ",
      "00000000000''   ",
      "000000000''&0   ",
      "0000000''&000   ",
      "00000''&00000   ",
      "000''&0000000   ",
      "0''&000000000   ",
      "'&00000000000   ",
      "0000000000000   ",
      "0000000000000   ",
      "000000000000'   ",
      "0000000000''&   ",
      "00000000''&00   "
    ],
    [
      ")))))))))       ",
      ")))))))))       ",
      ")))))))))       ",
      ")))))))))       ",
      ")))))))))       ",
      ")))))))))       ",
      ")))))))))       ",
      ")))))))))       ",
      ")))))))))       ",
      ")))))))))       ",
      ")))))))))       ",
      ")))))))))       ",
      ")))))))))       ",
      ")))))))))       ",
      ")))))))))       ",
      ")))))))))       "
    ],
    [
      " +      %       ",
      " /      %       ",
      " /      %       ",
      " /      %       ",
      " /      %       ",
      "//-/////%       ",
      "        %       ",
      "        %       ",
      "        %       ",
      "        %       ",
      "        %       ",
      "        %       ",
      "    $ * %       ",
      "        %       ",
      "        ((      ",
      "%%%%%%%%((      "
    ],
    [
      " ,      !       ",
      " /      %       ",
      " /      %       ",
      " /      %       ",
      " /      %       ",
      "//./////%       ",
      "        %       ",
      "        %       ",
      "        %       ",
      "        %       ",
      "        %       ",
      "        !       ",
      "        !       ",
      "        %       ",
      "        ((      ",
      "!!%%!!%%((      "
    ],
    [
      " /      !       ",
      " /      %       ",
      " /      %       ",
      " /      %       ",
      " /      %       ",
      "////////%       ",
      "        %       ",
      "        %       ",
      "        %       ",
      "        %       ",
      "        %       ",
      "        !       ",
      "        !       ",
      "        %       ",
      "        ((      ",
      "!!%%!!%%((      "
    ],
    [
      " /      %       ",
      " /      %       ",
      " /      %       ",
      " /      %       ",
      " /      %       ",
      "////////%       ",
      "        %       ",
      "        %       ",
      "        %       ",
      "        %       ",
      "        %       ",
      "        %       ",
      "        %       ",
      "        %       ",
      "        ((      ",
      "%%%%%%%%((      "
    ]
  ],
  "palette": {
    "palette": [
      {
        "char": "!",
        "block": "create:framed_glass"
      },
      {
        "char": "$",
        "block": "minecraft:barrel[facing=up,open=false]"
      },
      {
        "char": "%",
        "block": "minecraft:bricks"
      },
      {
        "char": "&",
        "block": "minecraft:coarse_dirt"
      },
      {
        "char": "'",
        "block": "minecraft:gravel"
      },
      {
        "char": "(",
        "block": "minecraft:mud_bricks"
      },
      {
        "char": ")",
        "block": "minecraft:oak_planks"
      },
      {
        "char": "*",
        "block": "kubejs:ruined_smoker[facing=north]"
      },
      {
        "char": "+",
        "block": "minecraft:spruce_door[facing=east,half=lower,hinge=left,open=false,powered=false]"
      },
      {
        "char": ",",
        "block": "minecraft:spruce_door[facing=east,half=upper,hinge=left,open=false,powered=false]"
      },
      {
        "char": "-",
        "block": "minecraft:spruce_door[facing=south,half=lower,hinge=left,open=false,powered=false]"
      },
      {
        "char": ".",
        "block": "minecraft:spruce_door[facing=south,half=upper,hinge=left,open=false,powered=false]"
      },
      {
        "char": "/",
        "block": "minecraft:stripped_spruce_wood"
      },
      {
        "char": "0",
        "block": "tfmg:asphalt"
      }
    ]
  }
}
