{
  "xsize": 16,
  "zsize": 16,
  "slices": [
    [
      "........$       ",
      " .      $       ",
      " .      $       ",
      " .      $       ",
      " .      !       ",
      " .      !       ",
      " .      $       ",
      " .      $       ",
      " .      $       ",
      " .      $       ",
      "--------$       ",
      " .      $       ",
      " .      $       ",
      " .      $       ",
      " .      $       ",
      " .      !       "
    ],
    [
      "........$       ",
      " .      $       ",
      " .      $       ",
      " .      $       ",
      " .      $       ",
      " .      $       ",
      " .      $       ",
      " .      $       ",
      " .      $       ",
      " .      $       ",
      "--------$       ",
      " .      $       ",
      " .      $       ",
      " .      $       ",
      " .      $       ",
      " .      $       "
    ],
    [
      "        $       ",
      "        $       ",
      "        $       ",
      "        $       ",
      "        $       ",
      "        $       ",
      "        $       ",
      "        $       ",
      "        $       ",
      "        $       ",
      "--------$       ",
      "        $       ",
      "        $       ",
      "        $       ",
      "        $       ",
      "        $       "
    ],
    [
      "        $       ",
      "        $       ",
      "        $       ",
      "        $       ",
      "        $       ",
      "        $       ",
      "        $       ",
      "        $       ",
      "        $       ",
      "        $       ",
      "        $       ",
      "        $       ",
      "        $       ",
      "        $       ",
      "        $       ",
      "        $       "
    ],
    [
      "''''''''**      ",
      "''''''''**      ",
      "''''''''**      ",
      "''''''''**      ",
      "''''''''**      ",
      "''''''''**      ",
      "''''''''**      ",
      "''''''''**      ",
      "''''''''**      ",
      "''''''''**      ",
      "''''''''**      ",
      "''''''''**      ",
      "''''''''**      ",
      "''''''''**      ",
      "''''''''**      ",
      "''''''''**      "
    ],
    [
      "..,.....$       ",
      " .      $       ",
      " .      $       ",
      " .      $       ",
      " .  %   $       ",
      " +  &   $       ",
      " .      $       ",
      " .      $       ",
      " .      $       ",
      " .      $       ",
      "--------$       ",
      " .      $       ",
      " .      $       ",
      " .  )   $       ",
      " .  (   $       ",
      " .      $       "
    ]
  ],
  "palette": {
    "palette": [
      {
        "char": "!",
        "block": "create:framed_glass"
      },
      {
        "char": "$",
        "block": "minecraft:bricks"
      },
      {
        "char": "%",
        "block": "minecraft:green_bed[facing=south,occupied=false,part=foot]"
      },
      {
        "char": "&",
        "block": "minecraft:green_bed[facing=south,occupied=false,part=head]"
      },
      {
        "char": "'",
        "block": "minecraft:oak_planks"
      },
      {
        "char": "(",
        "block": "minecraft:red_bed[facing=north,occupied=false,part=foot]"
      },
      {
        "char": ")",
        "block": "minecraft:red_bed[facing=north,occupied=false,part=head]"
      },
      {
        "char": "*",
        "block": "minecraft:smooth_stone_slab[type=top,waterlogged=false]"
      },
      {
        "char": "+",
        "block": "minecraft:spruce_door[facing=east,half=lower,hinge=left,open=false,powered=false]"
      },
      {
        "char": ",",
        "block": "minecraft:spruce_door[facing=south,half=lower,hinge=left,open=false,powered=false]"
      },
      {
        "char": "-",
        "block": "minecraft:stripped_oak_wood"
      },
      {
        "char": ".",
        "block": "minecraft:stripped_spruce_wood"
      }
    ]
  }
}
