{
  "xsize": 16,
  "zsize": 16,
  "slices": [
    [
      "3333(('333333333",
      "33(('33333333333",
      "(('3333333333333",
      "'333333333333333",
      "333333333333333(",
      "3333333333333(('",
      "33333333333(('33",
      "333333333(('3333",
      "3333333(('333333",
      "33333(('33333333",
      "333(('3333333333",
      "3(('333333333333",
      "('33333333333333",
      "3333333333333333",
      "33333333333333((",
      "333333333333(('3"
    ],
    [
      "    ++++++++++++",
      "    ++++++++++++",
      "    ++++++++++++",
      "    ++++++++++++",
      "    ++++++++++++",
      "    ++++++++++++",
      "    ++++++++++++",
      "    ++++++++++++",
      "    ++++++++++++",
      "    ++++++++++++",
      "    ++++++++++++",
      "    ++++++++++++",
      "    ++++++++++++",
      "    ++++++++++++",
      "    ++++++++++++",
      "    ++++++++++++"
    ],
    [
      "    $11111.11111",
      "    $        1  ",
      "    $        1  ",
      "    $        1 2",
      "    $  %     1  ",
      "    $  &     ,  ",
      "    $        1  ",
      "    $        1  ",
      "    $        1  ",
      "    $        1  ",
      "    $00000000000",
      "    $        1  ",
      "    $        1  ",
      "    $  *     1  ",
      "    $  )     1  ",
      "    $        1  "
    ],
    [
      "    $11111/11111",
      "    $        1  ",
      "    $        1  ",
      "    $        1  ",
      "    !        1  ",
      "    !        -  ",
      "    $        1  ",
      "    $        1  ",
      "    $        1  ",
      "    $        1  ",
      "    $00000000000",
      "    $        1  ",
      "    $        1  ",
      "    $        1  ",
      "    $        1  ",
      "    !        1  "
    ],
    [
      "    $11111111111",
      "    $        1  ",
      "    $        1  ",
      "    $        1  ",
      "    !        1  ",
      "    !        1  ",
      "    $        1  ",
      "    $        1  ",
      "    $        1  ",
      "    $        1  ",
      "    $00000000000",
      "    $        1  ",
      "    $        1  ",
      "    $        1  ",
      "    $        1  ",
      "    !        1  "
    ],
    [
      "    $11111111111",
      "    $        1  ",
      "    $        1  ",
      "    $        1  ",
      "    $        1  ",
      "    $        1  ",
      "    $        1  ",
      "    $        1  ",
      "    $        1  ",
      "    $        1  ",
      "    $00000000000",
      "    $        1  ",
      "    $        1  ",
      "    $        1  ",
      "    $        1  ",
      "    $        1  "
    ]
  ],
  "palette": {
    "palette": [
      {
        "char": "!",
        "block": "create:framed_glass"
      },
      {
        "char": "$",
        "block": "minecraft:bricks"
      },
      {
        "char": "%",
        "block": "minecraft:brown_bed[facing=south,occupied=false,part=foot]"
      },
      {
        "char": "&",
        "block": "minecraft:brown_bed[facing=south,occupied=false,part=head]"
      },
      {
        "char": "'",
        "block": "minecraft:coarse_dirt"
      },
      {
        "char": "(",
        "block": "minecraft:gravel"
      },
      {
        "char": ")",
        "block": "minecraft:gray_bed[facing=north,occupied=false,part=foot]"
      },
      {
        "char": "*",
        "block": "minecraft:gray_bed[facing=north,occupied=false,part=head]"
      },
      {
        "char": "+",
        "block": "minecraft:oak_planks"
      },
      {
        "char": ",",
        "block": "minecraft:spruce_door[facing=east,half=lower,hinge=left,open=false,powered=false]"
      },
      {
        "char": "-",
        "block": "minecraft:spruce_door[facing=east,half=upper,hinge=left,open=false,powered=false]"
      },
      {
        "char": ".",
        "block": "minecraft:spruce_door[facing=south,half=lower,hinge=left,open=false,powered=false]"
      },
      {
        "char": "/",
        "block": "minecraft:spruce_door[facing=south,half=upper,hinge=left,open=false,powered=false]"
      },
      {
        "char": "0",
        "block": "minecraft:stripped_oak_wood"
      },
      {
        "char": "1",
        "block": "minecraft:stripped_spruce_wood"
      },
      {
        "char": "2",
        "block": "kubejs:ruined_cauldron"
      },
      {
        "char": "3",
        "block": "tfmg:asphalt"
      }
    ]
  }
}
