{
  "xsize": 16,
  "zsize": 16,
  "slices": [
    [
      ")))))))))))))   ",
      ")))))))))))))   ",
      ")))))))))))))   ",
      ")))))))))))))   ",
      ")))))))))))))   ",
      ")))))))))))))   ",
      ")))))))))))))   ",
      "))))))))))))$   ",
      "))))))))))$$!   ",
      "))))))))$$!))   ",
      "))))))$$!))))   ",
      "))))$$!))))))   ",
      "))$$!))))))))   ",
      "$$!))))))))))   ",
      "!))))))))))))   ",
      ")))))))))))))   "
    ],
    [
      "                ",
      "                ",
      "                ",
      "                ",
      "                ",
      "&&&&&&&&&       ",
      "&&&&&&&&&       ",
      "&&&&&&&&&       ",
      "&&&&&&&&&       ",
      "&&&&&&&&&       ",
      "&&&&&&&&&       ",
      "&&&&&&&&&       ",
      "&&&&&&&&&       ",
      "$&&&&&&&&       ",
      "$&&&&&&&&       ",
      "$&&&&&&&&       "
    ],
    [
      "                ",
      "                ",
      "                ",
      "                ",
      "''  ''  %%      ",
      "                ",
      "                ",
      "                ",
      "                ",
      "                ",
      "                ",
      "                ",
      "                ",
      "$               ",
      "$               ",
      "$               "
    ],
    [
      "                ",
      "                ",
      "                ",
      "                ",
      "        %%      ",
      "                ",
      "                ",
      "                ",
      "                ",
      "                ",
      "                ",
      "                ",
      "                ",
      "$               ",
      "$               ",
      "$               "
    ],
    [
      "                ",
      "                ",
      "                ",
      "                ",
      "        %%      ",
      "                ",
      "                ",
      "                ",
      "                ",
      "                ",
      "                ",
      "                ",
      "                ",
      "$               ",
      "$               ",
      "$               "
    ],
    [
      "                ",
      "                ",
      "                ",
      "                ",
      "((  ((  %%      ",
      "                ",
      "                ",
      "                ",
      "                ",
      "                ",
      "                ",
      "                ",
      "                ",
      "$               ",
      "$               ",
      "$               "
    ]
  ],
  "palette": {
    "palette": [
      {
        "char": "!",
        "block": "minecraft:coarse_dirt"
      },
      {
        "char": "$",
        "block": "minecraft:gravel"
      },
      {
        "char": "%",
        "block": "minecraft:mud_bricks"
      },
      {
        "char": "&",
        "block": "minecraft:oak_planks"
      },
      {
        "char": "'",
        "block": "minecraft:spruce_slab[type=bottom,waterlogged=false]"
      },
      {
        "char": "(",
        "block": "minecraft:spruce_slab[type=top,waterlogged=false]"
      },
      {
        "char": ")",
        "block": "tfmg:asphalt"
      }
    ]
  }
}
