{
  "xsize": 16,
  "zsize": 16,
  "slices": [
    [
      "3333333333''&333",
      "33333333''&33333",
      "333333''&3333333",
      "3333''&333333333",
      "33''&33333333333",
      "''&3333333333333",
      "&333333333333333",
      "333333333333333'",
      "3333333333333''&",
      "33333333333''&33",
      "333333333''&3333",
      "3333333''&333333",
      "33333''&33333333",
      "333''&3333333333",
      "3''&333333333333",
      "'&33333333333333"
    ],
    [
      "    ))))))))))))",
      "    ))))))))))))",
      "    ))))))))))))",
      "    ))))))))))))",
      "    ))))))))))))",
      "    ))))))))))))",
      "    ))))))))))))",
      "    ))))))))))))",
      "    ))))))))))))",
      "    ))))))))))))",
      "    ))))))))))))",
      "    ))))))))))))",
      "    ))))))))))))",
      "    ))))))))))))",
      "    ))))))))))))",
      "    ))))))))))))"
    ],
    [
      "    %        -  ",
      "    %        1  ",
      "    %        1 2",
      "    %        1  ",
      "    %        1  ",
      "    %11111/11111",
      "    %           ",
      "    %           ",
      "    %     ,     ",
      "    %      *    ",
      "    %           ",
      "    %           ",
      "    % + $       ",
      "    %           ",
      "    ((          ",
      "    ((%%%%%%%%%%"
    ],
    [
      "    !        .  ",
      "    %        1  ",
      "    %        1  ",
      "    %        1  ",
      "    %        1  ",
      "    %11111011111",
      "    %           ",
      "    %           ",
      "    %           ",
      "    %           ",
      "    %           ",
      "    !           ",
      "    !           ",
      "    %           ",
      "    ((          ",
      "    ((!!%%%!!%%!"
    ],
    [
      "    !        1  ",
      "    %        1  ",
      "    %        1  ",
      "    %        1  ",
      "    %        1  ",
      "    %11111111111",
      "    %           ",
      "    %           ",
      "    %           ",
      "    %           ",
      "    %           ",
      "    !           ",
      "    !           ",
      "    %           ",
      "    ((          ",
      "    ((!!%%%!!%%!"
    ],
    [
      "    %        1  ",
      "    %        1  ",
      "    %        1  ",
      "    %        1  ",
      "    %        1  ",
      "    %11111111111",
      "    %           ",
      "    %           ",
      "    %           ",
      "    %           ",
      "    %           ",
      "    %           ",
      "    %           ",
      "    %           ",
      "    ((          ",
      "    ((%%%%%%%%%%"
    ]
  ],
  "palette": {
    "palette": [
      {
        "char": "!",
        "block": "create:framed_glass"
      },
      {
        "char": "$",
        "block": "minecraft:barrel[facing=up,open=false]"
      },
      {
        "char": "%",
        "block": "minecraft:bricks"
      },
      {
        "char": "&",
        "block": "minecraft:coarse_dirt"
      },
      {
        "char": "'",
        "block": "minecraft:gravel"
      },
      {
        "char": "(",
        "block": "minecraft:mud_bricks"
      },
      {
        "char": ")",
        "block": "minecraft:oak_planks"
      },
      {
        "char": "*",
        "block": "minecraft:oak_stairs[facing=east,half=bottom,shape=straight,waterlogged=false]"
      },
      {
        "char": "+",
        "block": "kubejs:ruined_smoker[facing=north]"
      },
      {
        "char": ",",
        "block": "minecraft:spawner",
        "tag": {
          "id": "minecraft:mob_spawner",
          "Delay": 200,
          "MinSpawnDelay": 240,
          "MaxSpawnDelay": 720,
          "SpawnCount": 2,
          "MaxNearbyEntities": 6,
          "RequiredPlayerRange": 14,
          "SpawnRange": 4,
          "SpawnData": {
            "entity": {
              "id": "minecraft:zombie"
            }
          },
          "SpawnPotentials": [
            {
              "weight": 1,
              "data": {
                "entity": {
                  "id": "minecraft:zombie"
                }
              }
            }
          ]
        }
      },
      {
        "char": "-",
        "block": "minecraft:spruce_door[facing=east,half=lower,hinge=left,open=false,powered=false]"
      },
      {
        "char": ".",
        "block": "minecraft:spruce_door[facing=east,half=upper,hinge=left,open=false,powered=false]"
      },
      {
        "char": "/",
        "block": "minecraft:spruce_door[facing=south,half=lower,hinge=left,open=false,powered=false]"
      },
      {
        "char": "0",
        "block": "minecraft:spruce_door[facing=south,half=upper,hinge=left,open=false,powered=false]"
      },
      {
        "char": "1",
        "block": "minecraft:stripped_spruce_wood"
      },
      {
        "char": "2",
        "block": "kubejs:ruined_cauldron"
      },
      {
        "char": "3",
        "block": "tfmg:asphalt"
      }
    ]
  }
}
