{
  "xsize": 16,
  "zsize": 16,
  "slices": [
    [
      "       % (  )   ",
      "       % (      ",
      "       ! (      ",
      "       ! (      ",
      "       % (      ",
      "       % (      ",
      "       % (      ",
      "       % (      ",
      "       % (      ",
      "       % (      ",
      "       % ((   ( ",
      "       % (      ",
      "       % (      ",
      "       ! (      ",
      "       ! (      ",
      "       % (      "
    ],
    [
      "       % (      ",
      "       % (      ",
      "       % (      ",
      "       % (      ",
      "       % (      ",
      "       % (      ",
      "       % (      ",
      "       % (      ",
      "       % (      ",
      "       % (      ",
      "       % ((   ( ",
      "       % (      ",
      "       % (      ",
      "       % (      ",
      "       % (      ",
      "       % (      "
    ],
    [
      "       %        ",
      "       %        ",
      "       %        ",
      "       %        ",
      "       %        ",
      "       %        ",
      "       %        ",
      "       %        ",
      "       % (      ",
      "       % (      ",
      "       % ((   ( ",
      "       % (      ",
      "       % (      ",
      "       % (      ",
      "       % (      ",
      "       % (      "
    ],
    [
      "       %        ",
      "       %        ",
      "       %        ",
      "       %        ",
      "       %        ",
      "       %        ",
      "       %        ",
      "       %        ",
      "       %        ",
      "       %        ",
      "       %        ",
      "       %        ",
      "       %        ",
      "       %        ",
      "       %        ",
      "       %        "
    ],
    [
      "       &&&      ",
      "       &&&      ",
      "       &&&      ",
      "       &&&      ",
      "       &&&      ",
      "       &&&      ",
      "       &&&      ",
      "       &&&      ",
      "       &&&      ",
      "       &&&   &  ",
      "       &&&&   & ",
      "       &&&&&&&&&",
      "       &&&&&&&&&",
      "       &&&&&&&&&",
      "       &&&&&&&&&",
      "       &&&&&&&&&"
    ],
    [
      "       %        ",
      "       %        ",
      "       %        ",
      "       %        ",
      "       %        ",
      "       %        ",
      "       %        ",
      "       %        ",
      "       %        ",
      "       %        ",
      "       % (((((((",
      "       % (      ",
      "       % (      ",
      "       % (   $' ",
      "       % (      ",
      "       % (      "
    ]
  ],
  "palette": {
    "palette": [
      {
        "char": "!",
        "block": "create:framed_glass"
      },
      {
        "char": "$",
        "block": "minecraft:barrel[facing=up,open=false]"
      },
      {
        "char": "%",
        "block": "minecraft:mud_bricks"
      },
      {
        "char": "&",
        "block": "minecraft:oak_planks"
      },
      {
        "char": "'",
        "block": "minecraft:spawner",
        "tag": {
          "id": "minecraft:mob_spawner",
          "Delay": 200,
          "MinSpawnDelay": 240,
          "MaxSpawnDelay": 720,
          "SpawnCount": 2,
          "MaxNearbyEntities": 7,
          "RequiredPlayerRange": 14,
          "SpawnRange": 4,
          "SpawnData": {
            "entity": {
              "id": "the_wasteland_reworked:ghoul"
            }
          },
          "SpawnPotentials": [
            {
              "weight": 1,
              "data": {
                "entity": {
                  "id": "the_wasteland_reworked:ghoul"
                }
              }
            }
          ]
        }
      },
      {
        "char": "(",
        "block": "minecraft:stripped_oak_wood"
      },
      {
        "char": ")",
        "block": "minecraft:stripped_spruce_wood"
      }
    ]
  }
}
