{
  "xsize": 16,
  "zsize": 16,
  "slices": [
    [
      "444444&&&&&&&&&&",
      "444444&&&&&&&&&&",
      "444444&&&&&&&&&&",
      "444444&&&&&&&&&&",
      "44444--&44444444",
      "444--&4444444444",
      "4--&444444444444",
      "-&44444444444444",
      "4444444444444444",
      "44444444444444--",
      "444444444444--&4",
      "4444444444--&444",
      "44444444--&44444",
      "444444--&4444444",
      "4444--&444444444",
      "44--&44444444444"
    ],
    [
      "000000   .......",
      "000000  1       ",
      "000000          ",
      "000000          ",
      "0000000000000000",
      "0000000000000000",
      "0000000000000000",
      "0000000000000000",
      "0000000000000000",
      "0000000000000000",
      "0000000000000000",
      "0000000000000000",
      "0000000000000000",
      "0000000000000000",
      "0000000000000000",
      "0000000000000000"
    ],
    [
      "   2 /          ",
      "   2 /          ",
      "   2 /          ",
      "   2 /          ",
      "   2 ///////////",
      "3332            ",
      "   2            ",
      "   2            ",
      "   ' '          ",
      "   2            ",
      "   2   $$$$$    ",
      "   2   $$$$$    ",
      "   2   $$$$$    ",
      "   2   $$$$$    ",
      "   //           ",
      "%%%//%%%%%%%%)*%"
    ],
    [
      "   2 /          ",
      "   2 /          ",
      "   2 /          ",
      "   2 /          ",
      "   2 ///////////",
      "3332            ",
      "   2            ",
      "   2            ",
      "   ( (          ",
      "   2            ",
      "   2   $$$$$    ",
      "   2   $$$$$    ",
      "   2   $$$$$    ",
      "   2   $$$$$    ",
      "   //           ",
      "!%%//%%%%%%%%+,%"
    ],
    [
      "   2 /          ",
      "   2 /          ",
      "   2 /          ",
      "   2 /          ",
      "   2 ///////////",
      "3332            ",
      "   2            ",
      "   2            ",
      "   2            ",
      "   2            ",
      "   2            ",
      "   2            ",
      "   2            ",
      "   2            ",
      "   //           ",
      "!%%//%%%%%%%%%%%"
    ],
    [
      "   2 /          ",
      "   2 /          ",
      "   2 /          ",
      "   2 /          ",
      "   2 ///////////",
      "3332            ",
      "   2            ",
      "   2            ",
      "   2            ",
      "   2            ",
      "   2            ",
      "   2            ",
      "   2            ",
      "   2            ",
      "   //           ",
      "%%%//%%%%%%%%%%%"
    ]
  ],
  "palette": {
    "palette": [
      {
        "char": "!",
        "block": "create:framed_glass"
      },
      {
        "char": "$",
        "block": "minecraft:barrel[facing=up,open=false]"
      },
      {
        "char": "%",
        "block": "minecraft:bricks"
      },
      {
        "char": "&",
        "block": "minecraft:coarse_dirt"
      },
      {
        "char": "'",
        "block": "minecraft:dark_oak_door[facing=east,half=lower,hinge=left,open=false,powered=false]"
      },
      {
        "char": "(",
        "block": "minecraft:dark_oak_door[facing=east,half=upper,hinge=left,open=false,powered=false]"
      },
      {
        "char": ")",
        "block": "minecraft:dark_oak_door[facing=south,half=lower,hinge=left,open=false,powered=false]"
      },
      {
        "char": "*",
        "block": "minecraft:dark_oak_door[facing=south,half=lower,hinge=right,open=false,powered=false]"
      },
      {
        "char": "+",
        "block": "minecraft:dark_oak_door[facing=south,half=upper,hinge=left,open=false,powered=false]"
      },
      {
        "char": ",",
        "block": "minecraft:dark_oak_door[facing=south,half=upper,hinge=right,open=false,powered=false]"
      },
      {
        "char": "-",
        "block": "minecraft:gravel"
      },
      {
        "char": ".",
        "block": "minecraft:moss_block"
      },
      {
        "char": "/",
        "block": "minecraft:mud_bricks"
      },
      {
        "char": "0",
        "block": "minecraft:oak_planks"
      },
      {
        "char": "1",
        "block": "minecraft:oak_slab[type=bottom,waterlogged=false]"
      },
      {
        "char": "2",
        "block": "minecraft:stripped_oak_wood"
      },
      {
        "char": "3",
        "block": "minecraft:stripped_spruce_wood"
      },
      {
        "char": "4",
        "block": "tfmg:asphalt"
      }
    ]
  }
}
