{
  "xsize": 16,
  "zsize": 16,
  "slices": [
    [
      "7777777777777777",
      "7777777777777777",
      "7777777777777777",
      "7777777772222222",
      "7777777772222222",
      "7777777772222222",
      "77777777-2222222",
      "777777--&2222222",
      "7777--&777777777",
      "77--&77777777777",
      "--&7777777777777",
      "&777777777777777",
      "777777777777777-",
      "7777777777777--&",
      "77777777777--&77",
      "777777&&&&&&&&&&"
    ],
    [
      "                ",
      "                ",
      "        1       ",
      "                ",
      "                ",
      "////////////////",
      "////////////////",
      "////////////////",
      "////////////////",
      "////////////////",
      "////////////////",
      "////////////////",
      "////////////////",
      "////////////////",
      "////////////////",
      "//////          "
    ],
    [
      "                ",
      "                ",
      "        1       ",
      "                ",
      "3  ..           ",
      "%%%..%%%%%%%%)*%",
      "   ..    0      ",
      "   5   $$$$$    ",
      "   5   $$$$$    ",
      "   5   $$$$$    ",
      "   5   $$$$$    ",
      "   5            ",
      "   ' '          ",
      "   5            ",
      "   5 ...........",
      "   5 .          "
    ],
    [
      "                ",
      "                ",
      "        1       ",
      "                ",
      "   ..           ",
      "!6%..%%%%%%%%+,%",
      "   ..           ",
      "   5   $$0$$    ",
      "   5   $$$$$    ",
      "   5   $$$$$    ",
      "   5   $$$$$    ",
      "   5            ",
      "   ( (          ",
      "   5            ",
      "   5 ...........",
      "   5 .          "
    ],
    [
      "                ",
      "                ",
      "        1       ",
      "                ",
      "   ..           ",
      "!6%..%%%%%%%%%%%",
      "   ..           ",
      "   5   $$ $$    ",
      "   5   $$0$$    ",
      "   5   $$$$$    ",
      "   5   $$$$$    ",
      "   5            ",
      "   5            ",
      "   5            ",
      "   5 ...........",
      "   5 .          "
    ],
    [
      "                ",
      "                ",
      "        1       ",
      "                ",
      "4  ..           ",
      "%%%..%%%%%%%%%%%",
      "   ..           ",
      "   5            ",
      "   5            ",
      "   5     0      ",
      "   5            ",
      "   5            ",
      "   5            ",
      "   5            ",
      "   5 ...........",
      "   5 .          "
    ]
  ],
  "palette": {
    "palette": [
      {
        "char": "!",
        "block": "create:framed_glass"
      },
      {
        "char": "$",
        "block": "minecraft:bookshelf"
      },
      {
        "char": "%",
        "block": "minecraft:bricks"
      },
      {
        "char": "&",
        "block": "minecraft:coarse_dirt"
      },
      {
        "char": "'",
        "block": "minecraft:dark_oak_door[facing=east,half=lower,hinge=left,open=false,powered=false]"
      },
      {
        "char": "(",
        "block": "minecraft:dark_oak_door[facing=east,half=upper,hinge=left,open=false,powered=false]"
      },
      {
        "char": ")",
        "block": "minecraft:dark_oak_door[facing=north,half=lower,hinge=left,open=false,powered=false]"
      },
      {
        "char": "*",
        "block": "minecraft:dark_oak_door[facing=north,half=lower,hinge=right,open=false,powered=false]"
      },
      {
        "char": "+",
        "block": "minecraft:dark_oak_door[facing=north,half=upper,hinge=left,open=false,powered=false]"
      },
      {
        "char": ",",
        "block": "minecraft:dark_oak_door[facing=north,half=upper,hinge=right,open=false,powered=false]"
      },
      {
        "char": "-",
        "block": "minecraft:gravel"
      },
      {
        "char": ".",
        "block": "minecraft:mud_bricks"
      },
      {
        "char": "/",
        "block": "minecraft:oak_planks"
      },
      {
        "char": "0",
        "block": "minecraft:oak_stairs[facing=south,half=bottom,shape=straight,waterlogged=false]"
      },
      {
        "char": "1",
        "block": "minecraft:polished_deepslate"
      },
      {
        "char": "2",
        "block": "minecraft:smooth_stone"
      },
      {
        "char": "3",
        "block": "minecraft:spruce_slab[type=bottom,waterlogged=false]"
      },
      {
        "char": "4",
        "block": "minecraft:spruce_slab[type=top,waterlogged=false]"
      },
      {
        "char": "5",
        "block": "minecraft:stripped_oak_wood"
      },
      {
        "char": "6",
        "block": "minecraft:stripped_spruce_log[axis=y]"
      },
      {
        "char": "7",
        "block": "tfmg:asphalt"
      }
    ]
  }
}
