{
  "xsize": 16,
  "zsize": 16,
  "slices": [
    [
      "3333333333333333",
      "3333333333333333",
      "3333333333333333",
      "....333333333333",
      "....333333333333",
      "....333333333))&",
      "....3333333))&33",
      "....33333))&3333",
      "3333333))&333333",
      "33333))&33333333",
      "333))&3333333333",
      "3))&333333333333",
      ")&33333333333333",
      "3333333333333333",
      "33333333333333))",
      "&&&&&&&33333))&3"
    ],
    [
      "                ",
      "                ",
      "    -           ",
      "                ",
      "                ",
      "++++++++++++++++",
      "++++++++++++++++",
      "++++++++++++++++",
      "++++++++++++++++",
      "++++++++++++++++",
      "++++++++++++++++",
      "++++++++++++++++",
      "++++++++++++++++",
      "++++++++++++++++",
      "++++++++++++++++",
      "       +++++++++"
    ],
    [
      "                ",
      "                ",
      "    -           ",
      "                ",
      "         **//   ",
      "$$$$$$$$$**$$$$$",
      "         **     ",
      "         1      ",
      " %       1      ",
      "         1      ",
      "         1      ",
      "         1     ,",
      "       ' '      ",
      "         1      ",
      "******** 1      ",
      "       * 1      "
    ],
    [
      "                ",
      "                ",
      "    -           ",
      "                ",
      "         **     ",
      "$$$$$$$$$**!!2$2",
      "         **     ",
      "         1      ",
      "         1      ",
      "         1      ",
      "         1      ",
      "         1      ",
      "       ( (      ",
      "         1      ",
      "******** 1      ",
      "       * 1      "
    ],
    [
      "                ",
      "                ",
      "    -           ",
      "                ",
      "         **     ",
      "$$$$$$$$$**!!2$2",
      "         **     ",
      "         1      ",
      "         1      ",
      "         1      ",
      "         1      ",
      "         1      ",
      "         1      ",
      "         1      ",
      "******** 1      ",
      "       * 1      "
    ],
    [
      "                ",
      "                ",
      "    -           ",
      "                ",
      "         **00   ",
      "$$$$$$$$$**$$$$$",
      "         **     ",
      "         1      ",
      "         1      ",
      "         1      ",
      "         1      ",
      "         1      ",
      "         1      ",
      "         1      ",
      "******** 1      ",
      "       * 1      "
    ]
  ],
  "palette": {
    "palette": [
      {
        "char": "!",
        "block": "create:framed_glass"
      },
      {
        "char": "$",
        "block": "minecraft:bricks"
      },
      {
        "char": "%",
        "block": "minecraft:cartography_table"
      },
      {
        "char": "&",
        "block": "minecraft:coarse_dirt"
      },
      {
        "char": "'",
        "block": "minecraft:dark_oak_door[facing=west,half=lower,hinge=left,open=false,powered=false]"
      },
      {
        "char": "(",
        "block": "minecraft:dark_oak_door[facing=west,half=upper,hinge=left,open=false,powered=false]"
      },
      {
        "char": ")",
        "block": "minecraft:gravel"
      },
      {
        "char": "*",
        "block": "minecraft:mud_bricks"
      },
      {
        "char": "+",
        "block": "minecraft:oak_planks"
      },
      {
        "char": ",",
        "block": "minecraft:oak_stairs[facing=west,half=bottom,shape=straight,waterlogged=false]"
      },
      {
        "char": "-",
        "block": "minecraft:polished_deepslate"
      },
      {
        "char": ".",
        "block": "minecraft:smooth_stone"
      },
      {
        "char": "/",
        "block": "minecraft:spruce_slab[type=bottom,waterlogged=false]"
      },
      {
        "char": "0",
        "block": "minecraft:spruce_slab[type=top,waterlogged=false]"
      },
      {
        "char": "1",
        "block": "minecraft:stripped_oak_wood"
      },
      {
        "char": "2",
        "block": "minecraft:stripped_spruce_log[axis=y]"
      },
      {
        "char": "3",
        "block": "tfmg:asphalt"
      }
    ]
  }
}
