{
  "xsize": 16,
  "zsize": 16,
  "slices": [
    [
      "                ",
      "                ",
      "                ",
      "                ",
      "         &&     ",
      "$$$$$$$$$&&!!-$-",
      "         &&     ",
      "         ,      ",
      "         ,      ",
      "         ,      ",
      "         ,      ",
      "         ,      ",
      "         ,      ",
      "         ,      ",
      "&&&&&&&& ,      ",
      "       & ,      "
    ],
    [
      "                ",
      "                ",
      "                ",
      "                ",
      "         &&++   ",
      "$$$$$$$$$&&$$$$$",
      "         &&     ",
      "         ,      ",
      "         ,      ",
      "         ,      ",
      "         ,      ",
      "         ,      ",
      "         ,      ",
      "         ,      ",
      "&&&&&&&& ,      ",
      "       & ,      "
    ],
    [
      "                ",
      "                ",
      "                ",
      "                ",
      "         &&     ",
      "$$$$$$$$$&&$$$$$",
      "         &&     ",
      "         ,      ",
      "         ,      ",
      "         ,      ",
      "         ,      ",
      "         ,      ",
      "         ,      ",
      "         ,      ",
      "&&&&&&&& ,      ",
      "       & ,      "
    ],
    [
      "                ",
      "                ",
      "                ",
      "                ",
      "         &&     ",
      "$$$$$$$$$&&$$$$$",
      "         &&     ",
      "                ",
      "                ",
      "                ",
      "                ",
      "                ",
      "                ",
      "                ",
      "&&&&&&&&        ",
      "       &        "
    ],
    [
      "                ",
      "                ",
      "                ",
      "                ",
      ")))))))))&&)))))",
      ")))))))))&&)))))",
      "'''''''''&&'''''",
      "''''''''''''''''",
      "''''''''''''''''",
      "''''''''''''''''",
      "''''''''''''''''",
      "''''''''''''''''",
      "''''''''''''''''",
      "''''''''''''''''",
      "''''''''''''''''",
      "       '''''''''"
    ],
    [
      "                ",
      "                ",
      "                ",
      "                ",
      "         &&**   ",
      "$$$$$$$$$&&$$$$$",
      "         &&     ",
      "''''''   ,      ",
      "''''''   ,      ",
      "''''''   ,      ",
      "''''''   ,      ",
      "''''''   ,     (",
      "'''''' % %      ",
      "''''''   ,      ",
      "&&&&&&&& ,      ",
      "       & ,      "
    ]
  ],
  "palette": {
    "palette": [
      {
        "char": "!",
        "block": "create:framed_glass"
      },
      {
        "char": "$",
        "block": "minecraft:bricks"
      },
      {
        "char": "%",
        "block": "minecraft:dark_oak_door[facing=west,half=lower,hinge=left,open=false,powered=false]"
      },
      {
        "char": "&",
        "block": "minecraft:mud_bricks"
      },
      {
        "char": "'",
        "block": "minecraft:oak_planks"
      },
      {
        "char": "(",
        "block": "minecraft:oak_stairs[facing=west,half=bottom,shape=straight,waterlogged=false]"
      },
      {
        "char": ")",
        "block": "minecraft:smooth_stone_slab[type=top,waterlogged=false]"
      },
      {
        "char": "*",
        "block": "minecraft:spruce_slab[type=bottom,waterlogged=false]"
      },
      {
        "char": "+",
        "block": "minecraft:spruce_slab[type=top,waterlogged=false]"
      },
      {
        "char": ",",
        "block": "minecraft:stripped_oak_wood"
      },
      {
        "char": "-",
        "block": "minecraft:stripped_spruce_log[axis=y]"
      }
    ]
  }
}
