{
  "xsize": 16,
  "zsize": 16,
  "slices": [
    [
      "%%%%%%%///''%///",
      "%%%%%%%/''%/////",
      "%%%%%%%'%///////",
      "%%%%%%%/////////",
      "%%%%%%%/////////",
      "%%%%%%%/////////",
      "%%%%%%%/////////",
      "%%%%%%%////////'",
      "%%%%%%%//////''%",
      "%%%%%%%////''%//",
      "%%%%%%%//''%////",
      "%%%%%%%''%//////",
      "%%%%%%%%////////",
      "%%%%%%%/////////",
      "%%%%%%%/////////",
      "%%%%%%%/////////"
    ],
    [
      "       *********",
      "    +  *********",
      "((((   *********",
      "((((   *********",
      "((((   *********",
      "((((   *********",
      "((((   *********",
      "((((   *********",
      "((((   *********",
      "((((   *********",
      "((((   *********",
      "((((   *********",
      "((((   *********",
      "((((   *********",
      "((((   *********",
      "((((   *********"
    ],
    [
      "       ) ,------",
      "       ) ,      ",
      "       ) ,      ",
      "       ) , .    ",
      "  &    ) ,      ",
      "       ) ,      ",
      "       ) ,      ",
      "       ) ,   $  ",
      "       ) ,      ",
      "       ) ,      ",
      "       ) ,,,,,,,",
      "       ) ,      ",
      "       ) ,      ",
      "       ) ,   $  ",
      "  &    ) ,      ",
      "       ) ,      "
    ],
    [
      "       ) ,------",
      "       ) ,      ",
      "       ! ,      ",
      "       ! ,      ",
      "       ) ,      ",
      "       ) ,      ",
      "       ) ,      ",
      "       ) ,      ",
      "       ) ,      ",
      "       ) ,      ",
      "       ) ,,,,,,,",
      "       ) ,      ",
      "       ) ,      ",
      "       ! ,      ",
      "       ! ,      ",
      "       ) ,      "
    ],
    [
      "       ) ,------",
      "       ) ,      ",
      "       ! ,      ",
      "       ! ,      ",
      "       ) ,      ",
      "       ) ,      ",
      "       ) ,      ",
      "       ) ,      ",
      "       ) ,      ",
      "       ) ,      ",
      "       ) ,,,,,,,",
      "       ) ,      ",
      "       ) ,      ",
      "       ! ,      ",
      "       ! ,      ",
      "       ) ,      "
    ],
    [
      "       ) ,------",
      "       ) ,      ",
      "       ) ,      ",
      "       ) ,      ",
      "       ) ,      ",
      "       ) ,      ",
      "       ) ,      ",
      "       ) ,      ",
      "       ) ,      ",
      "       ) ,      ",
      "       ) ,,,,,,,",
      "       ) ,      ",
      "       ) ,      ",
      "       ) ,      ",
      "       ) ,      ",
      "       ) ,      "
    ]
  ],
  "palette": {
    "palette": [
      {
        "char": "!",
        "block": "create:framed_glass"
      },
      {
        "char": "$",
        "block": "minecraft:barrel[facing=up,open=false]"
      },
      {
        "char": "%",
        "block": "minecraft:coarse_dirt"
      },
      {
        "char": "&",
        "block": "minecraft:flower_pot"
      },
      {
        "char": "'",
        "block": "minecraft:gravel"
      },
      {
        "char": "(",
        "block": "minecraft:moss_block"
      },
      {
        "char": ")",
        "block": "minecraft:mud_bricks"
      },
      {
        "char": "*",
        "block": "minecraft:oak_planks"
      },
      {
        "char": "+",
        "block": "minecraft:oak_slab[type=bottom,waterlogged=false]"
      },
      {
        "char": ",",
        "block": "minecraft:stripped_oak_wood"
      },
      {
        "char": "-",
        "block": "minecraft:stripped_spruce_wood"
      },
      {
        "char": ".",
        "block": "kubejs:ruined_cauldron"
      },
      {
        "char": "/",
        "block": "tfmg:asphalt"
      }
    ]
  }
}
