{
  "xsize": 16,
  "zsize": 16,
  "slices": [
    [
      "2222222222222   ",
      "22222222222&&   ",
      "222222222&&%2   ",
      "2222222&&%222   ",
      "22222&&%22222   ",
      "222&&%2222222   ",
      "2&&%222222222   ",
      "&%22222222222   ",
      "2222222222222   ",
      "2222222222222   ",
      "222222222222&   ",
      "2222222222&&%   ",
      "22222222&&%22   ",
      "222222&&%2222   ",
      "2222&&%222222   ",
      "22&&%22222222   "
    ],
    [
      ")))))))))       ",
      ")))))))))       ",
      ")))))))))       ",
      ")))))))))       ",
      ")))))))))       ",
      ")))))))))       ",
      ")))))))))       ",
      ")))))))))       ",
      ")))))))))       ",
      ")))))))))       ",
      ")))))))))       ",
      ")))))))))       ",
      ")))))))))       ",
      ")))))))))       ",
      ")))))))))       ",
      ")))))))))       "
    ],
    [
      "11.11111$       ",
      " 1      $       ",
      " 1      $       ",
      " 1      $       ",
      " 1  '   $       ",
      " ,  (   $       ",
      " 1      $       ",
      " 1      $       ",
      " 1      $       ",
      " 1      $       ",
      "00000000$       ",
      " 1      $       ",
      " 1      $       ",
      " 1  +   $       ",
      " 1  *   $       ",
      " 1      $       "
    ],
    [
      "11/11111$       ",
      " 1      $       ",
      " 1      $       ",
      " 1      $       ",
      " 1      !       ",
      " -      !       ",
      " 1      $       ",
      " 1      $       ",
      " 1      $       ",
      " 1      $       ",
      "00000000$       ",
      " 1      $       ",
      " 1      $       ",
      " 1      $       ",
      " 1      $       ",
      " 1      !       "
    ],
    [
      "11111111$       ",
      " 1      $       ",
      " 1      $       ",
      " 1      $       ",
      " 1      !       ",
      " 1      !       ",
      " 1      $       ",
      " 1      $       ",
      " 1      $       ",
      " 1      $       ",
      "00000000$       ",
      " 1      $       ",
      " 1      $       ",
      " 1      $       ",
      " 1      $       ",
      " 1      !       "
    ],
    [
      "11111111$       ",
      " 1      $       ",
      " 1      $       ",
      " 1      $       ",
      " 1      $       ",
      " 1      $       ",
      " 1      $       ",
      " 1      $       ",
      " 1      $       ",
      " 1      $       ",
      "00000000$       ",
      " 1      $       ",
      " 1      $       ",
      " 1      $       ",
      " 1      $       ",
      " 1      $       "
    ]
  ],
  "palette": {
    "palette": [
      {
        "char": "!",
        "block": "create:framed_glass"
      },
      {
        "char": "$",
        "block": "minecraft:bricks"
      },
      {
        "char": "%",
        "block": "minecraft:coarse_dirt"
      },
      {
        "char": "&",
        "block": "minecraft:gravel"
      },
      {
        "char": "'",
        "block": "minecraft:green_bed[facing=south,occupied=false,part=foot]"
      },
      {
        "char": "(",
        "block": "minecraft:green_bed[facing=south,occupied=false,part=head]"
      },
      {
        "char": ")",
        "block": "minecraft:oak_planks"
      },
      {
        "char": "*",
        "block": "minecraft:red_bed[facing=north,occupied=false,part=foot]"
      },
      {
        "char": "+",
        "block": "minecraft:red_bed[facing=north,occupied=false,part=head]"
      },
      {
        "char": ",",
        "block": "minecraft:spruce_door[facing=east,half=lower,hinge=left,open=false,powered=false]"
      },
      {
        "char": "-",
        "block": "minecraft:spruce_door[facing=east,half=upper,hinge=left,open=false,powered=false]"
      },
      {
        "char": ".",
        "block": "minecraft:spruce_door[facing=south,half=lower,hinge=left,open=false,powered=false]"
      },
      {
        "char": "/",
        "block": "minecraft:spruce_door[facing=south,half=upper,hinge=left,open=false,powered=false]"
      },
      {
        "char": "0",
        "block": "minecraft:stripped_oak_wood"
      },
      {
        "char": "1",
        "block": "minecraft:stripped_spruce_wood"
      },
      {
        "char": "2",
        "block": "tfmg:asphalt"
      }
    ]
  }
}
