{
  "xsize": 16,
  "zsize": 16,
  "slices": [
    [
      "    $11111111111",
      "    $        1  ",
      "    $        1  ",
      "    $        1  ",
      "    $        1  ",
      "    $        1  ",
      "    $        1  ",
      "    $        1  ",
      "    $        1  ",
      "    $        1  ",
      "    $00000000000",
      "    $        1  ",
      "    $        1  ",
      "    $        1  ",
      "    $        1  ",
      "    $        1  "
    ],
    [
      "    $           ",
      "    $           ",
      "    $           ",
      "    $           ",
      "    $           ",
      "    $           ",
      "    $           ",
      "    $           ",
      "    $           ",
      "    $           ",
      "    $00000000000",
      "    $           ",
      "    $           ",
      "    $           ",
      "    $           ",
      "    $           "
    ],
    [
      "    $           ",
      "    $           ",
      "    $           ",
      "    $           ",
      "    $           ",
      "    $           ",
      "    $           ",
      "    $           ",
      "    $           ",
      "    $           ",
      "    $           ",
      "    $           ",
      "    $           ",
      "    $           ",
      "    $           ",
      "    $           "
    ],
    [
      "   **)))))))))))",
      "   **)))))))))))",
      "   **)))))))))))",
      "   **)))))))))))",
      "   **)))))))))))",
      "   **)))))))))))",
      "   **)))))))))))",
      "   **)))))))))))",
      "   **)))))))))))",
      "   **)))))))))))",
      "   **)))))))))))",
      "   **)))))))))))",
      "   **)))))))))))",
      "   **)))))))))))",
      "   **)))))))))))",
      "   **)))))))))))"
    ],
    [
      "    $11111.11111",
      "    $        1  ",
      "    $        1  ",
      "    $        1 2",
      "    $  %    +1  ",
      "    $  &     ,  ",
      "    $        1  ",
      "    $        1  ",
      "    $        1  ",
      "    $        1  ",
      "    $00000000000",
      "    $        1  ",
      "    $        1  ",
      "    $  (     1  ",
      "    $  '     1  ",
      "    $        1  "
    ],
    [
      "    $11111/11111",
      "    $        1  ",
      "    $        1  ",
      "    $        1  ",
      "    !        1  ",
      "    !        -  ",
      "    $        1  ",
      "    $        1  ",
      "    $        1  ",
      "    $        1  ",
      "    $00000000000",
      "    $        1  ",
      "    $        1  ",
      "    $        1  ",
      "    $        1  ",
      "    !        1  "
    ]
  ],
  "palette": {
    "palette": [
      {
        "char": "!",
        "block": "create:framed_glass"
      },
      {
        "char": "$",
        "block": "minecraft:bricks"
      },
      {
        "char": "%",
        "block": "minecraft:brown_bed[facing=south,occupied=false,part=foot]"
      },
      {
        "char": "&",
        "block": "minecraft:brown_bed[facing=south,occupied=false,part=head]"
      },
      {
        "char": "'",
        "block": "minecraft:gray_bed[facing=north,occupied=false,part=foot]"
      },
      {
        "char": "(",
        "block": "minecraft:gray_bed[facing=north,occupied=false,part=head]"
      },
      {
        "char": ")",
        "block": "minecraft:oak_planks"
      },
      {
        "char": "*",
        "block": "minecraft:smooth_stone_slab[type=top,waterlogged=false]"
      },
      {
        "char": "+",
        "block": "minecraft:spawner",
        "tag": {
          "id": "minecraft:mob_spawner",
          "Delay": 200,
          "MinSpawnDelay": 240,
          "MaxSpawnDelay": 720,
          "SpawnCount": 2,
          "MaxNearbyEntities": 6,
          "RequiredPlayerRange": 14,
          "SpawnRange": 4,
          "SpawnData": {
            "entity": {
              "id": "the_wasteland_reworked:ghoul"
            }
          },
          "SpawnPotentials": [
            {
              "weight": 1,
              "data": {
                "entity": {
                  "id": "the_wasteland_reworked:ghoul"
                }
              }
            }
          ]
        }
      },
      {
        "char": ",",
        "block": "minecraft:spruce_door[facing=east,half=lower,hinge=left,open=false,powered=false]"
      },
      {
        "char": "-",
        "block": "minecraft:spruce_door[facing=east,half=upper,hinge=left,open=false,powered=false]"
      },
      {
        "char": ".",
        "block": "minecraft:spruce_door[facing=south,half=lower,hinge=left,open=false,powered=false]"
      },
      {
        "char": "/",
        "block": "minecraft:spruce_door[facing=south,half=upper,hinge=left,open=false,powered=false]"
      },
      {
        "char": "0",
        "block": "minecraft:stripped_oak_wood"
      },
      {
        "char": "1",
        "block": "minecraft:stripped_spruce_wood"
      },
      {
        "char": "2",
        "block": "minecraft:water_cauldron[level=3]"
      }
    ]
  }
}
