{
  "xsize": 16,
  "zsize": 16,
  "slices": [
    [
      "        %%%%%%  ",
      "        %%%%%%  ",
      "        %%%%%%  ",
      "        %%%%%%  ",
      "        %%%%%%  ",
      "                ",
      "$$$$$!!$$$$$$$$$",
      "                ",
      "                ",
      "                ",
      "                ",
      "                ",
      "                ",
      "                ",
      "                ",
      "                "
    ],
    [
      "        %%%%%%  ",
      "        %%%%%%  ",
      "        %%%%%%  ",
      "        %%%%%%  ",
      "        %%%%%%  ",
      "                ",
      "$$$$$$$$$$$$$$$$",
      "                ",
      "                ",
      "                ",
      "                ",
      "                ",
      "                ",
      "                ",
      "                ",
      "                "
    ],
    [
      "        %%%%%%  ",
      "        %%%%%%  ",
      "        %%%%%%  ",
      "        %%%%%%  ",
      "        %%%%%%  ",
      "                ",
      "$$$$$$$$$$$$$$$$",
      "                ",
      "                ",
      "                ",
      "                ",
      "                ",
      "                ",
      "                ",
      "                ",
      "                "
    ],
    [
      "((((((((%%%%%%((",
      "((((((((%%%%%%((",
      "((((((((%%%%%%((",
      "((((((((%%%%%%((",
      "((((((((%%%%%%((",
      "((((((((((((((((",
      "$$$$$$$$$$$$$$$$",
      "                ",
      "                ",
      "                ",
      "                ",
      "                ",
      "                ",
      "                ",
      "                ",
      "                "
    ],
    [
      "        %%%%%%  ",
      "        %%%%%%  ",
      "        %%%%%%  ",
      "        %%%%%%  ",
      "&     )*%%%%%% )",
      "               '",
      "$$$$$$$$$$$$$$$'",
      "               '",
      "               '",
      "                ",
      "                ",
      "                ",
      "                ",
      "                ",
      "                ",
      "                "
    ],
    [
      "        %%%%%%  ",
      "        %%%%%%  ",
      "        %%%%%%  ",
      "        %%%%%%  ",
      "        %%%%%%  ",
      "                ",
      "$$$$$$$$$$$$$$$$",
      "                ",
      "                ",
      "                ",
      "                ",
      "                ",
      "                ",
      "                ",
      "                ",
      "                "
    ]
  ],
  "palette": {
    "palette": [
      {
        "char": "!",
        "block": "create:framed_glass"
      },
      {
        "char": "$",
        "block": "minecraft:light_gray_concrete"
      },
      {
        "char": "%",
        "block": "minecraft:polished_blackstone_bricks"
      },
      {
        "char": "&",
        "block": "minecraft:quartz_stairs[facing=west,half=bottom,shape=straight,waterlogged=false]"
      },
      {
        "char": "'",
        "block": "minecraft:smooth_stone_slab[type=bottom,waterlogged=false]"
      },
      {
        "char": "(",
        "block": "minecraft:spruce_planks"
      },
      {
        "char": ")",
        "block": "minecraft:spruce_stairs[facing=north,half=bottom,shape=straight,waterlogged=false]"
      },
      {
        "char": "*",
        "block": "kubejs:ruined_cauldron"
      }
    ]
  }
}
