{
  "xsize": 16,
  "zsize": 16,
  "slices": [
    [
      "4444444444444444",
      "4444444444444444",
      "4444444444444444",
      "4444444444444444",
      "4444444444444444",
      "4444444444444444",
      "44444**%44444444",
      "444**%4444444444",
      "4**%444444444444",
      "*%44444444444444",
      "4444444444444444",
      "44444444444444**",
      "444444444444**%4",
      "4444444444**%444",
      "44444444**%44444",
      "444444**%4444444"
    ],
    [
      "                ",
      "                ",
      " 3     3     3  ",
      "                ",
      "         -      ",
      "                ",
      "    ,,,,,,,,,,,,",
      "    ,,,,,,,,,,,,",
      "    ,,,,,,,,,,,,",
      "    ,,,,,,,,,,,,",
      "    ,,,,,,,,,,,,",
      "    ,,,,,,,,,,,,",
      "    ,,,,,,,,,,,,",
      "    ,,,,,,,,,,,,",
      "    ,,,,,,,,,,,,",
      "    ,,,,,,,,,,,,"
    ],
    [
      "                ",
      "                ",
      "                ",
      "                ",
      "         -      ",
      "                ",
      "    ++++++++&'++",
      "    +           ",
      "    + 00        ",
      "    + 1         ",
      "    +           ",
      "    +5555555..55",
      "    +         5 ",
      "    +         5 ",
      "    + $$$$$   5 ",
      "    + $$$$$   5 "
    ],
    [
      "                ",
      "                ",
      "                ",
      "                ",
      "         -      ",
      "      000   000 ",
      "    ++++++++()++",
      "    +           ",
      "    +           ",
      "    +           ",
      "    +           ",
      "    +5555555//55",
      "    +         5 ",
      "    +         5 ",
      "    + $$$$$   5 ",
      "    + $$$$$   5 "
    ],
    [
      "                ",
      "                ",
      "                ",
      "                ",
      "         -      ",
      "                ",
      "    +2!!!2+2!!!2",
      "    +           ",
      "    +           ",
      "    +           ",
      "    +           ",
      "    +55555555555",
      "    +         5 ",
      "    +         5 ",
      "    +         5 ",
      "    +         5 "
    ],
    [
      "                ",
      "                ",
      "                ",
      "                ",
      "         -      ",
      "                ",
      "    +2!!!2+2!!!2",
      "    +           ",
      "    +           ",
      "    +           ",
      "    +           ",
      "    +55555555555",
      "    +         5 ",
      "    +         5 ",
      "    +         5 ",
      "    +         5 "
    ]
  ],
  "palette": {
    "palette": [
      {
        "char": "!",
        "block": "create:framed_glass"
      },
      {
        "char": "$",
        "block": "immersiveengineering:crate"
      },
      {
        "char": "%",
        "block": "minecraft:coarse_dirt"
      },
      {
        "char": "&",
        "block": "minecraft:dark_oak_door[facing=north,half=lower,hinge=left,open=false,powered=false]"
      },
      {
        "char": "'",
        "block": "minecraft:dark_oak_door[facing=north,half=lower,hinge=right,open=false,powered=false]"
      },
      {
        "char": "(",
        "block": "minecraft:dark_oak_door[facing=north,half=upper,hinge=left,open=false,powered=false]"
      },
      {
        "char": ")",
        "block": "minecraft:dark_oak_door[facing=north,half=upper,hinge=right,open=false,powered=false]"
      },
      {
        "char": "*",
        "block": "minecraft:gravel"
      },
      {
        "char": "+",
        "block": "minecraft:mud_bricks"
      },
      {
        "char": ",",
        "block": "minecraft:polished_andesite"
      },
      {
        "char": "-",
        "block": "minecraft:polished_deepslate"
      },
      {
        "char": ".",
        "block": "minecraft:spruce_door[facing=south,half=lower,hinge=left,open=false,powered=false]"
      },
      {
        "char": "/",
        "block": "minecraft:spruce_door[facing=south,half=upper,hinge=left,open=false,powered=false]"
      },
      {
        "char": "0",
        "block": "minecraft:spruce_slab[type=bottom,waterlogged=false]"
      },
      {
        "char": "1",
        "block": "minecraft:spruce_stairs[facing=north,half=bottom,shape=straight,waterlogged=false]"
      },
      {
        "char": "2",
        "block": "minecraft:stripped_spruce_log[axis=y]"
      },
      {
        "char": "3",
        "block": "minecraft:white_concrete"
      },
      {
        "char": "4",
        "block": "tfmg:asphalt"
      },
      {
        "char": "5",
        "block": "tfmg:cinder_block"
      }
    ]
  }
}
