{
  "xsize": 16,
  "zsize": 16,
  "slices": [
    [
      "                ",
      "                ",
      "                ",
      "                ",
      "                ",
      "                ",
      "                ",
      "                ",
      "                ",
      "                ",
      "                ",
      "                ",
      "                ",
      "                ",
      "                ",
      "        &&&&&&  "
    ],
    [
      "                ",
      "                ",
      "                ",
      "                ",
      "                ",
      "                ",
      "                ",
      "                ",
      "                ",
      "                ",
      "                ",
      "                ",
      "                ",
      "                ",
      "                ",
      "        &&&&&&  "
    ],
    [
      ",,,,,,,,,,,,,   ",
      ",,,,,,,,,,,,,   ",
      ",,,,,,,,,,,,,   ",
      ",,,,,,,,,,,,,   ",
      ",,,,,,,,,,,,,   ",
      ",,,,,,,,,,,,,   ",
      ",,,,,,,,,,,,,   ",
      ",,,,,,,,,,,,,   ",
      ",,,,,,,,,,,,,   ",
      ",,,,,,,,,,,,,   ",
      ",,,,,,,,,,,,,   ",
      "   ,,,,,,,,,,   ",
      "   ,,,,,,,,,,   ",
      "   ,,,,,,,,,,   ",
      "   ,,,,,,,,,,   ",
      "   ,,,,,&&&&&   "
    ],
    [
      "                ",
      "                ",
      "                ",
      "                ",
      "                ",
      "                ",
      "'     -.'       ",
      "                ",
      "      *         ",
      "                ",
      "                ",
      "      (         ",
      "     %          ",
      "     $  !       ",
      "                ",
      "        &&&&&   "
    ],
    [
      "                ",
      "                ",
      "                ",
      "                ",
      "                ",
      "                ",
      "                ",
      "                ",
      "      +         ",
      "                ",
      "                ",
      "      )         ",
      "                ",
      "       /        ",
      "                ",
      "        &&&&&   "
    ],
    [
      "                ",
      "                ",
      "                ",
      "                ",
      "                ",
      "                ",
      "                ",
      "                ",
      "                ",
      "                ",
      "                ",
      "                ",
      "                ",
      "                ",
      "                ",
      "        &&&&&   "
    ]
  ],
  "palette": {
    "palette": [
      {
        "char": "!",
        "block": "minecraft:barrel[facing=up,open=false]"
      },
      {
        "char": "$",
        "block": "minecraft:brown_bed[facing=north,occupied=false,part=foot]"
      },
      {
        "char": "%",
        "block": "minecraft:brown_bed[facing=north,occupied=false,part=head]"
      },
      {
        "char": "&",
        "block": "minecraft:polished_blackstone_bricks"
      },
      {
        "char": "'",
        "block": "minecraft:quartz_stairs[facing=west,half=bottom,shape=straight,waterlogged=false]"
      },
      {
        "char": "(",
        "block": "minecraft:spruce_door[facing=north,half=lower,hinge=left,open=false,powered=false]"
      },
      {
        "char": ")",
        "block": "minecraft:spruce_door[facing=north,half=upper,hinge=left,open=false,powered=false]"
      },
      {
        "char": "*",
        "block": "minecraft:spruce_door[facing=south,half=lower,hinge=left,open=false,powered=false]"
      },
      {
        "char": "+",
        "block": "minecraft:spruce_door[facing=south,half=upper,hinge=left,open=false,powered=false]"
      },
      {
        "char": ",",
        "block": "minecraft:spruce_planks"
      },
      {
        "char": "-",
        "block": "minecraft:spruce_stairs[facing=north,half=bottom,shape=straight,waterlogged=false]"
      },
      {
        "char": ".",
        "block": "kubejs:ruined_cauldron"
      },
      {
        "char": "/",
        "block": "supplementaries:item_shelf"
      }
    ]
  }
}
