{
  "xsize": 16,
  "zsize": 16,
  "slices": [
    [
      " 000000000000000",
      "--0000-0000-0000",
      "0000000000000000",
      "0000000000000000",
      "0000000000000000",
      "0000000000000000",
      "0000000000000000",
      "000000--$0000000",
      "0000--$000000000",
      "00--$00000000000",
      "--$0000000000000",
      "$000000000000000",
      "000000000000000-",
      "0000000000000--$",
      "00000000000--$00",
      "000000000--$0000"
    ],
    [
      "                ",
      "                ",
      "                ",
      "                ",
      " ...............",
      " ...............",
      " ...............",
      "................",
      "................",
      "................",
      "................",
      "................",
      "................",
      "................",
      "................",
      "................"
    ],
    [
      "                ",
      "                ",
      "                ",
      "                ",
      " ////////%&/////",
      " /              ",
      " /              ",
      "!/              ",
      " /              ",
      " ////////)*/////",
      "                ",
      "                ",
      "                ",
      "                ",
      "                ",
      "                "
    ],
    [
      "                ",
      "                ",
      "                ",
      "                ",
      " ////////'(/////",
      " /              ",
      " /              ",
      "!/              ",
      " /              ",
      " ////////+,/////",
      "                ",
      "                ",
      "                ",
      "                ",
      "                ",
      "                "
    ],
    [
      "                ",
      "                ",
      "                ",
      "                ",
      " ///////////////",
      " /              ",
      " /              ",
      "!/              ",
      " /              ",
      " ///////////////",
      "                ",
      "                ",
      "                ",
      "                ",
      "                ",
      "                "
    ],
    [
      "                ",
      "                ",
      "                ",
      "                ",
      " ///////////////",
      " /              ",
      " /              ",
      "!/              ",
      " /              ",
      " ///////////////",
      "                ",
      "                ",
      "                ",
      "                ",
      "                ",
      "                "
    ]
  ],
  "palette": {
    "palette": [
      {
        "char": "!",
        "block": "minecraft:bricks"
      },
      {
        "char": "$",
        "block": "minecraft:coarse_dirt"
      },
      {
        "char": "%",
        "block": "minecraft:dark_oak_door[facing=north,half=lower,hinge=left,open=false,powered=false]"
      },
      {
        "char": "&",
        "block": "minecraft:dark_oak_door[facing=north,half=lower,hinge=right,open=false,powered=false]"
      },
      {
        "char": "'",
        "block": "minecraft:dark_oak_door[facing=north,half=upper,hinge=left,open=false,powered=false]"
      },
      {
        "char": "(",
        "block": "minecraft:dark_oak_door[facing=north,half=upper,hinge=right,open=false,powered=false]"
      },
      {
        "char": ")",
        "block": "minecraft:dark_oak_door[facing=south,half=lower,hinge=left,open=false,powered=false]"
      },
      {
        "char": "*",
        "block": "minecraft:dark_oak_door[facing=south,half=lower,hinge=right,open=false,powered=false]"
      },
      {
        "char": "+",
        "block": "minecraft:dark_oak_door[facing=south,half=upper,hinge=left,open=false,powered=false]"
      },
      {
        "char": ",",
        "block": "minecraft:dark_oak_door[facing=south,half=upper,hinge=right,open=false,powered=false]"
      },
      {
        "char": "-",
        "block": "minecraft:gravel"
      },
      {
        "char": ".",
        "block": "minecraft:polished_andesite"
      },
      {
        "char": "/",
        "block": "minecraft:smooth_stone"
      },
      {
        "char": "0",
        "block": "tfmg:asphalt"
      }
    ]
  }
}
