{
  "xsize": 16,
  "zsize": 16,
  "slices": [
    [
      "555555555555--  ",
      "55555555555--   ",
      "5555555555--    ",
      "555555555--     ",
      "55555555.-      ",
      "555555..)       ",
      "5555..)55--     ",
      "55..)5555- -    ",
      "..)5555555--    ",
      ")5555555555 --  ",
      "555555555555- - ",
      "5555555555555-- ",
      "55555555555..) -",
      "555555555..)555-",
      "5555555..)555555",
      "55555..)55555555"
    ],
    [
      "77777777....    ",
      "7777777.77      ",
      "777777777.      ",
      "77777777.       ",
      "7777777.7       ",
      "777777777       ",
      "77777777.       ",
      "777777...       ",
      "777777....      ",
      "111111...11     ",
      "1111111111.1    ",
      "111111111111.   ",
      "11111111111111  ",
      "111111111111111 ",
      "111111111111111.",
      "1111111111111111"
    ],
    [
      " 8   3 '....    ",
      " 8   8 .'       ",
      " 8   8   .      ",
      " 8   8  .       ",
      " 8   8 .'       ",
      " 8   8 ''.      ",
      " 89  8  2       ",
      " 8   8... .     ",
      "$$$+$$....+$.   ",
      "000+00...0+.00  ",
      "    6     .  . 6",
      "%%  6 &&&&&&2  6",
      "%%  6 &&&&&&& .6",
      "%%  6 &&&&&&&  6",
      "(%  3 &&&&&&&  3",
      "%%* 6 &&&&&&&  6"
    ],
    [
      " 8   4 ''...    ",
      " 8   8 .'       ",
      " 8   8   .      ",
      " 8   8  .       ",
      " 8   8 .'       ",
      " 8   8 ''.      ",
      " 8   8          ",
      " 8   8... 2     ",
      "$$$,$$....,$.   ",
      "000,00...0,.00  ",
      "    6     .  . 6",
      "%%  6 &&&&&&&  6",
      "%%  6 &&&&/&& 26",
      "%%  6 &&&&&&&  6",
      "%%  4 &&&&&&&  4",
      "%%  6 &&&&&&&  6"
    ],
    [
      " 8   8 ''...    ",
      " 8   8 ''       ",
      " 8   8   .      ",
      " 8   8  .       ",
      " 8   8 .'       ",
      " 8   8 ''.      ",
      " 8   8          ",
      " 8   8...       ",
      "$$$$$$...$$$2   ",
      "000000...00.00  ",
      "    6     .  . 6",
      "%%  6 &&&&&&&  6",
      "%%  6 &&&&&&&  6",
      "%%  6 &&&&&&&  6",
      "%%  6 &&&&&&&  6",
      "%%  6 &&&&&&&  6"
    ],
    [
      " 8   8 !'...    ",
      " 8   8 ''       ",
      " 8   8          ",
      " 8   8  .       ",
      " 8   8 !'       ",
      " 8   8 ''.      ",
      " 8   8          ",
      " 8   8          ",
      "$$$$$$$$$$$$$   ",
      "00000000000000  ",
      "    6     .  . 6",
      "    6 &&&&&&&  6",
      "    6 &&&&&&&  6",
      "    6 &&&&&&&  6",
      "    6 &&&&&&&  6",
      "    6 &&&&&&&  6"
    ]
  ],
  "palette": {
    "palette": [
      {
        "char": "!",
        "block": "create:red_nixie_tube"
      },
      {
        "char": "$",
        "block": "immersiveengineering:concrete_reinforced"
      },
      {
        "char": "%",
        "block": "immersiveengineering:crate"
      },
      {
        "char": "&",
        "block": "immersiveengineering:sheetmetal_steel"
      },
      {
        "char": "'",
        "block": "minecraft:black_concrete"
      },
      {
        "char": "(",
        "block": "minecraft:chest[facing=east,type=single,waterlogged=false]",
        "tag": {
          "id": "minecraft:chest",
          "LootTable": "infinite_domain:chests/wasteland_data"
        }
      },
      {
        "char": ")",
        "block": "minecraft:coarse_dirt"
      },
      {
        "char": "*",
        "block": "minecraft:crafting_table"
      },
      {
        "char": "+",
        "block": "minecraft:dark_oak_door[facing=south,half=lower,hinge=left,open=false,powered=false]"
      },
      {
        "char": ",",
        "block": "minecraft:dark_oak_door[facing=south,half=upper,hinge=left,open=false,powered=false]"
      },
      {
        "char": "-",
        "block": "minecraft:deepslate"
      },
      {
        "char": ".",
        "block": "minecraft:gravel"
      },
      {
        "char": "/",
        "block": "minecraft:lever[face=wall,facing=south,powered=false]"
      },
      {
        "char": "0",
        "block": "minecraft:mud_bricks"
      },
      {
        "char": "1",
        "block": "minecraft:polished_andesite"
      },
      {
        "char": "2",
        "block": "minecraft:polished_deepslate"
      },
      {
        "char": "3",
        "block": "minecraft:spruce_door[facing=east,half=lower,hinge=left,open=false,powered=false]"
      },
      {
        "char": "4",
        "block": "minecraft:spruce_door[facing=east,half=upper,hinge=left,open=false,powered=false]"
      },
      {
        "char": "5",
        "block": "tfmg:asphalt"
      },
      {
        "char": "6",
        "block": "tfmg:cinder_block"
      },
      {
        "char": "7",
        "block": "tfmg:factory_floor"
      },
      {
        "char": "8",
        "block": "the_wasteland_reworked:cut_lead_plating"
      },
      {
        "char": "9",
        "block": "wastelands:scrap_pile"
      }
    ]
  }
}
