{
  "xsize": 16,
  "zsize": 16,
  "slices": [
    [
      "/////////////**'",
      "///////////**'//",
      "/////////**'////",
      "///////**'//////",
      "/////**'////////",
      "///**'//////////",
      "/**'////////////",
      "*'//////////////",
      "////////////////",
      "//////////////**",
      "////////////**'/",
      "//////////**'///",
      "////////**'/////",
      "//////**'///////",
      "////**'/////////",
      "//**'///////////"
    ],
    [
      "        00000000",
      "        00000000",
      "        00000000",
      "        00000000",
      "        00000000",
      "        00000000",
      "        00000000",
      "        00000000",
      "        00000000",
      "        ,,,,,,,,",
      "        ,,,,,,,,",
      "        ,,,,,,,,",
      "        ,,,,,,,,",
      "        ,,,,,,,,",
      "        ,,,,,,,,",
      "        ,,,,,,,,"
    ],
    [
      "        $ && .&&",
      "       -- &&  &&",
      "       --       ",
      "        $       ",
      "        $ &&  &&",
      "        $ &&  &&",
      "        $       ",
      "       --       ",
      "       --$$$$($$",
      "        +++++(++",
      "        +       ",
      "        + %%%%%%",
      "        + %%%%%%",
      "        + %%%%%%",
      "        + %%%%%%",
      "        + %%%%%%"
    ],
    [
      "        $ &&  &&",
      "       -- &&  &&",
      "       --       ",
      "        $       ",
      "        $ &&  &&",
      "        $ &&  &&",
      "        $       ",
      "       --       ",
      "       --$$$$)$$",
      "        +++++)++",
      "        +       ",
      "        + %%%%%%",
      "        + %%%%%%",
      "        + %%%%%%",
      "        + %%%%%%",
      "        + %%%%%%"
    ],
    [
      "        $ &&  &&",
      "       -- &&  &&",
      "       --       ",
      "        $       ",
      "        $ &&  &&",
      "        $ &&  &&",
      "        $       ",
      "       --       ",
      "       --$$$$$$$",
      "        ++++++++",
      "        +       ",
      "        + %%%%%%",
      "        + %%%%%%",
      "        + %%%%%%",
      "        + %%%%%%",
      "        + %%%%%%"
    ],
    [
      "        $ !&  !&",
      "       -- &&  &&",
      "       --       ",
      "        $       ",
      "        $ !&  !&",
      "        $ &&  &&",
      "        $       ",
      "       --       ",
      "       --$$$$$$$",
      "        ++++++++",
      "        +       ",
      "        +       ",
      "        +       ",
      "        +       ",
      "        +       ",
      "        +       "
    ]
  ],
  "palette": {
    "palette": [
      {
        "char": "!",
        "block": "create:red_nixie_tube"
      },
      {
        "char": "$",
        "block": "immersiveengineering:concrete_reinforced"
      },
      {
        "char": "%",
        "block": "immersiveengineering:crate"
      },
      {
        "char": "&",
        "block": "minecraft:black_concrete"
      },
      {
        "char": "'",
        "block": "minecraft:coarse_dirt"
      },
      {
        "char": "(",
        "block": "minecraft:dark_oak_door[facing=south,half=lower,hinge=left,open=false,powered=false]"
      },
      {
        "char": ")",
        "block": "minecraft:dark_oak_door[facing=south,half=upper,hinge=left,open=false,powered=false]"
      },
      {
        "char": "*",
        "block": "minecraft:gravel"
      },
      {
        "char": "+",
        "block": "minecraft:mud_bricks"
      },
      {
        "char": ",",
        "block": "minecraft:polished_andesite"
      },
      {
        "char": "-",
        "block": "minecraft:polished_deepslate"
      },
      {
        "char": ".",
        "block": "minecraft:spawner",
        "tag": {
          "id": "minecraft:mob_spawner",
          "Delay": 200,
          "MinSpawnDelay": 240,
          "MaxSpawnDelay": 720,
          "SpawnCount": 2,
          "MaxNearbyEntities": 7,
          "RequiredPlayerRange": 14,
          "SpawnRange": 4,
          "SpawnData": {
            "entity": {
              "id": "minecraft:zombie"
            }
          },
          "SpawnPotentials": [
            {
              "weight": 1,
              "data": {
                "entity": {
                  "id": "minecraft:zombie"
                }
              }
            }
          ]
        }
      },
      {
        "char": "/",
        "block": "tfmg:asphalt"
      },
      {
        "char": "0",
        "block": "tfmg:factory_floor"
      }
    ]
  }
}
