{
  "xsize": 16,
  "zsize": 16,
  "slices": [
    [
      "        $$$$$$  ",
      "        $$$$$$  ",
      "        $$$$$$  ",
      "        $$$$$$  ",
      "        $$$$$$  ",
      "                ",
      "                ",
      "                ",
      "                ",
      "!!!!!!!!!!!!!!!!",
      "                ",
      "                ",
      "                ",
      "                ",
      "                ",
      "                "
    ],
    [
      "        $$$$$$  ",
      "        $$$$$$  ",
      "        $$$$$$  ",
      "        $$$$$$  ",
      "        $$$$$$  ",
      "                ",
      "                ",
      "                ",
      "                ",
      "!!!!!!!!!!!!!!!!",
      "                ",
      "                ",
      "                ",
      "                ",
      "                ",
      "                "
    ],
    [
      "        $$$$$$  ",
      "        $$$$$$  ",
      "        $$$$$$  ",
      "        $$$$$$  ",
      "        $$$$$$  ",
      "                ",
      "                ",
      "                ",
      "                ",
      "!!!!!!!!!!!!!!!!",
      "                ",
      "                ",
      "                ",
      "                ",
      "                ",
      "                "
    ],
    [
      "        $$$$$$  ",
      "        $$$$$$  ",
      "        $$$$$$  ",
      "        $$$$$$  ",
      "        $$$$$$  ",
      "                ",
      "                ",
      "                ",
      "                ",
      "!!!!!!!!!!!!!!!!",
      "                ",
      "                ",
      "                ",
      "                ",
      "                ",
      "                "
    ],
    [
      "        $$$$$$  ",
      "        $$$$$$  ",
      "        $$$$$$  ",
      "        $$$$$$  ",
      "        $$$$$$  ",
      "                ",
      "                ",
      "                ",
      "                ",
      "!!!!!!!!!!!!!!!!",
      "                ",
      "                ",
      "                ",
      "                ",
      "                ",
      "                "
    ],
    [
      "        $$$$$$  ",
      "        $$$$$$  ",
      "        $$$$$$  ",
      "        $$$$$$  ",
      "        $$$$$$  ",
      "                ",
      "                ",
      "                ",
      "                ",
      "!!!!!!!!!!!!!!!!",
      "                ",
      "                ",
      "                ",
      "                ",
      "                ",
      "                "
    ]
  ],
  "palette": {
    "palette": [
      {
        "char": "!",
        "block": "minecraft:bricks"
      },
      {
        "char": "$",
        "block": "minecraft:polished_blackstone_bricks"
      }
    ]
  }
}
