{
  "xsize": 16,
  "zsize": 16,
  "slices": [
    [
      "(((((((((((((   ",
      "(((((((((((((   ",
      "(((((((((((((   ",
      "(((((((((((((   ",
      "(((((((((((((   ",
      "((((((((((%%%   ",
      "((((((((((%%%   ",
      "((((((((((%%%   ",
      "((((((((((%%%   ",
      "((((((((%%%%%   ",
      "((((((%%$(%%%   ",
      "((((%%$(((%%%   ",
      "((%%$(((((%%%   ",
      "%%$(((((((%%%   ",
      "$(((((((((%%%   ",
      "((((((((((%%%   "
    ],
    [
      "                ",
      "                ",
      " '     '        ",
      "                ",
      "                ",
      "                ",
      "                ",
      "                ",
      "***********     ",
      "***********     ",
      "**********&&&   ",
      "**********&&&   ",
      "**********&&&   ",
      "**********&&&   ",
      "**********&&&   ",
      "**********&&&   "
    ],
    [
      "                ",
      "                ",
      "                ",
      "                ",
      "                ",
      "                ",
      "                ",
      "                ",
      ")))))))))))     ",
      "          )     ",
      " !!!!!!!! &&&   ",
      " !!!!!!!! &!!   ",
      " !!!!!!!! &!!   ",
      " !!!!!!!! &!!   ",
      " !!!!!!!! &!!   ",
      " !!!!!!!! &!!   "
    ],
    [
      "                ",
      "                ",
      "                ",
      "                ",
      "                ",
      "                ",
      "                ",
      "                ",
      ")))))))))))     ",
      "          )     ",
      " !!!!!!!! &&&   ",
      " !!!!!!!! &!!   ",
      " !!!!!!!! &!!   ",
      " !!!!!!!! &!!   ",
      " !!!!!!!! &!!   ",
      " !!!!!!!! &!!   "
    ],
    [
      "                ",
      "                ",
      "                ",
      "                ",
      "                ",
      "                ",
      "                ",
      "                ",
      ")))))))))))     ",
      "          )     ",
      " !!!!!!!! &&&   ",
      " !!!!!!!! &!!   ",
      " !!!!!!!! &!!   ",
      " !!!!!!!! &!!   ",
      " !!!!!!!! &!!   ",
      " !!!!!!!! &!!   "
    ],
    [
      "                ",
      "                ",
      "                ",
      "                ",
      "                ",
      "                ",
      "                ",
      "                ",
      ")))))))))))     ",
      "          )     ",
      " !!!!!!!! &&&   ",
      " !!!!!!!! &&&   ",
      " !!!!!!!! &&&   ",
      " !!!!!!!! &&&   ",
      " !!!!!!!! &&&   ",
      " !!!!!!!! &&&   "
    ]
  ],
  "palette": {
    "palette": [
      {
        "char": "!",
        "block": "immersiveengineering:sheetmetal_steel"
      },
      {
        "char": "$",
        "block": "minecraft:coarse_dirt"
      },
      {
        "char": "%",
        "block": "minecraft:gravel"
      },
      {
        "char": "&",
        "block": "minecraft:polished_deepslate"
      },
      {
        "char": "'",
        "block": "minecraft:white_concrete"
      },
      {
        "char": "(",
        "block": "tfmg:asphalt"
      },
      {
        "char": ")",
        "block": "tfmg:cinder_block"
      },
      {
        "char": "*",
        "block": "tfmg:factory_floor"
      }
    ]
  }
}
