{
  "xsize": 16,
  "zsize": 16,
  "slices": [
    [
      ",,,,,,,,,,,,,%%$",
      ",,,,,,,,,,,%%$,,",
      ",,,,,,,,,%%$,,,,",
      ",,,,,,,%%$,,,,,,",
      ",,,,,%%$,,,,,,,,",
      ",,,%%$,,,,,,,,,,",
      ",%%$,,,,,,,,,,,,",
      "%$,,,,,,,,,,,,,,",
      ",,,,,,,,,,,,,,,,",
      ",,,,,,,,,,,,,,%%",
      ",,,,,,,,,,,,%%$,",
      ",,,,,,,,,,%%$,,,",
      ",,,,,,,,%%$,,,,,",
      ",$,,,,$%$,,$,,,,",
      "                ",
      "                "
    ],
    [
      "&&&&&&&&&&&&&&&&",
      "&&&&&&&&&&&&&&&&",
      "&&&&&&&&&&&&&&&&",
      "&&&&&&&&&&&&&&&&",
      "&&&&&&&&&&&&&&&&",
      "&&&&&&&&&&&&&&&&",
      "&&&&&&&&&&&&&&&&",
      "&&&&&&&&&&&&&&&&",
      "&&&&&&&&&&&&&&&&",
      "&&&&&&&&&&&&&&&&",
      "                ",
      "                ",
      "                ",
      "                ",
      "                ",
      "                "
    ],
    [
      "        ''''''  ",
      "(((  )) '''''' +",
      "(((  *  '''''' +",
      "(((     '''''' +",
      "(((     '''''' +",
      "(((            +",
      "(((            +",
      "(((            +",
      "                ",
      "!!!!!!!!!!!!!!!!",
      "                ",
      "                ",
      "                ",
      "                ",
      "                ",
      "                "
    ],
    [
      "        ''''''  ",
      "(((     '''''' +",
      "(((     '''''' +",
      "(((     '''''' +",
      "(((     '''''' +",
      "(((            +",
      "(((            +",
      "(((            +",
      "                ",
      "!!!!!!!!!!!!!!!!",
      "                ",
      "                ",
      "                ",
      "                ",
      "                ",
      "                "
    ],
    [
      "        ''''''  ",
      "(((     '''''' +",
      "(((     '''''' +",
      "(((     '''''' +",
      "(((     '''''' +",
      "(((            +",
      "(((            +",
      "(((            +",
      "                ",
      "!!!!!!!!!!!!!!!!",
      "                ",
      "                ",
      "                ",
      "                ",
      "                ",
      "                "
    ],
    [
      "        ''''''  ",
      "(((     ''''''  ",
      "(((     ''''''  ",
      "(((     ''''''  ",
      "(((     ''''''  ",
      "(((             ",
      "(((             ",
      "(((             ",
      "                ",
      "!!!!!!!!!!!!!!!!",
      "                ",
      "                ",
      "                ",
      "                ",
      "                ",
      "                "
    ]
  ],
  "palette": {
    "palette": [
      {
        "char": "!",
        "block": "minecraft:bricks"
      },
      {
        "char": "$",
        "block": "minecraft:coarse_dirt"
      },
      {
        "char": "%",
        "block": "minecraft:gravel"
      },
      {
        "char": "&",
        "block": "minecraft:polished_andesite"
      },
      {
        "char": "'",
        "block": "minecraft:polished_blackstone_bricks"
      },
      {
        "char": "(",
        "block": "minecraft:scaffolding"
      },
      {
        "char": ")",
        "block": "minecraft:spruce_slab[type=bottom,waterlogged=false]"
      },
      {
        "char": "*",
        "block": "minecraft:spruce_stairs[facing=north,half=bottom,shape=straight,waterlogged=false]"
      },
      {
        "char": "+",
        "block": "minecraft:white_wool"
      },
      {
        "char": ",",
        "block": "tfmg:asphalt"
      }
    ]
  }
}
