{
  "xsize": 16,
  "zsize": 16,
  "slices": [
    [
      "       &!       ",
      "       ((       ",
      "       (( $$  $$",
      "       &! $$  $$",
      "       &!       ",
      "       &!       ",
      "       &!       ",
      "       &!       ",
      "       &!       ",
      "       ((       ",
      "       ((       ",
      "       &! $$  $$",
      "&&&&&&&&! $$  $$",
      "        !       ",
      "        !       ",
      "        !       "
    ],
    [
      "       &!       ",
      "       ((       ",
      "       (( $$  $$",
      "       &! $$  $$",
      "       &!       ",
      "       &!       ",
      "       &!       ",
      "       &!       ",
      "       &!       ",
      "       ((       ",
      "       ((       ",
      "       &! $$  $$",
      "&&&&&&&&! $$  $$",
      "        !       ",
      "        !       ",
      "        !       "
    ],
    [
      "'''''''&!       ",
      "'''''''((       ",
      "'''''''((       ",
      "'''''''&!       ",
      "'''''''&!       ",
      "'''''''&!       ",
      "'''''''&!       ",
      "'''''''&!       ",
      "'''''''&!       ",
      "'''''''((       ",
      "'''''''((       ",
      "'''''''&!       ",
      "&&&&&&&&!       ",
      "        !       ",
      "        !       ",
      "        !       "
    ],
    [
      "       &!       ",
      "--+----((       ",
      "       ((       ",
      "   *   &!       ",
      " %     &!       ",
      "       &!       ",
      "       &!       ",
      "       &!       ",
      "    )  &!       ",
      "       ((       ",
      "       ((       ",
      "       &!       ",
      "&&&&&&&&!       ",
      "        !       ",
      "        !       ",
      "        !       "
    ],
    [
      "       &!       ",
      "--,----((       ",
      "       ((       ",
      "       &!       ",
      "       &!       ",
      "       &!       ",
      "       &!       ",
      "       &!       ",
      "       &!       ",
      "       ((       ",
      "       ((       ",
      "       &!       ",
      "&&&&&&&&!       ",
      "        !       ",
      "        !       ",
      "        !       "
    ],
    [
      "       &!       ",
      "-------((       ",
      "       ((       ",
      "       &!       ",
      "       &!       ",
      "       &!       ",
      "       &!       ",
      "       &!       ",
      "       &!       ",
      "       ((       ",
      "       ((       ",
      "       &!       ",
      "&&&&&&&&!       ",
      "        !       ",
      "        !       ",
      "        !       "
    ]
  ],
  "palette": {
    "palette": [
      {
        "char": "!",
        "block": "immersiveengineering:concrete_reinforced"
      },
      {
        "char": "$",
        "block": "minecraft:black_concrete"
      },
      {
        "char": "%",
        "block": "kubejs:ruined_cartography_table"
      },
      {
        "char": "&",
        "block": "minecraft:mud_bricks"
      },
      {
        "char": "'",
        "block": "minecraft:polished_andesite"
      },
      {
        "char": "(",
        "block": "minecraft:polished_deepslate"
      },
      {
        "char": ")",
        "block": "kubejs:ruined_smoker[facing=north]"
      },
      {
        "char": "*",
        "block": "minecraft:spawner",
        "tag": {
          "id": "minecraft:mob_spawner",
          "Delay": 300,
          "MinSpawnDelay": 240,
          "MaxSpawnDelay": 720,
          "SpawnCount": 2,
          "MaxNearbyEntities": 7,
          "RequiredPlayerRange": 14,
          "SpawnRange": 4,
          "SpawnData": {
            "entity": {
              "id": "minecraft:pillager"
            }
          },
          "SpawnPotentials": [
            {
              "weight": 1,
              "data": {
                "entity": {
                  "id": "minecraft:pillager"
                }
              }
            }
          ]
        }
      },
      {
        "char": "+",
        "block": "minecraft:spruce_door[facing=south,half=lower,hinge=left,open=false,powered=false]"
      },
      {
        "char": ",",
        "block": "minecraft:spruce_door[facing=south,half=upper,hinge=left,open=false,powered=false]"
      },
      {
        "char": "-",
        "block": "tfmg:cinder_block"
      }
    ]
  }
}
