{
  "xsize": 16,
  "zsize": 16,
  "slices": [
    [
      "    $           ",
      "    $           ",
      "    $           ",
      "    $           ",
      "    $           ",
      "    $           ",
      "    $           ",
      "    $           ",
      "    $           ",
      "    $ &         ",
      "    $           ",
      "    $           ",
      "    $$$$$$$$$$$$",
      "                ",
      "                ",
      "                "
    ],
    [
      "    $           ",
      "    $           ",
      "    $           ",
      "    $           ",
      "    $           ",
      "    $           ",
      "    $           ",
      "    $           ",
      "    $           ",
      "    $           ",
      "    $ &         ",
      "    $           ",
      "    $$$$$$$$$$$$",
      "                ",
      "                ",
      "                "
    ],
    [
      "    $%%%%%%%%%%%",
      "    $%%%%%%%%%%%",
      "    $%%%%%%%%%%%",
      "    $%%%%%%%%%%%",
      "    $%%%%%%%%%%%",
      "    $%%%%%%%%%%%",
      "    $%%%%%%%%%%%",
      "    $%%%%%%%%%%%",
      "    $%%%%%%%%%%%",
      "    $% %%%%%%%%%",
      "    $% %%%%%%%%%",
      "    $%%%%%%%%%%%",
      "    $$$$$$$$$$$$",
      "                ",
      "                ",
      "                "
    ],
    [
      "    $         + ",
      "    $++++)++++++",
      "    $         + ",
      "    $ !!!!!!  + ",
      "    $ !!!!!!  + ",
      "    $         + ",
      "    $         ' ",
      "    $         + ",
      "    $         + ",
      "    $         + ",
      "    $         + ",
      "    $         + ",
      "    $$$$$$$$$$$$",
      "                ",
      "                ",
      "                "
    ],
    [
      "    $         + ",
      "    $++++*++++++",
      "    $         + ",
      "    $ !!!!!!  + ",
      "    $ !!!!!!  + ",
      "    $         + ",
      "    $         ( ",
      "    $         + ",
      "    $         + ",
      "    $         + ",
      "    $         + ",
      "    $         + ",
      "    $$$$$$$$$$$$",
      "                ",
      "                ",
      "                "
    ],
    [
      "    $         + ",
      "    $+++++++++++",
      "    $         + ",
      "    $ !!!!!!  + ",
      "    $ !!!!!!  + ",
      "    $         + ",
      "    $         + ",
      "    $         + ",
      "    $         + ",
      "    $         + ",
      "    $         + ",
      "    $         + ",
      "    $$$$$$$$$$$$",
      "                ",
      "                ",
      "                "
    ]
  ],
  "palette": {
    "palette": [
      {
        "char": "!",
        "block": "minecraft:bookshelf"
      },
      {
        "char": "$",
        "block": "minecraft:mud_bricks"
      },
      {
        "char": "%",
        "block": "minecraft:polished_andesite"
      },
      {
        "char": "&",
        "block": "minecraft:polished_andesite_stairs[facing=south,half=bottom,shape=straight,waterlogged=false]"
      },
      {
        "char": "'",
        "block": "minecraft:spruce_door[facing=east,half=lower,hinge=left,open=false,powered=false]"
      },
      {
        "char": "(",
        "block": "minecraft:spruce_door[facing=east,half=upper,hinge=left,open=false,powered=false]"
      },
      {
        "char": ")",
        "block": "minecraft:spruce_door[facing=south,half=lower,hinge=left,open=false,powered=false]"
      },
      {
        "char": "*",
        "block": "minecraft:spruce_door[facing=south,half=upper,hinge=left,open=false,powered=false]"
      },
      {
        "char": "+",
        "block": "tfmg:cinder_block"
      }
    ]
  }
}
