{
  "xsize": 16,
  "zsize": 16,
  "slices": [
    [
      "       (( '     ",
      "       ((%'     ",
      "       (( '     ",
      "       (( '     ",
      "       (( '     ",
      "       (( '     ",
      "          '     ",
      "          '     ",
      "    '''''''     ",
      "   !!!!!!!!     ",
      "%     %   !     ",
      "    $$$$$ !     ",
      "    $$$$$ !     ",
      "    $$$$$ !     ",
      "    $$$$$ !     ",
      "    $$$$$ !     "
    ],
    [
      "        ( '     ",
      "       (  '     ",
      "       ((       ",
      "       (( '     ",
      "          '     ",
      "       (( '     ",
      "          '     ",
      "          '     ",
      "    '''''''     ",
      "   !  !!!!!     ",
      "          !     ",
      "    $$$$$ !     ",
      "     $$$$ !     ",
      "    $$$$$ !     ",
      "    $$$$$ !     ",
      "    $$$$$ !     "
    ],
    [
      "          '     ",
      "          '     ",
      "                ",
      "                ",
      "          '     ",
      "          '     ",
      "          '     ",
      "          '     ",
      "    ''' '''     ",
      "      !!!!!     ",
      "          !     ",
      "          !     ",
      "          !     ",
      "          !     ",
      "          !     ",
      "          !     "
    ],
    [
      "          '     ",
      "          '     ",
      "                ",
      "                ",
      "          '     ",
      "          '     ",
      "          '     ",
      "          '     ",
      "    '   '''     ",
      "      ! !!!     ",
      "          !     ",
      "          !     ",
      "          !     ",
      "          !     ",
      "          !     ",
      "          !     "
    ],
    [
      "          '     ",
      "          '     ",
      "                ",
      "                ",
      "          '     ",
      "          '     ",
      "          '     ",
      "          '     ",
      "        '''     ",
      "        !!!     ",
      "          !     ",
      "          !     ",
      "          !     ",
      "          !     ",
      "          !     ",
      "          !     "
    ],
    [
      "          '     ",
      "          '     ",
      "                ",
      "                ",
      "          '     ",
      "          '     ",
      "          '     ",
      "          '     ",
      "        '''     ",
      "        &&&     ",
      "       &&&&     ",
      "       &&&&     ",
      "      &&&&&     ",
      "&  &&&&&&&&     ",
      "&&&&&&&&&&&     ",
      "&&&&&&&&&&&     "
    ]
  ],
  "palette": {
    "palette": [
      {
        "char": "!",
        "block": "minecraft:mud_bricks"
      },
      {
        "char": "$",
        "block": "minecraft:oxidized_copper"
      },
      {
        "char": "%",
        "block": "minecraft:polished_deepslate"
      },
      {
        "char": "&",
        "block": "minecraft:smooth_stone"
      },
      {
        "char": "'",
        "block": "tfmg:cinder_block"
      },
      {
        "char": "(",
        "block": "tfmg:steel_block"
      }
    ]
  }
}
