{
  "xsize": 16,
  "zsize": 16,
  "slices": [
    [
      "1111111++(111111",
      "11111++(11111111",
      "111++(1111111111",
      "1++(111111111111",
      "+(11111111111111",
      "1111111111111111",
      "11111111111111++",
      "111111111111++(1",
      "1111111111++(111",
      "11111111++(11111",
      "111111++(1111111",
      "1111++(111111111",
      "11++(11111111111",
      "++(1111111111111",
      "(111111111111111",
      "111111111111111+"
    ],
    [
      "--------33333333",
      "--------33333333",
      "--------33333333",
      "--------33333333",
      "--------33333333",
      "--------33333333",
      "--------33333333",
      "--------33333333",
      "--------33333333",
      "--------33333333",
      "--------33333333",
      "--------33333333",
      "--------33333333",
      "        33333333",
      "        33333333",
      "        33333333"
    ],
    [
      "       ,$       ",
      "       ..       ",
      "&& &&  .. &&  &&",
      "&& &&  ,$ &&  &&",
      "       ,$       ",
      "22/2222,$       ",
      "       ,$       ",
      "'    ' ,$4444/44",
      "'    ' ,$       ",
      "'    ' ..       ",
      "'    ' .. %    %",
      "       )) %&  &%",
      ",,,,,,,,$ %&  &%",
      "        $       ",
      "        $       ",
      "        $       "
    ],
    [
      "       ,$       ",
      "       ..       ",
      "&& &&  .. &&  &&",
      "&& &&  ,$ &&  &&",
      "       ,$       ",
      "2202222,$       ",
      "       ,$       ",
      "'    ' ,$4444044",
      "'    ' ,$       ",
      "'    ' ..       ",
      "'    ' .. %    %",
      "       ** %&  &%",
      ",,,,,,,,$ %&  &%",
      "        $       ",
      "        $       ",
      "        $       "
    ],
    [
      "       ,$       ",
      "       ..       ",
      "&& &&  .. &&  &&",
      "&& &&  ,$ &&  &&",
      "       ,$       ",
      "2222222,$       ",
      "       ,$       ",
      "'    ' ,$4444444",
      "'    ' ,$       ",
      "'    ' ..       ",
      "'    ' .. %    %",
      "       ,$ %& 5&%",
      ",,,,,,,,$ %&  &%",
      "        $       ",
      "        $       ",
      "        $       "
    ],
    [
      "       ,$       ",
      "       ..       ",
      "!  !   .. !&  !&",
      "       ,$ &&  &&",
      "       ,$       ",
      "2222222,$       ",
      "       ,$       ",
      "       ,$4444444",
      "       ,$       ",
      "       ..       ",
      "       ..       ",
      "       ,$ !&  !&",
      ",,,,,,,,$ &&  &&",
      "        $       ",
      "        $       ",
      "        $       "
    ]
  ],
  "palette": {
    "palette": [
      {
        "char": "!",
        "block": "create:red_nixie_tube"
      },
      {
        "char": "$",
        "block": "immersiveengineering:concrete_reinforced"
      },
      {
        "char": "%",
        "block": "immersiveengineering:sheetmetal_steel"
      },
      {
        "char": "&",
        "block": "minecraft:black_concrete"
      },
      {
        "char": "'",
        "block": "minecraft:bookshelf"
      },
      {
        "char": "(",
        "block": "minecraft:coarse_dirt"
      },
      {
        "char": ")",
        "block": "minecraft:dark_oak_door[facing=east,half=lower,hinge=left,open=false,powered=false]"
      },
      {
        "char": "*",
        "block": "minecraft:dark_oak_door[facing=east,half=upper,hinge=left,open=false,powered=false]"
      },
      {
        "char": "+",
        "block": "minecraft:gravel"
      },
      {
        "char": ",",
        "block": "minecraft:mud_bricks"
      },
      {
        "char": "-",
        "block": "minecraft:polished_andesite"
      },
      {
        "char": ".",
        "block": "minecraft:polished_deepslate"
      },
      {
        "char": "/",
        "block": "minecraft:spruce_door[facing=south,half=lower,hinge=left,open=false,powered=false]"
      },
      {
        "char": "0",
        "block": "minecraft:spruce_door[facing=south,half=upper,hinge=left,open=false,powered=false]"
      },
      {
        "char": "1",
        "block": "tfmg:asphalt"
      },
      {
        "char": "2",
        "block": "tfmg:cinder_block"
      },
      {
        "char": "3",
        "block": "tfmg:factory_floor"
      },
      {
        "char": "4",
        "block": "the_wasteland_reworked:cut_lead_plating"
      },
      {
        "char": "5",
        "block": "the_wasteland_reworked:radio"
      }
    ]
  }
}
