{
  "xsize": 16,
  "zsize": 16,
  "slices": [
    [
      ".............**'",
      "...........**'..",
      ".........**'....",
      ".......**'......",
      ".....**'........",
      "...**'..........",
      ".**'............",
      "*'..............",
      "................",
      "..............**",
      "............**'.",
      "..........**'...",
      "........**'.....",
      "......**'.......",
      "....**'.........",
      "..**'..........."
    ],
    [
      "        ////////",
      "        ////////",
      "        ////////",
      "        ////////",
      "        ////////",
      "        ////////",
      "        ////////",
      "        ////////",
      "        ////////",
      "        ,,,,,,,,",
      "        ,,,,,,,,",
      "        ,,,,,,,,",
      "        ,,,,,,,,",
      "        ,,,,,,,,",
      "        ,,,,,,,,",
      "        ,,,,,,,,"
    ],
    [
      "        $ &&  &&",
      "       -- &&  &&",
      "       --       ",
      "        $       ",
      "        $ &&  &&",
      "        $ &&  &&",
      "        $       ",
      "       --       ",
      "       --$$$$($$",
      "        +++++(++",
      "        +       ",
      "        + %%%%%%",
      "        + %%%%%%",
      "        + %%%%%%",
      "        + %%%%%%",
      "        + %%%%%%"
    ],
    [
      "        $ &&  &&",
      "       -- &&  &&",
      "       --       ",
      "        $       ",
      "        $ &&  &&",
      "        $ &&  &&",
      "        $       ",
      "       --       ",
      "       --$$$$)$$",
      "        +++++)++",
      "        +       ",
      "        + %%%%%%",
      "        + %%%%%%",
      "        + %%%%%%",
      "        + %%%%%%",
      "        + %%%%%%"
    ],
    [
      "        $ &&  &&",
      "       -- &&  &&",
      "       --       ",
      "        $       ",
      "        $ &&  &&",
      "        $ &&  &&",
      "        $       ",
      "       --       ",
      "       --$$$$$$$",
      "        ++++++++",
      "        +       ",
      "        + %%%%%%",
      "        + %%%%%%",
      "        + %%%%%%",
      "        + %%%%%%",
      "        + %%%%%%"
    ],
    [
      "        $ !&  !&",
      "       -- &&  &&",
      "       --       ",
      "        $       ",
      "        $ !&  !&",
      "        $ &&  &&",
      "        $       ",
      "       --       ",
      "       --$$$$$$$",
      "        ++++++++",
      "        +       ",
      "        +       ",
      "        +       ",
      "        +       ",
      "        +       ",
      "        +       "
    ]
  ],
  "palette": {
    "palette": [
      {
        "char": "!",
        "block": "create:red_nixie_tube"
      },
      {
        "char": "$",
        "block": "immersiveengineering:concrete_reinforced"
      },
      {
        "char": "%",
        "block": "immersiveengineering:crate"
      },
      {
        "char": "&",
        "block": "minecraft:black_concrete"
      },
      {
        "char": "'",
        "block": "minecraft:coarse_dirt"
      },
      {
        "char": "(",
        "block": "minecraft:dark_oak_door[facing=south,half=lower,hinge=left,open=false,powered=false]"
      },
      {
        "char": ")",
        "block": "minecraft:dark_oak_door[facing=south,half=upper,hinge=left,open=false,powered=false]"
      },
      {
        "char": "*",
        "block": "minecraft:gravel"
      },
      {
        "char": "+",
        "block": "minecraft:mud_bricks"
      },
      {
        "char": ",",
        "block": "minecraft:polished_andesite"
      },
      {
        "char": "-",
        "block": "minecraft:polished_deepslate"
      },
      {
        "char": ".",
        "block": "tfmg:asphalt"
      },
      {
        "char": "/",
        "block": "tfmg:factory_floor"
      }
    ]
  }
}
