{
  "xsize": 16,
  "zsize": 16,
  "slices": [
    [
      "1111&&%111111111",
      "11&&%11111111111",
      "&&%1111111111111",
      "%111111111111111",
      "111111111111111&",
      "1111111111111&&%",
      "11111111111&&%11",
      "111111111&&%1111",
      "1111111&&%111111",
      "11111&&%11111111",
      "111&&%1111111111",
      "1&&%111111111111",
      "&%11111111111111",
      "1111111111111111",
      "11111111111111&&",
      "111111111111&&%1"
    ],
    [
      "    ((((((((((((",
      "    ((((((((((((",
      "    ((((((((((((",
      "    ((((((((((((",
      "    ((((((((((((",
      "    ((((((((((((",
      "    ((((((((((((",
      "    ((((((((((((",
      "    ((((((((((((",
      "    ((((((((((((",
      "    ((((((((((((",
      "    ((((((((((((",
      "    ((((((((((((",
      "                ",
      "                ",
      "                "
    ],
    [
      "    ' !!!!!   2 ",
      "    '         2 ",
      "    '       $ , ",
      "    '         2 ",
      "    '         2 ",
      "    '2)22.222222",
      "    '         2 ",
      "    '         2 ",
      "    ' 0 +  *  2 ",
      "    '         2 ",
      "    '         2 ",
      "    '         2 ",
      "    ''''''''''''",
      "                ",
      "                ",
      "                "
    ],
    [
      "    ' !!!!!   2 ",
      "    '         2 ",
      "    '         - ",
      "    '         2 ",
      "    '         2 ",
      "    '2 22/222222",
      "    ' )       2 ",
      "    '         2 ",
      "    '         2 ",
      "    '         2 ",
      "    '         2 ",
      "    '         2 ",
      "    ''''''''''''",
      "                ",
      "                ",
      "                "
    ],
    [
      "    '         2 ",
      "    '         2 ",
      "    '         2 ",
      "    '         2 ",
      "    '         2 ",
      "    '2 222222222",
      "    '         2 ",
      "    ' )       2 ",
      "    '         2 ",
      "    '         2 ",
      "    '         2 ",
      "    '         2 ",
      "    ''''''''''''",
      "                ",
      "                ",
      "                "
    ],
    [
      "    '         2 ",
      "    '         2 ",
      "    '         2 ",
      "    '         2 ",
      "    '         2 ",
      "    '22222222222",
      "    '         2 ",
      "    '         2 ",
      "    ' )       2 ",
      "    '         2 ",
      "    '         2 ",
      "    '         2 ",
      "    ''''''''''''",
      "                ",
      "                ",
      "                "
    ]
  ],
  "palette": {
    "palette": [
      {
        "char": "!",
        "block": "immersiveengineering:crate"
      },
      {
        "char": "$",
        "block": "minecraft:barrel[facing=up,open=false]"
      },
      {
        "char": "%",
        "block": "minecraft:coarse_dirt"
      },
      {
        "char": "&",
        "block": "minecraft:gravel"
      },
      {
        "char": "'",
        "block": "minecraft:mud_bricks"
      },
      {
        "char": "(",
        "block": "minecraft:polished_andesite"
      },
      {
        "char": ")",
        "block": "minecraft:polished_andesite_stairs[facing=south,half=bottom,shape=straight,waterlogged=false]"
      },
      {
        "char": "*",
        "block": "kubejs:ruined_smithing_table"
      },
      {
        "char": "+",
        "block": "minecraft:spawner",
        "tag": {
          "id": "minecraft:mob_spawner",
          "Delay": 200,
          "MinSpawnDelay": 240,
          "MaxSpawnDelay": 720,
          "SpawnCount": 2,
          "MaxNearbyEntities": 7,
          "RequiredPlayerRange": 14,
          "SpawnRange": 4,
          "SpawnData": {
            "entity": {
              "id": "minecraft:pillager"
            }
          },
          "SpawnPotentials": [
            {
              "weight": 1,
              "data": {
                "entity": {
                  "id": "minecraft:pillager"
                }
              }
            }
          ]
        }
      },
      {
        "char": ",",
        "block": "minecraft:spruce_door[facing=east,half=lower,hinge=left,open=false,powered=false]"
      },
      {
        "char": "-",
        "block": "minecraft:spruce_door[facing=east,half=upper,hinge=left,open=false,powered=false]"
      },
      {
        "char": ".",
        "block": "minecraft:spruce_door[facing=south,half=lower,hinge=left,open=false,powered=false]"
      },
      {
        "char": "/",
        "block": "minecraft:spruce_door[facing=south,half=upper,hinge=left,open=false,powered=false]"
      },
      {
        "char": "0",
        "block": "kubejs:ruined_cauldron"
      },
      {
        "char": "1",
        "block": "tfmg:asphalt"
      },
      {
        "char": "2",
        "block": "tfmg:cinder_block"
      }
    ]
  }
}
