{
  "xsize": 16,
  "zsize": 16,
  "slices": [
    [
      "          %     ",
      "          %     ",
      "          %     ",
      "          %     ",
      "          %     ",
      "          %     ",
      "          %     ",
      "          %     ",
      "%%%%%%%%%%%     ",
      "                ",
      "                ",
      "                ",
      "  !!   !!       ",
      "  !!   !!       ",
      "                ",
      "                "
    ],
    [
      "$$$$$$$$$$$     ",
      "$$!!$$$!!$$     ",
      "$$!!$$$!!$$     ",
      "$$$$$$$$$$$     ",
      "$$$$$$$$$$$     ",
      "$$$$$$$$$$$     ",
      "$$$$$$$$$$$     ",
      "$$$$$$$$$$$     ",
      "$$$$$$$$$$$     ",
      "                ",
      "                ",
      "                ",
      "  !!   !!       ",
      "  !!   !!       ",
      "                ",
      "                "
    ],
    [
      "                ",
      "  !!   !!       ",
      "  !!   !!       ",
      "                ",
      "                ",
      "                ",
      "                ",
      "                ",
      "                ",
      "                ",
      "                ",
      "                ",
      "  !!   !!       ",
      "  !!   !!       ",
      "                ",
      "                "
    ],
    [
      "                ",
      "  !!   !!       ",
      "  !!   !!       ",
      "                ",
      "                ",
      "                ",
      "                ",
      "                ",
      "                ",
      "                ",
      "                ",
      "                ",
      "  !!   !!       ",
      "  !!   !!       ",
      "                ",
      "                "
    ],
    [
      "                ",
      "  !!   !!       ",
      "  !!   !!       ",
      "                ",
      "                ",
      "                ",
      "                ",
      "                ",
      "                ",
      "                ",
      "                ",
      "                ",
      "  !!   !!       ",
      "  !!   !!       ",
      "                ",
      "                "
    ],
    [
      "                ",
      "  !!   !!       ",
      "  !!   !!       ",
      "                ",
      "                ",
      "                ",
      "                ",
      "                ",
      "                ",
      "                ",
      "                ",
      "                ",
      "  !!   !!       ",
      "  !!   !!       ",
      "                ",
      "                "
    ]
  ],
  "palette": {
    "palette": [
      {
        "char": "!",
        "block": "minecraft:oxidized_copper"
      },
      {
        "char": "$",
        "block": "minecraft:weathered_cut_copper"
      },
      {
        "char": "%",
        "block": "tfmg:cinder_block"
      }
    ]
  }
}
