{
  "xsize": 16,
  "zsize": 16,
  "slices": [
    [
      "    !           ",
      "    !           ",
      "    !           ",
      "    !           ",
      "    !           ",
      "    !           ",
      "    !           ",
      "    !           ",
      "    !           ",
      "    !           ",
      "    !           ",
      "                ",
      "                ",
      "                ",
      "                ",
      "                "
    ],
    [
      "    !      (((((",
      "    !      (((((",
      "    !      (((((",
      "    !      (((((",
      "    !      (((((",
      "    !      (((((",
      "    !      (((((",
      "    !      (((((",
      "    !      (((((",
      "    !      (((((",
      "    !      (((((",
      "                ",
      "                ",
      "                ",
      "                ",
      "                "
    ],
    [
      "    %%%%%%%$    ",
      "    %%%%%%%$    ",
      "    %%%%%%%$    ",
      "    %%%%%%%$    ",
      "    %%%%%%%$    ",
      "    %%%%%%%$    ",
      "    %%%%%%%$  )*",
      "    %%%%%%%$    ",
      "    %%%%%%%$  & ",
      "    %%%%%%%$    ",
      "    %%%%%%%$    ",
      "                ",
      "                ",
      "                ",
      "                ",
      "                "
    ],
    [
      "           $    ",
      "           $    ",
      "           $    ",
      "           $    ",
      "           $    ",
      "           $    ",
      "           $    ",
      "           $    ",
      "           $  ' ",
      "           $    ",
      "           $    ",
      "                ",
      "                ",
      "                ",
      "                ",
      "                "
    ],
    [
      "           $    ",
      "           $    ",
      "           $    ",
      "           $    ",
      "           $    ",
      "           $    ",
      "           $    ",
      "           $    ",
      "           $    ",
      "           $    ",
      "           $    ",
      "                ",
      "                ",
      "                ",
      "                ",
      "                "
    ],
    [
      "           $    ",
      "           $    ",
      "           $    ",
      "           $    ",
      "           $    ",
      "           $    ",
      "           $    ",
      "           $    ",
      "           $    ",
      "           $    ",
      "           $    ",
      "                ",
      "                ",
      "                ",
      "                ",
      "                "
    ]
  ],
  "palette": {
    "palette": [
      {
        "char": "!",
        "block": "minecraft:bricks"
      },
      {
        "char": "$",
        "block": "minecraft:light_gray_concrete"
      },
      {
        "char": "%",
        "block": "minecraft:smooth_stone"
      },
      {
        "char": "&",
        "block": "minecraft:spruce_door[facing=south,half=lower,hinge=left,open=false,powered=false]"
      },
      {
        "char": "'",
        "block": "minecraft:spruce_door[facing=south,half=upper,hinge=left,open=false,powered=false]"
      },
      {
        "char": "(",
        "block": "minecraft:spruce_planks"
      },
      {
        "char": ")",
        "block": "minecraft:spruce_stairs[facing=north,half=bottom,shape=straight,waterlogged=false]"
      },
      {
        "char": "*",
        "block": "minecraft:water_cauldron[level=1]"
      }
    ]
  }
}
