{
  "xsize": 16,
  "zsize": 16,
  "slices": [
    [
      "2222222222222222",
      "2222222222222222",
      "2222222222222222",
      "2222222222222222",
      "2222222222222222",
      "2222222222222222",
      "22222222**'22222",
      "222222**'2222222",
      "2222**'222222222",
      "22**'22222222222",
      "**'2222222222222",
      "'222222222222222",
      "222222222222222*",
      "2222222222222**'",
      "22222222222**'22",
      "222222222**'2222"
    ],
    [
      "                ",
      "                ",
      "   1     1     1",
      "                ",
      "  -             ",
      "                ",
      ",,,,,,,,44444444",
      ",,,,,,,,44444444",
      ",,,,,,,,44444444",
      ",,,,,,,,44444444",
      ",,,,,,,,44444444",
      ",,,,,,,,44444444",
      ",,,,,,,,44444444",
      ",,,,,,,,44444444",
      ",,,,,,,,44444444",
      ",,,,,,,,44444444"
    ],
    [
      "                ",
      "                ",
      "                ",
      "                ",
      "  -             ",
      "                ",
      "++++++++%%%%%%%%",
      "       +%       ",
      " ..    +%       ",
      " /     -- &&  &&",
      "       -- &&  &&",
      "3333333+%       ",
      "       +%       ",
      "       +% &&  &&",
      "&& &&  (( &&  &&",
      "&& &&  +%       "
    ],
    [
      "                ",
      "                ",
      "                ",
      "                ",
      "  -             ",
      "  ...           ",
      "++++++++%%%%%%%%",
      "       +%       ",
      "    5  +%       ",
      "       -- &&  &&",
      "       -- &&  &&",
      "3333333+%       ",
      "       +%       ",
      "       +% &&  &&",
      "&& &&  )) &&  &&",
      "&& &&  +%       "
    ],
    [
      "                ",
      "                ",
      "                ",
      "                ",
      "  -             ",
      "                ",
      "+0!!!0++%%%%%%%%",
      "       +%       ",
      "       +%       ",
      "       -- &&  &&",
      "       -- &&  &&",
      "3333333+%       ",
      "       +%       ",
      "       +% &&  &&",
      "&& &&  +% &&  &&",
      "&& &&  +%       "
    ],
    [
      "                ",
      "                ",
      "                ",
      "                ",
      "  -             ",
      "                ",
      "+0!!!0++%%%%%%%%",
      "       +%       ",
      "       +%       ",
      "       -- $&  $&",
      "       -- &&  &&",
      "3333333+%       ",
      "       +%       ",
      "       +% $&  $&",
      "$  $   +% &&  &&",
      "       +%       "
    ]
  ],
  "palette": {
    "palette": [
      {
        "char": "!",
        "block": "create:framed_glass"
      },
      {
        "char": "$",
        "block": "create:red_nixie_tube"
      },
      {
        "char": "%",
        "block": "immersiveengineering:concrete_reinforced"
      },
      {
        "char": "&",
        "block": "minecraft:black_concrete"
      },
      {
        "char": "'",
        "block": "minecraft:coarse_dirt"
      },
      {
        "char": "(",
        "block": "minecraft:dark_oak_door[facing=east,half=lower,hinge=left,open=false,powered=false]"
      },
      {
        "char": ")",
        "block": "minecraft:dark_oak_door[facing=east,half=upper,hinge=left,open=false,powered=false]"
      },
      {
        "char": "*",
        "block": "minecraft:gravel"
      },
      {
        "char": "+",
        "block": "minecraft:mud_bricks"
      },
      {
        "char": ",",
        "block": "minecraft:polished_andesite"
      },
      {
        "char": "-",
        "block": "minecraft:polished_deepslate"
      },
      {
        "char": ".",
        "block": "minecraft:spruce_slab[type=bottom,waterlogged=false]"
      },
      {
        "char": "/",
        "block": "minecraft:spruce_stairs[facing=north,half=bottom,shape=straight,waterlogged=false]"
      },
      {
        "char": "0",
        "block": "minecraft:stripped_spruce_log[axis=y]"
      },
      {
        "char": "1",
        "block": "minecraft:white_concrete"
      },
      {
        "char": "2",
        "block": "tfmg:asphalt"
      },
      {
        "char": "3",
        "block": "tfmg:cinder_block"
      },
      {
        "char": "4",
        "block": "tfmg:factory_floor"
      },
      {
        "char": "5",
        "block": "the_wasteland_reworked:radio"
      }
    ]
  }
}
