{
  "xsize": 16,
  "zsize": 16,
  "slices": [
    [
      "     %%+++&&&   ",
      "     % %++&&&   ",
      "      %% +&&&   ",
      "        %%&&&   ",
      "        % %&&   ",
      "         %%&&   ",
      "        %% &&   ",
      "       %% &&&   ",
      "      %% +&&&   ",
      "     %% ++&&&   ",
      "    %% +++&&&   ",
      "   %% ++++&&&   ",
      "% %% +++++&&&   ",
      " %% ++++++&&&   ",
      "%% +++++++&&&   ",
      "+ ++++++&&&&&   "
    ],
    [
      "       &---     ",
      "        -&-     ",
      "         --     ",
      "          &     ",
      "                ",
      "                ",
      "                ",
      "          -     ",
      "         --     ",
      "        )))     ",
      "       ))))     ",
      "      )))))     ",
      "     ))))))     ",
      "    )))))))     ",
      "   ))))))))     ",
      ") )))))))))     "
    ],
    [
      "       &. ,     ",
      "       ..&,     ",
      "       .& ,     ",
      "       &. &     ",
      "       .. ,     ",
      "        & ,     ",
      "       &  ,     ",
      "      &   ,     ",
      "     &,,,,,     ",
      "    &''&'''     ",
      "   &  &   '     ",
      "  * ((((( '     ",
      " &  &(((( '     ",
      "    ((((( '     ",
      "    ((((( !     ",
      "    ((((( '     "
    ],
    [
      "       &. ,     ",
      "       ..&,     ",
      "       .& ,     ",
      "       &. &     ",
      "       .. ,     ",
      "        . ,     ",
      "       &  ,     ",
      "      &   ,     ",
      "     &,,,,,     ",
      "    &''&'''     ",
      "   &  &   '     ",
      "    ((((( '     ",
      "    *(((( '     ",
      "    ((((( '     ",
      "    ((((( $     ",
      "    ((((( '     "
    ],
    [
      "       &. ,     ",
      "       ..&,     ",
      "       .& ,     ",
      "       &. &     ",
      "       .. ,     ",
      "       .. ,     ",
      "          ,     ",
      "      &   ,     ",
      "    ,,,,,,,     ",
      "   '&''&'''     ",
      "&  &  &   '     ",
      "    ((((( '     ",
      "    ((((( '     ",
      "    ((((( '     ",
      "    ((((( '     ",
      "    ((((( '     "
    ],
    [
      "       *. ,     ",
      "       ..&,     ",
      "       .. ,     ",
      "       &. &     ",
      "       .. ,     ",
      "       .. ,     ",
      "          ,     ",
      "          ,     ",
      "    ,,,,,,,     ",
      "   '*''''''     ",
      "&  &  &   '     ",
      "    ((((( '     ",
      "    ((((( '     ",
      "    ((((( '     ",
      "    ((((( '     ",
      "    ((((( '     "
    ]
  ],
  "palette": {
    "palette": [
      {
        "char": "!",
        "block": "minecraft:dark_oak_door[facing=east,half=lower,hinge=left,open=false,powered=false]"
      },
      {
        "char": "$",
        "block": "minecraft:dark_oak_door[facing=east,half=upper,hinge=left,open=false,powered=false]"
      },
      {
        "char": "%",
        "block": "minecraft:deepslate"
      },
      {
        "char": "&",
        "block": "minecraft:gravel"
      },
      {
        "char": "'",
        "block": "minecraft:mud_bricks"
      },
      {
        "char": "(",
        "block": "minecraft:oxidized_copper"
      },
      {
        "char": ")",
        "block": "minecraft:polished_andesite"
      },
      {
        "char": "*",
        "block": "minecraft:polished_deepslate"
      },
      {
        "char": "+",
        "block": "tfmg:asphalt"
      },
      {
        "char": ",",
        "block": "tfmg:cinder_block"
      },
      {
        "char": "-",
        "block": "tfmg:factory_floor"
      },
      {
        "char": ".",
        "block": "tfmg:steel_block"
      }
    ]
  }
}
