{
  "xsize": 16,
  "zsize": 16,
  "slices": [
    [
      ")))))))))))))   ",
      ")))))))))))))   ",
      ")))))))))))))   ",
      ")))))))))))))   ",
      ")))))))))))))   ",
      "))))))))))%%%   ",
      "))))))))))%%%   ",
      "))))))))))%%%   ",
      "))))))))))%%%   ",
      "))))))))%%%%%   ",
      "))))))%%$)%%%   ",
      "))))%%$)))%%%   ",
      "))%%$)))))%%%   ",
      "%%$)))))))%%%   ",
      "$)))))))))%%%   ",
      "))))))))))%%%   "
    ],
    [
      "                ",
      "                ",
      " (     (        ",
      "                ",
      "                ",
      "                ",
      "                ",
      "                ",
      "+++++++++++     ",
      "+++++++++++     ",
      "++++++++++&&&   ",
      "++++++++++&&&   ",
      "++++++++++&&&   ",
      "++++++++++&&&   ",
      "++++++++++&&&   ",
      "++++++++++&&&   "
    ],
    [
      "                ",
      "                ",
      "                ",
      "                ",
      "                ",
      "                ",
      "                ",
      "                ",
      "***********     ",
      "          *     ",
      " !!!!!!!! &&&   ",
      " !!!!!!!! &!!   ",
      " !!!!!!!! &!!   ",
      " !!!!!!!! &!!   ",
      " !!!!!!!! &!!   ",
      " !!!!'!!! &!!   "
    ],
    [
      "                ",
      "                ",
      "                ",
      "                ",
      "                ",
      "                ",
      "                ",
      "                ",
      "***********     ",
      "          *     ",
      " !!!!!!!! &&&   ",
      " !!!!!!!! &!!   ",
      " !!!!!!!! &!!   ",
      " !!!!!!!! &!!   ",
      " !!!!!!!! &!!   ",
      " !!!!!!!! &!!   "
    ],
    [
      "                ",
      "                ",
      "                ",
      "                ",
      "                ",
      "                ",
      "                ",
      "                ",
      "***********     ",
      "          *     ",
      " !!!!!!!! &&&   ",
      " !!!!!!!! &!!   ",
      " !!!!!!!! &!!   ",
      " !!!!!!!! &!!   ",
      " !!!!!!!! &!!   ",
      " !!!!!!!! &!!   "
    ],
    [
      "                ",
      "                ",
      "                ",
      "                ",
      "                ",
      "                ",
      "                ",
      "                ",
      "***********     ",
      "          *     ",
      " !!!!!!!! &&&   ",
      " !!!!!!!! &&&   ",
      " !!!!!!!! &&&   ",
      " !!!!!!!! &&&   ",
      " !!!!!!!! &&&   ",
      " !!!!!!!! &&&   "
    ]
  ],
  "palette": {
    "palette": [
      {
        "char": "!",
        "block": "immersiveengineering:sheetmetal_steel"
      },
      {
        "char": "$",
        "block": "minecraft:coarse_dirt"
      },
      {
        "char": "%",
        "block": "minecraft:gravel"
      },
      {
        "char": "&",
        "block": "minecraft:polished_deepslate"
      },
      {
        "char": "'",
        "block": "minecraft:spawner",
        "tag": {
          "id": "minecraft:mob_spawner",
          "Delay": 320,
          "MinSpawnDelay": 240,
          "MaxSpawnDelay": 720,
          "SpawnCount": 2,
          "MaxNearbyEntities": 7,
          "RequiredPlayerRange": 14,
          "SpawnRange": 4,
          "SpawnData": {
            "entity": {
              "id": "the_wasteland_reworked:irradiated"
            }
          },
          "SpawnPotentials": [
            {
              "weight": 1,
              "data": {
                "entity": {
                  "id": "the_wasteland_reworked:irradiated"
                }
              }
            }
          ]
        }
      },
      {
        "char": "(",
        "block": "minecraft:white_concrete"
      },
      {
        "char": ")",
        "block": "tfmg:asphalt"
      },
      {
        "char": "*",
        "block": "tfmg:cinder_block"
      },
      {
        "char": "+",
        "block": "tfmg:factory_floor"
      }
    ]
  }
}
