{
  "xsize": 16,
  "zsize": 16,
  "slices": [
    [
      "              !&",
      "              %&",
      "       $$  $$ %&",
      "       $$  $$ !&",
      "              !&",
      "              !&",
      "              !&",
      "              !&",
      "              !&",
      "              %&",
      "              %&",
      "       $$  $$ !&",
      "       $$  $$ !&",
      "              !&",
      "              !&",
      "              !&"
    ],
    [
      "              !&",
      "              %&",
      "       $$  $$ %&",
      "       $$  $$ !&",
      "              !&",
      "              !&",
      "              !&",
      "              !&",
      "              !&",
      "              %&",
      "              %&",
      "       $$  $$ !&",
      "       $$  $$ !&",
      "              !&",
      "              !&",
      "              !&"
    ],
    [
      "              !&",
      "              %&",
      "              %&",
      "              !&",
      "              !&",
      "              !&",
      "              !&",
      "              !&",
      "              !&",
      "              %&",
      "              %&",
      "              !&",
      "              !&",
      "              !&",
      "              !&",
      "              !&"
    ],
    [
      "              !&",
      "              %&",
      "              %&",
      "              !&",
      "              !&",
      "              !&",
      "              !&",
      "              !&",
      "              !&",
      "              %&",
      "              %&",
      "              !&",
      "              !&",
      "              !&",
      "              !&",
      "              !&"
    ],
    [
      "              !&",
      "              %&",
      "              %&",
      "              !&",
      "              !&",
      "              !&",
      "              !&",
      "              !&",
      "              !&",
      "              %&",
      "              %&",
      "              !&",
      "              !&",
      "              !&",
      "              !&",
      "              !&"
    ],
    [
      "              !&",
      "              %&",
      "              %&",
      "              !&",
      "              !&",
      "              !&",
      "              !&",
      "              !&",
      "              !&",
      "              %&",
      "              %&",
      "              !&",
      "              !&",
      "              !&",
      "              !&",
      "              !&"
    ]
  ],
  "palette": {
    "palette": [
      {
        "char": "!",
        "block": "immersiveengineering:concrete_reinforced"
      },
      {
        "char": "$",
        "block": "minecraft:black_concrete"
      },
      {
        "char": "%",
        "block": "minecraft:polished_deepslate"
      },
      {
        "char": "&",
        "block": "tfmg:cinder_block"
      }
    ]
  }
}
