{
  "xsize": 16,
  "zsize": 16,
  "slices": [
    [
      "0000&&%000000000",
      "00&&%00000000000",
      "&&%0000000000000",
      "%000000000000000",
      "000000000000000&",
      "0000000000000&&%",
      "00000000000&&%00",
      "000000000&&%0000",
      "0000000&&%000000",
      "00000&&%00000000",
      "000&&%0000000000",
      "0&&%000000000000",
      "&%00000000000000",
      "0000000000000000",
      "00000000000000&&",
      "000000000000&&%0"
    ],
    [
      "    ((((((((((((",
      "    ((((((((((((",
      "    ((((((((((((",
      "    ((((((((((((",
      "    ((((((((((((",
      "    ((((((((((((",
      "    ((((((((((((",
      "    ((((((((((((",
      "    ((((((((((((",
      "    ((((((((((((",
      "    ((((((((((((",
      "    ((((((((((((",
      "    ((((((((((((",
      "                ",
      "                ",
      "                "
    ],
    [
      "    ' !!!!!   1 ",
      "    '         1 ",
      "    '       $ + ",
      "    '         1 ",
      "    '         1 ",
      "    '1)11-111111",
      "    '         1 ",
      "    '         1 ",
      "    ' /    *  1 ",
      "    '         1 ",
      "    '         1 ",
      "    '         1 ",
      "    ''''''''''''",
      "                ",
      "                ",
      "                "
    ],
    [
      "    ' !!!!!   1 ",
      "    '         1 ",
      "    '         , ",
      "    '         1 ",
      "    '         1 ",
      "    '1 11.111111",
      "    ' )       1 ",
      "    '         1 ",
      "    '         1 ",
      "    '         1 ",
      "    '         1 ",
      "    '         1 ",
      "    ''''''''''''",
      "                ",
      "                ",
      "                "
    ],
    [
      "    '         1 ",
      "    '         1 ",
      "    '         1 ",
      "    '         1 ",
      "    '         1 ",
      "    '1 111111111",
      "    '         1 ",
      "    ' )       1 ",
      "    '         1 ",
      "    '         1 ",
      "    '         1 ",
      "    '         1 ",
      "    ''''''''''''",
      "                ",
      "                ",
      "                "
    ],
    [
      "    '         1 ",
      "    '         1 ",
      "    '         1 ",
      "    '         1 ",
      "    '         1 ",
      "    '11111111111",
      "    '         1 ",
      "    '         1 ",
      "    ' )       1 ",
      "    '         1 ",
      "    '         1 ",
      "    '         1 ",
      "    ''''''''''''",
      "                ",
      "                ",
      "                "
    ]
  ],
  "palette": {
    "palette": [
      {
        "char": "!",
        "block": "immersiveengineering:crate"
      },
      {
        "char": "$",
        "block": "minecraft:barrel[facing=up,open=false]"
      },
      {
        "char": "%",
        "block": "minecraft:coarse_dirt"
      },
      {
        "char": "&",
        "block": "minecraft:gravel"
      },
      {
        "char": "'",
        "block": "minecraft:mud_bricks"
      },
      {
        "char": "(",
        "block": "minecraft:polished_andesite"
      },
      {
        "char": ")",
        "block": "minecraft:polished_andesite_stairs[facing=south,half=bottom,shape=straight,waterlogged=false]"
      },
      {
        "char": "*",
        "block": "kubejs:ruined_smithing_table"
      },
      {
        "char": "+",
        "block": "minecraft:spruce_door[facing=east,half=lower,hinge=left,open=false,powered=false]"
      },
      {
        "char": ",",
        "block": "minecraft:spruce_door[facing=east,half=upper,hinge=left,open=false,powered=false]"
      },
      {
        "char": "-",
        "block": "minecraft:spruce_door[facing=south,half=lower,hinge=left,open=false,powered=false]"
      },
      {
        "char": ".",
        "block": "minecraft:spruce_door[facing=south,half=upper,hinge=left,open=false,powered=false]"
      },
      {
        "char": "/",
        "block": "kubejs:ruined_cauldron"
      },
      {
        "char": "0",
        "block": "tfmg:asphalt"
      },
      {
        "char": "1",
        "block": "tfmg:cinder_block"
      }
    ]
  }
}
