{
  "xsize": 16,
  "zsize": 16,
  "slices": [
    [
      "-------''$------",
      "-----''$--------",
      "---''$----------",
      "-''$------------",
      "'$--------------",
      "----------------",
      "--------------''",
      "------------''$-",
      "----------''$---",
      "--------''$-----",
      "------''$-------",
      "----''$---------",
      "--''$-----------",
      "''$-------------",
      "$---------------",
      "---------------'"
    ],
    [
      "((((((((((((((((",
      "((((((((((((((((",
      "((((((((((((((((",
      "((((((((((((((((",
      "((((((((((((((((",
      "((((((((((((((((",
      "((((((((((((((((",
      "((((((((((((((((",
      "((((((((((((((((",
      "((((((((((((((((",
      "((((((((((((((((",
      "((((((((((((((((",
      "((((((((((((((((",
      "((((((((((((((((",
      "((((((((((((((((",
      "(((((((((((((((("
    ],
    [
      "                ",
      "         ///////",
      "%%%%%           ",
      "%&%%%      !   *",
      "%%%%%           ",
      "%%%%%           ",
      "%%%%%           ",
      "%&%%%           ",
      "%%%%%           ",
      "%%%%%           ",
      "%%%%%           ",
      "                ",
      "                ",
      "....+...........",
      "                ",
      "        ))))))  "
    ],
    [
      "                ",
      "                ",
      "                ",
      "                ",
      "                ",
      "                ",
      "                ",
      "                ",
      "                ",
      "                ",
      "                ",
      "                ",
      "                ",
      "....,...........",
      "                ",
      "        ))))))  "
    ],
    [
      "                ",
      "                ",
      "                ",
      "                ",
      "                ",
      "                ",
      "                ",
      "                ",
      "                ",
      "                ",
      "                ",
      "                ",
      "                ",
      "................",
      "                ",
      "        ))))))  "
    ],
    [
      "                ",
      "                ",
      "                ",
      "                ",
      "                ",
      "                ",
      "                ",
      "                ",
      "                ",
      "                ",
      "                ",
      "                ",
      "                ",
      "................",
      "                ",
      "        ))))))  "
    ]
  ],
  "palette": {
    "palette": [
      {
        "char": "!",
        "block": "farmersdelight:stove[facing=north,lit=false]"
      },
      {
        "char": "$",
        "block": "minecraft:coarse_dirt"
      },
      {
        "char": "%",
        "block": "minecraft:dark_oak_planks"
      },
      {
        "char": "&",
        "block": "minecraft:dark_oak_stairs[facing=south,half=bottom,shape=straight,waterlogged=false]"
      },
      {
        "char": "'",
        "block": "minecraft:gravel"
      },
      {
        "char": "(",
        "block": "minecraft:polished_andesite"
      },
      {
        "char": ")",
        "block": "minecraft:polished_blackstone_bricks"
      },
      {
        "char": "*",
        "block": "kubejs:ruined_smoker[facing=north]"
      },
      {
        "char": "+",
        "block": "minecraft:spruce_door[facing=south,half=lower,hinge=left,open=false,powered=false]"
      },
      {
        "char": ",",
        "block": "minecraft:spruce_door[facing=south,half=upper,hinge=left,open=false,powered=false]"
      },
      {
        "char": "-",
        "block": "tfmg:asphalt"
      },
      {
        "char": ".",
        "block": "tfmg:cinder_block"
      },
      {
        "char": "/",
        "block": "zvhouses:stone_brick_countertop"
      }
    ]
  }
}
