{
  "xsize": 16,
  "zsize": 16,
  "slices": [
    [
      "       $$  $$ !(",
      "       $$  $$ &(",
      "              &(",
      "              !(",
      "       $$  $$ !(",
      "       $$  $$ !(",
      "              !(",
      "              &(",
      "!!!!!!!!!!!!!!&(",
      "%%%%%%%%%%%%%%%%",
      "                ",
      "                ",
      "                ",
      "                ",
      "                ",
      "                "
    ],
    [
      "       $$  $$ !(",
      "       $$  $$ &(",
      "              &(",
      "              !(",
      "       $$  $$ !(",
      "       $$  $$ !(",
      "              !(",
      "              &(",
      "!!!!!!!!!!!!!!&(",
      "%%%%%%%%%%%%%%%%",
      "                ",
      "                ",
      "                ",
      "                ",
      "                ",
      "                "
    ],
    [
      "              !(",
      "              &(",
      "              &(",
      "              !(",
      "              !(",
      "              !(",
      "              !(",
      "              &(",
      "!!!!!!!!!!!!!!&(",
      "%%%%%%%%%%%%%%%%",
      "                ",
      "                ",
      "                ",
      "                ",
      "                ",
      "                "
    ],
    [
      "              !(",
      "              &(",
      "              &(",
      "              !(",
      "              !(",
      "              !(",
      "              !(",
      "              &(",
      "!!!!!!!!!!!!!!&(",
      "%%%%%%%%%%%%%%%%",
      "                ",
      "                ",
      "                ",
      "                ",
      "                ",
      "                "
    ],
    [
      "              !(",
      "              &(",
      "              &(",
      "              !(",
      "              !(",
      "              !(",
      "              !(",
      "              &(",
      "!!!!!!!!!!!!!!&(",
      "%%%%%%%%%%%%%%%%",
      "                ",
      "                ",
      "                ",
      "                ",
      "                ",
      "                "
    ],
    [
      "              !(",
      "              &(",
      "              &(",
      "              !(",
      "              !(",
      "              !(",
      "              !(",
      "              &(",
      "!!!!!!!!!!!!!!&(",
      "''''''''''''''''",
      "''''''''''''''''",
      "''''''''''''''''",
      "''''''''''''''''",
      "''''''''''''''''",
      "''''''''''''''''",
      "''''''''''''''''"
    ]
  ],
  "palette": {
    "palette": [
      {
        "char": "!",
        "block": "immersiveengineering:concrete_reinforced"
      },
      {
        "char": "$",
        "block": "minecraft:black_concrete"
      },
      {
        "char": "%",
        "block": "minecraft:mud_bricks"
      },
      {
        "char": "&",
        "block": "minecraft:polished_deepslate"
      },
      {
        "char": "'",
        "block": "minecraft:smooth_stone"
      },
      {
        "char": "(",
        "block": "tfmg:cinder_block"
      }
    ]
  }
}
