{
  "xsize": 16,
  "zsize": 16,
  "slices": [
    [
      "................",
      "................",
      "................",
      "................",
      "................",
      "................",
      "...........))&..",
      ".........))&....",
      ".......))&......",
      ".....))&........",
      "...))&..........",
      ".))&............",
      ")&..............",
      "................",
      "..............))",
      "............))&."
    ],
    [
      "                ",
      "                ",
      "     -     -    ",
      "                ",
      "                ",
      "                ",
      "000000000000000 ",
      "000000000000000 ",
      "0000000000000000",
      "0000000000000000",
      "0000000000000000",
      "0000000000000000",
      "0000000000000000",
      "0000000000000000",
      "0000000000000000",
      "0000000000000000"
    ],
    [
      "                ",
      "                ",
      "                ",
      "                ",
      "                ",
      "                ",
      "$$$$$$$$$$$$$$$ ",
      " 1   1        $ ",
      " 1   1        $/",
      " 1   1 %%  %% */",
      " 1   1 %%  %% */",
      " 1   1        $/",
      " 1   1        $/",
      " 1   1 %%  %% $/",
      " +   1 %%  %% ''",
      " 1   1        $/"
    ],
    [
      "                ",
      "                ",
      "                ",
      "                ",
      "                ",
      "                ",
      "$$$$$$$$$$$$$$$ ",
      " 1   1        $ ",
      " 1   1        $/",
      " 1   1 %%  %% */",
      " 1   1 %%  %% */",
      " 1   1        $/",
      " 1   1        $/",
      " 1   1 %%  %% $/",
      " ,   1 %%  %% ((",
      " 1   1        $/"
    ],
    [
      "                ",
      "                ",
      "                ",
      "                ",
      "                ",
      "                ",
      "$$$$$$$$$$$$$$$ ",
      " 1   1        $ ",
      " 1   1        $/",
      " 1   1 %%  %% */",
      " 1   1 %%  %% */",
      " 1   1        $/",
      " 1   1        $/",
      " 1   1 %%  %% $/",
      " 1   1 %%  %% $/",
      " 1   1        $/"
    ],
    [
      "                ",
      "                ",
      "                ",
      "                ",
      "                ",
      "                ",
      "$$$$$$$$$$$$$$$ ",
      " 1   1        $ ",
      " 1   1        $/",
      " 1   1 !%  !% */",
      " 1   1 %%  %% */",
      " 1   1        $/",
      " 1   1        $/",
      " 1   1 !%  !% $/",
      " 1   1 %%  %% $/",
      " 1   1        $/"
    ]
  ],
  "palette": {
    "palette": [
      {
        "char": "!",
        "block": "create:red_nixie_tube"
      },
      {
        "char": "$",
        "block": "immersiveengineering:concrete_reinforced"
      },
      {
        "char": "%",
        "block": "minecraft:black_concrete"
      },
      {
        "char": "&",
        "block": "minecraft:coarse_dirt"
      },
      {
        "char": "'",
        "block": "minecraft:dark_oak_door[facing=east,half=lower,hinge=left,open=false,powered=false]"
      },
      {
        "char": "(",
        "block": "minecraft:dark_oak_door[facing=east,half=upper,hinge=left,open=false,powered=false]"
      },
      {
        "char": ")",
        "block": "minecraft:gravel"
      },
      {
        "char": "*",
        "block": "minecraft:polished_deepslate"
      },
      {
        "char": "+",
        "block": "minecraft:spruce_door[facing=east,half=lower,hinge=left,open=false,powered=false]"
      },
      {
        "char": ",",
        "block": "minecraft:spruce_door[facing=east,half=upper,hinge=left,open=false,powered=false]"
      },
      {
        "char": "-",
        "block": "minecraft:white_concrete"
      },
      {
        "char": ".",
        "block": "tfmg:asphalt"
      },
      {
        "char": "/",
        "block": "tfmg:cinder_block"
      },
      {
        "char": "0",
        "block": "tfmg:factory_floor"
      },
      {
        "char": "1",
        "block": "the_wasteland_reworked:cut_lead_plating"
      }
    ]
  }
}
