{
  "xsize": 16,
  "zsize": 16,
  "slices": [
    [
      "0000000000++'000",
      "00000000++'00000",
      "000000++'0000000",
      "0000++'000000000",
      "00++'00000000000",
      "++'0000000000000",
      "'000000000000000",
      "000000000000000+",
      "0000000000000++'",
      "00000000000++'00",
      "000000000++'0000",
      "0000000++'000000",
      "00000++'00000000",
      "000++'000000000*",
      "0++'0000000000**",
      "+'00000000000** "
    ],
    [
      "2222222222222222",
      "2222222222222222",
      "2222222222222222",
      "2222222222222222",
      "2222222222222222",
      "2222222222222222",
      "222222222222++++",
      "22222222222++++2",
      "2222222222+2+++2",
      "2222222+++22+2  ",
      "2222222+++2+2   ",
      "2222222++++2    ",
      "222222222+2     ",
      "22222222+2      ",
      "2222222+2+++    ",
      "222222222+++    "
    ],
    [
      " 3   3        $1",
      " 3   3        ,1",
      " 3   3 %%  %% ,1",
      " 3   3 %%  %% $1",
      " 3   3  -     $1",
      " 3   3        $1",
      " 3   3      +++1",
      "333.333333.++++1",
      " 3   3      +++1",
      " 3   3 +++  +   ",
      " 3   3 +++3+3   ",
      " 3   3 ++++     ",
      " 3   3 ( +&     ",
      " 3   3 3+3      ",
      " 3   3 + +++    ",
      " 3   3   +++    "
    ],
    [
      " 3   3        $1",
      " 3   3        ,1",
      " 3   3 %%  %% ,1",
      " 3   3 %%  %% $1",
      " 3   3        $1",
      " 3   3        $1",
      " 3   3      + $1",
      "333/333333/+3$+1",
      " 3   3        $1",
      " 3   3 +++      ",
      " 3   3 +++3+3   ",
      " 3   3 ++++     ",
      " 3   3 ) +      ",
      " 3   3 3+3      ",
      " 3   3 + +++    ",
      " 3   3   +++    "
    ],
    [
      " 3   3        $1",
      " 3   3        ,1",
      " 3   3 %%  %% ,1",
      " 3   3 %%  %% $1",
      " 3   3        $1",
      " 3   3        $1",
      " 3   3      + $1",
      "33333333333+33+1",
      " 3   3        $1",
      " 3   3          ",
      " 3   3 3$33,3   ",
      " 3   3 3  +     ",
      " 3   3 3 +      ",
      " 3   3 3+3      ",
      " 3   3 + +++    ",
      " 3   3   +++    "
    ],
    [
      " 3   3        $1",
      " 3   3        ,1",
      " 3   3 !%  !% ,1",
      " 3   3 %%  %% $1",
      " 3   3        $1",
      " 3   3        $1",
      " 3   3        $1",
      "33333333333+33+1",
      " 3   3        $1",
      " 3   3          ",
      " 3   3 333333   ",
      " 3   3 33333    ",
      " 3   3 33+3     ",
      " 3   3 333      ",
      " 3   3 + +++    ",
      " 3   3   +++    "
    ]
  ],
  "palette": {
    "palette": [
      {
        "char": "!",
        "block": "create:red_nixie_tube"
      },
      {
        "char": "$",
        "block": "immersiveengineering:concrete_reinforced"
      },
      {
        "char": "%",
        "block": "minecraft:black_concrete"
      },
      {
        "char": "&",
        "block": "minecraft:chest[facing=west,type=single,waterlogged=false]",
        "tag": {
          "id": "minecraft:chest",
          "LootTable": "infinite_domain:chests/wasteland_data"
        }
      },
      {
        "char": "'",
        "block": "minecraft:coarse_dirt"
      },
      {
        "char": "(",
        "block": "minecraft:dark_oak_door[facing=east,half=lower,hinge=left,open=false,powered=false]"
      },
      {
        "char": ")",
        "block": "minecraft:dark_oak_door[facing=east,half=upper,hinge=left,open=false,powered=false]"
      },
      {
        "char": "*",
        "block": "minecraft:deepslate"
      },
      {
        "char": "+",
        "block": "minecraft:gravel"
      },
      {
        "char": ",",
        "block": "minecraft:polished_deepslate"
      },
      {
        "char": "-",
        "block": "minecraft:spawner",
        "tag": {
          "id": "minecraft:mob_spawner",
          "Delay": 200,
          "MinSpawnDelay": 240,
          "MaxSpawnDelay": 720,
          "SpawnCount": 2,
          "MaxNearbyEntities": 7,
          "RequiredPlayerRange": 14,
          "SpawnRange": 4,
          "SpawnData": {
            "entity": {
              "id": "the_wasteland_reworked:irradiated"
            }
          },
          "SpawnPotentials": [
            {
              "weight": 1,
              "data": {
                "entity": {
                  "id": "the_wasteland_reworked:irradiated"
                }
              }
            }
          ]
        }
      },
      {
        "char": ".",
        "block": "minecraft:spruce_door[facing=south,half=lower,hinge=left,open=false,powered=false]"
      },
      {
        "char": "/",
        "block": "minecraft:spruce_door[facing=south,half=upper,hinge=left,open=false,powered=false]"
      },
      {
        "char": "0",
        "block": "tfmg:asphalt"
      },
      {
        "char": "1",
        "block": "tfmg:cinder_block"
      },
      {
        "char": "2",
        "block": "tfmg:factory_floor"
      },
      {
        "char": "3",
        "block": "the_wasteland_reworked:cut_lead_plating"
      }
    ]
  }
}
