{
  "xsize": 16,
  "zsize": 16,
  "slices": [
    [
      "---------(('----",
      "-------(('------",
      "-----(('--------",
      "---(('----------",
      "-(('------------",
      "('--------------",
      "----------------",
      "--------------((",
      "------------(('-",
      "----------(('---",
      "--------(('-----",
      "------(('-------",
      "----(('---------",
      "--(('-----------",
      "(('-------------",
      "'---------------"
    ],
    [
      "                ",
      "                ",
      "                ",
      "++ ++++         ",
      "++ ++++         ",
      "                ",
      "                ",
      "............    ",
      "............    ",
      "............    ",
      "............    ",
      "............    ",
      "............    ",
      "............    ",
      "............    ",
      "............    "
    ],
    [
      "                ",
      ",, ,,,,         ",
      ",, ,,,,         ",
      "                ",
      "                ",
      "                ",
      "                ",
      ")&&&&&&&&&&&    ",
      "           &    ",
      "           &    ",
      "           &    ",
      "   $$$  $$$&    ",
      "   $$$  $$$&    ",
      "   $$$  $$$&    ",
      "   $$$  $$$&    ",
      "   $$$  $$$&    "
    ],
    [
      "%% %%%%         ",
      "%% %%%%         ",
      "                ",
      "                ",
      "                ",
      "                ",
      "                ",
      "*&&&&&&&&&&&    ",
      "           &    ",
      "           &    ",
      "           &    ",
      "   $$$  $$$&    ",
      "   $$$  $$$&    ",
      "   $$$  $$$&    ",
      "   $$$  $$$&    ",
      "   $$$  $$$&    "
    ],
    [
      "                ",
      "                ",
      "                ",
      "                ",
      "                ",
      "                ",
      "                ",
      "&&&&&&&&&&&&    ",
      "           &    ",
      "           &    ",
      "           &    ",
      "   $$$  $$$&    ",
      "   $$$  $$$&    ",
      "   $$$  $$$&    ",
      "   $$$  $$$&    ",
      "   $$$  $$$&    "
    ],
    [
      "                ",
      "                ",
      "                ",
      "                ",
      "                ",
      "                ",
      "                ",
      "&&&&&&&&&&&&    ",
      "           &    ",
      "           &    ",
      "           &    ",
      "   $$$  $$$!    ",
      "   $$$  $$$!    ",
      "   $$$  $$$&    ",
      "   $$$  $$$&    ",
      "   $$$  $$$&    "
    ]
  ],
  "palette": {
    "palette": [
      {
        "char": "!",
        "block": "create:framed_glass"
      },
      {
        "char": "$",
        "block": "immersiveengineering:capacitor_hv"
      },
      {
        "char": "%",
        "block": "minecraft:black_stained_glass"
      },
      {
        "char": "&",
        "block": "minecraft:bricks"
      },
      {
        "char": "'",
        "block": "minecraft:coarse_dirt"
      },
      {
        "char": "(",
        "block": "minecraft:gravel"
      },
      {
        "char": ")",
        "block": "minecraft:iron_door[facing=north,half=lower,hinge=left,open=false,powered=false]"
      },
      {
        "char": "*",
        "block": "minecraft:iron_door[facing=north,half=upper,hinge=left,open=false,powered=false]"
      },
      {
        "char": "+",
        "block": "minecraft:polished_blackstone"
      },
      {
        "char": ",",
        "block": "oritech:big_solar_panel_block"
      },
      {
        "char": "-",
        "block": "tfmg:asphalt"
      },
      {
        "char": ".",
        "block": "tfmg:factory_floor"
      }
    ]
  }
}
