{
  "xsize": 16,
  "zsize": 16,
  "slices": [
    [
      "******''&*******",
      "****''&*********",
      "**''&***********",
      "''&*************",
      "&***************",
      "***************'",
      "*************''&",
      "***********''&**",
      "*********''&****",
      "*******''&******",
      "*****''&********",
      "***''&**********",
      "*''&************",
      "'&**************",
      "****************",
      "**************''"
    ],
    [
      "                ",
      "                ",
      "                ",
      "((( (((( (((( ((",
      "((( (((( (((( ((",
      "                ",
      "                ",
      "          ++++++",
      "          ++++++",
      "          ++++++",
      "          ++++++",
      "          ++++++",
      "          ++++++",
      "          ++++++",
      "          ++++++",
      "          ++++++"
    ],
    [
      "                ",
      "))) )))) )))) ))",
      "))) )))) )))) ))",
      "                ",
      "                ",
      "                ",
      "                ",
      "          %%%%%%",
      "          %     ",
      "          %     ",
      "      ,   %     ",
      "          %  !!!",
      "          %  !!!",
      "          %  !!!",
      "          %  !!!",
      "          %  !!!"
    ],
    [
      "$$$ $$$$ $$$$ $$",
      "$$$ $$$$ $$$$ $$",
      "                ",
      "                ",
      "                ",
      "                ",
      "                ",
      "          %%%%%%",
      "          %     ",
      "          %     ",
      "          %     ",
      "          %  !!!",
      "          %  !!!",
      "          %  !!!",
      "          %  !!!",
      "          %  !!!"
    ],
    [
      "                ",
      "                ",
      "                ",
      "                ",
      "                ",
      "                ",
      "                ",
      "          %%%%%%",
      "          %     ",
      "          %     ",
      "          %     ",
      "          %  !!!",
      "          %  !!!",
      "          %  !!!",
      "          %  !!!",
      "          %  !!!"
    ],
    [
      "                ",
      "                ",
      "                ",
      "                ",
      "                ",
      "                ",
      "                ",
      "          %%%%%%",
      "          %     ",
      "          %     ",
      "          %     ",
      "          %  !!!",
      "          %  !!!",
      "          %  !!!",
      "          %  !!!",
      "          %  !!!"
    ]
  ],
  "palette": {
    "palette": [
      {
        "char": "!",
        "block": "immersiveengineering:capacitor_hv"
      },
      {
        "char": "$",
        "block": "minecraft:black_stained_glass"
      },
      {
        "char": "%",
        "block": "minecraft:bricks"
      },
      {
        "char": "&",
        "block": "minecraft:coarse_dirt"
      },
      {
        "char": "'",
        "block": "minecraft:gravel"
      },
      {
        "char": "(",
        "block": "minecraft:polished_blackstone"
      },
      {
        "char": ")",
        "block": "oritech:big_solar_panel_block"
      },
      {
        "char": "*",
        "block": "tfmg:asphalt"
      },
      {
        "char": "+",
        "block": "tfmg:factory_floor"
      },
      {
        "char": ",",
        "block": "the_wasteland_reworked:radio"
      }
    ]
  }
}
