{
  "xsize": 16,
  "zsize": 16,
  "slices": [
    [
      "                ",
      "                ",
      "                ",
      "                ",
      "                ",
      "                ",
      "                ",
      "                ",
      "      %%%%%%%%%%",
      "      %         ",
      "      %         ",
      "      !  $$$  $$",
      "      !  $$$  $$",
      "      %  $$$  $$",
      "      %  $$$  $$",
      "      %  $$$  $$"
    ],
    [
      "                ",
      "                ",
      "                ",
      "                ",
      "                ",
      "                ",
      "                ",
      "                ",
      "      %%%%%%%%%%",
      "      %         ",
      "      %         ",
      "      %  $$$  $$",
      "      %  $$$  $$",
      "      %  $$$  $$",
      "      %  $$$  $$",
      "      %  $$$  $$"
    ],
    [
      "                ",
      "                ",
      "                ",
      "                ",
      "                ",
      "                ",
      "                ",
      "                ",
      "      %%%%%%%%%%",
      "      %         ",
      "      %         ",
      "      %         ",
      "      %         ",
      "      %         ",
      "      %         ",
      "      %         "
    ],
    [
      "                ",
      "                ",
      "                ",
      "                ",
      "                ",
      "                ",
      "                ",
      "                ",
      "      %%%%%%%%%%",
      "      %         ",
      "      %         ",
      "      %         ",
      "      %         ",
      "      %         ",
      "      %         ",
      "      %         "
    ],
    [
      "                ",
      "                ",
      "                ",
      "                ",
      "                ",
      "                ",
      "                ",
      "                ",
      "      %%%%%%%%%%",
      "      %         ",
      "      %         ",
      "      %         ",
      "      %         ",
      "      %         ",
      "      %         ",
      "      %         "
    ],
    [
      "                ",
      "                ",
      "                ",
      "                ",
      "                ",
      "                ",
      "                ",
      "                ",
      "      &&&&&&&&&&",
      "      &&&&&&&&&&",
      "      &&&&&&&&&&",
      "      &&&&&&&&&&",
      "      &&&&&&&&&&",
      "      &&&&&&&&&&",
      "      &&&&&&&&&&",
      "      &&&&&&&&&&"
    ]
  ],
  "palette": {
    "palette": [
      {
        "char": "!",
        "block": "create:framed_glass"
      },
      {
        "char": "$",
        "block": "immersiveengineering:capacitor_hv"
      },
      {
        "char": "%",
        "block": "minecraft:bricks"
      },
      {
        "char": "&",
        "block": "minecraft:smooth_stone"
      }
    ]
  }
}
