{
  "xsize": 16,
  "zsize": 16,
  "slices": [
    [
      "                ",
      "                ",
      "    '''''''     ",
      "    '''''''     ",
      "   ('''''''(((((",
      "   (           (",
      "   (           (",
      "   (           (",
      "   (           (",
      "   (           (",
      "   (           (",
      "   (          !(",
      "   (           (",
      "   (           (",
      "   (           (",
      "  &((((((((((((("
    ],
    [
      "                ",
      "                ",
      "                ",
      "  '$           %",
      "  '$(((((((((((%",
      "  '$           %",
      "  '$           %",
      "  '$           %",
      "  '$           %",
      "  '$           %",
      "  '$           %",
      "  '$          !%",
      "  '$           %",
      "  '$           %",
      "  '$           %",
      "  '$(((((((((((%"
    ],
    [
      "                ",
      "                ",
      "                ",
      "    $         % ",
      "    $(((((((((% ",
      "    $         % ",
      "    $         % ",
      "    $         % ",
      "    $         % ",
      "    $         % ",
      "    $         % ",
      "    $         ! ",
      "    $         % ",
      "    $         % ",
      "    $         % ",
      "    $(((((((((% "
    ],
    [
      "                ",
      "                ",
      "                ",
      "     $       %  ",
      "     $(((((((%  ",
      "     $       %  ",
      "     $       %  ",
      "     $       %  ",
      "     $       %  ",
      "     $       %  ",
      "     $       %  ",
      "     $       %! ",
      "     $       %  ",
      "     $       %  ",
      "     $       %  ",
      "     $(((((((%  "
    ],
    [
      "                ",
      "                ",
      "                ",
      "      $     %   ",
      "      $(((((%   ",
      "      $     %   ",
      "      $     %   ",
      "      $     %   ",
      "      $     %   ",
      "      $     %   ",
      "      $     %   ",
      "      $     % ! ",
      "      $     %   ",
      "      $     %   ",
      "      $     %   ",
      "      $(((((%   "
    ],
    [
      "                ",
      "                ",
      "                ",
      "       $   %    ",
      "       $(((%    ",
      "       $   %    ",
      "       $   %    ",
      "       $   %    ",
      "       $   %    ",
      "       $   %    ",
      "       $   %    ",
      "       $   %  ! ",
      "       $   %    ",
      "       $   %    ",
      "       $   %    ",
      "       $(((%    "
    ]
  ],
  "palette": {
    "palette": [
      {
        "char": "!",
        "block": "minecraft:bricks"
      },
      {
        "char": "$",
        "block": "minecraft:dark_oak_stairs[facing=east,half=bottom,shape=straight,waterlogged=false]"
      },
      {
        "char": "%",
        "block": "minecraft:dark_oak_stairs[facing=west,half=bottom,shape=straight,waterlogged=false]"
      },
      {
        "char": "&",
        "block": "minecraft:weathered_copper"
      },
      {
        "char": "'",
        "block": "minecraft:weathered_cut_copper_slab[type=bottom,waterlogged=false]"
      },
      {
        "char": "(",
        "block": "the_wasteland_reworked:decayed_planks"
      }
    ]
  }
}
