{
  "xsize": 16,
  "zsize": 16,
  "slices": [
    [
      "                ",
      "                ",
      "                ",
      "                ",
      "                ",
      "                ",
      "                ",
      "                ",
      "                ",
      "                ",
      "                ",
      "                ",
      "                ",
      "                ",
      "                ",
      "                "
    ],
    [
      "5555555555555555",
      "5555555555555555",
      "5555555555555555",
      "5555555555555555",
      "5555555555555555",
      "5555555555555555",
      "5555555555555555",
      "5555555555555555",
      "5555555555555555",
      "5555555555555555",
      "5555555555555555",
      "5555555555555555",
      "5555555555555555",
      "5555555555555555",
      "5555555555555555",
      "5555555555555555"
    ],
    [
      "!!!!!!!!!!!!!!!!",
      "               !",
      " .   22   22   !",
      "     3    3    !",
      "               !",
      "!              !",
      "&              &",
      "'          / 6 '",
      "               !",
      "!   44444440444!",
      "               !",
      "     $  $   $  !",
      "     $  $   %  !",
      "     $  $   $  !",
      "               !",
      "!!!!!!*+!!!!!!!!"
    ],
    [
      "!!!!!!!!!!!!!!!!",
      "               !",
      "               !",
      " .             !",
      "               !",
      "!              !",
      "(              (",
      ")              )",
      "               !",
      "!   44444441444!",
      "               !",
      "     $  $   $  !",
      "     $  $   $  !",
      "     $  $   $  !",
      "               !",
      "!!!!!!,-!!!!!!!!"
    ],
    [
      "!!!!!!!!!!!!!!!!",
      "               !",
      "               !",
      "               !",
      " .             !",
      "!              !",
      "                ",
      "                ",
      "               !",
      "!   44444444444!",
      "               !",
      "     $  $   $  !",
      "     $  $   $  !",
      "     $  $   $  !",
      "               !",
      "!!!!!!  !!!!!!!!"
    ],
    [
      "!!!!!!!!!!!!!!!!",
      "               !",
      "               !",
      "               !",
      "               !",
      "!.             !",
      "               !",
      "               !",
      "               !",
      "!   44444444444!",
      "               !",
      "               !",
      "               !",
      "               !",
      "               !",
      "!!!!!!!!!!!!!!!!"
    ]
  ],
  "palette": {
    "palette": [
      {
        "char": "!",
        "block": "immersiveengineering:concrete_reinforced"
      },
      {
        "char": "$",
        "block": "minecraft:bookshelf"
      },
      {
        "char": "%",
        "block": "minecraft:chest[facing=north,type=single,waterlogged=false]",
        "tag": {
          "id": "minecraft:chest",
          "LootTable": "infinite_domain:chests/wasteland_data"
        }
      },
      {
        "char": "&",
        "block": "minecraft:iron_door[facing=east,half=lower,hinge=left,open=false,powered=false]"
      },
      {
        "char": "'",
        "block": "minecraft:iron_door[facing=east,half=lower,hinge=right,open=false,powered=false]"
      },
      {
        "char": "(",
        "block": "minecraft:iron_door[facing=east,half=upper,hinge=left,open=false,powered=false]"
      },
      {
        "char": ")",
        "block": "minecraft:iron_door[facing=east,half=upper,hinge=right,open=false,powered=false]"
      },
      {
        "char": "*",
        "block": "minecraft:iron_door[facing=south,half=lower,hinge=left,open=false,powered=false]"
      },
      {
        "char": "+",
        "block": "minecraft:iron_door[facing=south,half=lower,hinge=right,open=false,powered=false]"
      },
      {
        "char": ",",
        "block": "minecraft:iron_door[facing=south,half=upper,hinge=left,open=false,powered=false]"
      },
      {
        "char": "-",
        "block": "minecraft:iron_door[facing=south,half=upper,hinge=right,open=false,powered=false]"
      },
      {
        "char": ".",
        "block": "minecraft:polished_andesite_stairs[facing=south,half=bottom,shape=straight,waterlogged=false]"
      },
      {
        "char": "/",
        "block": "minecraft:spawner",
        "tag": {
          "id": "minecraft:mob_spawner",
          "Delay": 220,
          "MinSpawnDelay": 240,
          "MaxSpawnDelay": 720,
          "SpawnCount": 4,
          "MaxNearbyEntities": 12,
          "RequiredPlayerRange": 14,
          "SpawnRange": 4,
          "SpawnData": {
            "entity": {
              "id": "minecraft:pillager"
            }
          },
          "SpawnPotentials": [
            {
              "weight": 1,
              "data": {
                "entity": {
                  "id": "minecraft:pillager"
                }
              }
            }
          ]
        }
      },
      {
        "char": "0",
        "block": "minecraft:spruce_door[facing=south,half=lower,hinge=left,open=false,powered=false]"
      },
      {
        "char": "1",
        "block": "minecraft:spruce_door[facing=south,half=upper,hinge=left,open=false,powered=false]"
      },
      {
        "char": "2",
        "block": "minecraft:spruce_slab[type=bottom,waterlogged=false]"
      },
      {
        "char": "3",
        "block": "minecraft:spruce_stairs[facing=north,half=bottom,shape=straight,waterlogged=false]"
      },
      {
        "char": "4",
        "block": "tfmg:cinder_block"
      },
      {
        "char": "5",
        "block": "tfmg:factory_floor"
      },
      {
        "char": "6",
        "block": "the_wasteland_reworked:radio"
      }
    ]
  }
}
