{
  "xsize": 16,
  "zsize": 16,
  "slices": [
    [
      " 222,    ,222   ",
      "$$$$+$'($+$$$$$+",
      "    +    +     +",
      "               $",
      " 22         7  $",
      " 4             $",
      "               $",
      "666666006666666$",
      "         6     $",
      "         622   $",
      "         64    $",
      "      &  .     $",
      "         6 %%% $",
      "         6 %%% $",
      "$$$$$$$$$$$$$$$$",
      "                "
    ],
    [
      "    ,    ,      ",
      "5!!!5$)*$5!!!5$+",
      "    +    +     +",
      "               $",
      "               $",
      "               $",
      "               $",
      "666666116666666$",
      "         6     $",
      "         6     $",
      "         6     !",
      "         /     !",
      "         6 %%% $",
      "         6 %%% $",
      "$$$$$$$$$$$$$$$$",
      "                "
    ],
    [
      "    ,    ,      ",
      "5!!!5$  $5!!!5$+",
      "    +    +     +",
      "               $",
      "               $",
      "               $",
      "               $",
      "666666666666666$",
      "         6     $",
      "         6     $",
      "         6     !",
      "         6     !",
      "         6 %%% $",
      "         6 %%% $",
      "$$$$$$$$$$$$$$$$",
      "                "
    ],
    [
      " 333,    ,333   ",
      "$$$$+$$$$+$$$$$+",
      "    +    +     +",
      "               $",
      "               $",
      "               $",
      "               $",
      "666666666666666$",
      "         6     $",
      "         6     $",
      "         6     $",
      "         6     $",
      "         6     $",
      "         6     $",
      "$$$$$$$$$$$$$$$$",
      "                "
    ],
    [
      "    ,    ,      ",
      "$$$$+$$$$+$$$$$+",
      "    +    +     +",
      "               $",
      "               $",
      "               $",
      "               $",
      "               $",
      "               $",
      "               $",
      "               $",
      "               $",
      "               $",
      "               $",
      "$$$$$$$$$$$$$$$$",
      "                "
    ],
    [
      "    ------      ",
      "$$$$------$$$$$+",
      "    ------     +",
      "               $",
      "               $",
      "               $",
      "               $",
      "               $",
      "               $",
      "               $",
      "               $",
      "               $",
      "               $",
      "               $",
      "$$$$$$$$$$$$$$$$",
      "                "
    ]
  ],
  "palette": {
    "palette": [
      {
        "char": "!",
        "block": "create:framed_glass"
      },
      {
        "char": "$",
        "block": "immersiveengineering:concrete_brick"
      },
      {
        "char": "%",
        "block": "immersiveengineering:sheetmetal_steel"
      },
      {
        "char": "&",
        "block": "minecraft:barrel[facing=up,open=false]"
      },
      {
        "char": "'",
        "block": "minecraft:iron_door[facing=north,half=lower,hinge=left,open=false,powered=false]"
      },
      {
        "char": "(",
        "block": "minecraft:iron_door[facing=north,half=lower,hinge=right,open=false,powered=false]"
      },
      {
        "char": ")",
        "block": "minecraft:iron_door[facing=north,half=upper,hinge=left,open=false,powered=false]"
      },
      {
        "char": "*",
        "block": "minecraft:iron_door[facing=north,half=upper,hinge=right,open=false,powered=false]"
      },
      {
        "char": "+",
        "block": "minecraft:mud_bricks"
      },
      {
        "char": ",",
        "block": "minecraft:polished_blackstone_bricks"
      },
      {
        "char": "-",
        "block": "minecraft:smooth_stone_slab[type=top,waterlogged=false]"
      },
      {
        "char": ".",
        "block": "minecraft:spruce_door[facing=east,half=lower,hinge=left,open=false,powered=false]"
      },
      {
        "char": "/",
        "block": "minecraft:spruce_door[facing=east,half=upper,hinge=left,open=false,powered=false]"
      },
      {
        "char": "0",
        "block": "minecraft:spruce_door[facing=south,half=lower,hinge=left,open=false,powered=false]"
      },
      {
        "char": "1",
        "block": "minecraft:spruce_door[facing=south,half=upper,hinge=left,open=false,powered=false]"
      },
      {
        "char": "2",
        "block": "minecraft:spruce_slab[type=bottom,waterlogged=false]"
      },
      {
        "char": "3",
        "block": "minecraft:spruce_slab[type=top,waterlogged=false]"
      },
      {
        "char": "4",
        "block": "minecraft:spruce_stairs[facing=north,half=bottom,shape=straight,waterlogged=false]"
      },
      {
        "char": "5",
        "block": "minecraft:stripped_spruce_log[axis=y]"
      },
      {
        "char": "6",
        "block": "tfmg:cinder_block"
      },
      {
        "char": "7",
        "block": "the_wasteland_reworked:radio"
      }
    ]
  }
}
