{
  "xsize": 16,
  "zsize": 16,
  "slices": [
    [
      "                ",
      "                ",
      "                ",
      "                ",
      "                ",
      "                ",
      "                ",
      "                ",
      "                ",
      "                ",
      "                ",
      "                ",
      "                ",
      "                ",
      "                ",
      "                "
    ],
    [
      " ............   ",
      " ............   ",
      " ............   ",
      " ............   ",
      " ............   ",
      ".............   ",
      ".............   ",
      ".............   ",
      ".............   ",
      ".............   ",
      " ............   ",
      " ............   ",
      " ............   ",
      " ............   ",
      " ............   ",
      " ............   "
    ],
    [
      " !          !   ",
      " ! $$$ $$$  !   ",
      " ! $$$ $$$  !   ",
      " !          !   ",
      " ! $$$ $$$  !   ",
      "!! $$$ $$$  !   ",
      " '          !   ",
      " (          !   ",
      " !----+-----!   ",
      "!!          !   ",
      " !          !   ",
      " ! $$$ $$$  !   ",
      " ! $$$ $&$  !   ",
      " !          !   ",
      " ! %%%%%%%% !   ",
      " !          !   "
    ],
    [
      " !          !   ",
      " ! $$$ $$$  !   ",
      " ! $$$ $$$  !   ",
      " !          !   ",
      " ! $$$ $$$  !   ",
      "!! $$$ $$$  !   ",
      " )          !   ",
      " *          !   ",
      " !----,-----!   ",
      "!!          !   ",
      " !          !   ",
      " ! $$$ $$$  !   ",
      " ! $$$ $$$  !   ",
      " !          !   ",
      " !          !   ",
      " !          !   "
    ],
    [
      " !          !   ",
      " ! $$$ $$$  !   ",
      " ! $$$ $$$  !   ",
      " !          !   ",
      " ! $$$ $$$  !   ",
      "!! $$$ $$$  !   ",
      "            !   ",
      "            !   ",
      " !----------!   ",
      "!!          !   ",
      " !          !   ",
      " ! $$$ $$$  !   ",
      " ! $$$ $$$  !   ",
      " !          !   ",
      " !          !   ",
      " !          !   "
    ],
    [
      " !          !   ",
      " !          !   ",
      " !          !   ",
      " !          !   ",
      " !          !   ",
      "!!          !   ",
      " !          !   ",
      " !          !   ",
      " !----------!   ",
      "!!          !   ",
      " !          !   ",
      " !          !   ",
      " !          !   ",
      " !          !   ",
      " !          !   ",
      " !          !   "
    ]
  ],
  "palette": {
    "palette": [
      {
        "char": "!",
        "block": "immersiveengineering:concrete_reinforced"
      },
      {
        "char": "$",
        "block": "immersiveengineering:crate"
      },
      {
        "char": "%",
        "block": "immersiveengineering:sheetmetal_steel"
      },
      {
        "char": "&",
        "block": "minecraft:chest[facing=east,type=single,waterlogged=false]",
        "tag": {
          "id": "minecraft:chest",
          "LootTable": "infinite_domain:chests/wasteland_military"
        }
      },
      {
        "char": "'",
        "block": "minecraft:iron_door[facing=east,half=lower,hinge=left,open=false,powered=false]"
      },
      {
        "char": "(",
        "block": "minecraft:iron_door[facing=east,half=lower,hinge=right,open=false,powered=false]"
      },
      {
        "char": ")",
        "block": "minecraft:iron_door[facing=east,half=upper,hinge=left,open=false,powered=false]"
      },
      {
        "char": "*",
        "block": "minecraft:iron_door[facing=east,half=upper,hinge=right,open=false,powered=false]"
      },
      {
        "char": "+",
        "block": "minecraft:spruce_door[facing=south,half=lower,hinge=left,open=false,powered=false]"
      },
      {
        "char": ",",
        "block": "minecraft:spruce_door[facing=south,half=upper,hinge=left,open=false,powered=false]"
      },
      {
        "char": "-",
        "block": "tfmg:cinder_block"
      },
      {
        "char": ".",
        "block": "tfmg:factory_floor"
      }
    ]
  }
}
