{
  "xsize": 16,
  "zsize": 16,
  "slices": [
    [
      "                ",
      "                ",
      "                ",
      "                ",
      "                ",
      "                ",
      "                ",
      "                ",
      "                ",
      "                ",
      "                ",
      "                ",
      "                ",
      "                ",
      "                ",
      "                "
    ],
    [
      "3333333333333333",
      "3333333333333333",
      "3333333333333333",
      "3333333333333333",
      "3333333333333333",
      "3333333333333333",
      "3333333333333333",
      "3333333333333333",
      "3333333333333333",
      "3333333333333333",
      "3333333333333333",
      "3333333333333333",
      "3333333333333333",
      "3333333333333333",
      "3333333333333333",
      "3333333333333333"
    ],
    [
      "!!!!!!!!!!!!!!!!",
      "               !",
      " -   00   00   !",
      "     1    1    !",
      "               !",
      "!              !",
      "%              %",
      "&            4 &",
      "               !",
      "!   2222222.222!",
      "               !",
      "     $  $   $  !",
      "     $  $   $  !",
      "     $  $   $  !",
      "               !",
      "!!!!!!)*!!!!!!!!"
    ],
    [
      "!!!!!!!!!!!!!!!!",
      "               !",
      "               !",
      " -             !",
      "               !",
      "!              !",
      "'              '",
      "(              (",
      "               !",
      "!   2222222/222!",
      "               !",
      "     $  $   $  !",
      "     $  $   $  !",
      "     $  $   $  !",
      "               !",
      "!!!!!!+,!!!!!!!!"
    ],
    [
      "!!!!!!!!!!!!!!!!",
      "               !",
      "               !",
      "               !",
      " -             !",
      "!              !",
      "                ",
      "                ",
      "               !",
      "!   22222222222!",
      "               !",
      "     $  $   $  !",
      "     $  $   $  !",
      "     $  $   $  !",
      "               !",
      "!!!!!!  !!!!!!!!"
    ],
    [
      "!!!!!!!!!!!!!!!!",
      "               !",
      "               !",
      "               !",
      "               !",
      "!-             !",
      "               !",
      "               !",
      "               !",
      "!   22222222222!",
      "               !",
      "               !",
      "               !",
      "               !",
      "               !",
      "!!!!!!!!!!!!!!!!"
    ]
  ],
  "palette": {
    "palette": [
      {
        "char": "!",
        "block": "immersiveengineering:concrete_reinforced"
      },
      {
        "char": "$",
        "block": "minecraft:bookshelf"
      },
      {
        "char": "%",
        "block": "minecraft:iron_door[facing=east,half=lower,hinge=left,open=false,powered=false]"
      },
      {
        "char": "&",
        "block": "minecraft:iron_door[facing=east,half=lower,hinge=right,open=false,powered=false]"
      },
      {
        "char": "'",
        "block": "minecraft:iron_door[facing=east,half=upper,hinge=left,open=false,powered=false]"
      },
      {
        "char": "(",
        "block": "minecraft:iron_door[facing=east,half=upper,hinge=right,open=false,powered=false]"
      },
      {
        "char": ")",
        "block": "minecraft:iron_door[facing=south,half=lower,hinge=left,open=false,powered=false]"
      },
      {
        "char": "*",
        "block": "minecraft:iron_door[facing=south,half=lower,hinge=right,open=false,powered=false]"
      },
      {
        "char": "+",
        "block": "minecraft:iron_door[facing=south,half=upper,hinge=left,open=false,powered=false]"
      },
      {
        "char": ",",
        "block": "minecraft:iron_door[facing=south,half=upper,hinge=right,open=false,powered=false]"
      },
      {
        "char": "-",
        "block": "minecraft:polished_andesite_stairs[facing=south,half=bottom,shape=straight,waterlogged=false]"
      },
      {
        "char": ".",
        "block": "minecraft:spruce_door[facing=south,half=lower,hinge=left,open=false,powered=false]"
      },
      {
        "char": "/",
        "block": "minecraft:spruce_door[facing=south,half=upper,hinge=left,open=false,powered=false]"
      },
      {
        "char": "0",
        "block": "minecraft:spruce_slab[type=bottom,waterlogged=false]"
      },
      {
        "char": "1",
        "block": "minecraft:spruce_stairs[facing=north,half=bottom,shape=straight,waterlogged=false]"
      },
      {
        "char": "2",
        "block": "tfmg:cinder_block"
      },
      {
        "char": "3",
        "block": "tfmg:factory_floor"
      },
      {
        "char": "4",
        "block": "the_wasteland_reworked:radio"
      }
    ]
  }
}
