{
  "xsize": 16,
  "zsize": 16,
  "slices": [
    [
      "  $%%%%%     $ $",
      "  %%%%%!%%   $ $",
      "  %%%%%%% !  $ $",
      "  $%%%%% !   $ $",
      "  %%!%% !    $ $",
      "  $ %% !     $$$",
      "  $ % !         ",
      "  $             ",
      "  $&&&&&&&&&&$  ",
      "  $          $$$",
      "  $          $ $",
      "  $          $ $",
      "  $          $ $",
      "  $          $ $",
      "  $          $ $",
      "  $          $ $"
    ],
    [
      "    ! %      $ $",
      "   ! %%      $ $",
      "  ! %%!%%    $ $",
      "   %%!%%     $ $",
      "     %%      $ $",
      "     %       $$$",
      "  $          $  ",
      "  $          $  ",
      "  $&&&&&&&&&&$  ",
      "  $          $$$",
      "  $          $ $",
      "  $          $ $",
      "  $          $ $",
      "  $          $ $",
      "  $          $ $",
      "  $          $ $"
    ],
    [
      "             $ $",
      "     %       $ $",
      "    %%       $ $",
      "             $ $",
      "             $ $",
      "             $$$",
      "  $          $  ",
      "  $          $  ",
      "  $          $  ",
      "  $          $$$",
      "  $          $ $",
      "  $          $ $",
      "  $          $ $",
      "  $          $ $",
      "  $          $ $",
      "  $          $ $"
    ],
    [
      "             $ $",
      "             $ $",
      "             $ $",
      "             $ $",
      "             $ $",
      "             $$$",
      "  $          $  ",
      "  $          $  ",
      "  $          $  ",
      "  $          $$$",
      "  $          $ $",
      "  $          $ $",
      "  $          $ $",
      "  $          $ $",
      "  $          $ $",
      "  $          $ $"
    ],
    [
      "          $$$$ $",
      "          $$$$ $",
      "          $$$$ $",
      "          $$$$ $",
      "          $$$$ $",
      "          $$$$$$",
      "  $$$$$$$$$$$$$$",
      "  $$$$$$$$$$$$$$",
      "  $$$$$$$$$$$$$$",
      "  $$$$$$$$$$$$$$",
      "  $$$$$$$$$$$$ $",
      "  $$$$$$$$$$$$ $",
      "  $$$$$$$$$$$$ $",
      "  $$$$$$$$$$$$ $",
      "  $$$$$$$$$$$$ $",
      "  $$$$$$$$$$$$ $"
    ],
    [
      "                ",
      "                ",
      "                ",
      "                ",
      "                ",
      "                ",
      "                ",
      "                ",
      "                ",
      "                ",
      "                ",
      "                ",
      "                ",
      "                ",
      "                ",
      "                "
    ]
  ],
  "palette": {
    "palette": [
      {
        "char": "!",
        "block": "immersiveengineering:concrete_brick_cracked"
      },
      {
        "char": "$",
        "block": "immersiveengineering:concrete_reinforced"
      },
      {
        "char": "%",
        "block": "minecraft:gravel"
      },
      {
        "char": "&",
        "block": "tfmg:cinder_block"
      }
    ]
  }
}
