{
  "xsize": 16,
  "zsize": 16,
  "slices": [
    [
      "                ",
      "                ",
      "                ",
      "                ",
      "                ",
      "                ",
      "                ",
      "                ",
      "                ",
      "                ",
      "                ",
      "                ",
      "                ",
      "                ",
      "                ",
      "                "
    ],
    [
      "  222222222222 2",
      "  222222222222 2",
      "  222222222222 2",
      "  222222222222 2",
      "  222222222222 2",
      "  22222222222222",
      "  22222222222222",
      "  22222222222222",
      "  22222222222222",
      "  22222222222222",
      "  222222222222 2",
      "  222222222222 2",
      "  222222222222 2",
      "  222222222222 2",
      "  222222222222 2",
      "  222222222222 2"
    ],
    [
      "  !  1  1  1 ! !",
      "  !  1  1  1 ! !",
      "  ! $1 $1 $1 ! !",
      "  ! %1 %1 %1 ! !",
      "  !  +  +  + ! !",
      "  !  1  1  1 !!!",
      "  !          &  ",
      "  !          '  ",
      "  !11111111-1!  ",
      "  !          !!!",
      "  !          ! !",
      "  ! //       ! !",
      "  ! 0    *   ! !",
      "  !          ! !",
      "  !          ! !",
      "  !          ! !"
    ],
    [
      "  !  1  1  1 ! !",
      "  !  1  1  1 ! !",
      "  !  1  1  1 ! !",
      "  !  1  1  1 ! !",
      "  !  ,  ,  , ! !",
      "  !  1  1  1 !!!",
      "  !          (  ",
      "  !          )  ",
      "  !11111111.1!  ",
      "  !          !!!",
      "  !          ! !",
      "  !          ! !",
      "  !          ! !",
      "  !          ! !",
      "  !          ! !",
      "  !          ! !"
    ],
    [
      "  !  1  1  1 ! !",
      "  !  1  1  1 ! !",
      "  !  1  1  1 ! !",
      "  !  1  1  1 ! !",
      "  !  1  1  1 ! !",
      "  !  1  1  1 !!!",
      "  !             ",
      "  !             ",
      "  !1111111111!  ",
      "  !          !!!",
      "  !          ! !",
      "  !          ! !",
      "  !          ! !",
      "  !          ! !",
      "  !          ! !",
      "  !          ! !"
    ],
    [
      "  !  1  1  1 ! !",
      "  !  1  1  1 ! !",
      "  !  1  1  1 ! !",
      "  !  1  1  1 ! !",
      "  !  1  1  1 ! !",
      "  !  1  1  1 !!!",
      "  !          !  ",
      "  !          !  ",
      "  !1111111111!  ",
      "  !          !!!",
      "  !          ! !",
      "  !          ! !",
      "  !          ! !",
      "  !          ! !",
      "  !          ! !",
      "  !          ! !"
    ]
  ],
  "palette": {
    "palette": [
      {
        "char": "!",
        "block": "immersiveengineering:concrete_reinforced"
      },
      {
        "char": "$",
        "block": "minecraft:gray_bed[facing=south,occupied=false,part=foot]"
      },
      {
        "char": "%",
        "block": "minecraft:gray_bed[facing=south,occupied=false,part=head]"
      },
      {
        "char": "&",
        "block": "minecraft:iron_door[facing=east,half=lower,hinge=left,open=false,powered=false]"
      },
      {
        "char": "'",
        "block": "minecraft:iron_door[facing=east,half=lower,hinge=right,open=false,powered=false]"
      },
      {
        "char": "(",
        "block": "minecraft:iron_door[facing=east,half=upper,hinge=left,open=false,powered=false]"
      },
      {
        "char": ")",
        "block": "minecraft:iron_door[facing=east,half=upper,hinge=right,open=false,powered=false]"
      },
      {
        "char": "*",
        "block": "kubejs:ruined_lectern[facing=north]"
      },
      {
        "char": "+",
        "block": "minecraft:spruce_door[facing=east,half=lower,hinge=left,open=false,powered=false]"
      },
      {
        "char": ",",
        "block": "minecraft:spruce_door[facing=east,half=upper,hinge=left,open=false,powered=false]"
      },
      {
        "char": "-",
        "block": "minecraft:spruce_door[facing=south,half=lower,hinge=left,open=false,powered=false]"
      },
      {
        "char": ".",
        "block": "minecraft:spruce_door[facing=south,half=upper,hinge=left,open=false,powered=false]"
      },
      {
        "char": "/",
        "block": "minecraft:spruce_slab[type=bottom,waterlogged=false]"
      },
      {
        "char": "0",
        "block": "minecraft:spruce_stairs[facing=north,half=bottom,shape=straight,waterlogged=false]"
      },
      {
        "char": "1",
        "block": "tfmg:cinder_block"
      },
      {
        "char": "2",
        "block": "tfmg:factory_floor"
      }
    ]
  }
}
