{
  "xsize": 16,
  "zsize": 16,
  "slices": [
    [
      " !          !   ",
      " !          !   ",
      " !          !   ",
      " !          !   ",
      " !          !   ",
      "!!          !   ",
      " !          !   ",
      " !          !   ",
      " !          !   ",
      "!!          !   ",
      " !          !   ",
      " !          !   ",
      " !          !   ",
      " !          !   ",
      " !          !   ",
      " !          !   "
    ],
    [
      " !          !   ",
      " !          !   ",
      " !          !   ",
      " !          !   ",
      " !          !   ",
      "!!          !   ",
      " !          !   ",
      " !          !   ",
      " !          !   ",
      "!!          !   ",
      " !          !   ",
      " !          !   ",
      " !          !   ",
      " !          !   ",
      " !          !   ",
      " !          !   "
    ],
    [
      " !!!!!!!!!!!!   ",
      " !!!!!!!!!!!!   ",
      " !!!!!!!!!!!!   ",
      " !!!!!!!!!!!!   ",
      " !!!!!!!!!!!!   ",
      "!!!!!!!!!!!!!   ",
      "!!!!!!!!!!!!!   ",
      "!!!!!!!!!!!!!   ",
      "!!!!!!!!!!!!!   ",
      "!!!!!!!!!!!!!   ",
      " !!!!!!!!!!!!   ",
      " !!!!!!!!!!!!   ",
      " !!!!!!!!!!!!   ",
      " !!!!!!!!!!!!   ",
      " !!!!!!!!!!!!   ",
      " !!!!!!!!!!!!   "
    ],
    [
      " 000000000000   ",
      " 000000000000   ",
      " 000000000000   ",
      " 000000000000   ",
      " 000000000000   ",
      "0000000000000   ",
      "0000000000000   ",
      "0000000000000   ",
      "0000000000000   ",
      "0000000000000   ",
      " 000000000000   ",
      " 000000000000   ",
      " 000000000000   ",
      " 000000000000   ",
      " 000000000000   ",
      " 000000000000   "
    ],
    [
      " !          !   ",
      " !          !   ",
      " ! & ' 1111 !   ",
      " !     1111 !   ",
      " !     1111 !   ",
      "!!          !   ",
      " (          !   ",
      " )          !   ",
      " !////-/////!   ",
      "!!          !   ",
      " !       %  !   ",
      " ! $$ $$    !   ",
      " ! $$ $$    !   ",
      " !         ,!   ",
      " ! $$ $$    !   ",
      " ! $$ $$    !   "
    ],
    [
      " !          !   ",
      " !          !   ",
      " !          !   ",
      " !          !   ",
      " !          !   ",
      "!!          !   ",
      " *          !   ",
      " +          !   ",
      " !////./////!   ",
      "!!          !   ",
      " !          !   ",
      " ! $$ $$    !   ",
      " ! $$ $$    !   ",
      " !         ,!   ",
      " ! $$ $$    !   ",
      " ! $$ $$    !   "
    ]
  ],
  "palette": {
    "palette": [
      {
        "char": "!",
        "block": "immersiveengineering:concrete_reinforced"
      },
      {
        "char": "$",
        "block": "immersiveengineering:crate"
      },
      {
        "char": "%",
        "block": "immersiveengineering:metal_barrel"
      },
      {
        "char": "&",
        "block": "kubejs:ruined_blast_furnace[facing=south]"
      },
      {
        "char": "'",
        "block": "kubejs:ruined_crafting_table"
      },
      {
        "char": "(",
        "block": "minecraft:iron_door[facing=east,half=lower,hinge=left,open=false,powered=false]"
      },
      {
        "char": ")",
        "block": "minecraft:iron_door[facing=east,half=lower,hinge=right,open=false,powered=false]"
      },
      {
        "char": "*",
        "block": "minecraft:iron_door[facing=east,half=upper,hinge=left,open=false,powered=false]"
      },
      {
        "char": "+",
        "block": "minecraft:iron_door[facing=east,half=upper,hinge=right,open=false,powered=false]"
      },
      {
        "char": ",",
        "block": "minecraft:ladder[facing=west,waterlogged=false]"
      },
      {
        "char": "-",
        "block": "minecraft:spruce_door[facing=south,half=lower,hinge=left,open=false,powered=false]"
      },
      {
        "char": ".",
        "block": "minecraft:spruce_door[facing=south,half=upper,hinge=left,open=false,powered=false]"
      },
      {
        "char": "/",
        "block": "tfmg:cinder_block"
      },
      {
        "char": "0",
        "block": "tfmg:factory_floor"
      },
      {
        "char": "1",
        "block": "zvhouses:stone_brick_countertop"
      }
    ]
  }
}
