{
  "xsize": 16,
  "zsize": 16,
  "slices": [
    [
      " !          !   ",
      " !          !   ",
      " !          !   ",
      " !          !   ",
      " !          !   ",
      "!!          !   ",
      "            !   ",
      "            !   ",
      " !''''''''''!   ",
      "!!          !   ",
      " !          !   ",
      " ! $$ $$    !   ",
      " ! $$ $$    !   ",
      " !         &!   ",
      " ! $$ $$    !   ",
      " ! $$ $$    !   "
    ],
    [
      " !          !   ",
      " !          !   ",
      " !          !   ",
      " !          !   ",
      " !          !   ",
      "!!          !   ",
      " !          !   ",
      " !          !   ",
      " !''''''''''!   ",
      "!!          !   ",
      " !          !   ",
      " !          !   ",
      " !          !   ",
      " !         &!   ",
      " !          !   ",
      " !          !   "
    ],
    [
      " !          !   ",
      " !          !   ",
      " !          !   ",
      " !          !   ",
      " !          !   ",
      "!!          !   ",
      " !          !   ",
      " !          !   ",
      " !          !   ",
      "!!          !   ",
      " !          !   ",
      " !          !   ",
      " !          !   ",
      " !         &!   ",
      " !          !   ",
      " !          !   "
    ],
    [
      " !          !   ",
      " !          !   ",
      " !          !   ",
      " !          !   ",
      " !          !   ",
      "!!          !   ",
      " !          !   ",
      " !          !   ",
      " !          !   ",
      "!!          !   ",
      " !          !   ",
      " !          !   ",
      " !          !   ",
      " !         &!   ",
      " !          !   ",
      " !          !   "
    ],
    [
      " !!!!!!!!!!!!   ",
      " !!!!!!!!!!!!   ",
      " !!!!!!!!!!!!   ",
      " !!!!!!!!!!!!   ",
      " !!!!!!!!!!!!   ",
      "!!!!!!!!!!!!!   ",
      "!!!!!!!!!!!!!   ",
      "!!!!!!!!!!!!!   ",
      "!!!!!!!!!!!!!   ",
      "!!!!!!!!!!!!!   ",
      " !!!!!!!!!!!!   ",
      " !!!!!!!!!!!!   ",
      " !!!!!!!!!!!!   ",
      " !!!!!!!!!!&!   ",
      " !!!!!!!!!!!!   ",
      " !!!!!!!!!!!!   "
    ],
    [
      "                ",
      "                ",
      "                ",
      "                ",
      "                ",
      "                ",
      "                ",
      "                ",
      "                ",
      "                ",
      "                ",
      "                ",
      "                ",
      "           %    ",
      "                ",
      "                "
    ]
  ],
  "palette": {
    "palette": [
      {
        "char": "!",
        "block": "immersiveengineering:concrete_reinforced"
      },
      {
        "char": "$",
        "block": "immersiveengineering:crate"
      },
      {
        "char": "%",
        "block": "minecraft:iron_trapdoor[facing=north,half=bottom,open=false,powered=false,waterlogged=false]"
      },
      {
        "char": "&",
        "block": "minecraft:ladder[facing=west,waterlogged=false]"
      },
      {
        "char": "'",
        "block": "tfmg:cinder_block"
      }
    ]
  }
}
