{
  "xsize": 16,
  "zsize": 16,
  "slices": [
    [
      "                ",
      "                ",
      "                ",
      "                ",
      "                ",
      "                ",
      "                ",
      "                ",
      "                ",
      "                ",
      "                ",
      "                ",
      "                ",
      "                ",
      "                ",
      "                "
    ],
    [
      "                ",
      "                ",
      "                ",
      "                ",
      "                ",
      "                ",
      "                ",
      "                ",
      "                ",
      "                ",
      "                ",
      "                ",
      "                ",
      "                ",
      "                ",
      "                "
    ],
    [
      "                ",
      "                ",
      "                ",
      "                ",
      "                ",
      "                ",
      "                ",
      "                ",
      "                ",
      "                ",
      "                ",
      "                ",
      "                ",
      "                ",
      "                ",
      "                "
    ],
    [
      "                ",
      "                ",
      " /////////////  ",
      " /////////////  ",
      " /////////////  ",
      " /////////////  ",
      " /////////////  ",
      " /////////////  ",
      " /////////////  ",
      " /////////////  ",
      " /////////////  ",
      " /////////////  ",
      " /////////////  ",
      " /////////////  ",
      "     /////      ",
      "     /////      "
    ],
    [
      "                ",
      "                ",
      " !!!!!!!!!!!!!  ",
      " !           !  ",
      " !       $$$ !  ",
      " !       $$$ !  ",
      " !       $$$ !  ",
      " !           !  ",
      " !....**.....!  ",
      " !           !  ",
      " !) ,,    0  !  ",
      " !  -        !  ",
      " !           !  ",
      " !!!!!%&!!!!!!  ",
      "     !   !      ",
      "     !   !      "
    ],
    [
      "                ",
      "                ",
      " !!!!!!!!!!!!!  ",
      " !           !  ",
      " !       $$$ !  ",
      " !       $$$ !  ",
      " !       $$$ !  ",
      " !           !  ",
      " !....++.....!  ",
      " !           !  ",
      " !)          !  ",
      " !           !  ",
      " !           !  ",
      " !!!!!'(!!!!!!  ",
      "     !   !      ",
      "     !   !      "
    ]
  ],
  "palette": {
    "palette": [
      {
        "char": "!",
        "block": "immersiveengineering:concrete_reinforced"
      },
      {
        "char": "$",
        "block": "immersiveengineering:sheetmetal_steel"
      },
      {
        "char": "%",
        "block": "minecraft:iron_door[facing=south,half=lower,hinge=left,open=false,powered=false]"
      },
      {
        "char": "&",
        "block": "minecraft:iron_door[facing=south,half=lower,hinge=right,open=false,powered=false]"
      },
      {
        "char": "'",
        "block": "minecraft:iron_door[facing=south,half=upper,hinge=left,open=false,powered=false]"
      },
      {
        "char": "(",
        "block": "minecraft:iron_door[facing=south,half=upper,hinge=right,open=false,powered=false]"
      },
      {
        "char": ")",
        "block": "minecraft:ladder[facing=east,waterlogged=false]"
      },
      {
        "char": "*",
        "block": "minecraft:spruce_door[facing=south,half=lower,hinge=left,open=false,powered=false]"
      },
      {
        "char": "+",
        "block": "minecraft:spruce_door[facing=south,half=upper,hinge=left,open=false,powered=false]"
      },
      {
        "char": ",",
        "block": "minecraft:spruce_slab[type=bottom,waterlogged=false]"
      },
      {
        "char": "-",
        "block": "minecraft:spruce_stairs[facing=north,half=bottom,shape=straight,waterlogged=false]"
      },
      {
        "char": ".",
        "block": "tfmg:cinder_block"
      },
      {
        "char": "/",
        "block": "tfmg:factory_floor"
      },
      {
        "char": "0",
        "block": "the_wasteland_reworked:radio"
      }
    ]
  }
}
