{
  "xsize": 16,
  "zsize": 16,
  "slices": [
    [
      "                ",
      "                ",
      "                ",
      "                ",
      "                ",
      "                ",
      "                ",
      "                ",
      "                ",
      "                ",
      "                ",
      "                ",
      "                ",
      "                ",
      "                ",
      "                "
    ],
    [
      "  333333333333 3",
      "  333333333333 3",
      "  333333333333 3",
      "  333333333333 3",
      "  333333333333 3",
      "  33333333333333",
      "  33333333333333",
      "  33333333333333",
      "  33333333333333",
      "  33333333333333",
      "  333333333333 3",
      "  333333333333 3",
      "  333333333333 3",
      "  333333333333 3",
      "  333333333333 3",
      "  333333333333 3"
    ],
    [
      "  !  2  2  2 ! !",
      "  !  2  2  2 ! !",
      "  ! $2 $2 $2 ! !",
      "  ! %2 %2 %2 ! !",
      "  !  ,  ,  , ! !",
      "  !  2  2  2 !!!",
      "  !          &  ",
      "  !          '  ",
      "  !22222222.2!  ",
      "  !          !!!",
      "  !          ! !",
      "  ! 00       ! !",
      "  ! 1    *+  ! !",
      "  !          ! !",
      "  !          ! !",
      "  !          ! !"
    ],
    [
      "  !  2  2  2 ! !",
      "  !  2  2  2 ! !",
      "  !  2  2  2 ! !",
      "  !  2  2  2 ! !",
      "  !  -  -  - ! !",
      "  !  2  2  2 !!!",
      "  !          (  ",
      "  !          )  ",
      "  !22222222/2!  ",
      "  !          !!!",
      "  !          ! !",
      "  !          ! !",
      "  !          ! !",
      "  !          ! !",
      "  !          ! !",
      "  !          ! !"
    ],
    [
      "  !  2  2  2 ! !",
      "  !  2  2  2 ! !",
      "  !  2  2  2 ! !",
      "  !  2  2  2 ! !",
      "  !  2  2  2 ! !",
      "  !  2  2  2 !!!",
      "  !             ",
      "  !             ",
      "  !2222222222!  ",
      "  !          !!!",
      "  !          ! !",
      "  !          ! !",
      "  !          ! !",
      "  !          ! !",
      "  !          ! !",
      "  !          ! !"
    ],
    [
      "  !  2  2  2 ! !",
      "  !  2  2  2 ! !",
      "  !  2  2  2 ! !",
      "  !  2  2  2 ! !",
      "  !  2  2  2 ! !",
      "  !  2  2  2 !!!",
      "  !          !  ",
      "  !          !  ",
      "  !2222222222!  ",
      "  !          !!!",
      "  !          ! !",
      "  !          ! !",
      "  !          ! !",
      "  !          ! !",
      "  !          ! !",
      "  !          ! !"
    ]
  ],
  "palette": {
    "palette": [
      {
        "char": "!",
        "block": "immersiveengineering:concrete_reinforced"
      },
      {
        "char": "$",
        "block": "minecraft:gray_bed[facing=south,occupied=false,part=foot]"
      },
      {
        "char": "%",
        "block": "minecraft:gray_bed[facing=south,occupied=false,part=head]"
      },
      {
        "char": "&",
        "block": "minecraft:iron_door[facing=east,half=lower,hinge=left,open=false,powered=false]"
      },
      {
        "char": "'",
        "block": "minecraft:iron_door[facing=east,half=lower,hinge=right,open=false,powered=false]"
      },
      {
        "char": "(",
        "block": "minecraft:iron_door[facing=east,half=upper,hinge=left,open=false,powered=false]"
      },
      {
        "char": ")",
        "block": "minecraft:iron_door[facing=east,half=upper,hinge=right,open=false,powered=false]"
      },
      {
        "char": "*",
        "block": "kubejs:ruined_lectern[facing=north]"
      },
      {
        "char": "+",
        "block": "minecraft:spawner",
        "tag": {
          "id": "minecraft:mob_spawner",
          "Delay": 220,
          "MinSpawnDelay": 240,
          "MaxSpawnDelay": 720,
          "SpawnCount": 3,
          "MaxNearbyEntities": 12,
          "RequiredPlayerRange": 14,
          "SpawnRange": 4,
          "SpawnData": {
            "entity": {
              "id": "minecraft:pillager"
            }
          },
          "SpawnPotentials": [
            {
              "weight": 1,
              "data": {
                "entity": {
                  "id": "minecraft:pillager"
                }
              }
            }
          ]
        }
      },
      {
        "char": ",",
        "block": "minecraft:spruce_door[facing=east,half=lower,hinge=left,open=false,powered=false]"
      },
      {
        "char": "-",
        "block": "minecraft:spruce_door[facing=east,half=upper,hinge=left,open=false,powered=false]"
      },
      {
        "char": ".",
        "block": "minecraft:spruce_door[facing=south,half=lower,hinge=left,open=false,powered=false]"
      },
      {
        "char": "/",
        "block": "minecraft:spruce_door[facing=south,half=upper,hinge=left,open=false,powered=false]"
      },
      {
        "char": "0",
        "block": "minecraft:spruce_slab[type=bottom,waterlogged=false]"
      },
      {
        "char": "1",
        "block": "minecraft:spruce_stairs[facing=north,half=bottom,shape=straight,waterlogged=false]"
      },
      {
        "char": "2",
        "block": "tfmg:cinder_block"
      },
      {
        "char": "3",
        "block": "tfmg:factory_floor"
      }
    ]
  }
}
