{
  "xsize": 16,
  "zsize": 16,
  "slices": [
    [
      "                ",
      "                ",
      "                ",
      "                ",
      "                ",
      "                ",
      "                ",
      "                ",
      "                ",
      "                ",
      "                ",
      "                ",
      "                ",
      "                ",
      "                ",
      "                "
    ],
    [
      "                ",
      "                ",
      "                ",
      "                ",
      "                ",
      "                ",
      "                ",
      "                ",
      "                ",
      "                ",
      "                ",
      "                ",
      "                ",
      "                ",
      "                ",
      "                "
    ],
    [
      "                ",
      "                ",
      "                ",
      "                ",
      "                ",
      "                ",
      "                ",
      "                ",
      "                ",
      "                ",
      "                ",
      "                ",
      "                ",
      "                ",
      "                ",
      "                "
    ],
    [
      "                ",
      "                ",
      " 0000000000000  ",
      " 0000000000000  ",
      " 0000000000000  ",
      " 0000000000000  ",
      " 0000000000000  ",
      " 0000000000000  ",
      " 0000000000000  ",
      " 0000000000000  ",
      " 0000000000000  ",
      " 0000000000000  ",
      " 0000000000000  ",
      " 0000000000000  ",
      "     00000      ",
      "     00000      "
    ],
    [
      "                ",
      "                ",
      " !!!!!!!!!!!!!  ",
      " !           !  ",
      " !       $$$ !  ",
      " !       $$$ !  ",
      " !       $$$ !  ",
      " !           !  ",
      " !////++/////!  ",
      " !           !  ",
      " !) --    *  !  ",
      " !  .        !  ",
      " !           !  ",
      " !!!!!%&!!!!!!  ",
      "     !   !      ",
      "     !   !      "
    ],
    [
      "                ",
      "                ",
      " !!!!!!!!!!!!!  ",
      " !           !  ",
      " !       $$$ !  ",
      " !       $$$ !  ",
      " !       $$$ !  ",
      " !           !  ",
      " !////,,/////!  ",
      " !           !  ",
      " !)          !  ",
      " !           !  ",
      " !           !  ",
      " !!!!!'(!!!!!!  ",
      "     !   !      ",
      "     !   !      "
    ]
  ],
  "palette": {
    "palette": [
      {
        "char": "!",
        "block": "immersiveengineering:concrete_reinforced"
      },
      {
        "char": "$",
        "block": "immersiveengineering:sheetmetal_steel"
      },
      {
        "char": "%",
        "block": "minecraft:iron_door[facing=south,half=lower,hinge=left,open=false,powered=false]"
      },
      {
        "char": "&",
        "block": "minecraft:iron_door[facing=south,half=lower,hinge=right,open=false,powered=false]"
      },
      {
        "char": "'",
        "block": "minecraft:iron_door[facing=south,half=upper,hinge=left,open=false,powered=false]"
      },
      {
        "char": "(",
        "block": "minecraft:iron_door[facing=south,half=upper,hinge=right,open=false,powered=false]"
      },
      {
        "char": ")",
        "block": "minecraft:ladder[facing=east,waterlogged=false]"
      },
      {
        "char": "*",
        "block": "minecraft:spawner",
        "tag": {
          "id": "minecraft:mob_spawner",
          "Delay": 220,
          "MinSpawnDelay": 240,
          "MaxSpawnDelay": 720,
          "SpawnCount": 3,
          "MaxNearbyEntities": 12,
          "RequiredPlayerRange": 14,
          "SpawnRange": 4,
          "SpawnData": {
            "entity": {
              "id": "minecraft:pillager"
            }
          },
          "SpawnPotentials": [
            {
              "weight": 1,
              "data": {
                "entity": {
                  "id": "minecraft:pillager"
                }
              }
            }
          ]
        }
      },
      {
        "char": "+",
        "block": "minecraft:spruce_door[facing=south,half=lower,hinge=left,open=false,powered=false]"
      },
      {
        "char": ",",
        "block": "minecraft:spruce_door[facing=south,half=upper,hinge=left,open=false,powered=false]"
      },
      {
        "char": "-",
        "block": "minecraft:spruce_slab[type=bottom,waterlogged=false]"
      },
      {
        "char": ".",
        "block": "minecraft:spruce_stairs[facing=north,half=bottom,shape=straight,waterlogged=false]"
      },
      {
        "char": "/",
        "block": "tfmg:cinder_block"
      },
      {
        "char": "0",
        "block": "tfmg:factory_floor"
      }
    ]
  }
}
