{
  "xsize": 16,
  "zsize": 16,
  "slices": [
    [
      "                ",
      "                ",
      " !!!!!!!!!!!!!  ",
      " !           !  ",
      " !       $$$ !  ",
      " !       $$$ !  ",
      " !       $$$ !  ",
      " !           !  ",
      " !+++++++++++!  ",
      " !           !  ",
      " !'          !  ",
      " !           !  ",
      " !           !  ",
      " !!!!!  !!!!!!  ",
      "     !   !      ",
      "     !   !      "
    ],
    [
      "                ",
      "                ",
      " !!!!!!!!!!!!!  ",
      " !           !  ",
      " !           !  ",
      " !           !  ",
      " !           !  ",
      " !           !  ",
      " !+++++++++++!  ",
      " !           !  ",
      " !'          !  ",
      " !           !  ",
      " !           !  ",
      " !!!!!!!!!!!!!  ",
      "     !   !      ",
      "     !   !      "
    ],
    [
      "                ",
      "                ",
      " !!!!!!!!!!!!!  ",
      " !           !  ",
      " !           !  ",
      " !           !  ",
      " !           !  ",
      " !           !  ",
      " !           !  ",
      " !           !  ",
      " !'          !  ",
      " !           !  ",
      " !           !  ",
      " !!!!!!!!!!!!!  ",
      "     !   !      ",
      "     !   !      "
    ],
    [
      "                ",
      "                ",
      " !!!!!!!!!!!!!  ",
      " !           !  ",
      " !           !  ",
      " !           !  ",
      " !           !  ",
      " !           !  ",
      " !           !  ",
      " !           !  ",
      " !'          !  ",
      " !           !  ",
      " !           !  ",
      " !!!!!!!!!!!!!  ",
      "     !   !      ",
      "     !   !      "
    ],
    [
      "                ",
      "                ",
      " !!!!!!!!!!!!!  ",
      " !!!!!!!!!!!!!  ",
      " !!!!!!!!!!!!!  ",
      " !!!!!!!!!!!!!  ",
      " !!!!!!!!!!!!!  ",
      " !!!!!!!!!!!!!  ",
      " !!!!!!!!!!!!!  ",
      " !!!!!!!!!!!!!  ",
      " !'!!!!!!!!!!!  ",
      " !!!!!!!!!!!!!  ",
      " !!!!!!!!!!!!!  ",
      " !!!!!!!!!!!!!  ",
      "     !!!!!      ",
      "     !!!!!      "
    ],
    [
      "  **)****)***   ",
      "((((((((((((((((",
      "((((((((((((((((",
      "((((((((((((((((",
      "((((((((((((((((",
      "((((((((((((((((",
      "((((((((((((((((",
      "((((((((((((((((",
      "((((((((((((((((",
      "((((((((((((((((",
      "((&(((((((((((((",
      "((((((((((((((((",
      "((((((((((((((((",
      "((((((((((((((((",
      "((((((((((((((((",
      "%%%%%%%%%%%%%%%%"
    ]
  ],
  "palette": {
    "palette": [
      {
        "char": "!",
        "block": "immersiveengineering:concrete_reinforced"
      },
      {
        "char": "$",
        "block": "immersiveengineering:sheetmetal_steel"
      },
      {
        "char": "%",
        "block": "minecraft:coarse_dirt"
      },
      {
        "char": "&",
        "block": "minecraft:iron_trapdoor[facing=north,half=bottom,open=false,powered=false,waterlogged=false]"
      },
      {
        "char": "'",
        "block": "minecraft:ladder[facing=east,waterlogged=false]"
      },
      {
        "char": "(",
        "block": "minecraft:polished_andesite"
      },
      {
        "char": ")",
        "block": "minecraft:polished_blackstone_bricks"
      },
      {
        "char": "*",
        "block": "tfmg:asphalt"
      },
      {
        "char": "+",
        "block": "tfmg:cinder_block"
      }
    ]
  }
}
