{
  "xsize": 16,
  "zsize": 16,
  "slices": [
    [
      "!!!!!!!!!!!!!!!!",
      "               !",
      "               !",
      "               !",
      "               !",
      "!              !",
      " /             !",
      "               !",
      "               !",
      "!              !",
      "               !",
      "               !",
      "               !",
      "               !",
      "               !",
      "!!!!!!!!!!!!!!!!"
    ],
    [
      "!!!!!!!!!!!!!!!!",
      "               !",
      "               !",
      "               !",
      "               !",
      "!              !",
      "               !",
      " /             !",
      "               !",
      "!              !",
      "               !",
      "               !",
      "               !",
      "               !",
      "               !",
      "!!!!!!!!!!!!!!!!"
    ],
    [
      "!!!!!!!!!!!!!!!!",
      "!!!!!!!!!!!!!!!!",
      "!!!!!!!!!!!!!!!!",
      "!!!!!!!!!!!!!!!!",
      "!!!!!!!!!!!!!!!!",
      "!!!!!!!!!!!!!!!!",
      "! !!!!!!!!!!!!!!",
      "! !!!!!!!!!!!!!!",
      "!/!!!!!!!!!!!!!!",
      "!!!!!!!!!!!!!!!!",
      "!!!!!!!!!!!!!!!!",
      "!!!!!!!!!!!!!!!!",
      "!!!!!!!!!!!!!!!!",
      "!!!!!!!!!!!!!!!!",
      "!!!!!!!!!!!!!!!!",
      "!!!!!!!!!!!!!!!!"
    ],
    [
      "4444444444444444",
      "4444444444444444",
      "4444444444444444",
      "4444444444444444",
      "4444444444444444",
      "4444444444444444",
      "4444444444444444",
      "4 44444444444444",
      "4 44444444444444",
      "4/..444444444444",
      "44..444444444444",
      "44..444444444444",
      "4444444444444444",
      "4444444444444444",
      "4444444444444444",
      "4444444444444444"
    ],
    [
      "!!!!!!)*!!!!!!!!",
      "               !",
      "   22    22    !",
      "   3     3     !",
      "               !",
      "!              !",
      "%   0000000    %",
      "&   0000000    &",
      "    0000000 $  !",
      "!   0000000    !",
      "               !",
      "           1-  !",
      "   22    22    !",
      "   3     3     !",
      "               !",
      "!!!!!!)*!!!!!!!!"
    ],
    [
      "!!!!!!+,!!!!!!!!",
      "               !",
      "               !",
      "               !",
      "               !",
      "!              !",
      "'              '",
      "(    22222     (",
      "     22222     !",
      "!              !",
      "               !",
      "               !",
      "               !",
      "               !",
      "               !",
      "!!!!!!+,!!!!!!!!"
    ]
  ],
  "palette": {
    "palette": [
      {
        "char": "!",
        "block": "immersiveengineering:concrete_reinforced"
      },
      {
        "char": "$",
        "block": "minecraft:cartography_table"
      },
      {
        "char": "%",
        "block": "minecraft:iron_door[facing=east,half=lower,hinge=left,open=false,powered=false]"
      },
      {
        "char": "&",
        "block": "minecraft:iron_door[facing=east,half=lower,hinge=right,open=false,powered=false]"
      },
      {
        "char": "'",
        "block": "minecraft:iron_door[facing=east,half=upper,hinge=left,open=false,powered=false]"
      },
      {
        "char": "(",
        "block": "minecraft:iron_door[facing=east,half=upper,hinge=right,open=false,powered=false]"
      },
      {
        "char": ")",
        "block": "minecraft:iron_door[facing=south,half=lower,hinge=left,open=false,powered=false]"
      },
      {
        "char": "*",
        "block": "minecraft:iron_door[facing=south,half=lower,hinge=right,open=false,powered=false]"
      },
      {
        "char": "+",
        "block": "minecraft:iron_door[facing=south,half=upper,hinge=left,open=false,powered=false]"
      },
      {
        "char": ",",
        "block": "minecraft:iron_door[facing=south,half=upper,hinge=right,open=false,powered=false]"
      },
      {
        "char": "-",
        "block": "minecraft:lectern[facing=west,has_book=false,powered=false]"
      },
      {
        "char": ".",
        "block": "minecraft:polished_andesite"
      },
      {
        "char": "/",
        "block": "minecraft:polished_andesite_stairs[facing=south,half=bottom,shape=straight,waterlogged=false]"
      },
      {
        "char": "0",
        "block": "minecraft:polished_deepslate"
      },
      {
        "char": "1",
        "block": "minecraft:spawner",
        "tag": {
          "id": "minecraft:mob_spawner",
          "Delay": 220,
          "MinSpawnDelay": 240,
          "MaxSpawnDelay": 720,
          "SpawnCount": 3,
          "MaxNearbyEntities": 12,
          "RequiredPlayerRange": 14,
          "SpawnRange": 4,
          "SpawnData": {
            "entity": {
              "id": "minecraft:pillager"
            }
          },
          "SpawnPotentials": [
            {
              "weight": 1,
              "data": {
                "entity": {
                  "id": "minecraft:pillager"
                }
              }
            }
          ]
        }
      },
      {
        "char": "2",
        "block": "minecraft:spruce_slab[type=bottom,waterlogged=false]"
      },
      {
        "char": "3",
        "block": "minecraft:spruce_stairs[facing=north,half=bottom,shape=straight,waterlogged=false]"
      },
      {
        "char": "4",
        "block": "tfmg:factory_floor"
      }
    ]
  }
}
