{
  "xsize": 16,
  "zsize": 16,
  "slices": [
    [
      "                ",
      "                ",
      "                ",
      "                ",
      "                ",
      "                ",
      "                ",
      "                ",
      "                ",
      "                ",
      "                ",
      "                ",
      "                ",
      "                ",
      "                ",
      "                "
    ],
    [
      "     +++++      ",
      "     +++++      ",
      "     +++++      ",
      "+++++++++++++++ ",
      "+++++++++++++++ ",
      "+++++++++++++++ ",
      "+++++++++++++++ ",
      "+++++++++++++++ ",
      "+++++++++++++++ ",
      "+++++++++++++++ ",
      "+++++++++++++++ ",
      "+++++++++++++++ ",
      "+++++++++++++++ ",
      "                ",
      "                ",
      "                "
    ],
    [
      "     %   %      ",
      "     %   %      ",
      "     %   %      ",
      "%%%%%%  %%%%%%% ",
      "% $$       $$ % ",
      "% $$       $$ % ",
      "% $$       $$ % ",
      "%             % ",
      "%*****((******% ",
      "%             % ",
      "% &&&& ! ,,,, % ",
      "% &&&&   ,,,, % ",
      "%%%%%%%%%%%%%%% ",
      "                ",
      "                ",
      "                "
    ],
    [
      "     %   %      ",
      "     %   %      ",
      "     %   %      ",
      "%%%%%%  %%%%%%% ",
      "% $$       $$ % ",
      "% $$       $$ % ",
      "% $$       $$ % ",
      "%             % ",
      "%*****))******% ",
      "%             % ",
      "% &&&& ' ,,,, % ",
      "% &&&&   ,,,, % ",
      "%%%%%%%%%%%%%%% ",
      "                ",
      "                ",
      "                "
    ],
    [
      "     %   %      ",
      "     %   %      ",
      "     %   %      ",
      "%%%%%%  %%%%%%% ",
      "% $$       $$ % ",
      "% $$       $$ % ",
      "% $$       $$ % ",
      "%             % ",
      "%*************% ",
      "%             % ",
      "% &&&&   ,,,, % ",
      "% &&&&   ,,,, % ",
      "%%%%%%%%%%%%%%% ",
      "                ",
      "                ",
      "                "
    ],
    [
      "     %   %      ",
      "     %   %      ",
      "     %   %      ",
      "%%%%%%%%%%%%%%% ",
      "% $$       $$ % ",
      "% $$       $$ % ",
      "% $$       $$ % ",
      "%             % ",
      "%*************% ",
      "%             % ",
      "%             % ",
      "%             % ",
      "%%%%%%%%%%%%%%% ",
      "                ",
      "                ",
      "                "
    ]
  ],
  "palette": {
    "palette": [
      {
        "char": "!",
        "block": "create:controls"
      },
      {
        "char": "$",
        "block": "create:fluid_tank"
      },
      {
        "char": "%",
        "block": "immersiveengineering:concrete_reinforced"
      },
      {
        "char": "&",
        "block": "immersiveengineering:sheetmetal_steel"
      },
      {
        "char": "'",
        "block": "minecraft:lever[face=wall,facing=north,powered=false]"
      },
      {
        "char": "(",
        "block": "minecraft:spruce_door[facing=south,half=lower,hinge=left,open=false,powered=false]"
      },
      {
        "char": ")",
        "block": "minecraft:spruce_door[facing=south,half=upper,hinge=left,open=false,powered=false]"
      },
      {
        "char": "*",
        "block": "tfmg:cinder_block"
      },
      {
        "char": "+",
        "block": "tfmg:factory_floor"
      },
      {
        "char": ",",
        "block": "tfmg:steel_block"
      }
    ]
  }
}
