{
  "xsize": 16,
  "zsize": 16,
  "slices": [
    [
      " !          !   ",
      " !          !   ",
      " !          !   ",
      " !          !   ",
      " !          !   ",
      "!!          !   ",
      " !          !   ",
      " !          !   ",
      " !          !   ",
      "!!          !   ",
      " !          !   ",
      " !          !   ",
      " !          !   ",
      " !          !   ",
      " !          !   ",
      " !          !   "
    ],
    [
      " !          !   ",
      " !          !   ",
      " !          !   ",
      " !          !   ",
      " !          !   ",
      "!!          !   ",
      " !          !   ",
      " !          !   ",
      " !          !   ",
      "!!          !   ",
      " !          !   ",
      " !          !   ",
      " !          !   ",
      " !          !   ",
      " !          !   ",
      " !          !   "
    ],
    [
      " !!!!!!!!!!!!   ",
      " !!!!!!!!!!!!   ",
      " !!!!!!!!!!!!   ",
      " !!!!!!!!!!!!   ",
      " !!!!!!!!!!!!   ",
      "!!!!!!!!!!!!!   ",
      "!!!!!!!!!!!!!   ",
      "!!!!!!!!!!!!!   ",
      "!!!!!!!!!!!!!   ",
      "!!!!!!!!!!!!!   ",
      " !!!!!!!!!!!!   ",
      " !!!!!!!!!!!!   ",
      " !!!!!!!!!!!!   ",
      " !!!!!!!!!!!!   ",
      " !!!!!!!!!!!!   ",
      " !!!!!!!!!!!!   "
    ],
    [
      " 222222222222   ",
      " 222222222222   ",
      " 222222222222   ",
      " 222222222222   ",
      " 222222222222   ",
      "2222222222222   ",
      "2222222222222   ",
      "2222222222222   ",
      "2222222222222   ",
      "2222222222222   ",
      " 222222222222   ",
      " 222222222222   ",
      " 222222222222   ",
      " 222222222222   ",
      " 222222222222   ",
      " 222222222222   "
    ],
    [
      " !          !   ",
      " !          !   ",
      " ! & ( 3333 !   ",
      " !     3333 !   ",
      " !     3333 !   ",
      "!!          !   ",
      " )          !   ",
      " *          !   ",
      " !1111/11111!   ",
      "!!          !   ",
      " !       %  !   ",
      " ! $$ $$    !   ",
      " ! $$ $$.   !   ",
      " !         -!   ",
      " ! $$ $$'   !   ",
      " ! $$ $$    !   "
    ],
    [
      " !          !   ",
      " !          !   ",
      " !          !   ",
      " !          !   ",
      " !          !   ",
      "!!          !   ",
      " +          !   ",
      " ,          !   ",
      " !1111011111!   ",
      "!!          !   ",
      " !          !   ",
      " ! $$ $$    !   ",
      " ! $$ $$    !   ",
      " !         -!   ",
      " ! $$ $$    !   ",
      " ! $$ $$    !   "
    ]
  ],
  "palette": {
    "palette": [
      {
        "char": "!",
        "block": "immersiveengineering:concrete_reinforced"
      },
      {
        "char": "$",
        "block": "immersiveengineering:crate"
      },
      {
        "char": "%",
        "block": "immersiveengineering:metal_barrel"
      },
      {
        "char": "&",
        "block": "minecraft:blast_furnace[facing=south,lit=false]"
      },
      {
        "char": "'",
        "block": "minecraft:chest[facing=east,type=single,waterlogged=false]",
        "tag": {
          "id": "minecraft:chest",
          "LootTable": "infinite_domain:chests/wasteland_military"
        }
      },
      {
        "char": "(",
        "block": "minecraft:crafting_table"
      },
      {
        "char": ")",
        "block": "minecraft:iron_door[facing=east,half=lower,hinge=left,open=false,powered=false]"
      },
      {
        "char": "*",
        "block": "minecraft:iron_door[facing=east,half=lower,hinge=right,open=false,powered=false]"
      },
      {
        "char": "+",
        "block": "minecraft:iron_door[facing=east,half=upper,hinge=left,open=false,powered=false]"
      },
      {
        "char": ",",
        "block": "minecraft:iron_door[facing=east,half=upper,hinge=right,open=false,powered=false]"
      },
      {
        "char": "-",
        "block": "minecraft:ladder[facing=west,waterlogged=false]"
      },
      {
        "char": ".",
        "block": "minecraft:spawner",
        "tag": {
          "id": "minecraft:mob_spawner",
          "Delay": 220,
          "MinSpawnDelay": 240,
          "MaxSpawnDelay": 720,
          "SpawnCount": 3,
          "MaxNearbyEntities": 12,
          "RequiredPlayerRange": 14,
          "SpawnRange": 4,
          "SpawnData": {
            "entity": {
              "id": "minecraft:pillager"
            }
          },
          "SpawnPotentials": [
            {
              "weight": 1,
              "data": {
                "entity": {
                  "id": "minecraft:pillager"
                }
              }
            }
          ]
        }
      },
      {
        "char": "/",
        "block": "minecraft:spruce_door[facing=south,half=lower,hinge=left,open=false,powered=false]"
      },
      {
        "char": "0",
        "block": "minecraft:spruce_door[facing=south,half=upper,hinge=left,open=false,powered=false]"
      },
      {
        "char": "1",
        "block": "tfmg:cinder_block"
      },
      {
        "char": "2",
        "block": "tfmg:factory_floor"
      },
      {
        "char": "3",
        "block": "zvhouses:stone_brick_countertop"
      }
    ]
  }
}
