{
  "xsize": 16,
  "zsize": 16,
  "slices": [
    [
      "       !      $ ",
      "       !      $ ",
      "       !      $ ",
      "       !      $ ",
      "       !      $ ",
      "       !      $ ",
      "              $ ",
      "              $ ",
      "              $ ",
      "              $ ",
      "                ",
      "                ",
      "                ",
      "                ",
      "                ",
      "                "
    ],
    [
      "       !!!!!!!$$",
      "       !!!!!!!$$",
      "       !!!!!!!$$",
      "       !!!!!!!$$",
      "       !!!!!!!$$",
      "!!!!!!!!!!!!!!!$",
      "!!!!!!!!!!!!!!!$",
      "!!!!!!!!!!!!!!!$",
      "!!!!!!!!!!!!!!!$",
      "!!!!!!!!!!!!!!!$",
      "!!!!!!!         ",
      "!!!!!!!         ",
      "!!!!!!!         ",
      "                ",
      "                ",
      "                "
    ],
    [
      "     &&&&&&&&&&&",
      "     &&&&&&&&&&&",
      "     &&&&&&&&&&&",
      "     &&&&&&&&&&&",
      "     &&&&&&&&&&&",
      "     &&&&&&&&&&&",
      "     &&&&&&&&&&&",
      "     &&&&&&&&&&&",
      "     &&&&&&&&&&&",
      "     &&&&&&&&&&&",
      "     &&         ",
      "     &&         ",
      "     &&         ",
      "     &&         ",
      "     &&         ",
      "     &&         "
    ],
    [
      "     '    ))))))",
      "     '          ",
      "     '          ",
      "     '          ",
      "     '          ",
      "     '          ",
      "     '          ",
      "     '          ",
      "     '          ",
      "     '          ",
      "     '          ",
      "     '(         ",
      "     '          ",
      "     '          ",
      "     '          ",
      "     '          "
    ],
    [
      "     '      %   ",
      "     '          ",
      "     '          ",
      "     '          ",
      "     '          ",
      "     '          ",
      "     '          ",
      "     '          ",
      "     '          ",
      "     '          ",
      "     '          ",
      "     '(         ",
      "     '          ",
      "     '          ",
      "     '          ",
      "     '          "
    ],
    [
      "     '          ",
      "     '          ",
      "     '          ",
      "     '          ",
      "     '          ",
      "     '          ",
      "     '          ",
      "     '          ",
      "     '          ",
      "     '          ",
      "     '          ",
      "     '(         ",
      "     '          ",
      "     '          ",
      "     '          ",
      "     '          "
    ]
  ],
  "palette": {
    "palette": [
      {
        "char": "!",
        "block": "immersiveengineering:concrete_reinforced"
      },
      {
        "char": "$",
        "block": "immersiveengineering:sheetmetal_steel"
      },
      {
        "char": "%",
        "block": "minecraft:iron_trapdoor[facing=north,half=top,open=false,powered=false,waterlogged=false]"
      },
      {
        "char": "&",
        "block": "minecraft:polished_andesite"
      },
      {
        "char": "'",
        "block": "minecraft:stone_bricks"
      },
      {
        "char": "(",
        "block": "tfmg:cinder_block"
      },
      {
        "char": ")",
        "block": "zvhouses:stone_brick_countertop"
      }
    ]
  }
}
