{
  "xsize": 16,
  "zsize": 16,
  "slices": [
    [
      "++++++++++&&%+++",
      "++++++++&&%+++++",
      "++++++&&%+++++++",
      "++++&&%+++++++++",
      "++&&%+++++++++++",
      "&&%++++++++++++&",
      "%+++++++++++++++",
      "+++++++++++++++&",
      "+++++++++++++&&%",
      "+++++++++++&&%++",
      "+++++++++&&%++++",
      "+++++++&&%+++++&",
      "+++++&&%++++++++",
      "+++&&%++++++++++",
      "+&&%++++++++++++",
      "&%++++++++++++++"
    ],
    [
      "(((!!!!!!!      ",
      "(((!!!!!!!      ",
      "(((!!!!!!!      ",
      "(((!!!!!!!      ",
      "(((!!!!!!!      ",
      "(((!!!!!!!      ",
      "(((!!!!!!!      ",
      "(((!!!!!!!      ",
      "(((!!!!!!!      ",
      "(((!!!!!!!      ",
      "(((!!!!!!!      ",
      "(((!!!!!!!      ",
      "(((!!!!!!!      ",
      "(((!!!!!!!      ",
      "(((!!!!!!!      ",
      "(((!!!!!!!      "
    ],
    [
      "  $      !      ",
      "  $      !      ",
      "  $ '''''!      ",
      "  $ '''''!      ",
      "  $ '''''!      ",
      "$$$ '''''!      ",
      "  $ '''''!      ",
      "  $ '''''!      ",
      ") $ '*'''!      ",
      ") $ '''''!      ",
      ") $ '''''!      ",
      ") $ '''''!      ",
      ") $ '''''!      ",
      ") $ '''''!      ",
      ") $ '''''!      ",
      ") $ '''''!      "
    ],
    [
      "  $      !      ",
      "  $      !      ",
      "  $ '''''!      ",
      "  $ '''''!      ",
      "  $ '''''!      ",
      "$$$ '''''!      ",
      "  $ '''''!      ",
      "  $ '''''!      ",
      ") $ ' '''!      ",
      ") $ '*'''!      ",
      ") $ '''''!      ",
      ") $ '''''!      ",
      ") $ '''''!      ",
      ") $ '''''!      ",
      ") $ '''''!      ",
      ") $ '''''!      "
    ],
    [
      "  $      !      ",
      "  $      !      ",
      "  $ '''''!      ",
      "  $ '''''!      ",
      "  $ '''''!      ",
      "$$$ '''''!      ",
      "  $ '''''!      ",
      "  $ '''''!      ",
      ") $ ' '''!      ",
      ") $ ' '''!      ",
      ") $ '*'''!      ",
      ") $ '''''!      ",
      ") $ '''''!      ",
      ") $ '''''!      ",
      ") $ '''''!      ",
      ") $ '''''!      "
    ],
    [
      "  $      !      ",
      "  $      !      ",
      "  $ '''''!      ",
      "  $ '''''!      ",
      "  $ '''''!      ",
      "$$$ '''''!      ",
      "  $ '''''!      ",
      "  $ '''''!      ",
      ") $ '''''!      ",
      ") $ ' '''!      ",
      ") $ ' '''!      ",
      ") $ '*'''!      ",
      ") $ '''''!      ",
      ") $ '''''!      ",
      ") $ '''''!      ",
      ") $ '''''!      "
    ]
  ],
  "palette": {
    "palette": [
      {
        "char": "!",
        "block": "immersiveengineering:concrete_reinforced"
      },
      {
        "char": "$",
        "block": "immersiveengineering:sheetmetal_steel"
      },
      {
        "char": "%",
        "block": "minecraft:coarse_dirt"
      },
      {
        "char": "&",
        "block": "minecraft:gravel"
      },
      {
        "char": "'",
        "block": "minecraft:oxidized_copper_grate"
      },
      {
        "char": "(",
        "block": "minecraft:polished_blackstone"
      },
      {
        "char": ")",
        "block": "minecraft:scaffolding"
      },
      {
        "char": "*",
        "block": "minecraft:stone_brick_stairs[facing=south,half=bottom,shape=straight,waterlogged=false]"
      },
      {
        "char": "+",
        "block": "tfmg:asphalt"
      }
    ]
  }
}
