{
  "xsize": 16,
  "zsize": 16,
  "slices": [
    [
      " )))&&%)))))))))",
      " )&&%)))))))))))",
      " &%)))))))))))))",
      " )))))))))))))))",
      " ))))))))))))))&",
      " %)))))))))))&&%",
      " ))))))))))&&%))",
      " ))))))))&&%))))",
      " ))))))&&%))))))",
      " ))))&&%))))))))",
      " ))&&%))))))))))",
      " %&%))))))))))))",
      " %))))))))))))))",
      " )))))))))))))))",
      " )))))))))))))&&",
      " )))))))))))&&%)"
    ],
    [
      "       !!!!!!!((",
      "       !!!!!!!((",
      "       !!!!!!!((",
      "       !!!!!!!((",
      "       !!!!!!!((",
      "!!!!!!!!!!!!!!!(",
      "!!!!!!!!!!!!!!!(",
      "!!!!!!!!!!!!!!!(",
      "!!!!!!!!!!!!!!!(",
      "!!!!!!!!!!!!!!!(",
      "!!!!!!!!!!!!!!!(",
      "!!!!!!!!!!!!!!!(",
      "!!!!!!!!!!!!!!!(",
      "       !!!!!!!((",
      "       !!!!!!!((",
      "       !!!!!!!(("
    ],
    [
      "       !      $ ",
      "       !      $ ",
      "       !''''' $ ",
      "       !''''' $ ",
      "       !''''' $ ",
      "       !''''' $$",
      "              $ ",
      "              $ ",
      "              $ ",
      "              $ ",
      "              $ ",
      "              $ ",
      "       !''''' $ ",
      "       !''''' $ ",
      "       !''''' $ ",
      "       !''''' $ "
    ],
    [
      "       !      $ ",
      "       !      $ ",
      "       !''''' $ ",
      "       !''''' $ ",
      "       !''''' $ ",
      "       !''''' $$",
      "              $ ",
      "              $ ",
      "              $ ",
      "              $ ",
      "              $ ",
      "              $ ",
      "       !''''' $ ",
      "       !''''' $ ",
      "       !''''' $ ",
      "       !''''' $ "
    ],
    [
      "       !      $ ",
      "       !      $ ",
      "       !''''' $ ",
      "       !''''' $ ",
      "       !''''' $ ",
      "       !''''' $$",
      "              $ ",
      "              $ ",
      "              $ ",
      "              $ ",
      "              $ ",
      "              $ ",
      "       !''''' $ ",
      "       !''''' $ ",
      "       !''''' $ ",
      "       !''''' $ "
    ],
    [
      "       !      $ ",
      "       !      $ ",
      "       !''''' $ ",
      "       !''''' $ ",
      "       !''''' $ ",
      "       !''''' $$",
      "              $ ",
      "              $ ",
      "              $ ",
      "              $ ",
      "                ",
      "                ",
      "                ",
      "                ",
      "                ",
      "                "
    ]
  ],
  "palette": {
    "palette": [
      {
        "char": "!",
        "block": "immersiveengineering:concrete_reinforced"
      },
      {
        "char": "$",
        "block": "immersiveengineering:sheetmetal_steel"
      },
      {
        "char": "%",
        "block": "minecraft:coarse_dirt"
      },
      {
        "char": "&",
        "block": "minecraft:gravel"
      },
      {
        "char": "'",
        "block": "minecraft:oxidized_copper_grate"
      },
      {
        "char": "(",
        "block": "minecraft:polished_blackstone"
      },
      {
        "char": ")",
        "block": "tfmg:asphalt"
      }
    ]
  }
}
