{
  "xsize": 16,
  "zsize": 16,
  "slices": [
    [
      "                ",
      "                ",
      "                ",
      "                ",
      "$$              ",
      " $$$    $$      ",
      " $$$    $$      ",
      " !!!!!!!!!!!!!!!",
      " !!!!!!!!!!!!!!!",
      "$!!!!!!!!!!!!!!!",
      " !!!!!!!!!!!!!!!",
      " !!!!!!!!!!!!!!!",
      " !!!!!!!!!!!!!!!",
      " !!!!!!!!!!!!!!!",
      " !!!!!!!!!!!!!!!",
      " !!!!!!!!!!!!!!!"
    ],
    [
      "                ",
      "                ",
      "                ",
      "                ",
      "$$              ",
      " $$$    $$      ",
      " $$$    $$      ",
      " !!!!!!!!!!!!!!!",
      " !!!!!!!!!!!!!!!",
      "$!!!!!!!!!!!!!!!",
      " !!!!!!!!!!!!!!!",
      " !!!!!!!!!!!!!!!",
      " !!!!!!!!!!!!!!!",
      " !!!!!!!!!!!!!!!",
      " !!!!!!!!!!!!!!!",
      " !!!!!!!!!!!!!!!"
    ],
    [
      "                ",
      "                ",
      "                ",
      "                ",
      "$$              ",
      " $$$    $$      ",
      " $$$    $$      ",
      " !!!!!!!!!!!!!!!",
      " !!!!!!!!!!!!!!!",
      "$!!!!!!!!!!!!!!!",
      " !!!!!!!!!!!!!!!",
      " !!!!!!!!!!!!!!!",
      " !!!!!!!!!!!!!!!",
      " !!!!!!!!!!!!!!!",
      " !!!!!!!!!!!!!!!",
      " !!!!!!!!!!!!!!!"
    ],
    [
      "                ",
      "                ",
      "                ",
      "                ",
      "$$              ",
      " $$$    $$      ",
      " $$$    $$      ",
      " $$$&&&&$$&&    ",
      " $         &    ",
      "$$         &    ",
      "           &    ",
      "           &    ",
      "           &    ",
      "           &    ",
      "           &    ",
      "           &    "
    ],
    [
      "                ",
      "                ",
      "                ",
      "                ",
      "%%              ",
      "%%$$    $$      ",
      "%%$$    $$      ",
      "%%$$&&&&$$&&    ",
      "%%         &    ",
      "%%         &    ",
      "           &    ",
      "           &    ",
      "           &    ",
      "           &    ",
      "           &    ",
      "           &    "
    ],
    [
      "                ",
      "                ",
      "                ",
      "                ",
      "                ",
      "                ",
      "                ",
      "                ",
      "                ",
      "                ",
      "                ",
      "                ",
      "                ",
      "                ",
      "                ",
      "                "
    ]
  ],
  "palette": {
    "palette": [
      {
        "char": "!",
        "block": "minecraft:gravel"
      },
      {
        "char": "$",
        "block": "minecraft:smooth_quartz"
      },
      {
        "char": "%",
        "block": "minecraft:smooth_stone_slab"
      },
      {
        "char": "&",
        "block": "minecraft:stone_bricks"
      }
    ]
  }
}
