{
  "xsize": 16,
  "zsize": 16,
  "slices": [
    [
      "  $      !      ",
      "$$$      !      ",
      "         !      ",
      "         !      ",
      "         !      ",
      "         !      ",
      "!!!!!!!!!!      ",
      "                ",
      "                ",
      "                ",
      "                ",
      "                ",
      "                ",
      "                ",
      "                ",
      "                "
    ],
    [
      "$$$!!!!!!!      ",
      "$$$!!!!!!!      ",
      "!!!!!!!!!!      ",
      "!!!!!!!!!!      ",
      "!!!!!!!!!!      ",
      "!!!!!!!!!!      ",
      "!!!!!!!!!!      ",
      "                ",
      "                ",
      "                ",
      "                ",
      "                ",
      "                ",
      "                ",
      "                ",
      "                "
    ],
    [
      "&&&&&&&&&&&&    ",
      "&&&&&&&&&&&&    ",
      "&&&&&&&&&&&&    ",
      "&&&&&&&&&&&&    ",
      "&&&&&&&&&&&&    ",
      "&&&&&&&&&&&&    ",
      "&&&&&&&&&&&&    ",
      "&&&&&&&&&&&&    ",
      "                ",
      "                ",
      "                ",
      "                ",
      "                ",
      "                ",
      "                ",
      "                "
    ],
    [
      "%% ) ''''' (    ",
      "%% ) ''''' (    ",
      "%% ) ''''' (    ",
      "%% ) ''''' (    ",
      "%% ) ''''' (    ",
      "   )       (    ",
      "   )       (    ",
      "((((((((((((    ",
      "                ",
      "                ",
      "                ",
      "                ",
      "                ",
      "                ",
      "                ",
      "                "
    ],
    [
      "%% ) ''''' (    ",
      "%% ) ''''' (    ",
      "%% ) ''''' (    ",
      "%% ) ''''' (    ",
      "%% ) ''''' (    ",
      "   )       (    ",
      "   )       (    ",
      "((((((((((((    ",
      "                ",
      "                ",
      "                ",
      "                ",
      "                ",
      "                ",
      "                ",
      "                "
    ],
    [
      "%% ) ''''' (    ",
      "%% ) ''''' (    ",
      "%% ) ''''' (    ",
      "%% ) ''''' (    ",
      "%% ) ''''' (    ",
      "   )       (    ",
      "   )       (    ",
      "((((((((((((    ",
      "                ",
      "                ",
      "                ",
      "                ",
      "                ",
      "                ",
      "                ",
      "                "
    ]
  ],
  "palette": {
    "palette": [
      {
        "char": "!",
        "block": "immersiveengineering:concrete_reinforced"
      },
      {
        "char": "$",
        "block": "immersiveengineering:sheetmetal_steel"
      },
      {
        "char": "%",
        "block": "minecraft:bookshelf"
      },
      {
        "char": "&",
        "block": "minecraft:polished_andesite"
      },
      {
        "char": "'",
        "block": "minecraft:scaffolding"
      },
      {
        "char": "(",
        "block": "minecraft:stone_bricks"
      },
      {
        "char": ")",
        "block": "tfmg:cinder_block"
      }
    ]
  }
}
