{
  "xsize": 16,
  "zsize": 16,
  "slices": [
    [
      "                ",
      "                ",
      "                ",
      "                ",
      "                ",
      "                ",
      "                ",
      "                ",
      "                ",
      "                ",
      "       !!!!!!!!!",
      "       !        ",
      "       !        ",
      "       !        ",
      "       !        ",
      "       !      $$"
    ],
    [
      "                ",
      "                ",
      "                ",
      "                ",
      "                ",
      "                ",
      "                ",
      "                ",
      "                ",
      "                ",
      "       !!!!!!!!!",
      "       !!!!!!!!!",
      "       !!!!!!!!!",
      "       !!!!!!!!!",
      "       !!!!!!!!!",
      "       !!!!!!!$$"
    ],
    [
      "                ",
      "                ",
      "                ",
      "                ",
      "               %",
      "        &&    &&",
      "        &&    &&",
      "     %%%&&%%%%&&",
      "     %%%%%%%%%%%",
      "     %%%%%%%%%%%",
      "     %%%%%%%%%%%",
      "     %%%%%%%%%%%",
      "     %%%%%%%%%%%",
      "     %%%%%%%%%%%",
      "     %%%%%%%%%%%",
      "     %%%%%%%%%%%"
    ],
    [
      "                ",
      "                ",
      "                ",
      "                ",
      "               &",
      "        &&    &&",
      "        &&    &&",
      "     '''&&''''&&",
      "     '         &",
      "     '         &",
      "     '          ",
      "     '          ",
      "     '          ",
      "     '          ",
      "     '          ",
      "     '          "
    ],
    [
      "                ",
      "                ",
      "                ",
      "                ",
      "               &",
      "        &&    &&",
      "        &&    &&",
      "     '''&&''''&&",
      "     '         &",
      "     '         &",
      "     '          ",
      "     '          ",
      "     '          ",
      "     '          ",
      "     '          ",
      "     '          "
    ],
    [
      "                ",
      "                ",
      "                ",
      "                ",
      "               &",
      "        &&    &&",
      "        &&    &&",
      "     '''&&''''&&",
      "     '         &",
      "     '         &",
      "     '          ",
      "     '          ",
      "     '          ",
      "     '          ",
      "     '          ",
      "     '          "
    ]
  ],
  "palette": {
    "palette": [
      {
        "char": "!",
        "block": "immersiveengineering:concrete_reinforced"
      },
      {
        "char": "$",
        "block": "immersiveengineering:sheetmetal_steel"
      },
      {
        "char": "%",
        "block": "minecraft:polished_andesite"
      },
      {
        "char": "&",
        "block": "minecraft:smooth_quartz"
      },
      {
        "char": "'",
        "block": "minecraft:stone_bricks"
      }
    ]
  }
}
