{
  "xsize": 16,
  "zsize": 16,
  "slices": [
    [
      "       !      $ ",
      "       !      $$",
      "       !        ",
      "       !        ",
      "       !        ",
      "       !        ",
      "       !!!!!!!!!",
      "                ",
      "                ",
      "                ",
      "                ",
      "                ",
      "                ",
      "                ",
      "                ",
      "                "
    ],
    [
      "       !!!!!!!$$",
      "       !!!!!!!$$",
      "       !!!!!!!!!",
      "       !!!!!!!!!",
      "       !!!!!!!!!",
      "       !!!!!!!!!",
      "       !!!!!!!!!",
      "                ",
      "                ",
      "                ",
      "                ",
      "                ",
      "                ",
      "                ",
      "                ",
      "                "
    ],
    [
      "     )))))))))))",
      "     )))))))))))",
      "     )))))))))))",
      "     )))))))))))",
      "     )))))))))))",
      "     )))))))))))",
      "     )))))))))))",
      "     )))))))))))",
      "                ",
      "                ",
      "                ",
      "                ",
      "                ",
      "                ",
      "                ",
      "                "
    ],
    [
      "     *         +",
      "     *         +",
      "     *         +",
      "     *         +",
      "     *         +",
      "     *         +",
      "     *         +",
      "     ***%&******",
      "                ",
      "                ",
      "                ",
      "                ",
      "                ",
      "                ",
      "                ",
      "                "
    ],
    [
      "     *         +",
      "     *         +",
      "     *         +",
      "     *         +",
      "     *         +",
      "     *         +",
      "     *         +",
      "     ***'(******",
      "                ",
      "                ",
      "                ",
      "                ",
      "                ",
      "                ",
      "                ",
      "                "
    ],
    [
      "     *         +",
      "     *         +",
      "     *         +",
      "     *         +",
      "     *         +",
      "     *         +",
      "     *         +",
      "     ***********",
      "                ",
      "                ",
      "                ",
      "                ",
      "                ",
      "                ",
      "                ",
      "                "
    ]
  ],
  "palette": {
    "palette": [
      {
        "char": "!",
        "block": "immersiveengineering:concrete_reinforced"
      },
      {
        "char": "$",
        "block": "immersiveengineering:sheetmetal_steel"
      },
      {
        "char": "%",
        "block": "minecraft:iron_door[facing=south,half=lower,hinge=left,open=false,powered=false]"
      },
      {
        "char": "&",
        "block": "minecraft:iron_door[facing=south,half=lower,hinge=right,open=false,powered=false]"
      },
      {
        "char": "'",
        "block": "minecraft:iron_door[facing=south,half=upper,hinge=left,open=false,powered=false]"
      },
      {
        "char": "(",
        "block": "minecraft:iron_door[facing=south,half=upper,hinge=right,open=false,powered=false]"
      },
      {
        "char": ")",
        "block": "minecraft:polished_andesite"
      },
      {
        "char": "*",
        "block": "minecraft:stone_bricks"
      },
      {
        "char": "+",
        "block": "tfmg:cinder_block"
      }
    ]
  }
}
