{
  "xsize": 16,
  "zsize": 16,
  "slices": [
    [
      "+++++++&&%++++++",
      "+++++&&%++++++++",
      "+++&&%++++++++++",
      "+&&%++++++++++++",
      "&%++++++++++++++",
      "++++++++++++++++",
      "++++++++++++++&&",
      "++++++++++++&&%+",
      "++++++++++&&%+++",
      "++++++++&&%+++++",
      "++++++&&%+++++++",
      "++++&&%+++++++++",
      "++&&%+++++++++++",
      "&&%+++++++++++++",
      "%+++++++++++++++",
      "+++++++++++++++&"
    ],
    [
      "''''''''''''''''",
      "''''''''''''''''",
      "''''''''''''''''",
      "''''''''''''''''",
      "''''''''''''''''",
      "''''''''''''''''",
      "''''''''''''''''",
      "''''''''''''''''",
      "''''''''''''''''",
      "''''''''''''''''",
      "''''''''''''''''",
      "''''''''''''''''",
      "''''''''''''''''",
      "''''''''''''''''",
      "''''''''''''''''",
      "''''''''''''''''"
    ],
    [
      "                ",
      "                ",
      "                ",
      "                ",
      "                ",
      "!!!!!!!)!!!!!!!!",
      "                ",
      "                ",
      "((  ((     ((  (",
      "((  ((     ((  (",
      "((  ((     ((  (",
      "((  ((     ((  (",
      "((  ((     ((  (",
      "((  ((     (($ (",
      "((  ((     ((  (",
      "((  ((     ((  ("
    ],
    [
      "                ",
      "                ",
      "                ",
      "                ",
      "                ",
      "!!!!!!!*!!!!!!!!",
      "                ",
      "                ",
      "((  ((     ((  (",
      "((  ((     ((  (",
      "((  ((     ((  (",
      "((  ((     ((  (",
      "((  ((     ((  (",
      "((  ((     ((  (",
      "((  ((     ((  (",
      "((  ((     ((  ("
    ],
    [
      "                ",
      "                ",
      "                ",
      "                ",
      "                ",
      "!!!!!!!!!!!!!!!!",
      "                ",
      "                ",
      "((  ((     ((  (",
      "((  ((     ((  (",
      "((  ((     ((  (",
      "((  ((     ((  (",
      "((  ((     ((  (",
      "((  ((     ((  (",
      "((  ((     ((  (",
      "((  ((     ((  ("
    ],
    [
      "                ",
      "                ",
      "                ",
      "                ",
      "                ",
      "!!!!!!!!!!!!!!!!",
      "                ",
      "                ",
      "((  ((     ((  (",
      "((  ((     ((  (",
      "((  ((     ((  (",
      "((  ((     ((  (",
      "((  ((     ((  (",
      "((  ((     ((  (",
      "((  ((     ((  (",
      "((  ((     ((  ("
    ]
  ],
  "palette": {
    "palette": [
      {
        "char": "!",
        "block": "immersiveengineering:sheetmetal_steel"
      },
      {
        "char": "$",
        "block": "minecraft:chest[facing=north,type=single,waterlogged=false]",
        "tag": {
          "id": "minecraft:chest",
          "LootTable": "infinite_domain:chests/wasteland_market"
        }
      },
      {
        "char": "%",
        "block": "minecraft:coarse_dirt"
      },
      {
        "char": "&",
        "block": "minecraft:gravel"
      },
      {
        "char": "'",
        "block": "minecraft:polished_blackstone"
      },
      {
        "char": "(",
        "block": "minecraft:scaffolding"
      },
      {
        "char": ")",
        "block": "minecraft:spruce_door[facing=south,half=lower,hinge=left,open=false,powered=false]"
      },
      {
        "char": "*",
        "block": "minecraft:spruce_door[facing=south,half=upper,hinge=left,open=false,powered=false]"
      },
      {
        "char": "+",
        "block": "tfmg:asphalt"
      }
    ]
  }
}
