{
  "xsize": 16,
  "zsize": 16,
  "slices": [
    [
      "       !      $ ",
      "       !      $ ",
      "       !      $ ",
      "       !      $ ",
      "       !      $ ",
      "       !      $ ",
      "              $ ",
      "              $ ",
      "              $ ",
      "              $ ",
      "              $ ",
      "              $ ",
      "       !      $ ",
      "       !      $ ",
      "       !      $ ",
      "       !      $ "
    ],
    [
      "       !!!!!!!$$",
      "       !!!!!!!$$",
      "       !!!!!!!$$",
      "       !!!!!!!$$",
      "       !!!!!!!$$",
      "!!!!!!!!!!!!!!!$",
      "!!!!!!!!!!!!!!!$",
      "!!!!!!!!!!!!!!!$",
      "!!!!!!!!!!!!!!!$",
      "!!!!!!!!!!!!!!!$",
      "!!!!!!!!!!!!!!!$",
      "!!!!!!!!!!!!!!!$",
      "!!!!!!!!!!!!!!!$",
      "       !!!!!!!$$",
      "       !!!!!!!$$",
      "       !!!!!!!$$"
    ],
    [
      "     &&&&&&&&&&&",
      "     &&&&&&&&&&&",
      "     &&&&&&&&&&&",
      "     &&&&&&&&&&&",
      "     &&&&&&&&&&&",
      "     &&&&&&&&&&&",
      "     &&&&&&&&&&&",
      "     &&&&&&&&&&&",
      "     &&&&&&&&&&&",
      "     &&&&&&&&&&&",
      "     &&&&&&&&&&&",
      "     &&&&&&&&&&&",
      "     &&&&&&&&&&&",
      "     &&&&&&&&&&&",
      "     &&&&&&&&&&&",
      "     &&&&&&&&&&&"
    ],
    [
      "     -    //////",
      "     -          ",
      "     -          ",
      "     -          ",
      "     -          ",
      "     -          ",
      "     -          ",
      "     -          ",
      "     -          ",
      "     -          ",
      "     -          ",
      "     -.....)....",
      "     -         .",
      "     -         .",
      "     -  ++     .",
      "     -  ,      '"
    ],
    [
      "     -      %   ",
      "     -          ",
      "     -          ",
      "     -          ",
      "     -          ",
      "     -          ",
      "     -          ",
      "     -          ",
      "     -          ",
      "     -          ",
      "     -          ",
      "     -.....*....",
      "     -         .",
      "     -         .",
      "     -         .",
      "     -         ("
    ],
    [
      "     -          ",
      "     -          ",
      "     -          ",
      "     -          ",
      "     -          ",
      "     -          ",
      "     -          ",
      "     -          ",
      "     -          ",
      "     -          ",
      "     -          ",
      "     -..........",
      "     -         .",
      "     -         .",
      "     -         .",
      "     -         ."
    ]
  ],
  "palette": {
    "palette": [
      {
        "char": "!",
        "block": "immersiveengineering:concrete_reinforced"
      },
      {
        "char": "$",
        "block": "immersiveengineering:sheetmetal_steel"
      },
      {
        "char": "%",
        "block": "minecraft:iron_trapdoor[facing=north,half=top,open=false,powered=false,waterlogged=false]"
      },
      {
        "char": "&",
        "block": "minecraft:polished_andesite"
      },
      {
        "char": "'",
        "block": "minecraft:spruce_door[facing=east,half=lower,hinge=left,open=false,powered=false]"
      },
      {
        "char": "(",
        "block": "minecraft:spruce_door[facing=east,half=upper,hinge=left,open=false,powered=false]"
      },
      {
        "char": ")",
        "block": "minecraft:spruce_door[facing=south,half=lower,hinge=left,open=false,powered=false]"
      },
      {
        "char": "*",
        "block": "minecraft:spruce_door[facing=south,half=upper,hinge=left,open=false,powered=false]"
      },
      {
        "char": "+",
        "block": "minecraft:spruce_slab[type=bottom,waterlogged=false]"
      },
      {
        "char": ",",
        "block": "minecraft:spruce_stairs[facing=north,half=bottom,shape=straight,waterlogged=false]"
      },
      {
        "char": "-",
        "block": "minecraft:stone_bricks"
      },
      {
        "char": ".",
        "block": "tfmg:cinder_block"
      },
      {
        "char": "/",
        "block": "zvhouses:stone_brick_countertop"
      }
    ]
  }
}
