{
  "xsize": 16,
  "zsize": 16,
  "slices": [
    [
      "*************&&%",
      "***********&&%**",
      "*********&&%****",
      "*******&&%******",
      "*****&&%********",
      "***&&%**********",
      "*&&%************",
      "&%**************",
      "****************",
      "**************&&",
      "************&&%*",
      "**********&&%***",
      "********&&%*****",
      "******&&%*******",
      "****&&%*********",
      "**&&%***********"
    ],
    [
      "&&&&&&&&&&&&&&&&",
      "&&&&&&&&&&&&&&&&",
      "&&&&&&&&&&&&&&&&",
      "&&&&&&&&&&&&&&&&",
      "&&&&&&&&&&&&&&&&",
      "&&&&&&&&&&&&&&&&",
      "&&&&&&&&&&&&&&&&",
      "&&&&&&&&&&&&&&&&",
      "&&&&&&&&&&&&&&&&",
      "&&&&&&&&&&&&&&&&",
      "&&&&&&&&&&&&&&&&",
      "&&&&&&&&&&&&&&&&",
      "&&&&&&&&&&&&&&&&",
      "&&&&&&&&&&&&&&&&",
      "                ",
      "                "
    ],
    [
      "  ))   ))   ))  ",
      "                ",
      "                ",
      "                ",
      "+++++++++       ",
      "+++++++++       ",
      "+++++++++       ",
      "+++++++++       ",
      "+++++++++       ",
      "+++++++++       ",
      "+++++++++       ",
      "+++++++++       ",
      "+++++++++       ",
      "+++++++++       ",
      "+++++++++       ",
      "+++++++++       "
    ],
    [
      "  ))   ))   ))  ",
      "                ",
      "                ",
      "                ",
      "$$$$$$$$$       ",
      "        $       ",
      "     ,  $       ",
      "!!!!!!  $       ",
      "!!!!!!  $       ",
      "!!!!!!  $       ",
      "!!!!!!  $       ",
      "!!!!!!  $       ",
      "!!!!!!  $       ",
      "        $       ",
      "        $       ",
      "$$$$'$$$$       "
    ],
    [
      "  ))   ))   ))  ",
      "                ",
      "                ",
      "                ",
      "$$$$$$$$$       ",
      "        $       ",
      "        $       ",
      "!!!!!!  $       ",
      "!!!!!!  $       ",
      "!!!!!!  $       ",
      "!!!!!!  $       ",
      "!!!!!!  $       ",
      "!!!!!!  $       ",
      "        $       ",
      "        $       ",
      "$$$$($$$$       "
    ],
    [
      "  ))   ))   ))  ",
      "                ",
      "                ",
      "                ",
      "$$$$$$$$$       ",
      "        $       ",
      "        $       ",
      "!!!!!!  $       ",
      "!!!!!!  $       ",
      "!!!!!!  $       ",
      "!!!!!!  $       ",
      "!!!!!!  $       ",
      "!!!!!!  $       ",
      "        $       ",
      "        $       ",
      "$$$$$$$$$       "
    ]
  ],
  "palette": {
    "palette": [
      {
        "char": "!",
        "block": "immersiveengineering:capacitor_mv"
      },
      {
        "char": "$",
        "block": "minecraft:bricks"
      },
      {
        "char": "%",
        "block": "minecraft:coarse_dirt"
      },
      {
        "char": "&",
        "block": "minecraft:gravel"
      },
      {
        "char": "'",
        "block": "minecraft:iron_door[facing=south,half=lower,hinge=left,open=false,powered=false]"
      },
      {
        "char": "(",
        "block": "minecraft:iron_door[facing=south,half=upper,hinge=left,open=false,powered=false]"
      },
      {
        "char": ")",
        "block": "minecraft:smooth_stone"
      },
      {
        "char": "*",
        "block": "tfmg:asphalt"
      },
      {
        "char": "+",
        "block": "tfmg:factory_floor"
      },
      {
        "char": ",",
        "block": "the_wasteland_reworked:radio"
      }
    ]
  }
}
