{
  "xsize": 16,
  "zsize": 16,
  "slices": [
    [
      "))))))&&%)))))))",
      "))))&&%)))))))))",
      "))&&%)))))))))))",
      "&&%)))))))))))))",
      "%)))))))))))))))",
      ")))))))))))))))&",
      ")))))))))))))&&%",
      ")))))))))))&&%))",
      ")))))))))&&%))))",
      ")))))))&&%))))))",
      ")))))&&%))))))))",
      ")))&&%))))))))))",
      ")&&%))))))))))))",
      "&%))))))))))))))",
      "))))))))))))))))",
      "))))%))))%))))%&"
    ],
    [
      "       *********",
      "       *********",
      "       *********",
      "       *********",
      "       *********",
      "       *********",
      "       *********",
      "       *********",
      "       *********",
      "       *********",
      "                ",
      "                ",
      "                ",
      "                ",
      "                ",
      "                "
    ],
    [
      "       $        ",
      "       $  !    !",
      "       $        ",
      "       $        ",
      "       $ ''     ",
      "       $ (      ",
      "       $        ",
      "       $        ",
      "       $        ",
      "       $$$$$$$$$",
      "                ",
      "                ",
      "                ",
      "                ",
      "                ",
      "                "
    ],
    [
      "       $        ",
      "       $        ",
      "       $        ",
      "       $        ",
      "       $        ",
      "       $        ",
      "       $        ",
      "       $        ",
      "       $        ",
      "       $$$$$$$$$",
      "                ",
      "                ",
      "                ",
      "                ",
      "                ",
      "                "
    ],
    [
      "       $        ",
      "       $        ",
      "       $        ",
      "       $        ",
      "       $        ",
      "       $        ",
      "       $        ",
      "       $        ",
      "       $        ",
      "       $$$$$$$$$",
      "                ",
      "                ",
      "                ",
      "                ",
      "                ",
      "                "
    ],
    [
      "       $        ",
      "       $        ",
      "       $        ",
      "       $        ",
      "       $        ",
      "       $        ",
      "       $        ",
      "       $        ",
      "       $        ",
      "       $$$$$$$$$",
      "                ",
      "                ",
      "                ",
      "                ",
      "                ",
      "                "
    ]
  ],
  "palette": {
    "palette": [
      {
        "char": "!",
        "block": "create:mechanical_pump[facing=south]"
      },
      {
        "char": "$",
        "block": "minecraft:bricks"
      },
      {
        "char": "%",
        "block": "minecraft:coarse_dirt"
      },
      {
        "char": "&",
        "block": "minecraft:gravel"
      },
      {
        "char": "'",
        "block": "minecraft:spruce_slab[type=bottom,waterlogged=false]"
      },
      {
        "char": "(",
        "block": "minecraft:spruce_stairs[facing=north,half=bottom,shape=straight,waterlogged=false]"
      },
      {
        "char": ")",
        "block": "tfmg:asphalt"
      },
      {
        "char": "*",
        "block": "tfmg:factory_floor"
      }
    ]
  }
}
