{
  "xsize": 16,
  "zsize": 16,
  "slices": [
    [
      "        %&   %& ",
      "        %    %  ",
      "        %    %  ",
      "        %    %  ",
      "       $$$$$$$$$",
      "       $        ",
      "       $        ",
      "       $        ",
      "       !        ",
      "       !        ",
      "       $        ",
      "       $        ",
      "       $        ",
      "       $        ",
      "       $        ",
      "       $$$$$$$$$"
    ],
    [
      "        &&   && ",
      "                ",
      "                ",
      "                ",
      "       $$$$$$$$$",
      "       $        ",
      "       $        ",
      "       $        ",
      "       !        ",
      "       !        ",
      "       $        ",
      "       $        ",
      "       $        ",
      "       $        ",
      "       $        ",
      "       $$$$$$$$$"
    ],
    [
      "        &&   && ",
      "                ",
      "                ",
      "                ",
      "       $$$$$$$$$",
      "       $        ",
      "       $        ",
      "       $        ",
      "       $        ",
      "       $        ",
      "       $        ",
      "       $        ",
      "       $        ",
      "       $        ",
      "       $        ",
      "       $$$$$$$$$"
    ],
    [
      "                ",
      "                ",
      "                ",
      "                ",
      "       $$$$$$$$$",
      "       $        ",
      "       $        ",
      "       $        ",
      "       $        ",
      "       $        ",
      "       $        ",
      "       $        ",
      "       $        ",
      "       $        ",
      "       $        ",
      "       $$$$$$$$$"
    ],
    [
      "                ",
      "                ",
      "                ",
      "                ",
      "       $$$$$$$$$",
      "       $        ",
      "       $        ",
      "       $        ",
      "       $        ",
      "       $        ",
      "       $        ",
      "       $        ",
      "       $        ",
      "       $        ",
      "       $        ",
      "       $$$$$$$$$"
    ],
    [
      "                ",
      "                ",
      "                ",
      "                ",
      "       $$$$$$$$$",
      "       $        ",
      "       $        ",
      "       $        ",
      "       $        ",
      "       $        ",
      "       $        ",
      "       $        ",
      "       $        ",
      "       $        ",
      "       $        ",
      "       $$$$$$$$$"
    ]
  ],
  "palette": {
    "palette": [
      {
        "char": "!",
        "block": "create:framed_glass"
      },
      {
        "char": "$",
        "block": "minecraft:bricks"
      },
      {
        "char": "%",
        "block": "minecraft:oxidized_copper"
      },
      {
        "char": "&",
        "block": "minecraft:smooth_stone"
      }
    ]
  }
}
