{
  "xsize": 16,
  "zsize": 16,
  "slices": [
    [
      "                ",
      "       %        ",
      "!             ! ",
      "!             ! ",
      "!&           &!$",
      "!             !$",
      "!             !$",
      "!             !$",
      "!             !$",
      "!             !$",
      "!             !$",
      "!&           &!$",
      "!             !$",
      "!             !$",
      "!             !$",
      "!             !$"
    ],
    [
      "                ",
      "                ",
      "!             ! ",
      "!             ! ",
      "!&           &!$",
      "!             !$",
      "!             !$",
      "!             !$",
      "!             !$",
      "!             !$",
      "!             !$",
      "!&           &!$",
      "!             !$",
      "!             !$",
      "!             !$",
      "!             !$"
    ],
    [
      "                ",
      "                ",
      "!             ! ",
      "!             ! ",
      "!&           &!$",
      "!             !$",
      "!             !$",
      "!             !$",
      "!             !$",
      "!             !$",
      "!             !$",
      "!&           &!$",
      "!             !$",
      "!             !$",
      "!             !$",
      "!             !$"
    ],
    [
      "                ",
      "                ",
      "!             ! ",
      "!             ! ",
      "!&           &!$",
      "!             !$",
      "!             !$",
      "!             !$",
      "!             !$",
      "!             !$",
      "!             !$",
      "!&           &!$",
      "!             !$",
      "!             !$",
      "!             !$",
      "!             !$"
    ],
    [
      "                ",
      "                ",
      "!             ! ",
      "!             ! ",
      "!&           &!$",
      "!             !$",
      "!             !$",
      "!             !$",
      "!             !$",
      "!             !$",
      "!             !$",
      "!&           &!$",
      "!             !$",
      "!             !$",
      "!             !$",
      "!             !$"
    ],
    [
      "                ",
      "                ",
      "!             ! ",
      "!             ! ",
      "!&           &!$",
      "!             !$",
      "!             !$",
      "!             !$",
      "!             !$",
      "!             !$",
      "!             !$",
      "!&           &!$",
      "!             !$",
      "!             !$",
      "!             !$",
      "!             !$"
    ]
  ],
  "palette": {
    "palette": [
      {
        "char": "!",
        "block": "immersiveengineering:concrete_reinforced"
      },
      {
        "char": "$",
        "block": "minecraft:deepslate"
      },
      {
        "char": "%",
        "block": "minecraft:oxidized_copper_grate"
      },
      {
        "char": "&",
        "block": "tfmg:steel_block"
      }
    ]
  }
}
