{
  "xsize": 16,
  "zsize": 16,
  "slices": [
    [
      "   $$$/////     ",
      "   $$$/////     ",
      "      /////     ",
      "      /////     ",
      "&&&&&&&&&&&&&&& ",
      "&000 '(  0000&& ",
      "&0          0&& ",
      "&0          0&& ",
      "&0 --       0&& ",
      "&0 .        0&& ",
      "&0          0&& ",
      "&00000+000000&& ",
      "&0          0&& ",
      "&0       %  0&& ",
      "&0          0&& ",
      "&0          0&& "
    ],
    [
      "   $$$/////     ",
      "   $$$/////     ",
      "      /////     ",
      "      /////     ",
      "&&&&&&&&&&&&&&& ",
      "&000 )*  0000&& ",
      "&0          0&& ",
      "&0          0&& ",
      "&0          0&& ",
      "&0          0&& ",
      "&0          0&& ",
      "&00000,000000&& ",
      "&0          0&& ",
      "&0          0&& ",
      "&0          0&& ",
      "&0          0&& "
    ],
    [
      "   $$$/////     ",
      "   $$$/////     ",
      "      /////     ",
      "      /////     ",
      "&&&&&&&&&&&&&&& ",
      "&0!!     0!!0&& ",
      "&0          0&& ",
      "&0          0&& ",
      "&0          0&& ",
      "&0          0&& ",
      "&0          0&& ",
      "&000000000000&& ",
      "&0          0&& ",
      "&0          0&& ",
      "&0          0&& ",
      "&0          0&& "
    ],
    [
      "   $$$/////     ",
      "   $$$/////     ",
      "      /////     ",
      "      /////     ",
      "&&&&&&&&&&&&&&& ",
      "&0!!     0!!0&& ",
      "&0          0&& ",
      "&0          0&& ",
      "&0          0&& ",
      "&0          0&& ",
      "&0          0&& ",
      "&000000000000&& ",
      "&0          0&& ",
      "&0          0&& ",
      "&0          0&& ",
      "&0          0&& "
    ],
    [
      "                ",
      "                ",
      "                ",
      "                ",
      "&&&&&&&&&&&&&&& ",
      "&000000000000&& ",
      "&0          0&& ",
      "&0          0&& ",
      "&0          0&& ",
      "&0          0&& ",
      "&0          0&& ",
      "&0          0&& ",
      "&0          0&& ",
      "&0          0&& ",
      "&0          0&& ",
      "&0          0&& "
    ],
    [
      "                ",
      "                ",
      "                ",
      "                ",
      "&&&&&&&&&&&&&&& ",
      "&000000000000&& ",
      "&0          0&& ",
      "&0          0&& ",
      "&0          0&& ",
      "&0          0&& ",
      "&0          0&& ",
      "&0          0&& ",
      "&0          0&& ",
      "&0          0&& ",
      "&0          0&& ",
      "&0          0&& "
    ]
  ],
  "palette": {
    "palette": [
      {
        "char": "!",
        "block": "create:framed_glass"
      },
      {
        "char": "$",
        "block": "minecraft:blue_concrete"
      },
      {
        "char": "%",
        "block": "minecraft:chest[facing=north,type=single,waterlogged=false]",
        "tag": {
          "id": "minecraft:chest",
          "LootTable": "infinite_domain:chests/wasteland_military"
        }
      },
      {
        "char": "&",
        "block": "minecraft:deepslate"
      },
      {
        "char": "'",
        "block": "minecraft:spruce_door[facing=north,half=lower,hinge=left,open=false,powered=false]"
      },
      {
        "char": "(",
        "block": "minecraft:spruce_door[facing=north,half=lower,hinge=right,open=false,powered=false]"
      },
      {
        "char": ")",
        "block": "minecraft:spruce_door[facing=north,half=upper,hinge=left,open=false,powered=false]"
      },
      {
        "char": "*",
        "block": "minecraft:spruce_door[facing=north,half=upper,hinge=right,open=false,powered=false]"
      },
      {
        "char": "+",
        "block": "minecraft:spruce_door[facing=south,half=lower,hinge=left,open=false,powered=false]"
      },
      {
        "char": ",",
        "block": "minecraft:spruce_door[facing=south,half=upper,hinge=left,open=false,powered=false]"
      },
      {
        "char": "-",
        "block": "minecraft:spruce_slab[type=bottom,waterlogged=false]"
      },
      {
        "char": ".",
        "block": "minecraft:spruce_stairs[facing=north,half=bottom,shape=straight,waterlogged=false]"
      },
      {
        "char": "/",
        "block": "minecraft:yellow_concrete"
      },
      {
        "char": "0",
        "block": "the_wasteland_reworked:cut_lead_plating"
      }
    ]
  }
}
