{
  "xsize": 16,
  "zsize": 16,
  "slices": [
    [
      "                ",
      "                ",
      "                ",
      "                ",
      "                ",
      "                ",
      "                ",
      "                ",
      "                ",
      "                ",
      "                ",
      "                ",
      "                ",
      "                ",
      "                ",
      "                "
    ],
    [
      "                ",
      "                ",
      "                ",
      "                ",
      "                ",
      "                ",
      "                ",
      "                ",
      "                ",
      "                ",
      "                ",
      "                ",
      "                ",
      "                ",
      "                ",
      "                "
    ],
    [
      "       !!!!     ",
      "       !!!!     ",
      "  $$$$$!!!!$$   ",
      "  $$$$$!!!!$$   ",
      " %%%%%%%%%%%%%% ",
      " %%%%%%%%%%%%%% ",
      " %%%%%%%%%%%%%% ",
      " %%%%%%%%%%%%%% ",
      " %%%%%%%%%%%%%% ",
      " %%%%%%%%%%%%%% ",
      " %%%%%%%%%%%%%% ",
      " %%%%%%%%%%%%%% ",
      " %%%%%%%%%%%%%% ",
      " %%%%%%%%%%%%%% ",
      " %%%%%%%%%%%%%% ",
      " %%%%%%%%%%%%%% "
    ],
    [
      "       !!!!     ",
      "       !!!!     ",
      "  $$$$$!!!!$$   ",
      "  $$$$$!!!!$$   ",
      " %%%%%%%%%%%%%% ",
      " %%%%%%%%%%%%%% ",
      " %%%%%%%%%%%%%% ",
      " %%%%%%%%%%%%%% ",
      " %%%%%%%%%%%%%% ",
      " %%%%%%%%%%%%%% ",
      " %%%%%%%%%%%%%% ",
      " %%%%%%%%%%%%%% ",
      " %%%%%%%%%%%%%% ",
      " %%%%%%%%%%%%%% ",
      " %%%%%%%%%%%%%% ",
      " %%%%%%%%%%%%%% "
    ],
    [
      "       !!!!     ",
      "       !!!!     ",
      "  $$$$$!!!!$$   ",
      "  $$$$$!!!!$$   ",
      " %%%%%%%%%%%%%% ",
      " %%%%%%%%%%%%%% ",
      " %%%%%%%%%%%%%% ",
      " %%%%%%%%%%%%%% ",
      " %%%%%%%%%%%%%% ",
      " %%%%%%%%%%%%%% ",
      " %%%%%%%%%%%%%% ",
      " %%%%%%%%%%%%%% ",
      " %%%%%%%%%%%%%% ",
      " %%%%%%%%%%%%%% ",
      " %%%%%%%%%%%%%% ",
      " %%%%%%%%%%%%%% "
    ],
    [
      "       !!!!     ",
      "       !!!!     ",
      "       !!!!     ",
      "       !!!!     ",
      " %%%%%%%%%%%%%% ",
      " %%%%%%%%%%%%%% ",
      " %%%%%%%%%%%%%% ",
      " %%%%%%%%%%%%%% ",
      " %%%%%%%%%%%%%% ",
      " %%%%%%%%%%%%%% ",
      " %%%%%%%%%%%%%% ",
      " %%%%%%%%%%%%%% ",
      " %%%%%%%%%%%%%% ",
      " %%%%%%%%%%%%%% ",
      " %%%%%%%%%%%%%% ",
      " %%%%%%%%%%%%%% "
    ]
  ],
  "palette": {
    "palette": [
      {
        "char": "!",
        "block": "immersiveengineering:concrete_reinforced"
      },
      {
        "char": "$",
        "block": "minecraft:deepslate_bricks"
      },
      {
        "char": "%",
        "block": "minecraft:gravel"
      }
    ]
  }
}
