{
  "xsize": 16,
  "zsize": 16,
  "slices": [
    [
      "                ",
      "                ",
      "                ",
      "                ",
      "!!!!!!!!!!!!!!! ",
      "!!!!!!!!!!!!!!! ",
      "!!!!!!!!!!!!!!! ",
      "!!!!!!!!!!!!!!! ",
      "!!!!!!!!!!!!!!! ",
      "!!!!!!!!!!!!!!! ",
      "!!!!!!!!!!!!!!! ",
      "!!!!!!!!!!!!!!! ",
      "!!!!!!!!!!!!!!! ",
      "!!!!!!!!!!!!!!! ",
      "!!!!!!!!!!!!!!! ",
      "!!!!!!!!!!!!!!! "
    ],
    [
      "                ",
      "                ",
      "                ",
      "                ",
      "!!!!!!!!!!!!!!! ",
      "!!!!!!!!!!!!!!! ",
      "!!!!!!!!!!!!!!! ",
      "!!!!!!!!!!!!!!! ",
      "!!!!!!!!!!!!!!! ",
      "!!!!!!!!!!!!!!! ",
      "!!!!!!!!!!!!!!! ",
      "!!!!!!!!!!!!!!! ",
      "!!!!!!!!!!!!!!! ",
      "!!!!!!!!!!!!!!! ",
      "!!!!!!!!!!!!!!! ",
      "!!!!!!!!!!!!!!! "
    ],
    [
      " %%%%%%%%%%%%%% ",
      "$%%%%%%%%%%%%%% ",
      "$%%%%%%%%%%%%%% ",
      "$%%%%%%%%%%%%%% ",
      "!%%%%%%%%%%%%%% ",
      "!%%%%%%%%%%%%%% ",
      "!%%%%%%%%%%%%%% ",
      "!!!!!!!!!!!!!!! ",
      "!!!!!!!!!!!!!!! ",
      "!!!!!!!!!!!!!!! ",
      "!!!!!!!!!!!!!!! ",
      "!!!!!!!!!!!!!!! ",
      "!!!!!!!!!!!!!!! ",
      "!!!!!!!!!!!!!!! ",
      "!!!!!!!!!!!!!!! ",
      "!!!!!!!!!!!!!!! "
    ],
    [
      " %%%%%%%%%%%%%% ",
      "$%%%%%%%%%%%%%% ",
      "$%%%%%%%%%%%%%% ",
      "$%%%%%%%%%%%%%% ",
      "!%%%%%%%%%%%%%% ",
      "!%%%%%%%%%%%%%% ",
      "!%%%%%%%%%%%%%% ",
      "!!!!!!!!!!!!!!! ",
      "!!!!!!!!!!!!!!! ",
      "!!!!!!!!!!!!!!! ",
      "!!!!!!!!!!!!!!! ",
      "!!!!!!!!!!!!!!! ",
      "!!!!!!!!!!!!!!! ",
      "!!!!!!!!!!!!!!! ",
      "!!!!!!!!!!!!!!! ",
      "!!!!!!!!!!!!!!! "
    ],
    [
      " %%%%%%%%%%%%%% ",
      "$%%%%%%%%%%%%%% ",
      "$%%%%%%%%%%%%%% ",
      "$%%%%%%%%%%%%%% ",
      "!%%%%%%%%%%%%%% ",
      "!%%%%%%%%%%%%%% ",
      "!%%%%%%%%%%%%%% ",
      "!!!!!!!!!!!!!!! ",
      "!!!!!!!!!!!!!!! ",
      "!!!!!!!!!!!!!!! ",
      "!!!!!!!!!!!!!!! ",
      "!!!!!!!!!!!!!!! ",
      "!!!!!!!!!!!!!!! ",
      "!!!!!!!!!!!!!!! ",
      "!!!!!!!!!!!!!!! ",
      "!!!!!!!!!!!!!!! "
    ],
    [
      " %%%%%%%%%%%%%% ",
      " %%%%%%%%%%%%%% ",
      " %%%%%%%%%%%%%% ",
      " %%%%%%%%%%%%%% ",
      "!%%%%%%%%%%%%%% ",
      "!%%%%%%%%%%%%%% ",
      "!%%%%%%%%%%%%%% ",
      "!&&&&&&&&&&&&!! ",
      "!&&&&&&&&&&&&!! ",
      "!&&&&&&&&&&&&!! ",
      "!&&&&&&&&&&&&!! ",
      "!&&&&&&&&&&&&!! ",
      "!&&&&&&&&&&&&!! ",
      "!&&&&&&&&&&&&!! ",
      "!&&&&&&&&&&&&!! ",
      "!&&&&&&&&&&&&!! "
    ]
  ],
  "palette": {
    "palette": [
      {
        "char": "!",
        "block": "minecraft:deepslate"
      },
      {
        "char": "$",
        "block": "minecraft:deepslate_bricks"
      },
      {
        "char": "%",
        "block": "minecraft:gravel"
      },
      {
        "char": "&",
        "block": "tfmg:factory_floor"
      }
    ]
  }
}
