{
  "xsize": 16,
  "zsize": 16,
  "slices": [
    [
      "!!!!!!!!$       ",
      "!!!!!!!!$       ",
      "!!!!!!!!$       ",
      "!!!!!!!!$       ",
      "!!!!!!!!$$$$$$$$",
      "                ",
      "                ",
      "                ",
      "         %      ",
      "                ",
      "                ",
      "                ",
      "                ",
      "                ",
      "                ",
      "                "
    ],
    [
      "!!!!!!!!$       ",
      "!!!!!!!!$       ",
      "!!!!!!!!$       ",
      "!!!!!!!!$       ",
      "!!!!!!!!$$$$$$$$",
      "                ",
      "                ",
      "                ",
      "                ",
      "         %      ",
      "                ",
      "                ",
      "                ",
      "                ",
      "                ",
      "                "
    ],
    [
      "!!!!!!!!$       ",
      "!!!!!!!!$       ",
      "!!!!!!!!$       ",
      "!!!!!!!!$       ",
      "!!!!!!!!$$$$$$$$",
      "                ",
      "                ",
      "                ",
      "                ",
      "                ",
      "         %      ",
      "                ",
      "                ",
      "                ",
      "                ",
      "                "
    ],
    [
      "!!!!!!!!$       ",
      "!!!!!!!!$       ",
      "!!!!!!!!$       ",
      "!!!!!!!!$       ",
      "!!!!!!!!$$$$$$$$",
      "                ",
      "                ",
      "                ",
      "                ",
      "                ",
      "                ",
      "                ",
      "                ",
      "                ",
      "                ",
      "                "
    ],
    [
      "        $       ",
      "        $       ",
      "        $       ",
      "        $       ",
      "        $$$$$$$$",
      "                ",
      "                ",
      "                ",
      "                ",
      "                ",
      "                ",
      "                ",
      "                ",
      "                ",
      "                ",
      "                "
    ],
    [
      "        $       ",
      "        $       ",
      "        $       ",
      "        $       ",
      "        $$$$$$$$",
      "                ",
      "                ",
      "                ",
      "                ",
      "                ",
      "                ",
      "                ",
      "                ",
      "                ",
      "                ",
      "                "
    ]
  ],
  "palette": {
    "palette": [
      {
        "char": "!",
        "block": "immersiveengineering:sheetmetal_steel"
      },
      {
        "char": "$",
        "block": "minecraft:polished_blackstone_bricks"
      },
      {
        "char": "%",
        "block": "minecraft:stone_brick_stairs[facing=south,half=bottom,shape=straight,waterlogged=false]"
      }
    ]
  }
}
