{
  "xsize": 16,
  "zsize": 16,
  "slices": [
    [
      "!!!!!!!!!!!!!!!!",
      "!!!!!!!!!!!!!!!!",
      "!!!!!!!!!!!!!!!!",
      "!!!!!!!!!!!!!!!!",
      "!!!!!!!!!!!!!!!!",
      "!!!!!!!!!!!!!!!!",
      "!!!!!!!!!!!!!!!!",
      "!!!!!!!!!!!!!!!!",
      "!!!!!!!!!!!!!!!!",
      "!!!!!!!!!!!!!!!!",
      "                ",
      "                ",
      "                ",
      "                ",
      "                ",
      "                "
    ],
    [
      "         %%%%%%%",
      "$$$$$$$$$%%%%%%%",
      "$$$$$$$$$%%%%%%%",
      "$$$$$$$$$%%%%%%%",
      "$$$$$$$$$%%%%%%%",
      "$$$$$$$$$%%%%%%%",
      "         %%%%%%%",
      "         %%%%%%%",
      "         %%%%%%%",
      "!!!!!!!!!%%%%%%%",
      "         %%%%%%%",
      "         %%%%%%%",
      "         %%%%%%%",
      "                ",
      "                ",
      "                "
    ],
    [
      "         %%%%%%%",
      "         %%%%%%%",
      "         %%%%%%%",
      "&&&&&&&&&%%%%%%%",
      "         %%%%%%%",
      "         %%%%%%%",
      "         %%%%%%%",
      "         %%%%%%%",
      "         %%%%%%%",
      "!!!!!!!!!%%%%%%%",
      "         %%%%%%%",
      "         %%%%%%%",
      "         %%%%%%%",
      "                ",
      "                ",
      "                "
    ],
    [
      "         %%%%%%%",
      "         %%%%%%%",
      "         %%%%%%%",
      "         %%%%%%%",
      "         %%%%%%%",
      "         %%%%%%%",
      "         %%%%%%%",
      "         %%%%%%%",
      "         %%%%%%%",
      "!!!!!!!!!%%%%%%%",
      "         %%%%%%%",
      "         %%%%%%%",
      "         %%%%%%%",
      "                ",
      "                ",
      "                "
    ],
    [
      "         %%%%%%%",
      "         %%%%%%%",
      "         %%%%%%%",
      "         %%%%%%%",
      "         %%%%%%%",
      "         %%%%%%%",
      "         %%%%%%%",
      "         %%%%%%%",
      "         %%%%%%%",
      "!!!!!!!!!%%%%%%%",
      "         %%%%%%%",
      "         %%%%%%%",
      "         %%%%%%%",
      "                ",
      "                ",
      "                "
    ],
    [
      "         %%%%%%%",
      "         %%%%%%%",
      "         %%%%%%%",
      "         %%%%%%%",
      "         %%%%%%%",
      "         %%%%%%%",
      "         %%%%%%%",
      "         %%%%%%%",
      "         %%%%%%%",
      "!!!!!!!!!%%%%%%%",
      "         %%%%%%%",
      "         %%%%%%%",
      "         %%%%%%%",
      "                ",
      "                ",
      "                "
    ]
  ],
  "palette": {
    "palette": [
      {
        "char": "!",
        "block": "immersiveengineering:concrete_reinforced"
      },
      {
        "char": "$",
        "block": "minecraft:deepslate_tiles"
      },
      {
        "char": "%",
        "block": "minecraft:gravel"
      },
      {
        "char": "&",
        "block": "minecraft:rail[shape=east_west,waterlogged=false]"
      }
    ]
  }
}
