{
  "xsize": 16,
  "zsize": 16,
  "slices": [
    [
      "                ",
      "                ",
      "                ",
      "                ",
      "                ",
      "                ",
      "                ",
      "         $$$$$$$",
      "         $$$$$$$",
      "         $$$$$$$",
      "         $$$$$$$",
      "         $$$$$$$",
      "         $$$$$$$",
      "!       !$$$$$$$",
      "         $$$$$$$",
      "         $$$$$$$"
    ],
    [
      "                ",
      "                ",
      "                ",
      "                ",
      "                ",
      "                ",
      "              %(",
      "         $$$$$$$",
      "         $$$$$$$",
      "         $$$$$$$",
      "         $$$$$$$",
      "         $$$$$$$",
      "         $$$$$$$",
      "%       %$$$$$$$",
      "         $$$$$$$",
      "         $$$$$$$"
    ],
    [
      "                ",
      "                ",
      "                ",
      "                ",
      "                ",
      "              %(",
      "                ",
      "         $$$$$$$",
      "         $$$$$$$",
      "         $$$$$$$",
      "         $$$$$$$",
      "         $$$$$$$",
      "         $$$$$$$",
      "%        $$$$$$$",
      "         $$$$$$$",
      "         $$$$$$$"
    ],
    [
      "'''   '''''   ''",
      "                ",
      "                ",
      "                ",
      "              %(",
      "              % ",
      "                ",
      "         $$$$$$$",
      "         $$$$$$$",
      "         $$$$$$$",
      "         $$$$$$$",
      "         $$$$$$$",
      "'''      $$$$$$$",
      "'''      $$$$$$$",
      "'''      $$$$$$$",
      "         $$$$$$$"
    ],
    [
      "                ",
      "                ",
      "                ",
      "              %(",
      "              % ",
      "              % ",
      "                ",
      "         $$$$$$$",
      "         $$$$$$$",
      "         $$$$$$$",
      "         $$$$$$$",
      "         $$$$$$$",
      "         $$$$$$$",
      "%        $$$$$$$",
      "         $$$$$$$",
      "         $$$$$$$"
    ],
    [
      "            &&&%",
      "            &&&%",
      "            &&%(",
      "            &&% ",
      "            &&% ",
      "            &&&&",
      "                ",
      "                ",
      "                ",
      "                ",
      "                ",
      "                ",
      "                ",
      "                ",
      "                ",
      "                "
    ]
  ],
  "palette": {
    "palette": [
      {
        "char": "!",
        "block": "create:red_nixie_tube"
      },
      {
        "char": "$",
        "block": "minecraft:gravel"
      },
      {
        "char": "%",
        "block": "minecraft:polished_blackstone_bricks"
      },
      {
        "char": "&",
        "block": "minecraft:smooth_stone"
      },
      {
        "char": "'",
        "block": "minecraft:smooth_stone_slab[type=bottom,waterlogged=false]"
      },
      {
        "char": "(",
        "block": "minecraft:stone_brick_stairs[facing=north,half=bottom,shape=straight,waterlogged=false]"
      }
    ]
  }
}
