{
  "xsize": 16,
  "zsize": 16,
  "slices": [
    [
      "                ",
      "                ",
      "                ",
      "                ",
      "                ",
      "                ",
      "                ",
      "                ",
      "                ",
      "                ",
      "                ",
      "                ",
      "                ",
      "                ",
      "                ",
      "                "
    ],
    [
      "                ",
      "                ",
      "                ",
      "                ",
      "                ",
      "                ",
      "                ",
      "                ",
      "                ",
      "                ",
      "                ",
      "                ",
      "                ",
      "                ",
      "                ",
      "                "
    ],
    [
      "                ",
      "                ",
      "                ",
      "                ",
      "                ",
      "                ",
      "                ",
      "                ",
      "                ",
      "                ",
      "                ",
      "                ",
      "                ",
      "                ",
      "                ",
      "                "
    ],
    [
      "                ",
      "                ",
      "                ",
      "                ",
      "                ",
      "                ",
      "                ",
      "                ",
      "                ",
      "                ",
      "                ",
      "                ",
      "                ",
      "                ",
      "     $$$$$$$$$$$",
      "     $$$$$$$$$$$"
    ],
    [
      "       !!!!!!!!!",
      "       !!!!!!!!!",
      "       !!!!!!!!!",
      "       !!!!!!!!!",
      "     $$!!!!!!!!!",
      "     $$!!!!!!!!!",
      "     $$!!!!!!!!!",
      "     $$!!!!!!!!!",
      "     $$!!!!!!!!!",
      "     $$!!!!!!!!!",
      "     $$$$$$$$$$$",
      "     $$$$$$$$$$$",
      "     $$$$$$$$$$$",
      "     $$$$$$$$$$$",
      "     $$$$$$$$$$$",
      "     $$$$$$$$$$$"
    ],
    [
      "     $$!!!!!!!!!",
      "     $$!!!!!!!!!",
      "     $$!!!!!!!!!",
      "     $$!!!!!!!!!",
      "     $$!!!!!!!!!",
      "     $$!!!!!!!!!",
      "     $$!!!!!!!!!",
      "     $$!!!!!!!!!",
      "     $$!!!!!!!!!",
      "     $$!!!!!!!!!",
      "     $$$$$$$$$$$",
      "     $$$$$$$$$$$",
      "     $$$$$$$$$$$",
      "     $$$$$$$$$$$",
      "     $          ",
      "     $          "
    ]
  ],
  "palette": {
    "palette": [
      {
        "char": "!",
        "block": "minecraft:cobbled_deepslate"
      },
      {
        "char": "$",
        "block": "minecraft:deepslate"
      }
    ]
  }
}
