{
  "xsize": 16,
  "zsize": 16,
  "slices": [
    [
      "                ",
      "                ",
      "                ",
      "                ",
      "                ",
      "                ",
      "                ",
      "                ",
      "                ",
      "                ",
      "!!              ",
      "!!              ",
      "!!              ",
      "!!              ",
      "!!              ",
      "!!              "
    ],
    [
      "                ",
      "                ",
      "                ",
      "                ",
      "                ",
      "                ",
      "                ",
      "                ",
      "                ",
      "                ",
      " !              ",
      " !              ",
      "'!              ",
      " !              ",
      " !              ",
      " !              "
    ],
    [
      "&&&$$$$$%%%%%%%%",
      ")))))))))))))))%",
      ")))))))))))))))%",
      ")))))))))))))))%",
      ")))))))))))))))%",
      ")))))))))))))))$",
      ")))))))))))))))$",
      ")))))))))))))))$",
      "$$$$$$$$%%%%%$$$",
      "$$$$$$$$%%%%%$$$",
      " !%&&&&&&&&&&%%%",
      " !%&&&&&&&&&&%%%",
      "'!%&&&&&&&&&&%%%",
      " !%&&&&&&&&&&%%%",
      " !%&&&&&&&&&&%%%",
      " !$&&&&&$$$$$&&&"
    ],
    [
      "                ",
      "                ",
      "                ",
      "                ",
      "      (      (  ",
      "                ",
      "                ",
      "                ",
      "                ",
      "  '             ",
      "                ",
      "                ",
      "'               ",
      "                ",
      "                ",
      "                "
    ],
    [
      "                ",
      "                ",
      "                ",
      "                ",
      "                ",
      "                ",
      "                ",
      "                ",
      "                ",
      "  '             ",
      "                ",
      "                ",
      "'               ",
      "                ",
      "                ",
      "                "
    ],
    [
      "                ",
      "                ",
      "                ",
      "                ",
      "                ",
      "                ",
      "                ",
      "                ",
      "                ",
      "  '             ",
      "                ",
      "                ",
      "'               ",
      "                ",
      "                ",
      "                "
    ]
  ],
  "palette": {
    "palette": [
      {
        "char": "!",
        "block": "minecraft:deepslate"
      },
      {
        "char": "$",
        "block": "minecraft:gravel"
      },
      {
        "char": "%",
        "block": "minecraft:gray_concrete"
      },
      {
        "char": "&",
        "block": "minecraft:polished_andesite"
      },
      {
        "char": "'",
        "block": "minecraft:stripped_dark_oak_log[axis=y]"
      },
      {
        "char": "(",
        "block": "minecraft:yellow_concrete"
      },
      {
        "char": ")",
        "block": "tfmg:asphalt"
      }
    ]
  }
}
