{
  "xsize": 16,
  "zsize": 16,
  "slices": [
    [
      "                ",
      "                ",
      "                ",
      "  !!!!!!!!!!!!!!",
      "  !!!!!!!!!!!!!!",
      "  !!!!!!!!!!!!!!",
      "  !!!!!!!!!!!!!!",
      "  !!!!!!!!!!!!!!",
      "  !!!!!!!!!!!!!!",
      "  !!!!!!!!!!!!!!",
      "  !!!!!!!!!!!!!!",
      "  !!!!!!!!!!!!!!",
      "  !!!!!!!!!!!!!!",
      "  !!!!!!!!!!!!!!",
      "  !!!!!!!!!!!!!!",
      "  !!!!!!!!!!!!!!"
    ],
    [
      "                ",
      "                ",
      "                ",
      "  !!!!!!!!!!!!!!",
      "  !             ",
      "  !             ",
      "  !             ",
      "  ! $$$$$$$$$$$$",
      "  ! $$$$$$$$$$$$",
      "  ! $$$$$$$$$$$$",
      "  ! $$$$$$$$$$$$",
      "  ! $$$$$$$$$$$$",
      "  !             ",
      "  !             ",
      "  !  '''''''''''",
      "  !  '''''''''''"
    ],
    [
      "                ",
      "                ",
      "                ",
      "  !!!!!!!!!!!!!!",
      "  !             ",
      "  !             ",
      "  !             ",
      "  !             ",
      "  !             ",
      "  !  &&&&&&&&&&&",
      "  !             ",
      "  !             ",
      "  !             ",
      "  !       %%    ",
      "  !  '''''%%''''",
      "  !  '''''%%''''"
    ],
    [
      "                ",
      "                ",
      "                ",
      "  !!!!!!!!!!!!!!",
      "  !             ",
      "  !             ",
      "  !             ",
      "  !             ",
      "  !             ",
      "  !             ",
      "  !             ",
      "  !             ",
      "  !             ",
      "  !             ",
      "  !  '''''''''''",
      "  !  ''''%(%''''"
    ],
    [
      "                ",
      "                ",
      "                ",
      "  !!!!!!!!!!!!!!",
      "  !             ",
      "  !             ",
      "  !             ",
      "  !             ",
      "  !             ",
      "  !             ",
      "  !             ",
      "  !             ",
      "  !             ",
      "  !             ",
      "  !             ",
      "  !     %% %    "
    ],
    [
      "                ",
      "                ",
      "                ",
      "  !!!!!!!!!!!!!!",
      "  !             ",
      "  !             ",
      "  !             ",
      "  !             ",
      "  !             ",
      "  !             ",
      "  !             ",
      "  !             ",
      "  !             ",
      "  !             ",
      "  !             ",
      "  !     %% %    "
    ]
  ],
  "palette": {
    "palette": [
      {
        "char": "!",
        "block": "immersiveengineering:concrete_reinforced"
      },
      {
        "char": "$",
        "block": "minecraft:deepslate_tiles"
      },
      {
        "char": "%",
        "block": "minecraft:polished_blackstone_bricks"
      },
      {
        "char": "&",
        "block": "minecraft:rail[shape=east_west,waterlogged=false]"
      },
      {
        "char": "'",
        "block": "minecraft:smooth_stone"
      },
      {
        "char": "(",
        "block": "minecraft:stone_brick_stairs[facing=south,half=bottom,shape=straight,waterlogged=false]"
      }
    ]
  }
}
