{
  "xsize": 16,
  "zsize": 16,
  "slices": [
    [
      "                ",
      "                ",
      "                ",
      "!!!!!!!!!!!!!   ",
      "            !   ",
      "            !   ",
      "))))))))))) !   ",
      ")&,&))))))) !   ",
      "))))))))))) !   ",
      "))))))))))) !   ",
      "))))))))))) !   ",
      "))))))))))) !   ",
      "))))))))))) !   ",
      "))))))))))) !   ",
      "))))))))))) !   ",
      "))))))))))) !   "
    ],
    [
      "                ",
      "                ",
      "                ",
      "!!!!!!!!!!!!!   ",
      "            !   ",
      "            !   ",
      "            !   ",
      " & &        !   ",
      "(&,&        !   ",
      "(( . -  '   !   ",
      "(( .        !   ",
      "   .        !   ",
      "   *        !   ",
      "   .        !   ",
      "   $        !   ",
      "   .        !   "
    ],
    [
      "                ",
      "                ",
      "                ",
      "!!!!!!!!!!!!!   ",
      "            !   ",
      "            !   ",
      "            !   ",
      " & &        !   ",
      "(& &        !   ",
      "(&,&        !   ",
      "(( .        !   ",
      "   .        !   ",
      "   +        !   ",
      "   .        !   ",
      "   %        !   ",
      "   .        !   "
    ],
    [
      "                ",
      "                ",
      "                ",
      "!!!!!!!!!!!!!   ",
      "            !   ",
      "            !   ",
      "            !   ",
      "   .        !   ",
      "(& &        !   ",
      "(& &        !   ",
      "(&,&        !   ",
      "   .        !   ",
      "   .        !   ",
      "   .        !   ",
      "   .        !   ",
      "   .        !   "
    ],
    [
      "                ",
      "                ",
      "                ",
      "!!!!!!!!!!!!!   ",
      "            !   ",
      "            !   ",
      "            !   ",
      "   .        !   ",
      "(( .        !   ",
      "(& &        !   ",
      "(& &        !   ",
      " &,&        !   ",
      "   .        !   ",
      "   .        !   ",
      "   .        !   ",
      "   .        !   "
    ],
    [
      "                ",
      "                ",
      "                ",
      "!!!!!!!!!!!!!   ",
      "            !   ",
      "            !   ",
      "            !   ",
      "            !   ",
      "            !   ",
      "            !   ",
      " & &        !   ",
      " & &        !   ",
      " &,&        !   ",
      "            !   ",
      "            !   ",
      "            !   "
    ]
  ],
  "palette": {
    "palette": [
      {
        "char": "!",
        "block": "immersiveengineering:concrete_reinforced"
      },
      {
        "char": "$",
        "block": "minecraft:iron_door[facing=east,half=lower,hinge=left,open=false,powered=false]"
      },
      {
        "char": "%",
        "block": "minecraft:iron_door[facing=east,half=upper,hinge=left,open=false,powered=false]"
      },
      {
        "char": "&",
        "block": "minecraft:polished_blackstone_bricks"
      },
      {
        "char": "'",
        "block": "minecraft:quartz_stairs[facing=west,half=bottom,shape=straight,waterlogged=false]"
      },
      {
        "char": "(",
        "block": "minecraft:scaffolding"
      },
      {
        "char": ")",
        "block": "minecraft:smooth_stone"
      },
      {
        "char": "*",
        "block": "minecraft:spruce_door[facing=east,half=lower,hinge=left,open=false,powered=false]"
      },
      {
        "char": "+",
        "block": "minecraft:spruce_door[facing=east,half=upper,hinge=left,open=false,powered=false]"
      },
      {
        "char": ",",
        "block": "minecraft:stone_brick_stairs[facing=south,half=bottom,shape=straight,waterlogged=false]"
      },
      {
        "char": "-",
        "block": "minecraft:water_cauldron[level=1]"
      },
      {
        "char": ".",
        "block": "tfmg:cinder_block"
      }
    ]
  }
}
