{
  "xsize": 16,
  "zsize": 16,
  "slices": [
    [
      "                ",
      "                ",
      "                ",
      "                ",
      "                ",
      "                ",
      "                ",
      "                ",
      "                ",
      "                ",
      "       %%%%%%%%%",
      "       %%%%%%%%%",
      "       %%%%%%%%%",
      "       %%%%%%%%%",
      "       %%%%%%%%%",
      "       %%%%%%%%%"
    ],
    [
      "                ",
      "                ",
      "                ",
      "                ",
      "                ",
      "                ",
      "                ",
      "                ",
      "                ",
      "                ",
      "                ",
      "                ",
      "      ' &&&&&&& ",
      "                ",
      "                ",
      "                "
    ],
    [
      "                ",
      "))))))))))))))))",
      "))))))))))))))))",
      "))))))))))))))))",
      "))))))))))))))))",
      "))))))))))))))))",
      "))))))))))))))))",
      "))))))))))))))))",
      "                ",
      "                ",
      "                ",
      "                ",
      "      '         ",
      "                ",
      "                ",
      "                "
    ],
    [
      "                ",
      "                ",
      "                ",
      "                ",
      " (      (      (",
      "                ",
      "                ",
      "                ",
      "                ",
      "    '           ",
      "                ",
      "                ",
      "      '         ",
      "                ",
      "***             ",
      "***             "
    ],
    [
      "                ",
      "                ",
      "                ",
      "                ",
      "                ",
      "                ",
      "                ",
      "                ",
      "                ",
      "    '    $$$$$  ",
      "                ",
      "                ",
      "      '         ",
      "                ",
      "!!!             ",
      "  !             "
    ],
    [
      "                ",
      "                ",
      "                ",
      "                ",
      "                ",
      "                ",
      "                ",
      "                ",
      "                ",
      "    '    $$$$$  ",
      "                ",
      "                ",
      "      '         ",
      "                ",
      "!!!             ",
      "  !             "
    ]
  ],
  "palette": {
    "palette": [
      {
        "char": "!",
        "block": "minecraft:bricks"
      },
      {
        "char": "$",
        "block": "minecraft:chain"
      },
      {
        "char": "%",
        "block": "minecraft:deepslate"
      },
      {
        "char": "&",
        "block": "minecraft:rail[shape=north_south,waterlogged=false]"
      },
      {
        "char": "'",
        "block": "minecraft:stripped_dark_oak_log[axis=y]"
      },
      {
        "char": "(",
        "block": "minecraft:yellow_concrete"
      },
      {
        "char": ")",
        "block": "tfmg:asphalt"
      },
      {
        "char": "*",
        "block": "tfmg:factory_floor"
      }
    ]
  }
}
