{
  "xsize": 16,
  "zsize": 16,
  "slices": [
    [
      "                ",
      "                ",
      "                ",
      "  $$$$$$$$$$$$$$",
      "  $             ",
      "  $             ",
      "  $             ",
      "  $             ",
      "  $             ",
      "  $             ",
      "  $             ",
      "  $             ",
      "  $             ",
      "  $             ",
      "  $             ",
      "  $     !       "
    ],
    [
      "                ",
      "                ",
      "                ",
      "  $$$$$$$$$$$$$$",
      "  $             ",
      "  $             ",
      "  $             ",
      "  $             ",
      "  $             ",
      "  $             ",
      "  $             ",
      "  $             ",
      "  $             ",
      "  $             ",
      "  $             ",
      "  $     %       "
    ],
    [
      "                ",
      "                ",
      "                ",
      "  $$$$$$$$$$$$$$",
      "  $             ",
      "  $             ",
      "  $             ",
      "  $             ",
      "  $             ",
      "  $             ",
      "  $             ",
      "  $             ",
      "  $             ",
      "  $             ",
      "  $             ",
      "  $     %       "
    ],
    [
      "                ",
      "                ",
      "                ",
      "  $$$$$$$$$$$$$$",
      "  $             ",
      "  $             ",
      "  $             ",
      "  $             ",
      "  $             ",
      "  $             ",
      "  $             ",
      "  $             ",
      "  $             ",
      "  $             ",
      "  $   '''''   ''",
      "  $   '''''   ''"
    ],
    [
      "                ",
      "                ",
      "                ",
      "  $$$$$$$$$$$$$$",
      "  $             ",
      "  $             ",
      "  $             ",
      "  $             ",
      "  $             ",
      "  $             ",
      "  $             ",
      "  $             ",
      "  $             ",
      "  $             ",
      "  $             ",
      "  $     %       "
    ],
    [
      "                ",
      "                ",
      "                ",
      "  $$$$$$$$$$$$$$",
      "  $             ",
      "  $             ",
      "  $ &&&&&&&&&&&&",
      "  $ &&&&&&&&&&&&",
      "  $ &&&&&&&&&&&&",
      "  $ &&&&&&&&&&&&",
      "  $ &&&&&&&&&&&&",
      "  $ &&&&&&&&&&&&",
      "  $ &&&&&&&&&&&&",
      "  $ &&&&&&&&&&&&",
      "  $ &&&&&&&&&&&&",
      "  $ &&&&&&&&&&&&"
    ]
  ],
  "palette": {
    "palette": [
      {
        "char": "!",
        "block": "create:red_nixie_tube"
      },
      {
        "char": "$",
        "block": "immersiveengineering:concrete_reinforced"
      },
      {
        "char": "%",
        "block": "minecraft:polished_blackstone_bricks"
      },
      {
        "char": "&",
        "block": "minecraft:smooth_stone"
      },
      {
        "char": "'",
        "block": "minecraft:smooth_stone_slab[type=bottom,waterlogged=false]"
      }
    ]
  }
}
