{
  "xsize": 16,
  "zsize": 16,
  "slices": [
    [
      "!!!!!!!!!!!!!   ",
      "!!!!!!!!!!!!!   ",
      "!!!!!!!!!!!!!   ",
      "!!!!!!!!!!!!!   ",
      "!!!!!!!!!!!!!   ",
      "!!!!!!!!!!!!!   ",
      "!!!!!!!!!!!!!   ",
      "!!!!!!!!!!!!!   ",
      "!!!!!!!!!!!!!   ",
      "!!!!!!!!!!!!!   ",
      "!!!!!!!!!!!!!   ",
      "!!!!!!!!!!!!!   ",
      "!!!!!!!!!!!!!   ",
      "!!!!!!!!!!!!!   ",
      "!!!!!!!!!!!!!   ",
      "!!!!!!!!!!!!!   "
    ],
    [
      "%%%%%%%%%%  !   ",
      "%%%%%%%%%%  !   ",
      "%%%%%%%%%%  !   ",
      "%%%%%%%%%%  !   ",
      "            !   ",
      "            !   ",
      "            !   ",
      "$$$$$$$$$$$$$$$ ",
      "$$$$$$$$$$$$$$$ ",
      "$$$$$$$$$$$$$$$ ",
      "$$$$$$$$$$$$$$$ ",
      "$$$$$$$$$$$$$$$ ",
      "$$$$$$$$$$$$$$$ ",
      "$$$$$$$$$$$$$$$ ",
      "$$$$$$$$$$$$$$$ ",
      "$$$$$$$$$$$$$$$ "
    ],
    [
      "%%%%%%%%%%  !   ",
      "%%%%%%%%%%  !   ",
      "%%%%%%%%%%  !   ",
      "%%%%%%%%%%  !   ",
      "            !   ",
      "            !   ",
      "            !   ",
      "$$$$$$$$$$$$$$$ ",
      "$$$$$$$$$$$$$$$ ",
      "$$$$$$$$$$$$$$$ ",
      "$$$$$$$$$$$$$$$ ",
      "$$$$$$$$$$$$$$$ ",
      "$$$$$$$$$$$$$$$ ",
      "$$$$$$$$$$$$$$$ ",
      "$$$$$$$$$$$$$$$ ",
      "$$$$$$$$$$$$$$$ "
    ],
    [
      "%%%%%%%%%%  !   ",
      "%%%%%%%%%%  !   ",
      "%%%%%%%%%%  !   ",
      "%%%%%%%%%%  !   ",
      "            !   ",
      "            !   ",
      "            !   ",
      "$$$$$$$$$$$$$$$ ",
      "$$$$$$$$$$$$$$$ ",
      "$$$$$$$$$$$$$$$ ",
      "$$$$$$$$$$$$$$$ ",
      "$$$$$$$$$$$$$$$ ",
      "$$$$$$$$$$$$$$$ ",
      "$$$$$$$$$$$$$$$ ",
      "$$$$$$$$$$$$$$$ ",
      "$$$$$$$$$$$$$$$ "
    ],
    [
      "            !   ",
      "            !   ",
      "            !   ",
      "            !   ",
      "            !   ",
      "            !   ",
      "            !   ",
      "$$$$$$$$$$$$$$$ ",
      "$$$$$$$$$$$$$$$ ",
      "$$$$$$$$$$$$$$$ ",
      "$$$$$$$$$$$$$$$ ",
      "$$$$$$$$$$$$$$$ ",
      "$$$$$$$$$$$$$$$ ",
      "$$$$$$$$$$$$$$$ ",
      "$$$$$$$$$$$$$$$ ",
      "$$$$$$$$$$$$$$$ "
    ],
    [
      "            !   ",
      "            !   ",
      "            !   ",
      "            !   ",
      "            !   ",
      "            !   ",
      "            !   ",
      "$$$$$$$$$$$$$$$ ",
      "$$$$$$$$$$$$$$$ ",
      "$$$$$$$$$$$$$$$ ",
      "$$$$$$$$$$$$$$$ ",
      "$$$$$$$$$$$$$$$ ",
      "$$$$$$$$$$$$$$$ ",
      "$$$$$$$$$$$$$$$ ",
      "$$$$$$$$$$$$$$$ ",
      "$$$$$$$$$$$$$$$ "
    ]
  ],
  "palette": {
    "palette": [
      {
        "char": "!",
        "block": "immersiveengineering:concrete_reinforced"
      },
      {
        "char": "$",
        "block": "minecraft:gravel"
      },
      {
        "char": "%",
        "block": "minecraft:smooth_stone"
      }
    ]
  }
}
