{
  "xsize": 16,
  "zsize": 16,
  "slices": [
    [
      "  $             ",
      "  $             ",
      "  $             ",
      "  $             ",
      "  $             ",
      "  $             ",
      "  $             ",
      "  $             ",
      "  $             ",
      "  $             ",
      "  $             ",
      "  $             ",
      "  $             ",
      "  $             ",
      "  $             ",
      "  $             "
    ],
    [
      "  $             ",
      "  $             ",
      "  $             ",
      "  $             ",
      "  $             ",
      "  $             ",
      "  $             ",
      "  $             ",
      "  $             ",
      "  $             ",
      "  $             ",
      "  $             ",
      "  $             ",
      "  $             ",
      "  $             ",
      "  $             "
    ],
    [
      "  $             ",
      "  $             ",
      "  $             ",
      "  $             ",
      "  $             ",
      "  $             ",
      "  $             ",
      "  $             ",
      "  $             ",
      "  $             ",
      "  $             ",
      "  $             ",
      "  $             ",
      "  $             ",
      "  $ %%%%%%%%%%%%",
      "  $ %%%%%%%%%%%%"
    ],
    [
      "  $$$$$$$$$$$$$$",
      "  $$$$$$$$$$$$$$",
      "  $$$$$$$$$$$$$$",
      "  $$$$$$$$$$$$$$",
      "  $$$$$$$$$$$$$$",
      "  $$$$$$$$$$$$$$",
      "  $$$$$$$$$$$$$$",
      "  $$$$$$$$$$$$$$",
      "  $$$$$$$$$$$$$$",
      "  $$$$$$$$$$$$$$",
      "  $$$$$$$$$$$$$$",
      "  $$$$$$$$$$$$$$",
      "  $$$$$$$$$$$$$$",
      "  $$$$$$$$$$$$$$",
      "  $$!!!!!!!!!!!!",
      "  $$!           "
    ],
    [
      "                ",
      "                ",
      "                ",
      "                ",
      "                ",
      "                ",
      "                ",
      "                ",
      "                ",
      "                ",
      "                ",
      "                ",
      "                ",
      "                ",
      "    !!!!!!!!!!!!",
      "    !           "
    ],
    [
      "                ",
      "                ",
      "                ",
      "                ",
      "                ",
      "                ",
      "                ",
      "                ",
      "                ",
      "                ",
      "                ",
      "                ",
      "                ",
      "                ",
      "    &&&&&&&&&&&&",
      "    &&&&&&&&&&&&"
    ]
  ],
  "palette": {
    "palette": [
      {
        "char": "!",
        "block": "create:framed_glass"
      },
      {
        "char": "$",
        "block": "immersiveengineering:concrete_reinforced"
      },
      {
        "char": "%",
        "block": "minecraft:smooth_stone"
      },
      {
        "char": "&",
        "block": "minecraft:smooth_stone_slab"
      }
    ]
  }
}
