{
  "xsize": 16,
  "zsize": 16,
  "slices": [
    [
      "     %%%%%%%%%%%",
      "     %%%%%%%%%%%",
      "     %%%%%%%%%%%",
      "     %%%%%%%%%%%",
      "     %          ",
      "     %          ",
      "     %+ ******* ",
      "     %          ",
      "     %          ",
      "     %          ",
      "     %          ",
      "     %+ ******* ",
      "     %          ",
      "     %          ",
      "     %          ",
      "     %          "
    ],
    [
      "     %          ",
      "     %+ ******* ",
      "     %          ",
      "     %          ",
      "     %          ",
      "     %          ",
      "     %+         ",
      "     %          ",
      "     %          ",
      "     %          ",
      "     %          ",
      "     %+         ",
      "     %          ",
      "     %          ",
      "     %          ",
      "     %          "
    ],
    [
      "))))'%          ",
      "))))'%+         ",
      "))))'%          ",
      "))))'%          ",
      "&&&&$%          ",
      "&&&&$%          ",
      "&&&&$%+         ",
      "&&&&$%          ",
      "&&&&$%          ",
      "$$$$$%          ",
      "$$$$$%          ",
      "$$$$$%+         ",
      "$$$$$%          ",
      "$$$$$%          ",
      "$$$$&%          ",
      "$$$$&%          "
    ],
    [
      ",,,             ",
      ",,,   +         ",
      ",,,             ",
      ",,,             ",
      ",,,             ",
      ",,,             ",
      ",,,   +         ",
      ",,,             ",
      ",,,             ",
      ",,,             ",
      ",,,             ",
      ",,,   +         ",
      ",,,             ",
      ",,,             ",
      ",,,             ",
      ",,,             "
    ],
    [
      "  !             ",
      "  !   +         ",
      "  !             ",
      "  !             ",
      "  !             ",
      "  !             ",
      "  !   +         ",
      "  !             ",
      "  !             ",
      "  !             ",
      "  !             ",
      "  !   +         ",
      "  !             ",
      "  !             ",
      "  !             ",
      "!!!             "
    ],
    [
      "  !             ",
      "  !   +         ",
      "  !             ",
      "  !             ",
      "  !             ",
      "  !             ",
      "  !   +    (    ",
      "  !             ",
      "  !             ",
      "  !             ",
      "  !             ",
      "  !   +    (    ",
      "  !             ",
      "  !             ",
      "  !             ",
      "!!!             "
    ]
  ],
  "palette": {
    "palette": [
      {
        "char": "!",
        "block": "minecraft:bricks"
      },
      {
        "char": "$",
        "block": "minecraft:coarse_dirt"
      },
      {
        "char": "%",
        "block": "minecraft:deepslate"
      },
      {
        "char": "&",
        "block": "minecraft:gravel"
      },
      {
        "char": "'",
        "block": "minecraft:gray_concrete"
      },
      {
        "char": "(",
        "block": "minecraft:lantern[hanging=true,waterlogged=false]"
      },
      {
        "char": ")",
        "block": "minecraft:polished_andesite"
      },
      {
        "char": "*",
        "block": "minecraft:rail[shape=north_south,waterlogged=false]"
      },
      {
        "char": "+",
        "block": "minecraft:stripped_dark_oak_log[axis=y]"
      },
      {
        "char": ",",
        "block": "tfmg:factory_floor"
      }
    ]
  }
}
