{
  "xsize": 16,
  "zsize": 16,
  "slices": [
    [
      "!!!!!!!!!!!!!   ",
      "!!!!!!!!!!!!!   ",
      "!!!!!!!!!!!!!   ",
      "!!!!!!!!!!!!!   ",
      "!!!!!!!!!!!!!   ",
      "!!!!!!!!!!!!!   ",
      "!!!!!!!!!!!!!   ",
      "!!!!!!!!!!!!!   ",
      "!!!!!!!!!!!!!   ",
      "!!!!!!!!!!!!!   ",
      "!!!!!!!!!!!!!   ",
      "!!!!!!!!!!!!!   ",
      "!!!!!!!!!!!!!   ",
      "!!!!!!!!!!!!!   ",
      "!!!!!!!!!!!!!   ",
      "!!!!!!!!!!!!!   "
    ],
    [
      "            !   ",
      "            !   ",
      "            !   ",
      "            !   ",
      "            !   ",
      "            !   ",
      "            !   ",
      "            !   ",
      "            !   ",
      "            !   ",
      "            !   ",
      "            !   ",
      "            !   ",
      "            !   ",
      "            !   ",
      "            !   "
    ],
    [
      "%%%%%%%%%%  !   ",
      "%%%%%%%%%%  !   ",
      "%%%%%%%%%%  !   ",
      "%%%%%%%%%%  !   ",
      "            !   ",
      "            !   ",
      "            !   ",
      "            !   ",
      "            !   ",
      "%%%%%%%%%%  !   ",
      "%%%%%%%%%%  !   ",
      "%%%%%%%%%%  !   ",
      "%%%%%%%%%%  !   ",
      "%%%%%%%%%%  !   ",
      "%%%%%%%%%%  !   ",
      "            !   "
    ],
    [
      "%%%%%%%%%%  !   ",
      "%%%%%%%%%%  !   ",
      "%%%%%%%%%%  !   ",
      "%%%%%%%%%%  !   ",
      "            !   ",
      "            !   ",
      "            !   ",
      "            !   ",
      "            !   ",
      "%%%%%%%%%%  !   ",
      "%%%%%%%%%%  !   ",
      "%%%%%%%%%%  !   ",
      "%%%%%%%%%%  !   ",
      "%%%%%%%%%%  !   ",
      "%%%%%%%%%%  !   ",
      "            !   "
    ],
    [
      "            !   ",
      "            !   ",
      "            !   ",
      "            !   ",
      "            !   ",
      "            !   ",
      "            !   ",
      "            !   ",
      "            !   ",
      "            !   ",
      "            !   ",
      "            !   ",
      "            !   ",
      "$       $   !   ",
      "            !   ",
      "            !   "
    ],
    [
      "            !   ",
      "            !   ",
      "            !   ",
      "            !   ",
      "            !   ",
      "            !   ",
      "            !   ",
      "            !   ",
      "            !   ",
      "            !   ",
      "            !   ",
      "            !   ",
      "            !   ",
      "$       $   !   ",
      "            !   ",
      "            !   "
    ]
  ],
  "palette": {
    "palette": [
      {
        "char": "!",
        "block": "immersiveengineering:concrete_reinforced"
      },
      {
        "char": "$",
        "block": "minecraft:polished_blackstone_bricks"
      },
      {
        "char": "%",
        "block": "minecraft:smooth_stone"
      }
    ]
  }
}
