{
  "xsize": 16,
  "zsize": 16,
  "slices": [
    [
      "0000000000000000",
      "0000000000000000",
      "0000000000000000",
      "0000000000000000",
      "000000000000000'",
      "0000000000000''&",
      "00000000000''&00",
      "000000000''&0000",
      "0000000''&000000",
      "00000''&00000000",
      "000''&0000000000",
      "0''&000000000000",
      "'&00000000000000",
      "0000000000000000",
      "0000000000000000",
      "000000000000'000"
    ],
    [
      "                ",
      "                ",
      "                ",
      "                ",
      "                ",
      "                ",
      "                ",
      "                ",
      "22222222222222  ",
      "22222222222222  ",
      "22222222222222$$",
      "22222222222222$$",
      "22222222222222$$",
      "22222222222222$$",
      "22222222222222$$",
      "22222222222222$$"
    ],
    [
      "                ",
      "                ",
      "                ",
      "                ",
      "                ",
      "                ",
      "                ",
      " *     *     *  ",
      "**************  ",
      "       1     *  ",
      "       1$$$$**$$",
      "3+%    1$$$$ *$$",
      " +%    ,$$$$ *$$",
      " +%    1     *$$",
      " +%    1     *$$",
      " +%    1     *$$"
    ],
    [
      "                ",
      "                ",
      "                ",
      "                ",
      "                ",
      "                ",
      "                ",
      " *     *     *  ",
      "1*11111*11111*  ",
      "       1     1  ",
      "       1$$$$**$(",
      "3+     1$$$$ 1$$",
      " +     -$$$$ 1$$",
      " +     1  )  1$$",
      " +     1     1$$",
      " +     1     1$$"
    ],
    [
      "                ",
      "                ",
      "                ",
      "                ",
      "                ",
      "                ",
      "                ",
      ".*  ...*  ...*  ",
      "1*11111*11111*  ",
      "       1     1  ",
      "       1$$$$**$$",
      "3      1$$$$ 1$$",
      "       1$$$$ 1$$",
      "       1     1$$",
      "       1     1$$",
      "       1     1$$"
    ],
    [
      "                ",
      "                ",
      "                ",
      "                ",
      "                ",
      "                ",
      "                ",
      " *     *     *  ",
      "!/1/!!!/1/!!!/  ",
      "       1     1  ",
      "       1    *!* ",
      "3      1     !  ",
      "       1     1  ",
      "       1     1  ",
      "       1     1  ",
      "       1     1  "
    ]
  ],
  "palette": {
    "palette": [
      {
        "char": "!",
        "block": "create:framed_glass"
      },
      {
        "char": "$",
        "block": "immersiveengineering:sheetmetal_steel"
      },
      {
        "char": "%",
        "block": "jaffabricate:pallet_full"
      },
      {
        "char": "&",
        "block": "minecraft:coarse_dirt"
      },
      {
        "char": "'",
        "block": "minecraft:gravel"
      },
      {
        "char": "(",
        "block": "minecraft:lever[face=wall,facing=north,powered=false]"
      },
      {
        "char": ")",
        "block": "minecraft:lever[face=wall,facing=south,powered=false]"
      },
      {
        "char": "*",
        "block": "minecraft:mud_bricks"
      },
      {
        "char": "+",
        "block": "minecraft:scaffolding"
      },
      {
        "char": ",",
        "block": "minecraft:spruce_door[facing=east,half=lower,hinge=left,open=false,powered=false]"
      },
      {
        "char": "-",
        "block": "minecraft:spruce_door[facing=east,half=upper,hinge=left,open=false,powered=false]"
      },
      {
        "char": ".",
        "block": "minecraft:spruce_slab[type=bottom,waterlogged=false]"
      },
      {
        "char": "/",
        "block": "minecraft:stripped_spruce_log[axis=y]"
      },
      {
        "char": "0",
        "block": "tfmg:asphalt"
      },
      {
        "char": "1",
        "block": "tfmg:cinder_block"
      },
      {
        "char": "2",
        "block": "tfmg:factory_floor"
      },
      {
        "char": "3",
        "block": "tfmg:steel_block"
      }
    ]
  }
}
