{
  "xsize": 16,
  "zsize": 16,
  "slices": [
    [
      "(((((((((((((%%$",
      "(((((((((((%%$((",
      "(((((((((%%$((((",
      "(((((((%%$((((((",
      "((((((((((((((((",
      "((((((((((((((((",
      "((((((((((((((((",
      "((((((((((((((((",
      "((((((((((((((((",
      "((((((((((((((((",
      "((((((((((((((((",
      "                ",
      "                ",
      "                ",
      "                ",
      "                "
    ],
    [
      "****************",
      "****************",
      "****************",
      "****************",
      "''''''''''''''''",
      "''''''''''''''''",
      "''''''''''''''''",
      "+'&&&&&''&&&&&''",
      "  &&&&&  &&&&&  ",
      "                ",
      "                ",
      "                ",
      "                ",
      "                ",
      "                ",
      "                "
    ],
    [
      "  ---   ---   --",
      "  --!   ---   --",
      "  ---   ---   --",
      "                ",
      "))     ))     ))",
      "                ",
      "                ",
      "+ &&&&&  &&&&&  ",
      "  &&&&&  &&&&&  ",
      "                ",
      "                ",
      "                ",
      "                ",
      "                ",
      "                ",
      "                "
    ],
    [
      "   ,     ,     ,",
      "                ",
      "                ",
      " +     ++     ++",
      ")+     ++     ++",
      " +     ++     ++",
      "                ",
      "+               ",
      "                ",
      "                ",
      "                ",
      "                ",
      "                ",
      "                ",
      "                ",
      "                "
    ],
    [
      "                ",
      "                ",
      "                ",
      " +     ++     ++",
      ")+     ++     ++",
      " +     ++     ++",
      "                ",
      "+               ",
      "                ",
      "                ",
      "                ",
      "                ",
      "                ",
      "                ",
      "                ",
      "                "
    ],
    [
      "                ",
      "                ",
      "                ",
      " +     ++     ++",
      ")+     ++     ++",
      " +     ++     ++",
      "                ",
      "+               ",
      "                ",
      "                ",
      "                ",
      "                ",
      "                ",
      "                ",
      "                ",
      "                "
    ]
  ],
  "palette": {
    "palette": [
      {
        "char": "!",
        "block": "minecraft:chest[facing=south,type=single,waterlogged=false]",
        "tag": {
          "id": "minecraft:chest",
          "LootTable": "infinite_domain:chests/wasteland_industrial"
        }
      },
      {
        "char": "$",
        "block": "minecraft:coarse_dirt"
      },
      {
        "char": "%",
        "block": "minecraft:gravel"
      },
      {
        "char": "&",
        "block": "minecraft:polished_blackstone"
      },
      {
        "char": "'",
        "block": "minecraft:smooth_stone"
      },
      {
        "char": "(",
        "block": "tfmg:asphalt"
      },
      {
        "char": ")",
        "block": "tfmg:cinder_block"
      },
      {
        "char": "*",
        "block": "tfmg:factory_floor"
      },
      {
        "char": "+",
        "block": "tfmg:steel_block"
      },
      {
        "char": ",",
        "block": "the_wasteland_reworked:cardboard_box"
      },
      {
        "char": "-",
        "block": "zvhouses:stone_brick_countertop"
      }
    ]
  }
}
