{
  "xsize": 16,
  "zsize": 16,
  "slices": [
    [
      "1111111))%111111",
      "11111))%11111111",
      "111))%1111111111",
      "1))%111111111111",
      ")%11111111111111",
      "1111111111111111",
      "11111111111111))",
      "111111111111))%1",
      "1111111111))%111",
      "11111111))%11111",
      "111111))%1111111",
      "1111))%111111111",
      "11))%11111111111",
      "))%1111111111111",
      "%111111111111111",
      "111111111111111)"
    ],
    [
      "***3333333333333",
      "***3333333333333",
      "***3333333333333",
      "***3333333333333",
      "***3333333333333",
      "***3333333333333",
      "***3333333333333",
      "3333333333333333",
      "3333333333333333",
      "3333333333333333",
      "3333333333333333",
      "3333333333333333",
      "3333333333333333",
      "3333333333333333",
      "3333333333333333",
      "3333333333333333"
    ],
    [
      "+ $  2 ,!   ,!  ",
      "  '  24,!  4,!  ",
      "/2$  2          ",
      " 555 -          ",
      "  $  2          ",
      "22/222          ",
      "$$$   4,!  4,!  ",
      "       ,!   ,!  ",
      "       ,!   ,!  ",
      "       ,!   ,!  ",
      "       ,!   ,!  ",
      "       ,!   ,!  ",
      "       ,!   ,!  ",
      "      4,!  4,!  ",
      "                ",
      "  555   555   55"
    ],
    [
      "  $  2 ,    ,   ",
      "  (  24,   4,   ",
      "02$  2          ",
      "  $& .          ",
      "  $  2          ",
      "220222          ",
      "$$$   4,   4,   ",
      "       ,    ,   ",
      "       ,    ,   ",
      "       ,    ,   ",
      "       ,    ,   ",
      "       ,    ,   ",
      "       ,    ,   ",
      "      4,   4,   ",
      "                ",
      "                "
    ],
    [
      "  $  2          ",
      "     24    4    ",
      "22$  2          ",
      "  $  2          ",
      "  $  2          ",
      "222222          ",
      "$$$   4    4    ",
      "                ",
      "                ",
      "                ",
      "                ",
      "                ",
      "                ",
      "      4    4    ",
      "                ",
      "                "
    ],
    [
      "  $  2          ",
      "  $  24    4    ",
      "22$  2          ",
      "  $  2          ",
      "  $  2          ",
      "222222          ",
      "$$$   4    4    ",
      "                ",
      "                ",
      "                ",
      "                ",
      "                ",
      "                ",
      "      4    4    ",
      "                ",
      "                "
    ]
  ],
  "palette": {
    "palette": [
      {
        "char": "!",
        "block": "jaffabricate:pallet_full"
      },
      {
        "char": "$",
        "block": "minecraft:bricks"
      },
      {
        "char": "%",
        "block": "minecraft:coarse_dirt"
      },
      {
        "char": "&",
        "block": "minecraft:crafting_table"
      },
      {
        "char": "'",
        "block": "minecraft:dark_oak_door[facing=east,half=lower,hinge=left,open=false,powered=false]"
      },
      {
        "char": "(",
        "block": "minecraft:dark_oak_door[facing=east,half=upper,hinge=left,open=false,powered=false]"
      },
      {
        "char": ")",
        "block": "minecraft:gravel"
      },
      {
        "char": "*",
        "block": "minecraft:polished_andesite"
      },
      {
        "char": "+",
        "block": "minecraft:quartz_stairs[facing=west,half=bottom,shape=straight,waterlogged=false]"
      },
      {
        "char": ",",
        "block": "minecraft:scaffolding"
      },
      {
        "char": "-",
        "block": "minecraft:spruce_door[facing=east,half=lower,hinge=left,open=false,powered=false]"
      },
      {
        "char": ".",
        "block": "minecraft:spruce_door[facing=east,half=upper,hinge=left,open=false,powered=false]"
      },
      {
        "char": "/",
        "block": "minecraft:spruce_door[facing=south,half=lower,hinge=left,open=false,powered=false]"
      },
      {
        "char": "0",
        "block": "minecraft:spruce_door[facing=south,half=upper,hinge=left,open=false,powered=false]"
      },
      {
        "char": "1",
        "block": "tfmg:asphalt"
      },
      {
        "char": "2",
        "block": "tfmg:cinder_block"
      },
      {
        "char": "3",
        "block": "tfmg:factory_floor"
      },
      {
        "char": "4",
        "block": "tfmg:steel_block"
      },
      {
        "char": "5",
        "block": "zvhouses:stone_brick_countertop"
      }
    ]
  }
}
