{
  "xsize": 16,
  "zsize": 16,
  "slices": [
    [
      "))))))))))))))))",
      "))))))))))))))))",
      "))))))))))))%)))",
      "))))))))))%%$)))",
      "))))))))))))))))",
      "))))))))))))))))",
      "))))))))))))))))",
      "))))))))))))))))",
      "))))))))))))))))",
      "))))))))))))))))",
      "))))))))))))))))",
      "                ",
      "                ",
      "                ",
      "                ",
      "                "
    ],
    [
      "++++++++++++++  ",
      "++++++++++++++  ",
      "++++++++++++++  ",
      "++++++++++++++  ",
      "((((((((((((((( ",
      "((((((((((((((( ",
      "((((((((((((((( ",
      "'''''(('''''((, ",
      "'''''  '''''    ",
      "                ",
      "                ",
      "                ",
      "                ",
      "                ",
      "                ",
      "                "
    ],
    [
      ".   ...   ...&  ",
      ".   ...   ...&  ",
      ".   ...   ...&  ",
      "             &  ",
      "     **     &&& ",
      "                ",
      "                ",
      "'''''  '''''  , ",
      "'''''  '''''    ",
      "                ",
      "                ",
      "                ",
      "                ",
      "                ",
      "                ",
      "                "
    ],
    [
      "     -     - *  ",
      "             *  ",
      "             *  ",
      "     ,,     ,*  ",
      "     ,,     ,&& ",
      "     ,,     ,   ",
      "                ",
      "              , ",
      "                ",
      "                ",
      "                ",
      "                ",
      "                ",
      "                ",
      "                ",
      "                "
    ],
    [
      "             *  ",
      "             *  ",
      "             *  ",
      "     ,,     ,*  ",
      "     ,,     ,&& ",
      "     ,,     ,   ",
      "                ",
      "              , ",
      "                ",
      "                ",
      "                ",
      "                ",
      "                ",
      "                ",
      "                ",
      "                "
    ],
    [
      "             !  ",
      "             *  ",
      "             *  ",
      "     ,,     ,*  ",
      "     ,,     ,&& ",
      "     ,,     ,   ",
      "                ",
      "              , ",
      "                ",
      "                ",
      "                ",
      "                ",
      "                ",
      "                ",
      "                ",
      "                "
    ]
  ],
  "palette": {
    "palette": [
      {
        "char": "!",
        "block": "create:framed_glass"
      },
      {
        "char": "$",
        "block": "minecraft:coarse_dirt"
      },
      {
        "char": "%",
        "block": "minecraft:gravel"
      },
      {
        "char": "&",
        "block": "minecraft:mud_bricks"
      },
      {
        "char": "'",
        "block": "minecraft:polished_blackstone"
      },
      {
        "char": "(",
        "block": "minecraft:smooth_stone"
      },
      {
        "char": ")",
        "block": "tfmg:asphalt"
      },
      {
        "char": "*",
        "block": "tfmg:cinder_block"
      },
      {
        "char": "+",
        "block": "tfmg:factory_floor"
      },
      {
        "char": ",",
        "block": "tfmg:steel_block"
      },
      {
        "char": "-",
        "block": "the_wasteland_reworked:cardboard_box"
      },
      {
        "char": ".",
        "block": "zvhouses:stone_brick_countertop"
      }
    ]
  }
}
