{
  "xsize": 16,
  "zsize": 16,
  "slices": [
    [
      "                ",
      "                ",
      "      1     1   ",
      "                ",
      "   &&&&&&&&&&&&&",
      "   &            ",
      "   &            ",
      "   &           '",
      "   &           '",
      "   &            ",
      "   &            ",
      "   &            ",
      "   &            ",
      "   &            ",
      "   &            ",
      "   &            "
    ],
    [
      "                ",
      "                ",
      "      *******   ",
      "      *******   ",
      "   &&&*******&&&",
      "   &((((((((((((",
      "   &((((((((((((",
      "   &((((((((((('",
      "   &((((((((((('",
      "   &((((((((((((",
      "   &((((((((((((",
      "   &((((((((((((",
      "   &((((((((((((",
      "   &((((((((((((",
      "   &((((((((((((",
      "   &(((((((((((("
    ],
    [
      "                ",
      "                ",
      "                ",
      "    .....  .....",
      "   &&&&&&&&&&&&&",
      "   &            ",
      "   & ..     ..  ",
      "   & 0      0  '",
      "   &           '",
      "   &            ",
      "   &            ",
      "   &33,3333333,3",
      "   &      3   3 ",
      "   &      3.. 3%",
      "   &      30  3%",
      "   &      3 + 3%"
    ],
    [
      "                ",
      "                ",
      "                ",
      "                ",
      "   2!!!!!22!!!!!",
      "   &            ",
      "   &            ",
      "   &           '",
      "   &           '",
      "   &            ",
      "   &            ",
      "   &33-3333333-3",
      "   &      3   3 ",
      "   &      3   3%",
      "   &      3   3%",
      "   &      3   3%"
    ],
    [
      "                ",
      "                ",
      "                ",
      "     )))))))))  ",
      "   2!!!!!22!!!!!",
      "   &            ",
      "   &            ",
      "   &           '",
      "   &           '",
      "   &            ",
      "   &            ",
      "   &333333333333",
      "   &      3   3 ",
      "   &      3   3%",
      "   &      3   3%",
      "   &      3   3%"
    ],
    [
      "                ",
      "                ",
      "       $$$$$    ",
      "    /////))/////",
      "   &&&&&&&&&&&&&",
      "   &            ",
      "   &            ",
      "   &           '",
      "   &           '",
      "   &            ",
      "   &            ",
      "   &333333333333",
      "   &      3   3 ",
      "   &      3   3 ",
      "   &      3   3 ",
      "   &      3   3 "
    ]
  ],
  "palette": {
    "palette": [
      {
        "char": "!",
        "block": "create:framed_glass"
      },
      {
        "char": "$",
        "block": "minecraft:blue_terracotta"
      },
      {
        "char": "%",
        "block": "minecraft:bookshelf"
      },
      {
        "char": "&",
        "block": "minecraft:bricks"
      },
      {
        "char": "'",
        "block": "minecraft:mud_bricks"
      },
      {
        "char": "(",
        "block": "minecraft:polished_andesite"
      },
      {
        "char": ")",
        "block": "minecraft:smooth_stone"
      },
      {
        "char": "*",
        "block": "minecraft:smooth_stone_slab[type=top,waterlogged=false]"
      },
      {
        "char": "+",
        "block": "minecraft:spawner",
        "tag": {
          "id": "minecraft:mob_spawner",
          "Delay": 200,
          "MinSpawnDelay": 240,
          "MaxSpawnDelay": 720,
          "SpawnCount": 2,
          "MaxNearbyEntities": 6,
          "RequiredPlayerRange": 14,
          "SpawnRange": 4,
          "SpawnData": {
            "entity": {
              "id": "minecraft:pillager"
            }
          },
          "SpawnPotentials": [
            {
              "weight": 1,
              "data": {
                "entity": {
                  "id": "minecraft:pillager"
                }
              }
            }
          ]
        }
      },
      {
        "char": ",",
        "block": "minecraft:spruce_door[facing=south,half=lower,hinge=left,open=false,powered=false]"
      },
      {
        "char": "-",
        "block": "minecraft:spruce_door[facing=south,half=upper,hinge=left,open=false,powered=false]"
      },
      {
        "char": ".",
        "block": "minecraft:spruce_slab[type=bottom,waterlogged=false]"
      },
      {
        "char": "/",
        "block": "minecraft:spruce_slab[type=top,waterlogged=false]"
      },
      {
        "char": "0",
        "block": "minecraft:spruce_stairs[facing=north,half=bottom,shape=straight,waterlogged=false]"
      },
      {
        "char": "1",
        "block": "minecraft:stripped_dark_oak_log[axis=y]"
      },
      {
        "char": "2",
        "block": "minecraft:stripped_spruce_log[axis=y]"
      },
      {
        "char": "3",
        "block": "tfmg:cinder_block"
      }
    ]
  }
}
