{
  "xsize": 16,
  "zsize": 16,
  "slices": [
    [
      "9999999999999999",
      "9999999999999999",
      "9999999999999999",
      "9999999999999999",
      "9999999999999999",
      "9999999999999999",
      "9999999999999999",
      "9999999999999999",
      "9999999999999999",
      "*%99999999999999",
      "9999999999999999",
      "99999999999999**",
      "999999999999**%9",
      "9999999999**%999",
      "99999999**%99999",
      "999999**%9999999"
    ],
    [
      "                ",
      "                ",
      "      5     5   ",
      "  8   8   8   8 ",
      "  8,,,,,,,,,,,,,",
      "  8,,,,,,,,,,,,,",
      "  8,,,,,,,,,,,,,",
      "  8,,,,,,,,,,,,,",
      "   ,,,,,,,,,,,,,",
      "   ,,,,,,,,,,,,,",
      "   ,,,,,,,,,,,,,",
      "   ,,,,,,,,,,,,,",
      "   ,,,,,,,,,,,,,",
      "   ,,,,,,,,,,,,,",
      "   ,,,,,,,,,,,,,",
      "   ,,,,,,,,,,,,,"
    ],
    [
      "                ",
      "                ",
      "      5     5   ",
      "    222    22222",
      "   $$$$$&'$$$$$$",
      "   $            ",
      "   $            ",
      "   $ 22     22 +",
      "   $ 4      4  +",
      "   $            ",
      "   $            ",
      "   $::0:::::::0:",
      "   $      :   : ",
      "   $ -<<< :22 : ",
      "   $      :4  :7",
      "   $      .   . "
    ],
    [
      "                ",
      "                ",
      "      5     5   ",
      "                ",
      "   6!!!6()6!!!!!",
      "   $            ",
      "   $            ",
      "   $          ;+",
      "   $           +",
      "   $            ",
      "   $            ",
      "   $::1:::::::1:",
      "   $      :   : ",
      "   $      :   : ",
      "   $ -    :   : ",
      "   $      /   / "
    ],
    [
      "                ",
      "                ",
      "      5     5   ",
      "                ",
      "   6!!!6  6!!!!!",
      "   $            ",
      "   $            ",
      "   $           +",
      "   $           +",
      "   $            ",
      "   $            ",
      "   $::::::::::::",
      "   $      :   : ",
      "   $      :   : ",
      "   $      :   : ",
      "   $ -    :   : "
    ],
    [
      "                ",
      "                ",
      "      5     5   ",
      "    333    33333",
      "   $$$$$$$$$$$$$",
      "   $            ",
      "   $            ",
      "   $           +",
      "   $           +",
      "   $            ",
      "   $            ",
      "   $::::::::::::",
      "   $      :   : ",
      "   $      :   : ",
      "   $      :   : ",
      "   $      :   : "
    ]
  ],
  "palette": {
    "palette": [
      {
        "char": "!",
        "block": "create:framed_glass"
      },
      {
        "char": "$",
        "block": "minecraft:bricks"
      },
      {
        "char": "%",
        "block": "minecraft:coarse_dirt"
      },
      {
        "char": "&",
        "block": "minecraft:dark_oak_door[facing=north,half=lower,hinge=left,open=false,powered=false]"
      },
      {
        "char": "'",
        "block": "minecraft:dark_oak_door[facing=north,half=lower,hinge=right,open=false,powered=false]"
      },
      {
        "char": "(",
        "block": "minecraft:dark_oak_door[facing=north,half=upper,hinge=left,open=false,powered=false]"
      },
      {
        "char": ")",
        "block": "minecraft:dark_oak_door[facing=north,half=upper,hinge=right,open=false,powered=false]"
      },
      {
        "char": "*",
        "block": "minecraft:gravel"
      },
      {
        "char": "+",
        "block": "minecraft:mud_bricks"
      },
      {
        "char": ",",
        "block": "minecraft:polished_andesite"
      },
      {
        "char": "-",
        "block": "minecraft:polished_andesite_stairs[facing=south,half=bottom,shape=straight,waterlogged=false]"
      },
      {
        "char": ".",
        "block": "minecraft:spruce_door[facing=east,half=lower,hinge=left,open=false,powered=false]"
      },
      {
        "char": "/",
        "block": "minecraft:spruce_door[facing=east,half=upper,hinge=left,open=false,powered=false]"
      },
      {
        "char": "0",
        "block": "minecraft:spruce_door[facing=south,half=lower,hinge=left,open=false,powered=false]"
      },
      {
        "char": "1",
        "block": "minecraft:spruce_door[facing=south,half=upper,hinge=left,open=false,powered=false]"
      },
      {
        "char": "2",
        "block": "minecraft:spruce_slab[type=bottom,waterlogged=false]"
      },
      {
        "char": "3",
        "block": "minecraft:spruce_slab[type=top,waterlogged=false]"
      },
      {
        "char": "4",
        "block": "minecraft:spruce_stairs[facing=north,half=bottom,shape=straight,waterlogged=false]"
      },
      {
        "char": "5",
        "block": "minecraft:stripped_dark_oak_log[axis=y]"
      },
      {
        "char": "6",
        "block": "minecraft:stripped_spruce_log[axis=y]"
      },
      {
        "char": "7",
        "block": "kubejs:ruined_cauldron"
      },
      {
        "char": "8",
        "block": "minecraft:white_concrete"
      },
      {
        "char": "9",
        "block": "tfmg:asphalt"
      },
      {
        "char": ":",
        "block": "tfmg:cinder_block"
      },
      {
        "char": ";",
        "block": "the_wasteland_reworked:radio"
      },
      {
        "char": "<",
        "block": "zvhouses:spruce_countertop"
      }
    ]
  }
}
