{
  "xsize": 16,
  "zsize": 16,
  "slices": [
    [
      "////////////////",
      "////////////////",
      "////////////////",
      "////////////////",
      "////////////''&/",
      "//////////''&///",
      "////////''&/////",
      "//////''&///////",
      "////''&/////////",
      "//''&///////////",
      "''&/////////////",
      "&///////////////",
      "///////////////'",
      "/////////////''&",
      "///////////''&//",
      "/////////''&////"
    ],
    [
      "                ",
      "                ",
      "                ",
      "  .             ",
      ")))             ",
      ")))             ",
      ")))             ",
      ")))             ",
      ")))1111111111111",
      ")))1111111111111",
      ")))1111111111111",
      ")))1111111111111",
      ")))1111111111111",
      ")))1111111111111",
      ")))1111111111111",
      ")))1111111111111"
    ],
    [
      "                ",
      "                ",
      "                ",
      "+               ",
      "%%%             ",
      "  %             ",
      "  %             ",
      "  %  (     (    ",
      "((((((((((((((((",
      "  %  0          ",
      "  %  0          ",
      "00%  02*$  2*$  ",
      "  %  0 *$   *$  ",
      "  %  0 *$   *$  ",
      "  %  0 *$   *$  ",
      "  %  0 *$   *$  "
    ],
    [
      "                ",
      "                ",
      "                ",
      "                ",
      "!-%             ",
      "  %             ",
      "  %             ",
      "  %  (     (    ",
      "  %00(00000(0000",
      "  %  0          ",
      "  %  0          ",
      "00%  02*   2*   ",
      "  %  0 *    *   ",
      "  %  0 *    *   ",
      "  %  0 *    *   ",
      "  %  0 *    *   "
    ],
    [
      "                ",
      "                ",
      "                ",
      "                ",
      "!-%             ",
      "  %             ",
      "  %             ",
      "  +++(  +++(  ++",
      "  %00(00000(0000",
      "  %  0          ",
      "  %  0          ",
      "00%  02    2    ",
      "  %  0          ",
      "  %  0          ",
      "  %  0          ",
      "  %  0          "
    ],
    [
      "                ",
      "                ",
      "                ",
      ",               ",
      "%%%             ",
      "  %             ",
      "  %             ",
      "  %  (     (    ",
      " -!!!-0-!!!-0-!!",
      "  %  0          ",
      "  %  0          ",
      "00%  02    2    ",
      "  %  0          ",
      "  %  0          ",
      "  %  0          ",
      "  %  0          "
    ]
  ],
  "palette": {
    "palette": [
      {
        "char": "!",
        "block": "create:framed_glass"
      },
      {
        "char": "$",
        "block": "jaffabricate:pallet_full"
      },
      {
        "char": "%",
        "block": "minecraft:bricks"
      },
      {
        "char": "&",
        "block": "minecraft:coarse_dirt"
      },
      {
        "char": "'",
        "block": "minecraft:gravel"
      },
      {
        "char": "(",
        "block": "minecraft:mud_bricks"
      },
      {
        "char": ")",
        "block": "minecraft:polished_andesite"
      },
      {
        "char": "*",
        "block": "minecraft:scaffolding"
      },
      {
        "char": "+",
        "block": "minecraft:spruce_slab[type=bottom,waterlogged=false]"
      },
      {
        "char": ",",
        "block": "minecraft:spruce_slab[type=top,waterlogged=false]"
      },
      {
        "char": "-",
        "block": "minecraft:stripped_spruce_log[axis=y]"
      },
      {
        "char": ".",
        "block": "minecraft:white_concrete"
      },
      {
        "char": "/",
        "block": "tfmg:asphalt"
      },
      {
        "char": "0",
        "block": "tfmg:cinder_block"
      },
      {
        "char": "1",
        "block": "tfmg:factory_floor"
      },
      {
        "char": "2",
        "block": "tfmg:steel_block"
      }
    ]
  }
}
