{
  "xsize": 16,
  "zsize": 16,
  "slices": [
    [
      "%%%%%%%%%%%%%%%%",
      "%%%%%%%%%%%%%%%%",
      "&&&&&&&&&&&&&&&&",
      "&&&&&&&&&&&&&&&&",
      "&&&&&&&&&&&&&&&&",
      "%%%%%%%%%%%%%%%%",
      "%%%%%%%%%%%%%%%%",
      "%%%%%%%%%%%%%%%%",
      "%%%%%%%%%%%%%%%%",
      "%%%%%%%%%%%%%%%%",
      "%%%%%%%%%%%%%%%%",
      "%%%%%%%%%%%%%%%%",
      "%%%%%%%%%%%%%   ",
      "                ",
      "                ",
      "                "
    ],
    [
      "!!!!!!!!!!!!!!!!",
      "!!!!!!!!!!!!!!!!",
      "!!!!!!!!!!!!!!!!",
      "!!!!!!!!!!!!!!!!",
      "!!!!!!!!!!!!!!!!",
      "!!!!!!!!!!!!!!!!",
      "!!!!!!!!!!!!!!!!",
      "!!!!!!!!!!!!!!!!",
      "!!!!!!!!!!!!!!!!",
      "!!!!!!!!!!!!!!!!",
      "!!!!!!!!!!!!!!!!",
      "!!!!!!!!!!!!!!!!",
      "!!!!!!!!!!!!!!!!",
      "                ",
      "                ",
      "                "
    ],
    [
      "$$$$  $$$$$ !  $",
      "$$$$  $$$$$ !  $",
      "$$$$  $$$$$ !  $",
      "$$$$  $$$$$ (  $",
      "$$$$  $$$$$ !  $",
      "$$$'  $$$$$ !  $",
      "$$$$  $$$$$ !  $",
      "$$$$  $$$$$ !  $",
      "$$$$  $$$$$ !  $",
      "$$$$  $$$$$ !  $",
      "            !   ",
      "%%%%%%%%%%%%!%%%",
      "%%%%%%%%%%%%%   ",
      "                ",
      "                ",
      "                "
    ],
    [
      "$$$$  $$$$$ !  $",
      "$$$$  $$$$$ !  $",
      "$$$$  $$$$$ !  $",
      "$$$$  $$$$$ )  $",
      "$$$$  $$$$$ !  $",
      "$$$$  $$$$$ !  $",
      "$$$$  $$$$$ !  $",
      "$$$$  $$$$$ !  $",
      "$$$$  $$$$$ !  $",
      "$$$$  $$$$$ !  $",
      "            !   ",
      "%%%%%%%%%%%%!%%%",
      "%%%%%%%%%%%%%   ",
      "                ",
      "                ",
      "                "
    ],
    [
      "!!!!!!!!!!!!!  $",
      "!!!!!!!!!!!!!  $",
      "!!!!!!!!!!!!!  $",
      "!!!!!!!!!!!!!  $",
      "!!!!!!!!!!!!!  $",
      "!!!!!!!!!!!!!  $",
      "!!!!!!!!!!!!!  $",
      "!!!!!!!!!!!!!  $",
      "!!!!!!!!!!!!!  $",
      "!!!!!!!!!!!!!  $",
      "!!!!!!!!!!!!!   ",
      "!!!!!!!!!!!!!%%%",
      "!!!!!!!!!!!!%   ",
      "!!!!!!!!!!!!    ",
      "!!!!!!!!!!!!    ",
      "!!!!!!!!!!!!    "
    ],
    [
      "           !!  $",
      "           !!  $",
      "           !!  $",
      "           !!  $",
      "           !!  $",
      "           !!  $",
      "           !!  $",
      "           !!  $",
      "           !!  $",
      "           !!  $",
      "           !!   ",
      "           !!%%%",
      "           !%   ",
      "!!!!!!!!!!!!    ",
      "!!!!!!!!!!!!    ",
      "!!!!!!!!!!!!    "
    ]
  ],
  "palette": {
    "palette": [
      {
        "char": "!",
        "block": "immersiveengineering:sheetmetal_steel"
      },
      {
        "char": "$",
        "block": "jaffabricate:pallet_full"
      },
      {
        "char": "%",
        "block": "minecraft:oxidized_copper"
      },
      {
        "char": "&",
        "block": "minecraft:polished_blackstone_bricks"
      },
      {
        "char": "'",
        "block": "minecraft:spawner",
        "tag": {
          "id": "minecraft:mob_spawner",
          "Delay": 200,
          "MinSpawnDelay": 240,
          "MaxSpawnDelay": 720,
          "SpawnCount": 2,
          "MaxNearbyEntities": 7,
          "RequiredPlayerRange": 14,
          "SpawnRange": 4,
          "SpawnData": {
            "entity": {
              "id": "minecraft:zombie"
            }
          },
          "SpawnPotentials": [
            {
              "weight": 1,
              "data": {
                "entity": {
                  "id": "minecraft:zombie"
                }
              }
            }
          ]
        }
      },
      {
        "char": "(",
        "block": "minecraft:spruce_door[facing=east,half=lower,hinge=left,open=false,powered=false]"
      },
      {
        "char": ")",
        "block": "minecraft:spruce_door[facing=east,half=upper,hinge=left,open=false,powered=false]"
      }
    ]
  }
}
