{
  "xsize": 16,
  "zsize": 16,
  "slices": [
    [
      "                ",
      "                ",
      "                ",
      "                ",
      "''''''''''      ",
      "''''''''''      ",
      "''''''''''      ",
      "''''''''''      ",
      "                ",
      "                ",
      "                ",
      "                ",
      "&&&             ",
      "&&&&&&          ",
      "&&&&&&          ",
      "&&&&&&          "
    ],
    [
      "                ",
      "                ",
      "                ",
      "                ",
      "''''''''''      ",
      "''''''''''      ",
      "''''''''''      ",
      "''''''''''      ",
      "                ",
      "                ",
      "$$$$$$$$$$$$$$$$",
      "$$$$$$$$$$$$$$$$",
      "$$$$$$$$$$$$$$$$",
      "$$$$$$$$$$$$$$$$",
      "$$$$$$$$$$$$$$$$",
      "$$$$$$$$$$$$$$$$"
    ],
    [
      "                ",
      "                ",
      "                ",
      "                ",
      "''''''''''      ",
      "''''''''''      ",
      "''''''''''      ",
      "''''''''''      ",
      "                ",
      "                ",
      "                ",
      "       $        ",
      "       $        ",
      "%%%%   $        ",
      "%%%%   $ !   !  ",
      "%%%%   $        "
    ],
    [
      "                ",
      "                ",
      "                ",
      "                ",
      "''''''''''      ",
      "''''''''''      ",
      "''''''''''      ",
      "''''''''''      ",
      "                ",
      "                ",
      "                ",
      "       $        ",
      "       $        ",
      "%%%%   $        ",
      "%%%%   $        ",
      "%%%%   $        "
    ],
    [
      "                ",
      "                ",
      "                ",
      "                ",
      "''''''''''      ",
      "''''''''''      ",
      "''''''''''      ",
      "''''''''''      ",
      "                ",
      "                ",
      "                ",
      "       $        ",
      "       $        ",
      "%%%%   $        ",
      "%%%%   $        ",
      "%%%%   $        "
    ],
    [
      "                ",
      "                ",
      "                ",
      "                ",
      "                ",
      "                ",
      "                ",
      "                ",
      "                ",
      "                ",
      "                ",
      "       $        ",
      "       $        ",
      "%%%%   $        ",
      "%%%%   $        ",
      "%%%%   $        "
    ]
  ],
  "palette": {
    "palette": [
      {
        "char": "!",
        "block": "create:mechanical_press"
      },
      {
        "char": "$",
        "block": "immersiveengineering:sheetmetal_steel"
      },
      {
        "char": "%",
        "block": "jaffabricate:pallet_full"
      },
      {
        "char": "&",
        "block": "minecraft:oxidized_copper"
      },
      {
        "char": "'",
        "block": "tfmg:steel_block"
      }
    ]
  }
}
