{
  "xsize": 16,
  "zsize": 16,
  "slices": [
    [
      "                ",
      "                ",
      "                ",
      "                ",
      "                ",
      "                ",
      "                ",
      "                ",
      "                ",
      "                ",
      "          ''''''",
      "       '''''''''",
      "    ''''''''''''",
      " '''''''''''''''",
      " '''''''''''''''",
      " '''''''''''''''"
    ],
    [
      "                ",
      "                ",
      "                ",
      "                ",
      "                ",
      "                ",
      "                ",
      "                ",
      "                ",
      "                ",
      "!!!!!!!!!!!!!!!!",
      "!!!!!!!!!!!!!!!!",
      "!!!!!!!!!!!!!!!!",
      "!!!!!!!!!!!!!!!!",
      "!!!!!!!!!!!!!!!!",
      "!!!!!!!!!!!!!!!!"
    ],
    [
      "                ",
      "                ",
      "                ",
      "                ",
      "                ",
      "                ",
      "                ",
      "                ",
      "                ",
      "                ",
      "          ''''''",
      " !  &  '&''!''''",
      " !  %   %  !    ",
      " !  $$$$$  !   $",
      " !  $$$$$  !   $",
      " !  $$$$$  !   $"
    ],
    [
      "                ",
      "                ",
      "                ",
      "                ",
      "                ",
      "                ",
      "                ",
      "                ",
      "                ",
      "                ",
      "          ''''''",
      " !     ''''!''''",
      " !         !    ",
      " !  $$$$$  !   $",
      " !  $$$$$  !   $",
      " !  $$$$$  !   $"
    ],
    [
      "         !!!!!!!",
      "         !!!!!!!",
      "         !!!!!!!",
      "         !!!!!!!",
      "         !!!!!!!",
      "         !!!!!!!",
      "         !!!!!!!",
      "         !!!!!!!",
      "         !!!!!!!",
      "         !!!!!!!",
      "         !!!!!!!",
      " !     ''!!!!!!!",
      " !       !!!!!!!",
      " !  $$$$$!!!!!!!",
      " !  $$$$$!!!!!!!",
      " !  $$$$$!!!!!!!"
    ],
    [
      "         !!!!!!!",
      "         !!!!!!!",
      "         !!!!!!!",
      "         !!!!!!!",
      "         !!!!!!!",
      "         !!!!!!!",
      "         !!!!!!!",
      "         !!!!!!!",
      "         !!!!!!!",
      "         !!!!!!!",
      "         !      ",
      " !     ''!      ",
      " !       !      ",
      " !  $$$$$!      ",
      " !  $$$$$!      ",
      " !  $$$$$!      "
    ]
  ],
  "palette": {
    "palette": [
      {
        "char": "!",
        "block": "immersiveengineering:sheetmetal_steel"
      },
      {
        "char": "$",
        "block": "jaffabricate:pallet_full"
      },
      {
        "char": "%",
        "block": "minecraft:gray_bed[facing=north,occupied=false,part=foot]"
      },
      {
        "char": "&",
        "block": "minecraft:gray_bed[facing=north,occupied=false,part=head]"
      },
      {
        "char": "'",
        "block": "minecraft:oxidized_copper"
      }
    ]
  }
}
