{
  "xsize": 16,
  "zsize": 16,
  "slices": [
    [
      "  !       (   ( ",
      "  !(((((((((((((",
      "  !       (   ( ",
      "  !       (   ( ",
      "  !       (   ( ",
      "  !(((((((((((((",
      "  !       (   ( ",
      "  !       (   ( ",
      "  !       (   ( ",
      "  !       (   ( ",
      "  !       (   ( ",
      "  !       (   ( ",
      "  !       (   ( ",
      "  !       (   ( ",
      "  !!!!!!!!!!!!!!",
      "                "
    ],
    [
      "  !             ",
      "  !             ",
      "  !             ",
      "  !             ",
      "  !             ",
      "  !             ",
      "  !             ",
      "  !             ",
      "  !             ",
      "  !             ",
      "  !             ",
      "  !             ",
      "  !             ",
      "  !             ",
      "  !!!!!!!!!!!!!!",
      "                "
    ],
    [
      "  %%%%%%&&&&&&&&",
      "  %%%%%%&&&&&&&&",
      "  %%%%%%&&&&&&&&",
      "  %%%%%%&&&&&&&&",
      "  %%%%%%&&&&&&&&",
      "  %%%%%%&&&&&&&&",
      "  %%%%%%&&&&&&&&",
      "  %%%%%%%%%%%%%%",
      "  %%%%%%%%%%%%%%",
      "  %%%%%%%%%%%%%%",
      "  %%%%%%%%%%%%%%",
      "  %%%%%%%%%%%%%%",
      "  %%%%%%%%%%%%%%",
      "  %%%%%%%%%%%%%%",
      "  %%%%%%%%%%%%%%",
      "                "
    ],
    [
      "     $$$$$$!!!!!",
      "     $$$$$$     ",
      "     $$$$$$     ",
      "     $$$$$$     ",
      "     $$$$$$     ",
      "     $$$$$$     ",
      "     $$$$$$!!!!!",
      "     $$$$$$     ",
      "     $$$$$$     ",
      "     $$$$$$     ",
      "     $$$$$$     ",
      "                ",
      "                ",
      "                ",
      "                ",
      "                "
    ],
    [
      "     '  !!'!!!!!",
      "        !       ",
      "        !       ",
      "        !       ",
      "        !       ",
      "        !       ",
      "        !!!!!!!!",
      "                ",
      "                ",
      "                ",
      "     '    '     ",
      "                ",
      "                ",
      "                ",
      "                ",
      "                "
    ],
    [
      "        %%%%%%%%",
      "        %%%%%%%%",
      "        %%%%%%%%",
      "        %%%%%%%%",
      "        %%%%%%%%",
      "        %%%%%%%%",
      "        %%%%%%%%",
      "                ",
      "                ",
      "                ",
      "                ",
      "                ",
      "                ",
      "                ",
      "                ",
      "                "
    ]
  ],
  "palette": {
    "palette": [
      {
        "char": "!",
        "block": "minecraft:mud_bricks"
      },
      {
        "char": "$",
        "block": "minecraft:oak_slab[type=top,waterlogged=false]"
      },
      {
        "char": "%",
        "block": "minecraft:smooth_stone"
      },
      {
        "char": "&",
        "block": "minecraft:spruce_planks"
      },
      {
        "char": "'",
        "block": "minecraft:stripped_oak_log[axis=y]"
      },
      {
        "char": "(",
        "block": "minecraft:stripped_spruce_wood"
      }
    ]
  }
}
