{
  "xsize": 16,
  "zsize": 16,
  "slices": [
    [
      "                ",
      "                ",
      "!!!!!!!!        ",
      "       !        ",
      "       !        ",
      "       !        ",
      "       !        ",
      "       !        ",
      "       !        ",
      "       !        ",
      "&&&&&&&!        ",
      "       !        ",
      "       !        ",
      "       !        ",
      "&&&&&&&!        ",
      "       !        "
    ],
    [
      "                ",
      "                ",
      "!!!!!!!!        ",
      "       !        ",
      "       !        ",
      "       !        ",
      "       !        ",
      "       !        ",
      "       !        ",
      "       !        ",
      "       !        ",
      "       !        ",
      "       !        ",
      "       !        ",
      "       !        ",
      "       !        "
    ],
    [
      "                ",
      "                ",
      "%%%%%%%%        ",
      "%%%%%%%%        ",
      "%%%%%%%%        ",
      "%%%%%%%%        ",
      "%%%%%%%%        ",
      "%%%%%%%%        ",
      "%%%%%%%%        ",
      "$%%%%%%%        ",
      "$%%%%%%%        ",
      "$%%%%%%%        ",
      "$%%%%%%%        ",
      "$%%%%%%%        ",
      "$%%%%%%%        ",
      "$%%%%%%%        "
    ],
    [
      "                ",
      "                ",
      "                ",
      "                ",
      "                ",
      "                ",
      "                ",
      "                ",
      "                ",
      "!               ",
      "!               ",
      "!               ",
      "!               ",
      "!               ",
      "!               ",
      "!               "
    ],
    [
      "                ",
      "                ",
      "                ",
      "                ",
      "                ",
      "                ",
      "                ",
      "                ",
      "                ",
      "!               ",
      "!               ",
      "!               ",
      "!               ",
      "!               ",
      "!               ",
      "!               "
    ],
    [
      "                ",
      "                ",
      "                ",
      "                ",
      "                ",
      "                ",
      "                ",
      "                ",
      "                ",
      "%               ",
      "%               ",
      "%               ",
      "%               ",
      "%               ",
      "%               ",
      "%               "
    ]
  ],
  "palette": {
    "palette": [
      {
        "char": "!",
        "block": "minecraft:bricks"
      },
      {
        "char": "$",
        "block": "minecraft:oak_planks"
      },
      {
        "char": "%",
        "block": "minecraft:smooth_stone"
      },
      {
        "char": "&",
        "block": "minecraft:stripped_spruce_wood"
      }
    ]
  }
}
