{
  "xsize": 16,
  "zsize": 16,
  "slices": [
    [
      "))))))))     !!!",
      "))))))))     !!!",
      "))))))))     !!!",
      "))))))))     !!!",
      "))))))))     !!!",
      "))))))))     !!!",
      "))))))))     !!!",
      "))))))))     !!!",
      "             !!!",
      "             !!!",
      "             !!!",
      "           )))))",
      "           )))))",
      "!!!!!!!!!!!)))))",
      "!!!!!!!!!!!)))))",
      "!!!!!!!!!!!)))))"
    ],
    [
      "$$$$$  !     !  ",
      "$$$$$  !     !  ",
      "$$$$$  !     !  ",
      "$$$$$  !     !  ",
      "$$$$$  !     !  ",
      "       !     !  ",
      "       !     !  ",
      "!!!!!!!!     !  ",
      "             !  ",
      "             !  ",
      "             !  ",
      "           !!!  ",
      "           !$$  ",
      "!!!!!!!!!!!!$$  ",
      "                ",
      "                "
    ],
    [
      "$$$$$  !     !  ",
      "$$$$$  !     !  ",
      "$$$$$  !     !  ",
      "$$$$$  !     !  ",
      "$$$$$  !     !  ",
      "       !     !  ",
      "       !     !  ",
      "!!!!!!!!     !  ",
      "             !  ",
      "             !  ",
      "             !  ",
      "           !!!  ",
      "           !$$  ",
      "!!!!!!!!!!!!$$  ",
      "                ",
      "                "
    ],
    [
      "$$$$$  !     !  ",
      "$$$$$  !     !  ",
      "$$$$$  !     !  ",
      "$$$$$  !     !  ",
      "$$$$$  !     !  ",
      "       !     !  ",
      "       !     !  ",
      "!!!!!!!!     !  ",
      "             !  ",
      "             !  ",
      "             !  ",
      "           !!!  ",
      "           !$$  ",
      "!!!!!!!!!!!!$$  ",
      "                ",
      "                "
    ],
    [
      "       !     !  ",
      "       !     !  ",
      "       !     !  ",
      "       !     !  ",
      "       !     !  ",
      "       !     !  ",
      "       !     !  ",
      "!!!!!!!!     !  ",
      "             !  ",
      "             !  ",
      "             !  ",
      "           !!!  ",
      "           !    ",
      "!!!!!!!!!!!!    ",
      "                ",
      "                "
    ],
    [
      "%%%%%%%%''&((!!!",
      "%%%%%%%%'''((!!!",
      "%%%%%%%%'''((!!!",
      "%%%%%%%%'''((!!!",
      "%%%%%%%%'''((!!!",
      "%%%%%%%%'''((!!!",
      "%%%%%%%%'''((!!!",
      "%%%%%%%%'''((!!!",
      "'''''''''''''!!!",
      "'''''''''&'''!!!",
      "'''''''''''''!!!",
      "(((((((('''!!!!!",
      "(((((((('''!!!!!",
      "!!!!!!!!!!!!!!!!",
      "!!!!!!!!!!!!!!!!",
      "!!!!!!!!!!!!!!!!"
    ]
  ],
  "palette": {
    "palette": [
      {
        "char": "!",
        "block": "immersiveengineering:concrete_reinforced"
      },
      {
        "char": "$",
        "block": "immersiveengineering:sheetmetal_steel"
      },
      {
        "char": "%",
        "block": "minecraft:oak_planks"
      },
      {
        "char": "&",
        "block": "minecraft:polished_blackstone_bricks"
      },
      {
        "char": "'",
        "block": "minecraft:smooth_stone"
      },
      {
        "char": "(",
        "block": "tfmg:asphalt"
      },
      {
        "char": ")",
        "block": "tfmg:factory_floor"
      }
    ]
  }
}
