{
  "xsize": 16,
  "zsize": 16,
  "slices": [
    [
      " )%(((((((((((((",
      " )%(((((((((((((",
      " )%(((((((((((((",
      " )%(((((((((((((",
      " )%(((((((((((((",
      " )%(((((((((((((",
      " )%(((((((((((((",
      " )%%%%%%%%%%%%%%",
      "                ",
      "                ",
      "                ",
      "                ",
      "                ",
      "                ",
      "                ",
      "                "
    ],
    [
      "  %   **  ,   ,*",
      "  %   +   ,   ,+",
      "  %     $ &   & ",
      "  %       ,   , ",
      "  %       ,   , ",
      "  %       ,   , ",
      "  %       ,   , ",
      "  %%%%%%%%%%%%%%",
      "                ",
      "                ",
      "                ",
      "                ",
      "                ",
      "                ",
      "                ",
      "                "
    ],
    [
      "  %       ,   , ",
      "  %       ,   , ",
      "  !       '   ' ",
      "  !       ,   , ",
      "  %       ,   , ",
      "  %       ,   , ",
      "  %       ,   , ",
      "  %%%%!!%%%%!!%%",
      "                ",
      "                ",
      "                ",
      "                ",
      "                ",
      "                ",
      "                ",
      "                "
    ],
    [
      "  %       ,   , ",
      "  %       ,   , ",
      "  !       ,   , ",
      "  !       ,   , ",
      "  %       ,   , ",
      "  %       ,   , ",
      "  %       ,   , ",
      "  %%%%!!%%%%!!%%",
      "                ",
      "                ",
      "                ",
      "                ",
      "                ",
      "                ",
      "                ",
      "                "
    ],
    [
      "  %       ,   , ",
      "  %       ,   , ",
      "  %       ,   , ",
      "  %       ,   , ",
      "  %       ,   , ",
      "  %       ,   , ",
      "  %       ,   , ",
      "  %%%%%%%%%%%%%%",
      "                ",
      "                ",
      "                ",
      "                ",
      "                ",
      "                ",
      "                ",
      "                "
    ],
    [
      "  %       ,   , ",
      "  %       ,   , ",
      "  %       ,   , ",
      "  %       ,   , ",
      "  %       ,   , ",
      "  %       ,   , ",
      "  %       ,   , ",
      "  %%%%%%%%%%%%%%",
      "                ",
      "                ",
      "                ",
      "                ",
      "                ",
      "                ",
      "                ",
      "                "
    ]
  ],
  "palette": {
    "palette": [
      {
        "char": "!",
        "block": "create:framed_glass"
      },
      {
        "char": "$",
        "block": "minecraft:bookshelf"
      },
      {
        "char": "%",
        "block": "minecraft:bricks"
      },
      {
        "char": "&",
        "block": "minecraft:dark_oak_door[facing=east,half=lower,hinge=left,open=false,powered=false]"
      },
      {
        "char": "'",
        "block": "minecraft:dark_oak_door[facing=east,half=upper,hinge=left,open=false,powered=false]"
      },
      {
        "char": "(",
        "block": "minecraft:oak_planks"
      },
      {
        "char": ")",
        "block": "minecraft:smooth_stone_slab[type=top,waterlogged=false]"
      },
      {
        "char": "*",
        "block": "minecraft:spruce_slab[type=bottom,waterlogged=false]"
      },
      {
        "char": "+",
        "block": "minecraft:spruce_stairs[facing=north,half=bottom,shape=straight,waterlogged=false]"
      },
      {
        "char": ",",
        "block": "minecraft:stripped_spruce_wood"
      }
    ]
  }
}
