{
  "xsize": 16,
  "zsize": 16,
  "slices": [
    [
      "       (        ",
      ",,&,,,,(        ",
      "       (        ",
      "       $        ",
      "       (        ",
      ",,&,,,,(        ",
      "       (        ",
      ")      (        ",
      "       (        ",
      "       (        ",
      "       (  +     ",
      "       (        ",
      "       (        ",
      "       (        ",
      "((((((((        ",
      "                "
    ],
    [
      "       (        ",
      ",,',,,,(        ",
      "       (        ",
      "       %        ",
      "       (        ",
      ",,',,,,(        ",
      "       (        ",
      "       (        ",
      "       (        ",
      "       !        ",
      "       !  +     ",
      "       (        ",
      "       (        ",
      "       (        ",
      "((!!((((        ",
      "                "
    ],
    [
      "       (        ",
      ",,,,,,,(        ",
      "       (        ",
      "                ",
      "       (        ",
      ",,,,,,,(        ",
      "       (        ",
      "       (        ",
      "       (        ",
      "       !        ",
      "       !  +     ",
      "       (        ",
      "       (        ",
      "       (        ",
      "((!!((((        ",
      "                "
    ],
    [
      "       (        ",
      ",,,,,,,(        ",
      "       (        ",
      "       (        ",
      "       (        ",
      ",,,,,,,(        ",
      "       (        ",
      "       (        ",
      "       (        ",
      "       (        ",
      "       (  +     ",
      "       (        ",
      "       (        ",
      "       (        ",
      "((((((((        ",
      "                "
    ],
    [
      "       (        ",
      ",,,,,,,(        ",
      "       (        ",
      "       (        ",
      "       (        ",
      ",,,,,,,(        ",
      "       (        ",
      "       (        ",
      "       (        ",
      "       (        ",
      "       (  +     ",
      "       (        ",
      "       (        ",
      "       (        ",
      "((((((((        ",
      "                "
    ],
    [
      "     ******     ",
      "     ******     ",
      "     ******     ",
      "     ******     ",
      "     ******     ",
      "     ******     ",
      "     ******     ",
      "     ******     ",
      "     ******     ",
      "     ******     ",
      "     ******     ",
      "       (        ",
      "       (        ",
      "       (        ",
      "((((((((        ",
      "                "
    ]
  ],
  "palette": {
    "palette": [
      {
        "char": "!",
        "block": "create:framed_glass"
      },
      {
        "char": "$",
        "block": "minecraft:dark_oak_door[facing=east,half=lower,hinge=left,open=false,powered=false]"
      },
      {
        "char": "%",
        "block": "minecraft:dark_oak_door[facing=east,half=upper,hinge=left,open=false,powered=false]"
      },
      {
        "char": "&",
        "block": "minecraft:dark_oak_door[facing=south,half=lower,hinge=left,open=false,powered=false]"
      },
      {
        "char": "'",
        "block": "minecraft:dark_oak_door[facing=south,half=upper,hinge=left,open=false,powered=false]"
      },
      {
        "char": "(",
        "block": "minecraft:mud_bricks"
      },
      {
        "char": ")",
        "block": "minecraft:oak_slab[type=bottom,waterlogged=false]"
      },
      {
        "char": "*",
        "block": "minecraft:red_terracotta"
      },
      {
        "char": "+",
        "block": "minecraft:stripped_dark_oak_log[axis=y]"
      },
      {
        "char": ",",
        "block": "minecraft:stripped_spruce_wood"
      }
    ]
  }
}
