{
  "xsize": 16,
  "zsize": 16,
  "slices": [
    [
      "  $       ,   ,-",
      "  $   **  ,   ,-",
      "  $   +   %   % ",
      "  $       ,   ,-",
      "  $       ,   , ",
      "  $       ,   , ",
      "  $       ,   , ",
      "  $$$$$$$$$$'$$$",
      "                ",
      "                ",
      "                ",
      "                ",
      "                ",
      "                ",
      "              ) ",
      "                "
    ],
    [
      "  $       ,   , ",
      "  $       ,   , ",
      "  !       &   & ",
      "  !       ,   , ",
      "  $       ,   , ",
      "  $       ,   , ",
      "  $       ,   , ",
      "  $$$$!!$$$$($$$",
      "                ",
      "                ",
      "                ",
      "                ",
      "                ",
      "                ",
      "                ",
      "                "
    ],
    [
      "  $       ,   , ",
      "  $       ,   , ",
      "  !       ,   , ",
      "  !       ,   , ",
      "  $       ,   , ",
      "  $       ,   , ",
      "  $       ,   , ",
      "  $$$$!!$$$$ $$$",
      "                ",
      "                ",
      "                ",
      "                ",
      "                ",
      "                ",
      "                ",
      "                "
    ],
    [
      "  $       ,   , ",
      "  $       ,   , ",
      "  $       ,   , ",
      "  $       ,   , ",
      "  $       ,   , ",
      "  $       ,   , ",
      "  $       ,   , ",
      "  $$$$$$$$$$$$$$",
      "                ",
      "                ",
      "                ",
      "                ",
      "                ",
      "                ",
      "                ",
      "                "
    ],
    [
      "  $       ,   , ",
      "  $       ,   , ",
      "  $       ,   , ",
      "  $       ,   , ",
      "  $       ,   , ",
      "  $       ,   , ",
      "  $       ,   , ",
      "  $$$$$$$$$$$$$$",
      "                ",
      "                ",
      "                ",
      "                ",
      "                ",
      "                ",
      "                ",
      "                "
    ],
    [
      "  $             ",
      "  $             ",
      "  $             ",
      "  $             ",
      "  $             ",
      "  $             ",
      "  $             ",
      "  $$$$$$$$$$$$$$",
      "                ",
      "                ",
      "                ",
      "                ",
      "                ",
      "                ",
      "                ",
      "                "
    ]
  ],
  "palette": {
    "palette": [
      {
        "char": "!",
        "block": "create:framed_glass"
      },
      {
        "char": "$",
        "block": "minecraft:bricks"
      },
      {
        "char": "%",
        "block": "minecraft:dark_oak_door[facing=east,half=lower,hinge=left,open=false,powered=false]"
      },
      {
        "char": "&",
        "block": "minecraft:dark_oak_door[facing=east,half=upper,hinge=left,open=false,powered=false]"
      },
      {
        "char": "'",
        "block": "minecraft:dark_oak_door[facing=south,half=lower,hinge=left,open=false,powered=false]"
      },
      {
        "char": "(",
        "block": "minecraft:dark_oak_door[facing=south,half=upper,hinge=left,open=false,powered=false]"
      },
      {
        "char": ")",
        "block": "minecraft:iron_trapdoor[facing=north,half=bottom,open=false,powered=false,waterlogged=false]"
      },
      {
        "char": "*",
        "block": "minecraft:spruce_slab[type=bottom,waterlogged=false]"
      },
      {
        "char": "+",
        "block": "minecraft:spruce_stairs[facing=north,half=bottom,shape=straight,waterlogged=false]"
      },
      {
        "char": ",",
        "block": "minecraft:stripped_spruce_wood"
      },
      {
        "char": "-",
        "block": "zvhouses:stone_brick_countertop"
      }
    ]
  }
}
