{
  "xsize": 16,
  "zsize": 16,
  "slices": [
    [
      "                ",
      "                ",
      "))))))))))))))) ",
      " ,   ,        ) ",
      " ,   ,        ) ",
      " , * ,        ) ",
      " %   %        ) ",
      " ,   ,        ) ",
      " ,   , $      ) ",
      " ,   ,        ) ",
      ",,   ,,,,',,,,) ",
      "              ) ",
      "              ) ",
      "              ) ",
      ",,   ,,,,',,,,) ",
      " ,   ,  +     ) "
    ],
    [
      "                ",
      "                ",
      ")))!!))))!!)))) ",
      " ,   ,        ) ",
      " ,   ,        ) ",
      " ,   ,        ) ",
      " & * &        ! ",
      " ,   ,        ! ",
      " ,   ,        ) ",
      " ,   ,        ) ",
      ",,   ,,,,(,,,,) ",
      "              ) ",
      "              ! ",
      "              ! ",
      ",,   ,,,,(,,,,) ",
      " ,   ,        ) "
    ],
    [
      "                ",
      "                ",
      ")))!!))))!!)))) ",
      " ,   ,        ) ",
      " ,   ,        ) ",
      " ,   ,        ) ",
      " ,   ,        ! ",
      " , * ,        ! ",
      " ,   ,        ) ",
      " ,   ,        ) ",
      ",,   ,,,,,,,,,) ",
      "              ) ",
      "              ! ",
      "              ! ",
      ",,   ,,,,,,,,,) ",
      " ,   ,        ) "
    ],
    [
      "                ",
      "                ",
      "))))))))))))))) ",
      " ,   ,        ) ",
      " ,   ,        ) ",
      " ,   ,        ) ",
      " ,   ,        ) ",
      " ,   ,        ) ",
      " , * ,        ) ",
      " ,   ,        ) ",
      ",,,,,,,,,,,,,,) ",
      " ,   ,        ) ",
      " ,   ,        ) ",
      " ,   ,        ) ",
      ",,,,,,,,,,,,,,) ",
      " ,   ,        ) "
    ],
    [
      "                ",
      "                ",
      "))))))))))))))) ",
      " ,   ,        ) ",
      " ,   ,        ) ",
      " ,   ,        ) ",
      " ,   ,        ) ",
      " ,   ,        ) ",
      " ,   ,        ) ",
      " , * ,        ) ",
      ",,,,,,,,,,,,,,) ",
      " ,   ,        ) ",
      " ,   ,        ) ",
      " ,   ,        ) ",
      ",,,,,,,,,,,,,,) ",
      " ,   ,        ) "
    ],
    [
      "                ",
      "                ",
      "))))))))))))))) ",
      "              ) ",
      "              ) ",
      "              ) ",
      "              ) ",
      "              ) ",
      "              ) ",
      "              ) ",
      "   *          ) ",
      "              ) ",
      "              ) ",
      "              ) ",
      "              ) ",
      "              ) "
    ]
  ],
  "palette": {
    "palette": [
      {
        "char": "!",
        "block": "create:framed_glass"
      },
      {
        "char": "$",
        "block": "kubejs:ruined_brewing_stand"
      },
      {
        "char": "%",
        "block": "minecraft:dark_oak_door[facing=east,half=lower,hinge=left,open=false,powered=false]"
      },
      {
        "char": "&",
        "block": "minecraft:dark_oak_door[facing=east,half=upper,hinge=left,open=false,powered=false]"
      },
      {
        "char": "'",
        "block": "minecraft:dark_oak_door[facing=south,half=lower,hinge=left,open=false,powered=false]"
      },
      {
        "char": "(",
        "block": "minecraft:dark_oak_door[facing=south,half=upper,hinge=left,open=false,powered=false]"
      },
      {
        "char": ")",
        "block": "minecraft:light_gray_concrete"
      },
      {
        "char": "*",
        "block": "minecraft:oak_stairs[facing=south,half=bottom,shape=straight,waterlogged=false]"
      },
      {
        "char": "+",
        "block": "minecraft:spawner",
        "tag": {
          "id": "minecraft:mob_spawner",
          "Delay": 200,
          "MinSpawnDelay": 240,
          "MaxSpawnDelay": 720,
          "SpawnCount": 2,
          "MaxNearbyEntities": 7,
          "RequiredPlayerRange": 14,
          "SpawnRange": 4,
          "SpawnData": {
            "entity": {
              "id": "the_wasteland_reworked:ghoul"
            }
          },
          "SpawnPotentials": [
            {
              "weight": 1,
              "data": {
                "entity": {
                  "id": "the_wasteland_reworked:ghoul"
                }
              }
            }
          ]
        }
      },
      {
        "char": ",",
        "block": "minecraft:stripped_spruce_wood"
      }
    ]
  }
}
