{
  "xsize": 16,
  "zsize": 16,
  "slices": [
    [
      "   .      .     ",
      "                ",
      "  )             ",
      "                ",
      "                ",
      "                ",
      "                ",
      "                ",
      "                ",
      "///&/////////// ",
      " -   -        / ",
      " -   -        / ",
      " - * -        / ",
      "+$   $        / ",
      " -   -,  (    / ",
      " -   -        / "
    ],
    [
      "                ",
      "                ",
      "                ",
      "                ",
      "                ",
      "                ",
      "                ",
      "                ",
      "                ",
      "///'/////!!//// ",
      " -   -        / ",
      " -   -        / ",
      " -   -        / ",
      "+% * %        ! ",
      " -   -        ! ",
      " -   -        / "
    ],
    [
      "                ",
      "                ",
      "                ",
      "                ",
      "                ",
      "                ",
      "                ",
      "                ",
      "                ",
      "/// /////!!//// ",
      " -   -        / ",
      " -   -        / ",
      " -   -        / ",
      " -   -        ! ",
      " - * -        ! ",
      " -   -        / "
    ],
    [
      "                ",
      "                ",
      "                ",
      "                ",
      "                ",
      "                ",
      "                ",
      "                ",
      "                ",
      "/////////////// ",
      " -   -        / ",
      " -   -        / ",
      " -   -        / ",
      " -   -        / ",
      " -   -        / ",
      " - * -        / "
    ],
    [
      "                ",
      "                ",
      "                ",
      "                ",
      "                ",
      "                ",
      "                ",
      "                ",
      "                ",
      "/////////////// ",
      " -   -        / ",
      " -   -        / ",
      " -   -        / ",
      " -   -        / ",
      " -   -        / ",
      " -   -        / "
    ],
    [
      "                ",
      "                ",
      "                ",
      "                ",
      "                ",
      "                ",
      "                ",
      "                ",
      "                ",
      "/////////////// ",
      "              / ",
      "              / ",
      "              / ",
      "              / ",
      "              / ",
      "              / "
    ]
  ],
  "palette": {
    "palette": [
      {
        "char": "!",
        "block": "create:framed_glass"
      },
      {
        "char": "$",
        "block": "minecraft:dark_oak_door[facing=east,half=lower,hinge=left,open=false,powered=false]"
      },
      {
        "char": "%",
        "block": "minecraft:dark_oak_door[facing=east,half=upper,hinge=left,open=false,powered=false]"
      },
      {
        "char": "&",
        "block": "minecraft:dark_oak_door[facing=north,half=lower,hinge=left,open=false,powered=false]"
      },
      {
        "char": "'",
        "block": "minecraft:dark_oak_door[facing=north,half=upper,hinge=left,open=false,powered=false]"
      },
      {
        "char": "(",
        "block": "minecraft:grindstone[face=floor,facing=south]"
      },
      {
        "char": ")",
        "block": "minecraft:iron_trapdoor[facing=north,half=bottom,open=false,powered=false,waterlogged=false]"
      },
      {
        "char": "*",
        "block": "minecraft:oak_stairs[facing=south,half=bottom,shape=straight,waterlogged=false]"
      },
      {
        "char": "+",
        "block": "minecraft:scaffolding"
      },
      {
        "char": ",",
        "block": "minecraft:smithing_table"
      },
      {
        "char": "-",
        "block": "minecraft:stripped_spruce_wood"
      },
      {
        "char": ".",
        "block": "minecraft:yellow_concrete"
      },
      {
        "char": "/",
        "block": "tfmg:cinder_block"
      }
    ]
  }
}
