{
  "xsize": 16,
  "zsize": 16,
  "slices": [
    [
      "******$$$$$$$$$$",
      "******$$$$$$$$$$",
      "******$$$$$$$$$$",
      "******$$$$$$$$$$",
      "******          ",
      "******          ",
      "$$$$            ",
      "$$$$            ",
      "$$$$            ",
      "$$$$     *******",
      "$$$$     *******",
      "$$$$     *******",
      "$$$$     *******",
      "$$$$     *******",
      "$$$$     *******",
      "$$$$     *******"
    ],
    [
      "!               ",
      "                ",
      "                ",
      "   &&$$$$$$$$$$$",
      "   &&$          ",
      "   $$$          ",
      "   $            ",
      "   $            ",
      "   $            ",
      "   $     $$$$$$$",
      "   $     $      ",
      "   $     $      ",
      "   $     $  %%%%",
      "   $     $  %%%%",
      "   $     $  %%%%",
      "   $     $  %%%%"
    ],
    [
      "                ",
      "                ",
      "                ",
      "   &&$$$$$$$$$$$",
      "   &&$          ",
      "   $$$          ",
      "   $            ",
      "   $            ",
      "   $            ",
      "   $     $$$$$$$",
      "   $     $      ",
      "   $     $      ",
      "   $     $  %%%%",
      "   $     $  %%%%",
      "   $     $  %%%%",
      "   $     $  %%%%"
    ],
    [
      "                ",
      "                ",
      "                ",
      "   &&$$$$$$$$$$$",
      "   &&$          ",
      "   $$$          ",
      "   $            ",
      "   $            ",
      "   $            ",
      "   $     $$$$$$$",
      "   $     $      ",
      "   $     $      ",
      "   $     $  %%%%",
      "   $     $  %%%%",
      "   $     $  %%%%",
      "   $     $  %%%%"
    ],
    [
      "                ",
      "                ",
      "                ",
      "     $$$$$$$$$$$",
      "     $          ",
      "   $$$          ",
      "   $            ",
      "   $            ",
      "   $            ",
      "   $     $$$$$$$",
      "   $     $      ",
      "   $     $      ",
      "   $     $      ",
      "   $     $      ",
      "   $     $      ",
      "   $     $      "
    ],
    [
      "$$$$$$$$$$$$$$$$",
      "$$$$$$$$$$$$$$$$",
      "$$$$$$$$$$$$$$$$",
      "$$$$$$$$$$$$$$$$",
      "$$$$$$((()))))))",
      "$$$$$$((()))))))",
      "$$$$((((((((((((",
      "$$$$((('((((((((",
      "$$$$((((((((((((",
      "$$$$))(((*******",
      "$$$$))(((*******",
      "$$$$))(((*******",
      "$$$$))(((*******",
      "$$$$))(((*******",
      "$$$$))(((*******",
      "$$$$))+((*******"
    ]
  ],
  "palette": {
    "palette": [
      {
        "char": "!",
        "block": "create:controls"
      },
      {
        "char": "$",
        "block": "immersiveengineering:concrete_reinforced"
      },
      {
        "char": "%",
        "block": "immersiveengineering:crate"
      },
      {
        "char": "&",
        "block": "immersiveengineering:sheetmetal_steel"
      },
      {
        "char": "'",
        "block": "minecraft:polished_blackstone_bricks"
      },
      {
        "char": "(",
        "block": "minecraft:smooth_stone"
      },
      {
        "char": ")",
        "block": "tfmg:asphalt"
      },
      {
        "char": "*",
        "block": "tfmg:factory_floor"
      },
      {
        "char": "+",
        "block": "tfmg:steel_block"
      }
    ]
  }
}
