{
  "xsize": 16,
  "zsize": 16,
  "slices": [
    [
      "                ",
      "                ",
      "+        )))))))",
      "         )      ",
      "         )      ",
      "         )     ,",
      "         ) $$$$$",
      "         )     ,",
      "         )     ,",
      "+        )     ,",
      "         )***%*,",
      "         )     ,",
      "         ' $$$$,",
      "         )     ,",
      "         )***%*,",
      "         )     ,"
    ],
    [
      "                ",
      "                ",
      "         ))))!!)",
      "         )      ",
      "         )      ",
      "         )      ",
      "         ! $$$$$",
      "         !      ",
      "         )      ",
      "         )      ",
      "         )***&**",
      "         )      ",
      "         ( $$$$$",
      "         )      ",
      "         )***&**",
      "         )      "
    ],
    [
      "                ",
      "                ",
      "         ))))!!)",
      "         )      ",
      "         )      ",
      "         )      ",
      "         ! $$$$$",
      "         !      ",
      "         )      ",
      "         )      ",
      "         )******",
      "         )      ",
      "           $$$$$",
      "         )      ",
      "         )******",
      "         )      "
    ],
    [
      "                ",
      "                ",
      "         )))))))",
      "         )      ",
      "         )      ",
      "         )      ",
      "         )      ",
      "         )      ",
      "         )      ",
      "         )      ",
      "         )******",
      "         )      ",
      "         )      ",
      "         )      ",
      "         )******",
      "         )      "
    ],
    [
      "                ",
      "                ",
      "         )))))))",
      "         )      ",
      "         )      ",
      "         )      ",
      "         )      ",
      "         )      ",
      "         )      ",
      "         )      ",
      "         )******",
      "         )      ",
      "         )      ",
      "         )      ",
      "         )******",
      "         )      "
    ],
    [
      "                ",
      "                ",
      "         )))))))",
      "         )      ",
      "         )      ",
      "         )      ",
      "         )      ",
      "         )      ",
      "         )      ",
      "         )      ",
      "         )      ",
      "         )      ",
      "         )      ",
      "         )      ",
      "         )      ",
      "         )      "
    ]
  ],
  "palette": {
    "palette": [
      {
        "char": "!",
        "block": "create:framed_glass"
      },
      {
        "char": "$",
        "block": "minecraft:bookshelf"
      },
      {
        "char": "%",
        "block": "minecraft:dark_oak_door[facing=south,half=lower,hinge=left,open=false,powered=false]"
      },
      {
        "char": "&",
        "block": "minecraft:dark_oak_door[facing=south,half=upper,hinge=left,open=false,powered=false]"
      },
      {
        "char": "'",
        "block": "minecraft:dark_oak_door[facing=west,half=lower,hinge=left,open=false,powered=false]"
      },
      {
        "char": "(",
        "block": "minecraft:dark_oak_door[facing=west,half=upper,hinge=left,open=false,powered=false]"
      },
      {
        "char": ")",
        "block": "minecraft:light_gray_concrete"
      },
      {
        "char": "*",
        "block": "minecraft:stripped_spruce_wood"
      },
      {
        "char": "+",
        "block": "minecraft:yellow_concrete"
      },
      {
        "char": ",",
        "block": "zvhouses:stone_brick_countertop"
      }
    ]
  }
}
