{
  "xsize": 16,
  "zsize": 16,
  "slices": [
    [
      "((((((((((((((( ",
      "((((((((((((((( ",
      "((((((((((((((( ",
      "((((((((((((((( ",
      "((((((((((((((( ",
      "((((((((((((((( ",
      "((((((((((((((( ",
      "((((((((((((((( ",
      "((((((((((((((( ",
      "((((((((((((((( ",
      "((((((((((((((( ",
      "((((((((((((((( ",
      "((((((((((((((( ",
      "((((((((((((((( ",
      "((((((((((((((( ",
      "                "
    ],
    [
      "              ! ",
      "              ! ",
      "              ! ",
      "              ! ",
      "              ! ",
      "              ! ",
      "              ! ",
      "       $$$$$  ! ",
      "       $%$$$  ! ",
      "       $$$$$  ! ",
      "       $$$$$  ! ",
      "       $$$$$  ! ",
      "              ! ",
      "              ! ",
      "!!!!!!!!!!!!!!! ",
      "                "
    ],
    [
      "              ! ",
      "              ! ",
      "              ! ",
      "              ! ",
      "              ! ",
      "              ! ",
      "              ! ",
      "       $$$$$  ! ",
      "       $$$$$  ! ",
      "       $$$$$  ! ",
      "       $$$$$  ! ",
      "       $$$$$  ! ",
      "              ! ",
      "              ! ",
      "!!!!!!!!!!!!!!! ",
      "                "
    ],
    [
      "              ! ",
      "              ! ",
      "              ! ",
      "              ! ",
      "              ! ",
      "              ! ",
      "              ! ",
      "       $$$$$  ! ",
      "       $$$$$  ! ",
      "       $$$$$  ! ",
      "       $$$$$  ! ",
      "       $$$$$  ! ",
      "              ! ",
      "              ! ",
      "!!!!!!!!!!!!!!! ",
      "                "
    ],
    [
      "              ! ",
      "              ! ",
      "              ! ",
      "              ! ",
      "              ! ",
      "              ! ",
      "              ! ",
      "              ! ",
      "              ! ",
      "              ! ",
      "              ! ",
      "              ! ",
      "              ! ",
      "              ! ",
      "!!!!!!!!!!!!!!! ",
      "                "
    ],
    [
      "(((&((((((((((('",
      "((((((((((((((('",
      "((((((((((((((('",
      "((((((((((((((('",
      "((((((((((((((('",
      "((((((((((((((('",
      "((((((((((((((('",
      "((((((((((((((('",
      "((((((((((((((('",
      "((((((((((((((('",
      "((((((((((((((('",
      "((((((((((((((('",
      "((((((((((((((('",
      "((((((((((((((('",
      "((((((((((((((('",
      "''''''''''''''''"
    ]
  ],
  "palette": {
    "palette": [
      {
        "char": "!",
        "block": "immersiveengineering:concrete_reinforced"
      },
      {
        "char": "$",
        "block": "immersiveengineering:sheetmetal_steel"
      },
      {
        "char": "%",
        "block": "minecraft:chest[facing=west,type=single,waterlogged=false]",
        "tag": {
          "id": "minecraft:chest",
          "LootTable": "infinite_domain:chests/wasteland_industrial"
        }
      },
      {
        "char": "&",
        "block": "minecraft:polished_andesite_stairs[facing=south,half=bottom,shape=straight,waterlogged=false]"
      },
      {
        "char": "'",
        "block": "minecraft:stone_bricks"
      },
      {
        "char": "(",
        "block": "tfmg:factory_floor"
      }
    ]
  }
}
