{
  "xsize": 16,
  "zsize": 16,
  "slices": [
    [
      "$$%&%%&%        ",
      "$$&%%&%%        ",
      "$$%%&%%&        ",
      "$$%&%%&%        ",
      "  &%%&%%        ",
      "  %%&%%&%       ",
      "   &%%&%%&      ",
      "   %%&%%&%%     ",
      "    &%%&%%&%    ",
      "****&&&&%&%%&%%&",
      "****&&&&&%%&%%&%",
      "****&&&&%%&%%&%%",
      "****&&&&%&%%&%%&",
      "******** %%&%%&%",
      "********   %%&%%",
      "********     $$$"
    ],
    [
      " !!!!!!!!       ",
      " !!!!!!!!       ",
      " !!!!!!!!       ",
      "$!!!!!!!!       ",
      "  &%            ",
      "  %%&           ",
      "   &%           ",
      "   %%&          ",
      "    &%%      !!!",
      "$$$$&&&&     !!!",
      "    &&&&&    !!!",
      "    &&&&%%   !!!",
      "    &&&&%&%% !!!",
      "       $ %%&%!!!",
      "       $   %%!!!",
      "       $     !!!"
    ],
    [
      " !!!!!!!!       ",
      " !!!!!!!!       ",
      " !!!!!!!!       ",
      "$!!!!!!!!       ",
      "  &             ",
      "  %%            ",
      "   &            ",
      "   %%           ",
      "    &        !!!",
      "$$$$&&&&     !!!",
      "    &&&&     !!!",
      "    &&&&     !!!",
      "    &&&&%&   !!!",
      "       $ %%& !!!",
      "       $   %%!!!",
      "       $     !!!"
    ],
    [
      " !!!!!!!!       ",
      " !!!!!!!!       ",
      " !!!!!!!!       ",
      "$!!!!!!!!       ",
      "  &             ",
      "  %             ",
      "                ",
      "   %            ",
      "             !!!",
      "$$$$&&&&     !!!",
      "    &&&&     !!!",
      "    &&&&     !!!",
      "    &&&&     !!!",
      "       $ %   !!!",
      "       $   %%!!!",
      "       $     !!!"
    ],
    [
      " !!!!!!!!       ",
      " !!!!!!!!       ",
      " !!!!!!!!       ",
      "$!!!!!!!!       ",
      "                ",
      "                ",
      "                ",
      "                ",
      "             !!!",
      "$$$$&&&&     !!!",
      "    &&&&     !!!",
      "    &&&&     !!!",
      "    &&&&     !!!",
      "       $     !!!",
      "       $     !!!",
      "       $     !!!"
    ],
    [
      "$$              ",
      "$$              ",
      "$$              ",
      "$$              ",
      "))              ",
      "))              ",
      "'''             ",
      "'''             ",
      "'               ",
      "(   &&&&        ",
      "((  &&&&        ",
      "( ( &&&&        ",
      "(  (&&&&        ",
      "(   (           ",
      "(    (   ''     ",
      "((    (  ''))$$$"
    ]
  ],
  "palette": {
    "palette": [
      {
        "char": "!",
        "block": "immersiveengineering:concrete_brick_cracked"
      },
      {
        "char": "$",
        "block": "immersiveengineering:concrete_reinforced"
      },
      {
        "char": "%",
        "block": "minecraft:coarse_dirt"
      },
      {
        "char": "&",
        "block": "minecraft:gravel"
      },
      {
        "char": "'",
        "block": "minecraft:smooth_stone"
      },
      {
        "char": "(",
        "block": "minecraft:spruce_planks"
      },
      {
        "char": ")",
        "block": "tfmg:asphalt"
      },
      {
        "char": "*",
        "block": "tfmg:factory_floor"
      }
    ]
  }
}
