{
  "xsize": 16,
  "zsize": 16,
  "slices": [
    [
      "       !        ",
      "&&&&&&&!        ",
      "       !        ",
      "       !        ",
      "       !        ",
      "&&&&&&&!        ",
      "       !        ",
      "       !        ",
      "       !        ",
      "       !        ",
      "       !        ",
      "       !        ",
      "       !        ",
      "       !        ",
      "!!!!!!!!        ",
      "                "
    ],
    [
      "       !        ",
      "       !        ",
      "       !        ",
      "       !        ",
      "       !        ",
      "       !        ",
      "       !        ",
      "       !        ",
      "       !        ",
      "       !        ",
      "       !        ",
      "       !        ",
      "       !        ",
      "       !        ",
      "!!!!!!!!        ",
      "                "
    ],
    [
      "%$$$$$$$        ",
      "%$$$$$$$        ",
      "%$$$$$$$        ",
      "%$$$$$$$        ",
      "%$$$$$$$        ",
      "%$$$$$$$        ",
      "%$$$$$$$        ",
      "$$$$$$$$        ",
      "$$$$$$$$        ",
      "$$$$$$$$        ",
      "$$$$$$$$        ",
      "$$$$$$$$        ",
      "$$$$$$$$        ",
      "$$$$$$$$        ",
      "$$$$$$$$        ",
      "                "
    ],
    [
      "!               ",
      "!               ",
      "!               ",
      "!               ",
      "!               ",
      "!               ",
      "!               ",
      "''''            ",
      "''''            ",
      "''''            ",
      "''''            ",
      "                ",
      "                ",
      "                ",
      "                ",
      "                "
    ],
    [
      "!               ",
      "!               ",
      "!               ",
      "!               ",
      "!               ",
      "!               ",
      "!               ",
      "''''            ",
      "''''            ",
      "''''            ",
      "''''            ",
      "                ",
      "                ",
      "                ",
      "                ",
      "                "
    ],
    [
      "$               ",
      "$               ",
      "$               ",
      "$               ",
      "$               ",
      "$               ",
      "$               ",
      "                ",
      "                ",
      "                ",
      "                ",
      "                ",
      "                ",
      "                ",
      "                ",
      "                "
    ]
  ],
  "palette": {
    "palette": [
      {
        "char": "!",
        "block": "minecraft:mud_bricks"
      },
      {
        "char": "$",
        "block": "minecraft:smooth_stone"
      },
      {
        "char": "%",
        "block": "minecraft:spruce_planks"
      },
      {
        "char": "&",
        "block": "minecraft:stripped_spruce_wood"
      },
      {
        "char": "'",
        "block": "minecraft:weathered_copper"
      }
    ]
  }
}
