{
  "xsize": 16,
  "zsize": 16,
  "slices": [
    [
      "                ",
      "                ",
      "  ))))))))))))))",
      "  ))))))))))))))",
      "  ))))))))))))))",
      "  ))))))))))))))",
      "  ))))))))))))))",
      "  ))))))))))))))",
      "  ))))))))))))))",
      "  ))))))))))))))",
      "  ))))))))))))))",
      "  ))))))))))))))",
      "  ))))))))))))))",
      "  ))))))))))))))",
      "  ))))))))))))))",
      "  ))))))))))))))"
    ],
    [
      "                ",
      "                ",
      "  !!!!!!!!!!!!!!",
      "  !             ",
      "  !             ",
      "  !  $$$$   '   ",
      "  !  $$$$       ",
      "  !  $$%$       ",
      "  !  $$$$       ",
      "  !             ",
      "  !             ",
      "  !             ",
      "  !             ",
      "  !             ",
      "  !             ",
      "  !             "
    ],
    [
      "                ",
      "                ",
      "  !!!!!!!!!!!!!!",
      "  !             ",
      "  !             ",
      "  !  $$$$       ",
      "  !  $$$$   '   ",
      "  !  $$$$       ",
      "  !  $$$$       ",
      "  !             ",
      "  !             ",
      "  !             ",
      "  !             ",
      "  !             ",
      "  !             ",
      "  !             "
    ],
    [
      "                ",
      "                ",
      "  !!!!!!!!!!!!!!",
      "  !             ",
      "  !             ",
      "  !  $$$$       ",
      "  !  $$$$       ",
      "  !  $$$$   '   ",
      "  !  $$$$       ",
      "  !             ",
      "  !             ",
      "  !             ",
      "  !             ",
      "  !             ",
      "  !             ",
      "  !             "
    ],
    [
      "                ",
      "                ",
      "  !!!!!!!!!!!!!!",
      "  !             ",
      "  !             ",
      "  !             ",
      "  !             ",
      "  !             ",
      "  !         '   ",
      "  !             ",
      "  !             ",
      "  !             ",
      "  !             ",
      "  !             ",
      "  !             ",
      "  !             "
    ],
    [
      "((((((((((((((((",
      "((((((((((((((((",
      "((&&&&&&&&&&&&&&",
      "((&&&&&&&&&&&&&&",
      "((&&&&&&&&&&&&&&",
      "((&&&&&&&&&&&&&&",
      "((&&&&&&&&&&&&&&",
      "((&&&&&&&&&& &&&",
      "((&&&&&&&&&& &&&",
      "((&&&&&&&&&&'&&&",
      "((&&&&&&&&&&&&&&",
      "((&&&&&&&&&&&&&&",
      "((&&&&&&&&&&&&&&",
      "((&&&&&&&&&&&&&&",
      "((&&&&&&&&&&&&&&",
      "((&&&&&&&&&&&&&&"
    ]
  ],
  "palette": {
    "palette": [
      {
        "char": "!",
        "block": "immersiveengineering:concrete_reinforced"
      },
      {
        "char": "$",
        "block": "immersiveengineering:crate"
      },
      {
        "char": "%",
        "block": "minecraft:chest[facing=east,type=single,waterlogged=false]",
        "tag": {
          "id": "minecraft:chest",
          "LootTable": "infinite_domain:chests/wasteland_office"
        }
      },
      {
        "char": "&",
        "block": "minecraft:oak_planks"
      },
      {
        "char": "'",
        "block": "minecraft:polished_andesite_stairs[facing=south,half=bottom,shape=straight,waterlogged=false]"
      },
      {
        "char": "(",
        "block": "minecraft:stone_bricks"
      },
      {
        "char": ")",
        "block": "tfmg:factory_floor"
      }
    ]
  }
}
