{
  "xsize": 16,
  "zsize": 16,
  "slices": [
    [
      "                ",
      "                ",
      "  $$$$$$$$$$$$$$",
      "  $       -   - ",
      "  $       -   - ",
      "  $       - ) -.",
      "  $       %   % ",
      "  $   ++  -   -.",
      "  $   ,   -   -.",
      "  $       -   -.",
      "  $---'----   -.",
      "  $            .",
      "  $            .",
      "  $            .",
      "  $---'----   -.",
      "  $     * -   -."
    ],
    [
      "                ",
      "                ",
      "  $$$$!!$$$$!!$$",
      "  $       -   - ",
      "  $       -   - ",
      "  $       -   - ",
      "  !       & ) & ",
      "  !       -   - ",
      "  $       -   - ",
      "  $       -   - ",
      "  $---(----   --",
      "  $             ",
      "  !             ",
      "  !             ",
      "  $---(----   --",
      "  $       -   - "
    ],
    [
      "                ",
      "                ",
      "  $$$$!!$$$$!!$$",
      "  $       -   - ",
      "  $       -   - ",
      "  $       -   - ",
      "  !       -   - ",
      "  !       - ) - ",
      "  $       -   - ",
      "  $       -   - ",
      "  $--------   --",
      "  $             ",
      "  !             ",
      "  !             ",
      "  $--------   --",
      "  $       -   - "
    ],
    [
      "                ",
      "                ",
      "  $$$$$$$$$$$$$$",
      "  $       -   - ",
      "  $       -   - ",
      "  $       -   - ",
      "  $       -   - ",
      "  $       -   - ",
      "  $       - ) - ",
      "  $       -   - ",
      "  $-------------",
      "  $       -   - ",
      "  $       -   - ",
      "  $       -   - ",
      "  $-------------",
      "  $       -   - "
    ],
    [
      "                ",
      "                ",
      "  $$$$$$$$$$$$$$",
      "  $       -   - ",
      "  $       -   - ",
      "  $       -   - ",
      "  $       -   - ",
      "  $       -   - ",
      "  $       -   - ",
      "  $       - ) - ",
      "  $-------------",
      "  $       -   - ",
      "  $       -   - ",
      "  $       -   - ",
      "  $-------------",
      "  $       -   - "
    ],
    [
      "                ",
      "                ",
      "  $$$$$$$$$$$$$$",
      "  $             ",
      "  $             ",
      "  $             ",
      "  $             ",
      "  $             ",
      "  $             ",
      "  $             ",
      "  $         )   ",
      "  $             ",
      "  $             ",
      "  $             ",
      "  $             ",
      "  $             "
    ]
  ],
  "palette": {
    "palette": [
      {
        "char": "!",
        "block": "create:framed_glass"
      },
      {
        "char": "$",
        "block": "minecraft:bricks"
      },
      {
        "char": "%",
        "block": "minecraft:dark_oak_door[facing=east,half=lower,hinge=left,open=false,powered=false]"
      },
      {
        "char": "&",
        "block": "minecraft:dark_oak_door[facing=east,half=upper,hinge=left,open=false,powered=false]"
      },
      {
        "char": "'",
        "block": "minecraft:dark_oak_door[facing=south,half=lower,hinge=left,open=false,powered=false]"
      },
      {
        "char": "(",
        "block": "minecraft:dark_oak_door[facing=south,half=upper,hinge=left,open=false,powered=false]"
      },
      {
        "char": ")",
        "block": "minecraft:oak_stairs[facing=south,half=bottom,shape=straight,waterlogged=false]"
      },
      {
        "char": "*",
        "block": "minecraft:spawner",
        "tag": {
          "id": "minecraft:mob_spawner",
          "Delay": 200,
          "MinSpawnDelay": 240,
          "MaxSpawnDelay": 720,
          "SpawnCount": 2,
          "MaxNearbyEntities": 7,
          "RequiredPlayerRange": 14,
          "SpawnRange": 4,
          "SpawnData": {
            "entity": {
              "id": "minecraft:zombie"
            }
          },
          "SpawnPotentials": [
            {
              "weight": 1,
              "data": {
                "entity": {
                  "id": "minecraft:zombie"
                }
              }
            }
          ]
        }
      },
      {
        "char": "+",
        "block": "minecraft:spruce_slab[type=bottom,waterlogged=false]"
      },
      {
        "char": ",",
        "block": "minecraft:spruce_stairs[facing=north,half=bottom,shape=straight,waterlogged=false]"
      },
      {
        "char": "-",
        "block": "minecraft:stripped_spruce_wood"
      },
      {
        "char": ".",
        "block": "zvhouses:stone_brick_countertop"
      }
    ]
  }
}
