{
  "xsize": 16,
  "zsize": 16,
  "slices": [
    [
      "%%%%%%%%        ",
      "%%%%%%%%        ",
      "%%%%%%%%        ",
      "%%%%%!!!!!!!    ",
      "%%%%%!!!!!!!    ",
      "%%%%%!!!!!!!    ",
      "%%%%%!!!$!!!    ",
      "     !!!!!!!    ",
      "     !!!!!!!    ",
      "     !!!!!!!    ",
      "                ",
      "                ",
      "                ",
      "                ",
      "                ",
      "                "
    ]
  ],
  "palette": {
    "palette": [
      {
        "char": "!",
        "block": "immersiveengineering:sheetmetal_steel"
      },
      {
        "char": "$",
        "block": "minecraft:lightning_rod[facing=up,waterlogged=false]"
      },
      {
        "char": "%",
        "block": "minecraft:smooth_stone"
      }
    ]
  }
}
