{
  "xsize": 16,
  "zsize": 16,
  "slices": [
    [
      "********     !!!",
      "********     !!!",
      "********     !!!",
      "********     !!!",
      "********     !!!",
      "********     !!!",
      "********     !!!",
      "********     !!!",
      "********     !!!",
      "********     !!!",
      "********     !!!",
      "********     !!!",
      "********     !!!",
      "********     !!!",
      "********     !!!",
      "             !!!"
    ],
    [
      "       !     !  ",
      "       !     !  ",
      "       !     !  ",
      "       !     !  ",
      "       !     !  ",
      "       !     !  ",
      "       !     !  ",
      "$$$$$  !     !  ",
      "$$$$$  !     !  ",
      "$$$$$  !     !  ",
      "$$$$$  !     !  ",
      "$$$$$  !     !  ",
      "       !     !  ",
      "       !     !  ",
      "!!!!!!!!     !  ",
      "             !  "
    ],
    [
      "       !     !  ",
      "       !     !  ",
      "       !     !  ",
      "       !     !  ",
      "       !     !  ",
      "       !     !  ",
      "       !     !  ",
      "$$$$$  !     !  ",
      "$$$$$  !     !  ",
      "$$$$$  !     !  ",
      "$$$$$  !     !  ",
      "$$$$$  !     !  ",
      "       !     !  ",
      "       !     !  ",
      "!!!!!!!!     !  ",
      "             !  "
    ],
    [
      "       !     !  ",
      "       !     !  ",
      "       !     !  ",
      "       !     !  ",
      "       !     !  ",
      "       !     !  ",
      "       !     !  ",
      "$$$$$  !     !  ",
      "$$$$$  !     !  ",
      "$$$$$  !     !  ",
      "$$$$$  !     !  ",
      "$$$$$  !     !  ",
      "       !     !  ",
      "       !     !  ",
      "!!!!!!!!     !  ",
      "             !  "
    ],
    [
      "       !     !  ",
      "       !     !  ",
      "       !     !  ",
      "       !     !  ",
      "       !     !  ",
      "       !     !  ",
      "       !     !  ",
      "       !     !  ",
      "       !     !  ",
      "       !     !  ",
      "       !     !  ",
      "       !     !  ",
      "       !     !  ",
      "       !     !  ",
      "!!!!!!!!     !  ",
      "             !  "
    ],
    [
      "&&&&&&&&%%%))!!!",
      "&&&&&&&&%%%))!!!",
      "&&&&&&&&%%%))!!!",
      "&&&&&&&&%%%))!!!",
      "&&&&&&&&%%%))!!!",
      "&&&&&&&&%%%))!!!",
      "&&&&&&&&%%%))!!!",
      "&&&&&&&&%%%))!!!",
      "&&&&&&&&%%%))!!!",
      "&&&&&&&&%%%))!!!",
      "&&&&&&&&%%())!!!",
      "&&&&&&&&%%%))!!!",
      "&&&&&&&&%%%))!!!",
      "&&&&&&&&%%%))!!!",
      "&&&&&&&&%%%))!!!",
      "''''''''%%%))!!!"
    ]
  ],
  "palette": {
    "palette": [
      {
        "char": "!",
        "block": "immersiveengineering:concrete_reinforced"
      },
      {
        "char": "$",
        "block": "immersiveengineering:sheetmetal_steel"
      },
      {
        "char": "%",
        "block": "minecraft:smooth_stone"
      },
      {
        "char": "&",
        "block": "minecraft:spruce_planks"
      },
      {
        "char": "'",
        "block": "minecraft:stone_bricks"
      },
      {
        "char": "(",
        "block": "minecraft:stripped_dark_oak_log[axis=y]"
      },
      {
        "char": ")",
        "block": "tfmg:asphalt"
      },
      {
        "char": "*",
        "block": "tfmg:factory_floor"
      }
    ]
  }
}
