{
  "xsize": 16,
  "zsize": 16,
  "slices": [
    [
      "         %      ",
      "         %$$$$$$",
      "         %      ",
      "         %      ",
      "         %      ",
      "         %$$$$$$",
      "         %      ",
      "         %      ",
      "         %      ",
      "         %      ",
      "         %      ",
      "         %      ",
      "         %      ",
      "         %      ",
      "         %%%%%%%",
      "                "
    ],
    [
      "         %      ",
      "         %$$$$$$",
      "         %      ",
      "         %      ",
      "         %      ",
      "         %$$$$$$",
      "         %      ",
      "         %      ",
      "         %      ",
      "         %      ",
      "         %      ",
      "         %      ",
      "         %      ",
      "         %      ",
      "         %%%%%%%",
      "                "
    ],
    [
      "         %      ",
      "         %      ",
      "         %      ",
      "         %      ",
      "         %      ",
      "         %      ",
      "         %      ",
      "         %      ",
      "         %      ",
      "         %      ",
      "         %      ",
      "         %      ",
      "         %      ",
      "         %      ",
      "         %%%%%%%",
      "                "
    ],
    [
      "         !!!!!!&",
      "         !!!!!!&",
      "         !!!!!!&",
      "         !!!!!!&",
      "         !!!!!!&",
      "         !!!!!!&",
      "         !!!!!!&",
      "         !!!!!!!",
      "         !!!!!!!",
      "         !!!!!!!",
      "         !!!!!!!",
      "         !!!!!!!",
      "         !!!!!!!",
      "         !!!!!!!",
      "         !!!!!!!",
      "                "
    ],
    [
      "               %",
      "               %",
      "               %",
      "               %",
      "               %",
      "               %",
      "               %",
      "                ",
      "                ",
      "                ",
      "                ",
      "                ",
      "                ",
      "                ",
      "                ",
      "                "
    ],
    [
      "               %",
      "               %",
      "               %",
      "               %",
      "               %",
      "               %",
      "               %",
      "                ",
      "                ",
      "                ",
      "                ",
      "                ",
      "                ",
      "                ",
      "                ",
      "                "
    ]
  ],
  "palette": {
    "palette": [
      {
        "char": "!",
        "block": "minecraft:smooth_stone"
      },
      {
        "char": "$",
        "block": "minecraft:stripped_spruce_wood"
      },
      {
        "char": "%",
        "block": "tfmg:cinder_block"
      },
      {
        "char": "&",
        "block": "tfmg:factory_floor"
      }
    ]
  }
}
