{
  "xsize": 16,
  "zsize": 16,
  "slices": [
    [
      "  ''''''''''''''",
      "  ''''''''''''''",
      "  ''''''''''''''",
      "  ''''''''''''''",
      "  ''''''''''''''",
      "  ''''''''''''''",
      "  ''''''''''''''",
      "  ''''''''''''''",
      "  ''''''''''''''",
      "  ''''''''''''''",
      "  ''''''''''''''",
      "  ''''''''''''''",
      "  ''''''''''''''",
      "  ''''''''''''''",
      "  ''''''''''''''",
      "                "
    ],
    [
      "  !             ",
      "  !             ",
      "  !             ",
      "  !             ",
      "  !             ",
      "  !             ",
      "  !             ",
      "  !             ",
      "  !             ",
      "  !             ",
      "  !             ",
      "  !             ",
      "  !             ",
      "  !             ",
      "  !!!!!!!!!!!!!!",
      "                "
    ],
    [
      "  !             ",
      "  !             ",
      "  !             ",
      "  !             ",
      "  !             ",
      "  !             ",
      "  !             ",
      "  !             ",
      "  !             ",
      "  !             ",
      "  !             ",
      "  !             ",
      "  !             ",
      "  !             ",
      "  !!!!!!!!!!!!!!",
      "                "
    ],
    [
      "  !             ",
      "  !             ",
      "  !             ",
      "  !             ",
      "  !             ",
      "  !             ",
      "  !             ",
      "  !             ",
      "  !             ",
      "  !             ",
      "  !             ",
      "  !             ",
      "  !             ",
      "  !             ",
      "  !!!!!!!!!!!!!!",
      "                "
    ],
    [
      "  !             ",
      "  !             ",
      "  !             ",
      "  !             ",
      "  !             ",
      "  !             ",
      "  !             ",
      "  !             ",
      "  !             ",
      "  !             ",
      "  !             ",
      "  !             ",
      "  !             ",
      "  !             ",
      "  !!!!!!!!!!!!!!",
      "                "
    ],
    [
      "&&%%%%%%%%%%$%%%",
      "&&%%%%%%%%%%%%%%",
      "&&%%%%%%%%%%%%%%",
      "&&%%%%%%%%%%%%%%",
      "&&%%%%%%%%%%%%%%",
      "&&%%%%%%%%%%%%%%",
      "&&%%%%%%%%%%%%%%",
      "&&%%%%%%%%%%%%%%",
      "&&%%%%%%%%%%%%%%",
      "&&%%%%%%%%%%%%%%",
      "&&%%%%%%%%%%%%%%",
      "&&%%%%%%%%%%%%%%",
      "&&%%%%%%%%%%%%%%",
      "&&%%%%%%%%%%%%%%",
      "&&%%%%%%%%%%%%%%",
      "&&&&&&&&&&&&&&&&"
    ]
  ],
  "palette": {
    "palette": [
      {
        "char": "!",
        "block": "immersiveengineering:concrete_reinforced"
      },
      {
        "char": "$",
        "block": "minecraft:polished_andesite_stairs[facing=south,half=bottom,shape=straight,waterlogged=false]"
      },
      {
        "char": "%",
        "block": "minecraft:spruce_planks"
      },
      {
        "char": "&",
        "block": "minecraft:stone_bricks"
      },
      {
        "char": "'",
        "block": "tfmg:factory_floor"
      }
    ]
  }
}
