{
  "xsize": 16,
  "zsize": 16,
  "slices": [
    [
      "         - )))))",
      "         -***$**",
      "  (      -      ",
      ",        &      ",
      "         -      ",
      "         -***$**",
      "         -      ",
      "         -      ",
      "         -      ",
      "      .  - )))))",
      ",        -      ",
      "         -      ",
      "         -      ",
      "         -      ",
      "         -------",
      "                "
    ],
    [
      "         - )))))",
      "         -***%**",
      "         -      ",
      "         '      ",
      "         -      ",
      "         -***%**",
      "         -      ",
      "         -      ",
      "         -      ",
      "      .  ! )))))",
      "         !      ",
      "         -      ",
      "         -      ",
      "         -      ",
      "         ----!!-",
      "                "
    ],
    [
      "         -      ",
      "         -******",
      "         -      ",
      "                ",
      "         -      ",
      "         -******",
      "         -      ",
      "         -      ",
      "         -      ",
      "      .  !      ",
      "         !      ",
      "         -      ",
      "         -      ",
      "         -      ",
      "         ----!!-",
      "                "
    ],
    [
      "         -      ",
      "         -******",
      "         -      ",
      "         -      ",
      "         -      ",
      "         -******",
      "         -      ",
      "         -      ",
      "         -      ",
      "      .  -      ",
      "         -      ",
      "         -      ",
      "         -      ",
      "         -      ",
      "         -------",
      "                "
    ],
    [
      "         -      ",
      "         -******",
      "         -      ",
      "         -      ",
      "         -      ",
      "         -******",
      "         -      ",
      "         -      ",
      "         -      ",
      "      .  -      ",
      "         -      ",
      "         -      ",
      "         -      ",
      "         -      ",
      "         -------",
      "                "
    ],
    [
      "      ++++      ",
      "      ++++      ",
      "      ++++      ",
      "      ++++      ",
      "      ++++      ",
      "      ++++      ",
      "      ++++      ",
      "      ++++      ",
      "      ++++      ",
      "      ++++      ",
      "         -      ",
      "         -      ",
      "         -      ",
      "         -      ",
      "         -------",
      "                "
    ]
  ],
  "palette": {
    "palette": [
      {
        "char": "!",
        "block": "create:framed_glass"
      },
      {
        "char": "$",
        "block": "minecraft:dark_oak_door[facing=south,half=lower,hinge=left,open=false,powered=false]"
      },
      {
        "char": "%",
        "block": "minecraft:dark_oak_door[facing=south,half=upper,hinge=left,open=false,powered=false]"
      },
      {
        "char": "&",
        "block": "minecraft:dark_oak_door[facing=west,half=lower,hinge=left,open=false,powered=false]"
      },
      {
        "char": "'",
        "block": "minecraft:dark_oak_door[facing=west,half=upper,hinge=left,open=false,powered=false]"
      },
      {
        "char": "(",
        "block": "minecraft:iron_trapdoor[facing=north,half=bottom,open=false,powered=false,waterlogged=false]"
      },
      {
        "char": ")",
        "block": "minecraft:scaffolding"
      },
      {
        "char": "*",
        "block": "minecraft:stripped_spruce_wood"
      },
      {
        "char": "+",
        "block": "minecraft:weathered_cut_copper"
      },
      {
        "char": ",",
        "block": "minecraft:yellow_concrete"
      },
      {
        "char": "-",
        "block": "tfmg:cinder_block"
      },
      {
        "char": ".",
        "block": "tfmg:steel_block"
      }
    ]
  }
}
