{
  "xsize": 16,
  "zsize": 16,
  "slices": [
    [
      "++++++ %  *     ",
      "++++++ %        ",
      "++++++ %        ",
      "++++++ %        ",
      "++++++ %        ",
      "++++++ %        ",
      "       %        ",
      "%%%%%%%%        ",
      "            - - ",
      "         *  - - ",
      "            - - ",
      "                ",
      "        ---     ",
      "                ",
      "        ---     ",
      "                "
    ],
    [
      "$$$$$$ %  *     ",
      "$    $ %        ",
      "(    $ !        ",
      "$  & $ !        ",
      "$    $ %        ",
      "$$$$$$ %        ",
      "       %        ",
      "%%!!%%%%        ",
      "                ",
      "         *      ",
      "                ",
      "                ",
      "                ",
      "                ",
      "                ",
      "                "
    ],
    [
      "$$$$$$ %  *     ",
      "$    $ %        ",
      ")    $ !        ",
      "$    $ !        ",
      "$    $ %        ",
      "$$$$$$ %        ",
      "       %        ",
      "%%!!%%%%        ",
      "                ",
      "         *      ",
      "                ",
      "                ",
      "                ",
      "                ",
      "                ",
      "                "
    ],
    [
      "$$$$$$ %  *     ",
      "$    $ %        ",
      "$    $ %        ",
      "$    $ %        ",
      "$    $ %        ",
      "$$$$$$ %        ",
      "       %        ",
      "%%%%%%%%        ",
      "                ",
      "         *      ",
      "                ",
      "                ",
      "                ",
      "                ",
      "                ",
      "                "
    ],
    [
      "$$$$$$ %  *     ",
      "$$$$$$ %        ",
      "$$$$$$ %        ",
      "$$$$$$ %        ",
      "$$$$$$ %        ",
      "$$$$$$ %        ",
      "       %        ",
      "%%%%%%%%        ",
      "                ",
      "         *      ",
      "         '      ",
      "                ",
      "                ",
      "                ",
      "                ",
      "                "
    ],
    [
      "     ,,,,,,     ",
      "       %        ",
      "       %        ",
      "       %        ",
      "       %        ",
      "       %        ",
      "       %        ",
      "%%%%%%%%        ",
      "                ",
      "         *      ",
      "         .      ",
      "                ",
      "                ",
      "                ",
      "                ",
      "                "
    ]
  ],
  "palette": {
    "palette": [
      {
        "char": "!",
        "block": "create:framed_glass"
      },
      {
        "char": "$",
        "block": "immersiveengineering:sheetmetal_steel"
      },
      {
        "char": "%",
        "block": "minecraft:bricks"
      },
      {
        "char": "&",
        "block": "minecraft:chest[facing=west,type=single,waterlogged=false]",
        "tag": {
          "id": "minecraft:chest",
          "LootTable": "infinite_domain:chests/wasteland_office"
        }
      },
      {
        "char": "'",
        "block": "minecraft:green_concrete"
      },
      {
        "char": "(",
        "block": "minecraft:iron_door[facing=west,half=lower,hinge=left,open=false,powered=false]"
      },
      {
        "char": ")",
        "block": "minecraft:iron_door[facing=west,half=upper,hinge=left,open=false,powered=false]"
      },
      {
        "char": "*",
        "block": "minecraft:polished_blackstone_bricks"
      },
      {
        "char": "+",
        "block": "minecraft:polished_deepslate"
      },
      {
        "char": ",",
        "block": "minecraft:weathered_cut_copper"
      },
      {
        "char": "-",
        "block": "minecraft:white_carpet"
      },
      {
        "char": ".",
        "block": "minecraft:yellow_concrete"
      }
    ]
  }
}
