{
  "xsize": 16,
  "zsize": 16,
  "slices": [
    [
      " -*///////// ///",
      " -*///////// ///",
      " -*/////////////",
      " -*/////////////",
      " -*/////////////",
      " -*/////////////",
      " -*/////////////",
      " -*/////////////",
      " -*/////////////",
      " -*/////////////",
      " -*/////////////",
      " -*/////////////",
      " -*/////////////",
      " -*/////////////",
      " -**************",
      "                "
    ],
    [
      "  *      ,0   0 ",
      "  *000(0000   00",
      "  *             ",
      "  *             ",
      "  *     .       ",
      "  *000(0000   00",
      "  *       0   0 ",
      "  *       0   0 ",
      "  *    $  0   0 ",
      "  *    %  &   & ",
      "  *      ,0   0 ",
      "  *       0   0 ",
      "  *       0   0 ",
      "  *       0   0 ",
      "  **************",
      "                "
    ],
    [
      "  *       0   0 ",
      "  *000)0000   00",
      "  *             ",
      "  !             ",
      "  !             ",
      "  *000)0000   00",
      "  *       0   0 ",
      "  *       0   0 ",
      "  *       0   0 ",
      "  !       '   ' ",
      "  !       0   0 ",
      "  *       0   0 ",
      "  *       0   0 ",
      "  *       0   0 ",
      "  ****!!****!!**",
      "                "
    ],
    [
      "  *       0   0 ",
      "  *00000000   00",
      "  *             ",
      "  !             ",
      "  !             ",
      "  *00000000   00",
      "  *       0   0 ",
      "  *       0   0 ",
      "  *       0   0 ",
      "  !       0   0 ",
      "  !       0   0 ",
      "  *       0   0 ",
      "  *       0   0 ",
      "  *       0   0 ",
      "  ****!!****!!**",
      "                "
    ],
    [
      "  *       0   0 ",
      "  *0000000000000",
      "  *       0   0 ",
      "  *       0   0 ",
      "  *       0   0 ",
      "  *0000000000000",
      "  *       0   0 ",
      "  *       0   0 ",
      "  *       0   0 ",
      "  *       0   0 ",
      "  *       0   0 ",
      "  *       0   0 ",
      "  *       0   0 ",
      "  *       0   0 ",
      "  **************",
      "                "
    ],
    [
      "  *       0 + 0 ",
      "  *0000000000000",
      "  *       0   0 ",
      "  *       0   0 ",
      "  *       0   0 ",
      "  *0000000000000",
      "  *       0   0 ",
      "  *       0   0 ",
      "  *       0   0 ",
      "  *       0   0 ",
      "  *       0   0 ",
      "  *       0   0 ",
      "  *       0   0 ",
      "  *       0   0 ",
      "  **************",
      "                "
    ]
  ],
  "palette": {
    "palette": [
      {
        "char": "!",
        "block": "create:framed_glass"
      },
      {
        "char": "$",
        "block": "minecraft:brown_bed[facing=south,occupied=false,part=foot]"
      },
      {
        "char": "%",
        "block": "minecraft:brown_bed[facing=south,occupied=false,part=head]"
      },
      {
        "char": "&",
        "block": "minecraft:dark_oak_door[facing=east,half=lower,hinge=left,open=false,powered=false]"
      },
      {
        "char": "'",
        "block": "minecraft:dark_oak_door[facing=east,half=upper,hinge=left,open=false,powered=false]"
      },
      {
        "char": "(",
        "block": "minecraft:dark_oak_door[facing=south,half=lower,hinge=left,open=false,powered=false]"
      },
      {
        "char": ")",
        "block": "minecraft:dark_oak_door[facing=south,half=upper,hinge=left,open=false,powered=false]"
      },
      {
        "char": "*",
        "block": "minecraft:mud_bricks"
      },
      {
        "char": "+",
        "block": "minecraft:oak_stairs[facing=south,half=bottom,shape=straight,waterlogged=false]"
      },
      {
        "char": ",",
        "block": "minecraft:smoker[facing=north,lit=false]"
      },
      {
        "char": "-",
        "block": "minecraft:smooth_stone_slab[type=top,waterlogged=false]"
      },
      {
        "char": ".",
        "block": "minecraft:spawner",
        "tag": {
          "id": "minecraft:mob_spawner",
          "Delay": 200,
          "MinSpawnDelay": 240,
          "MaxSpawnDelay": 720,
          "SpawnCount": 2,
          "MaxNearbyEntities": 7,
          "RequiredPlayerRange": 14,
          "SpawnRange": 4,
          "SpawnData": {
            "entity": {
              "id": "minecraft:zombie"
            }
          },
          "SpawnPotentials": [
            {
              "weight": 1,
              "data": {
                "entity": {
                  "id": "minecraft:zombie"
                }
              }
            }
          ]
        }
      },
      {
        "char": "/",
        "block": "minecraft:spruce_planks"
      },
      {
        "char": "0",
        "block": "minecraft:stripped_spruce_wood"
      }
    ]
  }
}
