{
  "xsize": 16,
  "zsize": 16,
  "slices": [
    [
      "----------------",
      "----------------",
      "----------------",
      "----------------",
      "----------------",
      "-------))(------",
      "-----))(--------",
      "---))(----------",
      "----------------",
      "----------------",
      "----------------",
      "--------------))",
      "------------))(-",
      "----------))(---",
      "--------))(-----",
      "------))(-------"
    ],
    [
      "                ",
      "                ",
      "                ",
      "                ",
      "                ",
      "                ",
      "                ",
      "   .............",
      "   .............",
      "   .............",
      "   .............",
      "  +++...........",
      "  +++...........",
      "  +++...........",
      "  +++...........",
      "  +++..........."
    ],
    [
      "                ",
      "                ",
      "                ",
      "                ",
      "                ",
      "                ",
      "   *      *     ",
      "   *************",
      "   &            ",
      "   &            ",
      "   &  ''' '''!!!",
      "      ''' '''!!!",
      "      ''' '''!!!",
      "             !!!",
      "      ''' '''!!!",
      "      ''' '''!!!"
    ],
    [
      "                ",
      "                ",
      "                ",
      "                ",
      "                ",
      "                ",
      "   *      *     ",
      "   *&&&&&&*&&&&&",
      "   &            ",
      "   &            ",
      "   &  ''' '''   ",
      "      ''' '''   ",
      "      ''' ''' $ ",
      "                ",
      "      ''' '''   ",
      "      ''' '''  %"
    ],
    [
      "                ",
      "                ",
      "                ",
      "                ",
      "                ",
      "                ",
      "   *      *     ",
      "   *&&&&&&*&&&&&",
      "   &            ",
      "   &            ",
      "   &  ''' '''   ",
      "      ''' '''   ",
      "      ''' '''   ",
      "                ",
      "      ''' '''   ",
      "      ''' '''   "
    ],
    [
      "                ",
      "                ",
      "                ",
      "                ",
      "                ",
      "                ",
      "   * ,,,, * ,,,,",
      "   *&&&&&&*&&&&&",
      "   &            ",
      "   &            ",
      "   &            ",
      "                ",
      "                ",
      "                ",
      "                ",
      "                "
    ]
  ],
  "palette": {
    "palette": [
      {
        "char": "!",
        "block": "create:andesite_casing"
      },
      {
        "char": "$",
        "block": "create:crushing_wheel"
      },
      {
        "char": "%",
        "block": "create:encased_fan"
      },
      {
        "char": "&",
        "block": "immersiveengineering:concrete_brick"
      },
      {
        "char": "'",
        "block": "jaffabricate:pallet_full"
      },
      {
        "char": "(",
        "block": "minecraft:coarse_dirt"
      },
      {
        "char": ")",
        "block": "minecraft:gravel"
      },
      {
        "char": "*",
        "block": "minecraft:mud_bricks"
      },
      {
        "char": "+",
        "block": "minecraft:smooth_stone"
      },
      {
        "char": ",",
        "block": "minecraft:spruce_slab[type=bottom,waterlogged=false]"
      },
      {
        "char": "-",
        "block": "tfmg:asphalt"
      },
      {
        "char": ".",
        "block": "tfmg:factory_floor"
      }
    ]
  }
}
