{
  "xsize": 16,
  "zsize": 16,
  "slices": [
    [
      ",,,,,,),,,,,,,,,",
      ",,,,,,,,,,,,,,,,",
      ",,,,,,,,,,,,,,,,",
      ",,,,,,,,,,,,,,,,",
      ",,,,,,,,,,,,,,,*",
      ",,,,,,,,,,,,,**)",
      ",,,,,,,,,,,**),,",
      ",,,,,,,,,**),,,,",
      ",,,,,,,**),,,,,,",
      ",,,,,,*),,,,,,,,",
      ",,,,,,,,,,,,,,,,",
      ",,,,,,,,,,,,,,,,",
      ",,,,,,,,,,,,,,,,",
      ",,,,,,,,,,,,,,,,",
      ",,,,,,,,,,,,,,**",
      ",,,,,,,,,,,,**),"
    ],
    [
      "   -------------",
      "   -------------",
      "   -------------",
      "   -------------",
      "   -------------",
      "   -------------",
      "   -------------",
      "   -------------",
      "   -------------",
      "  +++-----------",
      "  +++-----------",
      "  +++-----------",
      "  +++-----------",
      "  +++-----------",
      "   -------------",
      "   -------------"
    ],
    [
      "   '  ((( (((!!!",
      "   '            ",
      "   '        .   ",
      "   '         %  ",
      "   '         !  ",
      "   '            ",
      "   '            ",
      "   '         ///",
      "   '         ///",
      "      ((( (((///",
      "      ((( (((///",
      "      ((( (((///",
      "             ///",
      "      ((( (((   ",
      "   '  (((((((   ",
      "   '  (((((((   "
    ],
    [
      "   '  ((( (((   ",
      "   '            ",
      "   '        .   ",
      "   '            ",
      "   '            ",
      "   '            ",
      "   '            ",
      "   '            ",
      "   '          & ",
      "      ((( (((   ",
      "      ((( (((   ",
      "      ((( ((( $ ",
      "                ",
      "      ((( (((   ",
      "   '  ((( (((   ",
      "   '  ((( (((   "
    ],
    [
      "   '  ((( (((   ",
      "   '            ",
      "   '        .   ",
      "   '            ",
      "   '            ",
      "   '            ",
      "   '            ",
      "   '            ",
      "   '            ",
      "      ((( (((   ",
      "      ((( (((   ",
      "      ((( (((   ",
      "                ",
      "      ((( (((   ",
      "   '  ((( (((   ",
      "   '  ((( (((   "
    ],
    [
      "   '            ",
      "   '            ",
      "   '        .   ",
      "   '            ",
      "   '            ",
      "   '            ",
      "   '            ",
      "   '            ",
      "   '            ",
      "                ",
      "                ",
      "                ",
      "                ",
      "                ",
      "   '            ",
      "   '            "
    ]
  ],
  "palette": {
    "palette": [
      {
        "char": "!",
        "block": "create:andesite_casing"
      },
      {
        "char": "$",
        "block": "create:cardboard_block"
      },
      {
        "char": "%",
        "block": "create:depot"
      },
      {
        "char": "&",
        "block": "create:mechanical_press"
      },
      {
        "char": "'",
        "block": "immersiveengineering:concrete_brick"
      },
      {
        "char": "(",
        "block": "jaffabricate:pallet_full"
      },
      {
        "char": ")",
        "block": "minecraft:coarse_dirt"
      },
      {
        "char": "*",
        "block": "minecraft:gravel"
      },
      {
        "char": "+",
        "block": "minecraft:smooth_stone"
      },
      {
        "char": ",",
        "block": "tfmg:asphalt"
      },
      {
        "char": "-",
        "block": "tfmg:factory_floor"
      },
      {
        "char": ".",
        "block": "tfmg:steel_block"
      },
      {
        "char": "/",
        "block": "zvhouses:stone_brick_countertop"
      }
    ]
  }
}
