{
  "xsize": 16,
  "zsize": 16,
  "slices": [
    [
      "999999999999999 ",
      "999999999999999 ",
      "999999999999999 ",
      "999999999999999 ",
      "999999999999999 ",
      "999999999999999 ",
      "999999999999999 ",
      "999999999999999 ",
      "999999999999999 ",
      "999999999999999 ",
      "999999999999999 ",
      "9,,999999999999 ",
      ",&9999999999999 ",
      "999999999999999 ",
      "999999999999999 ",
      "999999999999999 "
    ],
    [
      "                ",
      "    8   8   8   ",
      "    6   8 6 8   ",
      "    8   8   8   ",
      "   ..........   ",
      "   ..........   ",
      "   ..........   ",
      ";;;..........   ",
      ";;;..........   ",
      ";;;..........   ",
      ";;;..........   ",
      ";;;..........   ",
      ";;;..........   ",
      ";;;..........   ",
      ";;;..........   ",
      ";;;..........   "
    ],
    [
      "                ",
      "                ",
      "    6     6     ",
      "   33    33     ",
      "   %%%()%%%%%   ",
      "   %        %   ",
      "   - 33     %   ",
      "---- 5      %   ",
      "   %        %   ",
      "   %        %   ",
      " ' %        %   ",
      "   %:::1::1:%   ",
      "/  % /  :   %   ",
      "   %33  :0  %   ",
      "   %5   :   %   ",
      "   %    :   %   "
    ],
    [
      "                ",
      "                ",
      "    6     6     ",
      "                ",
      "  7!!7*+7!!7%   ",
      "   %        %   ",
      "   -        %   ",
      "$$$-      < %   ",
      "   %        %   ",
      "   %        %   ",
      "   %        %   ",
      "   %:::2::2:%   ",
      "   %    :   %   ",
      "/  % /  :   %   ",
      "   %    :   %   ",
      "   %    :   %   "
    ],
    [
      "                ",
      "                ",
      "    6     6     ",
      "                ",
      "  7!!7  7!!7%   ",
      "   %        %   ",
      "   -        %   ",
      "$$$-        %   ",
      "   %        %   ",
      "   %        %   ",
      "   %        %   ",
      "   %::::::::%   ",
      "   %    :   %   ",
      "   %    :   %   ",
      "/  % /  :   %   ",
      "   %    :   %   "
    ],
    [
      "                ",
      "                ",
      "    6     6     ",
      "   44    44     ",
      "   %%%%%%%%%%   ",
      "   %        %   ",
      "   -        %   ",
      "$$$-        %   ",
      "   %        %   ",
      "   %        %   ",
      "   %        %   ",
      "   %::::::::%   ",
      "   %    :   %   ",
      "   %    :   %   ",
      "   %    :   %   ",
      "/  % /  :   %   "
    ]
  ],
  "palette": {
    "palette": [
      {
        "char": "!",
        "block": "create:framed_glass"
      },
      {
        "char": "$",
        "block": "immersiveengineering:concrete_brick"
      },
      {
        "char": "%",
        "block": "minecraft:bricks"
      },
      {
        "char": "&",
        "block": "minecraft:coarse_dirt"
      },
      {
        "char": "'",
        "block": "kubejs:ruined_crafting_table"
      },
      {
        "char": "(",
        "block": "minecraft:dark_oak_door[facing=north,half=lower,hinge=left,open=false,powered=false]"
      },
      {
        "char": ")",
        "block": "minecraft:dark_oak_door[facing=north,half=lower,hinge=right,open=false,powered=false]"
      },
      {
        "char": "*",
        "block": "minecraft:dark_oak_door[facing=north,half=upper,hinge=left,open=false,powered=false]"
      },
      {
        "char": "+",
        "block": "minecraft:dark_oak_door[facing=north,half=upper,hinge=right,open=false,powered=false]"
      },
      {
        "char": ",",
        "block": "minecraft:gravel"
      },
      {
        "char": "-",
        "block": "minecraft:mud_bricks"
      },
      {
        "char": ".",
        "block": "minecraft:polished_andesite"
      },
      {
        "char": "/",
        "block": "minecraft:polished_andesite_stairs[facing=south,half=bottom,shape=straight,waterlogged=false]"
      },
      {
        "char": "0",
        "block": "kubejs:ruined_smoker[facing=south]"
      },
      {
        "char": "1",
        "block": "minecraft:spruce_door[facing=south,half=lower,hinge=left,open=false,powered=false]"
      },
      {
        "char": "2",
        "block": "minecraft:spruce_door[facing=south,half=upper,hinge=left,open=false,powered=false]"
      },
      {
        "char": "3",
        "block": "minecraft:spruce_slab[type=bottom,waterlogged=false]"
      },
      {
        "char": "4",
        "block": "minecraft:spruce_slab[type=top,waterlogged=false]"
      },
      {
        "char": "5",
        "block": "minecraft:spruce_stairs[facing=north,half=bottom,shape=straight,waterlogged=false]"
      },
      {
        "char": "6",
        "block": "minecraft:stripped_dark_oak_log[axis=y]"
      },
      {
        "char": "7",
        "block": "minecraft:stripped_spruce_log[axis=y]"
      },
      {
        "char": "8",
        "block": "minecraft:white_concrete"
      },
      {
        "char": "9",
        "block": "tfmg:asphalt"
      },
      {
        "char": ":",
        "block": "tfmg:cinder_block"
      },
      {
        "char": ";",
        "block": "tfmg:factory_floor"
      },
      {
        "char": "<",
        "block": "the_wasteland_reworked:radio"
      }
    ]
  }
}
