{
  "xsize": 16,
  "zsize": 16,
  "slices": [
    [
      "-------**)------",
      "-----**)--------",
      "---**)----------",
      "-**)------------",
      "*)--------------",
      "----------------",
      "--------------**",
      "------------**)-",
      "----------**)---",
      "--------**)-----",
      "------**)-------",
      "----**)---------",
      "--**)-----------",
      "**)-------------",
      ")---------------",
      "---------------*"
    ],
    [
      "////////////////",
      "////////////////",
      "////////////////",
      "////////////////",
      "////////////////",
      "////////////////",
      "////////////////",
      "////////////////",
      "////////////////",
      "////////////////",
      "////////////////",
      "////////////////",
      "////////////////",
      "////////////////",
      "////////////////",
      "////////////////"
    ],
    [
      "!!!!  $$$$$$$.  ",
      "             .  ",
      "    0       0.  ",
      "&  &  &  &  &.  ",
      "!  !  !  !  !.  ",
      "             +  ",
      "             .  ",
      "  111  111  1.1 ",
      "  111  111  1.11",
      "  111  111  1.11",
      "  111  111  1.11",
      "  111  111  1.1 ",
      "  111  111  1.1 ",
      "             ...",
      " ((((((    (((((",
      " ((((((    ((((("
    ],
    [
      "             .  ",
      "             .  ",
      "    0       0.  ",
      "             .  ",
      "             .  ",
      "             ,  ",
      "             .  ",
      "             .  ",
      "   '    '    .  ",
      "             .  ",
      "             .  ",
      "   %    %    .  ",
      "             .  ",
      "             ...",
      "                ",
      "                "
    ],
    [
      "             .  ",
      "             .  ",
      "    0       0.  ",
      "             .  ",
      "             .  ",
      "             .  ",
      "             .  ",
      "             .  ",
      "             .  ",
      "             .  ",
      "             .  ",
      "             .  ",
      "             .  ",
      "             ...",
      "                ",
      "                "
    ],
    [
      "             .  ",
      "             .  ",
      "    0       0.  ",
      "             .  ",
      "             .  ",
      "             .  ",
      "             .  ",
      "             .  ",
      "             .  ",
      "             .  ",
      "             .  ",
      "             .  ",
      "             .  ",
      "             ...",
      "                ",
      "                "
    ]
  ],
  "palette": {
    "palette": [
      {
        "char": "!",
        "block": "create:andesite_casing"
      },
      {
        "char": "$",
        "block": "create:brass_casing"
      },
      {
        "char": "%",
        "block": "create:cardboard_block"
      },
      {
        "char": "&",
        "block": "create:depot"
      },
      {
        "char": "'",
        "block": "create:mechanical_press"
      },
      {
        "char": "(",
        "block": "jaffabricate:pallet_full"
      },
      {
        "char": ")",
        "block": "minecraft:coarse_dirt"
      },
      {
        "char": "*",
        "block": "minecraft:gravel"
      },
      {
        "char": "+",
        "block": "minecraft:spruce_door[facing=east,half=lower,hinge=left,open=false,powered=false]"
      },
      {
        "char": ",",
        "block": "minecraft:spruce_door[facing=east,half=upper,hinge=left,open=false,powered=false]"
      },
      {
        "char": "-",
        "block": "tfmg:asphalt"
      },
      {
        "char": ".",
        "block": "tfmg:cinder_block"
      },
      {
        "char": "/",
        "block": "tfmg:factory_floor"
      },
      {
        "char": "0",
        "block": "tfmg:steel_block"
      },
      {
        "char": "1",
        "block": "zvhouses:stone_brick_countertop"
      }
    ]
  }
}
