{
  "xsize": 16,
  "zsize": 16,
  "slices": [
    [
      "((((((((((%%$(((",
      "((((((((((((((((",
      "((((((((((((((((",
      "((((%(((((((((((",
      "((%%$(((((((((((",
      "                ",
      "                ",
      "                ",
      "                ",
      "                ",
      "                ",
      "                ",
      "                ",
      "                ",
      "                ",
      "                "
    ],
    [
      "   )))))))))))))",
      "   ))'''''''''''",
      "     '''''''''''",
      "     '''''''''''",
      "     *''''''''''",
      "                ",
      "                ",
      "                ",
      "                ",
      "                ",
      "                ",
      "                ",
      "                ",
      "                ",
      "                ",
      "                "
    ],
    [
      "   !  *       * ",
      "   &&&*       *&",
      "   &  *       * ",
      "                ",
      "     *          ",
      "                ",
      "                ",
      "                ",
      "                ",
      "                ",
      "                ",
      "                ",
      "                ",
      "                ",
      "                ",
      "                "
    ],
    [
      "   !  *       * ",
      "   &!!*       *!",
      "   &  *       * ",
      "                ",
      "     *          ",
      "                ",
      "                ",
      "                ",
      "                ",
      "                ",
      "                ",
      "                ",
      "                ",
      "                ",
      "                ",
      "                "
    ],
    [
      "   !  *       * ",
      "   &!!*       *!",
      "   &  *       * ",
      "                ",
      "     *          ",
      "                ",
      "                ",
      "                ",
      "                ",
      "                ",
      "                ",
      "                ",
      "                ",
      "                ",
      "                ",
      "                "
    ],
    [
      "   !  *       * ",
      "   &!!*       *!",
      "   &  *       * ",
      "                ",
      "     *          ",
      "                ",
      "                ",
      "                ",
      "                ",
      "                ",
      "                ",
      "                ",
      "                ",
      "                ",
      "                ",
      "                "
    ]
  ],
  "palette": {
    "palette": [
      {
        "char": "!",
        "block": "immersiveengineering:concrete_brick"
      },
      {
        "char": "$",
        "block": "minecraft:coarse_dirt"
      },
      {
        "char": "%",
        "block": "minecraft:gravel"
      },
      {
        "char": "&",
        "block": "minecraft:mud_bricks"
      },
      {
        "char": "'",
        "block": "minecraft:smooth_stone"
      },
      {
        "char": "(",
        "block": "tfmg:asphalt"
      },
      {
        "char": ")",
        "block": "tfmg:factory_floor"
      },
      {
        "char": "*",
        "block": "tfmg:steel_block"
      }
    ]
  }
}
