{
  "xsize": 16,
  "zsize": 16,
  "slices": [
    [
      ")  ' )      '   ",
      "   '        '   ",
      "  .'        '   ",
      "   '        '   ",
      "   ----------   ",
      "   -        -   ",
      "   - !!  !! -   ",
      "   - !!  !! -   ",
      "   - !!  !! -   ",
      "   -        -   ",
      "   -        -   ",
      "   -        -   ",
      "   - !!  !! -   ",
      "   - !!  !! -   ",
      "   - !!  !! -   ",
      "   -        -   "
    ],
    [
      "   '( (((((('   ",
      ")  '()(((((('   ",
      "  .'(((((((('   ",
      "   '(((((((('   ",
      "   ----------   ",
      "   -        -   ",
      "   -        -   ",
      "   - %   %  -   ",
      "   -        -   ",
      "   -        -   ",
      "   -        -   ",
      "   -        -   ",
      "   -        -   ",
      "   - %   %  -   ",
      "   -        -   ",
      "   -        -   "
    ],
    [
      "   '    +   '   ",
      "   '    -   '   ",
      ") .'    - & '   ",
      "   '    -   '   ",
      "   ----------   ",
      "   -        -   ",
      "   -        -   ",
      "   -        -   ",
      "   -        -   ",
      "   -        -   ",
      "   -        -   ",
      "   -        -   ",
      "   -        -   ",
      "   -        -   ",
      "   -        -   ",
      "   -        -   "
    ],
    [
      "   $    ,   '   ",
      "   $    -   '   ",
      "***$    -   '   ",
      "***'    -   '   ",
      "***----------   ",
      "***-        -   ",
      "***-        -   ",
      "***-        -   ",
      "***-        -   ",
      "***-        -   ",
      "***-        -   ",
      "***-        -   ",
      "***-        -   ",
      "***-        -   ",
      "***-        -   ",
      "   -        -   "
    ],
    [
      "   $    -   '   ",
      "   $    -   '   ",
      "   $    -   '   ",
      "   '    -   '   ",
      "   ----------   ",
      "   -        -   ",
      "   -        -   ",
      "   -        -   ",
      "   -        -   ",
      "   -        -   ",
      "   -        -   ",
      "   -        -   ",
      "   -        -   ",
      "   -        -   ",
      "   -        -   ",
      "   -        -   "
    ],
    [
      "   '    -   '   ",
      "   '    -   '   ",
      "   '    -   '   ",
      "   '    -   '   ",
      "   ----------   ",
      "   -        -   ",
      "   -        -   ",
      "   -        -   ",
      "   -        -   ",
      "   -        -   ",
      "   -        -   ",
      "   -        -   ",
      "   -        -   ",
      "   -        -   ",
      "   -        -   ",
      "   -        -   "
    ]
  ],
  "palette": {
    "palette": [
      {
        "char": "!",
        "block": "create:fluid_tank"
      },
      {
        "char": "$",
        "block": "create:framed_glass"
      },
      {
        "char": "%",
        "block": "create:steam_engine"
      },
      {
        "char": "&",
        "block": "minecraft:barrel[facing=up,open=false]"
      },
      {
        "char": "'",
        "block": "minecraft:bricks"
      },
      {
        "char": "(",
        "block": "minecraft:polished_andesite"
      },
      {
        "char": ")",
        "block": "minecraft:polished_andesite_stairs[facing=south,half=bottom,shape=straight,waterlogged=false]"
      },
      {
        "char": "*",
        "block": "minecraft:smooth_stone_slab[type=top,waterlogged=false]"
      },
      {
        "char": "+",
        "block": "minecraft:spruce_door[facing=east,half=lower,hinge=left,open=false,powered=false]"
      },
      {
        "char": ",",
        "block": "minecraft:spruce_door[facing=east,half=upper,hinge=left,open=false,powered=false]"
      },
      {
        "char": "-",
        "block": "tfmg:cinder_block"
      },
      {
        "char": ".",
        "block": "tfmg:steel_block"
      }
    ]
  }
}
