{
  "xsize": 16,
  "zsize": 16,
  "slices": [
    [
      "                ",
      "                ",
      "    0     0     ",
      "                ",
      "   &&&&&&&&&&   ",
      "   &        &   ",
      "   '        &   ",
      "$$$'        &   ",
      "   &        &   ",
      "   &        &   ",
      "   &        &   ",
      "   &        &   ",
      "   &        &   ",
      "   &        &   ",
      "   &        &   ",
      "   &        &   "
    ],
    [
      "                ",
      "                ",
      "    *******     ",
      "    *******     ",
      "   &*******&&   ",
      "   &((((((((&   ",
      "   '((((((((&   ",
      "$$$'((((((((&   ",
      "   &((((((((&   ",
      "   &((((((((&   ",
      "   &((((((((&   ",
      "   &((((((((&   ",
      "   &((((((((&   ",
      "   &((((((((&   ",
      "   &((((((((&   ",
      "   &( ((((((&   "
    ],
    [
      "                ",
      "                ",
      "                ",
      "    ---  --     ",
      "   &&&&&&&&&&   ",
      "   &        &   ",
      "   '--   %%%&   ",
      "$$$'/    %%%&   ",
      "   &     %%%&   ",
      "   &     %%%&   ",
      "   &        &   ",
      "   &3+3333+3&   ",
      "   &    3   &   ",
      "   &    3   &   ",
      "   &--  3 2 &   ",
      "   &/   3   &   "
    ],
    [
      "                ",
      "                ",
      "                ",
      "                ",
      "   1!!!11!!1&   ",
      "   &        &   ",
      "   '     %%%&   ",
      "$$$'     %%%&   ",
      "   !     %%%&   ",
      "   !     %%%&   ",
      "   !        &   ",
      "   !3,3333,3&   ",
      "   !    3   &   ",
      "   !    3   &   ",
      "   !    3   &   ",
      "   !    3   &   "
    ],
    [
      "                ",
      "                ",
      "                ",
      "                ",
      "   1!!!11!!1&   ",
      "   &        &   ",
      "   '     %%%&   ",
      "$$$'     %%%&   ",
      "   !     %%%&   ",
      "   !     %%%&   ",
      "   !        &   ",
      "   !33333333&   ",
      "   !    3   &   ",
      "   !    3   &   ",
      "   !    3   &   ",
      "   !    3   &   "
    ],
    [
      "                ",
      "                ",
      "                ",
      "    ...))..     ",
      "   &&&&&&&&&&   ",
      "   &        &   ",
      "   '        &   ",
      "$$$'        &   ",
      "   &        &   ",
      "   &        &   ",
      "   &        &   ",
      "   &33333333&   ",
      "   &    3   &   ",
      "   &    3   &   ",
      "   &    3   &   ",
      "   &    3   &   "
    ]
  ],
  "palette": {
    "palette": [
      {
        "char": "!",
        "block": "create:framed_glass"
      },
      {
        "char": "$",
        "block": "immersiveengineering:concrete_brick"
      },
      {
        "char": "%",
        "block": "minecraft:bookshelf"
      },
      {
        "char": "&",
        "block": "minecraft:bricks"
      },
      {
        "char": "'",
        "block": "minecraft:mud_bricks"
      },
      {
        "char": "(",
        "block": "minecraft:polished_andesite"
      },
      {
        "char": ")",
        "block": "minecraft:smooth_stone"
      },
      {
        "char": "*",
        "block": "minecraft:smooth_stone_slab[type=top,waterlogged=false]"
      },
      {
        "char": "+",
        "block": "minecraft:spruce_door[facing=south,half=lower,hinge=left,open=false,powered=false]"
      },
      {
        "char": ",",
        "block": "minecraft:spruce_door[facing=south,half=upper,hinge=left,open=false,powered=false]"
      },
      {
        "char": "-",
        "block": "minecraft:spruce_slab[type=bottom,waterlogged=false]"
      },
      {
        "char": ".",
        "block": "minecraft:spruce_slab[type=top,waterlogged=false]"
      },
      {
        "char": "/",
        "block": "minecraft:spruce_stairs[facing=north,half=bottom,shape=straight,waterlogged=false]"
      },
      {
        "char": "0",
        "block": "minecraft:stripped_dark_oak_log[axis=y]"
      },
      {
        "char": "1",
        "block": "minecraft:stripped_spruce_log[axis=y]"
      },
      {
        "char": "2",
        "block": "supplementaries:item_shelf"
      },
      {
        "char": "3",
        "block": "tfmg:cinder_block"
      }
    ]
  }
}
