{
  "xsize": 16,
  "zsize": 16,
  "slices": [
    [
      "1111111111111111",
      "1111111111111111",
      "1111111111111111",
      "1111111111111111",
      "1111111111111111",
      "1111111111..-111",
      "11111111..-11111",
      "111111..-1111111",
      "1111..-111111111",
      "11..-11111111111",
      "..-1111111111111",
      "-111111111111111",
      "111111111111111.",
      "1111111111111..-",
      "11111111111..-11",
      "111111111..-1111"
    ],
    [
      "                ",
      "                ",
      "                ",
      "                ",
      "                ",
      "                ",
      "                ",
      "3333333333333333",
      "3333333333333333",
      "3333333333333333",
      "3333333333333333",
      "3333333333333333",
      "3333333333333333",
      "3333333333333333",
      "3333333333333333",
      "3333333333333333"
    ],
    [
      "                ",
      "                ",
      "                ",
      "                ",
      "                ",
      "                ",
      " /      /      /",
      "////////////////",
      "             2  ",
      "             2  ",
      "!!!!  %%%%%%%2 ,",
      "!!!!  %%%%%%%2  ",
      "!!!!  %%%%%%%2  ",
      "!!!!  %%%%%%%2  ",
      "!!!!  %%%%%%%2  ",
      "!!!!  %%%%%%%2  "
    ],
    [
      "                ",
      "                ",
      "                ",
      "                ",
      "                ",
      "                ",
      " /      /      /",
      "+/++++++/++++++/",
      "             2  ",
      "             2  ",
      "             2  ",
      "             2  ",
      "& *    $  (  2  ",
      "             2  ",
      "             2  ",
      "            )2  "
    ],
    [
      "                ",
      "                ",
      "                ",
      "                ",
      "                ",
      "                ",
      " /      /      /",
      "+/++++++/++++++/",
      "             2  ",
      "             2  ",
      "             2  ",
      "             2  ",
      "             2  ",
      "             2  ",
      "             2  ",
      "             2  "
    ],
    [
      "                ",
      "                ",
      "                ",
      "                ",
      "                ",
      "                ",
      " / 0000 / 0000 /",
      "+/++++++/++++++/",
      "             2  ",
      "             2  ",
      "             2  ",
      "             2  ",
      "       '     2  ",
      "             2  ",
      "             2  ",
      "             2  "
    ]
  ],
  "palette": {
    "palette": [
      {
        "char": "!",
        "block": "create:andesite_casing"
      },
      {
        "char": "$",
        "block": "create:basin"
      },
      {
        "char": "%",
        "block": "create:brass_casing"
      },
      {
        "char": "&",
        "block": "create:crushing_wheel"
      },
      {
        "char": "'",
        "block": "create:mechanical_mixer"
      },
      {
        "char": "(",
        "block": "create:mechanical_press"
      },
      {
        "char": ")",
        "block": "create:mechanical_saw"
      },
      {
        "char": "*",
        "block": "create:millstone"
      },
      {
        "char": "+",
        "block": "immersiveengineering:concrete_brick"
      },
      {
        "char": ",",
        "block": "kubejs:ruined_blast_furnace[facing=south]"
      },
      {
        "char": "-",
        "block": "minecraft:coarse_dirt"
      },
      {
        "char": ".",
        "block": "minecraft:gravel"
      },
      {
        "char": "/",
        "block": "minecraft:mud_bricks"
      },
      {
        "char": "0",
        "block": "minecraft:spruce_slab[type=bottom,waterlogged=false]"
      },
      {
        "char": "1",
        "block": "tfmg:asphalt"
      },
      {
        "char": "2",
        "block": "tfmg:cinder_block"
      },
      {
        "char": "3",
        "block": "tfmg:factory_floor"
      }
    ]
  }
}
