{
  "xsize": 16,
  "zsize": 16,
  "slices": [
    [
      "                ",
      "                ",
      "                ",
      "''''         $$$",
      "   '         $  ",
      "   '         $  ",
      "   '   !!!   $  ",
      "   ' !!! !!! $  ",
      "   ' !     ! $  ",
      "   '!!     !!$  ",
      "   '!       !$  ",
      "   '!!     !!$  ",
      "   ' !     ! $  ",
      "   ' !!! !!! $  ",
      "   '   !!!   $  ",
      "   '         $( "
    ],
    [
      "                ",
      "                ",
      "                ",
      "''''         $$$",
      "   '         $  ",
      "   '         $  ",
      "   '   !!!   $  ",
      "   ' !!! !!! $  ",
      "   ' !     ! $  ",
      "   '!!     !!$  ",
      "   '!       !$  ",
      "   '!!     !!$  ",
      "   ' !     ! $  ",
      "   ' !!! !!! $  ",
      "   '   !!!   $  ",
      "   '         $  "
    ],
    [
      "                ",
      "                ",
      "   %            ",
      "'''%         $$$",
      "   %         $  ",
      "   %         $  ",
      "   %   !!!   $  ",
      "   % !!! !!! $  ",
      "   % !     ! $  ",
      "   %!!     !!$  ",
      "   %!       !$''",
      "   %!!     !!$''",
      "   % !     ! $''",
      "   % !!! !!! $''",
      "   %   !!!   $''",
      "   %         $ '"
    ],
    [
      "                ",
      "                ",
      "  %             ",
      "''%          $$$",
      "  %          $  ",
      "  %          $  ",
      "  %    !!!   $  ",
      "  %  !!! !!! $  ",
      "  %  !     ! $  ",
      "  % !!     !!$  ",
      "  % !       !$  ",
      "  % !!     !!$  ",
      "  %  !     ! $&&",
      "  %  !!! !!! $&&",
      "  %    !!!   $  ",
      "  %          $  "
    ],
    [
      "                ",
      "                ",
      " %              ",
      "'%           $$$",
      " %           $  ",
      " %           $  ",
      " %     !!!   $  ",
      " %   !!! !!! $  ",
      " %   !     ! $  ",
      " %  !!     !!$  ",
      " %  !       !$  ",
      " %  !!     !!$  ",
      " %   !     ! $&&",
      " %   !!! !!! $&&",
      " %     !!!   $  ",
      " %           $  "
    ],
    [
      "                ",
      "                ",
      "%               ",
      "%            $$$",
      "%            $  ",
      "%            $  ",
      "%      !!!   $  ",
      "%    !!! !!! $  ",
      "%    !     ! $  ",
      "%   !!     !!$  ",
      "%   !       !$  ",
      "%   !!     !!$  ",
      "%    !     ! $  ",
      "%    !!! !!! $  ",
      "%      !!!   $  ",
      "%            $  "
    ]
  ],
  "palette": {
    "palette": [
      {
        "char": "!",
        "block": "immersiveengineering:sheetmetal_steel"
      },
      {
        "char": "$",
        "block": "minecraft:dark_oak_planks"
      },
      {
        "char": "%",
        "block": "minecraft:dark_oak_stairs[facing=west,half=bottom,shape=straight,waterlogged=false]"
      },
      {
        "char": "&",
        "block": "minecraft:hay_block"
      },
      {
        "char": "'",
        "block": "minecraft:spruce_planks"
      },
      {
        "char": "(",
        "block": "minecraft:spruce_stairs[facing=south,half=bottom,shape=straight,waterlogged=false]"
      }
    ]
  }
}
