{
  "xsize": 16,
  "zsize": 16,
  "slices": [
    [
      "+++,,,,,,,+,,,,,",
      "+++,,,,,,,+,,,,,",
      "-.+,,,,,,,+,,,,,",
      "+++,,,,,,,+,,,,,",
      "+++///////+/////",
      "+.+,,,,,,,.,,,,,",
      "+++,,,,,,,+,,,,,",
      "+++,,,,,,,+,,,,,",
      "+-.,,,,,,,.,,,,,",
      "+++,,,,,,,+,,,,,",
      "+++++++-.+++++++",
      "++.+++++++-.++++",
      "+++++.+++++++-.+",
      "                ",
      "                ",
      "                "
    ],
    [
      "   1 72 03 $' %(",
      "    50 61  % !& ",
      "   36 47 5  )$ *",
      "   4 25 36 '* (!",
      "                ",
      "   61 72 0  $' %",
      "   7 50 61 *% !&",
      "    36 47  ! )$ ",
      "   14 25 3  '* (",
      "   2 03 14 %( &)",
      "                ",
      "                ",
      "                ",
      "                ",
      "                ",
      "                "
    ],
    [
      "                ",
      "                ",
      "                ",
      "                ",
      "                ",
      "                ",
      "                ",
      "                ",
      "                ",
      "                ",
      "                ",
      "                ",
      "                ",
      "                ",
      "                ",
      "                "
    ],
    [
      "                ",
      "                ",
      "                ",
      "                ",
      "                ",
      "                ",
      "                ",
      "                ",
      "                ",
      "                ",
      "                ",
      "                ",
      "                ",
      "                ",
      "                ",
      "                "
    ],
    [
      "                ",
      "                ",
      "                ",
      "                ",
      "                ",
      "                ",
      "                ",
      "                ",
      "                ",
      "                ",
      "                ",
      "                ",
      "                ",
      "                ",
      "                ",
      "                "
    ],
    [
      "                ",
      "                ",
      "                ",
      "                ",
      "                ",
      "                ",
      "                ",
      "                ",
      "                ",
      "                ",
      "                ",
      "                ",
      "                ",
      "                ",
      "                ",
      "                "
    ]
  ],
  "palette": {
    "palette": [
      {
        "char": "!",
        "block": "minecraft:carrots[age=0]"
      },
      {
        "char": "$",
        "block": "minecraft:carrots[age=1]"
      },
      {
        "char": "%",
        "block": "minecraft:carrots[age=2]"
      },
      {
        "char": "&",
        "block": "minecraft:carrots[age=3]"
      },
      {
        "char": "'",
        "block": "minecraft:carrots[age=4]"
      },
      {
        "char": "(",
        "block": "minecraft:carrots[age=5]"
      },
      {
        "char": ")",
        "block": "minecraft:carrots[age=6]"
      },
      {
        "char": "*",
        "block": "minecraft:carrots[age=7]"
      },
      {
        "char": "+",
        "block": "minecraft:coarse_dirt"
      },
      {
        "char": ",",
        "block": "minecraft:farmland[moisture=7]"
      },
      {
        "char": "-",
        "block": "minecraft:gravel"
      },
      {
        "char": ".",
        "block": "minecraft:podzol"
      },
      {
        "char": "/",
        "block": "minecraft:water[level=0]"
      },
      {
        "char": "0",
        "block": "minecraft:wheat[age=0]"
      },
      {
        "char": "1",
        "block": "minecraft:wheat[age=1]"
      },
      {
        "char": "2",
        "block": "minecraft:wheat[age=2]"
      },
      {
        "char": "3",
        "block": "minecraft:wheat[age=3]"
      },
      {
        "char": "4",
        "block": "minecraft:wheat[age=4]"
      },
      {
        "char": "5",
        "block": "minecraft:wheat[age=5]"
      },
      {
        "char": "6",
        "block": "minecraft:wheat[age=6]"
      },
      {
        "char": "7",
        "block": "minecraft:wheat[age=7]"
      }
    ]
  }
}
