{
  "xsize": 16,
  "zsize": 16,
  "slices": [
    [
      ",,,,,,++++++&&&&",
      ",,,,,,++++++&&&&",
      ",,&&&&&&&&&&&&&&",
      ",,&'''''''''''''",
      ",,&'''''''''''''",
      ",,&'''''''''''''",
      "))&'''''''''''''",
      "))&'''''''''''''",
      "))&'''''''''''''",
      "))&'''''''''''''",
      "))&'''''''''''''",
      "))&'''''''''''''",
      "((&'''''''''''''",
      "((&'''''''''''''",
      "((&'''''''''''''",
      "((&'''''''''''''"
    ],
    [
      "                ",
      "                ",
      "                ",
      "                ",
      "    ************",
      "    ************",
      "    ************",
      "  4 ************",
      "    ************",
      "    ************",
      "    ************",
      "    ************",
      "    ************",
      "    ************",
      "    ************",
      "    ************"
    ],
    [
      "                ",
      "                ",
      "                ",
      "                ",
      "    111111111111",
      "    1       5   ",
      "    1       5   ",
      "  4 1       5   ",
      "    1 22 6  5 22",
      "    1 3     5 3 ",
      "    1       -   ",
      "    1555/5555555",
      "    1       5   ",
      "    1       5 $$",
      "    1 %     5 $$",
      "    1       5 $$"
    ],
    [
      "                ",
      "                ",
      "                ",
      "                ",
      "    11!!111111!!",
      "    1       5   ",
      "    1       5   ",
      "    1       5   ",
      "    !       5   ",
      "    !       5   ",
      "    1       .   ",
      "    155505555555",
      "    1       5   ",
      "    1       5 $$",
      "    1       5 $$",
      "    1       5 $$"
    ],
    [
      "                ",
      "                ",
      "                ",
      "                ",
      "    11!!111111!!",
      "    1       5   ",
      "    1       5   ",
      "    1       5   ",
      "    !       5   ",
      "    !       5   ",
      "    1       5   ",
      "    155555555555",
      "    1       5   ",
      "    1       5   ",
      "    1       5   ",
      "    1       5   "
    ],
    [
      "                ",
      "                ",
      "                ",
      "                ",
      "    111111111111",
      "    1       5   ",
      "    1       5   ",
      "    1       5   ",
      "    1       5   ",
      "    1       5   ",
      "    1       5   ",
      "    155555555555",
      "    1       5   ",
      "    1       5   ",
      "    1       5   ",
      "    1       5   "
    ]
  ],
  "palette": {
    "palette": [
      {
        "char": "!",
        "block": "create:framed_glass"
      },
      {
        "char": "$",
        "block": "immersiveengineering:crate"
      },
      {
        "char": "%",
        "block": "kubejs:ruined_lectern[facing=south]"
      },
      {
        "char": "&",
        "block": "minecraft:coarse_dirt"
      },
      {
        "char": "'",
        "block": "minecraft:cobblestone"
      },
      {
        "char": "(",
        "block": "minecraft:dirt_path"
      },
      {
        "char": ")",
        "block": "minecraft:gravel"
      },
      {
        "char": "*",
        "block": "minecraft:oak_planks"
      },
      {
        "char": "+",
        "block": "minecraft:podzol"
      },
      {
        "char": ",",
        "block": "minecraft:rooted_dirt"
      },
      {
        "char": "-",
        "block": "minecraft:spruce_door[facing=east,half=lower,hinge=left,open=false,powered=false]"
      },
      {
        "char": ".",
        "block": "minecraft:spruce_door[facing=east,half=upper,hinge=left,open=false,powered=false]"
      },
      {
        "char": "/",
        "block": "minecraft:spruce_door[facing=south,half=lower,hinge=left,open=false,powered=false]"
      },
      {
        "char": "0",
        "block": "minecraft:spruce_door[facing=south,half=upper,hinge=left,open=false,powered=false]"
      },
      {
        "char": "1",
        "block": "minecraft:spruce_planks"
      },
      {
        "char": "2",
        "block": "minecraft:spruce_slab[type=bottom,waterlogged=false]"
      },
      {
        "char": "3",
        "block": "minecraft:spruce_stairs[facing=north,half=bottom,shape=straight,waterlogged=false]"
      },
      {
        "char": "4",
        "block": "minecraft:stripped_spruce_log[axis=y]"
      },
      {
        "char": "5",
        "block": "minecraft:stripped_spruce_wood"
      },
      {
        "char": "6",
        "block": "the_wasteland_reworked:radio"
      }
    ]
  }
}
