{
  "xsize": 16,
  "zsize": 16,
  "slices": [
    [
      "**'(((((((((((((",
      "**'(((((((((((((",
      "++'(((((((((((((",
      "++'(((((((((((((",
      "++''''''''''''''",
      "+'''''''''''''''",
      "+'((((((((((((((",
      "+'((((((((((((((",
      "*'((((((((((((((",
      "*'((((((((((((((",
      "*'((((((((((((((",
      "*'((((((((((((((",
      "*'((((((((((((((",
      "*'((((((((((((((",
      "+'((((((((((((((",
      "+'(((((((((((((("
    ],
    [
      "    ,,,,,,,,,,,,",
      "    ,,,,,,,,,,,,",
      "    ,,,,,,,,,,,,",
      "                ",
      "    444444444444",
      "                ",
      "    444444444444",
      "   1111111111111",
      "   1111111111111",
      "   1111111111111",
      "   1111111111111",
      "   1111111111111",
      "   1111111111111",
      "   1111111111111",
      "   1111111111111",
      "   1111111111111"
    ],
    [
      "    1       5   ",
      "    1       5   ",
      "    111111111/11",
      "                ",
      "     44444444444",
      "                ",
      "     44444444444",
      "   )))))))))))))",
      "   )           3",
      "   )           3",
      "   ) % $       3",
      "   )      &    3",
      "   )           -",
      "   )           3",
      "   ) 2222222   3",
      "   )           3"
    ],
    [
      "    1       5   ",
      "    1       5   ",
      "    111111111011",
      "                ",
      "      4444444444",
      "                ",
      "      4444444444",
      "   ))!!)))))))))",
      "   )           3",
      "   )           3",
      "   )           3",
      "   )           3",
      "   !           .",
      "   !           3",
      "   )           3",
      "   )           3"
    ],
    [
      "    1       5   ",
      "    1       5   ",
      "    111111111111",
      "                ",
      "                ",
      "                ",
      "                ",
      "   ))!!)))))))))",
      "   )           3",
      "   )           3",
      "   )           3",
      "   )           3",
      "   !           3",
      "   !           3",
      "   )           3",
      "   )           3"
    ],
    [
      "    1       5   ",
      "    1       5   ",
      "    111111111111",
      "                ",
      "                ",
      "                ",
      "                ",
      "   )))))))))))))",
      "   )           3",
      "   )           3",
      "   )           3",
      "   )           3",
      "   )           3",
      "   )           3",
      "   )           3",
      "   )           3"
    ]
  ],
  "palette": {
    "palette": [
      {
        "char": "!",
        "block": "create:framed_glass"
      },
      {
        "char": "$",
        "block": "kubejs:ruined_furnace[facing=south]"
      },
      {
        "char": "%",
        "block": "kubejs:ruined_smoker[facing=south]"
      },
      {
        "char": "&",
        "block": "minecraft:barrel[facing=up,open=false]"
      },
      {
        "char": "'",
        "block": "minecraft:coarse_dirt"
      },
      {
        "char": "(",
        "block": "minecraft:cobblestone"
      },
      {
        "char": ")",
        "block": "minecraft:dark_oak_planks"
      },
      {
        "char": "*",
        "block": "minecraft:dirt_path"
      },
      {
        "char": "+",
        "block": "minecraft:gravel"
      },
      {
        "char": ",",
        "block": "minecraft:oak_planks"
      },
      {
        "char": "-",
        "block": "minecraft:spruce_door[facing=east,half=lower,hinge=left,open=false,powered=false]"
      },
      {
        "char": ".",
        "block": "minecraft:spruce_door[facing=east,half=upper,hinge=left,open=false,powered=false]"
      },
      {
        "char": "/",
        "block": "minecraft:spruce_door[facing=south,half=lower,hinge=left,open=false,powered=false]"
      },
      {
        "char": "0",
        "block": "minecraft:spruce_door[facing=south,half=upper,hinge=left,open=false,powered=false]"
      },
      {
        "char": "1",
        "block": "minecraft:spruce_planks"
      },
      {
        "char": "2",
        "block": "minecraft:spruce_slab[type=bottom,waterlogged=false]"
      },
      {
        "char": "3",
        "block": "minecraft:stripped_dark_oak_wood"
      },
      {
        "char": "4",
        "block": "minecraft:stripped_spruce_log[axis=x]"
      },
      {
        "char": "5",
        "block": "minecraft:stripped_spruce_wood"
      }
    ]
  }
}
