{
  "xsize": 16,
  "zsize": 16,
  "slices": [
    [
      "................",
      "..&....&....&...",
      "................",
      ".%..............",
      "................",
      "................",
      "................",
      "................",
      " &&%............",
      " %..............",
      " ...............",
      " .............&&",
      " ...........&&%.",
      " .........&&%...",
      " .......&&%.....",
      " %....&&%......."
    ],
    [
      "                ",
      "                ",
      "                ",
      "                ",
      "                ",
      "                ",
      "                ",
      "    ************",
      "    ************",
      "    ************",
      "    ************",
      "    ************",
      "    ************",
      "    ************",
      "    ************",
      "    ************"
    ],
    [
      "                ",
      "                ",
      "                ",
      "                ",
      "                ",
      "                ",
      "                ",
      "    ////////(///",
      "    /         + ",
      "    /         + ",
      "    / $$$$$$  + ",
      "    / ' ,     + ",
      "    /         + ",
      "    /         + ",
      "    /         + ",
      "    /         + "
    ],
    [
      "                ",
      "                ",
      "                ",
      "                ",
      "                ",
      "                ",
      "                ",
      "    ///!!///)///",
      "    /         + ",
      "    /         + ",
      "    /      -  + ",
      "    /         + ",
      "    /         + ",
      "    /         + ",
      "    /         + ",
      "    /         + "
    ],
    [
      "                ",
      "                ",
      "                ",
      "                ",
      "                ",
      "                ",
      "                ",
      "    ///!!///////",
      "    /         + ",
      "    /         + ",
      "    /         + ",
      "    /         + ",
      "    /         + ",
      "    /         + ",
      "    /         + ",
      "    /         + "
    ],
    [
      "                ",
      "                ",
      "                ",
      "                ",
      "                ",
      "                ",
      "                ",
      "    ////////////",
      "    /         + ",
      "    /         + ",
      "    /         + ",
      "    /         + ",
      "    /         + ",
      "    /         + ",
      "    /         + ",
      "    /         + "
    ]
  ],
  "palette": {
    "palette": [
      {
        "char": "!",
        "block": "create:framed_glass"
      },
      {
        "char": "$",
        "block": "minecraft:barrel[facing=up,open=false]"
      },
      {
        "char": "%",
        "block": "minecraft:coarse_dirt"
      },
      {
        "char": "&",
        "block": "minecraft:gravel"
      },
      {
        "char": "'",
        "block": "minecraft:smoker[facing=north,lit=false]"
      },
      {
        "char": "(",
        "block": "minecraft:spruce_door[facing=north,half=lower,hinge=left,open=false,powered=false]"
      },
      {
        "char": ")",
        "block": "minecraft:spruce_door[facing=north,half=upper,hinge=left,open=false,powered=false]"
      },
      {
        "char": "*",
        "block": "minecraft:spruce_planks"
      },
      {
        "char": "+",
        "block": "minecraft:stripped_spruce_wood"
      },
      {
        "char": ",",
        "block": "minecraft:water_cauldron[level=1]"
      },
      {
        "char": "-",
        "block": "supplementaries:item_shelf"
      },
      {
        "char": ".",
        "block": "tfmg:asphalt"
      },
      {
        "char": "/",
        "block": "the_wasteland_reworked:decayed_planks"
      }
    ]
  }
}
