{
  "xsize": 16,
  "zsize": 16,
  "slices": [
    [
      "                ",
      "                ",
      "                ",
      "                ",
      "%%%%%%%%%%%%%%%%",
      "                ",
      "                ",
      "                ",
      "                ",
      "                ",
      "                ",
      "                ",
      "                ",
      "                ",
      "                ",
      "                "
    ],
    [
      "                ",
      "                ",
      "                ",
      "                ",
      "&&&&&&&&&&&&&&&&",
      "&&&&&&&&&&&&&&&&",
      "&&&&&&&&&&&&&&&&",
      "&&&&&&&&&&&&&&&&",
      "&&&&&&&&&&&&&&&&",
      "&&&&&&&&&&&&&&&&",
      "&&&&&&&&&&&&&&&&",
      "&&&&&&&&&&&&&&&&",
      "&&&&&&&&&&&&&&&&",
      "&&&&&&&&&&&&&&&&",
      "&&&&&&&&&&&&&&&&",
      "&&&&&&&&&&&&&&&&"
    ],
    [
      "                ",
      "                ",
      "                ",
      "                ",
      "                ",
      "                ",
      "                ",
      "                ",
      "$$$$$  $$$$$$$$ ",
      "    $  $      $ ",
      "    $  $      $ ",
      "    $  $      $ ",
      "    $  $      $ ",
      "    $  $      $ ",
      "    $  $      $ ",
      "    $  $      $ "
    ],
    [
      "                ",
      "                ",
      "                ",
      "                ",
      "                ",
      "                ",
      "                ",
      "                ",
      "!!!!$  $!!!!!!$ ",
      "    $  $      $ ",
      "    $  $      $ ",
      "    $  $      $ ",
      "    $  $      $ ",
      "    $  $      $ ",
      "    $  $      $ ",
      "    $  $      $ "
    ],
    [
      "                ",
      "                ",
      "                ",
      "                ",
      "                ",
      "                ",
      "                ",
      "                ",
      "!!!!$  $!!!!!!$ ",
      "    $  $      $ ",
      "    $  $      $ ",
      "    $  $      $ ",
      "    $  $      $ ",
      "    $  $      $ ",
      "    $  $      $ ",
      "    $  $      $ "
    ],
    [
      "                ",
      "                ",
      "                ",
      "                ",
      "                ",
      "                ",
      "                ",
      "                ",
      "$$$$$  $$$$$$$$ ",
      "$$$$$  $$$$$$$$ ",
      "$$$$$  $$$$$$$$ ",
      "$$$$$  $$$$$$$$ ",
      "$$$$$  $$$$$$$$ ",
      "$$$$$  $$$$$$$$ ",
      "$$$$$  $$$$$$$$ ",
      "$$$$$  $$$$$$$$ "
    ]
  ],
  "palette": {
    "palette": [
      {
        "char": "!",
        "block": "create:framed_glass"
      },
      {
        "char": "$",
        "block": "minecraft:spruce_planks"
      },
      {
        "char": "%",
        "block": "minecraft:stripped_dark_oak_wood"
      },
      {
        "char": "&",
        "block": "minecraft:weathered_cut_copper"
      }
    ]
  }
}
