{
  "xsize": 16,
  "zsize": 16,
  "slices": [
    [
      "((((((((((((((((",
      "((((((((((((((((",
      "&&*%****%****%**",
      "&&***%****%****%",
      "&&&****%****%***",
      "&&**&****%****%*",
      "&&%***&****%****",
      "&&**%***&****%**",
      "&&****%***&****%",
      "&&*%****%***&***",
      "&&***%****%***&*",
      "&&%****%****%***",
      "&&**%****%****%*",
      "&&&&&&&&&&&&&&&&",
      "&&&&&&&&&&&&&&&&",
      "&&&&&&&&&&&&&&&&"
    ],
    [
      "                ",
      "                ",
      "   .............",
      "----............",
      "----............",
      "----............",
      "   .............",
      "   .............",
      "   .............",
      "   .............",
      "----............",
      "----............",
      "----............",
      "   .............",
      "   .............",
      "   ............."
    ],
    [
      "                ",
      "                ",
      "   )))       )))",
      "----            ",
      "----            ",
      "----   $'''$    ",
      "   )   '''''    ",
      "   )   '''''    ",
      "   )   '''''    ",
      "   )   $'''$    ",
      "----            ",
      "----            ",
      "----////+///////",
      "   )           /",
      "   ) !!!!!!!!  /",
      "   ) !!!!!!!!  /"
    ],
    [
      "                ",
      "                ",
      "   )))       )))",
      "----            ",
      "----            ",
      "----   '''''    ",
      "   )   '''''    ",
      "   )   '''''    ",
      "   )   '''''    ",
      "   )   '''''    ",
      "----            ",
      "----            ",
      "----////,///////",
      "   )           /",
      "   ) !!!!!!!!  /",
      "   ) !!!!!!!!  /"
    ],
    [
      "                ",
      "                ",
      "   )))       )))",
      "   )            ",
      "   )            ",
      "   )   '''''    ",
      "   )   '''''    ",
      "   )   '''''    ",
      "   )   '''''    ",
      "   )   '''''    ",
      "   )            ",
      "   )            ",
      "   )////////////",
      "   )           /",
      "   )           /",
      "   )           /"
    ],
    [
      "                ",
      "                ",
      "   )))       )))",
      "   )            ",
      "   )            ",
      "   )            ",
      "   )            ",
      "   )            ",
      "   )            ",
      "   )            ",
      "   )            ",
      "   )            ",
      "   )////////////",
      "   )           /",
      "   )           /",
      "   )           /"
    ]
  ],
  "palette": {
    "palette": [
      {
        "char": "!",
        "block": "immersiveengineering:crate"
      },
      {
        "char": "$",
        "block": "minecraft:black_concrete"
      },
      {
        "char": "%",
        "block": "minecraft:coarse_dirt"
      },
      {
        "char": "&",
        "block": "minecraft:gravel"
      },
      {
        "char": "'",
        "block": "minecraft:green_terracotta"
      },
      {
        "char": "(",
        "block": "minecraft:mud"
      },
      {
        "char": ")",
        "block": "minecraft:mud_bricks"
      },
      {
        "char": "*",
        "block": "minecraft:podzol"
      },
      {
        "char": "+",
        "block": "minecraft:spruce_door[facing=south,half=lower,hinge=left,open=false,powered=false]"
      },
      {
        "char": ",",
        "block": "minecraft:spruce_door[facing=south,half=upper,hinge=left,open=false,powered=false]"
      },
      {
        "char": "-",
        "block": "minecraft:spruce_planks"
      },
      {
        "char": ".",
        "block": "minecraft:stone_bricks"
      },
      {
        "char": "/",
        "block": "minecraft:stripped_spruce_wood"
      }
    ]
  }
}
