{
  "xsize": 16,
  "zsize": 16,
  "slices": [
    [
      ")))&))))%))&&&&&",
      ")%)))&))))%&&&&&",
      ")))%)))&)))&&&&&",
      "%))))%)))&)&&&&&",
      "))%))))%)))&&&(&",
      "))))%))))%)&&&&&",
      ")%))))%))))&&&&&",
      ")))%))))%))&&&&&",
      "&))))%))))%&&&&&",
      "))&%%%%%%%%%%%%%",
      "%))%%%%%%%%%%%%%",
      "))%%%%%%%%%%%%(%",
      ")))%%%%%%%%%%%%%",
      ")%)%%%%%%%%%%%%%",
      ")))%))))%))&&&&&",
      "%))))%))))%&&&&&"
    ],
    [
      "                ",
      "                ",
      "                ",
      "                ",
      "'''''      *****",
      "'''''      *****",
      "'''''      *****",
      "'''''      *****",
      "'''''      *****",
      "'''''      *****",
      "'''''      *****",
      "'''''      *****",
      "'''''      *****",
      "'''''      *****",
      "'''''      *****",
      "'''''      *****"
    ],
    [
      "                ",
      "                ",
      "                ",
      "                ",
      "/////      000  ",
      "    /      0    ",
      "    /      0    ",
      "    /      0    ",
      " $  /      0 111",
      "    /      0    ",
      "    +      0    ",
      "-222/      0    ",
      "    /      0 111",
      "!!  /      0    ",
      "!!  /      0    ",
      "!!  /      0    "
    ],
    [
      "                ",
      "                ",
      "                ",
      "                ",
      "/////      000  ",
      "    /      0    ",
      "    /      0    ",
      "    /      0    ",
      "    /      0    ",
      "    /      0    ",
      "    ,      0    ",
      ".222/      0    ",
      "    /      0    ",
      "!!  /      0    ",
      "!!  /      0    ",
      "!!  /      0    "
    ],
    [
      "                ",
      "                ",
      "                ",
      "                ",
      "/////      000  ",
      "    /      0    ",
      "    /      0    ",
      "    /      0    ",
      "    /      0    ",
      "    /      0    ",
      "    /      0    ",
      "2222/      0    ",
      "    /      0    ",
      "    /      0    ",
      "    /      0    ",
      "    /      0    "
    ],
    [
      "                ",
      "                ",
      "                ",
      "                ",
      "/////      000  ",
      "    /      0    ",
      "    /      0    ",
      "    /      0    ",
      "    /      0    ",
      "    /      0    ",
      "    /      0    ",
      "2222/      0    ",
      "    /      0    ",
      "    /      0    ",
      "    /      0    ",
      "    /      0    "
    ]
  ],
  "palette": {
    "palette": [
      {
        "char": "!",
        "block": "immersiveengineering:crate"
      },
      {
        "char": "$",
        "block": "minecraft:cartography_table"
      },
      {
        "char": "%",
        "block": "minecraft:coarse_dirt"
      },
      {
        "char": "&",
        "block": "minecraft:gravel"
      },
      {
        "char": "'",
        "block": "minecraft:oak_planks"
      },
      {
        "char": "(",
        "block": "minecraft:packed_mud"
      },
      {
        "char": ")",
        "block": "minecraft:podzol"
      },
      {
        "char": "*",
        "block": "minecraft:polished_deepslate"
      },
      {
        "char": "+",
        "block": "minecraft:spruce_door[facing=east,half=lower,hinge=left,open=false,powered=false]"
      },
      {
        "char": ",",
        "block": "minecraft:spruce_door[facing=east,half=upper,hinge=left,open=false,powered=false]"
      },
      {
        "char": "-",
        "block": "minecraft:spruce_door[facing=south,half=lower,hinge=left,open=false,powered=false]"
      },
      {
        "char": ".",
        "block": "minecraft:spruce_door[facing=south,half=upper,hinge=left,open=false,powered=false]"
      },
      {
        "char": "/",
        "block": "minecraft:spruce_planks"
      },
      {
        "char": "0",
        "block": "minecraft:stripped_dark_oak_wood"
      },
      {
        "char": "1",
        "block": "minecraft:stripped_spruce_log[axis=x]"
      },
      {
        "char": "2",
        "block": "minecraft:stripped_spruce_wood"
      }
    ]
  }
}
