{
  "xsize": 16,
  "zsize": 16,
  "slices": [
    [
      " ///''&/////////",
      " /''&///////////",
      " '&/////////////",
      " ///////////////",
      " //////////////'",
      " &///////////''&",
      " //////////''&//",
      " ////////''&////",
      " //////''&//////",
      " ////''&////////",
      " //''&//////////",
      " &'&////////////",
      " &//////////////",
      " ///////////////",
      " /////////////''",
      " ///////////''&/"
    ],
    [
      "    ,,,,,,,,,,,,",
      "    ,,,,,,,,,,,,",
      "    ,,,,,,,,,,,,",
      "    ,,,,,,,,,,,,",
      "    ,,,,,,,,,,,,",
      "    ,,,,,,,,,,,,",
      "    ,,,,,,,,,,,,",
      "    ,,,,,,,,,,,,",
      "    ,,,,,,,,,,,,",
      "    ,,,,,,,,,,,,",
      "                ",
      "                ",
      "                ",
      "                ",
      "                ",
      "    -   -   -   "
    ],
    [
      "    0.....*.....",
      "    0         . ",
      "    0         . ",
      "    0         . ",
      "    0         ( ",
      "    0 %       . ",
      "    0 $       . ",
      "    0         . ",
      "    0         . ",
      "    000000000000",
      "                ",
      "                ",
      "                ",
      "                ",
      "                ",
      "    -   -   -   "
    ],
    [
      "    0.....+.....",
      "    0         . ",
      "    0         . ",
      "    0         . ",
      "    0         ) ",
      "    0         . ",
      "    0         . ",
      "    0         . ",
      "    0         . ",
      "    000!!0000000",
      "                ",
      "                ",
      "                ",
      "                ",
      "                ",
      "    -   -   -   "
    ],
    [
      "    0...........",
      "    0         . ",
      "    0         . ",
      "    0         . ",
      "    0         . ",
      "    0         . ",
      "    0         . ",
      "    0         . ",
      "    0         . ",
      "    000!!0000000",
      "                ",
      "                ",
      "                ",
      "                ",
      "                ",
      "                "
    ],
    [
      "    0...........",
      "    0         . ",
      "    0         . ",
      "    0         . ",
      "    0         . ",
      "    0         . ",
      "    0         . ",
      "    0         . ",
      "    0         . ",
      "    000000000000",
      "                ",
      "                ",
      "                ",
      "                ",
      "                ",
      "                "
    ]
  ],
  "palette": {
    "palette": [
      {
        "char": "!",
        "block": "create:framed_glass"
      },
      {
        "char": "$",
        "block": "minecraft:brown_bed[facing=north,occupied=false,part=foot]"
      },
      {
        "char": "%",
        "block": "minecraft:brown_bed[facing=north,occupied=false,part=head]"
      },
      {
        "char": "&",
        "block": "minecraft:coarse_dirt"
      },
      {
        "char": "'",
        "block": "minecraft:gravel"
      },
      {
        "char": "(",
        "block": "minecraft:spruce_door[facing=east,half=lower,hinge=left,open=false,powered=false]"
      },
      {
        "char": ")",
        "block": "minecraft:spruce_door[facing=east,half=upper,hinge=left,open=false,powered=false]"
      },
      {
        "char": "*",
        "block": "minecraft:spruce_door[facing=south,half=lower,hinge=left,open=false,powered=false]"
      },
      {
        "char": "+",
        "block": "minecraft:spruce_door[facing=south,half=upper,hinge=left,open=false,powered=false]"
      },
      {
        "char": ",",
        "block": "minecraft:spruce_planks"
      },
      {
        "char": "-",
        "block": "minecraft:stripped_oak_log"
      },
      {
        "char": ".",
        "block": "minecraft:stripped_spruce_wood"
      },
      {
        "char": "/",
        "block": "tfmg:asphalt"
      },
      {
        "char": "0",
        "block": "the_wasteland_reworked:decayed_planks"
      }
    ]
  }
}
