{
  "xsize": 16,
  "zsize": 16,
  "slices": [
    [
      "      $$$$$$$$$$",
      "      $$$$$$$$$$",
      "      $$$$$$$$$$",
      "      $$$$$$$$$$",
      "      $$$$$$$$$$",
      "      $$$$$$$$$$",
      "      $$$$$$$$$$",
      "      $$$$$$$$$$",
      "      $$$$$$$$$$",
      "      $$$$$$$$$$",
      "      $$$$$$$$$$",
      "      $$$$$$$$$$",
      "      $$$$$$$$$$",
      "      $$$$$$$$$$",
      "      $$$$$$$$$$",
      "&&    $$$$$$$$$$"
    ],
    [
      "             &  ",
      "             &  ",
      "             &  ",
      "             &  ",
      "             &  ",
      "             &  ",
      "             &  ",
      "             &  ",
      "             &  ",
      "             &  ",
      "             &  ",
      "             &  ",
      "             &  ",
      "             &  ",
      "             &  ",
      "&&      &&&&&&  "
    ],
    [
      "             &  ",
      "             &  ",
      "             &  ",
      "             &  ",
      "             &  ",
      "             &  ",
      "             &  ",
      "             &  ",
      "             &  ",
      "             &  ",
      "             &  ",
      "             &  ",
      "             &  ",
      "             &  ",
      "             &  ",
      "&&      &&&&&&  "
    ],
    [
      "%%%%%           ",
      "%%%%%           ",
      "%%%%%           ",
      "%%%%%           ",
      "%%%%%           ",
      "%%%%%           ",
      "%%%%%           ",
      "%%%%%           ",
      "%%%%%           ",
      "%%%%%           ",
      "%%%%%           ",
      "%%%%%           ",
      "%%%%%           ",
      "%%%%%           ",
      "                ",
      "&&&&&           "
    ],
    [
      "                ",
      "                ",
      "                ",
      "                ",
      "                ",
      "                ",
      "                ",
      "                ",
      "                ",
      "!!              ",
      "!!              ",
      "!!              ",
      "!!              ",
      "!!              ",
      "                ",
      "&&&&&           "
    ],
    [
      "                ",
      "                ",
      "                ",
      "                ",
      "                ",
      "                ",
      "                ",
      "                ",
      "                ",
      "!!              ",
      "!!              ",
      "!!              ",
      "!!              ",
      "!!              ",
      "                ",
      "&&&&&           "
    ]
  ],
  "palette": {
    "palette": [
      {
        "char": "!",
        "block": "farmersdelight:straw_bale"
      },
      {
        "char": "$",
        "block": "minecraft:gravel"
      },
      {
        "char": "%",
        "block": "minecraft:spruce_planks"
      },
      {
        "char": "&",
        "block": "minecraft:stripped_dark_oak_log"
      }
    ]
  }
}
