{
  "xsize": 16,
  "zsize": 16,
  "slices": [
    [
      "                ",
      "$'$$!$''''$'''''",
      "$$!'''''''''''''",
      "!''''''''''''''$",
      "'''''''''''''''$",
      "'''''''''''''$$!",
      "'''''''''''$$!''",
      "'''''''''$$!''''",
      "'''''''$$!''''''",
      "'''''$$!'''''''$",
      "'''$$!''''''''''",
      "'$$!''''''''''''",
      "$!''''''''''''''",
      "''''''''''''''''",
      "''''''''''''''$$",
      "''''''''''''$$!$"
    ],
    [
      "                ",
      "                ",
      "                ",
      "                ",
      "                ",
      "                ",
      "                ",
      "                ",
      "!!!!!!!!!!!!!!  ",
      "!!!!!!$$$$$$$$$$",
      "!!!!!!$$$$$$$$$$",
      "!!!!!!$$$$$$$$$$",
      "!!!!!!$$$$$$$$$$",
      "!!!!!!$$$$$$$$$$",
      "!!!!!!$$$$$$$$$$",
      "!!!!!!$$$$$$$$$$"
    ],
    [
      "                ",
      "                ",
      "                ",
      "                ",
      "                ",
      "                ",
      "                ",
      "                ",
      "%%      %%%%%%  ",
      "      $$$$$$$$$$",
      "      $$$$$$$$$$",
      "      $$$$$$$$$$",
      "&&    $$$$$$$$$$",
      "&&    $$$$$$$$$$",
      "&&    $$$$$$$$$$",
      "&&    $$$$$$$$$$"
    ],
    [
      "                ",
      "                ",
      "                ",
      "                ",
      "                ",
      "                ",
      "                ",
      "                ",
      "%%      %%%%%%  ",
      "      $$$$$$$$$$",
      "      $$$$$$$$$$",
      "      $$$$$$$$$$",
      "&&    $$$$$$$$$$",
      "&&    $$$$$$$$$$",
      "&&    $$$$$$$$$$",
      "&&    $$$$$$$$$$"
    ],
    [
      "                ",
      "                ",
      "                ",
      "                ",
      "                ",
      "                ",
      "                ",
      "                ",
      "%%      %%%%%%  ",
      "      $$$$$$$$$$",
      "      $$$$$$$$$$",
      "      $$$$$$$$$$",
      "&&    $$$$$$$$$$",
      "&&    $$$$$$$$$$",
      "&&    $$$$$$$$$$",
      "&&    $$$$$$$$$$"
    ],
    [
      "                ",
      "                ",
      "                ",
      "                ",
      "                ",
      "                ",
      "                ",
      "                ",
      "%%      %%%%%%  ",
      "      $$$$$$$$$$",
      "      $$$$$$$$$$",
      "      $$$$$$$$$$",
      "      $$$$$$$$$$",
      "      $$$$$$$$$$",
      "      $$$$$$$$$$",
      "      $$$$$$$$$$"
    ]
  ],
  "palette": {
    "palette": [
      {
        "char": "!",
        "block": "minecraft:coarse_dirt"
      },
      {
        "char": "$",
        "block": "minecraft:gravel"
      },
      {
        "char": "%",
        "block": "minecraft:stripped_dark_oak_log"
      },
      {
        "char": "&",
        "block": "minecraft:stripped_oak_log"
      },
      {
        "char": "'",
        "block": "tfmg:asphalt"
      }
    ]
  }
}
