{
  "xsize": 16,
  "zsize": 16,
  "slices": [
    [
      "0000000%%$000000",
      "00000%%$00000000",
      "000%%$0000000000",
      "0%%$000000000000",
      "%$00000000000000",
      "0000000000000000",
      "00000000000000%%",
      "000000000000%%$0",
      "0000000000%%$000",
      "00000000%%$00000",
      "000000%%$0000000",
      "0000%%$000000000",
      "00%%$00000000000",
      "%%$0000000000000",
      "$000000000000000",
      "000000000000000%"
    ],
    [
      "++++++++    $$$$",
      "++++++++    $$$$",
      "++++++++    $$$$",
      "++++++++    $$$$",
      "++++++++    $$$$",
      "++++++++    $$$$",
      "++++++++    $$$$",
      "++++++++    $$$$",
      "++++++++    $$$$",
      "++++++++    $$$$",
      "            $$$$",
      "            $$$$",
      "            $$$$",
      "            $$$$",
      "            $$$$",
      "-   -   -   $$$$"
    ],
    [
      "...)...1    ,   ",
      "       1    ,   ",
      "       1    ,---",
      "       1    ,---",
      "       1    ,---",
      "       1    ,---",
      "/ '    1    ,   ",
      "       1    ,   ",
      "       1    ,---",
      "11111111    ,---",
      "            ,--(",
      "            ,---",
      "            ,   ",
      "            ,   ",
      "            ,   ",
      "-   -   -   ,,,,"
    ],
    [
      "...*...1    ,   ",
      "       1    ,   ",
      "       1    ,---",
      "       1    ,---",
      "       1    ,---",
      "       1    ,---",
      "       1    ,   ",
      "  &    1    ,   ",
      "       1    ,---",
      "11!!1111    ,---",
      "            ,---",
      "            ,---",
      "            ,   ",
      "            ,   ",
      "            ,   ",
      "-   -   -   ,,,,"
    ],
    [
      ".......1    ,   ",
      "       1    ,   ",
      "       1    ,---",
      "       1    ,---",
      "       1    ,---",
      "       1    ,---",
      "       1    ,   ",
      "       1    ,   ",
      "       1    ,---",
      "11!!1111    ,---",
      "            ,---",
      "            ,---",
      "            ,   ",
      "            ,   ",
      "            ,   ",
      "            ,,,,"
    ],
    [
      ".......1    ,   ",
      "       1    ,   ",
      "       1    ,   ",
      "       1    ,   ",
      "       1    ,   ",
      "       1    ,   ",
      "       1    ,   ",
      "       1    ,   ",
      "       1    ,   ",
      "11111111    ,   ",
      "            ,   ",
      "            ,   ",
      "            ,   ",
      "            ,   ",
      "            ,   ",
      "            ,,,,"
    ]
  ],
  "palette": {
    "palette": [
      {
        "char": "!",
        "block": "create:framed_glass"
      },
      {
        "char": "$",
        "block": "minecraft:coarse_dirt"
      },
      {
        "char": "%",
        "block": "minecraft:gravel"
      },
      {
        "char": "&",
        "block": "minecraft:lever[face=wall,facing=south,powered=false]"
      },
      {
        "char": "'",
        "block": "minecraft:quartz_stairs[facing=north,half=bottom,shape=straight,waterlogged=false]"
      },
      {
        "char": "(",
        "block": "minecraft:spawner",
        "tag": {
          "id": "minecraft:mob_spawner",
          "Delay": 200,
          "MinSpawnDelay": 240,
          "MaxSpawnDelay": 720,
          "SpawnCount": 2,
          "MaxNearbyEntities": 6,
          "RequiredPlayerRange": 14,
          "SpawnRange": 4,
          "SpawnData": {
            "entity": {
              "id": "minecraft:zombie"
            }
          },
          "SpawnPotentials": [
            {
              "weight": 1,
              "data": {
                "entity": {
                  "id": "minecraft:zombie"
                }
              }
            }
          ]
        }
      },
      {
        "char": ")",
        "block": "minecraft:spruce_door[facing=south,half=lower,hinge=left,open=false,powered=false]"
      },
      {
        "char": "*",
        "block": "minecraft:spruce_door[facing=south,half=upper,hinge=left,open=false,powered=false]"
      },
      {
        "char": "+",
        "block": "minecraft:spruce_planks"
      },
      {
        "char": ",",
        "block": "minecraft:stripped_dark_oak_log"
      },
      {
        "char": "-",
        "block": "minecraft:stripped_oak_log"
      },
      {
        "char": ".",
        "block": "minecraft:stripped_spruce_wood"
      },
      {
        "char": "/",
        "block": "minecraft:water_cauldron[level=2]"
      },
      {
        "char": "0",
        "block": "tfmg:asphalt"
      },
      {
        "char": "1",
        "block": "the_wasteland_reworked:decayed_planks"
      }
    ]
  }
}
