{
  "xsize": 16,
  "zsize": 16,
  "slices": [
    [
      "+++---+---+--+--",
      "+++-+-----++----",
      "./+------++-----",
      "+++----+--+---+-",
      "+++0000000+00000",
      "+/++------+-----",
      "+++-----+-+----+",
      "+++---+---+--+--",
      "+./-+-----/+----",
      "+++------++-----",
      "+++++++./+++++++",
      "++/+++++++./++++",
      "+++++/+++++++./+",
      "                ",
      "                ",
      "                "
    ],
    [
      "   2 8, 14 $',%(",
      "    ,1 72  , !& ",
      "   47 58 ,  )$ *",
      "   5 36,47 '* ,!",
      "                ",
      "   ,2 83 1, $' %",
      "   8 61 ,2 *% !,",
      "    47,58  ! ,$ ",
      "   2, 36 4 ,'* (",
      "   3 14 2, %( &)",
      "                ",
      "                ",
      "                ",
      "                ",
      "                ",
      "                "
    ],
    [
      "                ",
      "                ",
      "                ",
      "                ",
      "                ",
      "                ",
      "                ",
      "                ",
      "                ",
      "                ",
      "                ",
      "                ",
      "                ",
      "                ",
      "                ",
      "                "
    ],
    [
      "                ",
      "                ",
      "                ",
      "                ",
      "                ",
      "                ",
      "                ",
      "                ",
      "                ",
      "                ",
      "                ",
      "                ",
      "                ",
      "                ",
      "                ",
      "                "
    ],
    [
      "                ",
      "                ",
      "                ",
      "                ",
      "                ",
      "                ",
      "                ",
      "                ",
      "                ",
      "                ",
      "                ",
      "                ",
      "                ",
      "                ",
      "                ",
      "                "
    ],
    [
      "                ",
      "                ",
      "                ",
      "                ",
      "                ",
      "                ",
      "                ",
      "                ",
      "                ",
      "                ",
      "                ",
      "                ",
      "                ",
      "                ",
      "                ",
      "                "
    ]
  ],
  "palette": {
    "palette": [
      {
        "char": "!",
        "block": "minecraft:carrots[age=0]"
      },
      {
        "char": "$",
        "block": "minecraft:carrots[age=1]"
      },
      {
        "char": "%",
        "block": "minecraft:carrots[age=2]"
      },
      {
        "char": "&",
        "block": "minecraft:carrots[age=3]"
      },
      {
        "char": "'",
        "block": "minecraft:carrots[age=4]"
      },
      {
        "char": "(",
        "block": "minecraft:carrots[age=5]"
      },
      {
        "char": ")",
        "block": "minecraft:carrots[age=6]"
      },
      {
        "char": "*",
        "block": "minecraft:carrots[age=7]"
      },
      {
        "char": "+",
        "block": "minecraft:coarse_dirt"
      },
      {
        "char": ",",
        "block": "minecraft:dead_bush"
      },
      {
        "char": "-",
        "block": "minecraft:farmland[moisture=7]"
      },
      {
        "char": ".",
        "block": "minecraft:gravel"
      },
      {
        "char": "/",
        "block": "minecraft:podzol"
      },
      {
        "char": "0",
        "block": "minecraft:water[level=0]"
      },
      {
        "char": "1",
        "block": "minecraft:wheat[age=0]"
      },
      {
        "char": "2",
        "block": "minecraft:wheat[age=1]"
      },
      {
        "char": "3",
        "block": "minecraft:wheat[age=2]"
      },
      {
        "char": "4",
        "block": "minecraft:wheat[age=3]"
      },
      {
        "char": "5",
        "block": "minecraft:wheat[age=4]"
      },
      {
        "char": "6",
        "block": "minecraft:wheat[age=5]"
      },
      {
        "char": "7",
        "block": "minecraft:wheat[age=6]"
      },
      {
        "char": "8",
        "block": "minecraft:wheat[age=7]"
      }
    ]
  }
}
