{
  "xsize": 16,
  "zsize": 16,
  "slices": [
    [
      "---&---(----&---",
      "&----&---(----&-",
      "--&----&---(----",
      "----&----&---(--",
      "-&----&----&---(",
      "---&----&----&--",
      "(----&----&----&",
      "--(----&----&---",
      "&---(----&----&-",
      "--&---(----&----",
      "----&---(----&--",
      "-&----&---(----&",
      "---&----&---(---",
      "&----&----&---(-",
      "--&----&----&---",
      "----&----&----&-"
    ],
    [
      "   4444444444444",
      "   4444444444444",
      "   4444444444444",
      "   4444444444444",
      "   4444444444444",
      "   4444444444444",
      "   4444444444444",
      "   4444444444444",
      "   4444444444444",
      "   4444444444444",
      "   4444444444444",
      "   4444444444444",
      "                ",
      "                ",
      "                ",
      "                "
    ],
    [
      "   '555505555555",
      "   '         5  ",
      "   ' +   $   5 +",
      "   ' ,   %   5 ,",
      "   '         5  ",
      "   '         .  ",
      "   '         5  ",
      "   ' )       5 )",
      "   ' *    !  5 *",
      "   '         5  ",
      "   '         5  ",
      "   ''''''''01'''",
      "                ",
      "                ",
      "                ",
      "                "
    ],
    [
      "   '555525555555",
      "   '         5  ",
      "   '         5  ",
      "   '         5  ",
      "   '         5  ",
      "   '         /  ",
      "   '         5  ",
      "   '         5  ",
      "   '         5  ",
      "   '         5  ",
      "   '         5  ",
      "   ''''''''23'''",
      "                ",
      "                ",
      "                ",
      "                "
    ],
    [
      "   '555555555555",
      "   '         5  ",
      "   '         5  ",
      "   '         5  ",
      "   '         5  ",
      "   '         5  ",
      "   '         5  ",
      "   '         5  ",
      "   '         5  ",
      "   '         5  ",
      "   '         5  ",
      "   '''''''''''''",
      "                ",
      "                ",
      "                ",
      "                "
    ],
    [
      "   '555555555555",
      "   '         5  ",
      "   '         5  ",
      "   '         5  ",
      "   '         5  ",
      "   '         5  ",
      "   '         5  ",
      "   '         5  ",
      "   '         5  ",
      "   '         5  ",
      "   '         5  ",
      "   '''''''''''''",
      "                ",
      "                ",
      "                ",
      "                "
    ]
  ],
  "palette": {
    "palette": [
      {
        "char": "!",
        "block": "minecraft:bookshelf"
      },
      {
        "char": "$",
        "block": "minecraft:brown_bed[facing=south,occupied=false,part=foot]"
      },
      {
        "char": "%",
        "block": "minecraft:brown_bed[facing=south,occupied=false,part=head]"
      },
      {
        "char": "&",
        "block": "minecraft:coarse_dirt"
      },
      {
        "char": "'",
        "block": "minecraft:dark_oak_planks"
      },
      {
        "char": "(",
        "block": "minecraft:gravel"
      },
      {
        "char": ")",
        "block": "minecraft:gray_bed[facing=south,occupied=false,part=foot]"
      },
      {
        "char": "*",
        "block": "minecraft:gray_bed[facing=south,occupied=false,part=head]"
      },
      {
        "char": "+",
        "block": "minecraft:green_bed[facing=south,occupied=false,part=foot]"
      },
      {
        "char": ",",
        "block": "minecraft:green_bed[facing=south,occupied=false,part=head]"
      },
      {
        "char": "-",
        "block": "minecraft:podzol"
      },
      {
        "char": ".",
        "block": "minecraft:spruce_door[facing=east,half=lower,hinge=left,open=false,powered=false]"
      },
      {
        "char": "/",
        "block": "minecraft:spruce_door[facing=east,half=upper,hinge=left,open=false,powered=false]"
      },
      {
        "char": "0",
        "block": "minecraft:spruce_door[facing=south,half=lower,hinge=left,open=false,powered=false]"
      },
      {
        "char": "1",
        "block": "minecraft:spruce_door[facing=south,half=lower,hinge=right,open=false,powered=false]"
      },
      {
        "char": "2",
        "block": "minecraft:spruce_door[facing=south,half=upper,hinge=left,open=false,powered=false]"
      },
      {
        "char": "3",
        "block": "minecraft:spruce_door[facing=south,half=upper,hinge=right,open=false,powered=false]"
      },
      {
        "char": "4",
        "block": "minecraft:spruce_planks"
      },
      {
        "char": "5",
        "block": "minecraft:stripped_dark_oak_wood"
      }
    ]
  }
}
