{
  "xsize": 16,
  "zsize": 16,
  "slices": [
    [
      "*&''''''''''''''",
      "*&''''''''''''''",
      "*&''''''''''''''",
      "*&''''''''''''''",
      ")&''''''''''''''",
      ")&''''''''''''''",
      ")&''''''''''''''",
      ")&''''''''''''''",
      ")&''''''''''''''",
      ")&''''''''''''''",
      "/&''''''''''''''",
      "/&''''''''''''''",
      "/&''''''''''''''",
      "/&&&&&&&&&&&&&&&",
      "////////////))))",
      "////////////))))"
    ],
    [
      "   6666666666666",
      "   6666666666666",
      "   6666666666666",
      "   6666666666666",
      "   6666666666666",
      "   6666666666666",
      "   6666666666666",
      "   6666666666666",
      "   6666666666666",
      "   6666666666666",
      "   6666666666666",
      "   6666666666666",
      "                ",
      "                ",
      "                ",
      "                "
    ],
    [
      "   (777727777777",
      "   (         7  ",
      "   ('-   $   7 -",
      "   ( .:  %   7 .",
      "   (      8  7  ",
      "   (  988: : 0  ",
      "   (9'89 ''  7  ",
      "   (99 8     7 +",
      "   ( ,    !  7 ,",
      "   (         7  ",
      "   (         7  ",
      "   ((((((((23(((",
      "                ",
      "                ",
      "                ",
      "                "
    ],
    [
      "   (777747777777",
      "   (         7  ",
      "   (         7  ",
      "   (         7  ",
      "   (      :  7  ",
      "   (    8    1  ",
      "   (         7  ",
      "   (         7  ",
      "   (         7  ",
      "   (         7  ",
      "   (         7  ",
      "   ((((((((45(((",
      "                ",
      "                ",
      "                ",
      "                "
    ],
    [
      "   (777777777777",
      "   (         7  ",
      "   (         7  ",
      "   (         7  ",
      "   (         7  ",
      "   (         7  ",
      "   (         7  ",
      "   (         7  ",
      "   (         7  ",
      "   (         7  ",
      "   (         7  ",
      "   (((((((((((((",
      "                ",
      "                ",
      "                ",
      "                "
    ],
    [
      "   (777777777777",
      "   (         7  ",
      "   (         7  ",
      "   (         7  ",
      "   (         7  ",
      "   (         7  ",
      "   (         7  ",
      "   (         7  ",
      "   (         7  ",
      "   (         7  ",
      "   (         7  ",
      "   (((((((((((((",
      "                ",
      "                ",
      "                ",
      "                "
    ]
  ],
  "palette": {
    "palette": [
      {
        "char": "!",
        "block": "minecraft:bookshelf"
      },
      {
        "char": "$",
        "block": "minecraft:brown_bed[facing=south,occupied=false,part=foot]"
      },
      {
        "char": "%",
        "block": "minecraft:brown_bed[facing=south,occupied=false,part=head]"
      },
      {
        "char": "&",
        "block": "minecraft:coarse_dirt"
      },
      {
        "char": "'",
        "block": "minecraft:cobblestone"
      },
      {
        "char": "(",
        "block": "minecraft:dark_oak_planks"
      },
      {
        "char": ")",
        "block": "minecraft:dirt_path"
      },
      {
        "char": "*",
        "block": "minecraft:gravel"
      },
      {
        "char": "+",
        "block": "minecraft:gray_bed[facing=south,occupied=false,part=foot]"
      },
      {
        "char": ",",
        "block": "minecraft:gray_bed[facing=south,occupied=false,part=head]"
      },
      {
        "char": "-",
        "block": "minecraft:green_bed[facing=south,occupied=false,part=foot]"
      },
      {
        "char": ".",
        "block": "minecraft:green_bed[facing=south,occupied=false,part=head]"
      },
      {
        "char": "/",
        "block": "minecraft:rooted_dirt"
      },
      {
        "char": "0",
        "block": "minecraft:spruce_door[facing=east,half=lower,hinge=left,open=false,powered=false]"
      },
      {
        "char": "1",
        "block": "minecraft:spruce_door[facing=east,half=upper,hinge=left,open=false,powered=false]"
      },
      {
        "char": "2",
        "block": "minecraft:spruce_door[facing=south,half=lower,hinge=left,open=false,powered=false]"
      },
      {
        "char": "3",
        "block": "minecraft:spruce_door[facing=south,half=lower,hinge=right,open=false,powered=false]"
      },
      {
        "char": "4",
        "block": "minecraft:spruce_door[facing=south,half=upper,hinge=left,open=false,powered=false]"
      },
      {
        "char": "5",
        "block": "minecraft:spruce_door[facing=south,half=upper,hinge=right,open=false,powered=false]"
      },
      {
        "char": "6",
        "block": "minecraft:spruce_planks"
      },
      {
        "char": "7",
        "block": "minecraft:stripped_dark_oak_wood"
      },
      {
        "char": "8",
        "block": "minecraft:stripped_spruce_wood"
      },
      {
        "char": "9",
        "block": "minecraft:weathered_cut_copper"
      },
      {
        "char": ":",
        "block": "the_wasteland_reworked:decayed_planks"
      }
    ]
  }
}
