{
  "xsize": 16,
  "zsize": 16,
  "slices": [
    [
      "****%****%***(**",
      "*%****%****%***(",
      "***%****%****%**",
      "(****%****%****%",
      "**(****%****%***",
      "%***(****%****%*",
      "**%***(****%****",
      "****%***(****%**",
      "*%****%***(****%",
      "***%****%***(***",
      "%****%****%***(*",
      "**%****%****%***",
      "****%****%****%*",
      "*(****%****%****",
      "***(****%****%**",
      "*%***(****%****%"
    ],
    [
      "    ))))))))))))",
      "    ))))))))))))",
      "    ))))))))))))",
      "                ",
      "    333333333333",
      "                ",
      "    333333333333",
      "   0000000000000",
      "   0000000000000",
      "   0000000000000",
      "   0000000000000",
      "   0000000000000",
      "   0000000000000",
      "   0000000000000",
      "   0000000000000",
      "   0000000000000"
    ],
    [
      "    0       4   ",
      "    0       4   ",
      "    000000000.00",
      "                ",
      "     33333333333",
      "                ",
      "     33333333333",
      "   &&&&&&&&&&&&&",
      "   &           2",
      "   &           2",
      "   & + '       2",
      "   &      $    2",
      "   &           ,",
      "   &           2",
      "   & 1111111   2",
      "   &           2"
    ],
    [
      "    0       4   ",
      "    0       4   ",
      "    000000000/00",
      "                ",
      "      3333333333",
      "                ",
      "      3333333333",
      "   &&!!&&&&&&&&&",
      "   &           2",
      "   &           2",
      "   &           2",
      "   &           2",
      "   !           -",
      "   !           2",
      "   &           2",
      "   &           2"
    ],
    [
      "    0       4   ",
      "    0       4   ",
      "    000000000000",
      "                ",
      "                ",
      "                ",
      "                ",
      "   &&!!&&&&&&&&&",
      "   &           2",
      "   &           2",
      "   &           2",
      "   &           2",
      "   !           2",
      "   !           2",
      "   &           2",
      "   &           2"
    ],
    [
      "    0       4   ",
      "    0       4   ",
      "    000000000000",
      "                ",
      "                ",
      "                ",
      "                ",
      "   &&&&&&&&&&&&&",
      "   &           2",
      "   &           2",
      "   &           2",
      "   &           2",
      "   &           2",
      "   &           2",
      "   &           2",
      "   &           2"
    ]
  ],
  "palette": {
    "palette": [
      {
        "char": "!",
        "block": "create:framed_glass"
      },
      {
        "char": "$",
        "block": "minecraft:barrel[facing=up,open=false]"
      },
      {
        "char": "%",
        "block": "minecraft:coarse_dirt"
      },
      {
        "char": "&",
        "block": "minecraft:dark_oak_planks"
      },
      {
        "char": "'",
        "block": "kubejs:ruined_furnace[facing=south]"
      },
      {
        "char": "(",
        "block": "minecraft:gravel"
      },
      {
        "char": ")",
        "block": "minecraft:oak_planks"
      },
      {
        "char": "*",
        "block": "minecraft:podzol"
      },
      {
        "char": "+",
        "block": "kubejs:ruined_smoker[facing=south]"
      },
      {
        "char": ",",
        "block": "minecraft:spruce_door[facing=east,half=lower,hinge=left,open=false,powered=false]"
      },
      {
        "char": "-",
        "block": "minecraft:spruce_door[facing=east,half=upper,hinge=left,open=false,powered=false]"
      },
      {
        "char": ".",
        "block": "minecraft:spruce_door[facing=south,half=lower,hinge=left,open=false,powered=false]"
      },
      {
        "char": "/",
        "block": "minecraft:spruce_door[facing=south,half=upper,hinge=left,open=false,powered=false]"
      },
      {
        "char": "0",
        "block": "minecraft:spruce_planks"
      },
      {
        "char": "1",
        "block": "minecraft:spruce_slab[type=bottom,waterlogged=false]"
      },
      {
        "char": "2",
        "block": "minecraft:stripped_dark_oak_wood"
      },
      {
        "char": "3",
        "block": "minecraft:stripped_spruce_log[axis=x]"
      },
      {
        "char": "4",
        "block": "minecraft:stripped_spruce_wood"
      }
    ]
  }
}
