{
  "xsize": 16,
  "zsize": 16,
  "slices": [
    [
      ",,&,,,,&,,,(((((",
      ",,,,&,,,,&,(((((",
      ",(,,,,&,,,,(((+(",
      ",,,(,,,,&,,(((((",
      ",&,,,(,,,,&(((((",
      ",,,&,,,(,,,(((((",
      "&,,,,&,,,(,(((((",
      ",,&,,,,&,,,(((((",
      ",,,,&,,,,&,(((((",
      ",&,,,,&,,,,(((+(",
      ",,,&,,,,&,,(((((",
      "(,,,,&,,,,&(((((",
      ",,(,,,,&,,,(((((",
      "&,,)))))))))))))",
      ",,&)))))))))))))",
      ",,,)))))))))))))"
    ],
    [
      "*****      -----",
      "*****      -----",
      "*****      -----",
      "           -----",
      "44444444   -----",
      "           -----",
      "44444444   -----",
      "00000000   -----",
      "00000000   -----",
      "00000000   -----",
      "00000000   -----",
      "00000000   -----",
      "00000000        ",
      "00000000        ",
      "00000000        ",
      "00000000        "
    ],
    [
      "  % 0      3    ",
      "    0      3 444",
      "00000      3    ",
      "           3    ",
      "44444444   3    ",
      "           35555",
      "44444444   3    ",
      "''''''''   3 2  ",
      "       '   3 11 ",
      "       '   3    ",
      " 6  6  '   3    ",
      "       '   33333",
      "       '        ",
      "       .        ",
      " $  $  '        ",
      "       '        "
    ],
    [
      "    0      3    ",
      "    0      3    ",
      "00000      3    ",
      "           3    ",
      "44444444   3    ",
      "           35555",
      "44444444   3    ",
      "'!!'''''   3    ",
      "       '   3    ",
      "       !   3    ",
      "       !   3    ",
      "       '   33333",
      "       '        ",
      "       /        ",
      "       '        ",
      "       '        "
    ],
    [
      "    0      3    ",
      "    0      3    ",
      "00000      3    ",
      "           3    ",
      "           3    ",
      "           35555",
      "           3    ",
      "'!!'''''   3    ",
      "       '   3    ",
      "       !   3    ",
      "       !   3    ",
      "       '   33333",
      "       '        ",
      "       '        ",
      "       '        ",
      "       '        "
    ],
    [
      "    0      3    ",
      "    0      3    ",
      "00000      3    ",
      "           3    ",
      "           3    ",
      "           35555",
      "           3    ",
      "''''''''   3    ",
      "       '   3    ",
      "       '   3    ",
      "       '   3    ",
      "       '   33333",
      "       '        ",
      "       '        ",
      "       '        ",
      "       '        "
    ]
  ],
  "palette": {
    "palette": [
      {
        "char": "!",
        "block": "create:framed_glass"
      },
      {
        "char": "$",
        "block": "minecraft:barrel[facing=up,open=false]"
      },
      {
        "char": "%",
        "block": "minecraft:chest[facing=west,type=single,waterlogged=false]",
        "tag": {
          "id": "minecraft:chest",
          "LootTable": "infinite_domain:chests/wasteland_office"
        }
      },
      {
        "char": "&",
        "block": "minecraft:coarse_dirt"
      },
      {
        "char": "'",
        "block": "minecraft:dark_oak_planks"
      },
      {
        "char": "(",
        "block": "minecraft:gravel"
      },
      {
        "char": ")",
        "block": "minecraft:mud"
      },
      {
        "char": "*",
        "block": "minecraft:oak_planks"
      },
      {
        "char": "+",
        "block": "minecraft:packed_mud"
      },
      {
        "char": ",",
        "block": "minecraft:podzol"
      },
      {
        "char": "-",
        "block": "minecraft:polished_deepslate"
      },
      {
        "char": ".",
        "block": "minecraft:spruce_door[facing=east,half=lower,hinge=left,open=false,powered=false]"
      },
      {
        "char": "/",
        "block": "minecraft:spruce_door[facing=east,half=upper,hinge=left,open=false,powered=false]"
      },
      {
        "char": "0",
        "block": "minecraft:spruce_planks"
      },
      {
        "char": "1",
        "block": "minecraft:spruce_slab[type=bottom,waterlogged=false]"
      },
      {
        "char": "2",
        "block": "minecraft:spruce_stairs[facing=south,half=bottom,shape=straight,waterlogged=false]"
      },
      {
        "char": "3",
        "block": "minecraft:stripped_dark_oak_wood"
      },
      {
        "char": "4",
        "block": "minecraft:stripped_spruce_log[axis=x]"
      },
      {
        "char": "5",
        "block": "minecraft:stripped_spruce_wood"
      },
      {
        "char": "6",
        "block": "minecraft:water_cauldron[level=3]"
      }
    ]
  }
}
