{
  "xsize": 16,
  "zsize": 16,
  "slices": [
    [
      "..,.,.....00///,",
      "..,......,00////",
      ",.1....,..00///,",
      "..,..,....00///,",
      "<<,<<<<<<<00///,",
      ".,1.....,.00///,",
      "..,...,...00///,",
      "..,.,.....00///,",
      "..,......,00///,",
      ",.,....,..00,,1,",
      "1,,,,,,,/100,,,,",
      ",,,1,,,,,,,/1,,,",
      ",,,,,,1,,,,,,,/1",
      "                ",
      "                ",
      "                "
    ],
    [
      " '  -9 72      :",
      "%(-47 58 -     :",
      "-  5 36-47     :",
      " *  9- 25  =   :",
      "               :",
      ")- 8 69 -2     :",
      " %  47-58      :",
      "+& 2- 36 4     :",
      "$ -3 94 2-     :",
      "-(  72 -3      :",
      "                ",
      "                ",
      "                ",
      "                ",
      "                ",
      "                "
    ],
    [
      "               ;",
      "               ;",
      "               ;",
      "               ;",
      "               ;",
      "               ;",
      "               ;",
      "               ;",
      "               ;",
      "               ;",
      "                ",
      "                ",
      "                ",
      "                ",
      "                ",
      "                "
    ],
    [
      "               ;",
      "               ;",
      "               !",
      "               !",
      "               ;",
      "               ;",
      "               ;",
      "               ;",
      "               ;",
      "               ;",
      "                ",
      "                ",
      "                ",
      "                ",
      "                ",
      "                "
    ],
    [
      "               ;",
      "               ;",
      "               !",
      "               !",
      "               ;",
      "               ;",
      "               ;",
      "               ;",
      "               ;",
      "               ;",
      "                ",
      "                ",
      "                ",
      "                ",
      "                ",
      "                "
    ],
    [
      "               ;",
      "               ;",
      "               ;",
      "               ;",
      "               ;",
      "               ;",
      "               ;",
      "               ;",
      "               ;",
      "               ;",
      "                ",
      "                ",
      "                ",
      "                ",
      "                ",
      "                "
    ]
  ],
  "palette": {
    "palette": [
      {
        "char": "!",
        "block": "create:framed_glass"
      },
      {
        "char": "$",
        "block": "minecraft:carrots[age=0]"
      },
      {
        "char": "%",
        "block": "minecraft:carrots[age=1]"
      },
      {
        "char": "&",
        "block": "minecraft:carrots[age=2]"
      },
      {
        "char": "'",
        "block": "minecraft:carrots[age=3]"
      },
      {
        "char": "(",
        "block": "minecraft:carrots[age=4]"
      },
      {
        "char": ")",
        "block": "minecraft:carrots[age=5]"
      },
      {
        "char": "*",
        "block": "minecraft:carrots[age=6]"
      },
      {
        "char": "+",
        "block": "minecraft:carrots[age=7]"
      },
      {
        "char": ",",
        "block": "minecraft:coarse_dirt"
      },
      {
        "char": "-",
        "block": "minecraft:dead_bush"
      },
      {
        "char": ".",
        "block": "minecraft:farmland[moisture=7]"
      },
      {
        "char": "/",
        "block": "minecraft:gravel"
      },
      {
        "char": "0",
        "block": "minecraft:mud"
      },
      {
        "char": "1",
        "block": "minecraft:podzol"
      },
      {
        "char": "2",
        "block": "minecraft:potatoes[age=0]"
      },
      {
        "char": "3",
        "block": "minecraft:potatoes[age=1]"
      },
      {
        "char": "4",
        "block": "minecraft:potatoes[age=2]"
      },
      {
        "char": "5",
        "block": "minecraft:potatoes[age=3]"
      },
      {
        "char": "6",
        "block": "minecraft:potatoes[age=4]"
      },
      {
        "char": "7",
        "block": "minecraft:potatoes[age=5]"
      },
      {
        "char": "8",
        "block": "minecraft:potatoes[age=6]"
      },
      {
        "char": "9",
        "block": "minecraft:potatoes[age=7]"
      },
      {
        "char": ":",
        "block": "minecraft:stone_bricks"
      },
      {
        "char": ";",
        "block": "minecraft:stripped_spruce_wood"
      },
      {
        "char": "<",
        "block": "minecraft:water[level=0]"
      },
      {
        "char": "=",
        "block": "wastelands:scrap_pile"
      }
    ]
  }
}
