{
  "xsize": 16,
  "zsize": 16,
  "slices": [
    [
      "'''+++++++++++,+",
      "'''+++++++++++++",
      "'''''''''&.*****",
      "'''''''''&.*****",
      "'''''''''&)*****",
      "'''''''''&)*****",
      "'''''''''&)*****",
      "'''''''''&)***,*",
      "'''''''''&)*****",
      "'''''''''&)*****",
      "'''''''''&&*****",
      "'''''''''&&*****",
      "'''''''''&&*****",
      "&&&&&&&&&&&*****",
      "))------&&&***,*",
      "))------&&&*****"
    ],
    [
      "11111111        ",
      "11111111        ",
      "11111111        ",
      "11111111 1111111",
      "11111111 1111111",
      "11111111 1111111",
      "11111111        ",
      "11111111        ",
      "11111111        ",
      "11111111        ",
      "11111111 1111111",
      "11111111 1111111",
      "         1111111",
      "                ",
      "                ",
      "                "
    ],
    [
      "222/222(        ",
      "       (        ",
      "   $   (        ",
      "   %   ( 1111111",
      "       ( 1111111",
      "       ( 1111111",
      "       (        ",
      "       (        ",
      "    !  (        ",
      "       (        ",
      "       ( 1111111",
      "(((((((( 1111111",
      "         1111111",
      "                ",
      "                ",
      "                "
    ],
    [
      "2220222(        ",
      "       (        ",
      "       (        ",
      "       ( 1111111",
      "       ( 1111111",
      "       ( 1111111",
      "       (        ",
      "       (        ",
      "       (        ",
      "       (        ",
      "       ( 1111111",
      "(((((((( 1111111",
      "         1111111",
      "                ",
      "                ",
      "                "
    ],
    [
      "2222222(        ",
      "       (        ",
      "       (        ",
      "       (        ",
      "       (  3    3",
      "       (        ",
      "       (        ",
      "       (        ",
      "       (        ",
      "       (        ",
      "       (        ",
      "((((((((        ",
      "                ",
      "                ",
      "                ",
      "                "
    ],
    [
      "2222222(        ",
      "       (        ",
      "       (        ",
      "       (        ",
      "       (  3    3",
      "       (        ",
      "       (        ",
      "       (        ",
      "       (        ",
      "       (        ",
      "       (        ",
      "((((((((        ",
      "                ",
      "                ",
      "                ",
      "                "
    ]
  ],
  "palette": {
    "palette": [
      {
        "char": "!",
        "block": "minecraft:barrel[facing=up,open=false]"
      },
      {
        "char": "$",
        "block": "minecraft:brown_bed[facing=south,occupied=false,part=foot]"
      },
      {
        "char": "%",
        "block": "minecraft:brown_bed[facing=south,occupied=false,part=head]"
      },
      {
        "char": "&",
        "block": "minecraft:coarse_dirt"
      },
      {
        "char": "'",
        "block": "minecraft:cobblestone"
      },
      {
        "char": "(",
        "block": "minecraft:dark_oak_planks"
      },
      {
        "char": ")",
        "block": "minecraft:dirt_path"
      },
      {
        "char": "*",
        "block": "minecraft:gravel"
      },
      {
        "char": "+",
        "block": "minecraft:mud"
      },
      {
        "char": ",",
        "block": "minecraft:packed_mud"
      },
      {
        "char": "-",
        "block": "minecraft:podzol"
      },
      {
        "char": ".",
        "block": "minecraft:rooted_dirt"
      },
      {
        "char": "/",
        "block": "minecraft:spruce_door[facing=south,half=lower,hinge=left,open=false,powered=false]"
      },
      {
        "char": "0",
        "block": "minecraft:spruce_door[facing=south,half=upper,hinge=left,open=false,powered=false]"
      },
      {
        "char": "1",
        "block": "minecraft:spruce_planks"
      },
      {
        "char": "2",
        "block": "minecraft:stripped_dark_oak_wood"
      },
      {
        "char": "3",
        "block": "minecraft:stripped_oak_log[axis=y]"
      }
    ]
  }
}
