{
  "xsize": 16,
  "zsize": 16,
  "slices": [
    [
      "                ",
      "                ",
      "                ",
      "                ",
      "                ",
      "                ",
      "                ",
      "''''''''        ",
      "       '    %%%%",
      "       '    %   ",
      "       '    %   ",
      "       '    %   ",
      "       '    %   ",
      "       '    %   ",
      "       '    %   ",
      "       '    %   "
    ],
    [
      "                ",
      "                ",
      "                ",
      "                ",
      "                ",
      "                ",
      "                ",
      "''''''''        ",
      "       '    %%%%",
      "       '    %   ",
      "       '    %   ",
      "       '    %   ",
      "       '    %   ",
      "       '    %   ",
      "       '    %   ",
      "       '    %   "
    ],
    [
      "                ",
      "                ",
      "                ",
      "                ",
      "                ",
      "                ",
      "                ",
      "''''''''        ",
      "       '    %%%%",
      "       '    %   ",
      "       '    %   ",
      "       '    %   ",
      "       '    %   ",
      "       '    %   ",
      "       '    %   ",
      "       '    %   "
    ],
    [
      "                ",
      "                ",
      "                ",
      "                ",
      "                ",
      "                ",
      "                ",
      "''''''''        ",
      "       '    %%%%",
      "       '    %   ",
      "       '    %$$$",
      "       '    %$$$",
      "       '    %$$$",
      "       '    %$$$",
      "       '    %$$$",
      "       '    %$$$"
    ],
    [
      "                ",
      "                ",
      "                ",
      "                ",
      "                ",
      "                ",
      "                ",
      "''''''''        ",
      "       '    %%%%",
      "       '    %   ",
      "       '    %   ",
      "       '    %   ",
      "       '    %   ",
      "       '    %   ",
      "       '    %   ",
      "       '    %   "
    ],
    [
      "                ",
      "                ",
      "                ",
      "                ",
      "                ",
      "                ",
      "       !        ",
      "'''''''!        ",
      "&&&&&&&!    %%%%",
      "&&&&&&&!    %   ",
      "&&&&&&&!    %   ",
      "&&&&&&&!    %   ",
      "&&&&&&&!    %   ",
      "&&&&&&&!    %   ",
      "&&&&&&&!    %   ",
      "&&&&&&&!    %   "
    ]
  ],
  "palette": {
    "palette": [
      {
        "char": "!",
        "block": "minecraft:dark_oak_stairs[facing=west,half=bottom,shape=straight,waterlogged=false]"
      },
      {
        "char": "$",
        "block": "minecraft:spruce_planks"
      },
      {
        "char": "%",
        "block": "minecraft:stripped_dark_oak_log"
      },
      {
        "char": "&",
        "block": "minecraft:weathered_cut_copper"
      },
      {
        "char": "'",
        "block": "the_wasteland_reworked:decayed_planks"
      }
    ]
  }
}
