{
  "xsize": 16,
  "zsize": 16,
  "slices": [
    [
      "       !        ",
      "       !        ",
      "       !        ",
      "       !        ",
      "       !  %    %",
      "       !        ",
      "       !        ",
      "       !        ",
      "       !        ",
      "       !        ",
      "       !        ",
      "!!!!!!!!        ",
      "                ",
      "                ",
      "                ",
      "                "
    ],
    [
      "       !        ",
      "       !        ",
      "       !        ",
      "       !        ",
      "       !  %    %",
      "       !        ",
      "       !        ",
      "       !        ",
      "       !        ",
      "       !        ",
      "       !        ",
      "!!!!!!!!        ",
      "                ",
      "                ",
      "                ",
      "                "
    ],
    [
      "       !        ",
      "       !        ",
      "       !        ",
      "       ! $$$$$$$",
      "       ! $$$$$$$",
      "       ! $$$$$$$",
      "       ! $$$$$$$",
      "       ! $$$$$$$",
      "       ! $$$$$$$",
      "       ! $$$$$$$",
      "       ! $$$$$$$",
      "!!!!!!!! $$$$$$$",
      "         $$$$$$$",
      "         $$$$$$$",
      "         $$$$$$$",
      "         $$$$$$$"
    ],
    [
      "       &        ",
      "       &        ",
      "       &        ",
      "       &        ",
      "       &        ",
      "       &        ",
      "       &        ",
      "       &        ",
      "       &        ",
      "       &        ",
      "       &        ",
      "!!!!!!!&        ",
      "       &        ",
      "                ",
      "                ",
      "                "
    ],
    [
      "      &         ",
      "      &         ",
      "      &         ",
      "      &         ",
      "      &         ",
      "      &         ",
      "      &         ",
      "      &         ",
      "      &         ",
      "      &         ",
      "      &         ",
      "!!!!!!&         ",
      "      &         ",
      "                ",
      "                ",
      "                "
    ],
    [
      "     &          ",
      "     &          ",
      "     &          ",
      "     &          ",
      "     &          ",
      "     &          ",
      "     &          ",
      "     &          ",
      "     &          ",
      "     &          ",
      "     &          ",
      "!!!!!&          ",
      "     &          ",
      "                ",
      "                ",
      "                "
    ]
  ],
  "palette": {
    "palette": [
      {
        "char": "!",
        "block": "minecraft:dark_oak_planks"
      },
      {
        "char": "$",
        "block": "minecraft:dark_oak_slab[type=top,waterlogged=false]"
      },
      {
        "char": "%",
        "block": "minecraft:stripped_oak_log[axis=y]"
      },
      {
        "char": "&",
        "block": "minecraft:weathered_cut_copper_stairs[facing=west,half=bottom,shape=straight,waterlogged=false]"
      }
    ]
  }
}
