{
  "xsize": 16,
  "zsize": 16,
  "slices": [
    [
      "''''''''''))$   ",
      "'''''''''')))   ",
      ")%))))$))))$)   ",
      ")))%))))$))))   ",
      ")$)))%))))$))   ",
      ")))$)))%))))$   ",
      "$))))$)))%)))   ",
      "))$))))$)))%)   ",
      "))))$))))$)))   ",
      ")$))))$))))$)   ",
      ")))$))))$))))   ",
      "%))))$))))$))   ",
      "))%))))$))))$   ",
      "%%%%%%%%%%%))   ",
      "%%%%%%%%%%%$)   ",
      "%%%%%%%%%%%))   "
    ],
    [
      "                ",
      "                ",
      "//////////      ",
      "//////////      ",
      "//////////      ",
      "//////////      ",
      "//////////      ",
      "//////////      ",
      "//////////      ",
      "//////////      ",
      "//////////      ",
      "//////////      ",
      "//////////      ",
      "//////////      ",
      "//////////      ",
      "//////////      "
    ],
    [
      "                ",
      "                ",
      "       (((      ",
      "         (      ",
      "         (      ",
      "         (      ",
      " *  &    (      ",
      "         (      ",
      "         (      ",
      "         (      ",
      "         (      ",
      "         (      ",
      "00-000000(      ",
      "         +      ",
      "         (      ",
      "  !   1  (      "
    ],
    [
      "                ",
      "                ",
      "       (((      ",
      "         (      ",
      "         (      ",
      "         (      ",
      "         (      ",
      "         (      ",
      "         (      ",
      "         (      ",
      "         (      ",
      "         (      ",
      "00.000000(      ",
      "         ,      ",
      "         (      ",
      "         (      "
    ],
    [
      "                ",
      "                ",
      "       (((      ",
      "         (      ",
      "         (      ",
      "         (      ",
      "         (      ",
      "         (      ",
      "         (      ",
      "         (      ",
      "         (      ",
      "         (      ",
      "000000000(      ",
      "         (      ",
      "         (      ",
      "         (      "
    ],
    [
      "                ",
      "                ",
      "       (((      ",
      "         (      ",
      "         (      ",
      "         (      ",
      "         (      ",
      "         (      ",
      "         (      ",
      "         (      ",
      "         (      ",
      "         (      ",
      "000000000(      ",
      "         (      ",
      "         (      ",
      "         (      "
    ]
  ],
  "palette": {
    "palette": [
      {
        "char": "!",
        "block": "immersiveengineering:metal_barrel"
      },
      {
        "char": "$",
        "block": "minecraft:coarse_dirt"
      },
      {
        "char": "%",
        "block": "minecraft:gravel"
      },
      {
        "char": "&",
        "block": "minecraft:grindstone[face=floor,facing=south]"
      },
      {
        "char": "'",
        "block": "minecraft:mud"
      },
      {
        "char": "(",
        "block": "minecraft:mud_bricks"
      },
      {
        "char": ")",
        "block": "minecraft:podzol"
      },
      {
        "char": "*",
        "block": "minecraft:smithing_table"
      },
      {
        "char": "+",
        "block": "minecraft:spruce_door[facing=east,half=lower,hinge=left,open=false,powered=false]"
      },
      {
        "char": ",",
        "block": "minecraft:spruce_door[facing=east,half=upper,hinge=left,open=false,powered=false]"
      },
      {
        "char": "-",
        "block": "minecraft:spruce_door[facing=south,half=lower,hinge=left,open=false,powered=false]"
      },
      {
        "char": ".",
        "block": "minecraft:spruce_door[facing=south,half=upper,hinge=left,open=false,powered=false]"
      },
      {
        "char": "/",
        "block": "minecraft:stone_bricks"
      },
      {
        "char": "0",
        "block": "minecraft:stripped_spruce_wood"
      },
      {
        "char": "1",
        "block": "the_wasteland_reworked:rusted_barrel"
      }
    ]
  }
}
