{
  "xsize": 16,
  "zsize": 16,
  "slices": [
    [
      "------2---000-02",
      "02-------2000---",
      "---02-----000---",
      "------02--000--2",
      "-2-------0000---",
      "----2-----0002--",
      "-------2--000--0",
      "-02-------2-----",
      "----02-------2--",
      "---///////-/////",
      "--2///////0/////",
      "---///////-/////",
      "2--///////-/////",
      "--0///////-/////",
      "---5555555-55555",
      "2--///////-/////"
    ],
    [
      "   1111111111111",
      "   1111111111111",
      "   1111111111111",
      "   1111111111111",
      "                ",
      "                ",
      "                ",
      "                ",
      "                ",
      "   8; 9< :  *% +",
      "   9 7: 8; (+ ),",
      "    =8 69  ) '* ",
      "   ;6 <7 =  %( &",
      "   < := ;6 +& ,'",
      "                ",
      "   69 7: 8  (+ )"
    ],
    [
      "   3   $ 4  . 4 ",
      "   3     4    4 ",
      "   3     4    4 ",
      "   3333333333333",
      "                ",
      "                ",
      "                ",
      "                ",
      "                ",
      "                ",
      "                ",
      "                ",
      "                ",
      "                ",
      "                ",
      "                "
    ],
    [
      "   3     4    4 ",
      "   3     4    4 ",
      "   3     4    4 ",
      "   33!!3333!!333",
      "                ",
      "                ",
      "                ",
      "                ",
      "                ",
      "                ",
      "                ",
      "                ",
      "                ",
      "                ",
      "                ",
      "                "
    ],
    [
      "   3     4    4 ",
      "   3     4    4 ",
      "   3     4    4 ",
      "   33!!3333!!333",
      "                ",
      "                ",
      "                ",
      "                ",
      "                ",
      "                ",
      "                ",
      "                ",
      "                ",
      "                ",
      "                ",
      "                "
    ],
    [
      "   3     4    4 ",
      "   3     4    4 ",
      "   3     4    4 ",
      "   3333333333333",
      "                ",
      "                ",
      "                ",
      "                ",
      "                ",
      "                ",
      "                ",
      "                ",
      "                ",
      "                ",
      "                ",
      "                "
    ]
  ],
  "palette": {
    "palette": [
      {
        "char": "!",
        "block": "create:framed_glass"
      },
      {
        "char": "$",
        "block": "minecraft:barrel[facing=up,open=false]"
      },
      {
        "char": "%",
        "block": "minecraft:carrots[age=0]"
      },
      {
        "char": "&",
        "block": "minecraft:carrots[age=1]"
      },
      {
        "char": "'",
        "block": "minecraft:carrots[age=2]"
      },
      {
        "char": "(",
        "block": "minecraft:carrots[age=3]"
      },
      {
        "char": ")",
        "block": "minecraft:carrots[age=4]"
      },
      {
        "char": "*",
        "block": "minecraft:carrots[age=5]"
      },
      {
        "char": "+",
        "block": "minecraft:carrots[age=6]"
      },
      {
        "char": ",",
        "block": "minecraft:carrots[age=7]"
      },
      {
        "char": "-",
        "block": "minecraft:coarse_dirt"
      },
      {
        "char": ".",
        "block": "kubejs:ruined_composter"
      },
      {
        "char": "/",
        "block": "minecraft:farmland[moisture=7]"
      },
      {
        "char": "0",
        "block": "minecraft:gravel"
      },
      {
        "char": "1",
        "block": "minecraft:oak_planks"
      },
      {
        "char": "2",
        "block": "minecraft:podzol"
      },
      {
        "char": "3",
        "block": "minecraft:spruce_planks"
      },
      {
        "char": "4",
        "block": "minecraft:stripped_spruce_wood"
      },
      {
        "char": "5",
        "block": "minecraft:water[level=0]"
      },
      {
        "char": "6",
        "block": "minecraft:wheat[age=0]"
      },
      {
        "char": "7",
        "block": "minecraft:wheat[age=1]"
      },
      {
        "char": "8",
        "block": "minecraft:wheat[age=2]"
      },
      {
        "char": "9",
        "block": "minecraft:wheat[age=3]"
      },
      {
        "char": ":",
        "block": "minecraft:wheat[age=4]"
      },
      {
        "char": ";",
        "block": "minecraft:wheat[age=5]"
      },
      {
        "char": "<",
        "block": "minecraft:wheat[age=6]"
      },
      {
        "char": "=",
        "block": "minecraft:wheat[age=7]"
      }
    ]
  }
}
