{
  "xsize": 16,
  "zsize": 16,
  "slices": [
    [
      "                ",
      "                ",
      "                ",
      "!!!!!!!!!!!!!!  ",
      "   &   &     !  ",
      "   &   &     !  ",
      "   &   &     !  ",
      "   &   &     !  ",
      "   &   &     !  ",
      "   &   &     !  ",
      "             !  ",
      "             !  ",
      "             !  ",
      "             !  ",
      "             !  ",
      "             !  "
    ],
    [
      "                ",
      "                ",
      "                ",
      "!!!!!!!!!!!!!!  ",
      "             !  ",
      "             !  ",
      "             !  ",
      "             !  ",
      "             !  ",
      "             !  ",
      "             !  ",
      "             !  ",
      "             !  ",
      "             !  ",
      "             !  ",
      "             !  "
    ],
    [
      "                ",
      "                ",
      "                ",
      "!!!!!!!!!!!!!!  ",
      "             !  ",
      "             !  ",
      "             !  ",
      "             !  ",
      "             !  ",
      "             !  ",
      "%%%     %%%%%!  ",
      "%%%     %%%%%!  ",
      "%%%     %%%%%!  ",
      "%%%     %%%%%!  ",
      "%%%     %%%%%!  ",
      "%%%     %%%%%!  "
    ],
    [
      "                ",
      "                ",
      "                ",
      "!!!!!!!!!!!!!!  ",
      "             !  ",
      "             !  ",
      "             !  ",
      "             !  ",
      "             !  ",
      "             !  ",
      "             !  ",
      "             !  ",
      "$$           !  ",
      "$$           !  ",
      "             !  ",
      "             !  "
    ],
    [
      "                ",
      "                ",
      "                ",
      "!!!!!!!!!!!!!!  ",
      "             !  ",
      "             !  ",
      "             !  ",
      "             !  ",
      "             !  ",
      "             !  ",
      "             !  ",
      "             !  ",
      "$$           !  ",
      "$$           !  ",
      "             !  ",
      "             !  "
    ],
    [
      "                ",
      "                ",
      "                ",
      "!!!!!!!!!!!!!!  ",
      "             !  ",
      "             !  ",
      "             !  ",
      "             !  ",
      "             !  ",
      "             !  ",
      "             !  ",
      "             !  ",
      "             !  ",
      "             !  ",
      "             !  ",
      "             !  "
    ]
  ],
  "palette": {
    "palette": [
      {
        "char": "!",
        "block": "minecraft:dark_oak_planks"
      },
      {
        "char": "$",
        "block": "minecraft:hay_block"
      },
      {
        "char": "%",
        "block": "minecraft:spruce_planks"
      },
      {
        "char": "&",
        "block": "minecraft:stripped_dark_oak_wood"
      }
    ]
  }
}
