{
  "xsize": 16,
  "zsize": 16,
  "slices": [
    [
      "&&(((%((((%((((%",
      "&&&((((%((((%(((",
      "&&((&((((%((((%(",
      "&&%(((&((((%((((",
      "&&((%(((&((((%((",
      "&&((((%(((&((((%",
      "&&(%((((%(((&(((",
      "&&(((%((((%(((&(",
      "&&%((((%((((%(((",
      "&&((%((((%((((%(",
      "&&((((%((((%((((",
      "&&(&((((%((((%((",
      "&&(((&((((%((((%",
      "''''''''''''''''",
      "''''''''''''''''",
      "''''''''''''''''"
    ],
    [
      "))))))))))))))))",
      "))))))))))))))))",
      "))))))))))))))))",
      "))))))))))))))))",
      "))))))))))))))))",
      "))))))))))))))))",
      "))))))))))))))))",
      "))))))))))))))))",
      "))))))))))))))))",
      "))))))))))))))))",
      "))))))))))))))))",
      "))))))))))))))))",
      "                ",
      "                ",
      "                ",
      "                "
    ],
    [
      "     *    !    *",
      "//// 0         0",
      "     0         0",
      "     0         0",
      "     0         0",
      ",000000000,00000",
      "     0         0",
      "     0 $$$$$$  0",
      "  1  0 $$$$$$  0",
      "     0 $$$$$$  0",
      "     0         0",
      "................",
      "                ",
      "                ",
      "                ",
      "                "
    ],
    [
      "     +         +",
      "     0         0",
      "     0         0",
      "     0         0",
      "     0         0",
      "-000000000-00000",
      "     0         0",
      "     0 $$$$$$  0",
      "     0 $$$$$$  0",
      "     0 $$$$$$  0",
      "     0         0",
      "................",
      "                ",
      "                ",
      "                ",
      "                "
    ],
    [
      "     0         0",
      "     0         0",
      "     0         0",
      "     0         0",
      "     0         0",
      "0000000000000000",
      "     0         0",
      "     0         0",
      "     0         0",
      "     0         0",
      "     0         0",
      "................",
      "                ",
      "                ",
      "                ",
      "                "
    ],
    [
      "     0         0",
      "     0         0",
      "     0         0",
      "     0         0",
      "     0         0",
      "0000000000000000",
      "     0         0",
      "     0         0",
      "     0         0",
      "     0         0",
      "     0         0",
      "................",
      "                ",
      "                ",
      "                ",
      "                "
    ]
  ],
  "palette": {
    "palette": [
      {
        "char": "!",
        "block": "create:mechanical_press[facing=north]"
      },
      {
        "char": "$",
        "block": "immersiveengineering:crate"
      },
      {
        "char": "%",
        "block": "minecraft:coarse_dirt"
      },
      {
        "char": "&",
        "block": "minecraft:gravel"
      },
      {
        "char": "'",
        "block": "minecraft:mud"
      },
      {
        "char": "(",
        "block": "minecraft:podzol"
      },
      {
        "char": ")",
        "block": "minecraft:polished_deepslate"
      },
      {
        "char": "*",
        "block": "minecraft:spruce_door[facing=east,half=lower,hinge=left,open=false,powered=false]"
      },
      {
        "char": "+",
        "block": "minecraft:spruce_door[facing=east,half=upper,hinge=left,open=false,powered=false]"
      },
      {
        "char": ",",
        "block": "minecraft:spruce_door[facing=south,half=lower,hinge=left,open=false,powered=false]"
      },
      {
        "char": "-",
        "block": "minecraft:spruce_door[facing=south,half=upper,hinge=left,open=false,powered=false]"
      },
      {
        "char": ".",
        "block": "minecraft:stripped_dark_oak_wood"
      },
      {
        "char": "/",
        "block": "minecraft:stripped_spruce_log[axis=x]"
      },
      {
        "char": "0",
        "block": "minecraft:stripped_spruce_wood"
      },
      {
        "char": "1",
        "block": "the_wasteland_reworked:radio"
      }
    ]
  }
}
