{
  "xsize": 16,
  "zsize": 16,
  "slices": [
    [
      "((((((((((%%*   ",
      "((((((((((&%*   ",
      "&&&&&&&&&&&%*   ",
      "&&&&&&&&&&&%*   ",
      "&&&&&&&&&&&%+   ",
      "&&&&&&&&&&&%+   ",
      "&&&&&&&&&&&%+   ",
      "&&&&&&&&&&&%+   ",
      "&&&&&&&&&&&%+   ",
      "&&&&&&&&&&&%+   ",
      "&&&&&&&&&&&%+   ",
      "&&&&&&&&&&&%+   ",
      "&&&&&&&&&&&%+   ",
      "'''''''''''%+   ",
      "'''''''''''%+   ",
      "'''''''''''%+   "
    ],
    [
      "                ",
      "                ",
      "1111111111      ",
      "1111111111      ",
      "1111111111      ",
      "1111111111      ",
      "1111111111      ",
      "1111111111      ",
      "1111111111      ",
      "1111111111      ",
      "1111111111      ",
      "1111111111      ",
      "1111111111      ",
      "1111111111      ",
      "1111111111      ",
      "1111111111      "
    ],
    [
      "                ",
      "                ",
      "       )))      ",
      "         )      ",
      "         )      ",
      "         )      ",
      " $  !    )      ",
      "         )      ",
      "         )      ",
      "         )      ",
      "         )      ",
      "         )      ",
      "22/222222)      ",
      "         -      ",
      "         )      ",
      "  ,   3  )      "
    ],
    [
      "                ",
      "                ",
      "       )))      ",
      "         )      ",
      "         )      ",
      "         )      ",
      "         )      ",
      "         )      ",
      "         )      ",
      "         )      ",
      "         )      ",
      "         )      ",
      "220222222)      ",
      "         .      ",
      "         )      ",
      "         )      "
    ],
    [
      "                ",
      "                ",
      "       )))      ",
      "         )      ",
      "         )      ",
      "         )      ",
      "         )      ",
      "         )      ",
      "         )      ",
      "         )      ",
      "         )      ",
      "         )      ",
      "222222222)      ",
      "         )      ",
      "         )      ",
      "         )      "
    ],
    [
      "                ",
      "                ",
      "       )))      ",
      "         )      ",
      "         )      ",
      "         )      ",
      "         )      ",
      "         )      ",
      "         )      ",
      "         )      ",
      "         )      ",
      "         )      ",
      "222222222)      ",
      "         )      ",
      "         )      ",
      "         )      "
    ]
  ],
  "palette": {
    "palette": [
      {
        "char": "!",
        "block": "kubejs:ruined_grindstone[face=floor,facing=south]"
      },
      {
        "char": "$",
        "block": "kubejs:ruined_smithing_table"
      },
      {
        "char": "%",
        "block": "minecraft:coarse_dirt"
      },
      {
        "char": "&",
        "block": "minecraft:cobblestone"
      },
      {
        "char": "'",
        "block": "minecraft:gravel"
      },
      {
        "char": "(",
        "block": "minecraft:mud"
      },
      {
        "char": ")",
        "block": "minecraft:mud_bricks"
      },
      {
        "char": "*",
        "block": "minecraft:podzol"
      },
      {
        "char": "+",
        "block": "minecraft:rooted_dirt"
      },
      {
        "char": ",",
        "block": "minecraft:spawner",
        "tag": {
          "id": "minecraft:mob_spawner",
          "Delay": 320,
          "MinSpawnDelay": 240,
          "MaxSpawnDelay": 720,
          "SpawnCount": 2,
          "MaxNearbyEntities": 6,
          "RequiredPlayerRange": 14,
          "SpawnRange": 4,
          "SpawnData": {
            "entity": {
              "id": "the_wasteland_reworked:ghoul"
            }
          },
          "SpawnPotentials": [
            {
              "weight": 1,
              "data": {
                "entity": {
                  "id": "the_wasteland_reworked:ghoul"
                }
              }
            }
          ]
        }
      },
      {
        "char": "-",
        "block": "minecraft:spruce_door[facing=east,half=lower,hinge=left,open=false,powered=false]"
      },
      {
        "char": ".",
        "block": "minecraft:spruce_door[facing=east,half=upper,hinge=left,open=false,powered=false]"
      },
      {
        "char": "/",
        "block": "minecraft:spruce_door[facing=south,half=lower,hinge=left,open=false,powered=false]"
      },
      {
        "char": "0",
        "block": "minecraft:spruce_door[facing=south,half=upper,hinge=left,open=false,powered=false]"
      },
      {
        "char": "1",
        "block": "minecraft:stone_bricks"
      },
      {
        "char": "2",
        "block": "minecraft:stripped_spruce_wood"
      },
      {
        "char": "3",
        "block": "the_wasteland_reworked:rusted_barrel"
      }
    ]
  }
}
