{
  "xsize": 16,
  "zsize": 16,
  "slices": [
    [
      "(((((((((((''   ",
      "(((((((((((''   ",
      "((((((((((('+   ",
      "((((((((((('+   ",
      "((((((((((('+   ",
      "((((((((((('+   ",
      "((((((((((('+   ",
      "((((((((((('+   ",
      "((((((((((('-   ",
      "((((((((((('-   ",
      "((((((((((('-   ",
      "((((((((((('-   ",
      "((((((((((('-   ",
      ",,,,,,,,,,''-   ",
      ",,,,,,,,,,//-   ",
      ",,,,,,,,,,//-   "
    ],
    [
      "..........      ",
      "..........      ",
      "..........      ",
      "..........      ",
      "..........      ",
      "..........      ",
      "..........      ",
      "..........      ",
      "..........      ",
      "..........      ",
      "..........      ",
      "..........      ",
      "                ",
      "           5    ",
      "                ",
      "                "
    ],
    [
      " 2222222 4      ",
      "         4      ",
      "         4      ",
      "    %    4      ",
      "         4      ",
      "6666066664      ",
      "         4      ",
      "         4      ",
      "  $   !  )      ",
      "    3  & 4      ",
      "         4      ",
      "4444444444      ",
      "                ",
      "           5    ",
      "                ",
      "                "
    ],
    [
      "         4      ",
      "         4      ",
      "         4      ",
      "         4      ",
      "         4      ",
      "6666166664      ",
      "         4      ",
      "         4      ",
      "         *      ",
      "    3    4      ",
      "         4      ",
      "4444444444      ",
      "                ",
      "                ",
      "                ",
      "                "
    ],
    [
      "         4      ",
      "         4      ",
      "         4      ",
      "         4      ",
      "         4      ",
      "6666666664      ",
      "         4      ",
      "         4      ",
      "         4      ",
      "    3    4      ",
      "         4      ",
      "4444444444      ",
      "                ",
      "                ",
      "                ",
      "                "
    ],
    [
      "         4      ",
      "         4      ",
      "         4      ",
      "         4      ",
      "         4      ",
      "6666666664      ",
      "         4      ",
      "         4      ",
      "         4      ",
      "    3    4      ",
      "         4      ",
      "4444444444      ",
      "                ",
      "                ",
      "                ",
      "                "
    ]
  ],
  "palette": {
    "palette": [
      {
        "char": "!",
        "block": "immersiveengineering:metal_barrel"
      },
      {
        "char": "$",
        "block": "kubejs:ruined_cauldron"
      },
      {
        "char": "%",
        "block": "kubejs:ruined_stonecutter[facing=north]"
      },
      {
        "char": "&",
        "block": "minecraft:chest[facing=west,type=single,waterlogged=false]",
        "tag": {
          "id": "minecraft:chest",
          "LootTable": "infinite_domain:chests/wasteland_industrial"
        }
      },
      {
        "char": "'",
        "block": "minecraft:coarse_dirt"
      },
      {
        "char": "(",
        "block": "minecraft:cobblestone"
      },
      {
        "char": ")",
        "block": "minecraft:dark_oak_door[facing=east,half=lower,hinge=left,open=false,powered=false]"
      },
      {
        "char": "*",
        "block": "minecraft:dark_oak_door[facing=east,half=upper,hinge=left,open=false,powered=false]"
      },
      {
        "char": "+",
        "block": "minecraft:gravel"
      },
      {
        "char": ",",
        "block": "minecraft:mud"
      },
      {
        "char": "-",
        "block": "minecraft:podzol"
      },
      {
        "char": ".",
        "block": "minecraft:polished_deepslate"
      },
      {
        "char": "/",
        "block": "minecraft:rooted_dirt"
      },
      {
        "char": "0",
        "block": "minecraft:spruce_door[facing=south,half=lower,hinge=left,open=false,powered=false]"
      },
      {
        "char": "1",
        "block": "minecraft:spruce_door[facing=south,half=upper,hinge=left,open=false,powered=false]"
      },
      {
        "char": "2",
        "block": "minecraft:spruce_planks"
      },
      {
        "char": "3",
        "block": "minecraft:stripped_dark_oak_log[axis=y]"
      },
      {
        "char": "4",
        "block": "minecraft:stripped_dark_oak_wood"
      },
      {
        "char": "5",
        "block": "minecraft:stripped_spruce_log[axis=y]"
      },
      {
        "char": "6",
        "block": "minecraft:stripped_spruce_wood"
      }
    ]
  }
}
