{
  "xsize": 16,
  "zsize": 16,
  "slices": [
    [
      "--------------!!",
      "!!-2!!!!!!!2!!!!",
      "!!!!!-2!!!!!!!2!",
      "2!!!!!!!-2!!!!!!",
      "!!!2!!!!!!!-2!!!",
      "!!!!!!2!!!!!!!-2",
      "-2!!!!!!!2!!!!!!",
      "!!!-2!!!!!!!2!!!",
      "!!!!!!-2!!!!!!!2",
      "!2!!!!!!!-2!!!!!",
      "!!!!2!!!!!!!-2!!",
      "!!!!!!!2!!!!!!!-",
      "!-2!!!!!!!2!!!!!",
      "!!!!-2!!!!!!!2!!",
      "!!!!!!!-2!!!!!!!",
      "!!2!!!!!!!-2!!!!"
    ],
    [
      "!!!!!!!!!!!!!!  ",
      "!!!!!!!!!!!!!!  ",
      "!!!!!!!!!!!!!!  ",
      "!!!!!!!!!----!  ",
      "!!!!!!!!!----!  ",
      "!!!!!!!!!----!  ",
      "!!!!!!!!!----!  ",
      "!!!!!!!!!----!  ",
      "!!!!!!!!!!!!!!  ",
      "!!!!!!!!!!!!!!  ",
      "                ",
      "                ",
      "                ",
      "                ",
      "333333333333333 ",
      "333333333333333 "
    ],
    [
      "             ,  ",
      "         6   ,  ",
      "             ,  ",
      "         ----,  ",
      "44.     0----,  ",
      "         ----,  ",
      "         ----,  ",
      "         ----,  ",
      "             ,  ",
      ",,,,(),,,,,,,,  ",
      "                ",
      "                ",
      "                ",
      "                ",
      "555  $%   55555 ",
      "          5   5 "
    ],
    [
      "             ,  ",
      "             ,  ",
      "             ,  ",
      "         ----,  ",
      "44/     1----,  ",
      "         ----,  ",
      "         ----,  ",
      "         ----,  ",
      "             ,  ",
      ",,,,*+,,,,,,,,  ",
      "                ",
      "                ",
      "                ",
      "                ",
      "555  &'   55555 ",
      "          5   5 "
    ],
    [
      "             ,  ",
      "             ,  ",
      "             ,  ",
      "             ,  ",
      "444     44444,  ",
      "             ,  ",
      "           7 ,  ",
      "             ,  ",
      "             ,  ",
      ",,,,,,,,,,,,,,  ",
      "                ",
      "                ",
      "                ",
      "                ",
      "555       55555 ",
      "          5   5 "
    ],
    [
      "             ,  ",
      "             ,  ",
      "             ,  ",
      "             ,  ",
      "             ,  ",
      "             ,  ",
      "             ,  ",
      "             ,  ",
      "             ,  ",
      ",,,,,,,,,,,,,,  ",
      "                ",
      "                ",
      "                ",
      "                ",
      "555       55555 ",
      "          5   5 "
    ]
  ],
  "palette": {
    "palette": [
      {
        "char": "!",
        "block": "minecraft:coarse_dirt"
      },
      {
        "char": "$",
        "block": "minecraft:dark_oak_door[facing=north,half=lower,hinge=left,open=false,powered=false]"
      },
      {
        "char": "%",
        "block": "minecraft:dark_oak_door[facing=north,half=lower,hinge=right,open=false,powered=false]"
      },
      {
        "char": "&",
        "block": "minecraft:dark_oak_door[facing=north,half=upper,hinge=left,open=false,powered=false]"
      },
      {
        "char": "'",
        "block": "minecraft:dark_oak_door[facing=north,half=upper,hinge=right,open=false,powered=false]"
      },
      {
        "char": "(",
        "block": "minecraft:dark_oak_door[facing=south,half=lower,hinge=left,open=false,powered=false]"
      },
      {
        "char": ")",
        "block": "minecraft:dark_oak_door[facing=south,half=lower,hinge=right,open=false,powered=false]"
      },
      {
        "char": "*",
        "block": "minecraft:dark_oak_door[facing=south,half=upper,hinge=left,open=false,powered=false]"
      },
      {
        "char": "+",
        "block": "minecraft:dark_oak_door[facing=south,half=upper,hinge=right,open=false,powered=false]"
      },
      {
        "char": ",",
        "block": "minecraft:dark_oak_planks"
      },
      {
        "char": "-",
        "block": "minecraft:gravel"
      },
      {
        "char": ".",
        "block": "minecraft:oak_door[facing=east,half=lower,hinge=left,open=false,powered=false]"
      },
      {
        "char": "/",
        "block": "minecraft:oak_door[facing=east,half=upper,hinge=left,open=false,powered=false]"
      },
      {
        "char": "0",
        "block": "minecraft:oak_door[facing=west,half=lower,hinge=left,open=false,powered=false]"
      },
      {
        "char": "1",
        "block": "minecraft:oak_door[facing=west,half=upper,hinge=left,open=false,powered=false]"
      },
      {
        "char": "2",
        "block": "minecraft:podzol"
      },
      {
        "char": "3",
        "block": "minecraft:stone_bricks"
      },
      {
        "char": "4",
        "block": "minecraft:stripped_oak_log[axis=y]"
      },
      {
        "char": "5",
        "block": "minecraft:stripped_spruce_wood"
      },
      {
        "char": "6",
        "block": "minecraft:water_cauldron[level=3]"
      },
      {
        "char": "7",
        "block": "minecraft:weathered_cut_copper"
      }
    ]
  }
}
