{
  "xsize": 16,
  "zsize": 16,
  "slices": [
    [
      "%%------((((((((",
      "%%------((((((((",
      "%%%%%%%-(%%(((((",
      "&&&&&&%-(%&(((((",
      "&&&&&&%-(%&(((*(",
      "&&&&&&%-(%&(((((",
      "&&&&&&%%'%&(((((",
      "&&&&&&%%'%&(((((",
      "&&&&&&%%'%&(((((",
      "&&&%%%%%%%%%%%%%",
      "&&&%%%%%%%%%%%%%",
      "&&&%%%%%%%%%%%*%",
      "&&&%%%%%%%%%%%%%",
      "&&&%%%%%%%%%%%%%",
      "&&&&&&%+'%&(((((",
      "&&&&&&%+'%&((((("
    ],
    [
      "                ",
      "                ",
      "                ",
      "                ",
      ")))))      ,,,,,",
      ")))))      ,,,,,",
      ")))))      ,,,,,",
      ")))))      ,,,,,",
      ")))))      ,,,,,",
      ")))))      ,,,,,",
      ")))))      ,,,,,",
      ")))))      ,,,,,",
      ")))))      ,,,,,",
      ")))))      ,,,,,",
      ")))))      ,,,44",
      ")))))      ,,,44"
    ],
    [
      "                ",
      "                ",
      "                ",
      "                ",
      "33333      444  ",
      "    3      4    ",
      "    3      4    ",
      "    3      4    ",
      " $  3      4 555",
      "    3      4    ",
      "    /      4    ",
      "16663      4    ",
      "    3      4 555",
      "!!  3      4    ",
      "!.  3      4    ",
      "!!  3      4    "
    ],
    [
      "                ",
      "                ",
      "                ",
      "                ",
      "33333      444  ",
      "    3      4    ",
      "    3      4    ",
      "    3      4    ",
      "    3      4    ",
      "    3      4    ",
      "    0      4    ",
      "26663      4    ",
      "    3      4    ",
      "!!  3      4    ",
      "!!  3      4    ",
      "!!  3      4    "
    ],
    [
      "                ",
      "                ",
      "                ",
      "                ",
      "33333      444  ",
      "    3      4    ",
      "    3      4    ",
      "    3      4    ",
      "    3      4    ",
      "    3      4    ",
      "    3      4    ",
      "66663      4    ",
      "    3      4    ",
      "    3      4    ",
      "    3      4    ",
      "    3      4    "
    ],
    [
      "                ",
      "                ",
      "                ",
      "                ",
      "33333      444  ",
      "    3      4    ",
      "    3      4    ",
      "    3      4    ",
      "    3      4    ",
      "    3      4    ",
      "    3      4    ",
      "66663      4    ",
      "    3      4    ",
      "    3      4    ",
      "    3      4    ",
      "    3      4    "
    ]
  ],
  "palette": {
    "palette": [
      {
        "char": "!",
        "block": "immersiveengineering:crate"
      },
      {
        "char": "$",
        "block": "kubejs:ruined_cartography_table"
      },
      {
        "char": "%",
        "block": "minecraft:coarse_dirt"
      },
      {
        "char": "&",
        "block": "minecraft:cobblestone"
      },
      {
        "char": "'",
        "block": "minecraft:dirt_path"
      },
      {
        "char": "(",
        "block": "minecraft:gravel"
      },
      {
        "char": ")",
        "block": "minecraft:oak_planks"
      },
      {
        "char": "*",
        "block": "minecraft:packed_mud"
      },
      {
        "char": "+",
        "block": "minecraft:podzol"
      },
      {
        "char": ",",
        "block": "minecraft:polished_deepslate"
      },
      {
        "char": "-",
        "block": "minecraft:rooted_dirt"
      },
      {
        "char": ".",
        "block": "minecraft:spawner",
        "tag": {
          "id": "minecraft:mob_spawner",
          "Delay": 200,
          "MinSpawnDelay": 240,
          "MaxSpawnDelay": 720,
          "SpawnCount": 2,
          "MaxNearbyEntities": 6,
          "RequiredPlayerRange": 14,
          "SpawnRange": 4,
          "SpawnData": {
            "entity": {
              "id": "the_wasteland_reworked:ghoul"
            }
          },
          "SpawnPotentials": [
            {
              "weight": 1,
              "data": {
                "entity": {
                  "id": "the_wasteland_reworked:ghoul"
                }
              }
            }
          ]
        }
      },
      {
        "char": "/",
        "block": "minecraft:spruce_door[facing=east,half=lower,hinge=left,open=false,powered=false]"
      },
      {
        "char": "0",
        "block": "minecraft:spruce_door[facing=east,half=upper,hinge=left,open=false,powered=false]"
      },
      {
        "char": "1",
        "block": "minecraft:spruce_door[facing=south,half=lower,hinge=left,open=false,powered=false]"
      },
      {
        "char": "2",
        "block": "minecraft:spruce_door[facing=south,half=upper,hinge=left,open=false,powered=false]"
      },
      {
        "char": "3",
        "block": "minecraft:spruce_planks"
      },
      {
        "char": "4",
        "block": "minecraft:stripped_dark_oak_wood"
      },
      {
        "char": "5",
        "block": "minecraft:stripped_spruce_log[axis=x]"
      },
      {
        "char": "6",
        "block": "minecraft:stripped_spruce_wood"
      }
    ]
  }
}
