{
  "xsize": 16,
  "zsize": 16,
  "slices": [
    [
      "///////%%$//////",
      "/////%%$////////",
      "///%%$//////////",
      "/%%$////////////",
      "%$//////////////",
      "////////////////",
      "//////////////%%",
      "////////////%%$/",
      "//////////%%$///",
      "////////%%$/////",
      "//////%%$///////",
      "////%%$/////////",
      "//%%$///////////",
      "%%$/////////////",
      "$///////////////",
      "///////////////%"
    ],
    [
      "********    $$$$",
      "********    $$$$",
      "********    $$$$",
      "********    $$$$",
      "********    $$$$",
      "********    $$$$",
      "********    $$$$",
      "********    $$$$",
      "********    $$$$",
      "********    $$$$",
      "            $$$$",
      "            $$$$",
      "            $$$$",
      "            $$$$",
      "            $$$$",
      ",   ,   ,   $$$$"
    ],
    [
      "---(---0    +   ",
      "       0    +   ",
      "       0    +,,,",
      "       0    +,,,",
      "       0    +,,,",
      "       0    +,,,",
      ". '    0    +   ",
      "       0    +   ",
      "       0    +,,,",
      "00000000    +,,,",
      "            +,,,",
      "            +,,,",
      "            +   ",
      "            +   ",
      "            +   ",
      ",   ,   ,   ++++"
    ],
    [
      "---)---0    +   ",
      "       0    +   ",
      "       0    +,,,",
      "       0    +,,,",
      "       0    +,,,",
      "       0    +,,,",
      "       0    +   ",
      "  &    0    +   ",
      "       0    +,,,",
      "00!!0000    +,,,",
      "            +,,,",
      "            +,,,",
      "            +   ",
      "            +   ",
      "            +   ",
      ",   ,   ,   ++++"
    ],
    [
      "-------0    +   ",
      "       0    +   ",
      "       0    +,,,",
      "       0    +,,,",
      "       0    +,,,",
      "       0    +,,,",
      "       0    +   ",
      "       0    +   ",
      "       0    +,,,",
      "00!!0000    +,,,",
      "            +,,,",
      "            +,,,",
      "            +   ",
      "            +   ",
      "            +   ",
      "            ++++"
    ],
    [
      "-------0    +   ",
      "       0    +   ",
      "       0    +   ",
      "       0    +   ",
      "       0    +   ",
      "       0    +   ",
      "       0    +   ",
      "       0    +   ",
      "       0    +   ",
      "00000000    +   ",
      "            +   ",
      "            +   ",
      "            +   ",
      "            +   ",
      "            +   ",
      "            ++++"
    ]
  ],
  "palette": {
    "palette": [
      {
        "char": "!",
        "block": "create:framed_glass"
      },
      {
        "char": "$",
        "block": "minecraft:coarse_dirt"
      },
      {
        "char": "%",
        "block": "minecraft:gravel"
      },
      {
        "char": "&",
        "block": "minecraft:lever[face=wall,facing=south,powered=false]"
      },
      {
        "char": "'",
        "block": "minecraft:quartz_stairs[facing=north,half=bottom,shape=straight,waterlogged=false]"
      },
      {
        "char": "(",
        "block": "minecraft:spruce_door[facing=south,half=lower,hinge=left,open=false,powered=false]"
      },
      {
        "char": ")",
        "block": "minecraft:spruce_door[facing=south,half=upper,hinge=left,open=false,powered=false]"
      },
      {
        "char": "*",
        "block": "minecraft:spruce_planks"
      },
      {
        "char": "+",
        "block": "minecraft:stripped_dark_oak_log"
      },
      {
        "char": ",",
        "block": "minecraft:stripped_oak_log"
      },
      {
        "char": "-",
        "block": "minecraft:stripped_spruce_wood"
      },
      {
        "char": ".",
        "block": "kubejs:ruined_cauldron"
      },
      {
        "char": "/",
        "block": "tfmg:asphalt"
      },
      {
        "char": "0",
        "block": "the_wasteland_reworked:decayed_planks"
      }
    ]
  }
}
