{
  "xsize": 16,
  "zsize": 16,
  "slices": [
    [
      "             !  ",
      "             !  ",
      "             !  ",
      "             !  ",
      "             !  ",
      "             !  ",
      "             !  ",
      "             !  ",
      "             !  ",
      "!!!!!!!!!!!!!!  ",
      "                ",
      "                ",
      "                ",
      "                ",
      "&&&       &&&&& ",
      "              & "
    ],
    [
      "             !  ",
      "             !  ",
      "             !  ",
      "             !  ",
      "             !  ",
      "             !  ",
      "             !  ",
      "             !  ",
      "             !  ",
      "!!!!!!!!!!!!!!  ",
      "                ",
      "                ",
      "                ",
      "                ",
      "&&&&&&&&&&&&&&& ",
      "              & "
    ],
    [
      "%%%     %%%%%!  ",
      "%%%     %%%%%!  ",
      "%%%     %%%%%!  ",
      "%%%     %%%%%!  ",
      "%%%     %%%%%!  ",
      "%%%     %%%%%!  ",
      "%%%     %%%%%!  ",
      "%%%%%%%%%%%%%!  ",
      "%%%     %%%%%!  ",
      "!!!!!!!!!!!!!!  ",
      "                ",
      "                ",
      "                ",
      "''''''''''''''''",
      "              & ",
      "              & "
    ],
    [
      "             !  ",
      "             !  ",
      "             !  ",
      "             !  ",
      "         $$$$!  ",
      "         $$$$!  ",
      "         $$$$!  ",
      "             !  ",
      "             !  ",
      "!!!!!!!!!!!!!!  ",
      "                ",
      "                ",
      "                ",
      "                ",
      "''''''''''''''''",
      "              & "
    ],
    [
      "             !  ",
      "             !  ",
      "             !  ",
      "             !  ",
      "         $$$$!  ",
      "         $$$$!  ",
      "         $$$$!  ",
      "             !  ",
      "             !  ",
      "!!!!!!!!!!!!!!  ",
      "                ",
      "                ",
      "                ",
      "                ",
      "                ",
      "''''''''''''''''"
    ],
    [
      "             !  ",
      "             !  ",
      "             !  ",
      "             !  ",
      "             !  ",
      "             !  ",
      "             !  ",
      "             !  ",
      "             !  ",
      "!!!!!!!!!!!!!!  ",
      "                ",
      "                ",
      "                ",
      "                ",
      "                ",
      "                "
    ]
  ],
  "palette": {
    "palette": [
      {
        "char": "!",
        "block": "minecraft:dark_oak_planks"
      },
      {
        "char": "$",
        "block": "minecraft:hay_block"
      },
      {
        "char": "%",
        "block": "minecraft:spruce_planks"
      },
      {
        "char": "&",
        "block": "minecraft:stripped_spruce_wood"
      },
      {
        "char": "'",
        "block": "minecraft:weathered_cut_copper_stairs[facing=south,half=bottom,shape=straight,waterlogged=false]"
      }
    ]
  }
}
