{
  "xsize": 16,
  "zsize": 16,
  "slices": [
    [
      "                ",
      "&&,,,,&,,,,&,,,,",
      ",,,,,,,,,,,,,,,,",
      ",,,,,,,,,,,,,,&&",
      ",,,,,,,,,,,,&&$,",
      ",,,,,,,,,,&&$,,,",
      ",,,,,,,,&&$,,,,,",
      ",,,,,,&&$,,,,,,,",
      ",,,,&&$,,,,,,,,,",
      ",,&&$,,,,,,,,,,,",
      "&&$,,,,,,,,,,,,,",
      "$,,,,,,,,,,,,,,,",
      ",,,,,,,,,,,,,,,&",
      ",,,,,,,,,,,,,&&$",
      ",,,,,,,,,,,&&$,,",
      ",,,,,,,,,&&$,,,,"
    ],
    [
      "                ",
      "                ",
      "                ",
      "                ",
      "                ",
      "                ",
      "                ",
      "''''''''        ",
      "''''''''    $$$$",
      "''''''''    $$$$",
      "''''''''    $$$$",
      "''''''''    $$$$",
      "''''''''    $$$$",
      "''''''''    $$$$",
      "''''''''    $$$$",
      "''''''''    $$$$"
    ],
    [
      "                ",
      "                ",
      "                ",
      "                ",
      "                ",
      "                ",
      "                ",
      "--------        ",
      "       -    ))))",
      "       -    )   ",
      "%%%    -    )   ",
      "    .  -    )   ",
      "       -    )***",
      " (     -    )***",
      "       -    )***",
      "       -    )***"
    ],
    [
      "                ",
      "                ",
      "                ",
      "                ",
      "                ",
      "                ",
      "                ",
      "--!!----        ",
      "       -    ))))",
      "       -    )   ",
      "       -    )   ",
      "    +  -    )   ",
      "       -    )***",
      "       -    )***",
      "       -    )***",
      "       -    )***"
    ],
    [
      "                ",
      "                ",
      "                ",
      "                ",
      "                ",
      "                ",
      "                ",
      "--!!----        ",
      "       -    ))))",
      "       -    )   ",
      "       -    )   ",
      "       -    )   ",
      "       -    )***",
      "       -    )***",
      "       -    )***",
      "       -    )***"
    ],
    [
      "                ",
      "                ",
      "                ",
      "                ",
      "                ",
      "                ",
      "                ",
      "--------        ",
      "       -    ))))",
      "       -    )   ",
      "       -    )   ",
      "       -    )   ",
      "       -    )   ",
      "       -    )   ",
      "       -    )   ",
      "       -    )   "
    ]
  ],
  "palette": {
    "palette": [
      {
        "char": "!",
        "block": "create:framed_glass"
      },
      {
        "char": "$",
        "block": "minecraft:coarse_dirt"
      },
      {
        "char": "%",
        "block": "minecraft:dark_oak_stairs[facing=south,half=bottom,shape=straight,waterlogged=false]"
      },
      {
        "char": "&",
        "block": "minecraft:gravel"
      },
      {
        "char": "'",
        "block": "minecraft:spruce_planks"
      },
      {
        "char": "(",
        "block": "minecraft:spruce_slab[type=bottom,waterlogged=false]"
      },
      {
        "char": ")",
        "block": "minecraft:stripped_dark_oak_log"
      },
      {
        "char": "*",
        "block": "minecraft:stripped_oak_log"
      },
      {
        "char": "+",
        "block": "supplementaries:item_shelf"
      },
      {
        "char": ",",
        "block": "tfmg:asphalt"
      },
      {
        "char": "-",
        "block": "the_wasteland_reworked:decayed_planks"
      },
      {
        "char": ".",
        "block": "the_wasteland_reworked:radio"
      }
    ]
  }
}
