{
  "xsize": 16,
  "zsize": 16,
  "slices": [
    [
      "*,((((((;;;;;;((",
      "(((*,(((;;;;;;((",
      "((((((*,;;;;;;(,",
      "(,((((((;;***;((",
      "((((,(((((***,((",
      "(((((((,((***((*",
      "(*,(((((((***(((",
      "((((*,((((***,((",
      "(((((((*,(***(((",
      "((,(((((((***(((",
      "(((((,((((****,(",
      ",(((((((,(***(((",
      "((*,((((((***(((",
      "(((((*,(((***(,(",
      ",(((((((*,***(((",
      "(((,((((((***((("
    ],
    [
      "                ",
      "                ",
      "                ",
      "   +++++++++++++",
      "   +++++++++++++",
      "   +++++++++++++",
      "   +++++++++++++",
      "   +++++++++++++",
      "   +++++++++++++",
      "   +++++++++++++",
      "   +++++++++++++",
      "   +++++++++++++",
      "   +++++++++++++",
      "   +++++++++++++",
      "   +++++++++++++",
      "   +++++++++++++"
    ],
    [
      "                ",
      "                ",
      "                ",
      "   5555555/05555",
      "   5      9     ",
      "   5 $    9     ",
      "   5      - 66  ",
      "   5  8   9 7  )",
      "   5      9     ",
      "   5993999993999",
      "   5     9    9 ",
      "   5     9    9 ",
      "   5     -    - ",
      "   5 %   9 :  9'",
      "   5 &   9    9 ",
      "   5     9    9 "
    ],
    [
      "                ",
      "                ",
      "                ",
      "   55!!55512555!",
      "   5      9     ",
      "   5      9     ",
      "   !      .     ",
      "   !      9     ",
      "   5      9     ",
      "   5994999994999",
      "   5     9    9 ",
      "   5     9    9 ",
      "   5     .    . ",
      "   5     9    9 ",
      "   5     9    9 ",
      "   5     9    9 "
    ],
    [
      "                ",
      "                ",
      "                ",
      "   55!!55555555!",
      "   5      9     ",
      "   5      9     ",
      "   !      9     ",
      "   !      9     ",
      "   5      9     ",
      "   5999999999999",
      "   5     9    9 ",
      "   5     9    9 ",
      "   5     9    9 ",
      "   5     9    9 ",
      "   5     9    9 ",
      "   5     9    9 "
    ],
    [
      "                ",
      "                ",
      "                ",
      "   5555555555555",
      "   5      9     ",
      "   5      9     ",
      "   5      9     ",
      "   5      9     ",
      "   5      9     ",
      "   5999999999999",
      "   5     9    9 ",
      "   5     9    9 ",
      "   5     9    9 ",
      "   5     9    9 ",
      "   5     9    9 ",
      "   5     9    9 "
    ]
  ],
  "palette": {
    "palette": [
      {
        "char": "!",
        "block": "create:framed_glass"
      },
      {
        "char": "$",
        "block": "minecraft:bookshelf"
      },
      {
        "char": "%",
        "block": "minecraft:brown_bed[facing=south,occupied=false,part=foot]"
      },
      {
        "char": "&",
        "block": "minecraft:brown_bed[facing=south,occupied=false,part=head]"
      },
      {
        "char": "'",
        "block": "minecraft:chest[facing=east,type=single,waterlogged=false]",
        "tag": {
          "id": "minecraft:chest",
          "LootTable": "infinite_domain:chests/wasteland_home"
        }
      },
      {
        "char": "(",
        "block": "minecraft:coarse_dirt"
      },
      {
        "char": ")",
        "block": "kubejs:ruined_crafting_table"
      },
      {
        "char": "*",
        "block": "minecraft:gravel"
      },
      {
        "char": "+",
        "block": "minecraft:oak_planks"
      },
      {
        "char": ",",
        "block": "minecraft:podzol"
      },
      {
        "char": "-",
        "block": "minecraft:spruce_door[facing=east,half=lower,hinge=left,open=false,powered=false]"
      },
      {
        "char": ".",
        "block": "minecraft:spruce_door[facing=east,half=upper,hinge=left,open=false,powered=false]"
      },
      {
        "char": "/",
        "block": "minecraft:spruce_door[facing=north,half=lower,hinge=left,open=false,powered=false]"
      },
      {
        "char": "0",
        "block": "minecraft:spruce_door[facing=north,half=lower,hinge=right,open=false,powered=false]"
      },
      {
        "char": "1",
        "block": "minecraft:spruce_door[facing=north,half=upper,hinge=left,open=false,powered=false]"
      },
      {
        "char": "2",
        "block": "minecraft:spruce_door[facing=north,half=upper,hinge=right,open=false,powered=false]"
      },
      {
        "char": "3",
        "block": "minecraft:spruce_door[facing=south,half=lower,hinge=left,open=false,powered=false]"
      },
      {
        "char": "4",
        "block": "minecraft:spruce_door[facing=south,half=upper,hinge=left,open=false,powered=false]"
      },
      {
        "char": "5",
        "block": "minecraft:spruce_planks"
      },
      {
        "char": "6",
        "block": "minecraft:spruce_slab[type=bottom,waterlogged=false]"
      },
      {
        "char": "7",
        "block": "minecraft:spruce_stairs[facing=north,half=bottom,shape=straight,waterlogged=false]"
      },
      {
        "char": "8",
        "block": "minecraft:spruce_stairs[facing=south,half=bottom,shape=straight,waterlogged=false]"
      },
      {
        "char": "9",
        "block": "minecraft:stripped_spruce_wood"
      },
      {
        "char": ":",
        "block": "kubejs:ruined_cauldron"
      },
      {
        "char": ";",
        "block": "tfmg:asphalt"
      }
    ]
  }
}
