{
  "xsize": 16,
  "zsize": 16,
  "slices": [
    [
      "(((((('/*'(+++++",
      "(((((('/*'(+++++",
      "(((((('*/'(+++.+",
      "(((((('*/'(+++++",
      "'''''''*/'(+++++",
      "''''''''''(+++++",
      "((((((((('(+++++",
      "((((((((('(+++++",
      "((((((((('(+++++",
      "((((((((('(+++.+",
      "((((((((('(+++++",
      "((((((((('(+++++",
      "((((((((('(+++++",
      "(((,,,,,,,,,,,,,",
      "(((,,,,,,,,,,,,,",
      "(((,,,,,,,,,,,,,"
    ],
    [
      "-----      11177",
      "-----      11111",
      "-----      11111",
      "           11111",
      "88888888   11111",
      "           11111",
      "88888888   11111",
      "44444444   11111",
      "44444444   11111",
      "44444444   11111",
      "44444444   11111",
      "44444444   11111",
      "44444444        ",
      "44444444        ",
      "44444444        ",
      "44444444        "
    ],
    [
      "  & 4      7 707",
      "    4      7 888",
      "44444      7    ",
      "           7    ",
      "88888888   7    ",
      "           79999",
      "88888888   7    ",
      "))))))))   7 6  ",
      "       )   7 55 ",
      "       )   7    ",
      " $  $  )   7    ",
      "       )   77777",
      "       )        ",
      "       2        ",
      " %  %  )        ",
      "       )        "
    ],
    [
      "    4      7 7 7",
      "    4      7 707",
      "44444      7    ",
      "           7    ",
      "88888888   7    ",
      "           79999",
      "88888888   7    ",
      ")!!)))))   7    ",
      "       )   7    ",
      "       !   7    ",
      "       !   7    ",
      "       )   77777",
      "       )        ",
      "       3        ",
      "       )        ",
      "       )        "
    ],
    [
      "    4      7 7 7",
      "    4      7 7 7",
      "44444      7 707",
      "           7    ",
      "           7    ",
      "           79999",
      "           7    ",
      ")!!)))))   7    ",
      "       )   7    ",
      "       !   7    ",
      "       !   7    ",
      "       )   77777",
      "       )        ",
      "       )        ",
      "       )        ",
      "       )        "
    ],
    [
      "    4      7    ",
      "    4      7 7 7",
      "44444      7 7 7",
      "           7 707",
      "           7    ",
      "           79999",
      "           7    ",
      "))))))))   7    ",
      "       )   7    ",
      "       )   7    ",
      "       )   7    ",
      "       )   77777",
      "       )        ",
      "       )        ",
      "       )        ",
      "       )        "
    ]
  ],
  "palette": {
    "palette": [
      {
        "char": "!",
        "block": "create:framed_glass"
      },
      {
        "char": "$",
        "block": "kubejs:ruined_cauldron"
      },
      {
        "char": "%",
        "block": "minecraft:barrel[facing=up,open=false]"
      },
      {
        "char": "&",
        "block": "minecraft:chest[facing=west,type=single,waterlogged=false]",
        "tag": {
          "id": "minecraft:chest",
          "LootTable": "infinite_domain:chests/wasteland_office"
        }
      },
      {
        "char": "'",
        "block": "minecraft:coarse_dirt"
      },
      {
        "char": "(",
        "block": "minecraft:cobblestone"
      },
      {
        "char": ")",
        "block": "minecraft:dark_oak_planks"
      },
      {
        "char": "*",
        "block": "minecraft:dirt_path"
      },
      {
        "char": "+",
        "block": "minecraft:gravel"
      },
      {
        "char": ",",
        "block": "minecraft:mud"
      },
      {
        "char": "-",
        "block": "minecraft:oak_planks"
      },
      {
        "char": ".",
        "block": "minecraft:packed_mud"
      },
      {
        "char": "/",
        "block": "minecraft:podzol"
      },
      {
        "char": "0",
        "block": "minecraft:polished_andesite_stairs[facing=south,half=bottom,shape=straight,waterlogged=false]"
      },
      {
        "char": "1",
        "block": "minecraft:polished_deepslate"
      },
      {
        "char": "2",
        "block": "minecraft:spruce_door[facing=east,half=lower,hinge=left,open=false,powered=false]"
      },
      {
        "char": "3",
        "block": "minecraft:spruce_door[facing=east,half=upper,hinge=left,open=false,powered=false]"
      },
      {
        "char": "4",
        "block": "minecraft:spruce_planks"
      },
      {
        "char": "5",
        "block": "minecraft:spruce_slab[type=bottom,waterlogged=false]"
      },
      {
        "char": "6",
        "block": "minecraft:spruce_stairs[facing=south,half=bottom,shape=straight,waterlogged=false]"
      },
      {
        "char": "7",
        "block": "minecraft:stripped_dark_oak_wood"
      },
      {
        "char": "8",
        "block": "minecraft:stripped_spruce_log[axis=x]"
      },
      {
        "char": "9",
        "block": "minecraft:stripped_spruce_wood"
      }
    ]
  }
}
