{
  "xsize": 16,
  "zsize": 16,
  "slices": [
    [
      "'''+++++++++++,+",
      "'''+++++++++++++",
      "'''''''''&.*****",
      "'''''''''&.*****",
      "'''''''''&)*****",
      "'''''''''&)*****",
      "'''''''''&)*****",
      "'''''''''&)***,*",
      "'''''''''&)*****",
      "'''''''''&)*****",
      "'''''''''&&*****",
      "'''''''''&&*****",
      "'''''''''&&*****",
      "&&&&&&&&&&&*****",
      "))------&&&***,*",
      "))------&&&*****"
    ],
    [
      "22222222        ",
      "22222222        ",
      "22222222        ",
      "22222222 2222222",
      "22222222 2222222",
      "22222222 2222222",
      "22222222        ",
      "22222222        ",
      "22222222        ",
      "22222222        ",
      "22222222 2222222",
      "22222222 2222222",
      "         2222222",
      "                ",
      "                ",
      "                "
    ],
    [
      "3330333(        ",
      "       (        ",
      "   $   (        ",
      "   %   ( 2222222",
      "       ( 2222222",
      "   /   ( 2222222",
      "       (        ",
      "       (        ",
      "    !  (        ",
      "       (        ",
      "       ( 2222222",
      "(((((((( 2222222",
      "         2222222",
      "                ",
      "                ",
      "                "
    ],
    [
      "3331333(        ",
      "       (        ",
      "       (        ",
      "       ( 2222222",
      "       ( 2222222",
      "       ( 2222222",
      "       (        ",
      "       (        ",
      "       (        ",
      "       (        ",
      "       ( 2222222",
      "(((((((( 2222222",
      "         2222222",
      "                ",
      "                ",
      "                "
    ],
    [
      "3333333(        ",
      "       (        ",
      "       (        ",
      "       (        ",
      "       (  4    4",
      "       (        ",
      "       (        ",
      "       (        ",
      "       (        ",
      "       (        ",
      "       (        ",
      "((((((((        ",
      "                ",
      "                ",
      "                ",
      "                "
    ],
    [
      "3333333(        ",
      "       (        ",
      "       (        ",
      "       (        ",
      "       (  4    4",
      "       (        ",
      "       (        ",
      "       (        ",
      "       (        ",
      "       (        ",
      "       (        ",
      "((((((((        ",
      "                ",
      "                ",
      "                ",
      "                "
    ]
  ],
  "palette": {
    "palette": [
      {
        "char": "!",
        "block": "minecraft:barrel[facing=up,open=false]"
      },
      {
        "char": "$",
        "block": "minecraft:brown_bed[facing=south,occupied=false,part=foot]"
      },
      {
        "char": "%",
        "block": "minecraft:brown_bed[facing=south,occupied=false,part=head]"
      },
      {
        "char": "&",
        "block": "minecraft:coarse_dirt"
      },
      {
        "char": "'",
        "block": "minecraft:cobblestone"
      },
      {
        "char": "(",
        "block": "minecraft:dark_oak_planks"
      },
      {
        "char": ")",
        "block": "minecraft:dirt_path"
      },
      {
        "char": "*",
        "block": "minecraft:gravel"
      },
      {
        "char": "+",
        "block": "minecraft:mud"
      },
      {
        "char": ",",
        "block": "minecraft:packed_mud"
      },
      {
        "char": "-",
        "block": "minecraft:podzol"
      },
      {
        "char": ".",
        "block": "minecraft:rooted_dirt"
      },
      {
        "char": "/",
        "block": "minecraft:spawner",
        "tag": {
          "id": "minecraft:mob_spawner",
          "Delay": 280,
          "MinSpawnDelay": 240,
          "MaxSpawnDelay": 720,
          "SpawnCount": 2,
          "MaxNearbyEntities": 6,
          "RequiredPlayerRange": 14,
          "SpawnRange": 4,
          "SpawnData": {
            "entity": {
              "id": "minecraft:zombie"
            }
          },
          "SpawnPotentials": [
            {
              "weight": 1,
              "data": {
                "entity": {
                  "id": "minecraft:zombie"
                }
              }
            }
          ]
        }
      },
      {
        "char": "0",
        "block": "minecraft:spruce_door[facing=south,half=lower,hinge=left,open=false,powered=false]"
      },
      {
        "char": "1",
        "block": "minecraft:spruce_door[facing=south,half=upper,hinge=left,open=false,powered=false]"
      },
      {
        "char": "2",
        "block": "minecraft:spruce_planks"
      },
      {
        "char": "3",
        "block": "minecraft:stripped_dark_oak_wood"
      },
      {
        "char": "4",
        "block": "minecraft:stripped_oak_log[axis=y]"
      }
    ]
  }
}
