{
  "xsize": 16,
  "zsize": 16,
  "slices": [
    [
      "      &     '   ",
      "      &     '   ",
      "      &     '   ",
      "      &     '   ",
      "      &     '   ",
      "      &     '   ",
      "      &     '   ",
      "      &     '   ",
      "      &     '   ",
      "((((((&     '!!!",
      "      &     '!!!",
      "            '!!!",
      "            '!!!",
      "            '!!!",
      "            '   ",
      "            ''''"
    ],
    [
      "     &      '   ",
      "     &      '   ",
      "     &      '   ",
      "     &      '   ",
      "     &      '   ",
      "     &      '   ",
      "     &      '   ",
      "     &      '   ",
      "     &      '   ",
      "(((((&      '   ",
      "     &      '   ",
      "            '   ",
      "            '   ",
      "            '   ",
      "            '   ",
      "            ''''"
    ],
    [
      "    &       %$$$",
      "    &       %$$$",
      "    &       %$$$",
      "    &       %$$$",
      "    &       %$$$",
      "    &       %$$$",
      "    &       %$$$",
      "    &       %$$$",
      "    &       %$$$",
      "((((&       %$$$",
      "    &       %$$$",
      "            %$$$",
      "            %$$$",
      "            %$$$",
      "            %$$$",
      "            %$$$"
    ],
    [
      "   &         %  ",
      "   &         %  ",
      "   &         %  ",
      "   &         %  ",
      "   &         %  ",
      "   &         %  ",
      "   &         %  ",
      "   &         %  ",
      "   &         %  ",
      "(((&         %  ",
      "   &         %  ",
      "             %  ",
      "             %  ",
      "             %  ",
      "             %  ",
      "             %$$"
    ],
    [
      "  &           % ",
      "  &           % ",
      "  &           % ",
      "  &           % ",
      "  &           % ",
      "  &           % ",
      "  &           % ",
      "  &           % ",
      "  &           % ",
      "((&           % ",
      "  &           % ",
      "              % ",
      "              % ",
      "              % ",
      "              % ",
      "              %$"
    ],
    [
      " &             %",
      " &             %",
      " &             %",
      " &             %",
      " &             %",
      " &             %",
      " &             %",
      " &             %",
      " &             %",
      "(&             %",
      " &             %",
      "               %",
      "               %",
      "               %",
      "               %",
      "               %"
    ]
  ],
  "palette": {
    "palette": [
      {
        "char": "!",
        "block": "farmersdelight:straw_bale"
      },
      {
        "char": "$",
        "block": "minecraft:dark_oak_planks"
      },
      {
        "char": "%",
        "block": "minecraft:dark_oak_stairs[facing=east,half=bottom,shape=straight,waterlogged=false]"
      },
      {
        "char": "&",
        "block": "minecraft:dark_oak_stairs[facing=west,half=bottom,shape=straight,waterlogged=false]"
      },
      {
        "char": "'",
        "block": "minecraft:stripped_dark_oak_log"
      },
      {
        "char": "(",
        "block": "the_wasteland_reworked:decayed_planks"
      }
    ]
  }
}
