{
  "xsize": 16,
  "zsize": 16,
  "slices": [
    [
      "--,-------//...,",
      "--,-------//....",
      "--0-------//...,",
      "--,-------//...,",
      ";;,;;;;;;;//...,",
      "--0-------//...,",
      "--,-------//...,",
      "--,-------//...,",
      "--.-------//...,",
      "--,-------//,,0,",
      "0,,,,,,,.0//,,,,",
      ",,,0,,,,,,,.0,,,",
      ",,,,,,0,,,,,,,.0",
      "                ",
      "                ",
      "                "
    ],
    [
      " '  58 61      9",
      "%( 36 47 5     9",
      "&  4 25 36     9",
      " *  83 14      9",
      "               9",
      ")  7 58 61     9",
      " %  36 47      9",
      "+& 14 25 3     9",
      "$  2 83 14     9",
      " (  61 72      9",
      "                ",
      "                ",
      "                ",
      "                ",
      "                ",
      "                "
    ],
    [
      "               :",
      "               :",
      "               :",
      "               :",
      "               :",
      "               :",
      "               :",
      "               :",
      "               :",
      "               :",
      "                ",
      "                ",
      "                ",
      "                ",
      "                ",
      "                "
    ],
    [
      "               :",
      "               :",
      "               !",
      "               !",
      "               :",
      "               :",
      "               :",
      "               :",
      "               :",
      "               :",
      "                ",
      "                ",
      "                ",
      "                ",
      "                ",
      "                "
    ],
    [
      "               :",
      "               :",
      "               !",
      "               !",
      "               :",
      "               :",
      "               :",
      "               :",
      "               :",
      "               :",
      "                ",
      "                ",
      "                ",
      "                ",
      "                ",
      "                "
    ],
    [
      "               :",
      "               :",
      "               :",
      "               :",
      "               :",
      "               :",
      "               :",
      "               :",
      "               :",
      "               :",
      "                ",
      "                ",
      "                ",
      "                ",
      "                ",
      "                "
    ]
  ],
  "palette": {
    "palette": [
      {
        "char": "!",
        "block": "create:framed_glass"
      },
      {
        "char": "$",
        "block": "minecraft:carrots[age=0]"
      },
      {
        "char": "%",
        "block": "minecraft:carrots[age=1]"
      },
      {
        "char": "&",
        "block": "minecraft:carrots[age=2]"
      },
      {
        "char": "'",
        "block": "minecraft:carrots[age=3]"
      },
      {
        "char": "(",
        "block": "minecraft:carrots[age=4]"
      },
      {
        "char": ")",
        "block": "minecraft:carrots[age=5]"
      },
      {
        "char": "*",
        "block": "minecraft:carrots[age=6]"
      },
      {
        "char": "+",
        "block": "minecraft:carrots[age=7]"
      },
      {
        "char": ",",
        "block": "minecraft:coarse_dirt"
      },
      {
        "char": "-",
        "block": "minecraft:farmland[moisture=7]"
      },
      {
        "char": ".",
        "block": "minecraft:gravel"
      },
      {
        "char": "/",
        "block": "minecraft:mud"
      },
      {
        "char": "0",
        "block": "minecraft:podzol"
      },
      {
        "char": "1",
        "block": "minecraft:potatoes[age=0]"
      },
      {
        "char": "2",
        "block": "minecraft:potatoes[age=1]"
      },
      {
        "char": "3",
        "block": "minecraft:potatoes[age=2]"
      },
      {
        "char": "4",
        "block": "minecraft:potatoes[age=3]"
      },
      {
        "char": "5",
        "block": "minecraft:potatoes[age=4]"
      },
      {
        "char": "6",
        "block": "minecraft:potatoes[age=5]"
      },
      {
        "char": "7",
        "block": "minecraft:potatoes[age=6]"
      },
      {
        "char": "8",
        "block": "minecraft:potatoes[age=7]"
      },
      {
        "char": "9",
        "block": "minecraft:stone_bricks"
      },
      {
        "char": ":",
        "block": "minecraft:stripped_spruce_wood"
      },
      {
        "char": ";",
        "block": "minecraft:water[level=0]"
      }
    ]
  }
}
