{
  "xsize": 16,
  "zsize": 16,
  "slices": [
    [
      "                ",
      "                ",
      "                ",
      "                ",
      "                ",
      "                ",
      "                ",
      "                ",
      "%%%%%%%%%%%%%%  ",
      "             %  ",
      "             %  ",
      "             %  ",
      "             %  ",
      "             %  ",
      "             %  ",
      "             %  "
    ],
    [
      "                ",
      "                ",
      "                ",
      "                ",
      "                ",
      "                ",
      "                ",
      "                ",
      "%%%%%%%%%%%%%%  ",
      "             %  ",
      "             %  ",
      "             %  ",
      "             %  ",
      "             %  ",
      "             %  ",
      "             %  "
    ],
    [
      "                ",
      "                ",
      "                ",
      "                ",
      "                ",
      "                ",
      "                ",
      "             $  ",
      "!!!!!!!!!!!!!$  ",
      "!!!!!!!!!!!!!$  ",
      "!!!!!!!!!!!!!$  ",
      "!!!!!!!!!!!!!$  ",
      "!!!!!!!!!!!!!$  ",
      "!!!!!!!!!!!!!$  ",
      "!!!!!!!!!!!!!$  ",
      "!!!!!!!!!!!!!$  "
    ],
    [
      "                ",
      "                ",
      "                ",
      "                ",
      "                ",
      "                ",
      "                ",
      "            $   ",
      "!!!!!!!!!!!!$   ",
      "            $   ",
      "            $   ",
      "            $   ",
      "            $   ",
      "            $   ",
      "            $   ",
      "            $   "
    ],
    [
      "                ",
      "                ",
      "                ",
      "                ",
      "                ",
      "                ",
      "                ",
      "           $    ",
      "!!!!!!!!!!!$    ",
      "           $    ",
      "           $    ",
      "           $    ",
      "           $    ",
      "           $    ",
      "           $    ",
      "           $    "
    ],
    [
      "                ",
      "                ",
      "                ",
      "                ",
      "                ",
      "                ",
      "                ",
      "          $     ",
      "!!!!!!!!!!$     ",
      "          $     ",
      "          $     ",
      "          $     ",
      "          $     ",
      "          $     ",
      "          $     ",
      "          $     "
    ]
  ],
  "palette": {
    "palette": [
      {
        "char": "!",
        "block": "minecraft:dark_oak_planks"
      },
      {
        "char": "$",
        "block": "minecraft:dark_oak_stairs[facing=west,half=bottom,shape=straight,waterlogged=false]"
      },
      {
        "char": "%",
        "block": "minecraft:stripped_dark_oak_log"
      }
    ]
  }
}
