{
  "xsize": 16,
  "zsize": 16,
  "slices": [
    [
      "!%%%%!%%%$%%%   ",
      "%%!%%%%!%%%$%   ",
      "%%%%!%%%%!%%%   ",
      "%!%%%%!%%%%!%   ",
      "%%%!%%%%!%%%%   ",
      "$%%%%!%%%%!%%   ",
      "%%$%%%%!%%%%!   ",
      "!%%%$%%%%!%%%   ",
      "%%!%%%$%%%%!%   ",
      "%%%%!%%%$%%%%   ",
      "%!%%%%!%%%$%%   ",
      "%%%!%%%%!%%%$   ",
      "!%%%%!%%%%!%%   ",
      "%%!%%%%!%%%%!   ",
      "%%%%!%%%%!%%%   ",
      "%$%%%%!%%%%!%   "
    ],
    [
      "                ",
      "                ",
      "                ",
      "                ",
      "&&&&&&&&&&      ",
      "&&&&&&&&&&      ",
      "&&&&&&&&&&      ",
      "&&&&&&&&&&      ",
      "&$$$&&&&&& *    ",
      "&$$$&&&&&&      ",
      "&$$$&&&&&&      ",
      "&&&&$$$&&&      ",
      "&&&&$$$&&&      ",
      "&&&&$$$&&&      ",
      "&&&&&&&$$$      ",
      "&&&&&&&$$$      "
    ],
    [
      "                ",
      "                ",
      "                ",
      "                ",
      "))      ))      ",
      "         )      ",
      "         )      ",
      "         )      ",
      " $$$'''' )      ",
      " $$$     )      ",
      " $$$     )      ",
      "    $$$  )      ",
      " '''$$$' )      ",
      "    $$$  )      ",
      "       $$$      ",
      "       $$$      "
    ],
    [
      "                ",
      "                ",
      "                ",
      "                ",
      "))      ))      ",
      "         )      ",
      "         )      ",
      "         )      ",
      " $$$     )      ",
      " $$$     )      ",
      " $$$     )      ",
      "    $$$  )      ",
      "    $$$  )      ",
      "    $$$  )      ",
      "         )      ",
      "        ()      "
    ],
    [
      "                ",
      "                ",
      "                ",
      "                ",
      "))      ))      ",
      "         )      ",
      "         )      ",
      "         )      ",
      "         )      ",
      "  (      )      ",
      "         )      ",
      "    $$$  )      ",
      "    $$$  )      ",
      "    $$$  )      ",
      "         )      ",
      "         )      "
    ],
    [
      "                ",
      "                ",
      "                ",
      "                ",
      "))      ))      ",
      "         )      ",
      "         )      ",
      "         )      ",
      "         )      ",
      "         )      ",
      "         )      ",
      "    $$$  )      ",
      "    $$$  )      ",
      "    $$$  )      ",
      "         )      ",
      "         )      "
    ]
  ],
  "palette": {
    "palette": [
      {
        "char": "!",
        "block": "minecraft:coarse_dirt"
      },
      {
        "char": "$",
        "block": "minecraft:gravel"
      },
      {
        "char": "%",
        "block": "minecraft:podzol"
      },
      {
        "char": "&",
        "block": "minecraft:polished_deepslate"
      },
      {
        "char": "'",
        "block": "minecraft:spruce_planks"
      },
      {
        "char": "(",
        "block": "minecraft:stripped_dark_oak_log[axis=x]"
      },
      {
        "char": ")",
        "block": "minecraft:stripped_dark_oak_wood"
      },
      {
        "char": "*",
        "block": "minecraft:stripped_spruce_log[axis=y]"
      }
    ]
  }
}
