{
  "xsize": 16,
  "zsize": 16,
  "slices": [
    [
      "%%------((((((((",
      "%%------((((((((",
      "%%%%%%%-(%%(((((",
      "&&&&&&%-(%&(((((",
      "&&&&&&%-(%&(((*(",
      "&&&&&&%-(%&(((((",
      "&&&&&&%%'%&(((((",
      "&&&&&&%%'%&(((((",
      "&&&&&&%%'%&(((((",
      "&&&%%%%%%%%%%%%%",
      "&&&%%%%%%%%%%%%%",
      "&&&%%%%%%%%%%%*%",
      "&&&%%%%%%%%%%%%%",
      "&&&%%%%%%%%%%%%%",
      "&&&&&&%+'%&(((((",
      "&&&&&&%+'%&((((("
    ],
    [
      "                ",
      "                ",
      "                ",
      "                ",
      ")))))      ,,,,,",
      ")))))      ,,,,,",
      ")))))      ,,,,,",
      ")))))      ,,,,,",
      ")))))      ,,,,,",
      ")))))      ,,,,,",
      ")))))      ,,,,,",
      ")))))      ,,,,,",
      ")))))      ,,,,,",
      ")))))      ,,,,,",
      ")))))      ,,,33",
      ")))))      ,,,33"
    ],
    [
      "                ",
      "                ",
      "                ",
      "                ",
      "22222      333  ",
      "    2      3    ",
      "    2      3    ",
      "    2      3    ",
      " $  2      3 444",
      "    2      3    ",
      "    .      3    ",
      "05552      3    ",
      "    2      3 444",
      "!!  2      3    ",
      "!!  2      3    ",
      "!!  2      3    "
    ],
    [
      "                ",
      "                ",
      "                ",
      "                ",
      "22222      333  ",
      "    2      3    ",
      "    2      3    ",
      "    2      3    ",
      "    2      3    ",
      "    2      3    ",
      "    /      3    ",
      "15552      3    ",
      "    2      3    ",
      "!!  2      3    ",
      "!!  2      3    ",
      "!!  2      3    "
    ],
    [
      "                ",
      "                ",
      "                ",
      "                ",
      "22222      333  ",
      "    2      3    ",
      "    2      3    ",
      "    2      3    ",
      "    2      3    ",
      "    2      3    ",
      "    2      3    ",
      "55552      3    ",
      "    2      3    ",
      "    2      3    ",
      "    2      3    ",
      "    2      3    "
    ],
    [
      "                ",
      "                ",
      "                ",
      "                ",
      "22222      333  ",
      "    2      3    ",
      "    2      3    ",
      "    2      3    ",
      "    2      3    ",
      "    2      3    ",
      "    2      3    ",
      "55552      3    ",
      "    2      3    ",
      "    2      3    ",
      "    2      3    ",
      "    2      3    "
    ]
  ],
  "palette": {
    "palette": [
      {
        "char": "!",
        "block": "immersiveengineering:crate"
      },
      {
        "char": "$",
        "block": "kubejs:ruined_cartography_table"
      },
      {
        "char": "%",
        "block": "minecraft:coarse_dirt"
      },
      {
        "char": "&",
        "block": "minecraft:cobblestone"
      },
      {
        "char": "'",
        "block": "minecraft:dirt_path"
      },
      {
        "char": "(",
        "block": "minecraft:gravel"
      },
      {
        "char": ")",
        "block": "minecraft:oak_planks"
      },
      {
        "char": "*",
        "block": "minecraft:packed_mud"
      },
      {
        "char": "+",
        "block": "minecraft:podzol"
      },
      {
        "char": ",",
        "block": "minecraft:polished_deepslate"
      },
      {
        "char": "-",
        "block": "minecraft:rooted_dirt"
      },
      {
        "char": ".",
        "block": "minecraft:spruce_door[facing=east,half=lower,hinge=left,open=false,powered=false]"
      },
      {
        "char": "/",
        "block": "minecraft:spruce_door[facing=east,half=upper,hinge=left,open=false,powered=false]"
      },
      {
        "char": "0",
        "block": "minecraft:spruce_door[facing=south,half=lower,hinge=left,open=false,powered=false]"
      },
      {
        "char": "1",
        "block": "minecraft:spruce_door[facing=south,half=upper,hinge=left,open=false,powered=false]"
      },
      {
        "char": "2",
        "block": "minecraft:spruce_planks"
      },
      {
        "char": "3",
        "block": "minecraft:stripped_dark_oak_wood"
      },
      {
        "char": "4",
        "block": "minecraft:stripped_spruce_log[axis=x]"
      },
      {
        "char": "5",
        "block": "minecraft:stripped_spruce_wood"
      }
    ]
  }
}
