{
  "xsize": 16,
  "zsize": 16,
  "slices": [
    [
      "&))))%))))%))))%",
      "))&))))%))))%)))",
      "%)))&))))%))))%)",
      "))%)))&))))%))))",
      "))))%)))&))))%))",
      ")%))))%)))&))))%",
      ")))%))))%)))&)))",
      "%))))%))))%)))&)",
      "))%))))%))))%)))",
      "))))%))))%))))%)",
      ")&))))%))))%))))",
      ")))&))))%))))%))",
      ")%)))&))))%))))%",
      ")))%)))&))))%)))",
      "%))))%)))&))))%)",
      "))%))))%)))&))))"
    ],
    [
      "                ",
      "                ",
      "                ",
      "                ",
      "    ((((((((((((",
      "    ((((((((((((",
      "    ((((((((((((",
      "  1 ((((((((((((",
      "    ((((((((((((",
      "    ((((((((((((",
      "    ((((((((((((",
      "    ((((((((((((",
      "    ((((((((((((",
      "    ((((((((((((",
      "    ((((((((((((",
      "    (((((((((((("
    ],
    [
      "                ",
      "                ",
      "                ",
      "                ",
      "    ............",
      "    .       2   ",
      "    .       2   ",
      "  1 .       2   ",
      "    . // 3  2 //",
      "    . 0     2 0 ",
      "    .       *   ",
      "    .222,2222222",
      "    .       2   ",
      "    .       2 $$",
      "    . '     2 $$",
      "    .       2 $$"
    ],
    [
      "                ",
      "                ",
      "                ",
      "                ",
      "    ..!!......!!",
      "    .       2   ",
      "    .       2   ",
      "    .       2   ",
      "    !       2   ",
      "    !       2   ",
      "    .       +   ",
      "    .222-2222222",
      "    .       2   ",
      "    .       2 $$",
      "    .       2 $$",
      "    .       2 $$"
    ],
    [
      "                ",
      "                ",
      "                ",
      "                ",
      "    ..!!......!!",
      "    .       2   ",
      "    .       2   ",
      "    .       2   ",
      "    !       2   ",
      "    !       2   ",
      "    .       2   ",
      "    .22222222222",
      "    .       2   ",
      "    .       2   ",
      "    .       2   ",
      "    .       2   "
    ],
    [
      "                ",
      "                ",
      "                ",
      "                ",
      "    ............",
      "    .       2   ",
      "    .       2   ",
      "    .       2   ",
      "    .       2   ",
      "    .       2   ",
      "    .       2   ",
      "    .22222222222",
      "    .       2   ",
      "    .       2   ",
      "    .       2   ",
      "    .       2   "
    ]
  ],
  "palette": {
    "palette": [
      {
        "char": "!",
        "block": "create:framed_glass"
      },
      {
        "char": "$",
        "block": "immersiveengineering:crate"
      },
      {
        "char": "%",
        "block": "minecraft:coarse_dirt"
      },
      {
        "char": "&",
        "block": "minecraft:gravel"
      },
      {
        "char": "'",
        "block": "minecraft:lectern[facing=south,has_book=false,powered=false]"
      },
      {
        "char": "(",
        "block": "minecraft:oak_planks"
      },
      {
        "char": ")",
        "block": "minecraft:podzol"
      },
      {
        "char": "*",
        "block": "minecraft:spruce_door[facing=east,half=lower,hinge=left,open=false,powered=false]"
      },
      {
        "char": "+",
        "block": "minecraft:spruce_door[facing=east,half=upper,hinge=left,open=false,powered=false]"
      },
      {
        "char": ",",
        "block": "minecraft:spruce_door[facing=south,half=lower,hinge=left,open=false,powered=false]"
      },
      {
        "char": "-",
        "block": "minecraft:spruce_door[facing=south,half=upper,hinge=left,open=false,powered=false]"
      },
      {
        "char": ".",
        "block": "minecraft:spruce_planks"
      },
      {
        "char": "/",
        "block": "minecraft:spruce_slab[type=bottom,waterlogged=false]"
      },
      {
        "char": "0",
        "block": "minecraft:spruce_stairs[facing=north,half=bottom,shape=straight,waterlogged=false]"
      },
      {
        "char": "1",
        "block": "minecraft:stripped_spruce_log[axis=y]"
      },
      {
        "char": "2",
        "block": "minecraft:stripped_spruce_wood"
      },
      {
        "char": "3",
        "block": "the_wasteland_reworked:radio"
      }
    ]
  }
}
