{
  "xsize": 16,
  "zsize": 16,
  "slices": [
    [
      "+&+)))))))))))*)",
      "+++)))))))))))))",
      "&++++&++++&(((((",
      "++&++++&+++(((((",
      "++++&++++&+(((((",
      "+(++++&++++(((((",
      "+++(++++&++(((((",
      "+&+++(++++&(((*(",
      "+++&+++(+++(((((",
      "&++++&+++(+(((((",
      "++&++++&+++(((((",
      "++++&++++&+(((((",
      "+&++++&++++(((((",
      "+++&++++&++(((((",
      "(++++&++++&(((*(",
      "++(++++&+++((((("
    ],
    [
      "........        ",
      "........        ",
      "........        ",
      "........ .......",
      "........ .......",
      "........ .......",
      "........        ",
      "........        ",
      "........        ",
      "........        ",
      "........ .......",
      "........ .......",
      "         .......",
      "                ",
      "                ",
      "                "
    ],
    [
      "///,///'        ",
      "       '        ",
      "   $   '        ",
      "   %   ' .......",
      "       ' .......",
      "       ' .......",
      "       '        ",
      "       '        ",
      "    !  '        ",
      "       '        ",
      "       ' .......",
      "'''''''' .......",
      "         .......",
      "                ",
      "                ",
      "                "
    ],
    [
      "///-///'        ",
      "       '        ",
      "       '        ",
      "       ' .......",
      "       ' .......",
      "       ' .......",
      "       '        ",
      "       '        ",
      "       '        ",
      "       '        ",
      "       ' .......",
      "'''''''' .......",
      "         .......",
      "                ",
      "                ",
      "                "
    ],
    [
      "///////'        ",
      "       '        ",
      "       '        ",
      "       '        ",
      "       '  0    0",
      "       '        ",
      "       '        ",
      "       '        ",
      "       '        ",
      "       '        ",
      "       '        ",
      "''''''''        ",
      "                ",
      "                ",
      "                ",
      "                "
    ],
    [
      "///////'        ",
      "       '        ",
      "       '        ",
      "       '        ",
      "       '  0    0",
      "       '        ",
      "       '        ",
      "       '        ",
      "       '        ",
      "       '        ",
      "       '        ",
      "''''''''        ",
      "                ",
      "                ",
      "                ",
      "                "
    ]
  ],
  "palette": {
    "palette": [
      {
        "char": "!",
        "block": "minecraft:barrel[facing=up,open=false]"
      },
      {
        "char": "$",
        "block": "minecraft:brown_bed[facing=south,occupied=false,part=foot]"
      },
      {
        "char": "%",
        "block": "minecraft:brown_bed[facing=south,occupied=false,part=head]"
      },
      {
        "char": "&",
        "block": "minecraft:coarse_dirt"
      },
      {
        "char": "'",
        "block": "minecraft:dark_oak_planks"
      },
      {
        "char": "(",
        "block": "minecraft:gravel"
      },
      {
        "char": ")",
        "block": "minecraft:mud"
      },
      {
        "char": "*",
        "block": "minecraft:packed_mud"
      },
      {
        "char": "+",
        "block": "minecraft:podzol"
      },
      {
        "char": ",",
        "block": "minecraft:spruce_door[facing=south,half=lower,hinge=left,open=false,powered=false]"
      },
      {
        "char": "-",
        "block": "minecraft:spruce_door[facing=south,half=upper,hinge=left,open=false,powered=false]"
      },
      {
        "char": ".",
        "block": "minecraft:spruce_planks"
      },
      {
        "char": "/",
        "block": "minecraft:stripped_dark_oak_wood"
      },
      {
        "char": "0",
        "block": "minecraft:stripped_oak_log[axis=y]"
      }
    ]
  }
}
