{
  "xsize": 16,
  "zsize": 16,
  "slices": [
    [
      "&&(((%((((%((((%",
      "&&&((((%((((%(((",
      "&&((&((((%((((%(",
      "&&%(((&((((%((((",
      "&&((%(((&((((%((",
      "&&((((%(((&((((%",
      "&&(%((((%(((&(((",
      "&&(((%((((%(((&(",
      "&&%((((%((((%(((",
      "&&((%((((%((((%(",
      "&&((((%((((%((((",
      "&&(&((((%((((%((",
      "&&(((&((((%((((%",
      "''''''''''''''''",
      "''''''''''''''''",
      "''''''''''''''''"
    ],
    [
      "))))))))))))))))",
      "))))))))))))))))",
      "))))))))))))))))",
      "))))))))))))))))",
      "))))))))))))))))",
      "))))))))))))))))",
      "))))))))))))))))",
      "))))))))))))))))",
      "))))))))))))))))",
      "))))))))))))))))",
      "))))))))))))))))",
      "))))))))))))))))",
      "                ",
      "                ",
      "                ",
      " 3              "
    ],
    [
      "     +    !*   +",
      "0000 1         1",
      "     1         1",
      "     1         1",
      "     1         1",
      "-111111111-11111",
      "     1         1",
      "     1 $$$$$$  1",
      "  2  1 $$$$$$  1",
      "     1 $$$$$$  1",
      "     1         1",
      "////////////////",
      "                ",
      "                ",
      "                ",
      "                "
    ],
    [
      "     ,         ,",
      "     1         1",
      "     1         1",
      "     1         1",
      "     1         1",
      ".111111111.11111",
      "     1         1",
      "     1 $$$$$$  1",
      "     1 $$$$$$  1",
      "     1 $$$$$$  1",
      "     1         1",
      "////////////////",
      "                ",
      "                ",
      "                ",
      "                "
    ],
    [
      "     1         1",
      "     1         1",
      "     1         1",
      "     1         1",
      "     1         1",
      "1111111111111111",
      "     1         1",
      "     1         1",
      "     1         1",
      "     1         1",
      "     1         1",
      "////////////////",
      "                ",
      "                ",
      "                ",
      "                "
    ],
    [
      "     1         1",
      "     1         1",
      "     1         1",
      "     1         1",
      "     1         1",
      "1111111111111111",
      "     1         1",
      "     1         1",
      "     1         1",
      "     1         1",
      "     1         1",
      "////////////////",
      "                ",
      "                ",
      "                ",
      "                "
    ]
  ],
  "palette": {
    "palette": [
      {
        "char": "!",
        "block": "create:mechanical_press[facing=north]"
      },
      {
        "char": "$",
        "block": "immersiveengineering:crate"
      },
      {
        "char": "%",
        "block": "minecraft:coarse_dirt"
      },
      {
        "char": "&",
        "block": "minecraft:gravel"
      },
      {
        "char": "'",
        "block": "minecraft:mud"
      },
      {
        "char": "(",
        "block": "minecraft:podzol"
      },
      {
        "char": ")",
        "block": "minecraft:polished_deepslate"
      },
      {
        "char": "*",
        "block": "minecraft:spawner",
        "tag": {
          "id": "minecraft:mob_spawner",
          "Delay": 240,
          "MinSpawnDelay": 240,
          "MaxSpawnDelay": 720,
          "SpawnCount": 2,
          "MaxNearbyEntities": 7,
          "RequiredPlayerRange": 14,
          "SpawnRange": 4,
          "SpawnData": {
            "entity": {
              "id": "minecraft:zombie"
            }
          },
          "SpawnPotentials": [
            {
              "weight": 1,
              "data": {
                "entity": {
                  "id": "minecraft:zombie"
                }
              }
            }
          ]
        }
      },
      {
        "char": "+",
        "block": "minecraft:spruce_door[facing=east,half=lower,hinge=left,open=false,powered=false]"
      },
      {
        "char": ",",
        "block": "minecraft:spruce_door[facing=east,half=upper,hinge=left,open=false,powered=false]"
      },
      {
        "char": "-",
        "block": "minecraft:spruce_door[facing=south,half=lower,hinge=left,open=false,powered=false]"
      },
      {
        "char": ".",
        "block": "minecraft:spruce_door[facing=south,half=upper,hinge=left,open=false,powered=false]"
      },
      {
        "char": "/",
        "block": "minecraft:stripped_dark_oak_wood"
      },
      {
        "char": "0",
        "block": "minecraft:stripped_spruce_log[axis=x]"
      },
      {
        "char": "1",
        "block": "minecraft:stripped_spruce_wood"
      },
      {
        "char": "2",
        "block": "the_wasteland_reworked:radio"
      },
      {
        "char": "3",
        "block": "wastelands:scrap_pile"
      }
    ]
  }
}
