{
  "xsize": 16,
  "zsize": 16,
  "slices": [
    [
      ",,,,,,,,,,,,,,,,",
      ",,(,,,,(,,,,(,,,",
      ",,,,,,,,,,,,,,,,",
      ",&,,,,,,,,,,,,,,",
      ",,,,,,,,,,,,,,,,",
      ",,,,,,,,,,,,,,,,",
      ",,,,,,,,,,,,,,,,",
      ",,,,,,,,,,,,,,,,",
      ",,,,,,,,,,,,,,,,",
      ",&,,,,,,,,,,,,,,",
      ",,&,,,,&,,,,&,,,",
      ",,,,,,,,,,,,,,,,",
      "                ",
      "                ",
      "                ",
      "                "
    ],
    [
      "                ",
      "                ",
      "  ((((((      $$",
      "  ((((((        ",
      "  ((((((        ",
      "  ((((((        ",
      "  ((((((        ",
      "                ",
      "                ",
      "    $$        $$",
      "                ",
      "                ",
      "                ",
      "                ",
      "                ",
      "                "
    ],
    [
      "                ",
      "                ",
      "  ((((((      $$",
      "  ((((((********",
      "  ((((((********",
      "  ((((((********",
      "  ((((((********",
      "   *************",
      "   *************",
      "    $$ .      $$",
      "                ",
      "                ",
      "                ",
      "                ",
      "                ",
      "                "
    ],
    [
      "                ",
      "                ",
      "    $$        $$",
      "        ********",
      "         -   ! '",
      "           % !  ",
      "   **     +  !  ",
      "   ** -  -   ! '",
      "   *************",
      "    $$        $$",
      "                ",
      "                ",
      "                ",
      "                ",
      "                ",
      "                "
    ],
    [
      "                ",
      "                ",
      "                ",
      "        ********",
      "         -   !  ",
      "             !  ",
      "   **        !  ",
      "   ** -  -   !  ",
      "   *************",
      "                ",
      "                ",
      "                ",
      "                ",
      "                ",
      "                ",
      "                "
    ],
    [
      "                ",
      "                ",
      "                ",
      "        *******)",
      "         -   !  ",
      "             !  ",
      "   **        !  ",
      "   ** -  -   !  ",
      "   ************)",
      "                ",
      "                ",
      "                ",
      "                ",
      "                ",
      "                ",
      "                "
    ]
  ],
  "palette": {
    "palette": [
      {
        "char": "!",
        "block": "immersiveengineering:sheetmetal_steel"
      },
      {
        "char": "$",
        "block": "minecraft:blackstone"
      },
      {
        "char": "%",
        "block": "minecraft:chest[facing=east,type=single,waterlogged=false]",
        "tag": {
          "id": "minecraft:chest",
          "LootTable": "infinite_domain:chests/wasteland_roadside"
        }
      },
      {
        "char": "&",
        "block": "minecraft:coarse_dirt"
      },
      {
        "char": "'",
        "block": "minecraft:dark_oak_stairs[facing=east,half=bottom,shape=straight,waterlogged=false]"
      },
      {
        "char": "(",
        "block": "minecraft:gravel"
      },
      {
        "char": ")",
        "block": "minecraft:light_blue_stained_glass"
      },
      {
        "char": "*",
        "block": "minecraft:light_gray_concrete"
      },
      {
        "char": "+",
        "block": "minecraft:spawner",
        "tag": {
          "id": "minecraft:mob_spawner",
          "Delay": 200,
          "MinSpawnDelay": 240,
          "MaxSpawnDelay": 720,
          "SpawnCount": 1,
          "MaxNearbyEntities": 3,
          "RequiredPlayerRange": 14,
          "SpawnRange": 4,
          "SpawnData": {
            "entity": {
              "id": "minecraft:zombie"
            }
          },
          "SpawnPotentials": [
            {
              "weight": 1,
              "data": {
                "entity": {
                  "id": "minecraft:zombie"
                }
              }
            }
          ]
        }
      },
      {
        "char": ",",
        "block": "tfmg:asphalt"
      },
      {
        "char": "-",
        "block": "the_wasteland_reworked:cardboard_box"
      },
      {
        "char": ".",
        "block": "wastelands:scrap_pile"
      }
    ]
  }
}
