{
  "xsize": 16,
  "zsize": 16,
  "slices": [
    [
      "////////////////",
      "//(////(////(///",
      "////////////////",
      "/&//////////////",
      "////////////////",
      "////////////////",
      "////////////////",
      "////////////////",
      "////////////////",
      "/&//////////////",
      "//&////&////&///",
      "////////////////",
      "                ",
      "                ",
      "                ",
      "                "
    ],
    [
      "                ",
      "                ",
      "                ",
      "                ",
      "                ",
      "                ",
      "                ",
      "                ",
      "                ",
      "                ",
      "                ",
      "                ",
      "                ",
      "                ",
      "                ",
      "                "
    ],
    [
      "                ",
      "                ",
      "    $$        $$",
      "   .............",
      "   .............",
      "   .............",
      "   .............",
      "   .............",
      "   .............",
      "    $$        $$",
      "                ",
      "                ",
      "                ",
      "                ",
      "                ",
      "                "
    ],
    [
      "                ",
      "                ",
      "    $$        $$",
      "   .............",
      "   .. 0  0   ! '",
      "   )*      % !  ",
      "   ..        !  ",
      "   .. 0  0   ! '",
      "   .............",
      "    $$        $$",
      "                ",
      "                ",
      "                ",
      "                ",
      "                ",
      "                "
    ],
    [
      "                ",
      "                ",
      "                ",
      "   .............",
      "   .. 0  0   !  ",
      "   +,        !  ",
      "   ..        !  ",
      "   .. 0  0   !  ",
      "   .............",
      "                ",
      "                ",
      "                ",
      "                ",
      "                ",
      "                ",
      "                "
    ],
    [
      "                ",
      "                ",
      "                ",
      "   ............-",
      "   .. 0  0   !  ",
      "   ..        !  ",
      "   ..        !  ",
      "   .. 0  0   !  ",
      "   ............-",
      "                ",
      "                ",
      "                ",
      "                ",
      "                ",
      "                ",
      "                "
    ]
  ],
  "palette": {
    "palette": [
      {
        "char": "!",
        "block": "immersiveengineering:sheetmetal_steel"
      },
      {
        "char": "$",
        "block": "minecraft:blackstone"
      },
      {
        "char": "%",
        "block": "minecraft:chest[facing=east,type=single,waterlogged=false]",
        "tag": {
          "id": "minecraft:chest",
          "LootTable": "infinite_domain:chests/wasteland_roadside"
        }
      },
      {
        "char": "&",
        "block": "minecraft:coarse_dirt"
      },
      {
        "char": "'",
        "block": "minecraft:dark_oak_stairs[facing=east,half=bottom,shape=straight,waterlogged=false]"
      },
      {
        "char": "(",
        "block": "minecraft:gravel"
      },
      {
        "char": ")",
        "block": "minecraft:iron_door[facing=west,half=lower,hinge=left,open=false,powered=false]"
      },
      {
        "char": "*",
        "block": "minecraft:iron_door[facing=west,half=lower,hinge=right,open=false,powered=false]"
      },
      {
        "char": "+",
        "block": "minecraft:iron_door[facing=west,half=upper,hinge=left,open=false,powered=false]"
      },
      {
        "char": ",",
        "block": "minecraft:iron_door[facing=west,half=upper,hinge=right,open=false,powered=false]"
      },
      {
        "char": "-",
        "block": "minecraft:light_blue_stained_glass"
      },
      {
        "char": ".",
        "block": "minecraft:light_gray_concrete"
      },
      {
        "char": "/",
        "block": "tfmg:asphalt"
      },
      {
        "char": "0",
        "block": "the_wasteland_reworked:cardboard_box"
      }
    ]
  }
}
