{
  "xsize": 16,
  "zsize": 16,
  "slices": [
    [
      "  %%%%%%%%%     ",
      "  %%%%%%%%%     ",
      "  %%%%%%%%%     ",
      "  %%%%%%%%%     ",
      "  %%%%%%%%%     ",
      "  %%%%%%%%%     ",
      "  %%%%%%%%%     ",
      "  %%%%%%%%%     ",
      "  %%%%%%%%%     ",
      "  %%%%%%%%%     ",
      "                ",
      "                ",
      "                ",
      "                ",
      "$$$$$$$$$$$     ",
      "$$$$$$$$$$$     "
    ],
    [
      "  %%%%%%%%%     ",
      "  %%%%%%%%%     ",
      "  %%%%%%%%%     ",
      "  %%%%%%%%%     ",
      "  %%%%%%%%%     ",
      "  %%%%%%%%%     ",
      "  %%%%%%%%%     ",
      "  %%%%%%%%%     ",
      "  %%%%%%%%%     ",
      "                ",
      "                ",
      "                ",
      "                ",
      "                ",
      "  $!!!!!$       ",
      "  $$$$$$$       "
    ],
    [
      "                ",
      "                ",
      "                ",
      "                ",
      "                ",
      "                ",
      "                ",
      "                ",
      "                ",
      "                ",
      "                ",
      "                ",
      "                ",
      "                ",
      "  $$$$$$$       ",
      "  $$$$$$$       "
    ],
    [
      "                ",
      "                ",
      "                ",
      "                ",
      "                ",
      "                ",
      "                ",
      "                ",
      "                ",
      "                ",
      "                ",
      "                ",
      "                ",
      "                ",
      "                ",
      "                "
    ],
    [
      "                ",
      "                ",
      "                ",
      "                ",
      "                ",
      "                ",
      "                ",
      "                ",
      "                ",
      "                ",
      "                ",
      "                ",
      "                ",
      "                ",
      "                ",
      "                "
    ],
    [
      "                ",
      "                ",
      "                ",
      "                ",
      "                ",
      "                ",
      "                ",
      "                ",
      "                ",
      "                ",
      "                ",
      "                ",
      "                ",
      "                ",
      "                ",
      "                "
    ]
  ],
  "palette": {
    "palette": [
      {
        "char": "!",
        "block": "minecraft:light_blue_stained_glass"
      },
      {
        "char": "$",
        "block": "minecraft:white_concrete"
      },
      {
        "char": "%",
        "block": "minecraft:yellow_terracotta"
      }
    ]
  }
}
