{
  "xsize": 16,
  "zsize": 16,
  "slices": [
    [
      "....(((.........",
      "....(((.........",
      "....(((.........",
      "....(((.........",
      "....(((.........",
      "....(((.........",
      "....(((.......''",
      "....(((.....''$.",
      "....(((.....$...",
      "....(((.........",
      "....(((.........",
      "....(((.........",
      "....(((.........",
      "....(((.........",
      "....(((.........",
      "....(((........'"
    ],
    [
      "''''''''' !!    ",
      "'''''''''       ",
      "'''''''''      $",
      "               $",
      "               $",
      "               $",
      "               $",
      "               $",
      "               $",
      "               $",
      "!!         !!  $",
      "!!         !!  $",
      "               $",
      "               $",
      "               $",
      "      ''''''''''"
    ],
    [
      "''''''''',!!    ",
      "''''''''',,     ",
      "'''''''''      )",
      "               +",
      "               +",
      "               +",
      "               +",
      "               +",
      " -----------   +",
      " -----------   +",
      "!!---------!!  +",
      "!!---------!!  +",
      " -----------   +",
      " -----------   +",
      " -----------   +",
      " -----''''''''''"
    ],
    [
      "''''''''',!!    ",
      "''''''''',,     ",
      "'''''''''      )",
      "               +",
      "               +",
      "               +",
      "               +",
      "               +",
      " -----------   +",
      " -----------   +",
      "!!-       -!!  +",
      "!!-       -!!  +",
      " --%    & --   +",
      " --       --   +",
      " --       --   +",
      " --%  ''''''''''"
    ],
    [
      "''''''''',,     ",
      "''''''''',,     ",
      "'''''''''       ",
      "                ",
      "                ",
      "                ",
      "                ",
      "                ",
      " -----------    ",
      " -----------    ",
      " --       --   +",
      " *-       -*   +",
      " *-       -*   +",
      " --       --   +",
      " *-       -*   +",
      " *-       -*   )"
    ],
    [
      "        ,,,     ",
      "        ,,,     ",
      "                ",
      "                ",
      "                ",
      "                ",
      "                ",
      "                ",
      " --*******--    ",
      " -----------    ",
      " --       --   +",
      " *-       -*   +",
      " *-       -*   +",
      " --       --   +",
      " *-       -*   +",
      " *-       -*   )"
    ]
  ],
  "palette": {
    "palette": [
      {
        "char": "!",
        "block": "minecraft:blackstone"
      },
      {
        "char": "$",
        "block": "minecraft:coarse_dirt"
      },
      {
        "char": "%",
        "block": "minecraft:dark_oak_stairs[facing=east,half=bottom,shape=straight,waterlogged=false]"
      },
      {
        "char": "&",
        "block": "minecraft:dark_oak_stairs[facing=west,half=bottom,shape=straight,waterlogged=false]"
      },
      {
        "char": "'",
        "block": "minecraft:gravel"
      },
      {
        "char": "(",
        "block": "minecraft:gray_concrete"
      },
      {
        "char": ")",
        "block": "minecraft:green_wool"
      },
      {
        "char": "*",
        "block": "minecraft:light_blue_stained_glass"
      },
      {
        "char": "+",
        "block": "minecraft:stripped_spruce_log"
      },
      {
        "char": ",",
        "block": "minecraft:white_concrete"
      },
      {
        "char": "-",
        "block": "minecraft:yellow_terracotta"
      },
      {
        "char": ".",
        "block": "tfmg:asphalt"
      }
    ]
  }
}
