{
  "xsize": 16,
  "zsize": 16,
  "slices": [
    [
      "****'''*****    ",
      "*&**'''****&****",
      "****'''*********",
      "****'''*******&&",
      "****'''*****&&%*",
      "****'''*****%***",
      "****'''*********",
      "****'''*********",
      "****'''*********",
      "****'''*********",
      "****'''*********",
      "****'''*********",
      "****'''********&",
      "****'''******&&%",
      "****'''*****&%**",
      "****'''*********"
    ],
    [
      "                ",
      "                ",
      "                ",
      "                ",
      "                ",
      "                ",
      "                ",
      "!         !!    ",
      "!         !!    ",
      "                ",
      "                ",
      "                ",
      "                ",
      "                ",
      "                ",
      "!         !!    "
    ],
    [
      "                ",
      "                ",
      "                ",
      "                ",
      "                ",
      ")))))))))))     ",
      ")))))))))))     ",
      "!)))))))))!!    ",
      "!)))))))))!!    ",
      ")))))))))))     ",
      ")))))))))))     ",
      ")))))))))))     ",
      ")))))))))))     ",
      ")))))))))))     ",
      ")))))))))))     ",
      "!)))))))))!!    "
    ],
    [
      "                ",
      "                ",
      "                ",
      "                ",
      "                ",
      ")))))))))))     ",
      ")))))))))))     ",
      "!)       )!!    ",
      "!)       )!!    ",
      "))+  +  +))     ",
      "))+  +  +))     ",
      "))+  +  $))     ",
      "))+  +  +))     ",
      "))+  +  +))     ",
      "))       ))     ",
      "!)       )!!    "
    ],
    [
      "                ",
      "                ",
      "                ",
      "                ",
      "                ",
      ")))))))))))     ",
      ")))))))))))     ",
      "))       ))     ",
      "))       ))     ",
      "))+  +  +))     ",
      "))+  +  +))     ",
      "))+  +  +))     ",
      "))+  +  +))     ",
      "))+  +  +))     ",
      "))       ))     ",
      "))       ))     "
    ],
    [
      "                ",
      "                ",
      "                ",
      "                ",
      "                ",
      "))((((((())     ",
      ")))))))))))     ",
      ")))))))))))     ",
      ")))))))))))     ",
      "))+  +  +))     ",
      "))+  +  +))     ",
      "))+  +  +))     ",
      "))+  +  +))     ",
      "))+  +  +))     ",
      "))       ))     ",
      "))       ))     "
    ]
  ],
  "palette": {
    "palette": [
      {
        "char": "!",
        "block": "minecraft:blackstone"
      },
      {
        "char": "$",
        "block": "minecraft:chest[facing=east,type=single,waterlogged=false]",
        "tag": {
          "id": "minecraft:chest",
          "LootTable": "infinite_domain:chests/wasteland_roadside"
        }
      },
      {
        "char": "%",
        "block": "minecraft:coarse_dirt"
      },
      {
        "char": "&",
        "block": "minecraft:gravel"
      },
      {
        "char": "'",
        "block": "minecraft:gray_concrete"
      },
      {
        "char": "(",
        "block": "minecraft:light_blue_stained_glass"
      },
      {
        "char": ")",
        "block": "minecraft:white_concrete"
      },
      {
        "char": "*",
        "block": "tfmg:asphalt"
      },
      {
        "char": "+",
        "block": "the_wasteland_reworked:cardboard_box"
      }
    ]
  }
}
