{
  "xsize": 16,
  "zsize": 16,
  "slices": [
    [
      ",,,,,,,,,,      ",
      ",,,,,,,,$$      ",
      ",,,,,,$$!,      ",
      ",,,,$$!,,,      ",
      ",,$$!,,,,,      ",
      "$$!,,,,,,$      ",
      "!,,,,,,,,,      ",
      ",,,,,,,,,,      ",
      ",,,,,,,,,,      ",
      ",,,,,,,,,,      ",
      ",,,,,,,,,$      ",
      ",,,,,,,$$$      ",
      ",,,,,$$!,,      ",
      ",,,$$!,,,,      ",
      ",$$!,,,,,,      ",
      "$!,,,,,,,,      "
    ],
    [
      "                ",
      "                ",
      "!!!!!!!!!       ",
      "!!!!!!!!!       ",
      "!!!!!!!!!       ",
      "!!!!!!!!!       ",
      "!!!!!!!!!       ",
      "!!!!!!!!!       ",
      "!!!!!!!!!       ",
      "!!!!!!!!!       ",
      "!!!!!!!!!       ",
      "!!!!!!!!!       ",
      "!!!!!!!!!       ",
      "!!!!!!!!!       ",
      "!!!!!!!!!       ",
      "!!!!!!!!!       "
    ],
    [
      "                ",
      "                ",
      "%%%'%%%%%       ",
      "        )       ",
      "        )       ",
      "        )       ",
      " +      )       ",
      " *      )       ",
      "        )       ",
      "     &&&)       ",
      "     &&&)       ",
      "     &&&)       ",
      "     &&&)       ",
      "        )       ",
      "        )       ",
      "%%%%%%%%%       "
    ],
    [
      "                ",
      "                ",
      "%%%(%%%%%       ",
      "        )       ",
      "        )       ",
      "        )       ",
      "        )       ",
      "        )       ",
      "        )       ",
      "     &&&)       ",
      "     &&&)       ",
      "     &&&)       ",
      "     &&&)       ",
      "        )       ",
      "        )       ",
      "%%%%%%%%%       "
    ],
    [
      "                ",
      "                ",
      "%%%%%%%%%       ",
      "        )       ",
      "        )       ",
      "        )       ",
      "        )       ",
      "        )       ",
      "        )       ",
      "     &&&)       ",
      "     &&&)       ",
      "     &&&)       ",
      "     &&&)       ",
      "        )       ",
      "        )       ",
      "%%%%%%%%%       "
    ],
    [
      "                ",
      "                ",
      "%%%%%%%%%       ",
      "        )       ",
      "        )       ",
      "        )       ",
      "        )       ",
      "        )       ",
      "        )       ",
      "        )       ",
      "        )       ",
      "        )       ",
      "        )       ",
      "        )       ",
      "        )       ",
      "%%%%%%%%%       "
    ]
  ],
  "palette": {
    "palette": [
      {
        "char": "!",
        "block": "minecraft:coarse_dirt"
      },
      {
        "char": "$",
        "block": "minecraft:gravel"
      },
      {
        "char": "%",
        "block": "minecraft:green_wool"
      },
      {
        "char": "&",
        "block": "minecraft:scaffolding"
      },
      {
        "char": "'",
        "block": "minecraft:spruce_door[facing=north,half=lower,hinge=left,open=false,powered=false]"
      },
      {
        "char": "(",
        "block": "minecraft:spruce_door[facing=north,half=upper,hinge=left,open=false,powered=false]"
      },
      {
        "char": ")",
        "block": "minecraft:stripped_spruce_log"
      },
      {
        "char": "*",
        "block": "minecraft:white_bed[facing=north,occupied=false,part=foot]"
      },
      {
        "char": "+",
        "block": "minecraft:white_bed[facing=north,occupied=false,part=head]"
      },
      {
        "char": ",",
        "block": "tfmg:asphalt"
      }
    ]
  }
}
