{
  "xsize": 16,
  "zsize": 16,
  "slices": [
    [
      "////'''/////////",
      "////'''/////////",
      "////'''////////&",
      "////'''//////&&%",
      "////'''/////&%//",
      "////'''/////////",
      "////'''/////////",
      "/%//'''////%////",
      "////'''/////    ",
      "                ",
      "                ",
      "                ",
      "                ",
      "                ",
      "                ",
      "                "
    ],
    [
      "!         !!    ",
      "!         !!    ",
      "                ",
      "                ",
      "!         !!    ",
      "!         !!    ",
      "                ",
      "                ",
      "                ",
      "                ",
      "                ",
      "                ",
      "                ",
      "                ",
      "                ",
      "                "
    ],
    [
      "!.........!!    ",
      "!.........!!    ",
      "...........     ",
      "...........     ",
      "!.........!!    ",
      "!.........!!    ",
      "...........     ",
      "                ",
      "                ",
      "                ",
      "                ",
      "                ",
      "                ",
      "                ",
      "                ",
      "                "
    ],
    [
      "!.       .!!    ",
      "!. -     .!!    ",
      ".. ,     ..     ",
      "..      $..     ",
      "!.       .!!    ",
      "!...  ....!!    ",
      "....().....     ",
      "                ",
      "                ",
      "                ",
      "                ",
      "                ",
      "                ",
      "                ",
      "                ",
      "                "
    ],
    [
      "..       ..     ",
      "..       ..     ",
      "..       ..     ",
      "..       ..     ",
      "..       ..     ",
      "....  .....     ",
      "....*+.....     ",
      "                ",
      "                ",
      "                ",
      "                ",
      "                ",
      "                ",
      "                ",
      "                ",
      "                "
    ],
    [
      "..       ..     ",
      "..       ..     ",
      "..       ..     ",
      "..       ..     ",
      "..       ..     ",
      "...........     ",
      "...........     ",
      "                ",
      "                ",
      "                ",
      "                ",
      "                ",
      "                ",
      "                ",
      "                ",
      "                "
    ]
  ],
  "palette": {
    "palette": [
      {
        "char": "!",
        "block": "minecraft:blackstone"
      },
      {
        "char": "$",
        "block": "minecraft:brewing_stand[has_bottle_0=false,has_bottle_1=false,has_bottle_2=false]"
      },
      {
        "char": "%",
        "block": "minecraft:coarse_dirt"
      },
      {
        "char": "&",
        "block": "minecraft:gravel"
      },
      {
        "char": "'",
        "block": "minecraft:gray_concrete"
      },
      {
        "char": "(",
        "block": "minecraft:iron_door[facing=south,half=lower,hinge=left,open=false,powered=false]"
      },
      {
        "char": ")",
        "block": "minecraft:iron_door[facing=south,half=lower,hinge=right,open=false,powered=false]"
      },
      {
        "char": "*",
        "block": "minecraft:iron_door[facing=south,half=upper,hinge=left,open=false,powered=false]"
      },
      {
        "char": "+",
        "block": "minecraft:iron_door[facing=south,half=upper,hinge=right,open=false,powered=false]"
      },
      {
        "char": ",",
        "block": "minecraft:white_bed[facing=north,occupied=false,part=foot]"
      },
      {
        "char": "-",
        "block": "minecraft:white_bed[facing=north,occupied=false,part=head]"
      },
      {
        "char": ".",
        "block": "minecraft:white_concrete"
      },
      {
        "char": "/",
        "block": "tfmg:asphalt"
      }
    ]
  }
}
