{
  "xsize": 16,
  "zsize": 16,
  "slices": [
    [
      "0000(((000000000",
      "0000(((000000000",
      "0000(((000000000",
      "0000(((000000000",
      "0000(((000000000",
      "0000(((000000000",
      "0000(((0000000''",
      "0000(((00000''$0",
      "0000(((00000$000",
      "0000(((000000000",
      "0000(((000000000",
      "0000(((000000000",
      "0000(((000000000",
      "0000(((000000000",
      "0000(((000000000",
      "0000(((00000000'"
    ],
    [
      "!         !!    ",
      "                ",
      "               $",
      "               $",
      "               $",
      "               $",
      "               $",
      "               $",
      "               $",
      "               $",
      "!!         !!  $",
      "!!         !!  $",
      "               $",
      "               $",
      "               $",
      "               $"
    ],
    [
      "!.........!!    ",
      "...........     ",
      "               )",
      "               -",
      "               -",
      "               -",
      "               -",
      "               -",
      " ///////////   -",
      " ///////////   -",
      "!!/////////!!  -",
      "!!/////////!!  -",
      " ///////////   -",
      " ///////////   -",
      " ///////////   -",
      " ///////////   )"
    ],
    [
      "!.... ....!!    ",
      ".....*.....     ",
      "               )",
      "               -",
      "               -",
      "               -",
      "               -",
      "               -",
      " ///////////   -",
      " ///////////   -",
      "!!/       /!!  -",
      "!!/       /!!  -",
      " //%    & //   -",
      " //       //   -",
      " //       //   -",
      " //%    & //   )"
    ],
    [
      "..... .....     ",
      ".....+.....     ",
      "               )",
      "               -",
      "               -",
      "               -",
      "               -",
      "               -",
      " ///////////   -",
      " ///////////   -",
      " //       //   -",
      " ,/       /,   -",
      " ,/       /,   -",
      " //       //   -",
      " ,/       /,   -",
      " ,/       /,   )"
    ],
    [
      "...........     ",
      "...........     ",
      "               )",
      "               -",
      "               -",
      "               -",
      "               -",
      "               -",
      " //,,,,,,,//   -",
      " ///////////   -",
      " //       //   -",
      " ,/       /,   -",
      " ,/       /,   -",
      " //       //   -",
      " ,/       /,   -",
      " ,/       /,   )"
    ]
  ],
  "palette": {
    "palette": [
      {
        "char": "!",
        "block": "minecraft:blackstone"
      },
      {
        "char": "$",
        "block": "minecraft:coarse_dirt"
      },
      {
        "char": "%",
        "block": "minecraft:dark_oak_stairs[facing=east,half=bottom,shape=straight,waterlogged=false]"
      },
      {
        "char": "&",
        "block": "minecraft:dark_oak_stairs[facing=west,half=bottom,shape=straight,waterlogged=false]"
      },
      {
        "char": "'",
        "block": "minecraft:gravel"
      },
      {
        "char": "(",
        "block": "minecraft:gray_concrete"
      },
      {
        "char": ")",
        "block": "minecraft:green_wool"
      },
      {
        "char": "*",
        "block": "minecraft:iron_door[facing=south,half=lower,hinge=left,open=false,powered=false]"
      },
      {
        "char": "+",
        "block": "minecraft:iron_door[facing=south,half=upper,hinge=left,open=false,powered=false]"
      },
      {
        "char": ",",
        "block": "minecraft:light_blue_stained_glass"
      },
      {
        "char": "-",
        "block": "minecraft:stripped_spruce_log"
      },
      {
        "char": ".",
        "block": "minecraft:white_concrete"
      },
      {
        "char": "/",
        "block": "minecraft:yellow_terracotta"
      },
      {
        "char": "0",
        "block": "tfmg:asphalt"
      }
    ]
  }
}
