{
  "xsize": 16,
  "zsize": 16,
  "slices": [
    [
      "++++++++++      ",
      "++++++++$$      ",
      "++++++$$!+      ",
      "++++$$!+++      ",
      "++$$!+++++      ",
      "$$!++++++$      ",
      "!+++++++++      ",
      "++++++++++      ",
      "++++++++++      ",
      "++++++++++      ",
      "+++++++++$      ",
      "+++++++$$$      ",
      "+++++$$!++      ",
      "+++$$!++++      ",
      "+$$!++++++      ",
      "$!++++++++      "
    ],
    [
      "                ",
      "                ",
      "!!!!!!!!!       ",
      "!!!!!!!!!       ",
      "!!!!!!!!!       ",
      "!!!!!!!!!       ",
      "!!!!!!!!!       ",
      "!!!!!!!!!       ",
      "!!!!!!!!!       ",
      "!!!!!!!!!       ",
      "!!!!!!!!!       ",
      "!!!!!!!!!       ",
      "!!!!!!!!!       ",
      "!!!!!!!!!       ",
      "!!!!!!!!!       ",
      "$!!!!!!!!       "
    ],
    [
      "                ",
      "                ",
      "%%%%%%%%%       ",
      "        (       ",
      "        (       ",
      "        (       ",
      " *      (       ",
      " )      (       ",
      "        (       ",
      "     &&&(       ",
      "     &&&(       ",
      "     &&&(       ",
      "   ' &&&(       ",
      "        (       ",
      "        (       ",
      "$%%%%%%%%       "
    ],
    [
      "                ",
      "                ",
      "%%%%%%%%%       ",
      "        (       ",
      "        (       ",
      "        (       ",
      "        (       ",
      "        (       ",
      "        (       ",
      "     &&&(       ",
      "     &&&(       ",
      "     &&&(       ",
      "     &&&(       ",
      "        (       ",
      "        (       ",
      "$%%%%%%%%       "
    ],
    [
      "                ",
      "                ",
      "                ",
      "                ",
      "                ",
      "                ",
      "                ",
      "                ",
      "                ",
      "                ",
      "     &&&(       ",
      "     &&&(       ",
      "     &&&(       ",
      "        (       ",
      "        (       ",
      "%%%%%%%%%       "
    ],
    [
      "                ",
      "                ",
      "                ",
      "                ",
      "                ",
      "                ",
      "                ",
      "                ",
      "                ",
      "                ",
      "        (       ",
      "        (       ",
      "        (       ",
      "        (       ",
      "        (       ",
      "%%%%%%%%%       "
    ]
  ],
  "palette": {
    "palette": [
      {
        "char": "!",
        "block": "minecraft:coarse_dirt"
      },
      {
        "char": "$",
        "block": "minecraft:gravel"
      },
      {
        "char": "%",
        "block": "minecraft:green_wool"
      },
      {
        "char": "&",
        "block": "minecraft:scaffolding"
      },
      {
        "char": "'",
        "block": "minecraft:spawner",
        "tag": {
          "id": "minecraft:mob_spawner",
          "Delay": 200,
          "MinSpawnDelay": 240,
          "MaxSpawnDelay": 720,
          "SpawnCount": 2,
          "MaxNearbyEntities": 6,
          "RequiredPlayerRange": 14,
          "SpawnRange": 4,
          "SpawnData": {
            "entity": {
              "id": "minecraft:pillager"
            }
          },
          "SpawnPotentials": [
            {
              "weight": 1,
              "data": {
                "entity": {
                  "id": "minecraft:pillager"
                }
              }
            }
          ]
        }
      },
      {
        "char": "(",
        "block": "minecraft:stripped_spruce_log"
      },
      {
        "char": ")",
        "block": "minecraft:white_bed[facing=north,occupied=false,part=foot]"
      },
      {
        "char": "*",
        "block": "minecraft:white_bed[facing=north,occupied=false,part=head]"
      },
      {
        "char": "+",
        "block": "tfmg:asphalt"
      }
    ]
  }
}
