{
  "xsize": 16,
  "zsize": 16,
  "slices": [
    [
      "                ",
      " 33333333333333)",
      " 333333333333))(",
      " 3333333333))(33",
      " 33333333))(3333",
      " 333333))(333333",
      " 3333))(33333333",
      " 33))(3333333333",
      " ))(333333333333",
      " (33333333333333",
      " 333333333333333",
      " 3333333333333))",
      " 33333333333))(3",
      " 333333333))(333",
      " 3333333))(33333",
      " 33333))(3333333"
    ],
    [
      "                ",
      "     1    1    1",
      "     1    1   /1",
      "     1    1    1",
      "     1    1    1",
      "     1    1    1",
      "                ",
      "   4444444444444",
      "   4444444444444",
      "   4444444444444",
      "   4444444444444",
      "   4444444444444",
      "   4444444444444",
      "   4444444444444",
      "   4444444444444",
      "   4444444444444"
    ],
    [
      "                ",
      "                ",
      "              / ",
      "                ",
      "                ",
      "                ",
      "   *  -----  *  ",
      "   *************",
      "   '+           ",
      "   '            ",
      "   ' $$ &&6   6 ",
      "   ' $$ &&6   6 ",
      "   '      6   6 ",
      "   ' !! %%      ",
      "   ' !! %%   ,  ",
      "   '         ,5 "
    ],
    [
      "                ",
      "                ",
      "              / ",
      "                ",
      "                ",
      "                ",
      "   *         *  ",
      "   *'0     0'*''",
      "   '+           ",
      "   '            ",
      "   '      2   2 ",
      "   '            ",
      "   '            ",
      "   '            ",
      "   '         ,  ",
      "   '         ,  "
    ],
    [
      "                ",
      "                ",
      "              / ",
      "                ",
      "                ",
      "                ",
      "   *         *  ",
      "   *'0     0'*''",
      "   '+           ",
      "   '            ",
      "   '            ",
      "   '            ",
      "   '            ",
      "   '            ",
      "   '            ",
      "   '            "
    ],
    [
      "                ",
      "                ",
      "              / ",
      "                ",
      "                ",
      "                ",
      "   *  .....  *  ",
      "   *'''''''''*''",
      "   '+           ",
      "   '            ",
      "   '            ",
      "   '            ",
      "   '            ",
      "   '            ",
      "   '            ",
      "   '            "
    ]
  ],
  "palette": {
    "palette": [
      {
        "char": "!",
        "block": "farmersdelight:cabbage_crate"
      },
      {
        "char": "$",
        "block": "farmersdelight:carrot_crate"
      },
      {
        "char": "%",
        "block": "farmersdelight:onion_crate"
      },
      {
        "char": "&",
        "block": "farmersdelight:potato_crate"
      },
      {
        "char": "'",
        "block": "minecraft:bricks"
      },
      {
        "char": "(",
        "block": "minecraft:coarse_dirt"
      },
      {
        "char": ")",
        "block": "minecraft:gravel"
      },
      {
        "char": "*",
        "block": "minecraft:mud_bricks"
      },
      {
        "char": "+",
        "block": "minecraft:polished_blackstone_bricks"
      },
      {
        "char": ",",
        "block": "minecraft:scaffolding"
      },
      {
        "char": "-",
        "block": "minecraft:spruce_slab[type=bottom,waterlogged=false]"
      },
      {
        "char": ".",
        "block": "minecraft:spruce_slab[type=top,waterlogged=false]"
      },
      {
        "char": "/",
        "block": "minecraft:stripped_dark_oak_log[axis=y]"
      },
      {
        "char": "0",
        "block": "minecraft:stripped_spruce_log[axis=y]"
      },
      {
        "char": "1",
        "block": "minecraft:white_concrete"
      },
      {
        "char": "2",
        "block": "supplementaries:item_shelf"
      },
      {
        "char": "3",
        "block": "tfmg:asphalt"
      },
      {
        "char": "4",
        "block": "tfmg:factory_floor"
      },
      {
        "char": "5",
        "block": "the_wasteland_reworked:cardboard_box"
      },
      {
        "char": "6",
        "block": "zvhouses:spruce_countertop"
      }
    ]
  }
}
