{
  "xsize": 16,
  "zsize": 16,
  "slices": [
    [
      "5555555**(555555",
      "55555**(55555555",
      "555**(5555555555",
      "5**(555555555555",
      "*(55555555555555",
      "5555555555555555",
      "55555555555555**",
      "555555555555**(5",
      "5555555555**(555",
      "55555555**(55555",
      "555555**(5555555",
      "5555**(555555555",
      "55**(55555555555",
      "**(5555555555555",
      "(555555555555555",
      "555555555555555*"
    ],
    [
      "7777777777777777",
      "7777777777777777",
      "7777777777777777",
      "7777777777777777",
      "7777777777777777",
      "7777777777777777",
      "7777777777777777",
      "7777777777777777",
      "7777777777777777",
      "7777777777777777",
      "7777777777777777",
      "7777777777777777",
      "7777777777777777",
      "7777777777777777",
      "                ",
      "                "
    ],
    [
      "  ,    ,    ,   ",
      "                ",
      "  ,    ,    ,   ",
      "  ,    ,    ,   ",
      "  ,!   ,!   ,!  ",
      " 8,    ,    ,   ",
      "                ",
      "6660666666666066",
      "        6     62",
      "%%   %% 6     63",
      "%%  -%% . & ) . ",
      "%%   %% 6     64",
      "        6     6 ",
      "''''''''+'''''+'",
      "        +     + ",
      "                "
    ],
    [
      "  ,    ,    ,   ",
      "                ",
      "  ,    ,    ,   ",
      "  ,    ,    ,   ",
      "  ,    ,    ,   ",
      "  ,    ,    ,   ",
      "                ",
      "6661666666666166",
      "        6     6 ",
      "%%   %% 6     6 ",
      "%%   %% /     / ",
      "%%   %% 6     6 ",
      "        6     6 ",
      "''''''''+'''''+'",
      "        +     + ",
      "                "
    ],
    [
      "                ",
      "                ",
      "                ",
      "                ",
      "                ",
      "                ",
      "                ",
      "6666666666666666",
      "        6     6 ",
      "        6     6 ",
      "        6     6 ",
      "        6     6 ",
      "        6     6 ",
      "'$$'''''+'$$''+'",
      "        +     + ",
      "                "
    ],
    [
      "                ",
      "                ",
      "                ",
      "                ",
      "                ",
      "                ",
      "                ",
      "6666666666666666",
      "        6     6 ",
      "        6     6 ",
      "        6     6 ",
      "        6     6 ",
      "        6     6 ",
      "'$$'''''+'$$''+'",
      "        +     + ",
      "                "
    ]
  ],
  "palette": {
    "palette": [
      {
        "char": "!",
        "block": "create:cardboard_block"
      },
      {
        "char": "$",
        "block": "create:framed_glass"
      },
      {
        "char": "%",
        "block": "immersiveengineering:crate"
      },
      {
        "char": "&",
        "block": "minecraft:barrel[facing=up,open=false]"
      },
      {
        "char": "'",
        "block": "minecraft:bricks"
      },
      {
        "char": "(",
        "block": "minecraft:coarse_dirt"
      },
      {
        "char": ")",
        "block": "kubejs:ruined_crafting_table"
      },
      {
        "char": "*",
        "block": "minecraft:gravel"
      },
      {
        "char": "+",
        "block": "minecraft:mud_bricks"
      },
      {
        "char": ",",
        "block": "minecraft:scaffolding"
      },
      {
        "char": "-",
        "block": "minecraft:spawner",
        "tag": {
          "id": "minecraft:mob_spawner",
          "Delay": 200,
          "MinSpawnDelay": 240,
          "MaxSpawnDelay": 720,
          "SpawnCount": 2,
          "MaxNearbyEntities": 6,
          "RequiredPlayerRange": 14,
          "SpawnRange": 4,
          "SpawnData": {
            "entity": {
              "id": "the_wasteland_reworked:ghoul"
            }
          },
          "SpawnPotentials": [
            {
              "weight": 1,
              "data": {
                "entity": {
                  "id": "the_wasteland_reworked:ghoul"
                }
              }
            }
          ]
        }
      },
      {
        "char": ".",
        "block": "minecraft:spruce_door[facing=east,half=lower,hinge=left,open=false,powered=false]"
      },
      {
        "char": "/",
        "block": "minecraft:spruce_door[facing=east,half=upper,hinge=left,open=false,powered=false]"
      },
      {
        "char": "0",
        "block": "minecraft:spruce_door[facing=south,half=lower,hinge=left,open=false,powered=false]"
      },
      {
        "char": "1",
        "block": "minecraft:spruce_door[facing=south,half=upper,hinge=left,open=false,powered=false]"
      },
      {
        "char": "2",
        "block": "minecraft:spruce_slab[type=bottom,waterlogged=false]"
      },
      {
        "char": "3",
        "block": "minecraft:spruce_stairs[facing=north,half=bottom,shape=straight,waterlogged=false]"
      },
      {
        "char": "4",
        "block": "kubejs:ruined_cauldron"
      },
      {
        "char": "5",
        "block": "tfmg:asphalt"
      },
      {
        "char": "6",
        "block": "tfmg:cinder_block"
      },
      {
        "char": "7",
        "block": "tfmg:factory_floor"
      },
      {
        "char": "8",
        "block": "the_wasteland_reworked:garbage_bag"
      }
    ]
  }
}
