{
  "xsize": 16,
  "zsize": 16,
  "slices": [
    [
      " ,,,''&,,,,,,,,,",
      " ,''&,,,,,,,,,,,",
      " '&,,,,,,,,,,,,,",
      " ,,,,,,,,,,,,,,,",
      " ,,,,,,,,,,,,,,'",
      " ,,,,,,,,,,,,''&",
      " ,,,,,,,,,,''&,,",
      " ,,,,,,,,''&,,,,",
      " ,,,,,,''&,,,,,,",
      " ,,,,''&,,,,,,,,",
      " ,,''&,,,,,,,,,,",
      " ''&,,,,,,,,,,,,",
      " &,,,,,,,,,,,,,,",
      " ,,,,,,,,,,,,,,,",
      " ,,,,,,,,,,,,,''",
      " ,,,,,,,,,,,''&,"
    ],
    [
      "   .............",
      "   .............",
      "   .............",
      "   .............",
      "   .............",
      "   .............",
      "  ''''''''''''.'",
      "  ''''''''''''''",
      "  ''''''''''''''",
      "  '''''''''''''%",
      "  ''''''''''''''",
      "  ''''''''''''''",
      "  ''''''''''''''",
      "  ''''''''''''''",
      "  ''''''''''''''",
      "  ''''''''''''''"
    ],
    [
      "   %         )  ",
      "   %            ",
      "   %   /     )  ",
      "   %         )  ",
      "   % 1111111 )! ",
      "   %  $  *   )  ",
      "   ' ''''''%''  ",
      "  '''''''''''''-",
      "  '%''''''''' ''",
      "  ''''''''''''' ",
      "  ''''''''''''''",
      "  ''''''''''''%'",
      "  ''''''''''''''",
      "  '''''''''''%''",
      "  ''''''''''0'' ",
      "   '''''''''%'''"
    ],
    [
      "   %         )  ",
      "   %            ",
      "   %         )  ",
      "   %         )  ",
      "   %         )  ",
      "   %         )  ",
      "   %  ''' '     ",
      "   %-%-''''-----",
      "   %''''''%'' - ",
      "   '% ''''''''- ",
      "   ''''''''' '' ",
      "  '%''''''''''-'",
      "  ''''''''''''''",
      "  % '''''''''%''",
      "  ''''''''''''' ",
      "   ''''''''' '  "
    ],
    [
      "   %            ",
      "   %            ",
      "   %            ",
      "   %            ",
      "   %            ",
      "   %            ",
      "   %            ",
      "   %+++++++++---",
      "   %   ' '    - ",
      "   %  ''''    - ",
      "     '' '%''  - ",
      "     '''''''' - ",
      "   '''''''' ''- ",
      "    '''''''''%(%",
      "      '%'' '  ( ",
      "      ' '''     "
    ],
    [
      "   %            ",
      "   %            ",
      "   %            ",
      "   %            ",
      "   %            ",
      "   %            ",
      "   %            ",
      "   %------------",
      "   %          - ",
      "   %          - ",
      "        '     - ",
      "       ''     - ",
      "       '%''   - ",
      "       ' '  %%(%",
      "        '     ( ",
      "                "
    ]
  ],
  "palette": {
    "palette": [
      {
        "char": "!",
        "block": "create:cardboard_block"
      },
      {
        "char": "$",
        "block": "farmersdelight:stove[facing=north,lit=false]"
      },
      {
        "char": "%",
        "block": "minecraft:bricks"
      },
      {
        "char": "&",
        "block": "minecraft:coarse_dirt"
      },
      {
        "char": "'",
        "block": "minecraft:gravel"
      },
      {
        "char": "(",
        "block": "minecraft:mud_bricks"
      },
      {
        "char": ")",
        "block": "minecraft:scaffolding"
      },
      {
        "char": "*",
        "block": "minecraft:smoker[facing=north,lit=false]"
      },
      {
        "char": "+",
        "block": "minecraft:stripped_dark_oak_log[axis=x]"
      },
      {
        "char": ",",
        "block": "tfmg:asphalt"
      },
      {
        "char": "-",
        "block": "tfmg:cinder_block"
      },
      {
        "char": ".",
        "block": "tfmg:factory_floor"
      },
      {
        "char": "/",
        "block": "the_wasteland_reworked:garbage_bag"
      },
      {
        "char": "0",
        "block": "wastelands:scrap_pile"
      },
      {
        "char": "1",
        "block": "zvhouses:stone_brick_countertop"
      }
    ]
  }
}
