{
  "xsize": 16,
  "zsize": 16,
  "slices": [
    [
      "//////          ",
      "//////          ",
      "//////          ",
      "////))          ",
      "//))$/          ",
      "))$///          ",
      "$/////          ",
      "//////          ",
      "//////          ",
      "//////          ",
      "//////          ",
      "//////          ",
      "/////)          ",
      "///))$          ",
      "/))$//          ",
      ")$////          "
    ],
    [
      "1111            ",
      "1111            ",
      "1111            ",
      "1111            ",
      "1111            ",
      "1111            ",
      "1111            ",
      "1111            ",
      "1111            ",
      "1111            ",
      "1111            ",
      "1111            ",
      "1111            ",
      "1111            ",
      "                ",
      "                "
    ],
    [
      "  -!            ",
      "   !            ",
      "  -!            ",
      "   !            ",
      "  -!            ",
      "   !            ",
      "   !            ",
      "000!            ",
      ",  !            ",
      "   !            ",
      "   !            ",
      " . !            ",
      "  +!            ",
      "%&!*            ",
      "   *            ",
      "                "
    ],
    [
      "   !            ",
      "   !            ",
      "   !            ",
      "   !            ",
      "   !            ",
      "   !            ",
      "   !            ",
      "000!            ",
      "   !            ",
      "   !            ",
      "   !            ",
      "   !            ",
      "  +!            ",
      "'(!*            ",
      "   *            ",
      "                "
    ],
    [
      "   !            ",
      "   !            ",
      "   !            ",
      "   !            ",
      "   !            ",
      "   !            ",
      "   !            ",
      "000!            ",
      "   !            ",
      "   !            ",
      "   !            ",
      "   !            ",
      "  +!            ",
      "  !*            ",
      "   *            ",
      "                "
    ],
    [
      "   !            ",
      "   !            ",
      "   !            ",
      "   !            ",
      "   !            ",
      "   !            ",
      "   !            ",
      "000!            ",
      "   !            ",
      "   !            ",
      "   !            ",
      "   !            ",
      "  +!            ",
      "!!!*            ",
      "   *            ",
      "                "
    ]
  ],
  "palette": {
    "palette": [
      {
        "char": "!",
        "block": "minecraft:bricks"
      },
      {
        "char": "$",
        "block": "minecraft:coarse_dirt"
      },
      {
        "char": "%",
        "block": "minecraft:dark_oak_door[facing=south,half=lower,hinge=left,open=false,powered=false]"
      },
      {
        "char": "&",
        "block": "minecraft:dark_oak_door[facing=south,half=lower,hinge=right,open=false,powered=false]"
      },
      {
        "char": "'",
        "block": "minecraft:dark_oak_door[facing=south,half=upper,hinge=left,open=false,powered=false]"
      },
      {
        "char": "(",
        "block": "minecraft:dark_oak_door[facing=south,half=upper,hinge=right,open=false,powered=false]"
      },
      {
        "char": ")",
        "block": "minecraft:gravel"
      },
      {
        "char": "*",
        "block": "minecraft:mud_bricks"
      },
      {
        "char": "+",
        "block": "minecraft:polished_blackstone_bricks"
      },
      {
        "char": ",",
        "block": "minecraft:spruce_slab[type=bottom,waterlogged=false]"
      },
      {
        "char": "-",
        "block": "oritech:cooler_block"
      },
      {
        "char": ".",
        "block": "supplementaries:item_shelf"
      },
      {
        "char": "/",
        "block": "tfmg:asphalt"
      },
      {
        "char": "0",
        "block": "tfmg:cinder_block"
      },
      {
        "char": "1",
        "block": "tfmg:factory_floor"
      }
    ]
  }
}
