{
  "xsize": 16,
  "zsize": 16,
  "slices": [
    [
      "..........''&...",
      "........''&.....",
      "......''&.......",
      "....''&.........",
      "..''&...........",
      "''&.............",
      "&...............",
      "...............'",
      ".............''&",
      "...........''&..",
      ".........''&....",
      ".......''&......",
      ".....''&........",
      "...''&..........",
      ".''&............",
      "'&.............."
    ],
    [
      "0000000(((((((((",
      "0000000(((((((((",
      "0000000(((((((((",
      "0000000(((((((((",
      "0000000(((((((((",
      "0000000(((((((((",
      "0000000(((((((((",
      "0000000(((((((((",
      "0000000(((((((((",
      "0000000(((((((((",
      "0000000(((((((((",
      "0000000(((((((((",
      "0000000(((((((((",
      "0000000(((((((((",
      "0000000(((((((((",
      "0000000((((((((("
    ],
    [
      "      %%  ,,    ",
      "      %%  -     ",
      "1               ",
      "1               ",
      "1               ",
      "1               ",
      "1       ////*///",
      "1               ",
      "1               ",
      "1         !!!!!)",
      "1         !!!!!!",
      "1         !!!!!!",
      "          !!!!!!",
      "      %%  !!!!!!",
      "      %%        ",
      "      %%        "
    ],
    [
      "      %%        ",
      "      %%        ",
      "1               ",
      "1               ",
      "1               ",
      "1               ",
      "1       ////+///",
      "1               ",
      "1               ",
      "1         !!!!!!",
      "1         !!!!!!",
      "1         !!!!!!",
      "          !!!!!!",
      "      %%  !!!!!!",
      "      %%        ",
      "      %%        "
    ],
    [
      "      %%        ",
      "      %%        ",
      "$               ",
      "$               ",
      "$               ",
      "$               ",
      "$       ////////",
      "$               ",
      "$               ",
      "$         !!!!!!",
      "$         !!!!!!",
      "$         !!!!!!",
      "          !!!!!!",
      "      %%  !!!!!!",
      "      %%        ",
      "      %%        "
    ],
    [
      "      %%        ",
      "      %%        ",
      "$               ",
      "$               ",
      "$               ",
      "$               ",
      "$       ////////",
      "$               ",
      "$               ",
      "$         !!!!!!",
      "$         !!!!!!",
      "$         !!!!!!",
      "          !!!!!!",
      "      %%  !!!!!!",
      "      %%        ",
      "      %%        "
    ]
  ],
  "palette": {
    "palette": [
      {
        "char": "!",
        "block": "immersiveengineering:capacitor_mv"
      },
      {
        "char": "$",
        "block": "immersiveengineering:sheetmetal_steel"
      },
      {
        "char": "%",
        "block": "minecraft:bricks"
      },
      {
        "char": "&",
        "block": "minecraft:coarse_dirt"
      },
      {
        "char": "'",
        "block": "minecraft:gravel"
      },
      {
        "char": "(",
        "block": "minecraft:smooth_stone"
      },
      {
        "char": ")",
        "block": "minecraft:spawner",
        "tag": {
          "id": "minecraft:mob_spawner",
          "Delay": 200,
          "MinSpawnDelay": 240,
          "MaxSpawnDelay": 720,
          "SpawnCount": 3,
          "MaxNearbyEntities": 8,
          "RequiredPlayerRange": 14,
          "SpawnRange": 4,
          "SpawnData": {
            "entity": {
              "id": "minecraft:pillager"
            }
          },
          "SpawnPotentials": [
            {
              "weight": 1,
              "data": {
                "entity": {
                  "id": "minecraft:pillager"
                }
              }
            }
          ]
        }
      },
      {
        "char": "*",
        "block": "minecraft:spruce_door[facing=south,half=lower,hinge=left,open=false,powered=false]"
      },
      {
        "char": "+",
        "block": "minecraft:spruce_door[facing=south,half=upper,hinge=left,open=false,powered=false]"
      },
      {
        "char": ",",
        "block": "minecraft:spruce_slab[type=bottom,waterlogged=false]"
      },
      {
        "char": "-",
        "block": "minecraft:spruce_stairs[facing=north,half=bottom,shape=straight,waterlogged=false]"
      },
      {
        "char": ".",
        "block": "tfmg:asphalt"
      },
      {
        "char": "/",
        "block": "tfmg:cinder_block"
      },
      {
        "char": "0",
        "block": "tfmg:factory_floor"
      },
      {
        "char": "1",
        "block": "tfmg:steel_block"
      }
    ]
  }
}
