{
  "xsize": 16,
  "zsize": 16,
  "slices": [
    [
      "            $   ",
      "            $   ",
      "            $   ",
      "            $   ",
      "            $   ",
      "            $   ",
      "            $   ",
      "            $   ",
      "            $   ",
      "!!!!!!!!!!  $   ",
      "!!!!!!!!!!  $   ",
      "!!!!!!!!!!  $   ",
      "!!!!!!!!!!  $   ",
      "!!!!!!!!!!  $   ",
      "            $   ",
      "            $   "
    ],
    [
      "            $   ",
      "            $   ",
      "            $   ",
      "            $   ",
      "            $   ",
      "            $   ",
      "            $   ",
      "            $   ",
      "            $   ",
      "!!!!!!!!!!  $   ",
      "!!!!!!!!!!  $   ",
      "!!!!!!!!!!  $   ",
      "!!!!!!!!!!  $   ",
      "!!!!!!!!!!  $   ",
      "            $   ",
      "            $   "
    ],
    [
      "            $   ",
      "            $   ",
      "            $   ",
      "            $   ",
      "            $   ",
      "            $   ",
      "            $   ",
      "            $   ",
      "            $   ",
      "            $   ",
      "            $   ",
      "            $   ",
      "            $   ",
      "            $   ",
      "            $   ",
      "            $   "
    ],
    [
      "            $   ",
      "            $   ",
      "            $   ",
      "            $   ",
      "            $   ",
      "            $   ",
      "            $   ",
      "            $   ",
      "            $   ",
      "            $   ",
      "            $   ",
      "            $   ",
      "            $   ",
      "            $   ",
      "            $   ",
      "            $   "
    ],
    [
      "            $   ",
      "            $   ",
      "            $   ",
      "            $   ",
      "            $   ",
      "            $   ",
      "            $   ",
      "            $   ",
      "            $   ",
      "            $   ",
      "            $   ",
      "            $   ",
      "            $   ",
      "            $   ",
      "            $   ",
      "            $   "
    ],
    [
      "            $   ",
      "            $   ",
      "            $   ",
      "            $   ",
      "            $   ",
      "            $   ",
      "            $   ",
      "            $   ",
      "            $   ",
      "            $   ",
      "            $   ",
      "            $   ",
      "            $   ",
      "            $   ",
      "            $   ",
      "            $   "
    ]
  ],
  "palette": {
    "palette": [
      {
        "char": "!",
        "block": "immersiveengineering:capacitor_mv"
      },
      {
        "char": "$",
        "block": "minecraft:bricks"
      }
    ]
  }
}
