{
  "xsize": 16,
  "zsize": 16,
  "slices": [
    [
      "                ",
      "                ",
      "               $",
      "                ",
      "                ",
      "                ",
      "                ",
      "                ",
      "                ",
      "                ",
      "                ",
      "          !!!!  ",
      "          !!!!  ",
      "          !!!!  ",
      "          !!!!  ",
      "                "
    ],
    [
      "                ",
      "                ",
      "                ",
      "               $",
      "                ",
      "                ",
      "                ",
      "                ",
      "                ",
      "                ",
      "                ",
      "          !!!!  ",
      "          !!!!  ",
      "          !!!!  ",
      "          !!!!  ",
      "                "
    ],
    [
      "                ",
      "                ",
      "                ",
      "                ",
      "               $",
      "                ",
      "                ",
      "                ",
      "                ",
      "                ",
      "                ",
      "          !!!!  ",
      "          !!!!  ",
      "          !!!!  ",
      "          !!!!  ",
      "                "
    ],
    [
      "                ",
      "                ",
      "                ",
      "                ",
      "                ",
      "               $",
      "                ",
      "                ",
      "                ",
      "                ",
      "                ",
      "          !!!!  ",
      "          !!!!  ",
      "          !!!!  ",
      "          !!!!  ",
      "                "
    ],
    [
      "                ",
      "                ",
      "                ",
      "                ",
      "                ",
      "                ",
      "               $",
      "                ",
      "                ",
      "                ",
      "                ",
      "          !!!!  ",
      "          !!!!  ",
      "          !!!!  ",
      "          !!!!  ",
      "                "
    ],
    [
      "!!!!!!!!!!!!!!!!",
      "!!!!!!!!!!!!!!!!",
      "!!!!!!!!!!!!!!!!",
      "!!!!!!!!!!!!!!!!",
      "!!!!!!!!!!!!!!!!",
      "!!!!!!!!!!!!!!! ",
      "!!!!!!!!!!!!!!! ",
      "!!!!!!!!!!!!!!!$",
      "!!!!!!!!!!!!!!!!",
      "!!!!!!!!!!!!!!!!",
      "!!!!!!!!!!!!!!!!",
      "!!!!!!!!!!!!!!!!",
      "!!!!!!!!!!!!!!!!",
      "!!!!!!!!!!!!!!!!",
      "!!!!!!!!!!!!!!!!",
      "!!!!!!!!!!!!!!!!"
    ]
  ],
  "palette": {
    "palette": [
      {
        "char": "!",
        "block": "immersiveengineering:concrete_reinforced"
      },
      {
        "char": "$",
        "block": "minecraft:stone_brick_stairs[facing=south,half=bottom,shape=straight,waterlogged=false]"
      }
    ]
  }
}
