{
  "xsize": 16,
  "zsize": 16,
  "slices": [
    [
      ",,,,,,,%%$,,,,,,",
      ",,,,,%%$,,,,,,,,",
      ",,,%%$,,,,,,,,,,",
      ",%%$,,,,,,,,,,,,",
      "%$,,,,,,,,,,,,,,",
      ",,,,,,,,,,,,,,,,",
      ",,,,,,,,,,,,,,%%",
      ",,,,,,,,,,,,%%$,",
      ",,,,,,,,,,%%$,,,",
      ",,,,,,,,%%$,,,,,",
      ",,,,,,%%$,,,,,,,",
      ",,,,%%$,,,,,,,,,",
      ",,%%$,,,,,,,,,,,",
      "%%$,,,,,,,,,,,,,",
      "$,,,,,,,,,,,,,,,",
      ",,,,,,,,,,,,,,,%"
    ],
    [
      "----------------",
      "----------------",
      "----------------",
      "----------------",
      "----------------",
      "----------------",
      "----------------",
      "----------------",
      "----------------",
      "----------------",
      "----------------",
      "----------------",
      "----------------",
      "----------------",
      "----------------",
      "----------------"
    ],
    [
      " +   '         (",
      " *   &         (",
      " )             (",
      " )             (",
      " )             (",
      " )             (",
      " +   '         (",
      " *   &         (",
      " )             (",
      " )             (",
      " )             (",
      " )             (",
      " +   '         (",
      " *   &         (",
      " )             (",
      " )             ("
    ],
    [
      " )             (",
      " )             (",
      " )             (",
      " )             (",
      " )             (",
      " )             (",
      " )             (",
      " )             (",
      " )             (",
      " )             (",
      " )             (",
      " )             (",
      " )             (",
      " )             (",
      " )             (",
      " )             ("
    ],
    [
      " )             (",
      " )             (",
      " )             (",
      " )             (",
      " )             (",
      " )             (",
      " )             (",
      " )             (",
      " )             (",
      " )             (",
      " )             (",
      " )             (",
      " )             (",
      " )             (",
      " )             (",
      " )             ("
    ],
    [
      " )             (",
      " )             (",
      " )!            !",
      " )!            !",
      " )             (",
      " )             (",
      " )             (",
      " )             (",
      " )             (",
      " )             (",
      " )             (",
      " )             (",
      " )             (",
      " )!            !",
      " )!            !",
      " )             ("
    ]
  ],
  "palette": {
    "palette": [
      {
        "char": "!",
        "block": "create:framed_glass"
      },
      {
        "char": "$",
        "block": "minecraft:coarse_dirt"
      },
      {
        "char": "%",
        "block": "minecraft:gravel"
      },
      {
        "char": "&",
        "block": "minecraft:gray_bed[facing=north,occupied=false,part=foot]"
      },
      {
        "char": "'",
        "block": "minecraft:gray_bed[facing=north,occupied=false,part=head]"
      },
      {
        "char": "(",
        "block": "minecraft:light_gray_concrete"
      },
      {
        "char": ")",
        "block": "minecraft:smooth_stone"
      },
      {
        "char": "*",
        "block": "minecraft:white_bed[facing=north,occupied=false,part=foot]"
      },
      {
        "char": "+",
        "block": "minecraft:white_bed[facing=north,occupied=false,part=head]"
      },
      {
        "char": ",",
        "block": "tfmg:asphalt"
      },
      {
        "char": "-",
        "block": "tfmg:factory_floor"
      }
    ]
  }
}
