{
  "xsize": 16,
  "zsize": 16,
  "slices": [
    [
      " ...%%$.........",
      " .%%$...........",
      " %$.............",
      " ...............",
      " ..............%",
      " $...........%%$",
      " ..........%%$..",
      " ........%%$....",
      " ......%%$......",
      " ....%%$........",
      " ..%%$..........",
      " $%$............",
      " $..............",
      " ...............",
      " .............%%",
      " ...........%%$."
    ],
    [
      "    000000000000",
      "    000000000000",
      "    000000000000",
      "    000000000000",
      "    000000000000",
      "    000000000000",
      "    000000000000",
      "    000000000000",
      "    000000000000",
      "    000000000000",
      "    000000000000",
      "    000000000000",
      "    000000000000",
      "    000000000000",
      "    000000000000",
      "    000000000000"
    ],
    [
      "    ( -   '    /",
      "    ( ,   &    /",
      "    (          *",
      "    (          /",
      "    (          /",
      "    (          /",
      "    ( -   '    /",
      "    ( ,   &    /",
      "    (          /",
      "    (      )   /",
      "    (          /",
      "    (          /",
      "    ( -   '    /",
      "    ( ,   &    /",
      "    (          /",
      "    (          /"
    ],
    [
      "    (          /",
      "    (          /",
      "    (          +",
      "    (          /",
      "    (          /",
      "    (          /",
      "    (          /",
      "    (          /",
      "    (          /",
      "    (          /",
      "    (          /",
      "    (          /",
      "    (          /",
      "    (          /",
      "    (          /",
      "    (          /"
    ],
    [
      "    (          /",
      "    (          /",
      "    (          /",
      "    !          /",
      "    !          /",
      "    (          /",
      "    (          /",
      "    (          /",
      "    (          /",
      "    (          /",
      "    (          /",
      "    !          /",
      "    !          /",
      "    (          /",
      "    (          /",
      "    (          /"
    ],
    [
      "    (          /",
      "    (          /",
      "    (          /",
      "    !          /",
      "    !          /",
      "    (          /",
      "    (          /",
      "    (          /",
      "    (          /",
      "    (          /",
      "    (          /",
      "    !          /",
      "    !          /",
      "    (          /",
      "    (          /",
      "    (          /"
    ]
  ],
  "palette": {
    "palette": [
      {
        "char": "!",
        "block": "create:framed_glass"
      },
      {
        "char": "$",
        "block": "minecraft:coarse_dirt"
      },
      {
        "char": "%",
        "block": "minecraft:gravel"
      },
      {
        "char": "&",
        "block": "minecraft:gray_bed[facing=north,occupied=false,part=foot]"
      },
      {
        "char": "'",
        "block": "minecraft:gray_bed[facing=north,occupied=false,part=head]"
      },
      {
        "char": "(",
        "block": "minecraft:light_gray_concrete"
      },
      {
        "char": ")",
        "block": "minecraft:spawner",
        "tag": {
          "id": "minecraft:mob_spawner",
          "Delay": 200,
          "MinSpawnDelay": 240,
          "MaxSpawnDelay": 720,
          "SpawnCount": 2,
          "MaxNearbyEntities": 7,
          "RequiredPlayerRange": 14,
          "SpawnRange": 4,
          "SpawnData": {
            "entity": {
              "id": "minecraft:pillager"
            }
          },
          "SpawnPotentials": [
            {
              "weight": 1,
              "data": {
                "entity": {
                  "id": "minecraft:pillager"
                }
              }
            }
          ]
        }
      },
      {
        "char": "*",
        "block": "minecraft:spruce_door[facing=east,half=lower,hinge=left,open=false,powered=false]"
      },
      {
        "char": "+",
        "block": "minecraft:spruce_door[facing=east,half=upper,hinge=left,open=false,powered=false]"
      },
      {
        "char": ",",
        "block": "minecraft:white_bed[facing=north,occupied=false,part=foot]"
      },
      {
        "char": "-",
        "block": "minecraft:white_bed[facing=north,occupied=false,part=head]"
      },
      {
        "char": ".",
        "block": "tfmg:asphalt"
      },
      {
        "char": "/",
        "block": "tfmg:cinder_block"
      },
      {
        "char": "0",
        "block": "tfmg:factory_floor"
      }
    ]
  }
}
