{
  "xsize": 16,
  "zsize": 16,
  "slices": [
    [
      "0000000000000000",
      "00000000000000&&",
      "000000000000&&%0",
      "0000000000&&%000",
      "00000000&&%00000",
      "000000&&%0000000",
      "0000&&%000000000",
      "00&&%0000000000&",
      "&&%0000000000000",
      "%0000%0000%00000",
      "                ",
      "                ",
      "                ",
      "                ",
      "                ",
      "                "
    ],
    [
      "2222222222222   ",
      "2222222222222   ",
      "2222222222222   ",
      "2222222222222   ",
      "2222222222222   ",
      "2222222222222   ",
      "2222222222222   ",
      "                ",
      "                ",
      "                ",
      "                ",
      "                ",
      "                ",
      "                ",
      "                ",
      "                "
    ],
    [
      "1111111-1111(   ",
      "   1        (   ",
      "   1      **(   ",
      "   +/ )/ )$*(   ",
      "   1      **(   ",
      "   1        (   ",
      "(((((((((((((   ",
      "                ",
      "                ",
      "                ",
      "                ",
      "                ",
      "                ",
      "                ",
      "                ",
      "                "
    ],
    [
      "1111111.1111(   ",
      "   1        (   ",
      "   1      **(   ",
      "   ,      **(   ",
      "   1  '  '**(   ",
      "   1        (   ",
      "(((((((((((((   ",
      "                ",
      "                ",
      "                ",
      "                ",
      "                ",
      "                ",
      "                ",
      "                ",
      "                "
    ],
    [
      "111111111111(   ",
      "   1        (   ",
      "   1      **(   ",
      "   1      **!   ",
      "   1      **!   ",
      "   1        (   ",
      "(((((((((((((   ",
      "                ",
      "                ",
      "                ",
      "                ",
      "                ",
      "                ",
      "                ",
      "                ",
      "                "
    ],
    [
      "111111111111(   ",
      "   1        (   ",
      "   1      **(   ",
      "   1      **!   ",
      "   1      **!   ",
      "   1        (   ",
      "(((((((((((((   ",
      "                ",
      "                ",
      "                ",
      "                ",
      "                ",
      "                ",
      "                ",
      "                ",
      "                "
    ]
  ],
  "palette": {
    "palette": [
      {
        "char": "!",
        "block": "create:framed_glass"
      },
      {
        "char": "$",
        "block": "minecraft:chest[facing=north,type=single,waterlogged=false]",
        "tag": {
          "id": "minecraft:chest",
          "LootTable": "infinite_domain:chests/wasteland_home"
        }
      },
      {
        "char": "%",
        "block": "minecraft:coarse_dirt"
      },
      {
        "char": "&",
        "block": "minecraft:gravel"
      },
      {
        "char": "'",
        "block": "minecraft:lever[face=wall,facing=south,powered=false]"
      },
      {
        "char": "(",
        "block": "minecraft:light_gray_concrete"
      },
      {
        "char": ")",
        "block": "minecraft:quartz_stairs[facing=north,half=bottom,shape=straight,waterlogged=false]"
      },
      {
        "char": "*",
        "block": "minecraft:scaffolding"
      },
      {
        "char": "+",
        "block": "minecraft:spruce_door[facing=east,half=lower,hinge=left,open=false,powered=false]"
      },
      {
        "char": ",",
        "block": "minecraft:spruce_door[facing=east,half=upper,hinge=left,open=false,powered=false]"
      },
      {
        "char": "-",
        "block": "minecraft:spruce_door[facing=south,half=lower,hinge=left,open=false,powered=false]"
      },
      {
        "char": ".",
        "block": "minecraft:spruce_door[facing=south,half=upper,hinge=left,open=false,powered=false]"
      },
      {
        "char": "/",
        "block": "minecraft:water_cauldron[level=2]"
      },
      {
        "char": "0",
        "block": "tfmg:asphalt"
      },
      {
        "char": "1",
        "block": "tfmg:cinder_block"
      },
      {
        "char": "2",
        "block": "tfmg:factory_floor"
      }
    ]
  }
}
