{
  "xsize": 16,
  "zsize": 16,
  "slices": [
    [
      "         !!!!!! ",
      "         !!!!!! ",
      "         !!!!!! ",
      "         !!!!!! ",
      "         !!!!!! ",
      "         !!!!!! ",
      "         !!!!!! ",
      "         !!!!!! ",
      "         !!!!!! ",
      "         !!!!!! ",
      "         !!!!!! ",
      "         !!!!!! ",
      "         !!!!!! ",
      "         !!!!!! ",
      "         !!!!!! ",
      "         !!!!!! "
    ],
    [
      "   $$$$$$!!!!!! ",
      "   $$$$$$!!!!!! ",
      "   $$$$$$!!!!!! ",
      "   $$$$$$!!!!!! ",
      "   $$$$$$!!!!!! ",
      "   $$$$$$!!!!!! ",
      "   $$$$$$!!!!!! ",
      "   $$$$$$!!!!!! ",
      "   $$$$$$!!!!!! ",
      "   $$$$$$!!!!!! ",
      "   $$$$$$!!!!!! ",
      "   $$$$$$!!!!!! ",
      "   $$$$$$!!!!!! ",
      "   $$$$$$!!!!!! ",
      "   $$$$$$!!!!!! ",
      "   $$$$$$!!!!!! "
    ],
    [
      "   $$$$$$       ",
      "   $$$$$$       ",
      "   $$$$$$       ",
      "   $$$$$$       ",
      "   $$$$$$       ",
      "   $$$$$$       ",
      "   $$$$$$       ",
      "   $$$$$$       ",
      "   $$$$$$       ",
      "   $$$$$$       ",
      "   $$$$$$       ",
      "   $$$$$$       ",
      "   $$$$$$       ",
      "   $$$$$$       ",
      "   $$$$$$       ",
      "   $$$$$$       "
    ],
    [
      "   $$$$$$       ",
      "   $$$$$$       ",
      "   $$$$$$       ",
      "   $$$$$$       ",
      "   $$$$$$       ",
      "   $$$$$$       ",
      "   $$$$$$       ",
      "   $$$$$$       ",
      "   $$$$$$       ",
      "   $$$$$$       ",
      "   $$$$$$       ",
      "   $$$$$$       ",
      "   $$$$$$       ",
      "   $$$$$$       ",
      "   $$$$$$       ",
      "   $$$$$$       "
    ],
    [
      "   $$$$$$       ",
      "   $$$$$$       ",
      "   $$$$$$       ",
      "   $$$$$$       ",
      "   $$$$$$       ",
      "   $$$$$$       ",
      "   $$$$$$       ",
      "   $$$$$$       ",
      "   $$$$$$       ",
      "   $$$$$$       ",
      "   $$$$$$       ",
      "   $$$$$$       ",
      "   $$$$$$       ",
      "   $$$$$$       ",
      "   $$$$$$       ",
      "   $$$$$$       "
    ],
    [
      "                ",
      "                ",
      "                ",
      "                ",
      "                ",
      "                ",
      "                ",
      "                ",
      "%%              ",
      "%%              ",
      "%%              ",
      "%%              ",
      "%%              ",
      "%%              ",
      "%%              ",
      "%%              "
    ]
  ],
  "palette": {
    "palette": [
      {
        "char": "!",
        "block": "minecraft:coarse_dirt"
      },
      {
        "char": "$",
        "block": "minecraft:dirt"
      },
      {
        "char": "%",
        "block": "tfmg:factory_floor"
      }
    ]
  }
}
