{
  "xsize": 16,
  "zsize": 16,
  "slices": [
    [
      "                ",
      "                ",
      "                ",
      "                ",
      "                ",
      "     %%%%%%%%%%%",
      "     %%%%%%%%%%%",
      "     %%%%%%%%%%%",
      "     %%%%%%%%%%%",
      "     %%%%%%%%%%%",
      "     %%%%%%%%%%%",
      "     %%%%%%%%%%%",
      "                ",
      "                ",
      "                ",
      "               $"
    ],
    [
      "                ",
      "                ",
      "                ",
      "                ",
      "                ",
      "     %%       !!",
      "     %%       ! ",
      "     %%%%%%%%%! ",
      "     %%%%%%%%%! ",
      "     %%%%%%%%%! ",
      "     %%%%%%%%%! ",
      "     %%%%%%%%%!!",
      "                ",
      "                ",
      "                ",
      "               $"
    ],
    [
      "                ",
      "                ",
      "                ",
      "                ",
      "                ",
      "     %%       !!",
      "     %%       ! ",
      "     %%%%%%%%%! ",
      "     %%%%%%%%%! ",
      "     %%%%%%%%%! ",
      "     %%%%%%%%%! ",
      "     %%%%%%%%%!!",
      "                ",
      "                ",
      "                ",
      "                "
    ],
    [
      "                ",
      "                ",
      "                ",
      "                ",
      "                ",
      "     %%       !!",
      "     %%       ! ",
      "     %%%%%%%%%! ",
      "     %%%%%%%%%! ",
      "     %%%%%%%%%! ",
      "     %%%%%%%%%! ",
      "     %%%%%%%%%!!",
      "                ",
      "                ",
      "                ",
      "                "
    ],
    [
      "                ",
      "                ",
      "                ",
      "                ",
      "                ",
      "     %%       !!",
      "     %%       ! ",
      "     %%%%%%%%%! ",
      "     %%%%%%%%%! ",
      "     %%%%%%%%%! ",
      "     %%%%%%%%%! ",
      "     %%%%%%%%%!!",
      "                ",
      "                ",
      "                ",
      "                "
    ],
    [
      "                ",
      "                ",
      "                ",
      "                ",
      "                ",
      "     %%%%%%%%%!!",
      "     %%%%%%%%%! ",
      "     %%%%%%%%%! ",
      "     %%%%%%%%%! ",
      "     %%%%%%%%%! ",
      "     %%%%%%%%%! ",
      "     %%%%%%%%%!!",
      "                ",
      "                ",
      "                ",
      "                "
    ]
  ],
  "palette": {
    "palette": [
      {
        "char": "!",
        "block": "create:framed_glass"
      },
      {
        "char": "$",
        "block": "minecraft:polished_blackstone"
      },
      {
        "char": "%",
        "block": "minecraft:yellow_concrete"
      }
    ]
  }
}
