{
  "xsize": 16,
  "zsize": 16,
  "slices": [
    [
      "                ",
      "                ",
      "                ",
      "                ",
      "                ",
      "                ",
      "                ",
      "                ",
      "                ",
      "                ",
      "                ",
      "                ",
      "                ",
      "                ",
      "                ",
      "                "
    ],
    [
      "$$$$            ",
      "$$$$            ",
      "$$$$            ",
      "$$$$            ",
      "$$$$            ",
      "$$$$            ",
      "$$$$            ",
      "$$$$            ",
      "$$$$            ",
      "$$$$            ",
      "$$$$            ",
      "$$$$            ",
      "$$$$            ",
      "$$$$            ",
      "$$$$            ",
      "                "
    ],
    [
      "                ",
      "                ",
      "%%%%%%%%%       ",
      "%%%%%%%%%       ",
      "%%%%%%%%%       ",
      "%%%%%%%%%       ",
      "%%%%%%%%%       ",
      "%%%%%%%%%       ",
      "%%%%%%%%%       ",
      "%%%%%%%%%       ",
      "%%%%%%%%%       ",
      "%%%%%%%%%       ",
      "%%%%%%%%%       ",
      "%%%%%%%%%       ",
      "                ",
      "                "
    ],
    [
      "                ",
      "                ",
      "%%%%%%%%%       ",
      "%%%%%%%%%       ",
      "%%%%%%%%%       ",
      "%%%%%%%%%       ",
      "%%%%%%%%%       ",
      "%%%%%%%%%       ",
      "%%%%%%%%%       ",
      "%%%%%%%%%       ",
      "%%%%%%%%%       ",
      "%%%%%%%%%       ",
      "%%%%%%%%%       ",
      "%%%%%%%%%       ",
      "                ",
      "                "
    ],
    [
      "                ",
      "                ",
      "%%%%%%%%%       ",
      "%%%%%%%%%       ",
      "%%%%%%%%%       ",
      "%%%%%%%%%       ",
      "%%%%%%%%%       ",
      "%%%%%%%%%       ",
      "%%%%%%%%%       ",
      "%%%%%%%%%       ",
      "%%%%%%%%%       ",
      "%%%%%%%%%       ",
      "%%%%%%%%%       ",
      "%%%%%%%%%       ",
      "                ",
      "!!!!            "
    ],
    [
      "!!!             ",
      "!!!             ",
      "%%%%%%%%%       ",
      "%%%%%%%%%       ",
      "%%%%%%%%%       ",
      "%%%%%%%%%       ",
      "%%%%%%%%%       ",
      "%%%%%%%%%       ",
      "%%%%%%%%%       ",
      "%%%%%%%%%       ",
      "%%%%%%%%%       ",
      "%%%%%%%%%       ",
      "%%%%%%%%%       ",
      "%%%%%%%%%       ",
      "                ",
      "                "
    ]
  ],
  "palette": {
    "palette": [
      {
        "char": "!",
        "block": "minecraft:coarse_dirt"
      },
      {
        "char": "$",
        "block": "minecraft:deepslate"
      },
      {
        "char": "%",
        "block": "minecraft:gravel"
      }
    ]
  }
}
