{
  "xsize": 16,
  "zsize": 16,
  "slices": [
    [
      "5555555**&555555",
      "55555**&55555555",
      "555**&5555555555",
      "5**&555555555555",
      "*&55555555555555",
      "5555555555555555",
      "55555555555555**",
      "555555555555**&5",
      "5555555555**&555",
      "55555555**&55555",
      "555555**&5555555",
      "5555**&555555555",
      "55**&55555555555",
      "**&5555555555555",
      "&555555555555555",
      "555555555555555*"
    ],
    [
      "777777777777,,,,",
      "777777777777,,,,",
      "777777777777,,,,",
      "777777777777,,,,",
      "777777777777,,,,",
      "777777777777,,,,",
      "777777777777,,,,",
      "777777777777,,,,",
      "777777777777,,,,",
      "777777777777,,,,",
      "777777777777,,,,",
      "777777777777,,,,",
      "777777777777,,,,",
      "777777777777,,,,",
      "777777777777,,,,",
      "777777777777,,,,"
    ],
    [
      "444         + - ",
      "444         +   ",
      "444         (   ",
      "444         +   ",
      "44$         +   ",
      "444         +   ",
      "            +   ",
      "            +661",
      "            +   ",
      "166666661666+   ",
      "    6       +   ",
      " '  6  3  % +   ",
      "    /       +   ",
      "    6       +   ",
      "888 6 !!!!! +   ",
      "   +6      ++   "
    ],
    [
      "444         6   ",
      "444         6 - ",
      "444         )   ",
      "444         6   ",
      "444         6   ",
      "444         6   ",
      "            6   ",
      "            6662",
      "            6   ",
      "2666666626666   ",
      "    6       6   ",
      "    6       6   ",
      "    0       6   ",
      "    6       6   ",
      "888 6 !!!!! 6   ",
      "   +6      +6   "
    ],
    [
      "444         6   ",
      "444         6   ",
      "444           - ",
      "444         6   ",
      "444         6   ",
      "444         6   ",
      "            6   ",
      "            6666",
      "            6   ",
      "6666666666666   ",
      "    6       6   ",
      "    6       6   ",
      "    6       6   ",
      "    6       6   ",
      "    6 !!!!! 6   ",
      "   +6      +6   "
    ],
    [
      "..          6   ",
      "..          6   ",
      "            6   ",
      "            6 - ",
      "            6   ",
      "            6   ",
      "            6   ",
      "            6666",
      "            6   ",
      "6666666666666   ",
      "    6       6   ",
      "    6       6   ",
      "    6       6   ",
      "    6       6   ",
      "    6       6   ",
      "   +6      +6   "
    ]
  ],
  "palette": {
    "palette": [
      {
        "char": "!",
        "block": "immersiveengineering:sheetmetal_steel"
      },
      {
        "char": "$",
        "block": "minecraft:black_concrete"
      },
      {
        "char": "%",
        "block": "minecraft:cauldron"
      },
      {
        "char": "&",
        "block": "minecraft:coarse_dirt"
      },
      {
        "char": "'",
        "block": "minecraft:crafting_table"
      },
      {
        "char": "(",
        "block": "minecraft:dark_oak_door[facing=east,half=lower,hinge=left,open=false,powered=false]"
      },
      {
        "char": ")",
        "block": "minecraft:dark_oak_door[facing=east,half=upper,hinge=left,open=false,powered=false]"
      },
      {
        "char": "*",
        "block": "minecraft:gravel"
      },
      {
        "char": "+",
        "block": "minecraft:mud_bricks"
      },
      {
        "char": ",",
        "block": "minecraft:polished_andesite"
      },
      {
        "char": "-",
        "block": "minecraft:polished_andesite_stairs[facing=south,half=bottom,shape=straight,waterlogged=false]"
      },
      {
        "char": ".",
        "block": "minecraft:red_concrete"
      },
      {
        "char": "/",
        "block": "minecraft:spruce_door[facing=east,half=lower,hinge=left,open=false,powered=false]"
      },
      {
        "char": "0",
        "block": "minecraft:spruce_door[facing=east,half=upper,hinge=left,open=false,powered=false]"
      },
      {
        "char": "1",
        "block": "minecraft:spruce_door[facing=south,half=lower,hinge=left,open=false,powered=false]"
      },
      {
        "char": "2",
        "block": "minecraft:spruce_door[facing=south,half=upper,hinge=left,open=false,powered=false]"
      },
      {
        "char": "3",
        "block": "minecraft:water_cauldron[level=2]"
      },
      {
        "char": "4",
        "block": "minecraft:white_concrete"
      },
      {
        "char": "5",
        "block": "tfmg:asphalt"
      },
      {
        "char": "6",
        "block": "tfmg:cinder_block"
      },
      {
        "char": "7",
        "block": "tfmg:factory_floor"
      },
      {
        "char": "8",
        "block": "zvhouses:stone_brick_countertop"
      }
    ]
  }
}
