{
  "xsize": 16,
  "zsize": 16,
  "slices": [
    [
      ",,,,,,,,,,,,,&&%",
      ",,,,,,,,,,,,,,,,",
      ",,,,,,,,,,,,,,,,",
      ",,,,,,,,,,,,,,,,",
      ",,,,,,,,,,,,,,,,",
      ",,,,,,,,,,,,,,,,",
      ",,,,,,,,,,,,,,,,",
      ",,,,,,,,,,,,,,,,",
      ",,,,,,,,,,,,,,,,",
      "                ",
      "                ",
      "                ",
      "                ",
      "                ",
      "                ",
      "                "
    ],
    [
      "............))))",
      "                ",
      "                ",
      "*****        !!!",
      "*****        !!!",
      "*****  +  +  !!!",
      "*****        !!!",
      "*****        !!!",
      "                ",
      "                ",
      "                ",
      "                ",
      "                ",
      "                ",
      "                ",
      "                "
    ],
    [
      "$$$($$$$$$$(----",
      "   (       (    ",
      "                ",
      "             !!'",
      "!!!!         !!!",
      "!!!!         !!!",
      "!!!!         !!!",
      "             !!!",
      "                ",
      "                ",
      "                ",
      "                ",
      "                ",
      "                ",
      "                ",
      "                "
    ],
    [
      "$$$($$$$$$$(----",
      "   (       (    ",
      "                ",
      "             !!!",
      "!!!!         !!!",
      "!!!!         !!!",
      "!!!!         !!!",
      "             !!!",
      "                ",
      "                ",
      "                ",
      "                ",
      "                ",
      "                ",
      "                ",
      "                "
    ],
    [
      "$$$($$$$$$$(----",
      "   (       (    ",
      "                ",
      "                ",
      "!!!!            ",
      "!!!!            ",
      "!!!!            ",
      "                ",
      "                ",
      "                ",
      "                ",
      "                ",
      "                ",
      "                ",
      "                ",
      "                "
    ],
    [
      "$$$($$$$$$$(----",
      "   (       (    ",
      "                ",
      "                ",
      "                ",
      "                ",
      "                ",
      "                ",
      "                ",
      "                ",
      "                ",
      "                ",
      "                ",
      "                ",
      "                ",
      "                "
    ]
  ],
  "palette": {
    "palette": [
      {
        "char": "!",
        "block": "immersiveengineering:sheetmetal_steel"
      },
      {
        "char": "$",
        "block": "minecraft:bricks"
      },
      {
        "char": "%",
        "block": "minecraft:coarse_dirt"
      },
      {
        "char": "&",
        "block": "minecraft:gravel"
      },
      {
        "char": "'",
        "block": "minecraft:lever[face=wall,facing=north,powered=false]"
      },
      {
        "char": "(",
        "block": "minecraft:mud_bricks"
      },
      {
        "char": ")",
        "block": "minecraft:polished_andesite"
      },
      {
        "char": "*",
        "block": "minecraft:smooth_stone"
      },
      {
        "char": "+",
        "block": "minecraft:target[power=0]"
      },
      {
        "char": ",",
        "block": "tfmg:asphalt"
      },
      {
        "char": "-",
        "block": "tfmg:cinder_block"
      },
      {
        "char": ".",
        "block": "tfmg:factory_floor"
      }
    ]
  }
}
