{
  "xsize": 16,
  "zsize": 16,
  "slices": [
    [
      "**********&&%***",
      "****************",
      "****************",
      "****************",
      "****************",
      "&&**************",
      "%***************",
      "****************",
      "****************",
      "                ",
      "                ",
      "                ",
      "                ",
      "                ",
      "                ",
      "                "
    ],
    [
      "   +++++++++++++",
      "                ",
      "                ",
      "    )))))))   ))",
      "    )))))))   ))",
      "    )))))))   ))",
      "    )))))))   ))",
      "    )))))))   ))",
      "                ",
      "                ",
      "                ",
      "                ",
      "                ",
      "                ",
      "                ",
      "                "
    ],
    [
      "   '$$$$$$$'$$$$",
      "   '       '    ",
      "                ",
      "                ",
      "     (((((     !",
      "     (((((     !",
      "     (((((     !",
      "                ",
      "                ",
      "                ",
      "                ",
      "                ",
      "                ",
      "                ",
      "                ",
      "                "
    ],
    [
      "   '$$$$$$$'$$$$",
      "   '       '    ",
      "                ",
      "                ",
      "     (((((     !",
      "     (((((     !",
      "     (((((     !",
      "                ",
      "                ",
      "                ",
      "                ",
      "                ",
      "                ",
      "                ",
      "                ",
      "                "
    ],
    [
      "   '$$$$$$$'$$$$",
      "   '       '    ",
      "                ",
      "                ",
      "     (((((     !",
      "     (((((     !",
      "     (((((     !",
      "                ",
      "                ",
      "                ",
      "                ",
      "                ",
      "                ",
      "                ",
      "                ",
      "                "
    ],
    [
      "   '$$$$$$$'$$$$",
      "   '       '    ",
      "                ",
      "                ",
      "                ",
      "                ",
      "                ",
      "                ",
      "                ",
      "                ",
      "                ",
      "                ",
      "                ",
      "                ",
      "                ",
      "                "
    ]
  ],
  "palette": {
    "palette": [
      {
        "char": "!",
        "block": "immersiveengineering:sheetmetal_steel"
      },
      {
        "char": "$",
        "block": "minecraft:bricks"
      },
      {
        "char": "%",
        "block": "minecraft:coarse_dirt"
      },
      {
        "char": "&",
        "block": "minecraft:gravel"
      },
      {
        "char": "'",
        "block": "minecraft:mud_bricks"
      },
      {
        "char": "(",
        "block": "minecraft:red_concrete"
      },
      {
        "char": ")",
        "block": "minecraft:smooth_stone"
      },
      {
        "char": "*",
        "block": "tfmg:asphalt"
      },
      {
        "char": "+",
        "block": "tfmg:factory_floor"
      }
    ]
  }
}
