{
  "xsize": 16,
  "zsize": 16,
  "slices": [
    [
      "                ",
      "                ",
      "                ",
      "                ",
      "                ",
      "                ",
      "    $      $$   ",
      "   !$      $$   ",
      "   !$      $$   ",
      "   !            ",
      "   !            ",
      "   !            ",
      "   !   & &      ",
      "   !   %%%      ",
      "   !   %%%      ",
      "   !   %%%      "
    ],
    [
      "                ",
      "                ",
      "                ",
      "                ",
      "                ",
      "                ",
      "    $      $$   ",
      "   !$      $$   ",
      "   !$      $$   ",
      "   !            ",
      "   !            ",
      "   !            ",
      "   !            ",
      "   !            ",
      "   !            ",
      "   !            "
    ],
    [
      "                ",
      "                ",
      "                ",
      "                ",
      "                ",
      "                ",
      "    $      $$   ",
      "   !$      $$   ",
      "   !$      $$   ",
      "   !            ",
      "   !            ",
      "   !            ",
      "   !            ",
      "   !            ",
      "   !            ",
      "   !            "
    ],
    [
      "                ",
      "                ",
      "                ",
      "                ",
      "                ",
      "                ",
      "    ''''''''''''",
      "   !''''''''''''",
      "   !''''''''''''",
      "   !            ",
      "   !            ",
      "   !            ",
      "   !            ",
      "   !            ",
      "   !            ",
      "   !            "
    ],
    [
      "                ",
      "                ",
      "                ",
      "                ",
      "                ",
      "       (       (",
      "    ''''''''''''",
      "   !''''''''''''",
      "   !''''''''''''",
      "   !            ",
      "   !            ",
      "   !            ",
      "   !            ",
      "   !            ",
      "   !            ",
      "   !            "
    ],
    [
      "                ",
      "                ",
      "                ",
      "                ",
      "                ",
      "                ",
      "                ",
      "   '''''''''''''",
      "   '''''''''''''",
      "   '''''''''''''",
      "   '''''''''''''",
      "   '''''''''''''",
      "   '''''''''''''",
      "   '''''''''''''",
      "   '''''''''''''",
      "   '''''''''''''"
    ]
  ],
  "palette": {
    "palette": [
      {
        "char": "!",
        "block": "minecraft:bricks"
      },
      {
        "char": "$",
        "block": "minecraft:mud_bricks"
      },
      {
        "char": "%",
        "block": "minecraft:red_terracotta"
      },
      {
        "char": "&",
        "block": "minecraft:redstone_lamp[lit=false]"
      },
      {
        "char": "'",
        "block": "minecraft:smooth_stone"
      },
      {
        "char": "(",
        "block": "minecraft:yellow_concrete"
      }
    ]
  }
}
