{
  "xsize": 16,
  "zsize": 16,
  "slices": [
    [
      "%,,,,,,,,,,,,,,,",
      ",,,,,,,,,,,,,,,,",
      ",,,,,,,,,,,,,,,,",
      ",,,,,,,,,,,,,,,,",
      ",,,,,,,,,,,,,,,,",
      ",,,,,,,,,,,,,,,,",
      ",,,,,,,,,,,,,,,,",
      ",,,,,,,,,,,,,,,,",
      ",,,,,,,,,,,,,,,,",
      "&%,,,,,,,,,,,,,,",
      ",,,,,,,,,,,,,,,,",
      ",,,,,,,,,,,,,,&&",
      ",,,,,,,,,,,,&&%,",
      ",,,,,,,,,,&&%,,,",
      ",,,,,,,,&&%,,,,,",
      ",,,,,,&&%,,,,,,,"
    ],
    [
      "    +       +   ",
      "    +       +   ",
      "    +       +   ",
      "    +       +   ",
      "    +       +   ",
      "    +       +   ",
      "    +       +   ",
      "   -------------",
      "   -------------",
      "   -------------",
      "   -------------",
      "   -------------",
      "   -------------",
      "   -------------",
      "   -------------",
      "   -------------"
    ],
    [
      "                ",
      "                ",
      "                ",
      "                ",
      "                ",
      "                ",
      "    (      ((   ",
      "   ((      ((   ",
      "   ((      ((   ",
      "   (            ",
      "   (            ",
      "   (            ",
      "   (  )))))     ",
      "   (  !)))!   ++",
      "   (  )))))   !+",
      "   (  )))))   ++"
    ],
    [
      "                ",
      "                ",
      "                ",
      "                ",
      "                ",
      "                ",
      "    (      ((   ",
      "   $(      ((   ",
      "   $(      ((   ",
      "   $            ",
      "   $            ",
      "   $            ",
      "   $  )))))     ",
      "   $  )))))   ++",
      "   $  )))))   ++",
      "   $  )))))   ++"
    ],
    [
      "                ",
      "                ",
      "                ",
      "                ",
      "                ",
      "                ",
      "    (      ((   ",
      "   $(      ((   ",
      "   $(      ((   ",
      "   $            ",
      "   $            ",
      "   $            ",
      "   $  )))))     ",
      "   $  )))))   ++",
      "   $  )))))   ++",
      "   $  )))))   ++"
    ],
    [
      "                ",
      "                ",
      "                ",
      "                ",
      "                ",
      "                ",
      "    (      ((   ",
      "   $(      ((   ",
      "   $(      ((   ",
      "   $            ",
      "   $            ",
      "   $            ",
      "   $  '''''     ",
      "   $   ***    ''",
      "   $   ***     )",
      "   $   ***     )"
    ]
  ],
  "palette": {
    "palette": [
      {
        "char": "!",
        "block": "minecraft:black_concrete"
      },
      {
        "char": "$",
        "block": "minecraft:bricks"
      },
      {
        "char": "%",
        "block": "minecraft:coarse_dirt"
      },
      {
        "char": "&",
        "block": "minecraft:gravel"
      },
      {
        "char": "'",
        "block": "minecraft:light_blue_stained_glass"
      },
      {
        "char": "(",
        "block": "minecraft:mud_bricks"
      },
      {
        "char": ")",
        "block": "minecraft:red_concrete"
      },
      {
        "char": "*",
        "block": "minecraft:red_terracotta"
      },
      {
        "char": "+",
        "block": "minecraft:white_concrete"
      },
      {
        "char": ",",
        "block": "tfmg:asphalt"
      },
      {
        "char": "-",
        "block": "tfmg:factory_floor"
      }
    ]
  }
}
