{
  "xsize": 16,
  "zsize": 16,
  "slices": [
    [
      "+++++++(('++++++",
      "+++++(('++++++++",
      "+++(('++++++++++",
      "+(('++++++++++++",
      "('++++++++++++++",
      "++++++++++++++++",
      "++++++++++++++((",
      "++++++++++++(('+",
      "++++++++++(('+++",
      "++++++++(('+++++",
      "++++++(('+++++++",
      "++++(('+++++++++",
      "++(('+++++++++++",
      "(('+++++++++++++",
      "'+++++++++++++++",
      "(((((((((((((((("
    ],
    [
      "(,,,,,,,,,,,,,,,",
      "(,,,,,,,,,,,,,,,",
      "(,,,,,,,,,,,,,,,",
      "(,,,,,,,,,,,,,,,",
      "(,,,,,,,,,,,,,,,",
      "(,,,,,,,,,,,,,,,",
      "(,,,,,,,,,,,,,,,",
      "(,,,,,,,,,,,,,,,",
      "(,,,,,,,,,,,,,,,",
      "),,,,,,,,,,,,,,,",
      ",,,,,,,,,,,,,,,,",
      ",,,,,,,,,,,,,,,,",
      ",,,,,,,,,,,,,,,,",
      "****************",
      "****************",
      "****************"
    ],
    [
      "(               ",
      "(               ",
      "(               ",
      "(               ",
      "(               ",
      "(               ",
      "(         $$  $$",
      "(..  ..   $$  $$",
      ")..  ..         ",
      " .-  ..    - &  ",
      " ..  ..   $$  $$",
      " ..  ..   $$  $$",
      "                ",
      "****************",
      "****************",
      "****************"
    ],
    [
      "(               ",
      "(               ",
      "(               ",
      ")               ",
      "                ",
      "                ",
      "          $$  $$",
      "          $$  $$",
      "                ",
      "  -   !    -    ",
      "          $$  $$",
      "          $$  $$",
      "                ",
      "      -%%-      ",
      "      -  -      ",
      "                "
    ],
    [
      "(               ",
      "(               ",
      ")               ",
      "                ",
      "                ",
      "                ",
      "          $$  $$",
      "          $$  $$",
      "--              ",
      "  -        -    ",
      "          $$  $$",
      "          $$  $$",
      "                ",
      "      -%%-      ",
      "      -  -      ",
      "                "
    ],
    [
      "                ",
      "                ",
      "                ",
      "                ",
      "                ",
      "                ",
      "                ",
      "                ",
      "                ",
      "  -        -    ",
      "                ",
      "                ",
      "                ",
      "      -%%-      ",
      "      -  -      ",
      "                "
    ]
  ],
  "palette": {
    "palette": [
      {
        "char": "!",
        "block": "create:cardboard_block"
      },
      {
        "char": "$",
        "block": "immersiveengineering:crate"
      },
      {
        "char": "%",
        "block": "minecraft:bricks"
      },
      {
        "char": "&",
        "block": "minecraft:chest[facing=west,type=single,waterlogged=false]",
        "tag": {
          "id": "minecraft:chest",
          "LootTable": "infinite_domain:chests/wasteland_industrial"
        }
      },
      {
        "char": "'",
        "block": "minecraft:coarse_dirt"
      },
      {
        "char": "(",
        "block": "minecraft:gravel"
      },
      {
        "char": ")",
        "block": "minecraft:mud_bricks"
      },
      {
        "char": "*",
        "block": "minecraft:smooth_stone"
      },
      {
        "char": "+",
        "block": "tfmg:asphalt"
      },
      {
        "char": ",",
        "block": "tfmg:factory_floor"
      },
      {
        "char": "-",
        "block": "tfmg:steel_block"
      },
      {
        "char": ".",
        "block": "zvhouses:stone_brick_countertop"
      }
    ]
  }
}
