{
  "xsize": 16,
  "zsize": 16,
  "slices": [
    [
      "////////////////",
      "////////////////",
      "////////////////",
      "////////////////",
      "////////////////",
      "///////++&//////",
      "/////++&////////",
      "///++&//////////",
      "/++&////////////",
      "+&//////////////",
      "////////////////",
      "//////////////++",
      "////////////++&/",
      "//////////++&///",
      "////////++&/////",
      "//////++&///////"
    ],
    [
      "                ",
      "                ",
      "                ",
      "                ",
      "                ",
      "                ",
      "                ",
      "   0000000000000",
      "  ,,+++++++++++,",
      "  ,+++++++++++++",
      "  ++++++++++++++",
      "  ++++++++++++++",
      "  ++++++++++++++",
      "  ++++++++++++++",
      "  ++++++++++++++",
      "  ++++++++++++++"
    ],
    [
      "                ",
      "                ",
      "                ",
      "                ",
      "                ",
      "                ",
      "   ,     ,     ,",
      "   ,,'(,,,,,,,,,",
      "  ,,  ++++++++, ",
      "   , ++++++++,, ",
      "   ,++++++++++$ ",
      "   +++++++++++++",
      "  ++++++++++++++",
      "  ++++++++++++++",
      "  ++++++++++++++",
      "  ++++++++++++++"
    ],
    [
      "                ",
      "                ",
      "                ",
      "                ",
      "                ",
      "                ",
      "   ,     ,     ,",
      "   ,%)*%%,%%%%%,",
      "  ,,   +,,      ",
      "   %  +,,+ ++   ",
      "   % +,,++++,,$ ",
      "   %+,,+++++,$$ ",
      "   +,,+++++++ ++",
      "  +,,++++++++++,",
      "  ,,+++++++++++,",
      "  ,+++++++++++++"
    ],
    [
      "                ",
      "                ",
      "                ",
      "                ",
      "                ",
      "                ",
      "   , --- , --- ,",
      "   ,%  %%,%%%%%,",
      "  ,,            ",
      "   %            ",
      "   % $$  $+  $$ ",
      "   % $$  ++, $$ ",
      "   %    ++,,    ",
      "   %   ++++  +  ",
      "  ,, $++++++++, ",
      "   % ++++++++,, "
    ],
    [
      "                ",
      "                ",
      "                ",
      "                ",
      "                ",
      "                ",
      "   ,     ,     ,",
      "   ,.!!!.,.!!!.,",
      "  ,,            ",
      "   %            ",
      "   !            ",
      "   !     1      ",
      "   %     +      ",
      "   %    +,,     ",
      "  ,,   +,,      ",
      "   %  +,,+ ++   "
    ]
  ],
  "palette": {
    "palette": [
      {
        "char": "!",
        "block": "create:framed_glass"
      },
      {
        "char": "$",
        "block": "jaffabricate:pallet_full"
      },
      {
        "char": "%",
        "block": "minecraft:bricks"
      },
      {
        "char": "&",
        "block": "minecraft:coarse_dirt"
      },
      {
        "char": "'",
        "block": "minecraft:dark_oak_door[facing=north,half=lower,hinge=left,open=false,powered=false]"
      },
      {
        "char": "(",
        "block": "minecraft:dark_oak_door[facing=north,half=lower,hinge=right,open=false,powered=false]"
      },
      {
        "char": ")",
        "block": "minecraft:dark_oak_door[facing=north,half=upper,hinge=left,open=false,powered=false]"
      },
      {
        "char": "*",
        "block": "minecraft:dark_oak_door[facing=north,half=upper,hinge=right,open=false,powered=false]"
      },
      {
        "char": "+",
        "block": "minecraft:gravel"
      },
      {
        "char": ",",
        "block": "minecraft:mud_bricks"
      },
      {
        "char": "-",
        "block": "minecraft:spruce_slab[type=bottom,waterlogged=false]"
      },
      {
        "char": ".",
        "block": "minecraft:stripped_spruce_log[axis=y]"
      },
      {
        "char": "/",
        "block": "tfmg:asphalt"
      },
      {
        "char": "0",
        "block": "tfmg:factory_floor"
      },
      {
        "char": "1",
        "block": "tfmg:steel_block"
      }
    ]
  }
}
