{
  "xsize": 16,
  "zsize": 16,
  "slices": [
    [
      "................",
      "................",
      "................",
      "................",
      "................",
      "..........))'...",
      "........))'.....",
      "......))'.......",
      "....))'.........",
      "..))'...........",
      "))'.............",
      "'...............",
      "...............)",
      ".............))'",
      "...........))'..",
      ".........))'...."
    ],
    [
      "                ",
      "                ",
      "                ",
      "                ",
      "                ",
      "                ",
      "                ",
      "////////////////",
      "////////////////",
      "////////////////",
      "////////////////",
      "////////////////",
      "////////////////",
      "////////////////",
      "////////////////",
      "////////////////"
    ],
    [
      "                ",
      "                ",
      "                ",
      "                ",
      "                ",
      "                ",
      "     +     +    ",
      "++++++++++++++++",
      "             %%%",
      "                ",
      "          $$  $$",
      " 10  11   $0  $$",
      " 11  11         ",
      " 11  11         ",
      " 11  11   $$  $$",
      " 11  11   $$  $$"
    ],
    [
      "                ",
      "                ",
      "                ",
      "                ",
      "                ",
      "                ",
      "     +     +    ",
      "&&&&&+&&&&&+&&&&",
      "             %*%",
      "                ",
      "          $$  $$",
      "  0       $0  $$",
      "  (             ",
      "                ",
      "          $$  $$",
      "          $$  $$"
    ],
    [
      "                ",
      "                ",
      "                ",
      "                ",
      "                ",
      "                ",
      " ,,, + ,,, + ,,,",
      "&&&&&+&&&&&+&&&&",
      "             %%%",
      "                ",
      "          $$  $$",
      "  0       $0  $$",
      "                ",
      "                ",
      "          $$  $$",
      "          $$  $$"
    ],
    [
      "                ",
      "                ",
      "                ",
      "                ",
      "                ",
      "                ",
      "     +     +    ",
      "-!!!-+-!!!-+-!!!",
      "                ",
      "                ",
      "                ",
      "  0        0    ",
      "                ",
      "                ",
      "                ",
      "                "
    ]
  ],
  "palette": {
    "palette": [
      {
        "char": "!",
        "block": "create:framed_glass"
      },
      {
        "char": "$",
        "block": "immersiveengineering:crate"
      },
      {
        "char": "%",
        "block": "immersiveengineering:sheetmetal_steel"
      },
      {
        "char": "&",
        "block": "minecraft:bricks"
      },
      {
        "char": "'",
        "block": "minecraft:coarse_dirt"
      },
      {
        "char": "(",
        "block": "kubejs:ruined_crafting_table"
      },
      {
        "char": ")",
        "block": "minecraft:gravel"
      },
      {
        "char": "*",
        "block": "minecraft:lever[face=wall,facing=north,powered=false]"
      },
      {
        "char": "+",
        "block": "minecraft:mud_bricks"
      },
      {
        "char": ",",
        "block": "minecraft:spruce_slab[type=bottom,waterlogged=false]"
      },
      {
        "char": "-",
        "block": "minecraft:stripped_spruce_log[axis=y]"
      },
      {
        "char": ".",
        "block": "tfmg:asphalt"
      },
      {
        "char": "/",
        "block": "tfmg:factory_floor"
      },
      {
        "char": "0",
        "block": "tfmg:steel_block"
      },
      {
        "char": "1",
        "block": "zvhouses:stone_brick_countertop"
      }
    ]
  }
}
