{
  "xsize": 16,
  "zsize": 16,
  "slices": [
    [
      "                ",
      "  ((((          ",
      "  ((((          ",
      "  ((((          ",
      "  ((((          ",
      "                ",
      "                ",
      "                ",
      "                ",
      "  (        (    ",
      "                ",
      "                ",
      "                ",
      "      (!!(      ",
      "      (  (      ",
      "                "
    ],
    [
      "                ",
      "  ((((          ",
      "  ((((          ",
      "  ((((          ",
      "  ((((          ",
      "                ",
      "                ",
      "                ",
      "                ",
      "  (        (    ",
      "                ",
      "                ",
      "                ",
      "      (!!(      ",
      "      (  (      ",
      "                "
    ],
    [
      "                ",
      "                ",
      "   $$           ",
      "   $$           ",
      "                ",
      "                ",
      "                ",
      "                ",
      "                ",
      "  (        (    ",
      "                ",
      "                ",
      "                ",
      "      (!!(      ",
      "      (  (      ",
      "                "
    ],
    [
      "                ",
      "                ",
      "   $$           ",
      "   $$           ",
      "                ",
      "                ",
      "                ",
      "                ",
      "                ",
      "  (        (    ",
      "                ",
      "                ",
      "                ",
      "!!!!!%(!!(!%!!!!",
      "&&&&&&&  &&&&&&&",
      "&&&&&&&  &&&&&&&"
    ],
    [
      "   ''           ",
      "   ''           ",
      "   $$           ",
      "   $$           ",
      "   ''           ",
      "   ''           ",
      "   ''           ",
      "   ''           ",
      "   ''           ",
      "  (        (    ",
      "                ",
      "                ",
      "                ",
      "!!!!!%(!!(!%!!!!",
      "&&&&&&&  &&&&&&&",
      "&&&&&&&  &&&&&&&"
    ],
    [
      "   ''           ",
      "   ''           ",
      "   ''           ",
      "   ''           ",
      "   ''           ",
      "   ''           ",
      "   ''           ",
      "   ''           ",
      "(((''(((((((((  ",
      "  (        (    ",
      "                ",
      "                ",
      "                ",
      "!!!!!%!!!!!%!!!!",
      "     %     %    ",
      "                "
    ]
  ],
  "palette": {
    "palette": [
      {
        "char": "!",
        "block": "minecraft:bricks"
      },
      {
        "char": "$",
        "block": "minecraft:chain"
      },
      {
        "char": "%",
        "block": "minecraft:mud_bricks"
      },
      {
        "char": "&",
        "block": "minecraft:weathered_cut_copper"
      },
      {
        "char": "'",
        "block": "minecraft:yellow_concrete"
      },
      {
        "char": "(",
        "block": "tfmg:steel_block"
      }
    ]
  }
}
