{
  "xsize": 16,
  "zsize": 16,
  "slices": [
    [
      " * (        *   ",
      " *          *   ",
      " *          *   ",
      " *          *   ",
      " ************   ",
      " %              ",
      "                ",
      "                ",
      "                ",
      " %              ",
      "                ",
      "                ",
      "                ",
      "+&              ",
      "+&     +        ",
      "                "
    ],
    [
      " *' ''''''''*   ",
      " *'(''''''''*   ",
      " *''''''''''*   ",
      " *''''''''''*   ",
      " ************   ",
      " %              ",
      "                ",
      "                ",
      "                ",
      " %              ",
      "                ",
      "                ",
      "                ",
      "+&              ",
      "+&     +        ",
      "                "
    ],
    [
      " *     *    *   ",
      " *     *  $ *   ",
      " *     *    *   ",
      " *     *    *   ",
      " ************   ",
      " %              ",
      " %              ",
      " %              ",
      " %              ",
      " %              ",
      " %              ",
      " %              ",
      " %              ",
      "+&              ",
      "+&     +        ",
      "                "
    ],
    [
      " !     *    *   ",
      " !     *    !   ",
      " !     *    !   ",
      " *     *    *   ",
      " ************   ",
      " )))))))        ",
      " )))))))        ",
      " )))))))        ",
      " )))))))        ",
      " )))))))        ",
      " )))))))        ",
      " )))))))        ",
      " )))))))        ",
      "+)))))))        ",
      "))))))))        ",
      ")               "
    ],
    [
      " !     *    *   ",
      " !     *    !   ",
      " !     *    !   ",
      " *     *    *   ",
      " ************   ",
      " %              ",
      " %              ",
      " %              ",
      " %              ",
      " %              ",
      " %              ",
      " %              ",
      " %              ",
      "+&              ",
      ")&              ",
      ")               "
    ],
    [
      " *     *    *   ",
      " *     *    *   ",
      " *     *    *   ",
      " *     *    *   ",
      " ************   ",
      " %              ",
      " %              ",
      " %              ",
      " %              ",
      " %              ",
      " %              ",
      " %              ",
      " %              ",
      "%&              ",
      " &              ",
      "                "
    ]
  ],
  "palette": {
    "palette": [
      {
        "char": "!",
        "block": "create:framed_glass"
      },
      {
        "char": "$",
        "block": "minecraft:barrel[facing=up,open=false]"
      },
      {
        "char": "%",
        "block": "minecraft:bricks"
      },
      {
        "char": "&",
        "block": "minecraft:mud_bricks"
      },
      {
        "char": "'",
        "block": "minecraft:polished_andesite"
      },
      {
        "char": "(",
        "block": "minecraft:polished_andesite_stairs[facing=south,half=bottom,shape=straight,waterlogged=false]"
      },
      {
        "char": ")",
        "block": "minecraft:weathered_cut_copper"
      },
      {
        "char": "*",
        "block": "tfmg:cinder_block"
      },
      {
        "char": "+",
        "block": "tfmg:steel_block"
      }
    ]
  }
}
