{
  "xsize": 16,
  "zsize": 16,
  "slices": [
    [
      "/////////////// ",
      "/////////////// ",
      "/////////////// ",
      "/////////////// ",
      "/////////////// ",
      "((///////////// ",
      "'////////////// ",
      "/////////////// ",
      "/////////////// ",
      "/////////////// ",
      "/////////////// ",
      "/////////////// ",
      "/////////////// ",
      "/////////////// ",
      "/(///////////// ",
      "((((((((((((((( "
    ],
    [
      "1++++++++++++   ",
      "1++++++++++++   ",
      "1++++++++++++   ",
      "1++++++++++++   ",
      "1++++++++++++   ",
      "1......         ",
      "1.....,,        ",
      "1.....,,$$$$$   ",
      "1.....,,$$$$$   ",
      "1...... $$$$$   ",
      "1.....,,$$$$$   ",
      "1.....,,$$$$$   ",
      "1.....,,        ",
      ".......         ",
      "..     2        ",
      "..              "
    ],
    [
      " 0     0    0   ",
      " 0     0    0   ",
      " 0   % 0 -  0   ",
      " 0     0    0   ",
      " 000000000000   ",
      " ......         ",
      " .....,,        ",
      " .....,,$$$$$   ",
      " .....,,$$$$$   ",
      " ...... $$$$$   ",
      " .....,,$$$$$   ",
      " .....,,$$$$$   ",
      " .....,,        ",
      ".......         ",
      "..     2        ",
      "..              "
    ],
    [
      " 0     0    0   ",
      " 0     0    !   ",
      " 0     0    !   ",
      " 0     0    0   ",
      " 000000000000   ",
      " &              ",
      "                ",
      "        $$)$$   ",
      "        $$$$$   ",
      " &      $$$$$   ",
      "        $$$$$   ",
      "        $$$$$   ",
      "                ",
      "2*              ",
      "2*     2        ",
      "                "
    ],
    [
      " 0     0    0   ",
      " 0     0    !   ",
      " 0     0    !   ",
      " 0     0    0   ",
      " 000000000000   ",
      " &              ",
      "                ",
      "        $$$$$   ",
      "        $$$$$   ",
      " &      $$$$$   ",
      "        $$$$$   ",
      "        $$$$$   ",
      "                ",
      "2*              ",
      "2*     2        ",
      "                "
    ],
    [
      " 0     0    0   ",
      " 0     0    0   ",
      " 0     0    0   ",
      " 0     0    0   ",
      " 000000000000   ",
      " &              ",
      "                ",
      "                ",
      "                ",
      " &              ",
      "                ",
      "                ",
      "                ",
      "2*              ",
      "2*     2        ",
      "                "
    ]
  ],
  "palette": {
    "palette": [
      {
        "char": "!",
        "block": "create:framed_glass"
      },
      {
        "char": "$",
        "block": "immersiveengineering:sheetmetal_steel"
      },
      {
        "char": "%",
        "block": "minecraft:barrel[facing=up,open=false]"
      },
      {
        "char": "&",
        "block": "minecraft:bricks"
      },
      {
        "char": "'",
        "block": "minecraft:coarse_dirt"
      },
      {
        "char": "(",
        "block": "minecraft:gravel"
      },
      {
        "char": ")",
        "block": "minecraft:lever[face=wall,facing=north,powered=false]"
      },
      {
        "char": "*",
        "block": "minecraft:mud_bricks"
      },
      {
        "char": "+",
        "block": "minecraft:polished_andesite"
      },
      {
        "char": ",",
        "block": "minecraft:polished_blackstone"
      },
      {
        "char": "-",
        "block": "minecraft:quartz_stairs[facing=east,half=bottom,shape=straight,waterlogged=false]"
      },
      {
        "char": ".",
        "block": "minecraft:smooth_stone"
      },
      {
        "char": "/",
        "block": "tfmg:asphalt"
      },
      {
        "char": "0",
        "block": "tfmg:cinder_block"
      },
      {
        "char": "1",
        "block": "tfmg:factory_floor"
      },
      {
        "char": "2",
        "block": "tfmg:steel_block"
      }
    ]
  }
}
