{
  "xsize": 16,
  "zsize": 16,
  "slices": [
    [
      "                ",
      "                ",
      "   .    .       ",
      "                ",
      " 222222222222   ",
      " 2          2   ",
      " 2          2   ",
      "/2          2   ",
      " 2          2   ",
      " 2          2   ",
      " 2          2   ",
      " 2          2   ",
      " 2          2   ",
      " 2          2   ",
      " 2          2   ",
      " 2          2   "
    ],
    [
      "                ",
      "                ",
      "   ((((((       ",
      "   ((((((       ",
      " 22((((((2222   ",
      " 2&&&&&&&&&&2   ",
      " 2&&&&&&&&&&2   ",
      "%2&&&&&&&&&&2   ",
      " 2&&&&&&&&&&2   ",
      " 2&&&&&&&&&&2   ",
      " 2&&&&&&&&&&2   ",
      " 2&&&&&&&&&&2   ",
      " 2&&&&&&&&&&2   ",
      " 2&&&&&&&&&&2   ",
      " 2&&&&&&&&&&2   ",
      " 2& &&&&&&&&2   "
    ],
    [
      "                ",
      "                ",
      "                ",
      "  +++   +++     ",
      " 222222222222   ",
      " 2     2    2   ",
      " 2 ++  2$$$ 2   ",
      "%2 -   2$$$ 2   ",
      " 2     2$$$ 2   ",
      " 2     2$$$ 2   ",
      " 2     2    2   ",
      " 2     2    2   ",
      " 2     )    2   ",
      " 2     2 1  2   ",
      " 2 ++  2    2   ",
      " 2 -   2    2   "
    ],
    [
      "                ",
      "                ",
      "                ",
      "                ",
      " /!!!/2/!!!/2   ",
      " 2     2    2   ",
      " 2     2$$$ !   ",
      "%2     2$$$ !   ",
      " !     2$$$ 2   ",
      " !     2$$$ 2   ",
      " !     2    2   ",
      " !     2    2   ",
      " !     *    !   ",
      " !     2    !   ",
      " !     2    2   ",
      " !     2    2   "
    ],
    [
      "                ",
      "                ",
      "                ",
      "   ''''''       ",
      " /!!!/2/!!!/2   ",
      " 2     2    2   ",
      " 2     2$$$ !   ",
      "%2     2$$$ !   ",
      " !     2$$$ 2   ",
      " !     2$$$ 2   ",
      " !     2    2   ",
      " !     2    2   ",
      " !     2    !   ",
      " !     2    !   ",
      " !     2    2   ",
      " !     2    2   "
    ],
    [
      "                ",
      "                ",
      "    0000        ",
      "  ,,,''',,,     ",
      " 222222222222   ",
      " 2     2    2   ",
      " 2     2    2   ",
      "%2     2    2   ",
      " 2     2    2   ",
      " 2     2    2   ",
      " 2     2    2   ",
      " 2     2    2   ",
      " 2     2    2   ",
      " 2     2    2   ",
      " 2     2    2   ",
      " 2     2    2   "
    ]
  ],
  "palette": {
    "palette": [
      {
        "char": "!",
        "block": "create:framed_glass"
      },
      {
        "char": "$",
        "block": "minecraft:bookshelf"
      },
      {
        "char": "%",
        "block": "minecraft:bricks"
      },
      {
        "char": "&",
        "block": "minecraft:polished_andesite"
      },
      {
        "char": "'",
        "block": "minecraft:smooth_stone"
      },
      {
        "char": "(",
        "block": "minecraft:smooth_stone_slab[type=top,waterlogged=false]"
      },
      {
        "char": ")",
        "block": "minecraft:spruce_door[facing=east,half=lower,hinge=left,open=false,powered=false]"
      },
      {
        "char": "*",
        "block": "minecraft:spruce_door[facing=east,half=upper,hinge=left,open=false,powered=false]"
      },
      {
        "char": "+",
        "block": "minecraft:spruce_slab[type=bottom,waterlogged=false]"
      },
      {
        "char": ",",
        "block": "minecraft:spruce_slab[type=top,waterlogged=false]"
      },
      {
        "char": "-",
        "block": "minecraft:spruce_stairs[facing=north,half=bottom,shape=straight,waterlogged=false]"
      },
      {
        "char": ".",
        "block": "minecraft:stripped_dark_oak_log[axis=y]"
      },
      {
        "char": "/",
        "block": "minecraft:stripped_spruce_log[axis=y]"
      },
      {
        "char": "0",
        "block": "minecraft:yellow_terracotta"
      },
      {
        "char": "1",
        "block": "supplementaries:item_shelf"
      },
      {
        "char": "2",
        "block": "tfmg:cinder_block"
      }
    ]
  }
}
