{
  "xsize": 16,
  "zsize": 16,
  "slices": [
    [
      "          $$$$$$",
      "          $$$$$$",
      "                ",
      "                ",
      "                ",
      "                ",
      "                ",
      "                ",
      "                ",
      "                ",
      "                ",
      "                ",
      "                ",
      "                ",
      "                ",
      "                "
    ],
    [
      "4444**%444444444",
      "44**%44444444444",
      "**%4444444444444",
      "%444444444444444",
      "4444444444444444",
      "4444444444444444",
      "4444444444444444",
      "444444444**%4444",
      "4444444**%444444",
      "44444**%44444444",
      "444**%4444444444",
      "4**%444444444444",
      "*%44444444444444",
      "4444444444444444",
      "44444444444444**",
      "444444444444**%4"
    ],
    [
      "       --       ",
      "                ",
      "                ",
      "         1   ,,,",
      "   //////////,,,",
      "   /////////////",
      "   6666666666666",
      "   6666666666666",
      "   6666666666666",
      "   6666666666666",
      "   6666666666666",
      "   6666666666666",
      "   6666666666666",
      "   6666666666666",
      "   6666666666666",
      "   6666666666666"
    ],
    [
      "       --       ",
      "                ",
      "                ",
      "         1    1 ",
      "                ",
      "   + 00000+  + 0",
      "   ++++++++&'+++",
      "   +            ",
      "  ++8888     777",
      "   +            ",
      "   +            ",
      "   +  .   .   . ",
      "   +  .   .   . ",
      "  ++            ",
      "   +  .   .   . ",
      "   +  .   .   . "
    ],
    [
      "       --       ",
      "                ",
      "                ",
      "         1    1 ",
      "                ",
      "   +      +  +  ",
      "   +2!!!!!2()+2!",
      "   5            ",
      "  ++ 3        3 ",
      "   5            ",
      "   !            ",
      "   !  .   .   . ",
      "   5  .   .   . ",
      "  ++            ",
      "   5  .   .   . ",
      "   5  .   .   . "
    ],
    [
      "       --       ",
      "                ",
      "                ",
      "         1    1 ",
      "                ",
      "   +      +  +  ",
      "   +2!!!!!2  +2!",
      "   5            ",
      "  ++            ",
      "   5            ",
      "   !            ",
      "   !            ",
      "   5            ",
      "  ++            ",
      "   5            ",
      "   5            "
    ]
  ],
  "palette": {
    "palette": [
      {
        "char": "!",
        "block": "create:framed_glass"
      },
      {
        "char": "$",
        "block": "immersiveengineering:concrete_reinforced"
      },
      {
        "char": "%",
        "block": "minecraft:coarse_dirt"
      },
      {
        "char": "&",
        "block": "minecraft:dark_oak_door[facing=north,half=lower,hinge=left,open=false,powered=false]"
      },
      {
        "char": "'",
        "block": "minecraft:dark_oak_door[facing=north,half=lower,hinge=right,open=false,powered=false]"
      },
      {
        "char": "(",
        "block": "minecraft:dark_oak_door[facing=north,half=upper,hinge=left,open=false,powered=false]"
      },
      {
        "char": ")",
        "block": "minecraft:dark_oak_door[facing=north,half=upper,hinge=right,open=false,powered=false]"
      },
      {
        "char": "*",
        "block": "minecraft:gravel"
      },
      {
        "char": "+",
        "block": "minecraft:mud_bricks"
      },
      {
        "char": ",",
        "block": "minecraft:polished_andesite"
      },
      {
        "char": "-",
        "block": "minecraft:polished_blackstone_bricks"
      },
      {
        "char": ".",
        "block": "minecraft:scaffolding"
      },
      {
        "char": "/",
        "block": "minecraft:smooth_stone"
      },
      {
        "char": "0",
        "block": "minecraft:spruce_slab[type=bottom,waterlogged=false]"
      },
      {
        "char": "1",
        "block": "minecraft:stripped_dark_oak_log[axis=y]"
      },
      {
        "char": "2",
        "block": "minecraft:stripped_spruce_log[axis=y]"
      },
      {
        "char": "3",
        "block": "supplementaries:item_shelf"
      },
      {
        "char": "4",
        "block": "tfmg:asphalt"
      },
      {
        "char": "5",
        "block": "tfmg:cinder_block"
      },
      {
        "char": "6",
        "block": "tfmg:factory_floor"
      },
      {
        "char": "7",
        "block": "zvhouses:spruce_countertop"
      },
      {
        "char": "8",
        "block": "zvhouses:stone_brick_countertop"
      }
    ]
  }
}
