{
  "xsize": 16,
  "zsize": 16,
  "slices": [
    [
      "                ",
      "                ",
      "                ",
      "                ",
      "                ",
      "                ",
      "                ",
      "               !",
      "               !",
      "                ",
      "                ",
      "                ",
      "                ",
      "                ",
      "                ",
      "               !"
    ],
    [
      "                ",
      "                ",
      "                ",
      "                ",
      "                ",
      "                ",
      "                ",
      "               !",
      "               !",
      "                ",
      "                ",
      "                ",
      "                ",
      "                ",
      "                ",
      "               !"
    ],
    [
      "                ",
      "                ",
      "                ",
      "                ",
      "                ",
      "                ",
      "                ",
      "   %        %  !",
      "               !",
      "                ",
      "                ",
      "                ",
      "                ",
      "                ",
      "                ",
      "   %        %  !"
    ],
    [
      "                ",
      "                ",
      "                ",
      "                ",
      "                ",
      "&&&&&&&&&&&&&&&&",
      "&&&&&&&&&&&&&&&&",
      "&&&&&&&&&&&&&&&&",
      "&&&&&&&&&&&&&&&&",
      "&&&&&&&&&&&&&&&&",
      "&&&&&&&&&&&&&&&&",
      "&&&&&&&&&&&&&&&&",
      "&&&&&&&&&&&&&&&&",
      "&&&&&&&&&&&&&&&&",
      "&&&&&&&&&&&&&&&&",
      "&&&&&&&&&&&&&&&&"
    ],
    [
      "                ",
      "                ",
      "                ",
      "                ",
      "                ",
      "$$$$$$$$$$$$$$$$",
      "       $$       ",
      "       $$       ",
      "       $$       ",
      "       $$       ",
      "       $$       ",
      "       $$       ",
      "       $$       ",
      "       $$       ",
      "       $$       ",
      "       $$       "
    ],
    [
      "                ",
      "                ",
      "                ",
      "                ",
      "                ",
      "                ",
      "                ",
      "                ",
      "                ",
      "                ",
      "                ",
      "                ",
      "                ",
      "                ",
      "                ",
      "                "
    ]
  ],
  "palette": {
    "palette": [
      {
        "char": "!",
        "block": "minecraft:polished_blackstone_bricks"
      },
      {
        "char": "$",
        "block": "minecraft:red_concrete"
      },
      {
        "char": "%",
        "block": "minecraft:sea_lantern"
      },
      {
        "char": "&",
        "block": "minecraft:smooth_stone"
      }
    ]
  }
}
