{
  "xsize": 16,
  "zsize": 16,
  "slices": [
    [
      "                ",
      "                ",
      "                ",
      "                ",
      "                ",
      "                ",
      "                ",
      "                ",
      "                ",
      "                ",
      "                ",
      "                ",
      "                ",
      "                ",
      "                ",
      "                "
    ],
    [
      "7777777777,,'777",
      "77777777,,'77777",
      "777777,,'7777777",
      "7777,,'777777777",
      "77,,'77777777777",
      ",,'7777777777777",
      "'777777777777777",
      "777777777777777,",
      "7777777777777,,'",
      "77777777777,,'77",
      "777777777,,'7777",
      "7777777,,'777777",
      "77777,,'77777777",
      "                ",
      "                ",
      "                "
    ],
    [
      "   9999999999999",
      "   9999999999999",
      "   9999999999999",
      "   9999999999999",
      "   9999999999999",
      "   9999999999999",
      "   9999999999999",
      "   9999999999999",
      "   9999999999999",
      "   9999999999999",
      "    .......     ",
      "    .......     ",
      "    5.....5     ",
      "                ",
      "                ",
      "                "
    ],
    [
      "   -    :       ",
      "   -888188888818",
      "  --      8     ",
      "   -%%  $$8 33 &",
      "   -%%  $$/ 4   ",
      "   -%%  $$8     ",
      "   -%%  $$8     ",
      "  --      8     ",
      "   - &    8     ",
      "   -88()88-88888",
      "   -      -     ",
      "                ",
      "    5     5     ",
      "                ",
      "                ",
      "                "
    ],
    [
      "   8            ",
      "   8888288888828",
      "  --      8     ",
      "   !%%  $$8     ",
      "   !%%  $$0     ",
      "   8%%  $$8     ",
      "   8%%  $$8     ",
      "  --      8     ",
      "   -      8    6",
      "   -88*+88-8!!88",
      "   -      -     ",
      "                ",
      "    5     5     ",
      "                ",
      "                ",
      "                "
    ],
    [
      "   8            ",
      "   8888888888888",
      "  --      8     ",
      "   !      8     ",
      "   !      8     ",
      "   8      8     ",
      "   8      8     ",
      "  --      8     ",
      "   -      8     ",
      "   -88  88-8!!88",
      "   -      -     ",
      "                ",
      "    5     5     ",
      "                ",
      "                ",
      "                "
    ]
  ],
  "palette": {
    "palette": [
      {
        "char": "!",
        "block": "create:framed_glass"
      },
      {
        "char": "$",
        "block": "immersiveengineering:crate"
      },
      {
        "char": "%",
        "block": "jaffabricate:pallet_full"
      },
      {
        "char": "&",
        "block": "minecraft:barrel[facing=up,open=false]"
      },
      {
        "char": "'",
        "block": "minecraft:coarse_dirt"
      },
      {
        "char": "(",
        "block": "minecraft:dark_oak_door[facing=south,half=lower,hinge=left,open=false,powered=false]"
      },
      {
        "char": ")",
        "block": "minecraft:dark_oak_door[facing=south,half=lower,hinge=right,open=false,powered=false]"
      },
      {
        "char": "*",
        "block": "minecraft:dark_oak_door[facing=south,half=upper,hinge=left,open=false,powered=false]"
      },
      {
        "char": "+",
        "block": "minecraft:dark_oak_door[facing=south,half=upper,hinge=right,open=false,powered=false]"
      },
      {
        "char": ",",
        "block": "minecraft:gravel"
      },
      {
        "char": "-",
        "block": "minecraft:mud_bricks"
      },
      {
        "char": ".",
        "block": "minecraft:smooth_stone"
      },
      {
        "char": "/",
        "block": "minecraft:spruce_door[facing=east,half=lower,hinge=left,open=false,powered=false]"
      },
      {
        "char": "0",
        "block": "minecraft:spruce_door[facing=east,half=upper,hinge=left,open=false,powered=false]"
      },
      {
        "char": "1",
        "block": "minecraft:spruce_door[facing=south,half=lower,hinge=left,open=false,powered=false]"
      },
      {
        "char": "2",
        "block": "minecraft:spruce_door[facing=south,half=upper,hinge=left,open=false,powered=false]"
      },
      {
        "char": "3",
        "block": "minecraft:spruce_slab[type=bottom,waterlogged=false]"
      },
      {
        "char": "4",
        "block": "minecraft:spruce_stairs[facing=north,half=bottom,shape=straight,waterlogged=false]"
      },
      {
        "char": "5",
        "block": "minecraft:stripped_dark_oak_log[axis=y]"
      },
      {
        "char": "6",
        "block": "supplementaries:item_shelf"
      },
      {
        "char": "7",
        "block": "tfmg:asphalt"
      },
      {
        "char": "8",
        "block": "tfmg:cinder_block"
      },
      {
        "char": "9",
        "block": "tfmg:factory_floor"
      },
      {
        "char": ":",
        "block": "the_wasteland_reworked:cardboard_box"
      }
    ]
  }
}
