{
  "xsize": 16,
  "zsize": 16,
  "slices": [
    [
      "                ",
      "                ",
      "                ",
      "                ",
      "                ",
      "                ",
      "                ",
      "                ",
      "                ",
      "                ",
      "                ",
      "                ",
      "                ",
      "                ",
      "                ",
      "                "
    ],
    [
      "                ",
      "                ",
      "                ",
      "                ",
      "                ",
      "                ",
      "                ",
      "!!!!!!!!!!!!!   ",
      "!!!!!!!!!!!!!   ",
      "!!!!!!!!!!!!!   ",
      "!!!!!!!!!!!!!   ",
      "!!!!!!!!!!!!!   ",
      "!!!!!!!!!!!!!   ",
      "!!!!!!!!!!!!!   ",
      "!!!!!!!!!!!!!   ",
      "!!!!!!!!!!!!!   "
    ],
    [
      "                ",
      "                ",
      "                ",
      "                ",
      "                ",
      "                ",
      "                ",
      "!!!!!!!!!!!!!   ",
      "  ((        !   ",
      "$ (( $$$$$  !   ",
      "& (( &$$$&  !   ",
      "& (( &$$$&  !   ",
      "& (( &$$$&  !   ",
      "& (( &$$$&  !   ",
      "& (( &$$$&  !   ",
      "$ (( $$$$$  !   "
    ],
    [
      "                ",
      "                ",
      "                ",
      "                ",
      "                ",
      "                ",
      "                ",
      "!!!!!!!!!!!!!   ",
      "            !   ",
      "$ %  $$$$$  !   ",
      "$    $   $  !   ",
      "$    $   $  !   ",
      "$    $   $  !   ",
      "$    $   $  !   ",
      "$    $   $  !   ",
      "$  ' $$$$$  !   "
    ],
    [
      "                ",
      "                ",
      "                ",
      "                ",
      "                ",
      "                ",
      "                ",
      "!!!!!!!!!!!!!   ",
      "            !   ",
      "$    $$$$$  !   ",
      "$    $   $  !   ",
      "$    $   $  !   ",
      "$    $   $  !   ",
      "$    $   $  !   ",
      "$    $   $  !   ",
      "$    $$$$$  !   "
    ],
    [
      "                ",
      "                ",
      "                ",
      "                ",
      "                ",
      "                ",
      "                ",
      "!!!!!!!!!!!!!   ",
      "            !   ",
      "$    $$$$$  !   ",
      "&    &$$$&  !   ",
      "&    &$$$&  !   ",
      "&    &$$$&  !   ",
      "&    &$$$&  !   ",
      "&    &$$$&  !   ",
      "$    $$$$$  !   "
    ]
  ],
  "palette": {
    "palette": [
      {
        "char": "!",
        "block": "immersiveengineering:concrete_reinforced"
      },
      {
        "char": "$",
        "block": "immersiveengineering:sheetmetal_steel"
      },
      {
        "char": "%",
        "block": "minecraft:barrel[facing=up,open=false]"
      },
      {
        "char": "&",
        "block": "minecraft:polished_andesite"
      },
      {
        "char": "'",
        "block": "minecraft:redstone_lamp[lit=false]"
      },
      {
        "char": "(",
        "block": "minecraft:smooth_stone"
      }
    ]
  }
}
