{
  "xsize": 16,
  "zsize": 16,
  "slices": [
    [
      "                ",
      "                ",
      "                ",
      "                ",
      "                ",
      "                ",
      "                ",
      "                ",
      "                ",
      "                ",
      "                ",
      "                ",
      "                ",
      "                ",
      "                ",
      "                "
    ],
    [
      "4444444444444''&",
      "44444444444''&44",
      "444444444''&4444",
      "4444444''&444444",
      "44444''&44444444",
      "444''&4444444444",
      "4''&444444444444",
      "'&44444444444444",
      "4444444444444444",
      "44444444444444''",
      "444444444444''&4",
      "4444444444''&444",
      "44444444''&44444",
      "                ",
      "                ",
      "                "
    ],
    [
      "666666662   2   ",
      "666666662   2   ",
      "666666662   2   ",
      "666666662   2   ",
      "666666662   2   ",
      "666666662   2   ",
      "666666662   2***",
      "666666662   2***",
      "66666666     ***",
      "66666666     ***",
      "             ***",
      "             ***",
      "                ",
      "                ",
      "                ",
      "                "
    ],
    [
      " !    3)        ",
      "5555/55)        ",
      " 5     ))       ",
      " 5 1  +)        ",
      " -     )        ",
      " 555/55)        ",
      " 5     )     ***",
      " 5%%  ,))    *  ",
      " 5%%   )     *  ",
      "5)55555)     *  ",
      " )     )     *  ",
      "             ***",
      "                ",
      "                ",
      "                ",
      "                "
    ],
    [
      "      35        ",
      "55550555        ",
      " 5     ))       ",
      " 5     5        ",
      " .    (5        ",
      " 5550555        ",
      " 5     5     ***",
      " 5%%  ())    *  ",
      " 5%%   )     *  ",
      "5)5$$55)     *  ",
      " )     )     *  ",
      "             ***",
      "                ",
      "                ",
      "                ",
      "                "
    ],
    [
      "       5        ",
      "55555555        ",
      " 5     ))       ",
      " 5     5        ",
      " 5     5        ",
      " 5555555        ",
      " 5     5        ",
      " 5%%   ))       ",
      " 5%%   )        ",
      "5)5$$55)        ",
      " )     )        ",
      "                ",
      "                ",
      "                ",
      "                ",
      "                "
    ]
  ],
  "palette": {
    "palette": [
      {
        "char": "!",
        "block": "create:cardboard_block"
      },
      {
        "char": "$",
        "block": "create:framed_glass"
      },
      {
        "char": "%",
        "block": "immersiveengineering:sheetmetal_steel"
      },
      {
        "char": "&",
        "block": "minecraft:coarse_dirt"
      },
      {
        "char": "'",
        "block": "minecraft:gravel"
      },
      {
        "char": "(",
        "block": "minecraft:lever[face=wall,facing=west,powered=false]"
      },
      {
        "char": ")",
        "block": "minecraft:mud_bricks"
      },
      {
        "char": "*",
        "block": "minecraft:oxidized_copper_grate"
      },
      {
        "char": "+",
        "block": "minecraft:quartz_stairs[facing=west,half=bottom,shape=straight,waterlogged=false]"
      },
      {
        "char": ",",
        "block": "minecraft:redstone_lamp[lit=false]"
      },
      {
        "char": "-",
        "block": "minecraft:spruce_door[facing=east,half=lower,hinge=left,open=false,powered=false]"
      },
      {
        "char": ".",
        "block": "minecraft:spruce_door[facing=east,half=upper,hinge=left,open=false,powered=false]"
      },
      {
        "char": "/",
        "block": "minecraft:spruce_door[facing=south,half=lower,hinge=left,open=false,powered=false]"
      },
      {
        "char": "0",
        "block": "minecraft:spruce_door[facing=south,half=upper,hinge=left,open=false,powered=false]"
      },
      {
        "char": "1",
        "block": "minecraft:water_cauldron[level=1]"
      },
      {
        "char": "2",
        "block": "minecraft:white_concrete"
      },
      {
        "char": "3",
        "block": "oritech:cooler_block"
      },
      {
        "char": "4",
        "block": "tfmg:asphalt"
      },
      {
        "char": "5",
        "block": "tfmg:cinder_block"
      },
      {
        "char": "6",
        "block": "tfmg:factory_floor"
      }
    ]
  }
}
