{
  "xsize": 16,
  "zsize": 16,
  "slices": [
    [
      "                ",
      "//&&%/          ",
      "&&%///          ",
      "%/////          ",
      "//////          ",
      "//////          ",
      "//////          ",
      "//////          ",
      "//////          ",
      "/////&          ",
      "///&&%          ",
      "/&&%//          ",
      "&%////          ",
      "//////          ",
      "//////          ",
      "//////          "
    ],
    [
      "                ",
      " -              ",
      "(((             ",
      "(((             ",
      "(((             ",
      "(((             ",
      "                ",
      "1111            ",
      "1111            ",
      "1111            ",
      "1111            ",
      "1111            ",
      "1111            ",
      "1111            ",
      "1111            ",
      "1111            "
    ],
    [
      "                ",
      "                ",
      "                ",
      "!               ",
      "                ",
      "                ",
      "   '            ",
      "''''            ",
      "  )$            ",
      "33 $            ",
      "   $            ",
      ",  $            ",
      "   $            ",
      " * $            ",
      "  .$            ",
      "000$            "
    ],
    [
      "                ",
      "                ",
      "                ",
      "                ",
      "                ",
      "                ",
      "   '            ",
      "+$$'            ",
      "  )$            ",
      "2  $            ",
      "   $            ",
      "   $            ",
      "   $            ",
      "   $            ",
      "   $            ",
      "000$            "
    ],
    [
      "                ",
      "                ",
      "                ",
      "                ",
      "                ",
      "                ",
      "   '            ",
      "+$$'            ",
      "  )$            ",
      "   $            ",
      "   $            ",
      "   $            ",
      "   $            ",
      "   $            ",
      "   $            ",
      "000$            "
    ],
    [
      "                ",
      "                ",
      "                ",
      "                ",
      "                ",
      "                ",
      "   '            ",
      "$$$'            ",
      "  )$            ",
      "   $            ",
      "   $            ",
      "   $            ",
      "   $            ",
      "   $            ",
      "   $            ",
      "000$            "
    ]
  ],
  "palette": {
    "palette": [
      {
        "char": "!",
        "block": "create:minecart_anchor"
      },
      {
        "char": "$",
        "block": "minecraft:bricks"
      },
      {
        "char": "%",
        "block": "minecraft:coarse_dirt"
      },
      {
        "char": "&",
        "block": "minecraft:gravel"
      },
      {
        "char": "'",
        "block": "minecraft:mud_bricks"
      },
      {
        "char": "(",
        "block": "minecraft:oxidized_copper_grate"
      },
      {
        "char": ")",
        "block": "minecraft:polished_blackstone_bricks"
      },
      {
        "char": "*",
        "block": "minecraft:quartz_stairs[facing=west,half=bottom,shape=straight,waterlogged=false]"
      },
      {
        "char": "+",
        "block": "minecraft:stripped_spruce_log[axis=y]"
      },
      {
        "char": ",",
        "block": "kubejs:ruined_cauldron"
      },
      {
        "char": "-",
        "block": "minecraft:white_concrete"
      },
      {
        "char": ".",
        "block": "oritech:cooler_block"
      },
      {
        "char": "/",
        "block": "tfmg:asphalt"
      },
      {
        "char": "0",
        "block": "tfmg:cinder_block"
      },
      {
        "char": "1",
        "block": "tfmg:factory_floor"
      },
      {
        "char": "2",
        "block": "the_wasteland_reworked:radio"
      },
      {
        "char": "3",
        "block": "zvhouses:spruce_countertop"
      }
    ]
  }
}
