{
  "xsize": 16,
  "zsize": 16,
  "slices": [
    [
      "                ",
      ".%<<<<<<<<<<<<<<",
      "<<<<<<<<<<<<<<<<",
      "<<<<<<<<<<<<<<..",
      "<<<<<<<<<<<<..%<",
      "<<<<<<<<<<..%<<<",
      "<<<<<<<<..%<<<<<",
      "<<<<<<..%<<<<<<<",
      "<<<<..%<<<<<<<<<",
      "<<..%<<<<<<<<<<<",
      "..%<<<<<<<<<<<<<",
      "%<<<<<<<<<<<<<<<",
      "<<<<<<<<<<<<<<<.",
      "<<<<<<<<<<<<<..%",
      "<<<<<<<<<<<..%<<",
      "<<<<<<<<<..%<<<<"
    ],
    [
      "                ",
      " 33333 :    :   ",
      " 33333 :8   : 00",
      " 33333 :    : 00",
      "1111111:    : 00",
      "1111111:    : 00",
      "1111111         ",
      "1111111>>>>>>>>>",
      "1111111>>>>>>>>>",
      ">>>>>>>>>>>>>>>>",
      ">>>>>>>>>>>>>>>>",
      ">>>>>>>>>>>>>>>>",
      ">>>>>>>>>>>>>>>>",
      ">>>>>>>>>>>>>>>>",
      ">>>>>>>>>>>>>>>>",
      ">>>>>>>>>>>>>>>>"
    ],
    [
      "                ",
      "                ",
      "        8       ",
      "                ",
      "33&'333         ",
      "3     3         ",
      "3     3  / 66666",
      "3     3/////////",
      "33*+333         ",
      "             @@@",
      "        @   @ = ",
      "        @   @ = ",
      "        @   @ = ",
      "              4 ",
      "  2    2    2 = ",
      "  2?   2?   2?=="
    ],
    [
      "                ",
      "                ",
      "        8       ",
      "                ",
      "33()333         ",
      "3     3         ",
      "3     3  /      ",
      "3     3$$/9!!!!!",
      "33,-333         ",
      "                ",
      "        ;   ; = ",
      "              = ",
      "              = ",
      "              5 ",
      "  2    2    2 = ",
      "  2    2    2 =="
    ],
    [
      "                ",
      "                ",
      "        8       ",
      "                ",
      "33  333         ",
      "3     3         ",
      "3     3  /      ",
      "3     3$$/9!!!!!",
      "33  333         ",
      "                ",
      "              = ",
      "              = ",
      "              = ",
      "              = ",
      "              = ",
      "              =="
    ],
    [
      "                ",
      "                ",
      "        8       ",
      "                ",
      "3333333         ",
      "3     3         ",
      "3     3  / 77777",
      "3     3$$/$$$$$$",
      "3333333         ",
      "                ",
      "              = ",
      "              = ",
      "              = ",
      "              = ",
      "              = ",
      "              =="
    ]
  ],
  "palette": {
    "palette": [
      {
        "char": "!",
        "block": "create:framed_glass"
      },
      {
        "char": "$",
        "block": "minecraft:bricks"
      },
      {
        "char": "%",
        "block": "minecraft:coarse_dirt"
      },
      {
        "char": "&",
        "block": "minecraft:dark_oak_door[facing=north,half=lower,hinge=left,open=false,powered=false]"
      },
      {
        "char": "'",
        "block": "minecraft:dark_oak_door[facing=north,half=lower,hinge=right,open=false,powered=false]"
      },
      {
        "char": "(",
        "block": "minecraft:dark_oak_door[facing=north,half=upper,hinge=left,open=false,powered=false]"
      },
      {
        "char": ")",
        "block": "minecraft:dark_oak_door[facing=north,half=upper,hinge=right,open=false,powered=false]"
      },
      {
        "char": "*",
        "block": "minecraft:dark_oak_door[facing=south,half=lower,hinge=left,open=false,powered=false]"
      },
      {
        "char": "+",
        "block": "minecraft:dark_oak_door[facing=south,half=lower,hinge=right,open=false,powered=false]"
      },
      {
        "char": ",",
        "block": "minecraft:dark_oak_door[facing=south,half=upper,hinge=left,open=false,powered=false]"
      },
      {
        "char": "-",
        "block": "minecraft:dark_oak_door[facing=south,half=upper,hinge=right,open=false,powered=false]"
      },
      {
        "char": ".",
        "block": "minecraft:gravel"
      },
      {
        "char": "/",
        "block": "minecraft:mud_bricks"
      },
      {
        "char": "0",
        "block": "minecraft:oxidized_copper_grate"
      },
      {
        "char": "1",
        "block": "minecraft:polished_andesite"
      },
      {
        "char": "2",
        "block": "minecraft:scaffolding"
      },
      {
        "char": "3",
        "block": "minecraft:smooth_stone"
      },
      {
        "char": "4",
        "block": "minecraft:spruce_door[facing=east,half=lower,hinge=left,open=false,powered=false]"
      },
      {
        "char": "5",
        "block": "minecraft:spruce_door[facing=east,half=upper,hinge=left,open=false,powered=false]"
      },
      {
        "char": "6",
        "block": "minecraft:spruce_slab[type=bottom,waterlogged=false]"
      },
      {
        "char": "7",
        "block": "minecraft:spruce_slab[type=top,waterlogged=false]"
      },
      {
        "char": "8",
        "block": "minecraft:stripped_dark_oak_log[axis=y]"
      },
      {
        "char": "9",
        "block": "minecraft:stripped_spruce_log[axis=y]"
      },
      {
        "char": ":",
        "block": "minecraft:white_concrete"
      },
      {
        "char": ";",
        "block": "supplementaries:item_shelf"
      },
      {
        "char": "<",
        "block": "tfmg:asphalt"
      },
      {
        "char": "=",
        "block": "tfmg:cinder_block"
      },
      {
        "char": ">",
        "block": "tfmg:factory_floor"
      },
      {
        "char": "?",
        "block": "the_wasteland_reworked:cardboard_box"
      },
      {
        "char": "@",
        "block": "zvhouses:spruce_countertop"
      }
    ]
  }
}
