{
  "xsize": 16,
  "zsize": 16,
  "slices": [
    [
      " 777,,'777777777",
      " 7,,'77777777777",
      " ,'7777777777777",
      " 777777777777777",
      " 77777777777777,",
      " 777777777777,,'",
      " 7777777777,,'77",
      " 77777777,,'7777",
      " 777777,,'777777",
      " 7777,,'77777777",
      " 77,,'7777777777",
      " ,,'777777777777",
      " '77777777777777",
      " 777777777777777",
      " 7777777777777,,",
      " 77777777777,,'7"
    ],
    [
      "   9999999999999",
      "   9999999999999",
      "   9999999999999",
      "   9999999999999",
      "   9999999999999",
      "   9999999999999",
      "   9999999999999",
      "   9999999999999",
      "   9999999999999",
      "   9999999999999",
      "   9999999999999",
      "   9999999999999",
      "   9999999999999",
      "   9999999999999",
      "     222222222  ",
      "     222222222  "
    ],
    [
      "   &         0  ",
      "   &            ",
      "   &         0  ",
      "   &         0  ",
      "   & ::::::: 0! ",
      "   &  $  1   0  ",
      "   &            ",
      "   &888858888888",
      "   &          8 ",
      "   & %%    %% 8 ",
      "   & %%    %% 3 ",
      "   & %%    %% 8 ",
      "   &/         8 ",
      "   -&&&&()&&&&-&",
      "   -  ....... - ",
      "                "
    ],
    [
      "   &         0  ",
      "   &            ",
      "   &         0  ",
      "   &         0  ",
      "   &         0  ",
      "   &         0  ",
      "   &            ",
      "   &888868888888",
      "   &          8 ",
      "   &          8 ",
      "   &          4 ",
      "   &          8 ",
      "   &/         8 ",
      "   -&&&&*+&&&&-&",
      "   -          - ",
      "                "
    ],
    [
      "   &            ",
      "   &            ",
      "   &            ",
      "   &            ",
      "   &            ",
      "   &            ",
      "   &            ",
      "   &888888888888",
      "   &          8 ",
      "   &          8 ",
      "   &          8 ",
      "   &          8 ",
      "   &/         8 ",
      "   -&&&&  &&&&-&",
      "   -          - ",
      "                "
    ],
    [
      "   &            ",
      "   &            ",
      "   &            ",
      "   &            ",
      "   &            ",
      "   &            ",
      "   &            ",
      "   &888888888888",
      "   &          8 ",
      "   &          8 ",
      "   &          8 ",
      "   &          8 ",
      "   &/         8 ",
      "   -&&&&  &&&&-&",
      "   -          - ",
      "                "
    ]
  ],
  "palette": {
    "palette": [
      {
        "char": "!",
        "block": "create:cardboard_block"
      },
      {
        "char": "$",
        "block": "farmersdelight:stove[facing=north,lit=false]"
      },
      {
        "char": "%",
        "block": "jaffabricate:pallet_full"
      },
      {
        "char": "&",
        "block": "minecraft:bricks"
      },
      {
        "char": "'",
        "block": "minecraft:coarse_dirt"
      },
      {
        "char": "(",
        "block": "minecraft:dark_oak_door[facing=south,half=lower,hinge=left,open=false,powered=false]"
      },
      {
        "char": ")",
        "block": "minecraft:dark_oak_door[facing=south,half=lower,hinge=right,open=false,powered=false]"
      },
      {
        "char": "*",
        "block": "minecraft:dark_oak_door[facing=south,half=upper,hinge=left,open=false,powered=false]"
      },
      {
        "char": "+",
        "block": "minecraft:dark_oak_door[facing=south,half=upper,hinge=right,open=false,powered=false]"
      },
      {
        "char": ",",
        "block": "minecraft:gravel"
      },
      {
        "char": "-",
        "block": "minecraft:mud_bricks"
      },
      {
        "char": ".",
        "block": "minecraft:polished_blackstone"
      },
      {
        "char": "/",
        "block": "minecraft:polished_blackstone_bricks"
      },
      {
        "char": "0",
        "block": "minecraft:scaffolding"
      },
      {
        "char": "1",
        "block": "kubejs:ruined_smoker[facing=north]"
      },
      {
        "char": "2",
        "block": "minecraft:smooth_stone"
      },
      {
        "char": "3",
        "block": "minecraft:spruce_door[facing=east,half=lower,hinge=left,open=false,powered=false]"
      },
      {
        "char": "4",
        "block": "minecraft:spruce_door[facing=east,half=upper,hinge=left,open=false,powered=false]"
      },
      {
        "char": "5",
        "block": "minecraft:spruce_door[facing=south,half=lower,hinge=left,open=false,powered=false]"
      },
      {
        "char": "6",
        "block": "minecraft:spruce_door[facing=south,half=upper,hinge=left,open=false,powered=false]"
      },
      {
        "char": "7",
        "block": "tfmg:asphalt"
      },
      {
        "char": "8",
        "block": "tfmg:cinder_block"
      },
      {
        "char": "9",
        "block": "tfmg:factory_floor"
      },
      {
        "char": ":",
        "block": "zvhouses:stone_brick_countertop"
      }
    ]
  }
}
