{
  "xsize": 16,
  "zsize": 16,
  "slices": [
    [
      "4444444**(444444",
      "44444**(44444444",
      "444**(4444444444",
      "4**(444444444444",
      "*(44444444444444",
      "4444444444444444",
      "44444444444444**",
      "444444444444**(4",
      "4444444444**(444",
      "44444444**(44444",
      "444444**(4444444",
      "4444**(444444444",
      "44**(44444444444",
      "**(4444444444444",
      "(444444444444444",
      "444444444444444*"
    ],
    [
      "6666666666666666",
      "6666666666666666",
      "6666666666666666",
      "6666666666666666",
      "6666666666666666",
      "6666666666666666",
      "6666666666666666",
      "6666666666666666",
      "6666666666666666",
      "6666666666666666",
      "6666666666666666",
      "6666666666666666",
      "6666666666666666",
      "6666666666666666",
      "                ",
      "                "
    ],
    [
      "  ,    ,    ,   ",
      "                ",
      "  ,    ,    ,   ",
      "  ,    ,    ,   ",
      "  ,!   ,!   ,!  ",
      "  ,    ,    ,   ",
      "                ",
      "555/555555555/55",
      "        5     51",
      "%%   %% 5     52",
      "%%   %% - & ) - ",
      "%%   %% 5     53",
      "        5     5 ",
      "''''''''+'''''+'",
      "        +     + ",
      "                "
    ],
    [
      "  ,    ,    ,   ",
      "                ",
      "  ,    ,    ,   ",
      "  ,    ,    ,   ",
      "  ,    ,    ,   ",
      "  ,    ,    ,   ",
      "                ",
      "5550555555555055",
      "        5     5 ",
      "%%   %% 5     5 ",
      "%%   %% .     . ",
      "%%   %% 5     5 ",
      "        5     5 ",
      "''''''''+'''''+'",
      "        +     + ",
      "                "
    ],
    [
      "                ",
      "                ",
      "                ",
      "                ",
      "                ",
      "                ",
      "                ",
      "5555555555555555",
      "        5     5 ",
      "        5     5 ",
      "        5     5 ",
      "        5     5 ",
      "        5     5 ",
      "'$$'''''+'$$''+'",
      "        +     + ",
      "                "
    ],
    [
      "                ",
      "                ",
      "                ",
      "                ",
      "                ",
      "                ",
      "                ",
      "5555555555555555",
      "        5     5 ",
      "        5     5 ",
      "        5     5 ",
      "        5     5 ",
      "        5     5 ",
      "'$$'''''+'$$''+'",
      "        +     + ",
      "                "
    ]
  ],
  "palette": {
    "palette": [
      {
        "char": "!",
        "block": "create:cardboard_block"
      },
      {
        "char": "$",
        "block": "create:framed_glass"
      },
      {
        "char": "%",
        "block": "immersiveengineering:crate"
      },
      {
        "char": "&",
        "block": "minecraft:barrel[facing=up,open=false]"
      },
      {
        "char": "'",
        "block": "minecraft:bricks"
      },
      {
        "char": "(",
        "block": "minecraft:coarse_dirt"
      },
      {
        "char": ")",
        "block": "minecraft:crafting_table"
      },
      {
        "char": "*",
        "block": "minecraft:gravel"
      },
      {
        "char": "+",
        "block": "minecraft:mud_bricks"
      },
      {
        "char": ",",
        "block": "minecraft:scaffolding"
      },
      {
        "char": "-",
        "block": "minecraft:spruce_door[facing=east,half=lower,hinge=left,open=false,powered=false]"
      },
      {
        "char": ".",
        "block": "minecraft:spruce_door[facing=east,half=upper,hinge=left,open=false,powered=false]"
      },
      {
        "char": "/",
        "block": "minecraft:spruce_door[facing=south,half=lower,hinge=left,open=false,powered=false]"
      },
      {
        "char": "0",
        "block": "minecraft:spruce_door[facing=south,half=upper,hinge=left,open=false,powered=false]"
      },
      {
        "char": "1",
        "block": "minecraft:spruce_slab[type=bottom,waterlogged=false]"
      },
      {
        "char": "2",
        "block": "minecraft:spruce_stairs[facing=north,half=bottom,shape=straight,waterlogged=false]"
      },
      {
        "char": "3",
        "block": "minecraft:water_cauldron[level=1]"
      },
      {
        "char": "4",
        "block": "tfmg:asphalt"
      },
      {
        "char": "5",
        "block": "tfmg:cinder_block"
      },
      {
        "char": "6",
        "block": "tfmg:factory_floor"
      }
    ]
  }
}
