{
  "xsize": 16,
  "zsize": 16,
  "slices": [
    [
      "                ",
      " 44444444444444*",
      " 444444444444**)",
      " 4444444444**)44",
      " 44444444**)4444",
      " 444444**)444444",
      " 4444**)44444444",
      " 44**)4444444444",
      " **)444444444444",
      " )44444444444444",
      " 444444444444444",
      " 4444444444444**",
      " 44444444444**)4",
      " 444444444**)444",
      " 4444444**)44444",
      " 44444**)4444444"
    ],
    [
      "                ",
      "     2    2    2",
      "     2    2   02",
      "     2    2    2",
      "     2    2    2",
      "     2    2    2",
      "                ",
      "   5555555555555",
      "   5555555555555",
      "   5555555555555",
      "   5555555555555",
      "   5555555555555",
      "   5555555555555",
      "   5555555555555",
      "   5555555555555",
      "   5555555555555"
    ],
    [
      "                ",
      "                ",
      "              0 ",
      "                ",
      "                ",
      "                ",
      "   +  .....  +  ",
      "   +++++++++++++",
      "   (,           ",
      "   (            ",
      "   ( %% ''7   7 ",
      "   ( %% ''7   7 ",
      "   (      7   7 ",
      "   ( $$ &&      ",
      "   ( $$ &&   -  ",
      "   (         -6 "
    ],
    [
      "                ",
      "                ",
      "              0 ",
      "                ",
      "                ",
      "                ",
      "   +         +  ",
      "   +(1!!!!!1(+((",
      "   (,           ",
      "   (            ",
      "   (      3   3 ",
      "   (            ",
      "   (            ",
      "   (            ",
      "   (         -  ",
      "   (         -  "
    ],
    [
      "                ",
      "                ",
      "              0 ",
      "                ",
      "                ",
      "                ",
      "   +         +  ",
      "   +(1!!!!!1(+((",
      "   (,           ",
      "   (            ",
      "   (            ",
      "   (            ",
      "   (            ",
      "   (            ",
      "   (            ",
      "   (            "
    ],
    [
      "                ",
      "                ",
      "              0 ",
      "                ",
      "                ",
      "                ",
      "   +  /////  +  ",
      "   +(((((((((+((",
      "   (,           ",
      "   (            ",
      "   (            ",
      "   (            ",
      "   (            ",
      "   (            ",
      "   (            ",
      "   (            "
    ]
  ],
  "palette": {
    "palette": [
      {
        "char": "!",
        "block": "create:framed_glass"
      },
      {
        "char": "$",
        "block": "farmersdelight:cabbage_crate"
      },
      {
        "char": "%",
        "block": "farmersdelight:carrot_crate"
      },
      {
        "char": "&",
        "block": "farmersdelight:onion_crate"
      },
      {
        "char": "'",
        "block": "farmersdelight:potato_crate"
      },
      {
        "char": "(",
        "block": "minecraft:bricks"
      },
      {
        "char": ")",
        "block": "minecraft:coarse_dirt"
      },
      {
        "char": "*",
        "block": "minecraft:gravel"
      },
      {
        "char": "+",
        "block": "minecraft:mud_bricks"
      },
      {
        "char": ",",
        "block": "minecraft:polished_blackstone_bricks"
      },
      {
        "char": "-",
        "block": "minecraft:scaffolding"
      },
      {
        "char": ".",
        "block": "minecraft:spruce_slab[type=bottom,waterlogged=false]"
      },
      {
        "char": "/",
        "block": "minecraft:spruce_slab[type=top,waterlogged=false]"
      },
      {
        "char": "0",
        "block": "minecraft:stripped_dark_oak_log[axis=y]"
      },
      {
        "char": "1",
        "block": "minecraft:stripped_spruce_log[axis=y]"
      },
      {
        "char": "2",
        "block": "minecraft:white_concrete"
      },
      {
        "char": "3",
        "block": "supplementaries:item_shelf"
      },
      {
        "char": "4",
        "block": "tfmg:asphalt"
      },
      {
        "char": "5",
        "block": "tfmg:factory_floor"
      },
      {
        "char": "6",
        "block": "the_wasteland_reworked:cardboard_box"
      },
      {
        "char": "7",
        "block": "zvhouses:spruce_countertop"
      }
    ]
  }
}
