{
  "xsize": 16,
  "zsize": 16,
  "slices": [
    [
      "  $$$'$$$$$$$$$$",
      "  $'$$$$$$$!!!&&",
      "$'$$$$$$$$!!!!!%",
      "$$$$$$$$$$!!!!! ",
      "$$$$$$$$$$!!!!!!",
      "$$$$$$$$$$!!!!!!",
      "$$$$$$$$'$!!!!!!",
      "$$$$$$'$$$!$$$'$",
      "$$$$'$$$'$$$'$$$",
      "$$'$$$'$$$'$$$$$",
      "'$$$'$$$'$$$$$$$",
      "  '$$$'$$$$$$$$$",
      "  $$'$$$$$$$$$$$",
      "  '$$$$$$$$$$$$$",
      "  $$$$$$$$$$$$$'",
      "  $$$$$$$$$$$'$$"
    ],
    [
      "    $'$$$$$$$$  ",
      "    $$$$$$$!!!&&",
      "  $$$$$$$$!!!!!%",
      "  $$$$$$$$!!!!! ",
      "  $$$$$$$$!!!!!!",
      "  $$$$$$$$!!!!!!",
      "  $$$$$$'$!!!!!!",
      "  $$$$'$$$!$$$'$",
      "  $$'$$$'$$$'$$$",
      "  '$$$'$$$'$$$$$",
      "  $$'$$$'$$$$$$$",
      "    $$'$$$$$$$  ",
      "    '$$$$$$$$$  ",
      "    $$$$$$$$$$  ",
      "    $$$$$$$$$$  ",
      "    $$$$$$$$$'  "
    ],
    [
      "      $$$$$$    ",
      "      $$$$$!!!&&",
      "    $$$$$$!!!!!%",
      "    $$$$$$!!!!! ",
      "    $$$$$$!!!!!!",
      "    $$$$$$!!!!!!",
      "    $$$$'$!!!!!!",
      "    $$'$$$!$$$  ",
      "    '$$$'$$$'$  ",
      "    $$'$$$'$$$  ",
      "    '$$$'$$$$$  ",
      "      '$$$$$    ",
      "      $$$$$$    ",
      "      $$$$$$    ",
      "      $$$$$$    ",
      "      $$$$$$    "
    ],
    [
      "        ))))))))",
      "        ))))))&&",
      "      $$)))))))%",
      "      $$))))))) ",
      "      $$))))))))",
      "      $$))))))))",
      "      $$))))))))",
      "      '$$$!$    ",
      "      $$'$$$    ",
      "      '$$$'$    ",
      "      $$'$$$    ",
      "        $$      ",
      "        $$      ",
      "        $$      ",
      "        $$      ",
      "        $$      "
    ],
    [
      "                ",
      "                ",
      "        $$(     ",
      "        $$      ",
      "        $$      ",
      "        $$      ",
      "        &&&&&&&&",
      "        $$      ",
      "        '$      ",
      "        $$      ",
      "        '$      ",
      "                ",
      "                ",
      "                ",
      "                ",
      "                "
    ],
    [
      "                ",
      "                ",
      "                ",
      "                ",
      "                ",
      "                ",
      "        &&&&&&&&",
      "                ",
      "                ",
      "                ",
      "                ",
      "                ",
      "                ",
      "                ",
      "                ",
      "                "
    ]
  ],
  "palette": {
    "palette": [
      {
        "char": "!",
        "block": "immersiveengineering:concrete_reinforced"
      },
      {
        "char": "$",
        "block": "minecraft:deepslate"
      },
      {
        "char": "%",
        "block": "minecraft:ladder[facing=south,waterlogged=false]"
      },
      {
        "char": "&",
        "block": "minecraft:polished_deepslate"
      },
      {
        "char": "'",
        "block": "minecraft:tuff"
      },
      {
        "char": "(",
        "block": "minecraft:yellow_concrete"
      },
      {
        "char": ")",
        "block": "tfmg:asphalt"
      }
    ]
  }
}
