{
  "xsize": 16,
  "zsize": 16,
  "slices": [
    [
      "++++++++++++++++",
      "!!!!!!++++++++++",
      "!!!!!!!+++++++++",
      "!!!!!!!+++++++++",
      "!!!!!!!+++++++++",
      "!!!!!!!+++++++++",
      "!!!!!!!+++++++++",
      "++++++!+++++++++",
      "++++++++++++++++",
      "++++++++++++++++",
      "++++++++++++++++",
      "++++++++++++++++",
      "++++++++++++++++",
      "++++++++++++++++",
      "++++++++++++++++",
      "++++++++++++++++"
    ],
    [
      "+++2++++++++++++",
      "!!!!!!++++++++++",
      "!!!!!!!+++++++2+",
      "!!!!!!!+++++2+++",
      "!!!!!!!+++2+++2+",
      "!!!!!!!+2+++2+++",
      "!!!!!!!+++2+++2+",
      "++++2+!+2+++2+++",
      "++2+++2+++2+++++",
      "2+++2+++2+++++++",
      "++2+++2+++++++++",
      "2+++2+++++++++++",
      "++2+++++++++++++",
      "2++++++++++++++2",
      "+++++++++++++2++",
      "+++++++++++2+++2"
    ],
    [
      "///////////////+",
      "///////////////+",
      "///////////////+",
      "///////////////+",
      "///////////////+",
      "///////////////+",
      "///////////////+",
      "///////////////+",
      "///////////////+",
      "///////////////+",
      "///////////////+",
      "///////////////+",
      "///////////////+",
      "///////////////2",
      "///////////////+",
      "///////////////2"
    ],
    [
      "           3 ( +",
      "////           +",
      " .             +",
      "          ++2+++",
      "!!!!!     2+++2+",
      "!!!!!     ++2+++",
      "!!!!!          +",
      " ,  %          +",
      " -  &          +",
      "           $$$ +",
      "           $$$ +",
      "   1       $$$  ",
      " ,  %      $$$ )",
      " -  &      $$$  ",
      "           $0$ +",
      "           $$$'2"
    ],
    [
      "               +",
      "////           +",
      " .             +",
      "          ++2+++",
      "!!!!!     2+++2+",
      "!!!!!     ++2+++",
      "!!!!!          +",
      "               +",
      "               +",
      "           $$$ +",
      "           $$$ +",
      "           $$$  ",
      "           $$$ *",
      "           $$$  ",
      "           $$$ +",
      "           $$$ 2"
    ],
    [
      "               +",
      "////           +",
      " .             +",
      "          ++2+++",
      "!!!!!     2+++2+",
      "!!!!!     ++2+++",
      "!!!!!          +",
      "               +",
      "               +",
      "           $$$ +",
      "           $$$ +",
      "           $$$  ",
      "           $$$  ",
      "           $$$  ",
      "           $$$ +",
      "           $$$ 2"
    ]
  ],
  "palette": {
    "palette": [
      {
        "char": "!",
        "block": "immersiveengineering:concrete_reinforced"
      },
      {
        "char": "$",
        "block": "immersiveengineering:crate"
      },
      {
        "char": "%",
        "block": "minecraft:brown_bed[facing=south,occupied=false,part=foot]"
      },
      {
        "char": "&",
        "block": "minecraft:brown_bed[facing=south,occupied=false,part=head]"
      },
      {
        "char": "'",
        "block": "minecraft:chest[facing=west,type=single,waterlogged=false]",
        "tag": {
          "id": "minecraft:chest",
          "LootTable": "infinite_domain:chests/wasteland_refuge"
        }
      },
      {
        "char": "(",
        "block": "minecraft:composter[level=0]"
      },
      {
        "char": ")",
        "block": "minecraft:dark_oak_door[facing=east,half=lower,hinge=left,open=false,powered=false]"
      },
      {
        "char": "*",
        "block": "minecraft:dark_oak_door[facing=east,half=upper,hinge=left,open=false,powered=false]"
      },
      {
        "char": "+",
        "block": "minecraft:deepslate"
      },
      {
        "char": ",",
        "block": "minecraft:gray_bed[facing=south,occupied=false,part=foot]"
      },
      {
        "char": "-",
        "block": "minecraft:gray_bed[facing=south,occupied=false,part=head]"
      },
      {
        "char": ".",
        "block": "minecraft:ladder[facing=south,waterlogged=false]"
      },
      {
        "char": "/",
        "block": "minecraft:polished_deepslate"
      },
      {
        "char": "0",
        "block": "minecraft:skeleton_skull[rotation=13]"
      },
      {
        "char": "1",
        "block": "minecraft:skeleton_skull[rotation=1]"
      },
      {
        "char": "2",
        "block": "minecraft:tuff"
      },
      {
        "char": "3",
        "block": "minecraft:water_cauldron[level=3]"
      }
    ]
  }
}
