{
  "xsize": 16,
  "zsize": 16,
  "slices": [
    [
      "   $            ",
      "   $            ",
      "   $            ",
      "   $         $ !",
      "   $$$$$$$$$$$ !",
      "               !",
      "               !",
      "               !",
      "               !",
      "               !",
      "               !",
      "               !",
      "               !",
      "               !",
      "               &",
      "               !"
    ],
    [
      "   $            ",
      "   $            ",
      "   $            ",
      "   $         $ !",
      "   $$$$$$$$$$$ !",
      "               !",
      "               !",
      "               !",
      "               !",
      "               !",
      "               !",
      "               !",
      "               !",
      "               !",
      "               &",
      "               !"
    ],
    [
      "   $$$$$$$$$$$  ",
      "   $$$$$$$$$$$  ",
      "   $$$$$$$$$$$ !",
      "   $$$$$$$$$$$ !",
      "   $$$$$$$$$$$ !",
      "               !",
      "               !",
      "               !",
      "               !",
      "               !",
      "               !",
      "               !",
      "               !",
      "               !",
      "               &",
      "               !"
    ],
    [
      "  %%%%%%%%%%%%% ",
      "  %%%%%%%%%%%%% ",
      "  %%%%%%%%%%%%% ",
      "  %%%%%%%%%%%%%!",
      "  %%%%%%%%%%%%%!",
      "  %%%%%%%%%%%%%!",
      "               !",
      "               !",
      "               !",
      "               !",
      "               !",
      "               !",
      "               !",
      "               !",
      "               &",
      "               !"
    ],
    [
      "                ",
      "                ",
      "                ",
      "                ",
      "                ",
      "                ",
      "                ",
      "                ",
      "               !",
      "               !",
      "               !",
      "               !",
      "               !",
      "               !",
      "               &",
      "               !"
    ],
    [
      "                ",
      "                ",
      "                ",
      "                ",
      "                ",
      "                ",
      "                ",
      "                ",
      "                ",
      "                ",
      "                ",
      "                ",
      "                ",
      "               !",
      "               &",
      "               !"
    ]
  ],
  "palette": {
    "palette": [
      {
        "char": "!",
        "block": "minecraft:deepslate"
      },
      {
        "char": "$",
        "block": "minecraft:smooth_stone"
      },
      {
        "char": "%",
        "block": "minecraft:smooth_stone_slab[type=top,waterlogged=false]"
      },
      {
        "char": "&",
        "block": "minecraft:tuff"
      }
    ]
  }
}
