{
  "xsize": 16,
  "zsize": 16,
  "slices": [
    [
      "      !!!!&!!!!&",
      "&&!!!!&!!!&!!!!&",
      " &!!!!&!!!&!!!!&",
      " &!!!!&!!!&!!!!&",
      "!&!!!!&!!!&!!!!&",
      "!&!!!!&!!!&!!!!&",
      "!&!!!!&         ",
      "%%              ",
      "%%              ",
      "%%              ",
      "%%              ",
      "                ",
      "                ",
      "                ",
      "                ",
      "                "
    ],
    [
      "      !!!!!!!!!!",
      "&&!!!!!!!!!!!!!!",
      " !!!!!!!!!!!!!!!",
      " !!!!!!!!!!!!!!!",
      "!!!!!!!!!!!!!!!!",
      "!!!!!!!!!!!!!!!!",
      "!!!!!!          ",
      "                ",
      "                ",
      "                ",
      "                ",
      "                ",
      "                ",
      "                ",
      "                ",
      "                "
    ],
    [
      "      !!!!!!!!!!",
      "&&!!!!!!!!!!!!!!",
      " !!!!!!!!!!!!!!!",
      " !!!!!!!!!!!!!!!",
      "!!!!!!!!!!!!!!!!",
      "!!!!!!!!!!!!!!!!",
      "!!!!!!          ",
      "                ",
      "                ",
      "                ",
      "                ",
      "                ",
      "                ",
      "                ",
      "                ",
      "                "
    ],
    [
      "****************",
      "&&**************",
      " ***************",
      " ***************",
      "****************",
      "****************",
      "****************",
      "                ",
      "                ",
      "                ",
      "                ",
      "                ",
      "                ",
      "                ",
      "                ",
      "                "
    ],
    [
      "        ,,,,,,,,",
      "        ,,,,,,,,",
      ")     ) ,,,,,,,,",
      "        ,,,,,,,,",
      "        ,,,,,,,,",
      "        ,,,,,,,,",
      "&&&&&&&&,,,,,,,,",
      "        ,,,,,,,,",
      "        ,,,,,,,,",
      "                ",
      "                ",
      "                ",
      "                ",
      "                ",
      "                ",
      "                "
    ],
    [
      "        + (     ",
      "        +       ",
      "        ++++'+++",
      "        +       ",
      "        + $    $",
      "        + $    $",
      "&&&&&&&&+ $    $",
      "        +       ",
      "        ++++++++",
      "                ",
      "                ",
      "                ",
      "                ",
      "                ",
      "                ",
      "                "
    ]
  ],
  "palette": {
    "palette": [
      {
        "char": "!",
        "block": "immersiveengineering:concrete_reinforced"
      },
      {
        "char": "$",
        "block": "minecraft:bookshelf"
      },
      {
        "char": "%",
        "block": "minecraft:deepslate"
      },
      {
        "char": "&",
        "block": "minecraft:polished_deepslate"
      },
      {
        "char": "'",
        "block": "minecraft:spruce_door[facing=south,half=lower,hinge=left,open=false,powered=false]"
      },
      {
        "char": "(",
        "block": "minecraft:spruce_stairs[facing=north,half=bottom,shape=straight,waterlogged=false]"
      },
      {
        "char": ")",
        "block": "minecraft:yellow_concrete"
      },
      {
        "char": "*",
        "block": "tfmg:asphalt"
      },
      {
        "char": "+",
        "block": "tfmg:cinder_block"
      },
      {
        "char": ",",
        "block": "tfmg:factory_floor"
      }
    ]
  }
}
