{
  "xsize": 16,
  "zsize": 16,
  "slices": [
    [
      "&&&&&&&&&&&&&&&&",
      "&&&&&&&&&&&&&&&&",
      "&&&&&&&&&&&&&&&&",
      "&&&&&&&&&&&&&&&&",
      "&&&&&&&&&&&&&&&&",
      "&&&&&&&&&&&&&&&&",
      "&&&&&&&&&&&&&&&&",
      "&&&&&&&&&&&&&&&&",
      "&&&&&&&&&&&&&&&&",
      "&&&&&&&&&&&&&&&&",
      "&&&&&&&&&&&&&&&&",
      "&&&&&&&&&&&&&&&&",
      "&&&&&&&&&&&&&&&&",
      "&&&&&&&&&&&&&&&&",
      "&&&&&&&&&&&&&&&&",
      "&&&&&&&&&&&&&&&&"
    ],
    [
      "////////////////",
      "////////////////",
      "////////////////",
      "////////////////",
      "////////////////",
      "////////////////",
      "////////////////",
      "////////////////",
      "////////////////",
      "////////////////",
      "&-              ",
      "&&              ",
      "&&              ",
      "&&              ",
      "&&              ",
      "&&              "
    ],
    [
      "!  ''''    '*'' ",
      "!  ''''    '''' ",
      "!  ''''    '''' ",
      "!               ",
      "$               ",
      "!...+.......+...",
      "!               ",
      "!               ",
      "!               ",
      ")!!!  !!!!!!  !!",
      ")-              ",
      ")&              ",
      ")&              ",
      ")&              ",
      ")&              ",
      ")&              "
    ],
    [
      "!  ''''    '''' ",
      "!  ''''    '''' ",
      "!  ''''    '''' ",
      "!               ",
      "%               ",
      "!...,.......,...",
      "!               ",
      "!               ",
      "!               ",
      " !!!  !!!!!!  !!",
      " -              ",
      " &              ",
      " &              ",
      " &              ",
      " &              ",
      " &              "
    ],
    [
      "! (''''    '''' ",
      "!  ''''    '''' ",
      "!  ''''    '''' ",
      "!               ",
      "!               ",
      "!...............",
      "!               ",
      "!               ",
      "!               ",
      " !!!  !!!!!!  !!",
      " -              ",
      " &              ",
      " &              ",
      " &              ",
      " &              ",
      " &              "
    ],
    [
      "!  ''''    '''' ",
      "! (''''    '''' ",
      "!  ''''    '''' ",
      "!               ",
      "!               ",
      "!...............",
      "!               ",
      "!               ",
      "!               ",
      " !!!  !!!!!!  !!",
      " -              ",
      " &              ",
      " &              ",
      " &              ",
      " &              ",
      " &              "
    ]
  ],
  "palette": {
    "palette": [
      {
        "char": "!",
        "block": "immersiveengineering:concrete_brick_cracked"
      },
      {
        "char": "$",
        "block": "minecraft:dark_oak_door[facing=west,half=lower,hinge=left,open=false,powered=false]"
      },
      {
        "char": "%",
        "block": "minecraft:dark_oak_door[facing=west,half=upper,hinge=left,open=false,powered=false]"
      },
      {
        "char": "&",
        "block": "minecraft:deepslate"
      },
      {
        "char": "'",
        "block": "minecraft:oxidized_copper"
      },
      {
        "char": "(",
        "block": "minecraft:polished_andesite_stairs[facing=south,half=bottom,shape=straight,waterlogged=false]"
      },
      {
        "char": ")",
        "block": "minecraft:polished_deepslate"
      },
      {
        "char": "*",
        "block": "minecraft:spawner",
        "tag": {
          "id": "minecraft:mob_spawner",
          "Delay": 200,
          "MinSpawnDelay": 240,
          "MaxSpawnDelay": 720,
          "SpawnCount": 2,
          "MaxNearbyEntities": 7,
          "RequiredPlayerRange": 14,
          "SpawnRange": 4,
          "SpawnData": {
            "entity": {
              "id": "the_wasteland_reworked:irradiated"
            }
          },
          "SpawnPotentials": [
            {
              "weight": 1,
              "data": {
                "entity": {
                  "id": "the_wasteland_reworked:irradiated"
                }
              }
            }
          ]
        }
      },
      {
        "char": "+",
        "block": "minecraft:spruce_door[facing=south,half=lower,hinge=left,open=false,powered=false]"
      },
      {
        "char": ",",
        "block": "minecraft:spruce_door[facing=south,half=upper,hinge=left,open=false,powered=false]"
      },
      {
        "char": "-",
        "block": "minecraft:tuff"
      },
      {
        "char": ".",
        "block": "tfmg:cinder_block"
      },
      {
        "char": "/",
        "block": "tfmg:factory_floor"
      }
    ]
  }
}
