{
  "xsize": 16,
  "zsize": 16,
  "slices": [
    [
      "                ",
      "                ",
      "        !!      ",
      "      !!%!!!    ",
      "      %!!!!!    ",
      "      !!!!!!    ",
      "      !!!!!!    ",
      "      !!!!!!    ",
      "    !!!!!!!!!%  ",
      "    !!!!!!!%!!  ",
      "    !!!!!%!!!%  ",
      "    !!!%!!!%!!  ",
      "    !%!!!%!!!%  ",
      "  !%!!!%!!!%!!!!",
      "  !!!%!!!%!!!!!!",
      "  !%!!!%!!!!!!!!"
    ],
    [
      "                ",
      "                ",
      "                ",
      "        %!      ",
      "        !!      ",
      "        !!      ",
      "        !!      ",
      "        !!      ",
      "      !!!!!!    ",
      "      !!!!!%    ",
      "      !!!%!!    ",
      "      !%!!!%    ",
      "      !!!%!!    ",
      "    !!!%!!!%!!  ",
      "    !%!!!%!!!!  ",
      "    !!!%!!!!!!  "
    ],
    [
      "                ",
      "                ",
      "                ",
      "                ",
      "                ",
      "                ",
      "                ",
      "                ",
      "        !!      ",
      "        !!      ",
      "        !%      ",
      "        !!      ",
      "        !%      ",
      "      !%!!!%    ",
      "      !!!%!!    ",
      "      !%!!!!    "
    ],
    [
      "                ",
      "                ",
      "                ",
      "                ",
      "                ",
      "                ",
      "                ",
      "                ",
      "                ",
      "                ",
      "                ",
      "                ",
      "                ",
      "        !!      ",
      "        !%      ",
      "        &&&&&&&&"
    ],
    [
      "                ",
      "                ",
      "                ",
      "                ",
      "                ",
      "                ",
      "                ",
      "                ",
      "                ",
      "                ",
      "                ",
      "                ",
      "                ",
      "                ",
      "                ",
      "        $$$$$$$$"
    ],
    [
      "                ",
      "                ",
      "                ",
      "                ",
      "                ",
      "                ",
      "                ",
      "                ",
      "                ",
      "                ",
      "                ",
      "                ",
      "                ",
      "                ",
      "                ",
      "        $$$$$$$$"
    ]
  ],
  "palette": {
    "palette": [
      {
        "char": "!",
        "block": "minecraft:deepslate"
      },
      {
        "char": "$",
        "block": "minecraft:polished_deepslate"
      },
      {
        "char": "%",
        "block": "minecraft:tuff"
      },
      {
        "char": "&",
        "block": "tfmg:asphalt"
      }
    ]
  }
}
