{
  "xsize": 16,
  "zsize": 16,
  "slices": [
    [
      "****************",
      "***********!!!!!",
      "**********!!!!!!",
      "**********!!!!!!",
      "**********!!!!!!",
      "**********!!!!!!",
      "**********!!!!!!",
      "**********!*****",
      "****************",
      "****************",
      "****************",
      "****************",
      "****************",
      "****************",
      "****************",
      "****************"
    ],
    [
      "*/***/**********",
      "***/*******!!!!!",
      "*/********!!!!!!",
      "**********!!!!!!",
      "**********!!!!!!",
      "**********!!!!!!",
      "********/*!!!!!!",
      "******/***!***/*",
      "****/***/***/***",
      "**/***/***/*****",
      "/***/***/*******",
      "**/***/*********",
      "/***/***********",
      "**/*************",
      "/**************/",
      "*************/**"
    ],
    [
      "*/..............",
      "**..............",
      "*/..............",
      "**..............",
      "**..............",
      "**..............",
      "**..............",
      "**..............",
      "**..............",
      "**..............",
      "/*..............",
      "**..............",
      "/*..............",
      "**..............",
      "/*..............",
      "**.............."
    ],
    [
      "*/           0 '",
      "**            ..",
      "*/             -",
      "*******         ",
      "*******     !!!!",
      "*******     !!!!",
      "**          !!!!",
      "** +  %         ",
      "** ,  &         ",
      "**           $$$",
      "/*           $$$",
      "             $$$",
      " ( +  %      $$$",
      "   ,  &      $$$",
      "/*           $$$",
      "**           $$$"
    ],
    [
      "*/              ",
      "**            ..",
      "*/             -",
      "*******         ",
      "*******     !!!!",
      "*******     !!!!",
      "**          !!!!",
      "**              ",
      "**              ",
      "**           $$$",
      "/*           $$$",
      "             $$$",
      " )           $$$",
      "             $$$",
      "/*           $$$",
      "**           $$$"
    ],
    [
      "*/              ",
      "**            ..",
      "*/             -",
      "*******         ",
      "*******     !!!!",
      "*******     !!!!",
      "**          !!!!",
      "**              ",
      "**              ",
      "**           $$$",
      "/*           $$$",
      "             $$$",
      "             $$$",
      "             $$$",
      "/*           $$$",
      "**           $$$"
    ]
  ],
  "palette": {
    "palette": [
      {
        "char": "!",
        "block": "immersiveengineering:concrete_reinforced"
      },
      {
        "char": "$",
        "block": "immersiveengineering:crate"
      },
      {
        "char": "%",
        "block": "minecraft:brown_bed[facing=south,occupied=false,part=foot]"
      },
      {
        "char": "&",
        "block": "minecraft:brown_bed[facing=south,occupied=false,part=head]"
      },
      {
        "char": "'",
        "block": "kubejs:ruined_composter"
      },
      {
        "char": "(",
        "block": "minecraft:dark_oak_door[facing=west,half=lower,hinge=left,open=false,powered=false]"
      },
      {
        "char": ")",
        "block": "minecraft:dark_oak_door[facing=west,half=upper,hinge=left,open=false,powered=false]"
      },
      {
        "char": "*",
        "block": "minecraft:deepslate"
      },
      {
        "char": "+",
        "block": "minecraft:gray_bed[facing=south,occupied=false,part=foot]"
      },
      {
        "char": ",",
        "block": "minecraft:gray_bed[facing=south,occupied=false,part=head]"
      },
      {
        "char": "-",
        "block": "minecraft:ladder[facing=south,waterlogged=false]"
      },
      {
        "char": ".",
        "block": "minecraft:polished_deepslate"
      },
      {
        "char": "/",
        "block": "minecraft:tuff"
      },
      {
        "char": "0",
        "block": "kubejs:ruined_cauldron"
      }
    ]
  }
}
