{
  "xsize": 16,
  "zsize": 16,
  "slices": [
    [
      "((((((((((((((((",
      "((((((((((((((((",
      "((((((((((((((((",
      "((((((((((((((((",
      "((((((((((((((((",
      "((((((((((((((((",
      "((((((((((((((((",
      "((((((((((((((((",
      "((((((((((((((((",
      "((((((((((((((((",
      "((((((((((((((((",
      "((((((((((((((((",
      "((((((((((((((((",
      "((((((((((((((((",
      "((((((((((((((((",
      "(((((((((((((((("
    ],
    [
      "    //      //  ",
      "    //      //  ",
      "    //      //  ",
      "    //      //  ",
      "2222222222222222",
      "2222222222222222",
      "2222222222222222",
      "2222222222222222",
      "2222222222222222",
      "2222222222222222",
      "2222222222222222",
      "2222222222222222",
      "2222222222222222",
      "2222222222222222",
      "2222222222222222",
      "2222222222222222"
    ],
    [
      "    //      //  ",
      "    //      //  ",
      "    //      //  ",
      "    //  **  //  ",
      "&$$$$$$$**$$$$$$",
      "        **      ",
      "                ",
      "       0    %   ",
      "                ",
      "                ",
      "+111111111+11111",
      "                ",
      "   ))))    )))) ",
      "   ))))    )))) ",
      "   ))))    )))) ",
      "   ))))    )))) "
    ],
    [
      "                ",
      "                ",
      "    *           ",
      "    --- **  --- ",
      "'$$$$$$$**$$$$$$",
      "        **      ",
      "                ",
      "                ",
      "                ",
      "                ",
      ",111111111,11111",
      "                ",
      "   ))))    )))) ",
      "   ))))    )))) ",
      "   ))))    )))) ",
      "   ))))    )))) "
    ],
    [
      "                ",
      "                ",
      "    *           ",
      "        **      ",
      "$$$.!!!.**$.!!!.",
      "        **      ",
      "                ",
      "                ",
      "                ",
      "                ",
      "1111111111111111",
      "                ",
      "   ))))    )))) ",
      "   ))))    )))) ",
      "   ))))    )))) ",
      "   ))))    )))) "
    ],
    [
      "                ",
      "                ",
      "    *           ",
      "        **      ",
      "$$$.!!!.**$.!!!.",
      "        **      ",
      "                ",
      "                ",
      "                ",
      "                ",
      "1111111111111111",
      "                ",
      "   ))))    )))) ",
      "   ))))    )))) ",
      "   ))))    )))) ",
      "   ))))    )))) "
    ]
  ],
  "palette": {
    "palette": [
      {
        "char": "!",
        "block": "create:framed_glass"
      },
      {
        "char": "$",
        "block": "immersiveengineering:concrete_brick_cracked"
      },
      {
        "char": "%",
        "block": "kubejs:ruined_crafting_table"
      },
      {
        "char": "&",
        "block": "minecraft:dark_oak_door[facing=north,half=lower,hinge=right,open=false,powered=false]"
      },
      {
        "char": "'",
        "block": "minecraft:dark_oak_door[facing=north,half=upper,hinge=right,open=false,powered=false]"
      },
      {
        "char": "(",
        "block": "minecraft:deepslate"
      },
      {
        "char": ")",
        "block": "minecraft:oxidized_copper"
      },
      {
        "char": "*",
        "block": "minecraft:polished_deepslate"
      },
      {
        "char": "+",
        "block": "minecraft:spruce_door[facing=south,half=lower,hinge=left,open=false,powered=false]"
      },
      {
        "char": ",",
        "block": "minecraft:spruce_door[facing=south,half=upper,hinge=left,open=false,powered=false]"
      },
      {
        "char": "-",
        "block": "minecraft:spruce_slab[type=bottom,waterlogged=false]"
      },
      {
        "char": ".",
        "block": "minecraft:stripped_spruce_log[axis=y]"
      },
      {
        "char": "/",
        "block": "minecraft:water"
      },
      {
        "char": "0",
        "block": "kubejs:ruined_cauldron"
      },
      {
        "char": "1",
        "block": "tfmg:cinder_block"
      },
      {
        "char": "2",
        "block": "tfmg:factory_floor"
      }
    ]
  }
}
