{
  "xsize": 16,
  "zsize": 16,
  "slices": [
    [
      "!  &&&&    &&&& ",
      "!  &&&&    &&&& ",
      "! )&&&&    &&&& ",
      "!               ",
      "!               ",
      "!               ",
      "!               ",
      "!               ",
      "!               ",
      " !!!  !!!!!!  !!",
      " *              ",
      " %              ",
      " %              ",
      " %              ",
      " %              ",
      " %              "
    ],
    [
      "!               ",
      "!               ",
      "!               ",
      "! )             ",
      "!               ",
      "!               ",
      "!               ",
      "!               ",
      "!   &&&     &&& ",
      " !!!&&&!!!!!&&&!",
      " *  &&&     &&& ",
      " %  &&&     &&& ",
      " %  &&&     &&& ",
      " %  &&&     &&& ",
      " %  &&&     &&& ",
      " %  &&&     &&& "
    ],
    [
      "!((((( (((((((((",
      "!((((( (((((((((",
      "!( ((( (((((((((",
      "!( (((((((((((((",
      "!(((((((((((((((",
      "!               ",
      "!               ",
      "!               ",
      "!   &&&     &&& ",
      " !!!&&&!!!!!&&&!",
      " *  &&&     &&& ",
      " %  &&&     &&& ",
      " %  &&&     &&& ",
      " %  &&&     &&& ",
      " %  &&&     &&& ",
      " %  &&&     &&& "
    ],
    [
      "!               ",
      "!            $  ",
      "!               ",
      "!               ",
      "!'''''''''''''''",
      "!               ",
      "!               ",
      "!               ",
      "!   &&&     &&& ",
      "!!!!&&&!!!!!&&&!",
      "%*  &&&     &&& ",
      "%%  &&&     &&& ",
      "%%  &&&     &&& ",
      "%%  &&&     &&& ",
      "%%  &&&     &&& ",
      "%%  &&&     &&& "
    ],
    [
      "!               ",
      "!               ",
      "!               ",
      "!               ",
      "!               ",
      "!               ",
      "!               ",
      "!               ",
      "!   &&&     &&& ",
      "!!!!&&&!!!!!&&&!",
      "%*  &&&     &&& ",
      "%%  &&&     &&& ",
      "%%  &&&     &&& ",
      "%%  &&&     &&& ",
      "%%  &&&     &&& ",
      "%%  &&&     &&& "
    ],
    [
      "!               ",
      "!               ",
      "!               ",
      "!               ",
      "!               ",
      "!               ",
      "!               ",
      "!               ",
      "!   &&&     &&& ",
      "!!!!&&&!!!!!&&&!",
      "%*  &&&     &&& ",
      "%%  &&&     &&& ",
      "%%  &&&     &&& ",
      "%%  &&&     &&& ",
      "%%  &&&     &&& ",
      "%%  &&&     &&& "
    ]
  ],
  "palette": {
    "palette": [
      {
        "char": "!",
        "block": "immersiveengineering:concrete_brick_cracked"
      },
      {
        "char": "$",
        "block": "minecraft:cartography_table"
      },
      {
        "char": "%",
        "block": "minecraft:deepslate"
      },
      {
        "char": "&",
        "block": "minecraft:oxidized_copper"
      },
      {
        "char": "'",
        "block": "minecraft:oxidized_copper_grate"
      },
      {
        "char": "(",
        "block": "minecraft:polished_andesite"
      },
      {
        "char": ")",
        "block": "minecraft:polished_andesite_stairs[facing=south,half=bottom,shape=straight,waterlogged=false]"
      },
      {
        "char": "*",
        "block": "minecraft:tuff"
      }
    ]
  }
}
