{
  "xsize": 16,
  "zsize": 16,
  "slices": [
    [
      "%%%%%%!!!!!!!!!!",
      "!!!!!!!!!!!!!!!!",
      "!!!!!!!!!!!!!!!!",
      "!!!!!!!!!!!!!!!!",
      "!!!!!!!!!!!!!!!!",
      "!!!!!!!!!!!!!!!!",
      "!!!!!!%%%%%%%%%%",
      "%%%%%%%%%%%%%%%%",
      "%%%%%%%%%%%%%%%%",
      "%%%%%%%%%%%%%%%%",
      "%%%%%%%%%%%%%%%%",
      "%%%%%%%%%%%%%%%%",
      "%%%%%%%%%%%%%%%%",
      "%%%%%%%%%%%%%%%%",
      "%%%%%%%%%%%%%%%%",
      "%%%%%%%%%%%%%%%%"
    ],
    [
      "%%    !!!!!!!!!!",
      "!!!!!!!!!!!!!!!!",
      "!!!!!!!!!!!!!!!!",
      "!!!!!!!!!!!!!!!!",
      "!!!!!!!!!!!!!!!!",
      "!!!!!!!!!!!!!!!!",
      "!!!!!!((((((((((",
      "%%((((((((((((((",
      "%%((((((((((((((",
      "%%((((((((((((((",
      "%%((((((((((((((",
      "%%((((((((((((((",
      "%%((((((((((((((",
      "%'((((((((((((((",
      "%%((((((((((((((",
      "%'(((((((((((((("
    ],
    [
      "&%    !!!!!!!!!!",
      "&!!!!!!!!!!!!!!!",
      "&!!!!!!!!!!!!!!!",
      "&!!!!!!!!!!!!!!!",
      "&!!!!!!!!!!!!!!!",
      "&!!!!!!!!!!!!!!!",
      "&!!!!!((((((((((",
      "&%((((((((((((((",
      "&%((((((((((((((",
      "&%((((((((((((((",
      "&%((((((((((((((",
      "&%((((((((((((((",
      "&%((((((((((((((",
      "&'((((((((((((((",
      "&%((((((((((((((",
      "&'(((((((((((((("
    ],
    [
      " %    !!!!!!!!!!",
      "&&!!!!!!!!!!!!!!",
      " !!!!!!!!!!!!!!!",
      " !!!!!!!!!!!!!!!",
      "!!!!!!!!!!!!!!!!",
      "!!!!!!!!!!!!!!!!",
      "!!!!!!((((((((((",
      " %((((((((((((((",
      " %((((((((((((((",
      " %((((((((((((((",
      " %((((((((((((((",
      " %((((((((((((((",
      " %((((((((((((((",
      " '((((((((((((((",
      " %((((((((((((((",
      "$'(((((((((((((("
    ],
    [
      " %    !!!!!!!!!!",
      "&&!!!!!!!!!!!!!!",
      " !!!!!!!!!!!!!!!",
      " !!!!!!!!!!!!!!!",
      "!!!!!!!!!!!!!!!!",
      "!!!!!!!!!!!!!!!!",
      "!!!!!!((((((((((",
      " %((((((((((((((",
      " %((((((((((((((",
      " %((((((((((((((",
      " %((((((((((((((",
      " %((((((((((((((",
      " %((((((((((((((",
      " '((((((((((((((",
      " %((((((((((((((",
      " '(((((((((((((("
    ],
    [
      " %    !!!!!!!!!!",
      "&&!!!!!!!!!!!!!!",
      " !!!!!!!!!!!!!!!",
      " !!!!!!!!!!!!!!!",
      "!!!!!!!!!!!!!!!!",
      "!!!!!!!!!!!!!!!!",
      "!!!!!!((((((((((",
      " %((((((((((((((",
      " %((((((((((((((",
      " %((((((((((((((",
      " %((((((((((((((",
      " %((((((((((((((",
      " %((((((((((((((",
      " '((((((((((((((",
      " %((((((((((((((",
      " '(((((((((((((("
    ]
  ],
  "palette": {
    "palette": [
      {
        "char": "!",
        "block": "immersiveengineering:concrete_reinforced"
      },
      {
        "char": "$",
        "block": "minecraft:chest[facing=west,type=single,waterlogged=false]",
        "tag": {
          "id": "minecraft:chest",
          "LootTable": "infinite_domain:chests/wasteland_refuge"
        }
      },
      {
        "char": "%",
        "block": "minecraft:deepslate"
      },
      {
        "char": "&",
        "block": "minecraft:polished_deepslate"
      },
      {
        "char": "'",
        "block": "minecraft:tuff"
      },
      {
        "char": "(",
        "block": "minecraft:water"
      }
    ]
  }
}
