{
  "xsize": 16,
  "zsize": 16,
  "slices": [
    [
      "))))))))))))))))",
      "))))))))))))))))",
      "))))))))))))))))",
      "))))))))))))))))",
      "))))))))))))))))",
      "))))))))))))))))",
      "))))))))))))))))",
      "))))))))))))))))",
      "))))))))))))))))",
      "))))))))))))))))",
      "))))))))))))))))",
      "))))))))))))))))",
      "))))))))))))))))",
      "))))))))))))))))",
      "))))))))))))))))",
      "))))))))))))))))"
    ],
    [
      "    11      11  ",
      "    11      11  ",
      "    11      11  ",
      "    11      11  ",
      "4444444444444444",
      "4444444444444444",
      "4444444444444444",
      "4444444444444444",
      "44444444***44444",
      "44444444***44444",
      "44444444***44444",
      "4444444444444444",
      "444444444444***4",
      "444444444444***4",
      "444444444444***4",
      "4444444444444444"
    ],
    [
      "    11      11  ",
      "    11      11  ",
      "    11      11  ",
      "    11  ,,  11  ",
      "'$$$$$$$,,$$$$$$",
      "        ,,      ",
      "                ",
      "       2    &   ",
      "        ***     ",
      "        ***     ",
      "-3333333***33333",
      "                ",
      "   ++++    +*** ",
      "   ++++    +*** ",
      "   ++++    +*** ",
      "   ++++    ++++ "
    ],
    [
      "                ",
      "                ",
      "    ,           ",
      "    /// ,,  /// ",
      "($$$$$$$,,$$$$$$",
      "        ,,      ",
      "                ",
      "                ",
      "        ***     ",
      "        ***     ",
      ".3333333***33333",
      "                ",
      "   ++++    +*** ",
      "   ++++    +*** ",
      "   ++++    +*** ",
      "   ++++    ++++ "
    ],
    [
      "                ",
      "                ",
      "    ,           ",
      "        ,,      ",
      "$$$0!!!0,,$0!!!0",
      "        ,,      ",
      "                ",
      "                ",
      "                ",
      "         %      ",
      "3333333333333333",
      "                ",
      "   ++++    +*** ",
      "   ++++    +*** ",
      "   ++++    +*** ",
      "   ++++    ++++ "
    ],
    [
      "                ",
      "                ",
      "    ,           ",
      "        ,,      ",
      "$$$0!!!0,,$0!!!0",
      "        ,,      ",
      "                ",
      "                ",
      "                ",
      "                ",
      "3333333333333333",
      "                ",
      "   ++++    +*** ",
      "   ++++    +*** ",
      "   ++++    +*** ",
      "   ++++    ++++ "
    ]
  ],
  "palette": {
    "palette": [
      {
        "char": "!",
        "block": "create:framed_glass"
      },
      {
        "char": "$",
        "block": "immersiveengineering:concrete_brick_cracked"
      },
      {
        "char": "%",
        "block": "immersiveengineering:concrete_reinforced"
      },
      {
        "char": "&",
        "block": "minecraft:crafting_table"
      },
      {
        "char": "'",
        "block": "minecraft:dark_oak_door[facing=north,half=lower,hinge=right,open=false,powered=false]"
      },
      {
        "char": "(",
        "block": "minecraft:dark_oak_door[facing=north,half=upper,hinge=right,open=false,powered=false]"
      },
      {
        "char": ")",
        "block": "minecraft:deepslate"
      },
      {
        "char": "*",
        "block": "minecraft:gravel"
      },
      {
        "char": "+",
        "block": "minecraft:oxidized_copper"
      },
      {
        "char": ",",
        "block": "minecraft:polished_deepslate"
      },
      {
        "char": "-",
        "block": "minecraft:spruce_door[facing=south,half=lower,hinge=left,open=false,powered=false]"
      },
      {
        "char": ".",
        "block": "minecraft:spruce_door[facing=south,half=upper,hinge=left,open=false,powered=false]"
      },
      {
        "char": "/",
        "block": "minecraft:spruce_slab[type=bottom,waterlogged=false]"
      },
      {
        "char": "0",
        "block": "minecraft:stripped_spruce_log[axis=y]"
      },
      {
        "char": "1",
        "block": "minecraft:water"
      },
      {
        "char": "2",
        "block": "minecraft:water_cauldron[level=3]"
      },
      {
        "char": "3",
        "block": "tfmg:cinder_block"
      },
      {
        "char": "4",
        "block": "tfmg:factory_floor"
      }
    ]
  }
}
