{
  "xsize": 16,
  "zsize": 16,
  "slices": [
    [
      "   %%%%    %%%% ",
      "   %%%%    %%%% ",
      "   %%%%    %%%% ",
      "                ",
      "                ",
      "                ",
      "                ",
      "                ",
      "                ",
      "!!!!  !!!!!!  !!",
      "               $",
      "               $",
      "               $",
      "               $",
      "               (",
      "               $"
    ],
    [
      "                ",
      "                ",
      "                ",
      "                ",
      "                ",
      "                ",
      "                ",
      "                ",
      "    %%%     %%% ",
      "!!!!%%%!!!!!%%%!",
      "    %%%     %%%$",
      "    %%%     %%%$",
      "    %%%     %%%$",
      "    %%%     %%%$",
      "    %%%     %%%(",
      "    %%%     %%%$"
    ],
    [
      " ''''''         ",
      " ''''''         ",
      " ''''''         ",
      "''''''''''''''''",
      "''''''''''''''''",
      "                ",
      "                ",
      "                ",
      "    %%%     %%% ",
      "!!!!%%%!!!!!%%%!",
      "    %%%     %%%$",
      "    %%%     %%%$",
      "    %%%     %%%$",
      "    %%%     %%%$",
      "    %%%     %%%(",
      "    %%%     %%%$"
    ],
    [
      "                ",
      "                ",
      "                ",
      "                ",
      "&&&&&&&&&&&&&&&&",
      "                ",
      "                ",
      "                ",
      "    %%%     %%% ",
      "!!!!%%%!!!!!%%%!",
      "    %%%     %%%$",
      "    %%%     %%%$",
      "    %%%     %%%$",
      "    %%%     %%%$",
      "    %%%     %%%(",
      "    %%%     %%%$"
    ],
    [
      "                ",
      "                ",
      "                ",
      "                ",
      "                ",
      "                ",
      "                ",
      "                ",
      "    %%%     %%% ",
      "!!!!%%%!!!!!%%%!",
      "    %%%     %%%$",
      "    %%%     %%%$",
      "    %%%     %%%$",
      "    %%%     %%%$",
      "    %%%     %%%(",
      "    %%%     %%%$"
    ],
    [
      "                ",
      "                ",
      "                ",
      "                ",
      "                ",
      "                ",
      "                ",
      "                ",
      "    %%%     %%% ",
      "!!!!%%%!!!!!%%%!",
      "    %%%     %%%$",
      "    %%%     %%%$",
      "    %%%     %%%$",
      "    %%%     %%%$",
      "    %%%     %%%(",
      "    %%%     %%%$"
    ]
  ],
  "palette": {
    "palette": [
      {
        "char": "!",
        "block": "immersiveengineering:concrete_brick_cracked"
      },
      {
        "char": "$",
        "block": "minecraft:deepslate"
      },
      {
        "char": "%",
        "block": "minecraft:oxidized_copper"
      },
      {
        "char": "&",
        "block": "minecraft:oxidized_copper_grate"
      },
      {
        "char": "'",
        "block": "minecraft:polished_andesite"
      },
      {
        "char": "(",
        "block": "minecraft:tuff"
      }
    ]
  }
}
