{
  "xsize": 16,
  "zsize": 16,
  "slices": [
    [
      "!               ",
      "!               ",
      "!$$$&     $$$$$$",
      "!$&$$     $$$$$$",
      "!$$$&     $$$$$$",
      "!$&$$     $$$$$$",
      "!$$$$     $$$$$&",
      "!$$$$%%%%%$$$&$$",
      "!$$$$     $&$$$&",
      "               $",
      "               &",
      "               $",
      "               $",
      "               $",
      "               $",
      "               $"
    ],
    [
      "!               ",
      "!               ",
      "!$$$&     $$$$$$",
      "!$&$$     $$$$$$",
      "!$$$&     $$$$$$",
      "!$&$$     $$$$$$",
      "!$$$$     $$$$$&",
      "!$$$$%%%%%$$$&$$",
      "!$$$$     $&$$$&",
      "               $",
      "               &",
      "               $",
      "               $",
      "               $",
      "               $",
      "               $"
    ],
    [
      "!               ",
      "!               ",
      "!$$$&     $$$$$$",
      "!$&$$     $$$$$$",
      "!$$$&     $$$$$$",
      "!$&$$     $$$$$$",
      "!$$$$     $$$$$&",
      "!$$$$     $$$&$$",
      "!$$$$     $&$$$&",
      "               $",
      "               &",
      "               $",
      "               $",
      "               $",
      "               $",
      "               $"
    ],
    [
      "!               ",
      "!               ",
      "!$$$&$$$&$$$$$$$",
      "!$&$$$&$$$$$$$$$",
      "!$$$&$$$$$$$$$$$",
      "!$&$$$$$$$$$$$$$",
      "!$$$$$$$$$$$$$$&",
      "!$$$$$$$$$$$$&$$",
      "!$$$$$$$$$$&$$$&",
      "!$$$$$$$$&$$$&$$",
      "$$$$$$$&$$$&$$$&",
      "$$$$$&$$$&$$$&$$",
      "$$$&$$$&$$$&$$$$",
      "$&$$$&$$$&$$$$$$",
      "$$$&$$$&$$$$$$$$",
      "$&$$$&$$$$$$$$$$"
    ],
    [
      "!               ",
      "!               ",
      "!$$$&$$$&$$$$$$$",
      "!$&$$$&$$$$$$$$$",
      "!$$$&$$$$$$$$$$$",
      "!$&$$$$$$$$$$$$$",
      "!$$$$$$$$$$$$$$&",
      "!$$$$$$$$$$$$&$$",
      "!$$$$$$$$$$&$$$&",
      "!$$$$$$$$&$$$&$$",
      "$$$$$$$&$$$&$$$&",
      "$$$$$&$$$&$$$&$$",
      "$$$&$$$&$$$&$$$$",
      "$&$$$&$$$&$$$$$$",
      "$$$&$$$&$$$$$$$$",
      "$&$$$&$$$$$$$$$$"
    ],
    [
      "!               ",
      "!               ",
      "!$$$&$$$&$$$$$$$",
      "!$&$$$&$$$$$$$$$",
      "!$$$&$$$$$$$$$$$",
      "!$&$$$$$$$$$$$$$",
      "!$$$$$$$$$$$$$$&",
      "!$$$$$$$$$$$$&$$",
      "!$$$$$$$$$$&$$$&",
      "!$$$$$$$$&$$$&$$",
      "$$$$$$$&$$$&$$$&",
      "$$$$$&$$$&$$$&$$",
      "$$$&$$$&$$$&$$$$",
      "$&$$$&$$$&$$$$$$",
      "$$$&$$$&$$$$$$$$",
      "$&$$$&$$$$$$$$$$"
    ]
  ],
  "palette": {
    "palette": [
      {
        "char": "!",
        "block": "immersiveengineering:concrete_brick_cracked"
      },
      {
        "char": "$",
        "block": "minecraft:deepslate"
      },
      {
        "char": "%",
        "block": "minecraft:stripped_dark_oak_log[axis=y]"
      },
      {
        "char": "&",
        "block": "minecraft:tuff"
      }
    ]
  }
}
