{
  "xsize": 16,
  "zsize": 16,
  "slices": [
    [
      "%%%%%%%%%%%%%%%%",
      "%%%%%%%%%%%%%%%%",
      "%%%%%%%%%%%%%%%%",
      "%%%%%%%%%%%%%%%%",
      "%%%%%%%%%%%%%%%%",
      "%%%%%%%%%%%%%%%%",
      "%%%%%%%%%%%%%%%%",
      "%%%%%%%%%%%%%%%%",
      "%%%%%%%%%%%%%%%%",
      "%%%%%%%%%%%%%%%%",
      "%%%%%%%%%%%%%%%%",
      "%%%%%%%%%%%%%%%%",
      "%%%%%%%%%%%%%%%%",
      "%%%%%%%%%%%%%%%%",
      "%%%%%%%%%%%%%%%%",
      "%%%%%%%%%%%%%%%%"
    ],
    [
      "++++++++++++++++",
      "++++++++++++++++",
      "++++++++++++++++",
      "++++++++++++++++",
      "++++++++++++++++",
      "++++++++++++++++",
      "++++++++++++++++",
      "++++++++++++++++",
      "++++++++++++++++",
      "++++++++++++++++",
      "               %",
      "               %",
      "               %",
      "               %",
      "               )",
      "               %"
    ],
    [
      "   &&&&    &&&& ",
      "   &&&&    &&&& ",
      "   &&&&    &&&& ",
      "                ",
      "                ",
      "****'*******'***",
      "                ",
      "              $ ",
      "                ",
      "!!!!  !!!!!!  !!",
      "               %",
      "               %",
      "               %",
      "               %",
      "               )",
      "               %"
    ],
    [
      "   &&&&    &&&& ",
      "   &&&&    &&&& ",
      "   &&&&    &&&& ",
      "                ",
      "                ",
      "****(*******(***",
      "                ",
      "                ",
      "                ",
      "!!!!  !!!!!!  !!",
      "               %",
      "               %",
      "               %",
      "               %",
      "               )",
      "               %"
    ],
    [
      "   &&&&    &&&& ",
      "   &&&&    &&&& ",
      "   &&&&    &&&& ",
      "                ",
      "                ",
      "****************",
      "                ",
      "                ",
      "                ",
      "!!!!  !!!!!!  !!",
      "               %",
      "               %",
      "               %",
      "               %",
      "               )",
      "               %"
    ],
    [
      "   &&&&    &&&& ",
      "   &&&&    &&&& ",
      "   &&&&    &&&& ",
      "                ",
      "                ",
      "****************",
      "                ",
      "                ",
      "                ",
      "!!!!  !!!!!!  !!",
      "               %",
      "               %",
      "               %",
      "               %",
      "               )",
      "               %"
    ]
  ],
  "palette": {
    "palette": [
      {
        "char": "!",
        "block": "immersiveengineering:concrete_brick_cracked"
      },
      {
        "char": "$",
        "block": "minecraft:chest[facing=west,type=single,waterlogged=false]",
        "tag": {
          "id": "minecraft:chest",
          "LootTable": "infinite_domain:chests/wasteland_industrial"
        }
      },
      {
        "char": "%",
        "block": "minecraft:deepslate"
      },
      {
        "char": "&",
        "block": "minecraft:oxidized_copper"
      },
      {
        "char": "'",
        "block": "minecraft:spruce_door[facing=south,half=lower,hinge=left,open=false,powered=false]"
      },
      {
        "char": "(",
        "block": "minecraft:spruce_door[facing=south,half=upper,hinge=left,open=false,powered=false]"
      },
      {
        "char": ")",
        "block": "minecraft:tuff"
      },
      {
        "char": "*",
        "block": "tfmg:cinder_block"
      },
      {
        "char": "+",
        "block": "tfmg:factory_floor"
      }
    ]
  }
}
