{
  "xsize": 16,
  "zsize": 16,
  "slices": [
    [
      "&&&&&&&&&&&&&&&&",
      "&&&&&&&&&&&&&&&&",
      "&&&&&&&&&&&&&&&&",
      "&&&&&&&&&&&&&&&&",
      "&&&&&&&&&&&&&&&&",
      "&&&&&&&&&&&&&&&&",
      "&&&&&&&&&&&&&&&&",
      "&&&&&&&&&&&&&&&&",
      "&&&&&&&&&&&&&&&&",
      "&&&&&&&&&&&&&&&&",
      "&&&&&&&&&&&&&&&&",
      "&&&&&&&&&&&&&&&&",
      "&&&&&&&&&&&&&&&&",
      "&&&&&&&&&&&&&&&&",
      "&&&&&&&&&&&&&&&&",
      "&&&&&&&&&&&&&&&&"
    ],
    [
      "&&&&&&&&&&&*&&&*",
      "&&&&&&&&&*&&&*&&",
      "&&&&&&&*&&&*&&&*",
      "&&&&&*&&&*&&&*&&",
      "&&&*&&&*&&&*&&&&",
      "&*&&&*&&&*&&&&&&",
      "&&&*&&&*&&&&&&&&",
      "&*&&&*&&&&&&&&&&",
      "&&&*&&&&&&&&&&&&",
      "&*&&&&&&&&&&&&&&",
      "&&&&&&&&&&&&&&*&",
      "&&&&&&&&&&&&*&&&",
      "&&&&&&&&&&*&&&*&",
      "                ",
      "                ",
      "                "
    ],
    [
      "&&))))))))))))))",
      "&&))))))))))))))",
      "&&&&&&&)))))&&&*",
      "&&&&&*&)))))&*&&",
      "&&&*&&&)))))&&&&",
      "&*&&&*&)))))&&&&",
      "&&&*&&&*&&&&&&&&",
      "&*&&&*&&&&&&&&&&",
      "&&&*&&&&&&&&&&&&",
      "&*&&&&&&&&&&&&&&",
      "&&&&&&&&&&&&&&*&",
      "&&&&&&&&&&&&*&&&",
      "&&&&&&&&&&*&&&*&",
      "                ",
      "                ",
      "                "
    ],
    [
      "&& '  !         ",
      "&& (  $         ",
      "&&&&&&&     &&&*",
      "&&&&&*&  %  &*&&",
      "&&&*&&&     &&&&",
      "&*&&&*&     &&&&",
      "&&&*&&&*&&&&&&&&",
      "&*&&&*&&&&&&&&&&",
      "&&&*&&&&&&&&&&&&",
      "&*&&&&&&&&&&&&&&",
      "&&&&&&&&&&&&&&*&",
      "&&&&&&&&&&&&*&&&",
      "&&&&&&&&&&*&&&*&",
      "                ",
      "                ",
      "                "
    ],
    [
      "&&              ",
      "&&              ",
      "&&&&&&&     &&&*",
      "&&&&&*&     &*&&",
      "&&&*&&&     &&&&",
      "&*&&&*&     &&&&",
      "&&&*&&&*&&&&&&&&",
      "&*&&&*&&&&&&&&&&",
      "&&&*&&&&&&&&&&&&",
      "&*&&&&&&&&&&&&&&",
      "&&&&&&&&&&&&&&*&",
      "&&&&&&&&&&&&*&&&",
      "&&&&&&&&&&*&&&*&",
      "                ",
      "                ",
      "                "
    ],
    [
      "&&              ",
      "&&              ",
      "&&&&&&&     &&&*",
      "&&&&&*&     &*&&",
      "&&&*&&&     &&&&",
      "&*&&&*&     &&&&",
      "&&&*&&&*&&&&&&&&",
      "&*&&&*&&&&&&&&&&",
      "&&&*&&&&&&&&&&&&",
      "&*&&&&&&&&&&&&&&",
      "&&&&&&&&&&&&&&*&",
      "&&&&&&&&&&&&*&&&",
      "&&&&&&&&&&*&&&*&",
      "                ",
      "                ",
      "                "
    ]
  ],
  "palette": {
    "palette": [
      {
        "char": "!",
        "block": "minecraft:brown_bed[facing=south,occupied=false,part=foot]"
      },
      {
        "char": "$",
        "block": "minecraft:brown_bed[facing=south,occupied=false,part=head]"
      },
      {
        "char": "%",
        "block": "kubejs:ruined_campfire[facing=north]"
      },
      {
        "char": "&",
        "block": "minecraft:deepslate"
      },
      {
        "char": "'",
        "block": "minecraft:gray_bed[facing=south,occupied=false,part=foot]"
      },
      {
        "char": "(",
        "block": "minecraft:gray_bed[facing=south,occupied=false,part=head]"
      },
      {
        "char": ")",
        "block": "minecraft:polished_deepslate"
      },
      {
        "char": "*",
        "block": "minecraft:tuff"
      }
    ]
  }
}
