{
  "xsize": 16,
  "zsize": 16,
  "slices": [
    [
      "((((((((((((((((",
      "((((((((((((((((",
      "((((((((((((((((",
      "((((((((((((((((",
      "((((((((((((((((",
      "((((((((((((((((",
      "((((((((((((((((",
      "((((((((((((((((",
      "((((((((((((((((",
      "((((((((((((((((",
      "((((((((((((((((",
      "((((((((((((((((",
      "((((((((((((((((",
      "((((((((((((((((",
      "((((((((((((((((",
      "(((((((((((((((("
    ],
    [
      "    11      11  ",
      "    11      11  ",
      "    11      11  ",
      "    11      11  ",
      "3333333333333333",
      "3333333333333333",
      "3333333333333333",
      "3333333333333333",
      "3333333333333333",
      "3333333333333333",
      "3333333333333333",
      "3333333333333333",
      "3333333333333333",
      "3333333333333333",
      "3333333333333333",
      "3333333333333333"
    ],
    [
      "    11      11  ",
      "    11      11  ",
      "    11      11  ",
      "++  11  ++  11  ",
      "++$$$$$$++$$$$$&",
      "++      ++      ",
      "$          %%%% ",
      "$  ..      %%%% ",
      "$  /       %%%% ",
      "$               ",
      "$22222,222222222",
      "$               ",
      "$  ))))    )))) ",
      "$  ))))    )))) ",
      "$ *))))    )))) ",
      "$  ))))    )))) "
    ],
    [
      "                ",
      "                ",
      "            +   ",
      "++...   ++...   ",
      "++$$$$$$++$$$$$'",
      "++      ++      ",
      "$          %%%% ",
      "$      4   %%%% ",
      "$          %%%% ",
      "$               ",
      "$22222-222222222",
      "$               ",
      "$  ))))    )))) ",
      "$  ))))    )))) ",
      "$  ))))    )))) ",
      "$ *))))    )))) "
    ],
    [
      "                ",
      "                ",
      "            +   ",
      "++      ++      ",
      "+0!!!0$$+0!!!0$$",
      "++      ++      ",
      "$          %%%% ",
      "$          %%%% ",
      "$          %%%% ",
      "$               ",
      "$222222222222222",
      "$               ",
      "$  ))))    )))) ",
      "$  ))))    )))) ",
      "$  ))))    )))) ",
      "$  ))))    )))) "
    ],
    [
      "                ",
      "                ",
      "            +   ",
      "++      ++      ",
      "+0!!!0$$+0!!!0$$",
      "++      ++      ",
      "$               ",
      "$               ",
      "$               ",
      "$               ",
      "$222222222222222",
      "$               ",
      "$  ))))    )))) ",
      "$  ))))    )))) ",
      "$  ))))    )))) ",
      "$  ))))    )))) "
    ]
  ],
  "palette": {
    "palette": [
      {
        "char": "!",
        "block": "create:framed_glass"
      },
      {
        "char": "$",
        "block": "immersiveengineering:concrete_brick_cracked"
      },
      {
        "char": "%",
        "block": "immersiveengineering:crate"
      },
      {
        "char": "&",
        "block": "minecraft:dark_oak_door[facing=north,half=lower,hinge=left,open=false,powered=false]"
      },
      {
        "char": "'",
        "block": "minecraft:dark_oak_door[facing=north,half=upper,hinge=left,open=false,powered=false]"
      },
      {
        "char": "(",
        "block": "minecraft:deepslate"
      },
      {
        "char": ")",
        "block": "minecraft:oxidized_copper"
      },
      {
        "char": "*",
        "block": "minecraft:polished_andesite_stairs[facing=south,half=bottom,shape=straight,waterlogged=false]"
      },
      {
        "char": "+",
        "block": "minecraft:polished_deepslate"
      },
      {
        "char": ",",
        "block": "minecraft:spruce_door[facing=south,half=lower,hinge=left,open=false,powered=false]"
      },
      {
        "char": "-",
        "block": "minecraft:spruce_door[facing=south,half=upper,hinge=left,open=false,powered=false]"
      },
      {
        "char": ".",
        "block": "minecraft:spruce_slab[type=bottom,waterlogged=false]"
      },
      {
        "char": "/",
        "block": "minecraft:spruce_stairs[facing=north,half=bottom,shape=straight,waterlogged=false]"
      },
      {
        "char": "0",
        "block": "minecraft:stripped_spruce_log[axis=y]"
      },
      {
        "char": "1",
        "block": "minecraft:water"
      },
      {
        "char": "2",
        "block": "tfmg:cinder_block"
      },
      {
        "char": "3",
        "block": "tfmg:factory_floor"
      },
      {
        "char": "4",
        "block": "the_wasteland_reworked:radio"
      }
    ]
  }
}
