{
  "xsize": 16,
  "zsize": 16,
  "slices": [
    [
      "         '      ",
      "         '      ",
      "         '      ",
      "         '      ",
      "         '      ",
      "         '      ",
      "         '      ",
      "         '      ",
      "''''''''''      ",
      "                ",
      "                ",
      "                ",
      "                ",
      "                ",
      "                ",
      "                "
    ],
    [
      "         '      ",
      "         '      ",
      "         '      ",
      "         '      ",
      "         '      ",
      "         '      ",
      "         '      ",
      "         '      ",
      "''''''''''      ",
      "                ",
      "                ",
      "                ",
      "                ",
      "                ",
      "                ",
      "                "
    ],
    [
      "&&&&&&&&&&      ",
      "&&&&&&&&&&      ",
      "&&&&&&&&&&      ",
      "&&&&&&&&&&      ",
      "&&&&&&&&&&      ",
      "&&&&&&&&&&      ",
      "&&&&&&&&&&      ",
      "&&&&&&&&&&      ",
      "&&&&&&&&&&      ",
      "                ",
      "                ",
      "                ",
      "                ",
      "                ",
      "                ",
      "                "
    ],
    [
      "                ",
      "                ",
      "!$              ",
      "$$              ",
      "                ",
      "                ",
      "                ",
      "                ",
      "%%%%%%%%%%      ",
      "                ",
      "                ",
      "                ",
      "                ",
      "                ",
      "                ",
      "                "
    ]
  ],
  "palette": {
    "palette": [
      {
        "char": "!",
        "block": "minecraft:lightning_rod[facing=up,waterlogged=false]"
      },
      {
        "char": "$",
        "block": "minecraft:oxidized_copper"
      },
      {
        "char": "%",
        "block": "minecraft:polished_deepslate"
      },
      {
        "char": "&",
        "block": "minecraft:weathered_cut_copper"
      },
      {
        "char": "'",
        "block": "tfmg:cinder_block"
      }
    ]
  }
}
