{
  "xsize": 16,
  "zsize": 16,
  "slices": [
    [
      "                ",
      "                ",
      "    '           ",
      "    *** ''  *** ",
      "!!!!!!!!''!!!!!!",
      "        ''      ",
      "                ",
      "                ",
      "                ",
      "                ",
      "                ",
      "                ",
      "   %%%%    %%%% ",
      "   %%%%    %%%% ",
      "   %%%%    %%%% ",
      "   %%%%    %%%% "
    ],
    [
      "                ",
      "                ",
      "    '           ",
      "        ''      ",
      "!!!!!!!!''!!!!!!",
      "        ''      ",
      "                ",
      "                ",
      "                ",
      "                ",
      "                ",
      "                ",
      "                ",
      "                ",
      "                ",
      "    $       $   "
    ],
    [
      "                ",
      "                ",
      "(((((           ",
      "(((((   ''      ",
      "(((((!!!''!!!!!!",
      "(((((   ''      ",
      "                ",
      "                ",
      "                ",
      "                ",
      "                ",
      "&&&&&&&&&&&&&&&&",
      " &&&&&&&&& &&&&&",
      " &&&&&&&&& &&&&&",
      " &&&&&&&&& &&&&&",
      " &&&&&&&&& &&&&&"
    ],
    [
      "                ",
      "                ",
      "                ",
      "        ''      ",
      "!!!!!!!!''!!!!!!",
      "        ''      ",
      "                ",
      "                ",
      "                ",
      "                ",
      "                ",
      "                ",
      "     ))         ",
      "     +          ",
      "                ",
      "                "
    ],
    [
      "                ",
      "                ",
      "                ",
      "        ''      ",
      "!!!!!!!!''!!!!!!",
      "        ''      ",
      "                ",
      "                ",
      "                ",
      "                ",
      "                ",
      "                ",
      "                ",
      "                ",
      "                ",
      "                "
    ],
    [
      "                ",
      "                ",
      "                ",
      "        ''      ",
      "!!!!!!!!''!!!!!!",
      "        ''      ",
      "                ",
      "                ",
      "                ",
      "                ",
      "                ",
      "                ",
      "                ",
      "                ",
      "                ",
      "                "
    ]
  ],
  "palette": {
    "palette": [
      {
        "char": "!",
        "block": "immersiveengineering:concrete_brick_cracked"
      },
      {
        "char": "$",
        "block": "minecraft:lightning_rod[facing=up,waterlogged=false]"
      },
      {
        "char": "%",
        "block": "minecraft:oxidized_copper"
      },
      {
        "char": "&",
        "block": "minecraft:polished_andesite"
      },
      {
        "char": "'",
        "block": "minecraft:polished_deepslate"
      },
      {
        "char": "(",
        "block": "minecraft:smooth_stone_slab[type=top,waterlogged=false]"
      },
      {
        "char": ")",
        "block": "minecraft:spruce_slab[type=bottom,waterlogged=false]"
      },
      {
        "char": "*",
        "block": "minecraft:spruce_slab[type=top,waterlogged=false]"
      },
      {
        "char": "+",
        "block": "minecraft:spruce_stairs[facing=north,half=bottom,shape=straight,waterlogged=false]"
      }
    ]
  }
}
