{
  "xsize": 16,
  "zsize": 16,
  "slices": [
    [
      "1111111111111111",
      "1111111111111111",
      "1111111111111111",
      "1111111111111111",
      "1111111111111111",
      "1111111111111111",
      "1111111111111111",
      "1111111111111111",
      "1111111111111111",
      "1111111111111111",
      "1111111111111111",
      "1111111111111111",
      "1111111111111111",
      "1111111111111111",
      "1111111111111111",
      "1111111111111111"
    ],
    [
      "22              ",
      "22              ",
      "2211811181111111",
      ":181118111111111",
      ":111811111111111",
      ":181111111111111",
      ":111111111111118",
      ":111111111111811",
      ":111111111181118",
      ":111111118111811",
      "1111111811181118",
      "1111181118111811",
      "1118111811181111",
      "1811181118111111",
      "1118111811111111",
      "1811181111111111"
    ],
    [
      "22              ",
      "22   33333      ",
      "2211833333111111",
      "!181133333111111",
      "'111833333111111",
      "!181133333111111",
      "!111133333111118",
      "!111133333111811",
      "!111133333181118",
      "3333333333333331",
      "3333333333333338",
      "3333333333333331",
      "3333333333333331",
      "3333333333333331",
      "3333333333333331",
      "3333333333333331"
    ],
    [
      "!               ",
      "$               ",
      "!1118     111111",
      "!1811 )*  111111",
      "(1118     111111",
      "!1811     111111",
      "!1111     111118",
      "!11117-.77111811",
      "!1111     181118",
      "               1",
      "               8",
      " 9&        5 % 1",
      "               1",
      "      6        1",
      "               1",
      "  4            1"
    ],
    [
      "!               ",
      "!               ",
      "!1118     111111",
      "!1811 +,  111111",
      "!1118     111111",
      "!1811     111111",
      "!1111     111118",
      "!11117/077111811",
      "!1111     181118",
      "               1",
      "               8",
      "               1",
      "               1",
      "               1",
      "               1",
      "               1"
    ],
    [
      "!               ",
      "!               ",
      "!1118     111111",
      "!1811     111111",
      "!1118     111111",
      "!1811     111111",
      "!1111     111118",
      "!111177777111811",
      "!1111     181118",
      "               1",
      "               8",
      "               1",
      "               1",
      "               1",
      "               1",
      "               1"
    ]
  ],
  "palette": {
    "palette": [
      {
        "char": "!",
        "block": "immersiveengineering:concrete_brick_cracked"
      },
      {
        "char": "$",
        "block": "immersiveengineering:concrete_reinforced"
      },
      {
        "char": "%",
        "block": "minecraft:barrel[facing=up,open=false]"
      },
      {
        "char": "&",
        "block": "kubejs:ruined_crafting_table"
      },
      {
        "char": "'",
        "block": "minecraft:dark_oak_door[facing=east,half=lower,hinge=left,open=false,powered=false]"
      },
      {
        "char": "(",
        "block": "minecraft:dark_oak_door[facing=east,half=upper,hinge=left,open=false,powered=false]"
      },
      {
        "char": ")",
        "block": "minecraft:dark_oak_door[facing=north,half=lower,hinge=left,open=false,powered=false]"
      },
      {
        "char": "*",
        "block": "minecraft:dark_oak_door[facing=north,half=lower,hinge=right,open=false,powered=false]"
      },
      {
        "char": "+",
        "block": "minecraft:dark_oak_door[facing=north,half=upper,hinge=left,open=false,powered=false]"
      },
      {
        "char": ",",
        "block": "minecraft:dark_oak_door[facing=north,half=upper,hinge=right,open=false,powered=false]"
      },
      {
        "char": "-",
        "block": "minecraft:dark_oak_door[facing=south,half=lower,hinge=left,open=false,powered=false]"
      },
      {
        "char": ".",
        "block": "minecraft:dark_oak_door[facing=south,half=lower,hinge=right,open=false,powered=false]"
      },
      {
        "char": "/",
        "block": "minecraft:dark_oak_door[facing=south,half=upper,hinge=left,open=false,powered=false]"
      },
      {
        "char": "0",
        "block": "minecraft:dark_oak_door[facing=south,half=upper,hinge=right,open=false,powered=false]"
      },
      {
        "char": "1",
        "block": "minecraft:deepslate"
      },
      {
        "char": "2",
        "block": "minecraft:gravel"
      },
      {
        "char": "3",
        "block": "minecraft:polished_deepslate"
      },
      {
        "char": "4",
        "block": "minecraft:skeleton_skull[rotation=5]"
      },
      {
        "char": "5",
        "block": "kubejs:ruined_smoker[facing=south]"
      },
      {
        "char": "6",
        "block": "minecraft:spawner",
        "tag": {
          "id": "minecraft:mob_spawner",
          "Delay": 320,
          "MinSpawnDelay": 240,
          "MaxSpawnDelay": 720,
          "SpawnCount": 2,
          "MaxNearbyEntities": 6,
          "RequiredPlayerRange": 14,
          "SpawnRange": 4,
          "SpawnData": {
            "entity": {
              "id": "minecraft:zombie"
            }
          },
          "SpawnPotentials": [
            {
              "weight": 1,
              "data": {
                "entity": {
                  "id": "minecraft:zombie"
                }
              }
            }
          ]
        }
      },
      {
        "char": "7",
        "block": "minecraft:stripped_dark_oak_log[axis=y]"
      },
      {
        "char": "8",
        "block": "minecraft:tuff"
      },
      {
        "char": "9",
        "block": "minecraft:white_bed[facing=south,occupied=false,part=foot]"
      },
      {
        "char": ":",
        "block": "tfmg:factory_floor"
      }
    ]
  }
}
