{
  "xsize": 16,
  "zsize": 16,
  "slices": [
    [
      " $ %%%%%%%%%%%%%",
      " $ %%%%%%%%%%%%%",
      " $ %%&&%%%%%%%%%",
      " $ %%'%%%%%%%%%%",
      " $ %%%%%%%%%%%%%",
      " $ %%%%%%%%%%%%%",
      " $ %%%%%%%%%%%%%",
      " $ %%%%%%%%%%%%%",
      " $ %%%%%%%%%%%%%",
      " $ %%%%%%%%%%%%%",
      " $ %%%%%%%%%%%%%",
      " $ %%&&%%%%%%%%%",
      " $ %%'%%%%%%%%%%",
      " $ %%%%%%%%%%%%%",
      " $ %%%%%%%%%%%%%",
      " $ %%%%%%%%%%%%%"
    ],
    [
      " %%%%%%%%%%%%%%%",
      " %%%%%%%%%%%%%%%",
      " %%%%%%%%%%%%%%%",
      " %%%%%%%%%%%%%%%",
      " %%%%%%%%%%%%%%%",
      " %%%%%%%%%%%%%%%",
      " %%%%%%%%%%%%%%%",
      " %%%%%%%%%%%%%%%",
      " %%%%%%%%%%%%%%%",
      " %%%%%%%%%%%%%%%",
      " %%%%%%%%%%%%%%%",
      " %%%%%%%%%%%%%%%",
      " %%%%%%%%%%%%%%%",
      " %%%%%%%%%%%%%%%",
      " %%%%%%%%%%%%%%%",
      " %%%%%%%%%%%%%%%"
    ],
    [
      "  !             ",
      "  !             ",
      "  !             ",
      "  !             ",
      "  !             ",
      "  !             ",
      "  !             ",
      "  !             ",
      "  !             ",
      "  !             ",
      "  !             ",
      "  !             ",
      "  !             ",
      "  !             ",
      "  !             ",
      "  !             "
    ],
    [
      "  !             ",
      "  !             ",
      "  !             ",
      "  !             ",
      "  !             ",
      "  !             ",
      "  !             ",
      "  !             ",
      "  !             ",
      "  !             ",
      "  !             ",
      "  !             ",
      "  !             ",
      "  !             ",
      "  !             ",
      "  !             "
    ],
    [
      "  !             ",
      "  !             ",
      "  !             ",
      "  !             ",
      "  !             ",
      "  !             ",
      "  !             ",
      "  !             ",
      "  !             ",
      "  !             ",
      "  !             ",
      "  !             ",
      "  !             ",
      "  !             ",
      "  !             ",
      "  !             "
    ],
    [
      "  !             ",
      "  !             ",
      "  !             ",
      "  !             ",
      "  !             ",
      "  !             ",
      "  !             ",
      "  !             ",
      "  !             ",
      "  !             ",
      "  !             ",
      "  !             ",
      "  !             ",
      "  !             ",
      "  !             ",
      "  !             "
    ]
  ],
  "palette": {
    "palette": [
      {
        "char": "!",
        "block": "immersiveengineering:sheetmetal_steel"
      },
      {
        "char": "$",
        "block": "minecraft:bricks"
      },
      {
        "char": "%",
        "block": "minecraft:smooth_stone"
      },
      {
        "char": "&",
        "block": "minecraft:spruce_slab[type=bottom,waterlogged=false]"
      },
      {
        "char": "'",
        "block": "minecraft:spruce_stairs[facing=north,half=bottom,shape=straight,waterlogged=false]"
      }
    ]
  }
}
