{
  "xsize": 16,
  "zsize": 16,
  "slices": [
    [
      "    ' $         ",
      "    ' $         ",
      "    ' $         ",
      "    ' $         ",
      "    ' $         ",
      "    ' $         ",
      "    ' $         ",
      "    ' $         ",
      "    ' $         ",
      "    ' $         ",
      "    ' $         ",
      "    ' $         ",
      "    ' $         ",
      "    ' $         ",
      "    ' $         ",
      "    ' $         "
    ],
    [
      "   '  $         ",
      "   '  $         ",
      "   '  $         ",
      "   '  $         ",
      "   '  $         ",
      "   '  $         ",
      "   '  $         ",
      "   '  $         ",
      "   '  $         ",
      "   '  $         ",
      "   '  $         ",
      "   '  $         ",
      "   '  $         ",
      "   '  $         ",
      "   '  $         ",
      "   '  $         "
    ],
    [
      "  '   %%%%!!!!!!",
      "  '   %%%%!!!!!!",
      "  '   %%%%!!!!!!",
      "  '   %%%%%%%%%%",
      "  '   %%%%%%%%%%",
      "  '   %%%%%%%%%%",
      "  '   %%%%%%%%%%",
      "  '   %%%%%%%%%%",
      "  '   %%%%%%%%%%",
      "  '   %%%%%%%%%%",
      "  '   %%%%%%%%%%",
      "  '   %%%%!!!!!!",
      "  '   %%%%!!!!!!",
      "  '   %%%%!!!!!!",
      "  '   %%%%%%%%%%",
      "  '   %%%%%%%%%%"
    ],
    [
      " '        !!!!!!",
      " '        !!!!!!",
      " '        !!!!!!",
      " '              ",
      " '              ",
      " '              ",
      " '              ",
      " '              ",
      " '              ",
      " '              ",
      " '              ",
      " '        !!!!!!",
      " '        !!!!!!",
      " '        !!!!!!",
      " '              ",
      " '              "
    ],
    [
      "'         !!!!!!",
      "'         !!!!!!",
      "'         !!!!!!",
      "'               ",
      "'               ",
      "'               ",
      "'               ",
      "'               ",
      "'               ",
      "'               ",
      "'               ",
      "'         !!!!!!",
      "'         !!!!!!",
      "'         !!!!!!",
      "'               ",
      "'               "
    ],
    [
      "          &&&&&&",
      "          &&&&&&",
      "          &&&&&&",
      "          &&&&&&",
      "                ",
      "                ",
      "                ",
      "                ",
      "                ",
      "                ",
      "                ",
      "          &&&&&&",
      "          &&&&&&",
      "          &&&&&&",
      "          &&&&&&",
      "                "
    ]
  ],
  "palette": {
    "palette": [
      {
        "char": "!",
        "block": "create:framed_glass"
      },
      {
        "char": "$",
        "block": "immersiveengineering:sheetmetal_steel"
      },
      {
        "char": "%",
        "block": "minecraft:weathered_cut_copper"
      },
      {
        "char": "&",
        "block": "minecraft:weathered_cut_copper_slab[type=bottom,waterlogged=false]"
      },
      {
        "char": "'",
        "block": "minecraft:weathered_cut_copper_stairs[facing=west,half=bottom,shape=straight,waterlogged=false]"
      }
    ]
  }
}
