{
  "xsize": 16,
  "zsize": 16,
  "slices": [
    [
      "&&%)))))))))))))",
      "%)))))))))))))))",
      ")))))))))))))))&",
      ")))))))))))))&&%",
      ")))))))))))&&%))",
      ")))))))))&&%))))",
      ")))))))&&%))))))",
      ")))))&&%))))))))",
      ")))&&%))))))))))",
      ")&&%))))))))))))",
      "&%))))))))))))))",
      "))))))))))))))))",
      "))))))))))))))&&",
      "))))))))))))&&%)",
      "))))))))))&&%)))",
      "))))))))&&%)))))"
    ],
    [
      "+(((((((((((((((",
      "+(((((((((((((((",
      "+(((((((((((((((",
      "+(((((((((((((((",
      "+++             ",
      "+++             ",
      "+++             ",
      "+++        !    ",
      "+++     !!!!!!! ",
      "+++    !!!!!!!!!",
      "+++    !!!!!!!!!",
      "+++    !!!!!!!!!",
      "+++   !!!!!!!!!!",
      "+++    !!!!!!!!!",
      "+++    !!!!!!!!!",
      "+++    !!!!!!!!!"
    ],
    [
      "    ''''''''''''",
      " $              ",
      " $              ",
      " $$$$$$$$$$$$$$$",
      "  !             ",
      "  !             ",
      "  !             ",
      "**!        !    ",
      "  !     !!!!!!! ",
      "  !    !!     !!",
      "  !    !       !",
      "  !    !       !",
      "  !   !!       !",
      "  !    !       !",
      "  !    !       !",
      "  !    !!     !!"
    ],
    [
      "    ''''''''''''",
      " $              ",
      " $              ",
      " $$$$$$$$$$$$$$$",
      "  !             ",
      "  !             ",
      "  !             ",
      "**!        !    ",
      "  !     !!!!!!! ",
      "  !    !!     !!",
      "  !    !       !",
      "  !    !       !",
      "  !   !!       !",
      "  !    !       !",
      "  !    !       !",
      "  !    !!     !!"
    ],
    [
      "    ''''''''''''",
      " $              ",
      " $              ",
      " $$$$$$$$$$$$$$$",
      "  !             ",
      "  !             ",
      "  !             ",
      "**!        !    ",
      "  !     !!!!!!! ",
      "  !    !!     !!",
      "  !    !       !",
      "  !    !       !",
      "  !   !!       !",
      "  !    !       !",
      "  !    !       !",
      "  !    !!     !!"
    ],
    [
      "    ''''''''''''",
      " $              ",
      " $              ",
      " $$$$$$$$$$$$$$$",
      "  !             ",
      "  !             ",
      "  !             ",
      "**!        !    ",
      "  !     !!!!!!! ",
      "  !    !!     !!",
      "  !    !       !",
      "  !    !       !",
      "  !   !!       !",
      "  !    !       !",
      "  !    !       !",
      "  !    !!     !!"
    ]
  ],
  "palette": {
    "palette": [
      {
        "char": "!",
        "block": "immersiveengineering:sheetmetal_steel"
      },
      {
        "char": "$",
        "block": "minecraft:bricks"
      },
      {
        "char": "%",
        "block": "minecraft:coarse_dirt"
      },
      {
        "char": "&",
        "block": "minecraft:gravel"
      },
      {
        "char": "'",
        "block": "minecraft:scaffolding"
      },
      {
        "char": "(",
        "block": "minecraft:smooth_stone"
      },
      {
        "char": ")",
        "block": "tfmg:asphalt"
      },
      {
        "char": "*",
        "block": "tfmg:cinder_block"
      },
      {
        "char": "+",
        "block": "tfmg:factory_floor"
      }
    ]
  }
}
