{
  "xsize": 16,
  "zsize": 16,
  "slices": [
    [
      ",,,,++++++++++**",
      ",,,,++++++++++**",
      "****************",
      "$$$$$$$$$$$$$$$$",
      "$$$$$$$$$$$$$$$$",
      "$$$$$......$$$$$",
      "$$$$$......$$$$$",
      "$$$$$......$$$$$",
      "$$$$$......$$$$$",
      "'''$$......$$'''",
      "'''$$......$$'''",
      "'''$$......$$'''",
      "'''$$......$$'''",
      "'''$$......$$'''",
      "'''$$......$$'''",
      "'''$$......$$'''"
    ],
    [
      "                ",
      "          &     ",
      "                ",
      "%%%%00000000%%%%",
      "   %        %   ",
      "   % '    ' %   ",
      "   % ')  -' %   ",
      "   % '    ' %   ",
      "   % '    ' %   ",
      "   % '    ' %   ",
      "%1%% '    ' %%1%",
      "   % '    ' %   ",
      "%(%% '    ' %%(%",
      "   % '    ' %   ",
      "   % ' 3  ' %   ",
      "   % '    ' %   "
    ],
    [
      "                ",
      "          &     ",
      "                ",
      "%!%%00000000%%!%",
      "   %        %   ",
      "   % '    ' %   ",
      "   % '    ' %   ",
      "   % '    ' %   ",
      "   % '    ' %   ",
      "   % '    ' %   ",
      "%2%% '    ' %%2%",
      "   % '    ' %   ",
      "% %% '    ' %% %",
      "%(%% '    ' %%(%",
      "   % '    ' %   ",
      "   % '    ' %   "
    ],
    [
      "                ",
      "          &     ",
      "                ",
      "%!%%00000000%%!%",
      "   %        %   ",
      "   % '    ' %   ",
      "   % '    ' %   ",
      "   % '    ' %   ",
      "   % '    ' %   ",
      "   % '    ' %   ",
      "%%%% '    ' %%%%",
      "   % '    ' %   ",
      "% %% '    ' %% %",
      "% %% '    ' %% %",
      "%(%% '    ' %%(%",
      "   % '    ' %   "
    ],
    [
      "                ",
      "          /     ",
      "                ",
      "%!%%00000000%%!%",
      "   %        %   ",
      "   % '    ' %   ",
      "   % '    ' %   ",
      "   % '    ' %   ",
      "   % '    ' %   ",
      "   % '    ' %   ",
      "%%%% '    ' %%%%",
      "   % '    ' %   ",
      "   % '    ' %   ",
      "% %% '    ' %% %",
      "% %% '    ' %% %",
      "%(%% '    ' %%(%"
    ],
    [
      "                ",
      "                ",
      "                ",
      "%%%%00000000%%%%",
      "   %        %   ",
      "   %        %   ",
      "   %        %   ",
      "   %        %   ",
      "   %        %   ",
      "   %        %   ",
      "   %        %   ",
      "   %        %   ",
      "   %        %   ",
      "   %        %   ",
      "% %%        %% %",
      "% %%        %% %"
    ]
  ],
  "palette": {
    "palette": [
      {
        "char": "!",
        "block": "create:framed_glass"
      },
      {
        "char": "$",
        "block": "immersiveengineering:concrete"
      },
      {
        "char": "%",
        "block": "immersiveengineering:concrete_brick"
      },
      {
        "char": "&",
        "block": "immersiveengineering:concrete_pillar"
      },
      {
        "char": "'",
        "block": "immersiveengineering:concrete_tile"
      },
      {
        "char": "(",
        "block": "immersiveengineering:stairs_concrete[facing=south,half=bottom,shape=straight,waterlogged=false]"
      },
      {
        "char": ")",
        "block": "minecraft:barrel"
      },
      {
        "char": "*",
        "block": "minecraft:coarse_dirt"
      },
      {
        "char": "+",
        "block": "minecraft:gravel"
      },
      {
        "char": ",",
        "block": "minecraft:gray_concrete"
      },
      {
        "char": "-",
        "block": "supplementaries:item_shelf"
      },
      {
        "char": ".",
        "block": "tfmg:factory_floor"
      },
      {
        "char": "/",
        "block": "tfmg:gas_lamp"
      },
      {
        "char": "0",
        "block": "tfmg:gray_rebar_concrete"
      },
      {
        "char": "1",
        "block": "the_wasteland_reworked:industrial_door[facing=south,half=lower,hinge=left,open=false,powered=false]"
      },
      {
        "char": "2",
        "block": "the_wasteland_reworked:industrial_door[facing=south,half=upper,hinge=left,open=false,powered=false]"
      },
      {
        "char": "3",
        "block": "zvhouses:spruce_bench"
      }
    ]
  }
}
