{
  "xsize": 16,
  "zsize": 16,
  "slices": [
    [
      "0000000000-----*",
      "0000000000-----*",
      "))))))))))))))))",
      "$$$$$$$$$$$$$$$$",
      "''''''''''''''''",
      "''''''''''''''''",
      "''''''''''''''''",
      "''''''''''''''''",
      "''''''''''''''''",
      "''''''''''''''''",
      "''''''''''''''''",
      "''''''''''''''''",
      "''''''''''''''''",
      "''''''''''''''''",
      "''''''''''''''''",
      "''''''''''''''''"
    ],
    [
      "                ",
      "      &   ,     ",
      "             +  ",
      "2  %%%%%2  22  2",
      "   %   %        ",
      "   %   %        ",
      "   %   %        ",
      "   %   %        ",
      "   %   %  //    ",
      "   %   %        ",
      "   %%5%%        ",
      "   %   %  //    ",
      "   %%(%%        ",
      "   3   %        ",
      "   %   %        ",
      "   %   %        "
    ],
    [
      "                ",
      "      &         ",
      "                ",
      "2  %%!%%2  22  2",
      "   %   %        ",
      "   %   %        ",
      "   %   %        ",
      "   %   %        ",
      "   %   %        ",
      "   %   %        ",
      "   %%6%%        ",
      "   %   %        ",
      "   %% %%        ",
      "   4%(%%        ",
      "   %   %        ",
      "   %   %        "
    ],
    [
      "                ",
      "      &         ",
      "                ",
      "2  %%!%%2 .22  2",
      "   %   %        ",
      "   %   %        ",
      "   %   %        ",
      "   %   %        ",
      "   %   %        ",
      "   %   %        ",
      "   %%%%%        ",
      "   %   %        ",
      "   %% %%        ",
      "   %% %%        ",
      "   %%(%%        ",
      "   %   %        "
    ],
    [
      "                ",
      "      1         ",
      "                ",
      "222%%!%%22222222",
      "   %   %        ",
      "   %   %        ",
      "   %   %        ",
      "   %   %        ",
      "   %   %        ",
      "   %   %        ",
      "   %%%%%        ",
      "   %   %        ",
      "   %   %        ",
      "   %% %%        ",
      "   %% %%        ",
      "   %%(%%        "
    ],
    [
      "                ",
      "                ",
      "                ",
      "222%%%%%22222222",
      "   %   %        ",
      "   %   %        ",
      "   %   %        ",
      "   %   %        ",
      "   %   %        ",
      "   %   %        ",
      "   %   %        ",
      "   %   %        ",
      "   %   %        ",
      "   %   %        ",
      "   %% %%        ",
      "   %% %%        "
    ]
  ],
  "palette": {
    "palette": [
      {
        "char": "!",
        "block": "create:framed_glass"
      },
      {
        "char": "$",
        "block": "immersiveengineering:concrete"
      },
      {
        "char": "%",
        "block": "immersiveengineering:concrete_brick"
      },
      {
        "char": "&",
        "block": "immersiveengineering:concrete_pillar"
      },
      {
        "char": "'",
        "block": "immersiveengineering:concrete_tile"
      },
      {
        "char": "(",
        "block": "immersiveengineering:stairs_concrete[facing=south,half=bottom,shape=straight,waterlogged=false]"
      },
      {
        "char": ")",
        "block": "minecraft:coarse_dirt"
      },
      {
        "char": "*",
        "block": "minecraft:cracked_stone_bricks"
      },
      {
        "char": "+",
        "block": "minecraft:glass_pane"
      },
      {
        "char": ",",
        "block": "minecraft:gravel"
      },
      {
        "char": "-",
        "block": "minecraft:gray_concrete"
      },
      {
        "char": ".",
        "block": "quark:dirty_glass_pane"
      },
      {
        "char": "/",
        "block": "supplementaries:item_shelf"
      },
      {
        "char": "0",
        "block": "tfmg:asphalt"
      },
      {
        "char": "1",
        "block": "tfmg:gas_lamp"
      },
      {
        "char": "2",
        "block": "tfmg:gray_rebar_concrete"
      },
      {
        "char": "3",
        "block": "the_wasteland_reworked:industrial_door[facing=east,half=lower,hinge=left,open=false,powered=false]"
      },
      {
        "char": "4",
        "block": "the_wasteland_reworked:industrial_door[facing=east,half=upper,hinge=left,open=false,powered=false]"
      },
      {
        "char": "5",
        "block": "the_wasteland_reworked:industrial_door[facing=south,half=lower,hinge=left,open=false,powered=false]"
      },
      {
        "char": "6",
        "block": "the_wasteland_reworked:industrial_door[facing=south,half=upper,hinge=left,open=false,powered=false]"
      }
    ]
  }
}
