{
  "xsize": 16,
  "zsize": 16,
  "slices": [
    [
      "***********/////",
      "***********/////",
      "))))))))))))))))",
      "$$$$$$$$$$$$$$$$",
      "''''''''''''''''",
      "''''''''''''''''",
      "''''''''''''''''",
      "''''''''''''''''",
      "''''''''''''''''",
      "''''''''''''''''",
      "''''''''''''''''",
      "''''''''''''''''",
      "''''''''''''''''",
      "''''''''''''''''",
      "''''''''''''''''",
      "''''''''''''''''"
    ],
    [
      "                ",
      "  ,       &   , ",
      "             +  ",
      "1  111%%%%%11  1",
      "      %   %     ",
      "      %   %     ",
      "      %   %     ",
      "      %   %     ",
      "  ..  %   %     ",
      "      %   %     ",
      "      %%4%%     ",
      "  ..  %   %     ",
      "      %%(%%     ",
      "      2   %     ",
      "      %   %     ",
      "      %   %     "
    ],
    [
      "                ",
      "          &     ",
      "                ",
      "1  111%%!%%11  1",
      "      %   %     ",
      "      %   %     ",
      "      %   %     ",
      "      %   %     ",
      "      %   %     ",
      "      %   %     ",
      "      %%5%%     ",
      "      %   %     ",
      "      %% %%     ",
      "      3%(%%     ",
      "      %   %     ",
      "      %   %     "
    ],
    [
      "                ",
      "          &     ",
      "                ",
      "1 -111%%!%%11 -1",
      "      %   %     ",
      "      %   %     ",
      "      %   %     ",
      "      %   %     ",
      "      %   %     ",
      "      %   %     ",
      "      %%%%%     ",
      "      %   %     ",
      "      %% %%     ",
      "      %% %%     ",
      "      %%(%%     ",
      "      %   %     "
    ],
    [
      "                ",
      "          0     ",
      "                ",
      "111111%%!%%11111",
      "      %   %     ",
      "      %   %     ",
      "      %   %     ",
      "      %   %     ",
      "      %   %     ",
      "      %   %     ",
      "      %%%%%     ",
      "      %   %     ",
      "      %   %     ",
      "      %% %%     ",
      "      %% %%     ",
      "      %%(%%     "
    ],
    [
      "                ",
      "                ",
      "                ",
      "111111%%%%%11111",
      "      %   %     ",
      "      %   %     ",
      "      %   %     ",
      "      %   %     ",
      "      %   %     ",
      "      %   %     ",
      "      %   %     ",
      "      %   %     ",
      "      %   %     ",
      "      %   %     ",
      "      %% %%     ",
      "      %% %%     "
    ]
  ],
  "palette": {
    "palette": [
      {
        "char": "!",
        "block": "create:framed_glass"
      },
      {
        "char": "$",
        "block": "immersiveengineering:concrete"
      },
      {
        "char": "%",
        "block": "immersiveengineering:concrete_brick"
      },
      {
        "char": "&",
        "block": "immersiveengineering:concrete_pillar"
      },
      {
        "char": "'",
        "block": "immersiveengineering:concrete_tile"
      },
      {
        "char": "(",
        "block": "immersiveengineering:stairs_concrete[facing=south,half=bottom,shape=straight,waterlogged=false]"
      },
      {
        "char": ")",
        "block": "minecraft:coarse_dirt"
      },
      {
        "char": "*",
        "block": "minecraft:cracked_stone_bricks"
      },
      {
        "char": "+",
        "block": "minecraft:glass_pane"
      },
      {
        "char": ",",
        "block": "minecraft:gravel"
      },
      {
        "char": "-",
        "block": "quark:dirty_glass_pane"
      },
      {
        "char": ".",
        "block": "supplementaries:item_shelf"
      },
      {
        "char": "/",
        "block": "tfmg:asphalt"
      },
      {
        "char": "0",
        "block": "tfmg:gas_lamp"
      },
      {
        "char": "1",
        "block": "tfmg:gray_rebar_concrete"
      },
      {
        "char": "2",
        "block": "the_wasteland_reworked:industrial_door[facing=east,half=lower,hinge=left,open=false,powered=false]"
      },
      {
        "char": "3",
        "block": "the_wasteland_reworked:industrial_door[facing=east,half=upper,hinge=left,open=false,powered=false]"
      },
      {
        "char": "4",
        "block": "the_wasteland_reworked:industrial_door[facing=south,half=lower,hinge=left,open=false,powered=false]"
      },
      {
        "char": "5",
        "block": "the_wasteland_reworked:industrial_door[facing=south,half=upper,hinge=left,open=false,powered=false]"
      }
    ]
  }
}
