{
  "xsize": 16,
  "zsize": 16,
  "slices": [
    [
      ")))))***********",
      ")))))***********",
      "))((((((((((((((",
      "))(!!!!!!!!!!!!!",
      "))(!!!!!!!!!!!!!",
      "))(!!/////////!!",
      "))(!!/////////!!",
      "))(!!/////////!!",
      "))(!!/////////!!",
      "))(!!/////////!!",
      "--(!!/////////!!",
      "--(!!/////////!!",
      "--(!!/////////!!",
      "--(!!/////////!!",
      "--(!!/////////!!",
      "(((!!/////////!!"
    ],
    [
      "     %%         ",
      "  %           % ",
      "                ",
      "   ,1.111111111$",
      "   1           $",
      "   1 &       & $",
      "   1 &'     +& $",
      "   1 &       & $",
      "   1 &       & $",
      "   1 &       & $",
      "   1 &       & $",
      "   1 &       & $",
      "   1 &       & $",
      "   1 &       & $",
      "   1 & 2     & $",
      "   1 &       & $"
    ],
    [
      "     %%         ",
      "  %           % ",
      "                ",
      "   11.111111111$",
      "   1           $",
      "   1 &       & $",
      "   1 &       & $",
      "   1 &       & $",
      "   1 &       & $",
      "   1 &       & $",
      "   1 &       & $",
      "   1 &       & $",
      "   1 &       & $",
      "   1 &       & $",
      "   1 &       & $",
      "   1 &       & $"
    ],
    [
      "     ..         ",
      "  %  ..       % ",
      "     ..         ",
      "   11..11111111$",
      "   1           $",
      "   1 &       & $",
      "   1 &       & $",
      "   1 &       & $",
      "   1 &       & $",
      "   1 &       & $",
      "   1 &       & $",
      "   1 &       & $",
      "   1 &       & $",
      "   1 &       & $",
      "   1 &       & $",
      "   1 &       & $"
    ],
    [
      "                ",
      "  0           0 ",
      "                ",
      "   111111111111$",
      "   1           $",
      "   1 &       & $",
      "   1 &       & $",
      "   1 &       & $",
      "   1 &       & $",
      "   1 &       & $",
      "   1 &       & $",
      "   1 &       & $",
      "   1 &       & $",
      "   1 &       & $",
      "   1 &       & $",
      "   1 &       & $"
    ],
    [
      "                ",
      "                ",
      "                ",
      "   111111111111$",
      "   1           $",
      "   1           $",
      "   1           $",
      "   1           $",
      "   1           $",
      "   1           $",
      "   1           $",
      "   1           $",
      "   1           $",
      "   1           $",
      "   1           $",
      "   1           $"
    ]
  ],
  "palette": {
    "palette": [
      {
        "char": "!",
        "block": "immersiveengineering:concrete"
      },
      {
        "char": "$",
        "block": "immersiveengineering:concrete_brick"
      },
      {
        "char": "%",
        "block": "immersiveengineering:concrete_pillar"
      },
      {
        "char": "&",
        "block": "immersiveengineering:concrete_tile"
      },
      {
        "char": "'",
        "block": "minecraft:barrel"
      },
      {
        "char": "(",
        "block": "minecraft:coarse_dirt"
      },
      {
        "char": ")",
        "block": "minecraft:gravel"
      },
      {
        "char": "*",
        "block": "minecraft:gray_concrete"
      },
      {
        "char": "+",
        "block": "supplementaries:item_shelf"
      },
      {
        "char": ",",
        "block": "supplementaries:notice_board"
      },
      {
        "char": "-",
        "block": "tfmg:asphalt"
      },
      {
        "char": ".",
        "block": "tfmg:concrete_encased_industrial_pipe"
      },
      {
        "char": "/",
        "block": "tfmg:factory_floor"
      },
      {
        "char": "0",
        "block": "tfmg:gas_lamp"
      },
      {
        "char": "1",
        "block": "tfmg:gray_rebar_concrete"
      },
      {
        "char": "2",
        "block": "zvhouses:spruce_bench"
      }
    ]
  }
}
