{
  "xsize": 16,
  "zsize": 16,
  "slices": [
    [
      "   )$$$$$$$$$$$$",
      "   )$(((((((((((",
      "   )$(((((((((((",
      "   )$(((((((((((",
      "   )$$$$$$$$$$$$",
      "   )$$$$$$$$$$$$",
      "   )$$$$$$$$$$$$",
      "   )$$$$$$$$$$$$",
      "   )$$$$$$$$$$$$",
      "   )$$$$$$$$$$$$",
      "   )$$$$$$$$$$$$",
      "   )$$$$$$$$$$$$",
      "   )$$$$$$$$$$$$",
      "   )$$$$$$$$$$$$",
      "   )$$$$$$$$$$$$",
      "   )$$$$$$$$$$$$"
    ],
    [
      "    %%%%*%%%%%%%",
      "    %           ",
      "    % %%%       ",
      "    % %%%       ",
      "    %%%%%%%%%%%%",
      "    %%%%%%%%%%%%",
      "    %%%%%%%%%%%%",
      "    %%%%%%%%%%%%",
      "    %%%%%%%%%%%%",
      "    %%%%%%%%%%%%",
      "    %%%%%%%%%%%%",
      "    %%%%%%%%%%%%",
      "    %%%%%%%%%%%%",
      "    %%%%%%%%%%%%",
      "    %%%%%%%%%%%%",
      "    %%%%%%%%%%%%"
    ],
    [
      "    %%%%+%%%%%%%",
      "    %   %       ",
      "    %'''&'''''''",
      "    %   %       ",
      "    %%%%%%%%%%%%",
      "    %%%%%%%%%%%%",
      "    %%%%%%%%%%%%",
      "    %%%%%%%%%%%%",
      "    %%%%%%%%%%%%",
      "    %%%%%%%%%%%%",
      "    %%%%%%%%%%%%",
      "    %%%%%%%%%%%%",
      "    %%%%%%%%%%%%",
      "    %%%%%%%%%%%%",
      "    %%%%%%%%%%%%",
      "    %%%%%%%%%%%%"
    ],
    [
      "    %%%%%%%%%%%%",
      "    %   %%      ",
      "    %    &      ",
      "    %   %%      ",
      "    %%%%%%%%%%%%",
      "    %%%%%%%%%%%%",
      "    %%%%%%%%%%%%",
      "    %%%%%%%%%%%%",
      "    %%%%%%%%%%%%",
      "    %%%%%%%%%%%%",
      "    %%%%%%%%%%%%",
      "    %%%%%%%%%%%%",
      "    %%%%%%%%%%%%",
      "    %%%%%%%%%%%%",
      "    %%%%%%%%%%%%",
      "    %%%%%%%%%%%%"
    ],
    [
      "    %%%%%%%%%%%%",
      "    %%%%%%%%%%%%",
      "    %%%%  &%%%%%",
      "    %%%%%!%%%%%%",
      "    %%%%%%%%%%%%",
      "    %%%%%%%%%%%%",
      "    %%%%%%%%%%%%",
      "    %%%%%%%%%%%%",
      "    %%%%%%%%%%%%",
      "    %%%%%%%%%%%%",
      "    %%%%%%%%%%%%",
      "    %%%%%%%%%%%%",
      "    %%%%%%%%%%%%",
      "    %%%%%%%%%%%%",
      "    %%%%%%%%%%%%",
      "    %%%%%%%%%%%%"
    ],
    [
      "    %%%%%%%%%%%%",
      "    %%%%%%%%%%%%",
      "    %%%%%  &%%%%",
      "    %%%%%%%%%%%%",
      "    %%%%%%%%%%%%",
      "    %%%%%%%%%%%%",
      "    %%%%%%%%%%%%",
      "    %%%%%%%%%%%%",
      "    %%%%%%%%%%%%",
      "    %%%%%%%%%%%%",
      "    %%%%%%%%%%%%",
      "    %%%%%%%%%%%%",
      "    %%%%%%%%%%%%",
      "    %%%%%%%%%%%%",
      "    %%%%%%%%%%%%",
      "    %%%%%%%%%%%%"
    ]
  ],
  "palette": {
    "palette": [
      {
        "char": "!",
        "block": "immersiveengineering:cagelamp"
      },
      {
        "char": "$",
        "block": "immersiveengineering:concrete"
      },
      {
        "char": "%",
        "block": "immersiveengineering:concrete_brick"
      },
      {
        "char": "&",
        "block": "immersiveengineering:stairs_concrete[facing=east,half=bottom,shape=straight,waterlogged=false]"
      },
      {
        "char": "'",
        "block": "tfmg:concrete_encased_industrial_pipe"
      },
      {
        "char": "(",
        "block": "tfmg:factory_floor"
      },
      {
        "char": ")",
        "block": "tfmg:gray_rebar_concrete"
      },
      {
        "char": "*",
        "block": "the_wasteland_reworked:industrial_door[facing=south,half=lower,hinge=left,open=false,powered=false]"
      },
      {
        "char": "+",
        "block": "the_wasteland_reworked:industrial_door[facing=south,half=upper,hinge=left,open=false,powered=false]"
      }
    ]
  }
}
