{
  "xsize": 16,
  "zsize": 16,
  "slices": [
    [
      "$$$%%%%%!!!!!   ",
      "$$$%%%%%!!!!!   ",
      "$$$%%%%%!!!!!   ",
      "$$$%%%%%!!!!!   ",
      "!!!$$$$$!!!!!   ",
      "!!!$$$$$!!!!!   ",
      "!!!$$$$$!!!!!   ",
      "!!!$$$$$!!!!!   ",
      "!!!$$$$$!!!!!   ",
      "%%%$$$$$%%%%%   ",
      "%%%$$$$$%%%%%   ",
      "%%%$$$$$%%%%%   ",
      "%%%$$$$$%%%%%   ",
      "%%%$$$$$%%%%%   ",
      "%%%$$$$$$$$$$   ",
      "%%%$$$$$$$$$$   "
    ],
    [
      "     &          ",
      "     &          ",
      "     &          ",
      "     &          ",
      "     &          ",
      "     &          ",
      "     &          ",
      "     &          ",
      "     &          ",
      "     &          ",
      "     &          ",
      "     &          ",
      "     &          ",
      "     &          ",
      "     &          ",
      "     &          "
    ],
    [
      "                ",
      "                ",
      "                ",
      "                ",
      "                ",
      "                ",
      "                ",
      "                ",
      "                ",
      "                ",
      "                ",
      "                ",
      "                ",
      "                ",
      "                ",
      "                "
    ],
    [
      "                ",
      "                ",
      "                ",
      "                ",
      "                ",
      "                ",
      "                ",
      "                ",
      "                ",
      "                ",
      "                ",
      "                ",
      "                ",
      "                ",
      "                ",
      "                "
    ],
    [
      "                ",
      "                ",
      "                ",
      "                ",
      "                ",
      "                ",
      "                ",
      "                ",
      "                ",
      "                ",
      "                ",
      "                ",
      "                ",
      "                ",
      "                ",
      "                "
    ],
    [
      "                ",
      "                ",
      "                ",
      "                ",
      "                ",
      "                ",
      "                ",
      "                ",
      "                ",
      "                ",
      "                ",
      "                ",
      "                ",
      "                ",
      "                ",
      "                "
    ]
  ],
  "palette": {
    "palette": [
      {
        "char": "!",
        "block": "minecraft:coarse_dirt"
      },
      {
        "char": "$",
        "block": "minecraft:grass_block"
      },
      {
        "char": "%",
        "block": "minecraft:mossy_cobblestone"
      },
      {
        "char": "&",
        "block": "minecraft:oxidized_copper_grate"
      }
    ]
  }
}
