{
  "xsize": 16,
  "zsize": 16,
  "slices": [
    [
      ",,+++++22222----",
      ",,+++++22222----",
      "++++++++++++++++",
      "$$$$$$$$$$$$$$$$",
      "$'''$$$$$$$$$$$$",
      "$'''$$$$$$$$$333",
      "$'''$$$$$$$$$333",
      "$'''$$$$$$$$$333",
      "$'''$$$$$$$$$333",
      "$'''$$$$'''$$333",
      "$'''$$$$'''$$333",
      "$'''$$$$'''$$333",
      "$'''$$$$'''$$333",
      "$'''$$$$'''$$333",
      "$'''$$$$'''$$333",
      "$'''$$$$'''$$333"
    ],
    [
      "55.55           ",
      "5 & 5         & ",
      "5   5           ",
      "5505555%%%%%5555",
      "'   '  %   %    ",
      "'   '  %   % '  ",
      "'   '  %   % '* ",
      "'   '  %   % '  ",
      "'   '  %   % '  ",
      "'   '  %   % '  ",
      "'   '  %%6%% '  ",
      "'   '  %   % '  ",
      "'   '  %%)%% '  ",
      "'   '  %   % '  ",
      "'   '  %   % ' 8",
      "'   '  %   % '  "
    ],
    [
      "55/55           ",
      "5 & 5         & ",
      "5   5           ",
      "5515555%%!%%5555",
      "'   '  %   %    ",
      "'   '  %   % '  ",
      "'   '  %   % '  ",
      "'   '  %   % '  ",
      "'   '  %   % '  ",
      "'   '  %   % '  ",
      "'   '  %%7%% '  ",
      "'   '  %   % '  ",
      "'   '  %% %% '  ",
      "'   '  %%)%% '  ",
      "'   '  %   % '  ",
      "'   '  %   % '  "
    ],
    [
      "55555           ",
      "5 & 5         & ",
      "5   5           ",
      "5555555%%!%%5555",
      "'   '  %   %    ",
      "'   '  %   % '  ",
      "'   '  %   % '  ",
      "'   '  %   % '  ",
      "'   '  %   % '  ",
      "'   '  %   % '  ",
      "'   '  %%%%% '  ",
      "'   '  %   % '  ",
      "'   '  %% %% '  ",
      "'   '  %% %% '  ",
      "'   '  %%)%% '  ",
      "'   '  %   % '  "
    ],
    [
      "55555           ",
      "55455         4 ",
      "55555           ",
      "5555555%%!%%5555",
      "'   '  %   %    ",
      "'   '  %   % '  ",
      "'   '  %   % '  ",
      "'   '  %   % '  ",
      "'   '  %   % '  ",
      "'   '  %   % '  ",
      "'   '  %%%%% '  ",
      "'   '  %   % '  ",
      "'   '  %   % '  ",
      "'   '  %% %% '  ",
      "'   '  %% %% '  ",
      "'   '  %%)%% '  "
    ],
    [
      "((((((          ",
      "((((((          ",
      "((((((          ",
      "5555555%%%%%5555",
      "       %   %    ",
      "       %   %    ",
      "       %   %    ",
      "       %   %    ",
      "       %   %    ",
      "       %   %    ",
      "       %   %    ",
      "       %   %    ",
      "       %   %    ",
      "       %   %    ",
      "       %% %%    ",
      "       %% %%    "
    ]
  ],
  "palette": {
    "palette": [
      {
        "char": "!",
        "block": "create:framed_glass"
      },
      {
        "char": "$",
        "block": "immersiveengineering:concrete"
      },
      {
        "char": "%",
        "block": "immersiveengineering:concrete_brick"
      },
      {
        "char": "&",
        "block": "immersiveengineering:concrete_pillar"
      },
      {
        "char": "'",
        "block": "immersiveengineering:concrete_tile"
      },
      {
        "char": "(",
        "block": "immersiveengineering:slab_concrete"
      },
      {
        "char": ")",
        "block": "immersiveengineering:stairs_concrete[facing=south,half=bottom,shape=straight,waterlogged=false]"
      },
      {
        "char": "*",
        "block": "minecraft:barrel"
      },
      {
        "char": "+",
        "block": "minecraft:coarse_dirt"
      },
      {
        "char": ",",
        "block": "minecraft:gravel"
      },
      {
        "char": "-",
        "block": "minecraft:gray_concrete"
      },
      {
        "char": ".",
        "block": "minecraft:iron_door[facing=north,half=lower,hinge=left,open=false,powered=false]"
      },
      {
        "char": "/",
        "block": "minecraft:iron_door[facing=north,half=upper,hinge=left,open=false,powered=false]"
      },
      {
        "char": "0",
        "block": "minecraft:oak_door[facing=north,half=lower,hinge=left,open=false,powered=false]"
      },
      {
        "char": "1",
        "block": "minecraft:oak_door[facing=north,half=upper,hinge=left,open=false,powered=false]"
      },
      {
        "char": "2",
        "block": "tfmg:asphalt"
      },
      {
        "char": "3",
        "block": "tfmg:factory_floor"
      },
      {
        "char": "4",
        "block": "tfmg:gas_lamp"
      },
      {
        "char": "5",
        "block": "tfmg:gray_rebar_concrete"
      },
      {
        "char": "6",
        "block": "the_wasteland_reworked:industrial_door[facing=south,half=lower,hinge=left,open=false,powered=false]"
      },
      {
        "char": "7",
        "block": "the_wasteland_reworked:industrial_door[facing=south,half=upper,hinge=left,open=false,powered=false]"
      },
      {
        "char": "8",
        "block": "zvhouses:spruce_bench"
      }
    ]
  }
}
