{
  "xsize": 16,
  "zsize": 16,
  "slices": [
    [
      "&&&'''&&&&&&&&&&",
      "&&&'''&&&&&&&&&&",
      "&&%%%%%%%%%%%%%&",
      "''%)))))))))))%'",
      "''%)))))))))))%'",
      "''%)))))))))))%'",
      "++%)))))))))))%+",
      "++%)))))))))))%+",
      "++%)))))))))))%+",
      "&&%)))))))))))%+",
      "&&%)))))))))))%+",
      "&&%)))))))))))%+",
      "''%)))))))))))%&",
      "''%)))))))))))%&",
      "''%%%%%%%%%%%%%&",
      "+++'''&&&&&&&&&'"
    ],
    [
      "                ",
      " $((((((((((((($",
      " (             (",
      " (             (",
      " (  !!!!-!!!!  (",
      " (  !       !  (",
      " (  !       !  (",
      " (  !       !  (",
      " (  !       !  (",
      " (  !       !  (",
      " (  !       !  (",
      " (  !       !  (",
      " (  !!!!!!!!!  (",
      " (             (",
      " (             (",
      " $((((((((((((($"
    ],
    [
      "                ",
      " $             $",
      "                ",
      "                ",
      "    !!!!.!!!!   ",
      "    !       !   ",
      "    !       !   ",
      "    !       !   ",
      "    !       !   ",
      "    !       !   ",
      "    !       !   ",
      "    !       !   ",
      "    !!!!!!!!!   ",
      "                ",
      "                ",
      " $             $"
    ],
    [
      "                ",
      "                ",
      "                ",
      "                ",
      "    !!!!!!!!!   ",
      "    !       !   ",
      "    !       !   ",
      "    !       !   ",
      "    !       ,   ",
      "    !       !   ",
      "    !       !   ",
      "    !       !   ",
      "    !!!(((!!!   ",
      "                ",
      "                ",
      "                "
    ],
    [
      "                ",
      "                ",
      "                ",
      "                ",
      "    !!!!!!!!!   ",
      "    !!!!!!!!!   ",
      "    !!!!!!!!!   ",
      "    !!!!!!!!!   ",
      "    !!!!!!!!!   ",
      "    !!!!!!!!!   ",
      "    !!!!!!!!!   ",
      "    !!!!!!!!!   ",
      "    !!!!!!!!!   ",
      "                ",
      "                ",
      "                "
    ],
    [
      "                ",
      "                ",
      "                ",
      "                ",
      "    *********   ",
      "    *********   ",
      "    *********   ",
      "    *********   ",
      "    *********   ",
      "    *********   ",
      "    *********   ",
      "    *********   ",
      "    *********   ",
      "                ",
      "                ",
      "                "
    ]
  ],
  "palette": {
    "palette": [
      {
        "char": "!",
        "block": "immersiveengineering:concrete_sprayed"
      },
      {
        "char": "$",
        "block": "immersiveengineering:steel_post"
      },
      {
        "char": "%",
        "block": "minecraft:coarse_dirt"
      },
      {
        "char": "&",
        "block": "minecraft:cracked_stone_bricks"
      },
      {
        "char": "'",
        "block": "minecraft:gray_concrete"
      },
      {
        "char": "(",
        "block": "minecraft:oxidized_copper_grate"
      },
      {
        "char": ")",
        "block": "minecraft:polished_andesite"
      },
      {
        "char": "*",
        "block": "quark:gray_shingles"
      },
      {
        "char": "+",
        "block": "tfmg:asphalt"
      },
      {
        "char": ",",
        "block": "tfmg:yellow_caution_block"
      },
      {
        "char": "-",
        "block": "the_wasteland_reworked:industrial_door[facing=north,half=lower,hinge=left,open=false,powered=false]"
      },
      {
        "char": ".",
        "block": "the_wasteland_reworked:industrial_door[facing=north,half=upper,hinge=left,open=false,powered=false]"
      }
    ]
  }
}
