{
  "xsize": 16,
  "zsize": 16,
  "slices": [
    [
      "****+++++&&&&&''",
      "****+++++&&&&&''",
      "****+++++&&&&&''",
      "****+++++&&&&&''",
      "****+++++&&&&&''",
      "&&&&+++++(((((**",
      "&&&&+++++(((((**",
      "&&&&+++++(((((**",
      "&&&&&&&&&(((((**",
      "&&&&&&&&&(((((**",
      "((((''''''''''**",
      "((((''''''''''**",
      "((((''''''''''**",
      "((((''''''''''**",
      "&&&&&&&&&&&&&&&*",
      ",,,,,,,,,,,,,,&*"
    ],
    [
      "                ",
      "                ",
      "                ",
      "                ",
      "                ",
      "                ",
      "                ",
      ")))%     %))))))",
      "                ",
      "                ",
      "              $$",
      "              $ ",
      "              $ ",
      "              $ ",
      "              $ ",
      "              $$"
    ],
    [
      "                ",
      "                ",
      "                ",
      "                ",
      "                ",
      "                ",
      "                ",
      "   %     %      ",
      "                ",
      "                ",
      "              $$",
      "              $ ",
      "              $ ",
      "              $ ",
      "              $ ",
      "              $$"
    ],
    [
      "                ",
      "                ",
      "                ",
      "                ",
      "                ",
      "                ",
      "                ",
      "   %     %      ",
      "                ",
      "                ",
      "              $$",
      "              $ ",
      "              $ ",
      "              $ ",
      "              $ ",
      "              $$"
    ],
    [
      "                ",
      "                ",
      "                ",
      "                ",
      "                ",
      "                ",
      "                ",
      "   -            ",
      "                ",
      "                ",
      "              $$",
      "              $$",
      "              $$",
      "              $$",
      "              $$",
      "              $$"
    ],
    [
      "                ",
      "                ",
      "                ",
      "                ",
      "                ",
      "                ",
      "                ",
      "                ",
      "                ",
      "                ",
      "              !!",
      "              !!",
      "              !!",
      "              !!",
      "              !!",
      "              !!"
    ]
  ],
  "palette": {
    "palette": [
      {
        "char": "!",
        "block": "immersiveengineering:concrete_sheet"
      },
      {
        "char": "$",
        "block": "immersiveengineering:concrete_tile"
      },
      {
        "char": "%",
        "block": "immersiveengineering:steel_post"
      },
      {
        "char": "&",
        "block": "minecraft:coarse_dirt"
      },
      {
        "char": "'",
        "block": "minecraft:grass_block"
      },
      {
        "char": "(",
        "block": "minecraft:mossy_cobblestone"
      },
      {
        "char": ")",
        "block": "minecraft:oxidized_copper_grate"
      },
      {
        "char": "*",
        "block": "minecraft:podzol"
      },
      {
        "char": "+",
        "block": "tfmg:asphalt"
      },
      {
        "char": ",",
        "block": "tfmg:gray_rebar_concrete"
      },
      {
        "char": "-",
        "block": "tfmg:yellow_caution_block"
      }
    ]
  }
}
