{
  "xsize": 16,
  "zsize": 16,
  "slices": [
    [
      "))))))))))))))$%",
      "))))))))))))))$%",
      "))))))))))))))$%",
      "))))))))))))))$%",
      "))))))))))))))$$",
      "))))))))))))))$$",
      "))))))))))))))$$",
      "))))))))))))))$$",
      "))))))))))))))$$",
      "))))))))))))))$'",
      "))))))))))))))$'",
      "))))))))))))))$'",
      "))))))))))))))$'",
      "))))))))))))))$'",
      "$$$$$$$$$$$$$$$'",
      "%%%%((((((((((''"
    ],
    [
      "      +++++++++ ",
      "      +         ",
      "      +         ",
      "      +         ",
      "      +         ",
      "      +         ",
      "      +         ",
      "                ",
      "                ",
      "                ",
      "        !       ",
      "                ",
      "                ",
      "                ",
      "                ",
      "                "
    ],
    [
      "                ",
      "                ",
      "                ",
      "                ",
      "    *   *       ",
      "                ",
      "      +         ",
      "                ",
      "    *   *       ",
      "                ",
      "                ",
      "                ",
      "                ",
      "                ",
      "                ",
      "                "
    ],
    [
      "                ",
      "                ",
      "                ",
      "                ",
      "    *   *       ",
      "    &           ",
      "    * +         ",
      "                ",
      "    *   *       ",
      "                ",
      "                ",
      "                ",
      "                ",
      "                ",
      "                ",
      "                "
    ],
    [
      "                ",
      "                ",
      "                ",
      "                ",
      "    *   *       ",
      "    &           ",
      "    * +         ",
      "                ",
      "    *   *       ",
      "                ",
      "                ",
      "                ",
      "                ",
      "                ",
      "                ",
      "                "
    ],
    [
      "                ",
      "                ",
      "                ",
      "                ",
      "    *****       ",
      "    &   *       ",
      "    * + *       ",
      "    *   *       ",
      "    *****       ",
      "                ",
      "                ",
      "                ",
      "                ",
      "                ",
      "                ",
      "                "
    ]
  ],
  "palette": {
    "palette": [
      {
        "char": "!",
        "block": "immersiveengineering:concrete_brick_cracked"
      },
      {
        "char": "$",
        "block": "minecraft:coarse_dirt"
      },
      {
        "char": "%",
        "block": "minecraft:grass_block"
      },
      {
        "char": "&",
        "block": "minecraft:ladder[facing=north,waterlogged=false]"
      },
      {
        "char": "'",
        "block": "minecraft:mossy_cobblestone"
      },
      {
        "char": "(",
        "block": "minecraft:podzol"
      },
      {
        "char": ")",
        "block": "tfmg:gray_rebar_concrete"
      },
      {
        "char": "*",
        "block": "tfmg:steel_block"
      },
      {
        "char": "+",
        "block": "the_wasteland_reworked:pipe_block"
      }
    ]
  }
}
