{
  "xsize": 16,
  "zsize": 16,
  "slices": [
    [
      "                ",
      "                ",
      "                ",
      "                ",
      "    !!!!!!!!!!!!",
      "    !+++++++++!!",
      "    !+++++++++!!",
      "    !+++++++++!!",
      "    !+++++++++!!",
      "    !+++++++++!!",
      "    !+++++++++!!",
      "    !+++++++++!!",
      "    !+++++++++!!",
      "    !+++++++++!!",
      "    !+++++++++!!",
      "    !+++++++++!!"
    ],
    [
      "                ",
      "                ",
      "                ",
      "               $",
      "    $$$$$$$$$$$$",
      "    $%      ,% $",
      "    $%       % $",
      "    $%'    -.% $",
      "    $%(      % $",
      "    $%       % $",
      "    $%       % $",
      "    $%       % $",
      "    $%       % $",
      "    $%       % $",
      "    $%&     *% $",
      "    $%       % $"
    ],
    [
      "                ",
      "                ",
      "                ",
      "               $",
      "    $))!$))!$))$",
      "    )%      ,% $",
      "    )%       % $",
      "    !%       % $",
      "    $%       % $",
      "    )%       % $",
      "    )%       % $",
      "    !%       % $",
      "    $%       % $",
      "    )%       % $",
      "    )%       % $",
      "    !%       % $"
    ],
    [
      "                ",
      "                ",
      "                ",
      "               $",
      "    $))!$))!$))$",
      "    )%      ,% $",
      "    )%       % $",
      "    !%       % $",
      "    $%       % $",
      "    )%       % $",
      "    )%       % $",
      "    !%       % $",
      "    $%       % $",
      "    )%       % $",
      "    )%       % $",
      "    !%       % $"
    ],
    [
      "                ",
      "                ",
      "                ",
      "               $",
      "    $!!!$!!!$!!$",
      "    !%       % $",
      "    !%       % $",
      "    !%       % $",
      "    $%       % $",
      "    !%       % $",
      "    !%       % $",
      "    !%       % $",
      "    $%       % $",
      "    !%       % $",
      "    !%       % $",
      "    !%       % $"
    ],
    [
      "                ",
      "                ",
      "                ",
      "               $",
      "    $!!!$!!!$!!$",
      "    !          $",
      "    !          $",
      "    !          $",
      "    $          $",
      "    !          $",
      "    !          $",
      "    !          $",
      "    $          $",
      "    !          $",
      "    !          $",
      "    !          $"
    ]
  ],
  "palette": {
    "palette": [
      {
        "char": "!",
        "block": "immersiveengineering:concrete"
      },
      {
        "char": "$",
        "block": "immersiveengineering:concrete_brick"
      },
      {
        "char": "%",
        "block": "immersiveengineering:concrete_tile"
      },
      {
        "char": "&",
        "block": "minecraft:barrel"
      },
      {
        "char": "'",
        "block": "minecraft:gray_bed[facing=south,occupied=false,part=foot]"
      },
      {
        "char": "(",
        "block": "minecraft:gray_bed[facing=south,occupied=false,part=head]"
      },
      {
        "char": ")",
        "block": "quark:gray_framed_glass"
      },
      {
        "char": "*",
        "block": "supplementaries:item_shelf"
      },
      {
        "char": "+",
        "block": "tfmg:factory_floor"
      },
      {
        "char": ",",
        "block": "the_wasteland_reworked:pipe_block"
      },
      {
        "char": "-",
        "block": "zvhouses:spruce_chair"
      },
      {
        "char": ".",
        "block": "zvhouses:spruce_table"
      }
    ]
  }
}
