{
  "xsize": 16,
  "zsize": 16,
  "slices": [
    [
      "333333333333333)",
      "333333333333333)",
      "33((((((((((((((",
      "33(!!!!!!%%%!!!!",
      "33(!!%%%%%%%%%%%",
      ",,(!!%%%%%%%%%%%",
      ",,(!!%%%%%%%%%%%",
      ",,(!!%%%%%%%%%%%",
      ",,(!!%%%%%%%%%%%",
      ",,(!!%%%%%%%%%%%",
      "))(!!%%%%%%%%%%%",
      "))(!!%%%%%%%%%%%",
      "))(!!%%%%%%%%%%%",
      "))(!!%%%%%%%%%%%",
      "))(!!%%%%%%%%%%%",
      "))(!!%%%%%%%%%%%"
    ],
    [
      "     $$ 77-77   ",
      "  $  5+97   7 $ ",
      "     *  7   7   ",
      "   27  777/77777",
      "   7    %   %   ",
      "   7    %   %   ",
      "   7    %   %   ",
      "   7    %   %   ",
      "   7    %   %   ",
      "   7    %   %   ",
      "   7    %   %   ",
      "   7    %   %   ",
      "   7    %   %   ",
      "   7    %   %   ",
      "   7    %   %   ",
      "   7    %  '%   "
    ],
    [
      "     $$ 77.77   ",
      "  $     7   7 $ ",
      "        7   7   ",
      "   77  777077777",
      "   7    %   %   ",
      "   7    %   %   ",
      "   7    %   %   ",
      "   7    %   %   ",
      "   7    %   %   ",
      "   7    %   %   ",
      "   7    %   %   ",
      "   7    %   %   ",
      "   7    %   %   ",
      "   7    %   %   ",
      "   7    %   %   ",
      "   7    %   %   "
    ],
    [
      "     88 77777   ",
      "  $     7   7 $ ",
      "     88 7   7   ",
      "   77 1777777777",
      "   7    %   %   ",
      "   7    %   %   ",
      "   7    %   %   ",
      "   7    %   %   ",
      "   7    %   %   ",
      "   7    %   %   ",
      "   7    %   %   ",
      "   7    %   %   ",
      "   7    %   %   ",
      "   7    %   %   ",
      "   7    %   %   ",
      "   7    %4  %   "
    ],
    [
      "        77777   ",
      "  6     77777 6 ",
      "        77777   ",
      "   7777777777777",
      "   7    %   %   ",
      "   7    %   %   ",
      "   7    %   %   ",
      "   7    %   %   ",
      "   7    %   %   ",
      "   7    %   %   ",
      "   7    %   %   ",
      "   7    %   %   ",
      "   7    %   %   ",
      "   7    %   %   ",
      "   7    %   %   ",
      "   7    %   %   "
    ],
    [
      "       &&&&&&&  ",
      "       &&&&&&&  ",
      "       &&&&&&&  ",
      "   7777777777777",
      "   7            ",
      "   7            ",
      "   7            ",
      "   7            ",
      "   7            ",
      "   7            ",
      "   7            ",
      "   7            ",
      "   7            ",
      "   7            ",
      "   7            ",
      "   7            "
    ]
  ],
  "palette": {
    "palette": [
      {
        "char": "!",
        "block": "immersiveengineering:concrete"
      },
      {
        "char": "$",
        "block": "immersiveengineering:concrete_pillar"
      },
      {
        "char": "%",
        "block": "immersiveengineering:concrete_tile"
      },
      {
        "char": "&",
        "block": "immersiveengineering:slab_concrete"
      },
      {
        "char": "'",
        "block": "minecraft:bookshelf"
      },
      {
        "char": "(",
        "block": "minecraft:coarse_dirt"
      },
      {
        "char": ")",
        "block": "minecraft:cracked_stone_bricks"
      },
      {
        "char": "*",
        "block": "minecraft:glass_pane"
      },
      {
        "char": "+",
        "block": "minecraft:gravel"
      },
      {
        "char": ",",
        "block": "minecraft:gray_concrete"
      },
      {
        "char": "-",
        "block": "minecraft:iron_door[facing=north,half=lower,hinge=left,open=false,powered=false]"
      },
      {
        "char": ".",
        "block": "minecraft:iron_door[facing=north,half=upper,hinge=left,open=false,powered=false]"
      },
      {
        "char": "/",
        "block": "minecraft:oak_door[facing=north,half=lower,hinge=left,open=false,powered=false]"
      },
      {
        "char": "0",
        "block": "minecraft:oak_door[facing=north,half=upper,hinge=left,open=false,powered=false]"
      },
      {
        "char": "1",
        "block": "quark:dirty_glass_pane"
      },
      {
        "char": "2",
        "block": "supplementaries:notice_board"
      },
      {
        "char": "3",
        "block": "tfmg:asphalt"
      },
      {
        "char": "4",
        "block": "tfmg:circular_light"
      },
      {
        "char": "5",
        "block": "tfmg:concrete_encased_industrial_pipe"
      },
      {
        "char": "6",
        "block": "tfmg:gas_lamp"
      },
      {
        "char": "7",
        "block": "tfmg:gray_rebar_concrete"
      },
      {
        "char": "8",
        "block": "tfmg:industrial_pipe"
      },
      {
        "char": "9",
        "block": "tfmg:yellow_caution_block"
      }
    ]
  }
}
