{
  "xsize": 16,
  "zsize": 16,
  "slices": [
    [
      "))'!!!!!!%%%!!!!",
      "))'!!%%%%%%%%%%%",
      "))'!!%%%%%%%%%%%",
      "))'!!%%%%%%%%%%%",
      "))'!!!!!!!!!!!!!",
      "))'!!+++++++++++",
      "))'!!+++++++++++",
      "))'!!+++++++++++",
      "))'!!+++++++++++",
      "(('!!+++++++++++",
      "(('!!+++++++++++",
      "(('!!+++++++++++",
      "(('!!+++++++++++",
      "(('!!+++++++++++",
      "))'!!+++++++++++",
      "))'!!+++++++++++"
    ],
    [
      "   , %%%%   %%%%",
      "   ,       $$   ",
      "   ,            ",
      "   ,       $$   ",
      "   , %%%%%%%%%%%",
      "   ,            ",
      "   ,            ",
      "   ,            ",
      "   ,            ",
      "   ,            ",
      "   ,            ",
      "   ,            ",
      "   ,    &    &  ",
      "   ,            ",
      "   ,    *    *  ",
      "   ,            "
    ],
    [
      "   , %%%%   %%%%",
      "   ,        $   ",
      "   ,            ",
      "   ,        $   ",
      "   , %%%%%%%%%%%",
      "   ,            ",
      "   ,            ",
      "   ,            ",
      "   ,            ",
      "   ,            ",
      "   ,            ",
      "   ,            ",
      "   ,            ",
      "   ,            ",
      "   ,            ",
      "   ,            "
    ],
    [
      "   , %%%%   %%%%",
      "   ,            ",
      "   ,            ",
      "   ,            ",
      "   , %%%%%%%%%%%",
      "   ,            ",
      "   ,            ",
      "   ,            ",
      "   ,            ",
      "   ,            ",
      "   ,            ",
      "   ,            ",
      "   ,            ",
      "   ,            ",
      "   ,            ",
      "   ,            "
    ],
    [
      "   , %%%%%%%%%%%",
      "   ,            ",
      "   ,            ",
      "   ,            ",
      "   , %%%%%%%%%%%",
      "   ,            ",
      "   ,            ",
      "   ,            ",
      "   ,            ",
      "   ,            ",
      "   ,            ",
      "   ,            ",
      "   ,            ",
      "   ,            ",
      "   ,            ",
      "   ,            "
    ],
    [
      "   ,            ",
      "   ,            ",
      "   ,            ",
      "   ,            ",
      "   ,            ",
      "   ,            ",
      "   ,            ",
      "   ,            ",
      "   ,            ",
      "   ,            ",
      "   ,            ",
      "   ,            ",
      "   ,            ",
      "   ,            ",
      "   ,            ",
      "   ,            "
    ]
  ],
  "palette": {
    "palette": [
      {
        "char": "!",
        "block": "immersiveengineering:concrete"
      },
      {
        "char": "$",
        "block": "immersiveengineering:concrete_brick"
      },
      {
        "char": "%",
        "block": "immersiveengineering:concrete_tile"
      },
      {
        "char": "&",
        "block": "minecraft:barrel"
      },
      {
        "char": "'",
        "block": "minecraft:coarse_dirt"
      },
      {
        "char": "(",
        "block": "minecraft:cracked_stone_bricks"
      },
      {
        "char": ")",
        "block": "minecraft:gray_concrete"
      },
      {
        "char": "*",
        "block": "supplementaries:item_shelf"
      },
      {
        "char": "+",
        "block": "tfmg:factory_floor"
      },
      {
        "char": ",",
        "block": "tfmg:gray_rebar_concrete"
      }
    ]
  }
}
