{
  "xsize": 16,
  "zsize": 16,
  "slices": [
    [
      "****.....*****..",
      "****.....*****..",
      "))))))))))))))))",
      "$$$$$$$$$$$$$$$$",
      "''''''''''''''''",
      "''''''''''''''''",
      "''''''''''''''''",
      "''''''''''''''''",
      "''''''''''''''''",
      "''''''''''''''''",
      "''''''''''''''''",
      "''''''''''''''''",
      "''''''''''''''''",
      "''''''''''''''''",
      "''''''''''''''''",
      "''''''''''''''''"
    ],
    [
      "                ",
      "  &           & ",
      "             +  ",
      "%%%%%0000  00  0",
      "%   %           ",
      "%   %           ",
      "%   %           ",
      "%   %           ",
      "%   %     --    ",
      "%   %           ",
      "%%3%%           ",
      "%   %     --    ",
      "%%(%%           ",
      "1   %           ",
      "%   %           ",
      "%   %           "
    ],
    [
      "                ",
      "  &           & ",
      "                ",
      "%%!%%0000  00  0",
      "%   %           ",
      "%   %           ",
      "%   %           ",
      "%   %           ",
      "%   %           ",
      "%   %           ",
      "%%4%%           ",
      "%   %           ",
      "%% %%           ",
      "2%(%%           ",
      "%   %           ",
      "%   %           "
    ],
    [
      "                ",
      "  &           & ",
      "                ",
      "%%!%%0000  00, 0",
      "%   %           ",
      "%   %           ",
      "%   %           ",
      "%   %           ",
      "%   %           ",
      "%   %           ",
      "%%%%%           ",
      "%   %           ",
      "%% %%           ",
      "%% %%           ",
      "%%(%%           ",
      "%   %           "
    ],
    [
      "                ",
      "  /           / ",
      "                ",
      "%%!%%00000000000",
      "%   %           ",
      "%   %           ",
      "%   %           ",
      "%   %           ",
      "%   %           ",
      "%   %           ",
      "%%%%%           ",
      "%   %           ",
      "%   %           ",
      "%% %%           ",
      "%% %%           ",
      "%%(%%           "
    ],
    [
      "                ",
      "                ",
      "                ",
      "%%%%%00000000000",
      "%   %           ",
      "%   %           ",
      "%   %           ",
      "%   %           ",
      "%   %           ",
      "%   %           ",
      "%   %           ",
      "%   %           ",
      "%   %           ",
      "%   %           ",
      "%% %%           ",
      "%% %%           "
    ]
  ],
  "palette": {
    "palette": [
      {
        "char": "!",
        "block": "create:framed_glass"
      },
      {
        "char": "$",
        "block": "immersiveengineering:concrete"
      },
      {
        "char": "%",
        "block": "immersiveengineering:concrete_brick"
      },
      {
        "char": "&",
        "block": "immersiveengineering:concrete_pillar"
      },
      {
        "char": "'",
        "block": "immersiveengineering:concrete_tile"
      },
      {
        "char": "(",
        "block": "immersiveengineering:stairs_concrete[facing=south,half=bottom,shape=straight,waterlogged=false]"
      },
      {
        "char": ")",
        "block": "minecraft:coarse_dirt"
      },
      {
        "char": "*",
        "block": "minecraft:cracked_stone_bricks"
      },
      {
        "char": "+",
        "block": "minecraft:glass_pane"
      },
      {
        "char": ",",
        "block": "quark:dirty_glass_pane"
      },
      {
        "char": "-",
        "block": "supplementaries:item_shelf"
      },
      {
        "char": ".",
        "block": "tfmg:asphalt"
      },
      {
        "char": "/",
        "block": "tfmg:gas_lamp"
      },
      {
        "char": "0",
        "block": "tfmg:gray_rebar_concrete"
      },
      {
        "char": "1",
        "block": "the_wasteland_reworked:industrial_door[facing=east,half=lower,hinge=left,open=false,powered=false]"
      },
      {
        "char": "2",
        "block": "the_wasteland_reworked:industrial_door[facing=east,half=upper,hinge=left,open=false,powered=false]"
      },
      {
        "char": "3",
        "block": "the_wasteland_reworked:industrial_door[facing=south,half=lower,hinge=left,open=false,powered=false]"
      },
      {
        "char": "4",
        "block": "the_wasteland_reworked:industrial_door[facing=south,half=upper,hinge=left,open=false,powered=false]"
      }
    ]
  }
}
