{
  "xsize": 16,
  "zsize": 16,
  "slices": [
    [
      "11-----11111****",
      "11-----11111****",
      "))))))))))))))))",
      "$$$$$$$$$$$$$$$$",
      "''''''''''''''''",
      "''''''''''''''''",
      "''''''''''''''''",
      "''''''''''''''''",
      "''''''''''''''''",
      "''''''''''''''''",
      "''''''''''''''''",
      "''''''''''''''''",
      "''''''''''''''''",
      "''''''''''''''''",
      "''''''''''''''''",
      "''''''''''''''''"
    ],
    [
      "                ",
      "  &   ,       & ",
      "     +          ",
      "4  44  4%%%%%44/",
      "        %   %  .",
      "        %   %  /",
      "        %   %  .",
      "        %   %  /",
      "        %   %  .",
      "        %   %  /",
      "        %%7%%  .",
      "        %   %  /",
      "        %%(%%  .",
      "        5   %  /",
      " 9999999999 %  .",
      "        %   %   "
    ],
    [
      "                ",
      "  &           & ",
      "                ",
      "4  44  4%%!%%444",
      "        %   %   ",
      "        %   %   ",
      "        %   %   ",
      "        %   %   ",
      "        %   %   ",
      "        %   %   ",
      "        %%8%%   ",
      "        %   %   ",
      "        %% %%   ",
      "        6%(%%   ",
      " :::::::::: %   ",
      "        %   %   "
    ],
    [
      "                ",
      "  &           & ",
      "                ",
      "40 44 04%%!%%444",
      "        %   %   ",
      "        %   %   ",
      "        %   %   ",
      "        %   %   ",
      "        %   %   ",
      "        %   %   ",
      "        %%%%%   ",
      "        %   %   ",
      "        %% %%   ",
      "        %% %%   ",
      "        %%(%%   ",
      "        %   %   "
    ],
    [
      "                ",
      "  3           3 ",
      "                ",
      "44444  4%%!%%444",
      "        %   %   ",
      "        %   %   ",
      "        %   %   ",
      "        %   %   ",
      "        %   %   ",
      "        %   %   ",
      "        %%%%%   ",
      "        %   %   ",
      "        %   %   ",
      "        %% %%   ",
      "        %% %%   ",
      "        %%(%%   "
    ],
    [
      "                ",
      "                ",
      "                ",
      "44444444%%%%%444",
      "        %   %   ",
      "        %   %   ",
      "        %   %   ",
      "        %   %   ",
      "        %   %   ",
      "        %   %   ",
      "        %   %   ",
      "        %   %   ",
      "        %   %   ",
      "   2    2   %   ",
      "        %% %%   ",
      "        %% %%   "
    ]
  ],
  "palette": {
    "palette": [
      {
        "char": "!",
        "block": "create:framed_glass"
      },
      {
        "char": "$",
        "block": "immersiveengineering:concrete"
      },
      {
        "char": "%",
        "block": "immersiveengineering:concrete_brick"
      },
      {
        "char": "&",
        "block": "immersiveengineering:concrete_pillar"
      },
      {
        "char": "'",
        "block": "immersiveengineering:concrete_tile"
      },
      {
        "char": "(",
        "block": "immersiveengineering:stairs_concrete[facing=south,half=bottom,shape=straight,waterlogged=false]"
      },
      {
        "char": ")",
        "block": "minecraft:coarse_dirt"
      },
      {
        "char": "*",
        "block": "minecraft:cracked_stone_bricks"
      },
      {
        "char": "+",
        "block": "minecraft:glass_pane"
      },
      {
        "char": ",",
        "block": "minecraft:gravel"
      },
      {
        "char": "-",
        "block": "minecraft:gray_concrete"
      },
      {
        "char": ".",
        "block": "minecraft:ice"
      },
      {
        "char": "/",
        "block": "minecraft:packed_ice"
      },
      {
        "char": "0",
        "block": "quark:dirty_glass_pane"
      },
      {
        "char": "1",
        "block": "tfmg:asphalt"
      },
      {
        "char": "2",
        "block": "tfmg:circular_light"
      },
      {
        "char": "3",
        "block": "tfmg:gas_lamp"
      },
      {
        "char": "4",
        "block": "tfmg:gray_rebar_concrete"
      },
      {
        "char": "5",
        "block": "the_wasteland_reworked:industrial_door[facing=east,half=lower,hinge=left,open=false,powered=false]"
      },
      {
        "char": "6",
        "block": "the_wasteland_reworked:industrial_door[facing=east,half=upper,hinge=left,open=false,powered=false]"
      },
      {
        "char": "7",
        "block": "the_wasteland_reworked:industrial_door[facing=south,half=lower,hinge=left,open=false,powered=false]"
      },
      {
        "char": "8",
        "block": "the_wasteland_reworked:industrial_door[facing=south,half=upper,hinge=left,open=false,powered=false]"
      },
      {
        "char": "9",
        "block": "zvhouses:spruce_counter"
      },
      {
        "char": ":",
        "block": "zvhouses:spruce_countertop"
      }
    ]
  }
}
