{
  "xsize": 16,
  "zsize": 16,
  "slices": [
    [
      "                ",
      "                ",
      "                ",
      "                ",
      "$$$$$$$$$$$$$$$$",
      "$$$$$$$$$$$$$$$$",
      "$$$$$$$$$$$$$$$$",
      "$$$$$$$$$$$$$$$$",
      "$$$$$$$$$$$$$$$$",
      "$$$$$$$$$$$$$$$$",
      "$$$$$$$$$$$$$$$$",
      "$$$$$$$$$$$$$$$$",
      "$$$$$$$$$$$$$$$$",
      "$$$$$$$$$$$$$$$$",
      "$$$$$$$$$$$$$$$$",
      "$$$$$$$$$$$$$$$$"
    ],
    [
      "                ",
      "                ",
      "                ",
      "                ",
      "!!!!!!!!!!!!!!!!",
      "                ",
      "                ",
      "                ",
      "                ",
      "                ",
      "                ",
      "%%%%            ",
      "%%%%            ",
      "%%%%            ",
      "%%%%            ",
      "%%%%            "
    ],
    [
      "                ",
      "                ",
      "                ",
      "                ",
      "!!!!!!!!!!!!!!!!",
      "                ",
      "                ",
      "                ",
      "                ",
      "                ",
      "                ",
      "%%%%            ",
      "%%%%            ",
      "%%%%            ",
      "%%%%            ",
      "%%%%            "
    ],
    [
      "                ",
      "                ",
      "                ",
      "                ",
      "&&&&&&&&&&&&&&&&",
      "                ",
      "                ",
      "                ",
      "                ",
      "                ",
      "                ",
      "%%%%            ",
      "%%%%            ",
      "%%%%            ",
      "%%%%            ",
      "%%%%            "
    ]
  ],
  "palette": {
    "palette": [
      {
        "char": "!",
        "block": "immersiveengineering:concrete"
      },
      {
        "char": "$",
        "block": "immersiveengineering:concrete_sheet"
      },
      {
        "char": "%",
        "block": "immersiveengineering:concrete_tile"
      },
      {
        "char": "&",
        "block": "immersiveengineering:slab_concrete[type=bottom,waterlogged=false]"
      }
    ]
  }
}
