{
  "xsize": 16,
  "zsize": 16,
  "slices": [
    [
      "22++++++++++****",
      "22++++++++++****",
      "))))))))))))))))",
      "$$$$$$$$$$$$$$$$",
      "''''''''''''''''",
      "''''''''''''''''",
      "''''''''''''''''",
      "''''''''''''''''",
      "''''''''''''''''",
      "''''''''''''''''",
      "''''''''''''''''",
      "''''''''''''''''",
      "''''''''''''''''",
      "''''''''''''''''",
      "''''''''''''''''",
      "''''''''''''''''"
    ],
    [
      "                ",
      "  &           & ",
      "                ",
      "50055,-5%%%%%555",
      "        %   %   ",
      "        %   %   ",
      "        %   %   ",
      "        %   %   ",
      "        %   %   ",
      "        %   %   ",
      "        %%8%%   ",
      "        %   %   ",
      "        %%(%%   ",
      "        6   %   ",
      " ;;;;;;;;;; %   ",
      "        %   %   "
    ],
    [
      "                ",
      "  &           & ",
      "                ",
      "50055./5%%!%%555",
      "        %   %   ",
      "        %   %   ",
      "        %   %   ",
      "        %   %   ",
      "        %   %   ",
      "        %   %   ",
      "        %%9%%   ",
      "        %   %   ",
      "        %% %%   ",
      "        7%(%%   ",
      " <<<<<<<<<< %   ",
      "        %   %   "
    ],
    [
      "                ",
      "  &           & ",
      "                ",
      "50055555%%!%%555",
      "        %   %   ",
      "        %   %   ",
      "        %   %   ",
      "        %   %   ",
      "        %   %   ",
      "        %   %   ",
      "        %%%%%   ",
      "        %   %   ",
      "        %% %%   ",
      "        %% %%   ",
      "        %%(%%   ",
      "        %   %   "
    ],
    [
      "                ",
      "  4           4 ",
      "                ",
      "55555:15%%!%%555",
      "        %   %   ",
      "        %   %   ",
      "        %   %   ",
      "        %   %   ",
      "        %   %   ",
      "        %   %   ",
      "        %%%%%   ",
      "        %   %   ",
      "        %   %   ",
      "        %% %%   ",
      "        %% %%   ",
      "        %%(%%   "
    ],
    [
      "                ",
      "                ",
      "                ",
      "55555555%%%%%555",
      "        %   %   ",
      "        %   %   ",
      "        %   %   ",
      "        %   %   ",
      "        %   %   ",
      "        %   %   ",
      "        %   %   ",
      "        %   %   ",
      "        %   %   ",
      "   3    3   %   ",
      "        %% %%   ",
      "        %% %%   "
    ]
  ],
  "palette": {
    "palette": [
      {
        "char": "!",
        "block": "create:framed_glass"
      },
      {
        "char": "$",
        "block": "immersiveengineering:concrete"
      },
      {
        "char": "%",
        "block": "immersiveengineering:concrete_brick"
      },
      {
        "char": "&",
        "block": "immersiveengineering:concrete_pillar"
      },
      {
        "char": "'",
        "block": "immersiveengineering:concrete_tile"
      },
      {
        "char": "(",
        "block": "immersiveengineering:stairs_concrete[facing=south,half=bottom,shape=straight,waterlogged=false]"
      },
      {
        "char": ")",
        "block": "minecraft:coarse_dirt"
      },
      {
        "char": "*",
        "block": "minecraft:cracked_stone_bricks"
      },
      {
        "char": "+",
        "block": "minecraft:gray_concrete"
      },
      {
        "char": ",",
        "block": "minecraft:iron_door[facing=north,half=lower,hinge=left,open=false,powered=false]"
      },
      {
        "char": "-",
        "block": "minecraft:iron_door[facing=north,half=lower,hinge=right,open=false,powered=false]"
      },
      {
        "char": ".",
        "block": "minecraft:iron_door[facing=north,half=upper,hinge=left,open=false,powered=false]"
      },
      {
        "char": "/",
        "block": "minecraft:iron_door[facing=north,half=upper,hinge=right,open=false,powered=false]"
      },
      {
        "char": "0",
        "block": "quark:white_framed_glass"
      },
      {
        "char": "1",
        "block": "supplementaries:notice_board"
      },
      {
        "char": "2",
        "block": "tfmg:asphalt"
      },
      {
        "char": "3",
        "block": "tfmg:circular_light"
      },
      {
        "char": "4",
        "block": "tfmg:gas_lamp"
      },
      {
        "char": "5",
        "block": "tfmg:gray_rebar_concrete"
      },
      {
        "char": "6",
        "block": "the_wasteland_reworked:industrial_door[facing=east,half=lower,hinge=left,open=false,powered=false]"
      },
      {
        "char": "7",
        "block": "the_wasteland_reworked:industrial_door[facing=east,half=upper,hinge=left,open=false,powered=false]"
      },
      {
        "char": "8",
        "block": "the_wasteland_reworked:industrial_door[facing=south,half=lower,hinge=left,open=false,powered=false]"
      },
      {
        "char": "9",
        "block": "the_wasteland_reworked:industrial_door[facing=south,half=upper,hinge=left,open=false,powered=false]"
      },
      {
        "char": ":",
        "block": "the_wasteland_reworked:road_sign"
      },
      {
        "char": ";",
        "block": "zvhouses:spruce_counter"
      },
      {
        "char": "<",
        "block": "zvhouses:spruce_countertop"
      }
    ]
  }
}
