{
  "xsize": 16,
  "zsize": 16,
  "slices": [
    [
      ".....*****)))))*",
      ".....*****)))))*",
      "..((((((((((((((",
      "..(!!!!!!!!!!!!!",
      "..(!!!!!!!!!!!!!",
      "**(!!000000000!!",
      "**(!!000000000!!",
      "**(!!000000000!!",
      "**(!!000000000!!",
      "**(!!000000000!!",
      "**(!!000000000!!",
      "**(!!000000000!!",
      "**(!!000000000!!",
      "**(!!000000000!!",
      "**(!!000000000!!",
      "..(!!000000000!!"
    ],
    [
      "     %%         ",
      "  %  //4      % ",
      "     +          ",
      "   -2))22222222$",
      "   2           $",
      "   2 &       & $",
      "   2 &'     ,& $",
      "   2 &       & $",
      "   2 &       & $",
      "   2 &       & $",
      "   2 &       & $",
      "   2 &       & $",
      "   2 &       & $",
      "   2 &       & $",
      "   2 & 5     & $",
      "   2 &       & $"
    ],
    [
      "     %%         ",
      "  %           % ",
      "                ",
      "   22  22222222$",
      "   2           $",
      "   2 &       & $",
      "   2 &       & $",
      "   2 &       & $",
      "   2 &       & $",
      "   2 &       & $",
      "   2 &       & $",
      "   2 &       & $",
      "   2 &       & $",
      "   2 &       & $",
      "   2 &       & $",
      "   2 &       & $"
    ],
    [
      "     33         ",
      "  %           % ",
      "     33         ",
      "   22 /22222222$",
      "   2           $",
      "   2 &       & $",
      "   2 &       & $",
      "   2 &       & $",
      "   2 &       & $",
      "   2 &       & $",
      "   2 &       & $",
      "   2 &       & $",
      "   2 &       & $",
      "   2 &       & $",
      "   2 &       & $",
      "   2 &       & $"
    ],
    [
      "                ",
      "  1           1 ",
      "                ",
      "   222222222222$",
      "   2           $",
      "   2 &       & $",
      "   2 &       & $",
      "   2 &       & $",
      "   2 &       & $",
      "   2 &       & $",
      "   2 &       & $",
      "   2 &       & $",
      "   2 &       & $",
      "   2 &       & $",
      "   2 &       & $",
      "   2 &       & $"
    ],
    [
      "                ",
      "                ",
      "                ",
      "   222222222222$",
      "   2           $",
      "   2           $",
      "   2           $",
      "   2           $",
      "   2           $",
      "   2           $",
      "   2           $",
      "   2           $",
      "   2           $",
      "   2           $",
      "   2           $",
      "   2           $"
    ]
  ],
  "palette": {
    "palette": [
      {
        "char": "!",
        "block": "immersiveengineering:concrete"
      },
      {
        "char": "$",
        "block": "immersiveengineering:concrete_brick"
      },
      {
        "char": "%",
        "block": "immersiveengineering:concrete_pillar"
      },
      {
        "char": "&",
        "block": "immersiveengineering:concrete_tile"
      },
      {
        "char": "'",
        "block": "minecraft:barrel"
      },
      {
        "char": "(",
        "block": "minecraft:coarse_dirt"
      },
      {
        "char": ")",
        "block": "minecraft:gravel"
      },
      {
        "char": "*",
        "block": "minecraft:gray_concrete"
      },
      {
        "char": "+",
        "block": "minecraft:packed_ice"
      },
      {
        "char": ",",
        "block": "supplementaries:item_shelf"
      },
      {
        "char": "-",
        "block": "supplementaries:notice_board"
      },
      {
        "char": ".",
        "block": "tfmg:asphalt"
      },
      {
        "char": "/",
        "block": "tfmg:concrete_encased_industrial_pipe"
      },
      {
        "char": "0",
        "block": "tfmg:factory_floor"
      },
      {
        "char": "1",
        "block": "tfmg:gas_lamp"
      },
      {
        "char": "2",
        "block": "tfmg:gray_rebar_concrete"
      },
      {
        "char": "3",
        "block": "tfmg:industrial_pipe"
      },
      {
        "char": "4",
        "block": "tfmg:yellow_caution_block"
      },
      {
        "char": "5",
        "block": "zvhouses:spruce_bench"
      }
    ]
  }
}
