{
  "xsize": 16,
  "zsize": 16,
  "slices": [
    [
      ")))))*****)))))*",
      ")))))*****)))))*",
      "))((((((((((((((",
      "))(!!!!!!%%%!!!!",
      "))(!!%%%%%%%%%%%",
      "))(!!%%%%%%%%%%%",
      "))(!!%%%%%%%%%%%",
      "))(!!%%%%%%%%%%%",
      "))(!!%%%%%%%%%%%",
      "))(!!%%%%%%%%%%%",
      "))(!!%%%%%%%%%%%",
      "))(!!%%%%%%%%%%%",
      "))(!!%%%%%%%%%%%",
      "))(!!%%%%%%%%%%%",
      "))(!!%%%%%%%%%%%",
      "**(!!%%%%%%%%%%%"
    ],
    [
      "     $$ 44+44   ",
      "  $     4   4 $ ",
      "        4   4   ",
      "   042/444-44444",
      "   4    %   %   ",
      "   4    %   %   ",
      "   4    %   %   ",
      "   4    %   %   ",
      "   4    %   %   ",
      "   4    %   %   ",
      "   4    %   %   ",
      "   4    %   %   ",
      "   4    %   %   ",
      "   4    %   %   ",
      "   4    %   %   ",
      "   4    %  '%   "
    ],
    [
      "     $$ 44,44   ",
      "  $     4   4 $ ",
      "        4   4   ",
      "   442/444.44444",
      "   4    %   %   ",
      "   4    %   %   ",
      "   4    %   %   ",
      "   4    %   %   ",
      "   4    %   %   ",
      "   4    %   %   ",
      "   4    %   %   ",
      "   4    %   %   ",
      "   4    %   %   ",
      "   4    %   %   ",
      "   4    %   %   ",
      "   4    %   %   "
    ],
    [
      "     22 44444   ",
      "  $  22 4   4 $ ",
      "     22 4   4   ",
      "   4422444444444",
      "   4    %   %   ",
      "   4    %   %   ",
      "   4    %   %   ",
      "   4    %   %   ",
      "   4    %   %   ",
      "   4    %   %   ",
      "   4    %   %   ",
      "   4    %   %   ",
      "   4    %   %   ",
      "   4    %   %   ",
      "   4    %   %   ",
      "   4    %1  %   "
    ],
    [
      "        44444   ",
      "  3     44444 3 ",
      "        44444   ",
      "   4444444444444",
      "   4    %   %   ",
      "   4    %   %   ",
      "   4    %   %   ",
      "   4    %   %   ",
      "   4    %   %   ",
      "   4    %   %   ",
      "   4    %   %   ",
      "   4    %   %   ",
      "   4    %   %   ",
      "   4    %   %   ",
      "   4    %   %   ",
      "   4    %   %   "
    ],
    [
      "       &&&&&&&  ",
      "       &&&&&&&  ",
      "       &&&&&&&  ",
      "   4444444444444",
      "   4            ",
      "   4            ",
      "   4            ",
      "   4            ",
      "   4            ",
      "   4            ",
      "   4            ",
      "   4            ",
      "   4            ",
      "   4            ",
      "   4            ",
      "   4            "
    ]
  ],
  "palette": {
    "palette": [
      {
        "char": "!",
        "block": "immersiveengineering:concrete"
      },
      {
        "char": "$",
        "block": "immersiveengineering:concrete_pillar"
      },
      {
        "char": "%",
        "block": "immersiveengineering:concrete_tile"
      },
      {
        "char": "&",
        "block": "immersiveengineering:slab_concrete"
      },
      {
        "char": "'",
        "block": "minecraft:bookshelf"
      },
      {
        "char": "(",
        "block": "minecraft:coarse_dirt"
      },
      {
        "char": ")",
        "block": "minecraft:cracked_stone_bricks"
      },
      {
        "char": "*",
        "block": "minecraft:gray_concrete"
      },
      {
        "char": "+",
        "block": "minecraft:iron_door[facing=north,half=lower,hinge=left,open=false,powered=false]"
      },
      {
        "char": ",",
        "block": "minecraft:iron_door[facing=north,half=upper,hinge=left,open=false,powered=false]"
      },
      {
        "char": "-",
        "block": "minecraft:oak_door[facing=north,half=lower,hinge=left,open=false,powered=false]"
      },
      {
        "char": ".",
        "block": "minecraft:oak_door[facing=north,half=upper,hinge=left,open=false,powered=false]"
      },
      {
        "char": "/",
        "block": "quark:white_framed_glass"
      },
      {
        "char": "0",
        "block": "supplementaries:notice_board"
      },
      {
        "char": "1",
        "block": "tfmg:circular_light"
      },
      {
        "char": "2",
        "block": "tfmg:concrete_encased_industrial_pipe"
      },
      {
        "char": "3",
        "block": "tfmg:gas_lamp"
      },
      {
        "char": "4",
        "block": "tfmg:gray_rebar_concrete"
      }
    ]
  }
}
