{
  "xsize": 16,
  "zsize": 16,
  "slices": [
    [
      "(((*************",
      "(((*************",
      "((&*************",
      "''&,,,,,,,,,,,,,",
      "''&,,,,,,,,,,,,,",
      "''&,,,,,,,,,,,,,",
      "''&,,,,,,,,,,,,,",
      "''&,,,,,,,,,,,,,",
      "''&,,,,,,,,,,,,,",
      "**&,,,,,,,,,,,,,",
      "**&&&&&&&&&&&&&&",
      "***'''''''''***(",
      "(((******'''***(",
      "(((******'''***(",
      "(((******'''***(",
      "'''(((((('''***'"
    ],
    [
      "                ",
      "                ",
      "                ",
      "  -,,,,,,,,,,,,,",
      "                ",
      "                ",
      "    !           ",
      "    ! . . . . . ",
      "    $!!!$!!!$!!!",
      "                ",
      "                ",
      "                ",
      "                ",
      "                ",
      "                ",
      "                "
    ],
    [
      "                ",
      "                ",
      "                ",
      "                ",
      "                ",
      "                ",
      "    !           ",
      "    )           ",
      "    $!!!$!!!$!!!",
      "    !           ",
      "                ",
      "                ",
      "                ",
      "                ",
      "                ",
      "                "
    ],
    [
      "                ",
      "                ",
      "                ",
      "                ",
      "                ",
      "                ",
      "    !           ",
      "    )           ",
      "    $!!!$!!!$!!!",
      "    !           ",
      "                ",
      "                ",
      "                ",
      "                ",
      "                ",
      "                "
    ],
    [
      "                ",
      "                ",
      "                ",
      "                ",
      "                ",
      "                ",
      "    !           ",
      "    !     +     ",
      "    $!!!$!!!$!!!",
      "                ",
      "                ",
      "                ",
      "                ",
      "                ",
      "                ",
      "                "
    ],
    [
      "                ",
      "                ",
      "                ",
      "                ",
      "    %%%%%%%%%%%%",
      "    %%%%%%%%%%%%",
      "    %%%%%%%%%%%%",
      "    %%%%%%%%%%%%",
      "    %%%%%%%%%%%%",
      "                ",
      "                ",
      "                ",
      "                ",
      "                ",
      "                ",
      "                "
    ]
  ],
  "palette": {
    "palette": [
      {
        "char": "!",
        "block": "immersiveengineering:concrete"
      },
      {
        "char": "$",
        "block": "immersiveengineering:concrete_brick"
      },
      {
        "char": "%",
        "block": "immersiveengineering:concrete_sheet"
      },
      {
        "char": "&",
        "block": "minecraft:coarse_dirt"
      },
      {
        "char": "'",
        "block": "minecraft:cracked_stone_bricks"
      },
      {
        "char": "(",
        "block": "minecraft:gray_concrete"
      },
      {
        "char": ")",
        "block": "quark:white_framed_glass"
      },
      {
        "char": "*",
        "block": "tfmg:asphalt"
      },
      {
        "char": "+",
        "block": "tfmg:circular_light"
      },
      {
        "char": ",",
        "block": "tfmg:gray_rebar_concrete"
      },
      {
        "char": "-",
        "block": "the_wasteland_reworked:barricade"
      },
      {
        "char": ".",
        "block": "zvhouses:spruce_bench"
      }
    ]
  }
}
