{
  "xsize": 16,
  "zsize": 16,
  "slices": [
    [
      "++++'''''))     ",
      "++++'''''))     ",
      "++++'''''))     ",
      "++++'''''))     ",
      "++++'''''))     ",
      "'''')))))))     ",
      "'''')))))))     ",
      "'''')))))))     ",
      ",,,')))))))     ",
      ",,,')))))))     ",
      ",,,'+++++))     ",
      ",,,'+++++))     ",
      ",,,'+++++))     ",
      ",,,'+++++))     ",
      ",,,'+++++))     ",
      ",,,'(((((((     "
    ],
    [
      "                ",
      "                ",
      "                ",
      "                ",
      "&*****&         ",
      "      *         ",
      "      *         ",
      "%%%.%%%         ",
      "%     %         ",
      "%     %         ",
      "%     %         ",
      "%     %         ",
      "%%%%%%%         ",
      "0     *         ",
      "      *         ",
      "      *         "
    ],
    [
      "                ",
      "                ",
      "                ",
      "                ",
      "&     &         ",
      "                ",
      "                ",
      "%%%/%%%         ",
      "%     %         ",
      "%     %         ",
      "%     %         ",
      "%     %         ",
      "%%%%%%%         ",
      "                ",
      "                ",
      "                "
    ],
    [
      "                ",
      "                ",
      "                ",
      "                ",
      "&     &         ",
      "                ",
      "                ",
      "%%%%%%%         ",
      "%     %         ",
      "%     -         ",
      "%     %         ",
      "% !   %         ",
      "%%%%%%%         ",
      "                ",
      "                ",
      "                "
    ],
    [
      "                ",
      "                ",
      "                ",
      "                ",
      "                ",
      "                ",
      "                ",
      "%%%%%%%         ",
      "%%%%%%%         ",
      "%%%%%%%         ",
      "%%%%%%%         ",
      "%%%%%%%         ",
      "%%%%%%%         ",
      "                ",
      "                ",
      "                "
    ],
    [
      "                ",
      "                ",
      "                ",
      "                ",
      "                ",
      "                ",
      "                ",
      "$$$$$$$         ",
      "$$$$$$$         ",
      "$$$$$$$         ",
      "$$$$$$$         ",
      "$$$$$$$         ",
      "$$$$$$$         ",
      "                ",
      "                ",
      "                "
    ]
  ],
  "palette": {
    "palette": [
      {
        "char": "!",
        "block": "immersiveengineering:cagelamp"
      },
      {
        "char": "$",
        "block": "immersiveengineering:concrete_sheet"
      },
      {
        "char": "%",
        "block": "immersiveengineering:concrete_tile"
      },
      {
        "char": "&",
        "block": "immersiveengineering:steel_post"
      },
      {
        "char": "'",
        "block": "minecraft:coarse_dirt"
      },
      {
        "char": "(",
        "block": "minecraft:grass_block"
      },
      {
        "char": ")",
        "block": "minecraft:mossy_cobblestone"
      },
      {
        "char": "*",
        "block": "minecraft:oxidized_copper_grate"
      },
      {
        "char": "+",
        "block": "minecraft:podzol"
      },
      {
        "char": ",",
        "block": "tfmg:gray_rebar_concrete"
      },
      {
        "char": "-",
        "block": "tfmg:yellow_caution_block"
      },
      {
        "char": ".",
        "block": "the_wasteland_reworked:industrial_door[facing=north,half=lower,hinge=left,open=false,powered=false]"
      },
      {
        "char": "/",
        "block": "the_wasteland_reworked:industrial_door[facing=north,half=upper,hinge=left,open=false,powered=false]"
      },
      {
        "char": "0",
        "block": "the_wasteland_reworked:pipe_block"
      }
    ]
  }
}
