{
  "xsize": 16,
  "zsize": 16,
  "slices": [
    [
      "!!!!!!!!!!!!!!!!",
      "%%%%%%%%%%%%%%%%",
      "%%%%%%%%%%%%%%%%",
      "%%%%%%%%%%%%%%%%",
      "!!!!!!!!!!!!!!!!",
      "))))))))))))))))",
      "))))))))))))))))",
      "))))))))))))))))",
      "))))))))))))))))",
      "))))))))))))))))",
      "))))))))))))))))",
      "))))))))))))))))",
      "))))))))))))))))",
      "))))))))))))))))",
      "))))))))))))))))",
      "))))))))))))))))"
    ],
    [
      "%%%%%%%%%%%%%%%%",
      "   $   $        ",
      "   $   $        ",
      "                ",
      "%%%%%%%%%%%%%%%%",
      "            %   ",
      "            %   ",
      "            *   ",
      "            %   ",
      "            %   ",
      "            %   ",
      "            %   ",
      "   '    '   %   ",
      "            %   ",
      "   (    (   %  '",
      "            %   "
    ],
    [
      "%%%%%%%%%%%%%%%%",
      "   $   $        ",
      "   $   $        ",
      "                ",
      "%%%%%%%%%%%%%%%%",
      "            %   ",
      "            %   ",
      "            +   ",
      "            %   ",
      "            %   ",
      "            %   ",
      "            %   ",
      "            %   ",
      "            %   ",
      "            %   ",
      "            %   "
    ],
    [
      "%%%%%%%%%%%%%%%%",
      "   $   $        ",
      "   $   $        ",
      "                ",
      "%%%%%%%%%%%%%%%%",
      "            %   ",
      "            %   ",
      "            %   ",
      "            %   ",
      "            %   ",
      "            %   ",
      "            %   ",
      "            %   ",
      "            %   ",
      "            %   ",
      "            %   "
    ],
    [
      "%%%%%%%%%%%%%%%%",
      "   $   $        ",
      "   $   $        ",
      "                ",
      "%%%%%%%%%%%%%%%%",
      "            %   ",
      "            %   ",
      "            %   ",
      "            %   ",
      "            %   ",
      "            %   ",
      "            %   ",
      "            %   ",
      "            %   ",
      "            %   ",
      "            %   "
    ],
    [
      "   $$&$$        ",
      "   $   $        ",
      "   $   $        ",
      "                ",
      "                ",
      "                ",
      "                ",
      "                ",
      "                ",
      "                ",
      "                ",
      "                ",
      "                ",
      "                ",
      "                ",
      "                "
    ]
  ],
  "palette": {
    "palette": [
      {
        "char": "!",
        "block": "immersiveengineering:concrete"
      },
      {
        "char": "$",
        "block": "immersiveengineering:concrete_brick"
      },
      {
        "char": "%",
        "block": "immersiveengineering:concrete_tile"
      },
      {
        "char": "&",
        "block": "immersiveengineering:stairs_concrete[facing=south,half=bottom,shape=straight,waterlogged=false]"
      },
      {
        "char": "'",
        "block": "minecraft:barrel"
      },
      {
        "char": "(",
        "block": "supplementaries:item_shelf"
      },
      {
        "char": ")",
        "block": "tfmg:factory_floor"
      },
      {
        "char": "*",
        "block": "the_wasteland_reworked:industrial_door[facing=east,half=lower,hinge=left,open=false,powered=false]"
      },
      {
        "char": "+",
        "block": "the_wasteland_reworked:industrial_door[facing=east,half=upper,hinge=left,open=false,powered=false]"
      }
    ]
  }
}
