{
  "xsize": 16,
  "zsize": 16,
  "slices": [
    [
      "''''$$$$&&&&$$$$",
      "''''$$$$&&&&$$$$",
      "''''$$$$&&&&$$$$",
      "''''$$$$&&&&$$$$",
      "''''''''$$$$''''",
      "''''''''$$$$''''",
      "''''''''$$$$''''",
      "''''''''$$$$''''",
      "''''%%%%&&&&%%%%",
      "''''%%%%&&&&%%%%",
      "''''%%%%&&&&%%%%",
      "''''%%%%&&&&%%%%",
      "''''%%%%&&&&''''",
      "''''%%%%&&&&''''",
      "''''%%%%&&&&''''",
      "''''%%%%&&&&''''"
    ],
    [
      "                ",
      "                ",
      "                ",
      "                ",
      "                ",
      "                ",
      "****            ",
      "    ,           ",
      "!    (  !   !   ",
      "!    (  !   !   ",
      "     %+         ",
      "****            ",
      "                ",
      "                ",
      "                ",
      "                "
    ],
    [
      "                ",
      "                ",
      "                ",
      "                ",
      "                ",
      "                ",
      "****            ",
      "                ",
      "!       !   !   ",
      "!       !   !   ",
      "                ",
      "****            ",
      "                ",
      "                ",
      "                ",
      "                "
    ],
    [
      "                ",
      "                ",
      "                ",
      "                ",
      "                ",
      "                ",
      "****            ",
      "                ",
      "((()   )((((((((",
      "((()   )((((((((",
      "                ",
      "****            ",
      "                ",
      "                ",
      "                ",
      "                "
    ],
    [
      "                ",
      "                ",
      "                ",
      "                ",
      "                ",
      "                ",
      "****            ",
      "                ",
      "                ",
      "                ",
      "                ",
      "****            ",
      "                ",
      "                ",
      "                ",
      "                "
    ],
    [
      "                ",
      "                ",
      "                ",
      "                ",
      "                ",
      "                ",
      "****            ",
      "****            ",
      "****            ",
      "****            ",
      "****            ",
      "****            ",
      "                ",
      "                ",
      "                ",
      "                "
    ]
  ],
  "palette": {
    "palette": [
      {
        "char": "!",
        "block": "immersiveengineering:concrete_pillar"
      },
      {
        "char": "$",
        "block": "minecraft:coarse_dirt"
      },
      {
        "char": "%",
        "block": "minecraft:gravel"
      },
      {
        "char": "&",
        "block": "minecraft:gray_concrete"
      },
      {
        "char": "'",
        "block": "tfmg:asphalt"
      },
      {
        "char": "(",
        "block": "tfmg:concrete_encased_industrial_pipe"
      },
      {
        "char": ")",
        "block": "tfmg:industrial_pipe"
      },
      {
        "char": "*",
        "block": "tfmg:steel_block"
      },
      {
        "char": "+",
        "block": "tfmg:yellow_caution_block"
      },
      {
        "char": ",",
        "block": "wastelands:scrap_pile"
      }
    ]
  }
}
