{
  "xsize": 16,
  "zsize": 16,
  "slices": [
    [
      "11,,,,,+++++1111",
      "11,,,,,+++++1111",
      "++++++++++++++++",
      "$$$$$$$$$$$$$$$$",
      "$'''$$$$$$$$$$$$",
      "$'''$$$$$$$$$222",
      "$'''$$$$$$$$$222",
      "$'''$$$$$$$$$222",
      "$'''$$$$$$$$$222",
      "$'''$$$$'''$$222",
      "$'''$$$$'''$$222",
      "$'''$$$$'''$$222",
      "$'''$$$$'''$$222",
      "$'''$$$$'''$$222",
      "$'''$$$$'''$$222",
      "$'''$$$$'''$$222"
    ],
    [
      "44-44           ",
      "4 & 4         & ",
      "4   4           ",
      "44/4444%%%%%4444",
      "'   '  %   %    ",
      "'   '  %   % '  ",
      "'   '  %   % '* ",
      "'   '  %   % '  ",
      "'   '  %   % '  ",
      "'   '  %   % '  ",
      "'   '  %%5%% '  ",
      "'   '  %   % '  ",
      "'   '  %%)%% '  ",
      "'   '  %   % '  ",
      "'   '  %   % ' 7",
      "'   '  %   % '  "
    ],
    [
      "44.44           ",
      "4 & 4         & ",
      "4   4           ",
      "4404444%%!%%4444",
      "'   '  %   %    ",
      "'   '  %   % '  ",
      "'   '  %   % '  ",
      "'   '  %   % '  ",
      "'   '  %   % '  ",
      "'   '  %   % '  ",
      "'   '  %%6%% '  ",
      "'   '  %   % '  ",
      "'   '  %% %% '  ",
      "'   '  %%)%% '  ",
      "'   '  %   % '  ",
      "'   '  %   % '  "
    ],
    [
      "44444           ",
      "4 & 4         & ",
      "4   4           ",
      "4444444%%!%%4444",
      "'   '  %   %    ",
      "'   '  %   % '  ",
      "'   '  %   % '  ",
      "'   '  %   % '  ",
      "'   '  %   % '  ",
      "'   '  %   % '  ",
      "'   '  %%%%% '  ",
      "'   '  %   % '  ",
      "'   '  %% %% '  ",
      "'   '  %% %% '  ",
      "'   '  %%)%% '  ",
      "'   '  %   % '  "
    ],
    [
      "44444           ",
      "44344         3 ",
      "44444           ",
      "4444444%%!%%4444",
      "'   '  %   %    ",
      "'   '  %   % '  ",
      "'   '  %   % '  ",
      "'   '  %   % '  ",
      "'   '  %   % '  ",
      "'   '  %   % '  ",
      "'   '  %%%%% '  ",
      "'   '  %   % '  ",
      "'   '  %   % '  ",
      "'   '  %% %% '  ",
      "'   '  %% %% '  ",
      "'   '  %%)%% '  "
    ],
    [
      "((((((          ",
      "((((((          ",
      "((((((          ",
      "4444444%%%%%4444",
      "       %   %    ",
      "       %   %    ",
      "       %   %    ",
      "       %   %    ",
      "       %   %    ",
      "       %   %    ",
      "       %   %    ",
      "       %   %    ",
      "       %   %    ",
      "       %   %    ",
      "       %% %%    ",
      "       %% %%    "
    ]
  ],
  "palette": {
    "palette": [
      {
        "char": "!",
        "block": "create:framed_glass"
      },
      {
        "char": "$",
        "block": "immersiveengineering:concrete"
      },
      {
        "char": "%",
        "block": "immersiveengineering:concrete_brick"
      },
      {
        "char": "&",
        "block": "immersiveengineering:concrete_pillar"
      },
      {
        "char": "'",
        "block": "immersiveengineering:concrete_tile"
      },
      {
        "char": "(",
        "block": "immersiveengineering:slab_concrete"
      },
      {
        "char": ")",
        "block": "immersiveengineering:stairs_concrete[facing=south,half=bottom,shape=straight,waterlogged=false]"
      },
      {
        "char": "*",
        "block": "minecraft:barrel"
      },
      {
        "char": "+",
        "block": "minecraft:coarse_dirt"
      },
      {
        "char": ",",
        "block": "minecraft:gray_concrete"
      },
      {
        "char": "-",
        "block": "minecraft:iron_door[facing=north,half=lower,hinge=left,open=false,powered=false]"
      },
      {
        "char": ".",
        "block": "minecraft:iron_door[facing=north,half=upper,hinge=left,open=false,powered=false]"
      },
      {
        "char": "/",
        "block": "minecraft:oak_door[facing=north,half=lower,hinge=left,open=false,powered=false]"
      },
      {
        "char": "0",
        "block": "minecraft:oak_door[facing=north,half=upper,hinge=left,open=false,powered=false]"
      },
      {
        "char": "1",
        "block": "tfmg:asphalt"
      },
      {
        "char": "2",
        "block": "tfmg:factory_floor"
      },
      {
        "char": "3",
        "block": "tfmg:gas_lamp"
      },
      {
        "char": "4",
        "block": "tfmg:gray_rebar_concrete"
      },
      {
        "char": "5",
        "block": "the_wasteland_reworked:industrial_door[facing=south,half=lower,hinge=left,open=false,powered=false]"
      },
      {
        "char": "6",
        "block": "the_wasteland_reworked:industrial_door[facing=south,half=upper,hinge=left,open=false,powered=false]"
      },
      {
        "char": "7",
        "block": "zvhouses:spruce_bench"
      }
    ]
  }
}
