{
  "xsize": 16,
  "zsize": 16,
  "slices": [
    [
      "'''!!!!!!!!!!!!!",
      "'''!!%%%%%%%%%%%",
      "'''!!%%%%%%%%%%%",
      "'''!!%%%%%%%%%%%",
      "(('!!!!!!!!!!!!!",
      "(('!!/////////!!",
      "(('!!/////////!!",
      "(('!!/////////!!",
      "(('!!/////////!!",
      "..'!!/////////!!",
      "..'!!/////////!!",
      "..'!!/////////!!",
      "..'!!/////////!!",
      "..'!!/////////!!",
      "..'!!/////////!!",
      "..'!!/////////!!"
    ],
    [
      "   0 %%%%+%%%% $",
      "   0       $$  $",
      "   0           $",
      "   0       $$   ",
      "   0 %%%%)%%%%  ",
      "   0 %       %  ",
      "   0 %&     -%  ",
      "   0 %       %  ",
      "   0 %       %  ",
      "   0 %       %  ",
      "   0 %       %  ",
      "   0 %       %  ",
      "   0 %       %  ",
      "   0 %       %  ",
      "   0 % 1     %  ",
      "   0 %       %  "
    ],
    [
      "   0 %%%%,%%%% $",
      "   0        $  $",
      "   0           $",
      "   0        $   ",
      "   0 %%%%*%%%%  ",
      "   0 %       %  ",
      "   0 %       %  ",
      "   0 %       %  ",
      "   0 %       %  ",
      "   0 %       %  ",
      "   0 %       %  ",
      "   0 %       %  ",
      "   0 %       %  ",
      "   0 %       %  ",
      "   0 %       %  ",
      "   0 %       %  "
    ],
    [
      "   0 %%%%%%%%% $",
      "   0           $",
      "   0           $",
      "   0            ",
      "   0 %%%%%%%%%  ",
      "   0 %       %  ",
      "   0 %       %  ",
      "   0 %       %  ",
      "   0 %       %  ",
      "   0 %       %  ",
      "   0 %       %  ",
      "   0 %       %  ",
      "   0 %       %  ",
      "   0 %       %  ",
      "   0 %       %  ",
      "   0 %       %  "
    ],
    [
      "   0 %%%%%%%%% $",
      "   0           $",
      "   0           $",
      "   0            ",
      "   0 %%%%%%%%%  ",
      "   0 %       %  ",
      "   0 %       %  ",
      "   0 %       %  ",
      "   0 %       %  ",
      "   0 %       %  ",
      "   0 %       %  ",
      "   0 %       %  ",
      "   0 %       %  ",
      "   0 %       %  ",
      "   0 %       %  ",
      "   0 %       %  "
    ],
    [
      "   0           $",
      "   0           $",
      "   0           $",
      "   0            ",
      "   0            ",
      "   0            ",
      "   0            ",
      "   0            ",
      "   0            ",
      "   0            ",
      "   0            ",
      "   0            ",
      "   0            ",
      "   0            ",
      "   0            ",
      "   0            "
    ]
  ],
  "palette": {
    "palette": [
      {
        "char": "!",
        "block": "immersiveengineering:concrete"
      },
      {
        "char": "$",
        "block": "immersiveengineering:concrete_brick"
      },
      {
        "char": "%",
        "block": "immersiveengineering:concrete_tile"
      },
      {
        "char": "&",
        "block": "minecraft:barrel"
      },
      {
        "char": "'",
        "block": "minecraft:coarse_dirt"
      },
      {
        "char": "(",
        "block": "minecraft:gravel"
      },
      {
        "char": ")",
        "block": "minecraft:spruce_door[facing=north,half=lower,hinge=left,open=false,powered=false]"
      },
      {
        "char": "*",
        "block": "minecraft:spruce_door[facing=north,half=upper,hinge=left,open=false,powered=false]"
      },
      {
        "char": "+",
        "block": "minecraft:spruce_door[facing=south,half=lower,hinge=left,open=false,powered=false]"
      },
      {
        "char": ",",
        "block": "minecraft:spruce_door[facing=south,half=upper,hinge=left,open=false,powered=false]"
      },
      {
        "char": "-",
        "block": "supplementaries:item_shelf"
      },
      {
        "char": ".",
        "block": "tfmg:asphalt"
      },
      {
        "char": "/",
        "block": "tfmg:factory_floor"
      },
      {
        "char": "0",
        "block": "tfmg:gray_rebar_concrete"
      },
      {
        "char": "1",
        "block": "zvhouses:spruce_bench"
      }
    ]
  }
}
