{
  "xsize": 16,
  "zsize": 16,
  "slices": [
    [
      "****************",
      "****************",
      "))))))))))))))))",
      "$$$$$$$$$$$$$$$$",
      "''''''''''''''''",
      "''''''''''''''''",
      "''''''''''''''''",
      "''''''''''''''''",
      "''''''''''''''''",
      "''''''''''''''''",
      "''''''''''''''''",
      "''''''''''''''''",
      "''''''''''''''''",
      "''''''''''''''''",
      "''''''''''''''''",
      "''''''''''''''''"
    ],
    [
      "                ",
      "          &     ",
      "                ",
      "%%%%%....++..%%%",
      "%   %        %  ",
      "%   %        %  ",
      "%   %        %  ",
      "%   %        %  ",
      "%   %     ,, %  ",
      "%   %        %  ",
      "%%1%%        %%1",
      "%   %     ,, %  ",
      "%%(%%        %%(",
      "/   %        /  ",
      "%   %        %  ",
      "%   %        %  "
    ],
    [
      "                ",
      "          &     ",
      "                ",
      "%%!%%....++..%%!",
      "%   %        %  ",
      "%   %        %  ",
      "%   %        %  ",
      "%   %        %  ",
      "%   %        %  ",
      "%   %        %  ",
      "%%2%%        %%2",
      "%   %        %  ",
      "%% %%        %% ",
      "0%(%%        0%(",
      "%   %        %  ",
      "%   %        %  "
    ],
    [
      "                ",
      "          &     ",
      "                ",
      "%%!%%....++..%%!",
      "%   %        %  ",
      "%   %        %  ",
      "%   %        %  ",
      "%   %        %  ",
      "%   %        %  ",
      "%   %        %  ",
      "%%%%%        %%%",
      "%   %        %  ",
      "%% %%        %% ",
      "%% %%        %% ",
      "%%(%%        %%(",
      "%   %        %  "
    ],
    [
      "                ",
      "          -     ",
      "                ",
      "%%!%%........%%!",
      "%   %        %  ",
      "%   %        %  ",
      "%   %        %  ",
      "%   %        %  ",
      "%   %        %  ",
      "%   %        %  ",
      "%%%%%        %%%",
      "%   %        %  ",
      "%   %        %  ",
      "%% %%        %% ",
      "%% %%        %% ",
      "%%(%%        %%("
    ],
    [
      "                ",
      "                ",
      "                ",
      "%%%%%........%%%",
      "%   %        %  ",
      "%   %        %  ",
      "%   %        %  ",
      "%   %        %  ",
      "%   %        %  ",
      "%   %        %  ",
      "%   %        %  ",
      "%   %        %  ",
      "%   %        %  ",
      "%   %        %  ",
      "%% %%        %% ",
      "%% %%        %% "
    ]
  ],
  "palette": {
    "palette": [
      {
        "char": "!",
        "block": "create:framed_glass"
      },
      {
        "char": "$",
        "block": "immersiveengineering:concrete"
      },
      {
        "char": "%",
        "block": "immersiveengineering:concrete_brick"
      },
      {
        "char": "&",
        "block": "immersiveengineering:concrete_pillar"
      },
      {
        "char": "'",
        "block": "immersiveengineering:concrete_tile"
      },
      {
        "char": "(",
        "block": "immersiveengineering:stairs_concrete[facing=south,half=bottom,shape=straight,waterlogged=false]"
      },
      {
        "char": ")",
        "block": "minecraft:coarse_dirt"
      },
      {
        "char": "*",
        "block": "minecraft:gray_concrete"
      },
      {
        "char": "+",
        "block": "quark:white_framed_glass"
      },
      {
        "char": ",",
        "block": "supplementaries:item_shelf"
      },
      {
        "char": "-",
        "block": "tfmg:gas_lamp"
      },
      {
        "char": ".",
        "block": "tfmg:gray_rebar_concrete"
      },
      {
        "char": "/",
        "block": "the_wasteland_reworked:industrial_door[facing=east,half=lower,hinge=left,open=false,powered=false]"
      },
      {
        "char": "0",
        "block": "the_wasteland_reworked:industrial_door[facing=east,half=upper,hinge=left,open=false,powered=false]"
      },
      {
        "char": "1",
        "block": "the_wasteland_reworked:industrial_door[facing=south,half=lower,hinge=left,open=false,powered=false]"
      },
      {
        "char": "2",
        "block": "the_wasteland_reworked:industrial_door[facing=south,half=upper,hinge=left,open=false,powered=false]"
      }
    ]
  }
}
