{
  "xsize": 16,
  "zsize": 16,
  "slices": [
    [
      "!%%%!!!!%%%!!!!!",
      "%%%%%%%%%%%%%%%%",
      "%%%%%%%%%%%%%%%%",
      "%%%%%%%%%%%%%%%%",
      "!!!!!!!!!!!!!!!!",
      "!!!!!!!!!!!!!...",
      "!!!!!!!!!!!!!...",
      "!!!!!!!!!!!!!...",
      "!!!!!!!!!!!!!...",
      "!!!!!!!!!!!!!...",
      "!!!!!!!!!!!!!...",
      "!!!!!!!!!!!!!...",
      "!!!!!!!!!!!!!...",
      "!!!!!!!!!!!!!...",
      "!!!!!!!!!!!!!...",
      "!!!!!!!!!!!!!..."
    ],
    [
      "%  (%  $   $ %%+",
      "%   %  $   $    ",
      "       $   $    ",
      "                ",
      "             %%)",
      "             %  ",
      "             %' ",
      "             %  ",
      "             %  ",
      "             %  ",
      "             %  ",
      "             %  ",
      "             %  ",
      "             %  ",
      "             % /",
      "             %  "
    ],
    [
      "%   %  $   $ %%,",
      "%   %  $   $    ",
      "       $   $    ",
      "                ",
      "             %%*",
      "             %  ",
      "             %  ",
      "             %  ",
      "             %  ",
      "             %  ",
      "             %  ",
      "             %  ",
      "             %  ",
      "             %  ",
      "             %  ",
      "             %  "
    ],
    [
      "%-  %  $   $ %%%",
      "%   %  $   $    ",
      "       $   $    ",
      "                ",
      "             %%%",
      "             %  ",
      "             %  ",
      "             %  ",
      "             %  ",
      "             %  ",
      "             %  ",
      "             %  ",
      "             %  ",
      "             %  ",
      "             %  ",
      "             %  "
    ],
    [
      "%   %  $   $ %%%",
      "%   %  $   $    ",
      "       $   $    ",
      "                ",
      "             %%%",
      "             %  ",
      "             %  ",
      "             %  ",
      "             %  ",
      "             %  ",
      "             %  ",
      "             %  ",
      "             %  ",
      "             %  ",
      "             %  ",
      "             %  "
    ],
    [
      "       $$&$$    ",
      "       $   $    ",
      "       $   $    ",
      "                ",
      "                ",
      "                ",
      "                ",
      "                ",
      "                ",
      "                ",
      "                ",
      "                ",
      "                ",
      "                ",
      "                ",
      "                "
    ]
  ],
  "palette": {
    "palette": [
      {
        "char": "!",
        "block": "immersiveengineering:concrete"
      },
      {
        "char": "$",
        "block": "immersiveengineering:concrete_brick"
      },
      {
        "char": "%",
        "block": "immersiveengineering:concrete_tile"
      },
      {
        "char": "&",
        "block": "immersiveengineering:stairs_concrete[facing=south,half=bottom,shape=straight,waterlogged=false]"
      },
      {
        "char": "'",
        "block": "minecraft:barrel"
      },
      {
        "char": "(",
        "block": "minecraft:bookshelf"
      },
      {
        "char": ")",
        "block": "minecraft:spruce_door[facing=north,half=lower,hinge=left,open=false,powered=false]"
      },
      {
        "char": "*",
        "block": "minecraft:spruce_door[facing=north,half=upper,hinge=left,open=false,powered=false]"
      },
      {
        "char": "+",
        "block": "minecraft:spruce_door[facing=south,half=lower,hinge=left,open=false,powered=false]"
      },
      {
        "char": ",",
        "block": "minecraft:spruce_door[facing=south,half=upper,hinge=left,open=false,powered=false]"
      },
      {
        "char": "-",
        "block": "tfmg:circular_light"
      },
      {
        "char": ".",
        "block": "tfmg:factory_floor"
      },
      {
        "char": "/",
        "block": "zvhouses:spruce_bench"
      }
    ]
  }
}
