{
  "xsize": 16,
  "zsize": 16,
  "slices": [
    [
      "                ",
      "%%((((%((((%((((",
      "((((((((((((((((",
      "((((((((((((((%%",
      "((((((((((((%%$(",
      "((((((((((%%$(((",
      "((((((((%%$(((((",
      "((((((%%$(((((((",
      "((((%%$(((((((((",
      "((%%$(((((((((((",
      "%%$(((((((((((((",
      "((((((((((((((((",
      "((((((((((((((((",
      "((((((((((((((((",
      "((((((((((((((((",
      "(((((((((((((((("
    ],
    [
      "                ",
      "                ",
      "                ",
      ")))             ",
      ")))             ",
      ")))             ",
      ")))             ",
      ")))             ",
      ")))             ",
      ")))   *    *    ",
      "                ",
      " '''''          ",
      " '''''          ",
      " '''''          ",
      " '''''          ",
      "                "
    ],
    [
      "                ",
      "                ",
      "                ",
      "+++             ",
      "  +             ",
      "&&+             ",
      "&&+             ",
      "&&+             ",
      ", +             ",
      "+++             ",
      "                ",
      " '''''          ",
      " '''''          ",
      " '''''          ",
      " '''''          ",
      "                "
    ],
    [
      "                ",
      "                ",
      "                ",
      "+++             ",
      "  +             ",
      "&&+             ",
      "&&+             ",
      "&&+             ",
      "  +             ",
      "+++             ",
      "                ",
      " '''''          ",
      " '''''          ",
      " '''''          ",
      " '''''          ",
      "                "
    ],
    [
      "                ",
      "                ",
      "                ",
      "+++             ",
      "  +             ",
      "&&+             ",
      "&&+             ",
      "&&+             ",
      "  +             ",
      "!!+             ",
      "                ",
      "                ",
      "                ",
      "                ",
      "                ",
      "                "
    ],
    [
      "                ",
      "                ",
      "                ",
      "+++             ",
      "  +             ",
      "  +             ",
      "  +             ",
      "  +             ",
      "  +             ",
      "!!+             ",
      "                ",
      "                ",
      "                ",
      "                ",
      "                ",
      "                "
    ]
  ],
  "palette": {
    "palette": [
      {
        "char": "!",
        "block": "create:framed_glass"
      },
      {
        "char": "$",
        "block": "minecraft:coarse_dirt"
      },
      {
        "char": "%",
        "block": "minecraft:gravel"
      },
      {
        "char": "&",
        "block": "minecraft:scaffolding"
      },
      {
        "char": "'",
        "block": "minecraft:yellow_concrete"
      },
      {
        "char": "(",
        "block": "tfmg:asphalt"
      },
      {
        "char": ")",
        "block": "tfmg:factory_floor"
      },
      {
        "char": "*",
        "block": "the_wasteland_reworked:barricade"
      },
      {
        "char": "+",
        "block": "the_wasteland_reworked:cut_lead_plating"
      },
      {
        "char": ",",
        "block": "the_wasteland_reworked:radio"
      }
    ]
  }
}
