{
  "xsize": 16,
  "zsize": 16,
  "slices": [
    [
      "/////////////   ",
      "/////////////   ",
      "/////////////   ",
      "/////////////   ",
      "//$$!///////    ",
      "$$!////////$    ",
      "!///////////    ",
      "////////////    ",
      "////////////    ",
      "///////////$    ",
      "/////////$$!    ",
      "///////$$!/$    ",
      "/////$$!////    ",
      "!//$$!////!/    ",
      "                ",
      "                "
    ],
    [
      "                ",
      "                ",
      "                ",
      "                ",
      "   ,            ",
      "111111111 2     ",
      "111111111       ",
      "111111111       ",
      "111111111       ",
      "111111111       ",
      "111111111       ",
      "111111111       ",
      "111111111       ",
      "                ",
      "                ",
      "                "
    ],
    [
      "                ",
      "                ",
      "                ",
      "                ",
      "   ,            ",
      ")++++++++       ",
      "   0    +       ",
      "   0    +       ",
      "   -    +       ",
      " & ' &  +       ",
      " % 0 %  +       ",
      "   0    +       ",
      "+++++++++       ",
      "                ",
      "                ",
      "                "
    ],
    [
      "                ",
      "                ",
      "                ",
      "                ",
      "   ,            ",
      "*++++++++       ",
      "   0    +       ",
      "   0    +       ",
      "   .    +       ",
      "   (    +       ",
      "   0    +       ",
      "   0    +       ",
      "+++++++++       ",
      "                ",
      "                ",
      "                "
    ],
    [
      "                ",
      "                ",
      "                ",
      "                ",
      "   ,            ",
      "+++++++++       ",
      "   0    +       ",
      "   0    +       ",
      "   0    +       ",
      "   0    +       ",
      "   0    +       ",
      "   0    +       ",
      "+++++++++       ",
      "                ",
      "                ",
      "                "
    ],
    [
      "                ",
      "                ",
      "                ",
      "                ",
      "   ,            ",
      "+++++++++       ",
      "   0    +       ",
      "   0    +       ",
      "   0    +       ",
      "   0    +       ",
      "   0    +       ",
      "   0    +       ",
      "+++++++++       ",
      "                ",
      "                ",
      "                "
    ]
  ],
  "palette": {
    "palette": [
      {
        "char": "!",
        "block": "minecraft:coarse_dirt"
      },
      {
        "char": "$",
        "block": "minecraft:gravel"
      },
      {
        "char": "%",
        "block": "minecraft:gray_bed[facing=north,occupied=false,part=foot]"
      },
      {
        "char": "&",
        "block": "minecraft:gray_bed[facing=north,occupied=false,part=head]"
      },
      {
        "char": "'",
        "block": "minecraft:iron_door[facing=east,half=lower,hinge=left,open=false,powered=false]"
      },
      {
        "char": "(",
        "block": "minecraft:iron_door[facing=east,half=upper,hinge=left,open=false,powered=false]"
      },
      {
        "char": ")",
        "block": "minecraft:iron_door[facing=north,half=lower,hinge=right,open=false,powered=false]"
      },
      {
        "char": "*",
        "block": "minecraft:iron_door[facing=north,half=upper,hinge=right,open=false,powered=false]"
      },
      {
        "char": "+",
        "block": "minecraft:mud_bricks"
      },
      {
        "char": ",",
        "block": "minecraft:polished_blackstone_bricks"
      },
      {
        "char": "-",
        "block": "minecraft:spruce_door[facing=east,half=lower,hinge=left,open=false,powered=false]"
      },
      {
        "char": ".",
        "block": "minecraft:spruce_door[facing=east,half=upper,hinge=left,open=false,powered=false]"
      },
      {
        "char": "/",
        "block": "tfmg:asphalt"
      },
      {
        "char": "0",
        "block": "tfmg:cinder_block"
      },
      {
        "char": "1",
        "block": "tfmg:factory_floor"
      },
      {
        "char": "2",
        "block": "the_wasteland_reworked:barricade"
      }
    ]
  }
}
