{
  "xsize": 16,
  "zsize": 16,
  "slices": [
    [
      "                ",
      "                ",
      "                ",
      "&&&             ",
      "  &             ",
      "  &             ",
      "  &             ",
      "  &             ",
      "  &             ",
      "&&&             ",
      "                ",
      "                ",
      "                ",
      "                ",
      "                ",
      "                "
    ],
    [
      "                ",
      "                ",
      "                ",
      "&&&             ",
      "  &             ",
      "  &             ",
      "  &             ",
      "  &             ",
      "  &             ",
      "&&&             ",
      "                ",
      "                ",
      "                ",
      "                ",
      "                ",
      "                "
    ],
    [
      "                ",
      "                ",
      "                ",
      "&&&             ",
      "  &             ",
      "  &             ",
      "  &             ",
      "  &             ",
      "  &             ",
      "&&&             ",
      "                ",
      "                ",
      "                ",
      "                ",
      "                ",
      "                "
    ],
    [
      "                ",
      "                ",
      "                ",
      "&&&             ",
      "  &             ",
      "  &             ",
      "  &             ",
      "  &             ",
      "  &             ",
      "&&&             ",
      "!!!!!!!!!!!!!!!!",
      "!!!!!!!!!!!!!!!!",
      "!!!!!!!!!!!!!!!!",
      "!!!!!!!!!!!!!!!!",
      "!!!!!!!!!!!!!!!!",
      "!!!!!!!!!!!!!!!!"
    ],
    [
      "                ",
      "                ",
      "                ",
      "%%%             ",
      "%%%             ",
      "%%%             ",
      "%%%             ",
      "%%%             ",
      "%%%             ",
      "%%%             ",
      "                ",
      "                ",
      "                ",
      "   %%%%%%%      ",
      "   %%%%%%%      ",
      "   %%%%%%%      "
    ],
    [
      "                ",
      "                ",
      "                ",
      "                ",
      "                ",
      "                ",
      "                ",
      "                ",
      "                ",
      "                ",
      "                ",
      "                ",
      "                ",
      "   $$   $$      ",
      "   $     $      ",
      "   $  '  $      "
    ]
  ],
  "palette": {
    "palette": [
      {
        "char": "!",
        "block": "immersiveengineering:sheetmetal_steel"
      },
      {
        "char": "$",
        "block": "minecraft:polished_blackstone_bricks"
      },
      {
        "char": "%",
        "block": "minecraft:smooth_stone"
      },
      {
        "char": "&",
        "block": "the_wasteland_reworked:cut_lead_plating"
      },
      {
        "char": "'",
        "block": "the_wasteland_reworked:radio"
      }
    ]
  }
}
