{
  "xsize": 16,
  "zsize": 16,
  "slices": [
    [
      "  1    1    1  3",
      "  1    1    1  3",
      "  1    1    1  3",
      "  1    1    1  3",
      "               3",
      "               3",
      "               3",
      "               3",
      "               3",
      "  1    1    1  3",
      "  1    1    1  3",
      "  1    1    1  3",
      "  1    1    1  3",
      "  1    1    1  3",
      "  1    1    1  3",
      "  1    1    1  3"
    ],
    [
      "---------------3",
      "---------------3",
      "---------------3",
      "---------------3",
      "---------------3",
      "---------------3",
      "---------------3",
      "---------------3",
      "---------------3",
      "---------------3",
      "---------------3",
      "---------------3",
      "---------------3",
      "---------------3",
      "---------------3",
      "---------------3"
    ],
    [
      "  111/1111/11113",
      "  1 %  1 %  1  3",
      "  1 $ !1 $ !1  3",
      "  1    1    1  3",
      "  111/1111/11113",
      "             113",
      "             (!3",
      "             113",
      "& 111/1111/11113",
      "  1    1    1  3",
      "  1 * !1 * !1  3",
      " ,1 +  1 +  1  3",
      "  1    1    1  3",
      "  111/1111/11113",
      "  1    1    1  3",
      "  1 2 .1 2 .1  3"
    ],
    [
      "  11101111011113",
      "  1    1    1  3",
      "  1    1    1  3",
      "  1    1    1  3",
      "  11101111011113",
      "             113",
      "             )13",
      "             113",
      "' 11101111011113",
      "  1    1    1  3",
      "  1    1    1  3",
      "  1    1    1  3",
      "  1    1    1  3",
      "  11101111011113",
      "  1    1    1  3",
      "  1    1    1  3"
    ],
    [
      "  11111111111113",
      "  1    1    1  3",
      "  1    1    1  3",
      "  1    1    1  3",
      "  11111111111113",
      "             113",
      "             113",
      "             113",
      "  11111111111113",
      "  1    1    1  3",
      "  1    1    1  3",
      "  1    1    1  3",
      "  1    1    1  3",
      "  11111111111113",
      "  1    1    1  3",
      "  1    1    1  3"
    ],
    [
      "  11111111111113",
      "  1    1    1  3",
      "  1    1    1  3",
      "  1    1    1  3",
      "  11111111111113",
      "             113",
      "             113",
      "             113",
      "  11111111111113",
      "  1    1    1  3",
      "  1    1    1  3",
      "  1    1    1  3",
      "  1    1    1  3",
      "  11111111111113",
      "  1    1    1  3",
      "  1    1    1  3"
    ]
  ],
  "palette": {
    "palette": [
      {
        "char": "!",
        "block": "minecraft:barrel[facing=up,open=false]"
      },
      {
        "char": "$",
        "block": "minecraft:brown_bed[facing=north,occupied=false,part=foot]"
      },
      {
        "char": "%",
        "block": "minecraft:brown_bed[facing=north,occupied=false,part=head]"
      },
      {
        "char": "&",
        "block": "minecraft:dark_oak_door[facing=south,half=lower,hinge=right,open=false,powered=false]"
      },
      {
        "char": "'",
        "block": "minecraft:dark_oak_door[facing=south,half=upper,hinge=right,open=false,powered=false]"
      },
      {
        "char": "(",
        "block": "minecraft:dark_oak_door[facing=west,half=lower,hinge=left,open=false,powered=false]"
      },
      {
        "char": ")",
        "block": "minecraft:dark_oak_door[facing=west,half=upper,hinge=left,open=false,powered=false]"
      },
      {
        "char": "*",
        "block": "minecraft:gray_bed[facing=south,occupied=false,part=foot]"
      },
      {
        "char": "+",
        "block": "minecraft:gray_bed[facing=south,occupied=false,part=head]"
      },
      {
        "char": ",",
        "block": "minecraft:loom"
      },
      {
        "char": "-",
        "block": "minecraft:oak_planks"
      },
      {
        "char": ".",
        "block": "minecraft:quartz_stairs[facing=south,half=bottom,shape=straight,waterlogged=false]"
      },
      {
        "char": "/",
        "block": "minecraft:spruce_door[facing=south,half=lower,hinge=left,open=false,powered=false]"
      },
      {
        "char": "0",
        "block": "minecraft:spruce_door[facing=south,half=upper,hinge=left,open=false,powered=false]"
      },
      {
        "char": "1",
        "block": "minecraft:stripped_oak_wood"
      },
      {
        "char": "2",
        "block": "minecraft:water_cauldron[level=1]"
      },
      {
        "char": "3",
        "block": "minecraft:yellow_terracotta"
      }
    ]
  }
}
