{
  "xsize": 16,
  "zsize": 16,
  "slices": [
    [
      "%999999999999999",
      "999999999999999(",
      "9999999999999((%",
      "99999999999((%99",
      "999999999((%9999",
      "9999)))))%999999",
      "9999)))))9999999",
      "999()))))9999999",
      "9((%)))))9999999",
      "(%99)))))9999999",
      "9999999999999999",
      "99999999999999((",
      "999999999999((%9",
      "9999999999((%999",
      "99999999((%99999",
      "999999((%9999999"
    ],
    [
      "              --",
      "          3   --",
      "              --",
      "              --",
      "   ------- +++++",
      "   -66666- +++++",
      "   -66666- +++++",
      "   -66666- +++++",
      "   -66666- +++++",
      "   -66666- +++++",
      "   ------- +++++",
      "           +++++",
      "   +++++++++++++",
      "   +++++++++++++",
      "   +++++++++++++",
      "   +++++++++++++"
    ],
    [
      "                ",
      "          3     ",
      "                ",
      "                ",
      "           88883",
      "           8   3",
      "           8 '  ",
      "           8   '",
      "           8 &&&",
      "           8 4  ",
      "           8//  ",
      "   * // * //14$ ",
      "   **********4**",
      "   8    4    4  ",
      "   8 7 ,4 7 ,4  ",
      "   8    4    4  "
    ],
    [
      "                ",
      "          3     ",
      "                ",
      "                ",
      "           88883",
      "           8   3",
      "           8    ",
      "           8    ",
      "           8  :'",
      "           8 4  ",
      "           8 .  ",
      "   *    *  8 4  ",
      "   85!!585!!5488",
      "   8    4    4  ",
      "   8    4    4  ",
      "   8    4    4  "
    ],
    [
      "                ",
      "          3     ",
      "                ",
      "                ",
      "           88883",
      "           8   3",
      "           8    ",
      "           8    ",
      "           8    ",
      "           8 4 '",
      "           8 4  ",
      "   *    *  8 4  ",
      "   85!!585!!5488",
      "   8    4    4  ",
      "   8    4    4  ",
      "   8    4    4  "
    ],
    [
      "                ",
      "          3     ",
      "                ",
      "                ",
      "           88882",
      "           8   2",
      "           8    ",
      "           8    ",
      "           8    ",
      "           8 4  ",
      "           8 4 '",
      "   * 00 * 00 4  ",
      "   8888888888488",
      "   8    4    4  ",
      "   8    4    4  ",
      "   8    4    4  "
    ]
  ],
  "palette": {
    "palette": [
      {
        "char": "!",
        "block": "create:framed_glass"
      },
      {
        "char": "$",
        "block": "minecraft:barrel[facing=up,open=false]"
      },
      {
        "char": "%",
        "block": "minecraft:coarse_dirt"
      },
      {
        "char": "&",
        "block": "minecraft:dark_oak_slab[type=bottom,waterlogged=false]"
      },
      {
        "char": "'",
        "block": "minecraft:dark_oak_stairs[facing=south,half=bottom,shape=straight,waterlogged=false]"
      },
      {
        "char": "(",
        "block": "minecraft:gravel"
      },
      {
        "char": ")",
        "block": "minecraft:light_blue_concrete"
      },
      {
        "char": "*",
        "block": "minecraft:mud_bricks"
      },
      {
        "char": "+",
        "block": "minecraft:oak_planks"
      },
      {
        "char": ",",
        "block": "minecraft:quartz_stairs[facing=north,half=bottom,shape=straight,waterlogged=false]"
      },
      {
        "char": "-",
        "block": "minecraft:smooth_stone"
      },
      {
        "char": ".",
        "block": "minecraft:spruce_door[facing=east,half=upper,hinge=left,open=false,powered=false]"
      },
      {
        "char": "/",
        "block": "minecraft:spruce_slab[type=bottom,waterlogged=false]"
      },
      {
        "char": "0",
        "block": "minecraft:spruce_slab[type=top,waterlogged=false]"
      },
      {
        "char": "1",
        "block": "minecraft:spruce_stairs[facing=north,half=bottom,shape=straight,waterlogged=false]"
      },
      {
        "char": "2",
        "block": "minecraft:stripped_dark_oak_log[axis=x]"
      },
      {
        "char": "3",
        "block": "minecraft:stripped_dark_oak_log[axis=y]"
      },
      {
        "char": "4",
        "block": "minecraft:stripped_oak_wood"
      },
      {
        "char": "5",
        "block": "minecraft:stripped_spruce_log[axis=y]"
      },
      {
        "char": "6",
        "block": "minecraft:water"
      },
      {
        "char": "7",
        "block": "minecraft:water_cauldron[level=1]"
      },
      {
        "char": "8",
        "block": "minecraft:yellow_terracotta"
      },
      {
        "char": "9",
        "block": "tfmg:asphalt"
      },
      {
        "char": ":",
        "block": "the_wasteland_reworked:radio"
      }
    ]
  }
}
