{
  "xsize": 16,
  "zsize": 16,
  "slices": [
    [
      "   3    1    1  ",
      "   3    1    1  ",
      "   3    1    1  ",
      "   3    1    1  ",
      "   3            ",
      "   3            ",
      "   3            ",
      "   3            ",
      "   3            ",
      "   3    1    1  ",
      "   3    1    1  ",
      "   3    1    1  ",
      "   3    1    1  ",
      "   3    1    1  ",
      "   3    1    1  ",
      "   3    1    1  "
    ],
    [
      "  *3------------",
      "  *3------------",
      "  *3------------",
      "  *3------------",
      "  *3------------",
      "  *3------------",
      "  *3------------",
      "  *3------------",
      "  *3------------",
      "  *3------------",
      "  *3------------",
      "  *3------------",
      "  *3------------",
      "  *3------------",
      "  *3------------",
      "  *3------------"
    ],
    [
      "   311/1111/11  ",
      "   3 %  1 %  1  ",
      "   3 $ !1 $ !1  ",
      "   3    1    1  ",
      "   311/1111/11  ",
      "   311          ",
      "   3!&          ",
      "   311          ",
      "   311/1111/11 (",
      "   3    1    1  ",
      "   3 + !1 + !1  ",
      "   3 ,  1 ,  1! ",
      "   3    1    1  ",
      "   311/1111/11  ",
      "   3    1    1  ",
      "   3 2 .1 2 .1  "
    ],
    [
      "   31101111011  ",
      "   3    1    1  ",
      "   3    1    1  ",
      "   3    1    1  ",
      "   31101111011  ",
      "   341          ",
      "   31'          ",
      "   311          ",
      "   31101111011 )",
      "   3    1    1  ",
      "   3    1    1  ",
      "   3    1    1  ",
      "   3    1    1  ",
      "   31101111011  ",
      "   3    1    1  ",
      "   3    1    1  "
    ],
    [
      "   31111111111  ",
      "   3    1    1  ",
      "   3    1    1  ",
      "   3    1    1  ",
      "   31111111111  ",
      "   311          ",
      "   311          ",
      "   311          ",
      "   31111111111  ",
      "   3    1    1  ",
      "   3    1    1  ",
      "   3    1    1  ",
      "   3    1    1  ",
      "   31111111111  ",
      "   3    1    1  ",
      "   3    1    1  "
    ],
    [
      "   31111111111  ",
      "   3    1    1  ",
      "   3    1    1  ",
      "   3    1    1  ",
      "   31111111111  ",
      "   311          ",
      "   311          ",
      "   311          ",
      "   31111111111  ",
      "   3    1    1  ",
      "   3    1    1  ",
      "   3    1    1  ",
      "   3    1    1  ",
      "   31111111111  ",
      "   3    1    1  ",
      "   3    1    1  "
    ]
  ],
  "palette": {
    "palette": [
      {
        "char": "!",
        "block": "minecraft:barrel[facing=up,open=false]"
      },
      {
        "char": "$",
        "block": "minecraft:brown_bed[facing=north,occupied=false,part=foot]"
      },
      {
        "char": "%",
        "block": "minecraft:brown_bed[facing=north,occupied=false,part=head]"
      },
      {
        "char": "&",
        "block": "minecraft:dark_oak_door[facing=east,half=lower,hinge=left,open=false,powered=false]"
      },
      {
        "char": "'",
        "block": "minecraft:dark_oak_door[facing=east,half=upper,hinge=left,open=false,powered=false]"
      },
      {
        "char": "(",
        "block": "minecraft:dark_oak_door[facing=south,half=lower,hinge=left,open=false,powered=false]"
      },
      {
        "char": ")",
        "block": "minecraft:dark_oak_door[facing=south,half=upper,hinge=left,open=false,powered=false]"
      },
      {
        "char": "*",
        "block": "minecraft:dark_oak_slab[type=bottom,waterlogged=false]"
      },
      {
        "char": "+",
        "block": "minecraft:gray_bed[facing=south,occupied=false,part=foot]"
      },
      {
        "char": ",",
        "block": "minecraft:gray_bed[facing=south,occupied=false,part=head]"
      },
      {
        "char": "-",
        "block": "minecraft:oak_planks"
      },
      {
        "char": ".",
        "block": "minecraft:quartz_stairs[facing=south,half=bottom,shape=straight,waterlogged=false]"
      },
      {
        "char": "/",
        "block": "minecraft:spruce_door[facing=south,half=lower,hinge=left,open=false,powered=false]"
      },
      {
        "char": "0",
        "block": "minecraft:spruce_door[facing=south,half=upper,hinge=left,open=false,powered=false]"
      },
      {
        "char": "1",
        "block": "minecraft:stripped_oak_wood"
      },
      {
        "char": "2",
        "block": "minecraft:water_cauldron[level=1]"
      },
      {
        "char": "3",
        "block": "minecraft:yellow_terracotta"
      },
      {
        "char": "4",
        "block": "supplementaries:item_shelf"
      }
    ]
  }
}
