{
  "xsize": 16,
  "zsize": 16,
  "slices": [
    [
      "6666++&666666666",
      "66++&66666666666",
      "++&6666666666666",
      "&666666666666666",
      "666666666666666+",
      "6666666666666++&",
      "66666666666++&66",
      "666666666++&6666",
      "6666666++&666666",
      "66666++&66666666",
      "666++&6666666666",
      "6++&666666666666",
      "+&66666666666666",
      "6666666666666666",
      "66666666666666++",
      "666666666666++&6"
    ],
    [
      "   .............",
      "   .............",
      "   .............",
      "   .............",
      "   .............",
      "   .............",
      "   .............",
      "   .............",
      "   .............",
      "   .............",
      "   .............",
      "   .............",
      "   .............",
      "   .............",
      "   .............",
      "   ............."
    ],
    [
      "   42202222022  ",
      "   4 %  2 %  2  ",
      "   4 $ !2 $ !2  ",
      "   4    2    2  ",
      "   42202222022  ",
      "   422          ",
      "   4!'          ",
      "   422          ",
      "   42202222022 )",
      "   4    2    2  ",
      "   4 , !2 , !2  ",
      "   4 -  2 -  2! ",
      "   4    2    2  ",
      "   42202222022  ",
      "   4    2    2  ",
      "   4 3 /2 3 /2  "
    ],
    [
      "   42212222122  ",
      "   4    2    2  ",
      "   4    2    2  ",
      "   4    2    2  ",
      "   42212222122  ",
      "   452          ",
      "   42(          ",
      "   422          ",
      "   42212222122 *",
      "   4    2    2  ",
      "   4    2    2  ",
      "   4    2    2  ",
      "   4    2    2  ",
      "   42212222122  ",
      "   4    2    2  ",
      "   4    2    2  "
    ],
    [
      "   42222222222  ",
      "   4    2    2  ",
      "   4    2    2  ",
      "   4    2    2  ",
      "   42222222222  ",
      "   422          ",
      "   422          ",
      "   422          ",
      "   42222222222  ",
      "   4    2    2  ",
      "   4    2    2  ",
      "   4    2    2  ",
      "   4    2    2  ",
      "   42222222222  ",
      "   4    2    2  ",
      "   4    2    2  "
    ],
    [
      "   42222222222  ",
      "   4    2    2  ",
      "   4    2    2  ",
      "   4    2    2  ",
      "   42222222222  ",
      "   422          ",
      "   422          ",
      "   422          ",
      "   42222222222  ",
      "   4    2    2  ",
      "   4    2    2  ",
      "   4    2    2  ",
      "   4    2    2  ",
      "   42222222222  ",
      "   4    2    2  ",
      "   4    2    2  "
    ]
  ],
  "palette": {
    "palette": [
      {
        "char": "!",
        "block": "minecraft:barrel[facing=up,open=false]"
      },
      {
        "char": "$",
        "block": "minecraft:brown_bed[facing=north,occupied=false,part=foot]"
      },
      {
        "char": "%",
        "block": "minecraft:brown_bed[facing=north,occupied=false,part=head]"
      },
      {
        "char": "&",
        "block": "minecraft:coarse_dirt"
      },
      {
        "char": "'",
        "block": "minecraft:dark_oak_door[facing=east,half=lower,hinge=left,open=false,powered=false]"
      },
      {
        "char": "(",
        "block": "minecraft:dark_oak_door[facing=east,half=upper,hinge=left,open=false,powered=false]"
      },
      {
        "char": ")",
        "block": "minecraft:dark_oak_door[facing=south,half=lower,hinge=left,open=false,powered=false]"
      },
      {
        "char": "*",
        "block": "minecraft:dark_oak_door[facing=south,half=upper,hinge=left,open=false,powered=false]"
      },
      {
        "char": "+",
        "block": "minecraft:gravel"
      },
      {
        "char": ",",
        "block": "minecraft:gray_bed[facing=south,occupied=false,part=foot]"
      },
      {
        "char": "-",
        "block": "minecraft:gray_bed[facing=south,occupied=false,part=head]"
      },
      {
        "char": ".",
        "block": "minecraft:oak_planks"
      },
      {
        "char": "/",
        "block": "minecraft:quartz_stairs[facing=south,half=bottom,shape=straight,waterlogged=false]"
      },
      {
        "char": "0",
        "block": "minecraft:spruce_door[facing=south,half=lower,hinge=left,open=false,powered=false]"
      },
      {
        "char": "1",
        "block": "minecraft:spruce_door[facing=south,half=upper,hinge=left,open=false,powered=false]"
      },
      {
        "char": "2",
        "block": "minecraft:stripped_oak_wood"
      },
      {
        "char": "3",
        "block": "minecraft:water_cauldron[level=1]"
      },
      {
        "char": "4",
        "block": "minecraft:yellow_terracotta"
      },
      {
        "char": "5",
        "block": "supplementaries:item_shelf"
      },
      {
        "char": "6",
        "block": "tfmg:asphalt"
      }
    ]
  }
}
