{
  "xsize": 16,
  "zsize": 16,
  "slices": [
    [
      "6666666++&666666",
      "66666++&66666666",
      "666++&6666666666",
      "6++&666666666666",
      "+&66666666666666",
      "6666666666666666",
      "66666666666666++",
      "666666666666++&6",
      "6666666666++&666",
      "66666666++&66666",
      "666666++&6666666",
      "6666++&666666666",
      "66++&66666666666",
      "++&6666666666666",
      "&666666666666666",
      "666666666666666+"
    ],
    [
      "////////////////",
      "////////////////",
      "////////////////",
      "////////////////",
      "////////////////",
      "////////////////",
      "////////////////",
      "////////////////",
      "////////////////",
      "////////////////",
      "////////////////",
      "////////////////",
      "////////////////",
      "////////////////",
      "////////////////",
      "////////////////"
    ],
    [
      "  33313333133335",
      "  3 %  3 %  3  5",
      "  3 $ !3 $ !3  5",
      "  3    3    3  5",
      "  33313333133335",
      "             335",
      "             )!5",
      "             335",
      "' 33313333133335",
      "  3    3    3  5",
      "  3 , !3 , !3  5",
      " .3 -  3 -  3  5",
      "  3    3    3  5",
      "  33313333133335",
      "  3    3    3  5",
      "  3 4 03 4 03  5"
    ],
    [
      "  33323333233335",
      "  3    3    3  5",
      "  3    3    3  5",
      "  3    3    3  5",
      "  33323333233335",
      "             335",
      "             *35",
      "             335",
      "( 33323333233335",
      "  3    3    3  5",
      "  3    3    3  5",
      "  3    3    3  5",
      "  3    3    3  5",
      "  33323333233335",
      "  3    3    3  5",
      "  3    3    3  5"
    ],
    [
      "  33333333333335",
      "  3    3    3  5",
      "  3    3    3  5",
      "  3    3    3  5",
      "  33333333333335",
      "             335",
      "             335",
      "             335",
      "  33333333333335",
      "  3    3    3  5",
      "  3    3    3  5",
      "  3    3    3  5",
      "  3    3    3  5",
      "  33333333333335",
      "  3    3    3  5",
      "  3    3    3  5"
    ],
    [
      "  33333333333335",
      "  3    3    3  5",
      "  3    3    3  5",
      "  3    3    3  5",
      "  33333333333335",
      "             335",
      "             335",
      "             335",
      "  33333333333335",
      "  3    3    3  5",
      "  3    3    3  5",
      "  3    3    3  5",
      "  3    3    3  5",
      "  33333333333335",
      "  3    3    3  5",
      "  3    3    3  5"
    ]
  ],
  "palette": {
    "palette": [
      {
        "char": "!",
        "block": "minecraft:barrel[facing=up,open=false]"
      },
      {
        "char": "$",
        "block": "minecraft:brown_bed[facing=north,occupied=false,part=foot]"
      },
      {
        "char": "%",
        "block": "minecraft:brown_bed[facing=north,occupied=false,part=head]"
      },
      {
        "char": "&",
        "block": "minecraft:coarse_dirt"
      },
      {
        "char": "'",
        "block": "minecraft:dark_oak_door[facing=south,half=lower,hinge=right,open=false,powered=false]"
      },
      {
        "char": "(",
        "block": "minecraft:dark_oak_door[facing=south,half=upper,hinge=right,open=false,powered=false]"
      },
      {
        "char": ")",
        "block": "minecraft:dark_oak_door[facing=west,half=lower,hinge=left,open=false,powered=false]"
      },
      {
        "char": "*",
        "block": "minecraft:dark_oak_door[facing=west,half=upper,hinge=left,open=false,powered=false]"
      },
      {
        "char": "+",
        "block": "minecraft:gravel"
      },
      {
        "char": ",",
        "block": "minecraft:gray_bed[facing=south,occupied=false,part=foot]"
      },
      {
        "char": "-",
        "block": "minecraft:gray_bed[facing=south,occupied=false,part=head]"
      },
      {
        "char": ".",
        "block": "kubejs:ruined_loom"
      },
      {
        "char": "/",
        "block": "minecraft:oak_planks"
      },
      {
        "char": "0",
        "block": "minecraft:quartz_stairs[facing=south,half=bottom,shape=straight,waterlogged=false]"
      },
      {
        "char": "1",
        "block": "minecraft:spruce_door[facing=south,half=lower,hinge=left,open=false,powered=false]"
      },
      {
        "char": "2",
        "block": "minecraft:spruce_door[facing=south,half=upper,hinge=left,open=false,powered=false]"
      },
      {
        "char": "3",
        "block": "minecraft:stripped_oak_wood"
      },
      {
        "char": "4",
        "block": "kubejs:ruined_cauldron"
      },
      {
        "char": "5",
        "block": "minecraft:yellow_terracotta"
      },
      {
        "char": "6",
        "block": "tfmg:asphalt"
      }
    ]
  }
}
