{
  "xsize": 16,
  "zsize": 16,
  "slices": [
    [
      "///////////,,   ",
      "///////////((   ",
      "/////////(('/   ",
      "///////(('/,,   ",
      "/////(('///,,   ",
      "///(('/////,,   ",
      "/(('/////////   ",
      "('///////////   ",
      "///////////,,   ",
      "///////////,,   ",
      "///////////,,   ",
      "//////////(('   ",
      "////////(('//   ",
      "//////(('//,,   ",
      "////(('////,,   ",
      "//(('//////,,   "
    ],
    [
      "++++++++  $,,   ",
      "++++++++  $     ",
      "++++++++  $     ",
      "++++++++  $,,   ",
      "++++++++  $,,   ",
      "++++++++  $,,   ",
      "++++++++  $     ",
      "++++++++  $     ",
      "++++++++  $,,   ",
      "++++++++  $,,   ",
      "++++++++  $,,   ",
      "++++++++  $     ",
      "++++++++  $     ",
      "++++++++  $,,   ",
      "++++++++  $,,   ",
      "++++++++  $,,   "
    ],
    [
      " .  &  0  $,,   ",
      "       0  $     ",
      "       0  $     ",
      "00)00000  $,,   ",
      "       0  $,,   ",
      "       0  $,,   ",
      " %  %  0  $     ",
      "       0  $     ",
      "       0  $,,   ",
      " -   - 0  $,,   ",
      "       0  $,,   ",
      "       0  $     ",
      " %  %  0  $     ",
      "       0  $,,   ",
      "       0  $,,   ",
      "       0  $,,   "
    ],
    [
      "       0  $,,   ",
      "       0  $     ",
      "       0  $     ",
      "00*00000  $     ",
      "       0  $     ",
      "       0  $     ",
      "       0  $     ",
      "       0  $     ",
      "       !  $,,   ",
      "       !  $,,   ",
      "       0  $,,   ",
      "       0  $     ",
      "       0  $     ",
      "       0  $     ",
      "       0  $     ",
      "       0  $     "
    ],
    [
      "       0  $     ",
      "       0  $     ",
      "       0  $     ",
      "00000000  $     ",
      "       0  $     ",
      "       0  $     ",
      "       0  $     ",
      "       0  $     ",
      "       !  $     ",
      "       !  $     ",
      "       0  $     ",
      "       0  $     ",
      "       0  $     ",
      "       0  $     ",
      "       0  $     ",
      "       0  $     "
    ],
    [
      "       0  $     ",
      "       0  $     ",
      "       0  $     ",
      "00000000  $     ",
      "       0  $     ",
      "       0  $     ",
      "       0  $     ",
      "       0  $     ",
      "       0  $     ",
      "       0  $     ",
      "       0  $     ",
      "       0  $     ",
      "       0  $     ",
      "       0  $     ",
      "       0  $     ",
      "       0  $     "
    ]
  ],
  "palette": {
    "palette": [
      {
        "char": "!",
        "block": "create:framed_glass"
      },
      {
        "char": "$",
        "block": "immersiveengineering:concrete_reinforced"
      },
      {
        "char": "%",
        "block": "minecraft:barrel[facing=up,open=false]"
      },
      {
        "char": "&",
        "block": "minecraft:brewing_stand[has_bottle_0=false,has_bottle_1=false,has_bottle_2=false]"
      },
      {
        "char": "'",
        "block": "minecraft:coarse_dirt"
      },
      {
        "char": "(",
        "block": "minecraft:gravel"
      },
      {
        "char": ")",
        "block": "minecraft:spruce_door[facing=south,half=lower,hinge=left,open=false,powered=false]"
      },
      {
        "char": "*",
        "block": "minecraft:spruce_door[facing=south,half=upper,hinge=left,open=false,powered=false]"
      },
      {
        "char": "+",
        "block": "minecraft:spruce_planks"
      },
      {
        "char": ",",
        "block": "minecraft:stone"
      },
      {
        "char": "-",
        "block": "minecraft:water_cauldron[level=3]"
      },
      {
        "char": ".",
        "block": "minecraft:white_bed[facing=south,occupied=false,part=head]"
      },
      {
        "char": "/",
        "block": "tfmg:asphalt"
      },
      {
        "char": "0",
        "block": "tfmg:cinder_block"
      }
    ]
  }
}
