{
  "xsize": 16,
  "zsize": 16,
  "slices": [
    [
      "....(('.........",
      "..(('...........",
      "(('.............",
      "'...............",
      "...............(",
      ".............(('",
      "...........(('..",
      ".........(('....",
      ".......(('......",
      ".....(('........",
      "...(('..........",
      ".(('............",
      "('..............",
      "................",
      "..............((",
      "............(('."
    ],
    [
      "                ",
      "                ",
      "                ",
      "****            ",
      "****            ",
      "****            ",
      "****            ",
      "****            ",
      "****            ",
      "****            ",
      "****            ",
      "****            ",
      "****            ",
      "****////////////",
      "****////////////",
      "****////////////"
    ],
    [
      "                ",
      "                ",
      "                ",
      "%%%%            ",
      "   %            ",
      "   %            ",
      ")  %            ",
      "   %            ",
      "   %            ",
      "+$$%            ",
      "   %            ",
      " - %            ",
      "   %            ",
      " & %$$$$$$$$$$$$",
      "   %$           ",
      " %%%$           "
    ],
    [
      "                ",
      "                ",
      "                ",
      "%%%%            ",
      "   %            ",
      "   %            ",
      "   %            ",
      "   %            ",
      "   %            ",
      ",$$%            ",
      "   %            ",
      "   %            ",
      "   %            ",
      "   %$$$$$$$$$$$$",
      "   %$           ",
      " %%%$           "
    ],
    [
      "                ",
      "                ",
      "                ",
      "!%%%            ",
      "   %            ",
      "   %            ",
      "   %            ",
      "   %            ",
      "   %            ",
      "$$$%            ",
      "   %            ",
      "   %            ",
      "   %            ",
      "   %$$$$$$$$$$$$",
      "   %$           ",
      " %%%$           "
    ],
    [
      "                ",
      "                ",
      "                ",
      "!%%%            ",
      "   %            ",
      "   %            ",
      "   %            ",
      "   %            ",
      "   %            ",
      "$$$%            ",
      "   %            ",
      "   %            ",
      "   %            ",
      "   %$$$$$$$$$$$$",
      "   %$           ",
      " %%%$           "
    ]
  ],
  "palette": {
    "palette": [
      {
        "char": "!",
        "block": "create:framed_glass"
      },
      {
        "char": "$",
        "block": "immersiveengineering:concrete_leaded"
      },
      {
        "char": "%",
        "block": "immersiveengineering:concrete_reinforced"
      },
      {
        "char": "&",
        "block": "minecraft:chest[facing=west,type=single,waterlogged=false]",
        "tag": {
          "id": "minecraft:chest",
          "LootTable": "infinite_domain:chests/wasteland_office"
        }
      },
      {
        "char": "'",
        "block": "minecraft:coarse_dirt"
      },
      {
        "char": "(",
        "block": "minecraft:gravel"
      },
      {
        "char": ")",
        "block": "kubejs:ruined_lectern[facing=north]"
      },
      {
        "char": "*",
        "block": "minecraft:polished_andesite"
      },
      {
        "char": "+",
        "block": "minecraft:spruce_door[facing=south,half=lower,hinge=left,open=false,powered=false]"
      },
      {
        "char": ",",
        "block": "minecraft:spruce_door[facing=south,half=upper,hinge=left,open=false,powered=false]"
      },
      {
        "char": "-",
        "block": "kubejs:ruined_cauldron"
      },
      {
        "char": ".",
        "block": "tfmg:asphalt"
      },
      {
        "char": "/",
        "block": "tfmg:factory_floor"
      }
    ]
  }
}
