{
  "xsize": 16,
  "zsize": 16,
  "slices": [
    [
      ".))&............",
      ")&..............",
      "................",
      "................",
      "..............-.",
      "..........).....",
      "........))&.....",
      "......))&.......",
      "....))&.........",
      "..))&...........",
      "))&...........-.",
      "&...............",
      "................",
      "................",
      "...........*****",
      ".........))*****"
    ],
    [
      "                ",
      "                ",
      "$$$********     ",
      "   ********     ",
      "   ********     ",
      "   ********     ",
      "   ********     ",
      "   ********     ",
      "   ********     ",
      "   ********     ",
      "   ********     ",
      "                ",
      "                ",
      "///////////     ",
      "///////////     ",
      "///////////     "
    ],
    [
      "                ",
      "                ",
      "$$$$$$$$$$$     ",
      "   $      $     ",
      "   $      $     ",
      "   $++  0 $     ",
      "   $,     $     ",
      "   $      $     ",
      "   $    % $     ",
      "   $      $     ",
      "   $$$'$$$$     ",
      "                ",
      "                ",
      "$$$$$$$$$$$     ",
      "          $     ",
      "          $     "
    ],
    [
      "                ",
      "                ",
      "$$$$$$$$$$$     ",
      "   $      $     ",
      "   $      $     ",
      "   $      $     ",
      "   $      $     ",
      "   $      $     ",
      "   $      $     ",
      "   $      $     ",
      "   $!!($!!$     ",
      "                ",
      "                ",
      "$$$$$$$$$$$     ",
      "          $     ",
      "          $     "
    ],
    [
      "                ",
      "                ",
      "$$$$$$$$$$$     ",
      "   $      $     ",
      "   $      $     ",
      "   $      $     ",
      "   $      $     ",
      "   $      $     ",
      "   $      $     ",
      "   $      $     ",
      "   $!!$$!!$     ",
      "                ",
      "                ",
      "$$$!!$$!!$$     ",
      "          $     ",
      "          $     "
    ],
    [
      "                ",
      "                ",
      "$$$$$$$$$$$     ",
      "   $      $     ",
      "   $      $     ",
      "   $      $     ",
      "   $      $     ",
      "   $      $     ",
      "   $      $     ",
      "   $      $     ",
      "   $$$$$$$$     ",
      "                ",
      "                ",
      "$$$!!$$!!$$     ",
      "          $     ",
      "          $     "
    ]
  ],
  "palette": {
    "palette": [
      {
        "char": "!",
        "block": "create:framed_glass"
      },
      {
        "char": "$",
        "block": "immersiveengineering:concrete_reinforced"
      },
      {
        "char": "%",
        "block": "immersiveengineering:crate"
      },
      {
        "char": "&",
        "block": "minecraft:coarse_dirt"
      },
      {
        "char": "'",
        "block": "minecraft:dark_oak_door[facing=south,half=lower,hinge=left,open=false,powered=false]"
      },
      {
        "char": "(",
        "block": "minecraft:dark_oak_door[facing=south,half=upper,hinge=left,open=false,powered=false]"
      },
      {
        "char": ")",
        "block": "minecraft:gravel"
      },
      {
        "char": "*",
        "block": "minecraft:polished_andesite"
      },
      {
        "char": "+",
        "block": "minecraft:spruce_slab[type=bottom,waterlogged=false]"
      },
      {
        "char": ",",
        "block": "minecraft:spruce_stairs[facing=north,half=bottom,shape=straight,waterlogged=false]"
      },
      {
        "char": "-",
        "block": "minecraft:yellow_concrete"
      },
      {
        "char": ".",
        "block": "tfmg:asphalt"
      },
      {
        "char": "/",
        "block": "tfmg:factory_floor"
      },
      {
        "char": "0",
        "block": "the_wasteland_reworked:radio"
      }
    ]
  }
}
