{
  "xsize": 16,
  "zsize": 16,
  "slices": [
    [
      "%///////////////",
      "///////////////,",
      "/////////////,,%",
      "///////////,,%//",
      "/////////,,%////",
      "///////,,%//////",
      "/////,,%////////",
      "///,,%//////////",
      "/,,%////////////",
      ",,//////////////",
      ",,//////////////",
      ",,////////////,,",
      "////////////,,%/",
      "//////////,,%///",
      ",,//////,,%/////",
      ",,////,,%///////"
    ],
    [
      "                ",
      "                ",
      "  $$$$$$$$$$$$$$",
      "  $......       ",
      "  $......       ",
      "  $......       ",
      "  $......       ",
      "  $......       ",
      "  $......       ",
      ",,$             ",
      ",,$             ",
      ",,$             ",
      "  $             ",
      "  $  00000000000",
      ",,$  00000000000",
      ",,$  00000000000"
    ],
    [
      "                ",
      "                ",
      "  $$$$$$$$$$$$$$",
      "  $$$$$$$       ",
      "  $$    $       ",
      "  $$    $       ",
      "  $$    &       ",
      "  $$-   $       ",
      "  $$$$$$$       ",
      ",,$             ",
      ",,$             ",
      ",,$             ",
      "  $             ",
      "  $  $$$$$$$$$()",
      ",,$  $          ",
      ",,$  $          "
    ],
    [
      "                ",
      "                ",
      "  $$$$$$$$$$$$$$",
      "  $$$$$$$       ",
      "  $$    $       ",
      "  $$    $       ",
      "  $$    '       ",
      "  $$-   $       ",
      "  $$$$$$$       ",
      ",,$             ",
      ",,$             ",
      ",,$             ",
      "  $             ",
      "  $  $$$$$$$$$*+",
      "  $  $          ",
      "  $  $          "
    ],
    [
      "                ",
      "                ",
      "  $$$$$$$$$$$$$$",
      "  $$$$$$$       ",
      "  $$    $       ",
      "  $$    $       ",
      "  $$    $       ",
      "  $$-   $       ",
      "  $$$$$$$       ",
      "  $             ",
      "  $             ",
      "  $             ",
      "  $             ",
      "  $  $$!!$$$!!$$",
      "  $  $          ",
      "  $  $          "
    ],
    [
      "                ",
      "                ",
      "  $$$$$$$$$$$$$$",
      "  $$$$$$$       ",
      "  $$    $       ",
      "  $$    $       ",
      "  $$    $       ",
      "  $$-   $       ",
      "  $$$$$$$       ",
      "  $             ",
      "  $             ",
      "  $             ",
      "  $             ",
      "  $  $$!!$$$!!$$",
      "  $  $          ",
      "  $  $          "
    ]
  ],
  "palette": {
    "palette": [
      {
        "char": "!",
        "block": "create:framed_glass"
      },
      {
        "char": "$",
        "block": "immersiveengineering:concrete_reinforced"
      },
      {
        "char": "%",
        "block": "minecraft:coarse_dirt"
      },
      {
        "char": "&",
        "block": "minecraft:dark_oak_door[facing=east,half=lower,hinge=left,open=false,powered=false]"
      },
      {
        "char": "'",
        "block": "minecraft:dark_oak_door[facing=east,half=upper,hinge=left,open=false,powered=false]"
      },
      {
        "char": "(",
        "block": "minecraft:dark_oak_door[facing=north,half=lower,hinge=left,open=false,powered=false]"
      },
      {
        "char": ")",
        "block": "minecraft:dark_oak_door[facing=north,half=lower,hinge=right,open=false,powered=false]"
      },
      {
        "char": "*",
        "block": "minecraft:dark_oak_door[facing=north,half=upper,hinge=left,open=false,powered=false]"
      },
      {
        "char": "+",
        "block": "minecraft:dark_oak_door[facing=north,half=upper,hinge=right,open=false,powered=false]"
      },
      {
        "char": ",",
        "block": "minecraft:gravel"
      },
      {
        "char": "-",
        "block": "minecraft:ladder[facing=north,waterlogged=false]"
      },
      {
        "char": ".",
        "block": "minecraft:polished_andesite"
      },
      {
        "char": "/",
        "block": "tfmg:asphalt"
      },
      {
        "char": "0",
        "block": "tfmg:factory_floor"
      }
    ]
  }
}
