{
  "xsize": 16,
  "zsize": 16,
  "slices": [
    [
      "''&-------------",
      "&---------------",
      "----------------",
      "----------------",
      "--------------,-",
      "---------''-----",
      "-------''&------",
      "-----''&--------",
      "---''&----------",
      "-''&------------",
      "'&--------------",
      "----------------",
      "--------------''",
      "                ",
      "                ",
      "                "
    ],
    [
      "((((((((((((((((",
      "((((((((((((((((",
      "((((((((((((((((",
      "((((((((((((((((",
      "((((((((((((((((",
      "                ",
      "                ",
      "                ",
      "                ",
      "                ",
      "!!!!!!!!!!!!!!!!",
      "                ",
      "                ",
      "                ",
      "                ",
      "                "
    ],
    [
      " . $$$$$$  .  % ",
      " * $$$$)$  *    ",
      " . $$$$$$  .    ",
      " .         .    ",
      "!!!!!!!!!!!!!!!!",
      "                ",
      "                ",
      "                ",
      "                ",
      "                ",
      "!!!!!!!!!!!!!!!!",
      "                ",
      "                ",
      "                ",
      "                ",
      "                "
    ],
    [
      " . $$$$$$  .    ",
      " + $$$$$$  +    ",
      " . $$$$$$  .    ",
      " .         .    ",
      "!!!!!!!!!!!!!!!!",
      "                ",
      "                ",
      "                ",
      "                ",
      "                ",
      "!!!!!!!!!!!!!!!!",
      "                ",
      "                ",
      "                ",
      "                ",
      "                "
    ],
    [
      " .         .    ",
      " .         .    ",
      " .         .    ",
      " .         .    ",
      "!!!!!!!!!!!!!!!!",
      "                ",
      "                ",
      "                ",
      "                ",
      "                ",
      "!!!!!!!!!!!!!!!!",
      "                ",
      "                ",
      "                ",
      "                ",
      "                "
    ],
    [
      " .         .    ",
      " .         .    ",
      " .         .    ",
      " .         .    ",
      "!!!!!!!!!!!!!!!!",
      "                ",
      "                ",
      "                ",
      "                ",
      "                ",
      "!!!!!!!!!!!!!!!!",
      "                ",
      "                ",
      "                ",
      "                ",
      "                "
    ]
  ],
  "palette": {
    "palette": [
      {
        "char": "!",
        "block": "immersiveengineering:concrete_reinforced"
      },
      {
        "char": "$",
        "block": "immersiveengineering:crate"
      },
      {
        "char": "%",
        "block": "immersiveengineering:metal_barrel"
      },
      {
        "char": "&",
        "block": "minecraft:coarse_dirt"
      },
      {
        "char": "'",
        "block": "minecraft:gravel"
      },
      {
        "char": "(",
        "block": "minecraft:polished_deepslate"
      },
      {
        "char": ")",
        "block": "minecraft:spawner",
        "tag": {
          "id": "minecraft:mob_spawner",
          "Delay": 240,
          "MinSpawnDelay": 240,
          "MaxSpawnDelay": 720,
          "SpawnCount": 3,
          "MaxNearbyEntities": 10,
          "RequiredPlayerRange": 14,
          "SpawnRange": 4,
          "SpawnData": {
            "entity": {
              "id": "minecraft:pillager"
            }
          },
          "SpawnPotentials": [
            {
              "weight": 1,
              "data": {
                "entity": {
                  "id": "minecraft:pillager"
                }
              }
            }
          ]
        }
      },
      {
        "char": "*",
        "block": "minecraft:spruce_door[facing=east,half=lower,hinge=left,open=false,powered=false]"
      },
      {
        "char": "+",
        "block": "minecraft:spruce_door[facing=east,half=upper,hinge=left,open=false,powered=false]"
      },
      {
        "char": ",",
        "block": "minecraft:yellow_concrete"
      },
      {
        "char": "-",
        "block": "tfmg:asphalt"
      },
      {
        "char": ".",
        "block": "tfmg:cinder_block"
      }
    ]
  }
}
