{
  "xsize": 16,
  "zsize": 16,
  "slices": [
    [
      "...........)''''",
      "...........)''''",
      "...........)))))",
      "................",
      "................",
      "................",
      ".''&............",
      "'&..............",
      "..............-.",
      "................",
      "................",
      "..........'.....",
      "........''&.....",
      "......''&.......",
      "....''&.......-.",
      "..''&..........."
    ],
    [
      "00000000000     ",
      "00000000000     ",
      "                ",
      "                ",
      "****************",
      "****************",
      "****************",
      "****************",
      "****************",
      "****************",
      "****************",
      "****************",
      "****************",
      "****************",
      "****************",
      "****************"
    ],
    [
      "/         !     ",
      "!!!!!!!!!!!     ",
      "                ",
      "                ",
      "!!!      !!!    ",
      "                ",
      "                ",
      "    $(($     $%%",
      "    ((((     %%%",
      "    ((((     %%%",
      "    ((((     %%%",
      "    $(($     $%%",
      "                ",
      "                ",
      "//////+/////////",
      " /         /    "
    ],
    [
      "/         !     ",
      "!!!!!!!!!!!     ",
      "                ",
      "                ",
      "!!!      !!!    ",
      "                ",
      "                ",
      "    ((((     %%%",
      "    ((((     %%%",
      "    ((((     %%%",
      "    ((((     %%%",
      "    ((((     %%%",
      "                ",
      "                ",
      "//////,/////////",
      " /         /    "
    ],
    [
      "/         !     ",
      "!!!!!!!!!!!     ",
      "                ",
      "                ",
      "!!!      !!!    ",
      "                ",
      "                ",
      "    ((((     %%%",
      "    ((((     %%%",
      "    ((((     %%%",
      "    ((((     %%%",
      "    ((((     %%%",
      "                ",
      "                ",
      "////////////////",
      " /         /    "
    ],
    [
      "/         !     ",
      "!!!!!!!!!!!     ",
      "                ",
      "                ",
      "!!!      !!!    ",
      "                ",
      "                ",
      "                ",
      "                ",
      "                ",
      "                ",
      "                ",
      "                ",
      "                ",
      "////////////////",
      " /         /    "
    ]
  ],
  "palette": {
    "palette": [
      {
        "char": "!",
        "block": "immersiveengineering:concrete_reinforced"
      },
      {
        "char": "$",
        "block": "minecraft:black_concrete"
      },
      {
        "char": "%",
        "block": "minecraft:brown_terracotta"
      },
      {
        "char": "&",
        "block": "minecraft:coarse_dirt"
      },
      {
        "char": "'",
        "block": "minecraft:gravel"
      },
      {
        "char": "(",
        "block": "minecraft:gray_terracotta"
      },
      {
        "char": ")",
        "block": "minecraft:polished_andesite"
      },
      {
        "char": "*",
        "block": "minecraft:polished_deepslate"
      },
      {
        "char": "+",
        "block": "minecraft:spruce_door[facing=south,half=lower,hinge=left,open=false,powered=false]"
      },
      {
        "char": ",",
        "block": "minecraft:spruce_door[facing=south,half=upper,hinge=left,open=false,powered=false]"
      },
      {
        "char": "-",
        "block": "minecraft:yellow_concrete"
      },
      {
        "char": ".",
        "block": "tfmg:asphalt"
      },
      {
        "char": "/",
        "block": "tfmg:cinder_block"
      },
      {
        "char": "0",
        "block": "tfmg:factory_floor"
      }
    ]
  }
}
