{
  "xsize": 16,
  "zsize": 16,
  "slices": [
    [
      "8(('888888888888",
      "('88888888888888",
      "8888888888888888",
      "888888888888888(",
      "8888888888888888",
      "8888888888888888",
      "8888888888888888",
      "888888((88888888",
      "8888(('888888888",
      "88(('88888888888",
      "(('8888888888888",
      "'888888888888888",
      "888888888888888(",
      "888888888888888'",
      "88888888888(('88",
      "888888888(('8888"
    ],
    [
      "                ",
      "                ",
      "                ",
      "   )))))))))))))",
      "   )))))))))))))",
      "   )))))))))))))",
      "   )))))))))))))",
      "   )))))))))))))",
      "   )))))))))))))",
      "   )))))))))))))",
      "   )))))))))))))",
      "   )))))))))))))",
      "   )))))))))))))",
      "999)))))))))))))",
      "999)))))))))))))",
      "999)))))))))))))"
    ],
    [
      "                ",
      "                ",
      "                ",
      "   %%%%%%%-.%%%%",
      "   %     $    $ ",
      "   %     $    $ ",
      "   % 5*  +55  + ",
      "   % 6 ; $6   $ ",
      "   %     $    $ ",
      "   %$$1$$$$1$$$$",
      "   %       $    ",
      "   % &  &  $  7 ",
      "   %       +    ",
      "%%%%       $:   ",
      "   %   12  $  12",
      "   %%%%   %%%%  "
    ],
    [
      "                ",
      "                ",
      "                ",
      "   %%%%%%%/0%%%%",
      "   %     $    $ ",
      "   %     $    $ ",
      "   %     ,    , ",
      "   %     $    $ ",
      "   %     $    $ ",
      "   %$$3$$$$3$$$$",
      "   %       $    ",
      "   %       $    ",
      "   %       ,    ",
      "%%%%       $    ",
      "   %   34  $  34",
      "   %%%%   %%%%  "
    ],
    [
      "                ",
      "                ",
      "                ",
      "   %%!!%%%!!%%%!",
      "   %     $    $ ",
      "   %     $    $ ",
      "   %     $    $ ",
      "   %     $    $ ",
      "   %     $    $ ",
      "   %$$$$$$$$$$$$",
      "   %       $    ",
      "   %       $    ",
      "   %       $    ",
      "%%!!   !!  $    ",
      "   %       $    ",
      "   %%%%   %%%%  "
    ],
    [
      "                ",
      "                ",
      "                ",
      "   %%!!%%%!!%%%!",
      "   %     $    $ ",
      "   %     $    $ ",
      "   %     $    $ ",
      "   %     $    $ ",
      "   %     $    $ ",
      "   %$$$$$$$$$$$$",
      "   %       $    ",
      "   %       $    ",
      "   %       $    ",
      "%%!!   !!  $    ",
      "   %       $    ",
      "   %%%%   %%%%  "
    ]
  ],
  "palette": {
    "palette": [
      {
        "char": "!",
        "block": "create:framed_glass"
      },
      {
        "char": "$",
        "block": "immersiveengineering:concrete_leaded"
      },
      {
        "char": "%",
        "block": "immersiveengineering:concrete_reinforced"
      },
      {
        "char": "&",
        "block": "minecraft:barrel[facing=up,open=false]"
      },
      {
        "char": "'",
        "block": "minecraft:coarse_dirt"
      },
      {
        "char": "(",
        "block": "minecraft:gravel"
      },
      {
        "char": ")",
        "block": "minecraft:polished_andesite"
      },
      {
        "char": "*",
        "block": "minecraft:spawner",
        "tag": {
          "id": "minecraft:mob_spawner",
          "Delay": 200,
          "MinSpawnDelay": 240,
          "MaxSpawnDelay": 720,
          "SpawnCount": 2,
          "MaxNearbyEntities": 8,
          "RequiredPlayerRange": 14,
          "SpawnRange": 4,
          "SpawnData": {
            "entity": {
              "id": "minecraft:pillager"
            }
          },
          "SpawnPotentials": [
            {
              "weight": 1,
              "data": {
                "entity": {
                  "id": "minecraft:pillager"
                }
              }
            }
          ]
        }
      },
      {
        "char": "+",
        "block": "minecraft:spruce_door[facing=east,half=lower,hinge=left,open=false,powered=false]"
      },
      {
        "char": ",",
        "block": "minecraft:spruce_door[facing=east,half=upper,hinge=left,open=false,powered=false]"
      },
      {
        "char": "-",
        "block": "minecraft:spruce_door[facing=north,half=lower,hinge=left,open=false,powered=false]"
      },
      {
        "char": ".",
        "block": "minecraft:spruce_door[facing=north,half=lower,hinge=right,open=false,powered=false]"
      },
      {
        "char": "/",
        "block": "minecraft:spruce_door[facing=north,half=upper,hinge=left,open=false,powered=false]"
      },
      {
        "char": "0",
        "block": "minecraft:spruce_door[facing=north,half=upper,hinge=right,open=false,powered=false]"
      },
      {
        "char": "1",
        "block": "minecraft:spruce_door[facing=south,half=lower,hinge=left,open=false,powered=false]"
      },
      {
        "char": "2",
        "block": "minecraft:spruce_door[facing=south,half=lower,hinge=right,open=false,powered=false]"
      },
      {
        "char": "3",
        "block": "minecraft:spruce_door[facing=south,half=upper,hinge=left,open=false,powered=false]"
      },
      {
        "char": "4",
        "block": "minecraft:spruce_door[facing=south,half=upper,hinge=right,open=false,powered=false]"
      },
      {
        "char": "5",
        "block": "minecraft:spruce_slab[type=bottom,waterlogged=false]"
      },
      {
        "char": "6",
        "block": "minecraft:spruce_stairs[facing=north,half=bottom,shape=straight,waterlogged=false]"
      },
      {
        "char": "7",
        "block": "kubejs:ruined_cauldron"
      },
      {
        "char": "8",
        "block": "tfmg:asphalt"
      },
      {
        "char": "9",
        "block": "tfmg:factory_floor"
      },
      {
        "char": ":",
        "block": "the_wasteland_reworked:radiation_hazard_sign"
      },
      {
        "char": ";",
        "block": "the_wasteland_reworked:radio"
      }
    ]
  }
}
