{
  "xsize": 16,
  "zsize": 16,
  "slices": [
    [
      "''--''&---------",
      "--''&-----------",
      "''&-------------",
      "''--------------",
      "''-------------'",
      "''-----------''&",
      "-----------''&--",
      "---------''&----",
      "''-----''&------",
      "''---''&--------",
      "''-''&----------",
      "-''&------------",
      "'&--------------",
      "''--------------",
      "''------------''",
      "''----------''&-"
    ],
    [
      "''$  ///////////",
      "  $  ///////////",
      "  $  ///////////",
      "''$  ///////////",
      "''$  ///////////",
      "''$  ///////////",
      "  $  ///////////",
      "  $  ///////////",
      "''$  ///////////",
      "''$  ///////////",
      "''$  ///////////",
      "  $  ///////////",
      "  $  ///////////",
      "''$  ///////////",
      "''$  ///////////",
      "''$  ///////////"
    ],
    [
      "''$  $ **  %    ",
      "  $  $ +        ",
      "  $  $          ",
      "''$  $          ",
      "''$  $....(.....",
      "''$  $          ",
      "  $  $          ",
      "  $  $ ,  ,  ,  ",
      "''$  $ ** ** ** ",
      "''$  $          ",
      "''$  $          ",
      "  $  $          ",
      "  $  $          ",
      "''$  $          ",
      "''$  $          ",
      "''$  $          "
    ],
    [
      "  $  $          ",
      "  $  $          ",
      "  $  $          ",
      "''$  $          ",
      "''$  $....).....",
      "''$  $          ",
      "  $  $          ",
      "  $  $          ",
      "  $  $          ",
      "  $  $          ",
      "  $  $          ",
      "  $  $          ",
      "  $  $          ",
      "''$  $          ",
      "''$  $          ",
      "''$  $          "
    ],
    [
      "  $  $          ",
      "  $  $          ",
      "  $  $          ",
      "  $  $          ",
      "  $  $..........",
      "  $  $          ",
      "  $  $          ",
      "  $  $          ",
      "  $  !          ",
      "  $  !          ",
      "  $  $          ",
      "  $  $          ",
      "  $  $          ",
      "  $  $          ",
      "  $  $          ",
      "  $  $          "
    ],
    [
      "  $  $          ",
      "  $  $          ",
      "  $  $          ",
      "  $  $          ",
      "  $  $..........",
      "  $  $          ",
      "  $  $          ",
      "  $  $          ",
      "  $  !          ",
      "  $  !          ",
      "  $  $          ",
      "  $  $          ",
      "  $  $          ",
      "  $  $          ",
      "  $  $          ",
      "  $  $          "
    ]
  ],
  "palette": {
    "palette": [
      {
        "char": "!",
        "block": "create:framed_glass"
      },
      {
        "char": "$",
        "block": "immersiveengineering:concrete_reinforced"
      },
      {
        "char": "%",
        "block": "minecraft:cartography_table"
      },
      {
        "char": "&",
        "block": "minecraft:coarse_dirt"
      },
      {
        "char": "'",
        "block": "minecraft:gravel"
      },
      {
        "char": "(",
        "block": "minecraft:spruce_door[facing=south,half=lower,hinge=left,open=false,powered=false]"
      },
      {
        "char": ")",
        "block": "minecraft:spruce_door[facing=south,half=upper,hinge=left,open=false,powered=false]"
      },
      {
        "char": "*",
        "block": "minecraft:spruce_slab[type=bottom,waterlogged=false]"
      },
      {
        "char": "+",
        "block": "minecraft:spruce_stairs[facing=north,half=bottom,shape=straight,waterlogged=false]"
      },
      {
        "char": ",",
        "block": "minecraft:spruce_stairs[facing=south,half=bottom,shape=straight,waterlogged=false]"
      },
      {
        "char": "-",
        "block": "tfmg:asphalt"
      },
      {
        "char": ".",
        "block": "tfmg:cinder_block"
      },
      {
        "char": "/",
        "block": "tfmg:factory_floor"
      }
    ]
  }
}
