{
  "xsize": 16,
  "zsize": 16,
  "slices": [
    [
      "0000000000(('000",
      "(((00000(('00000",
      "(((000(('0000000",
      "(((0(('000000000",
      "00(('00000000000",
      "(('0000000000000",
      "(((0000000000000",
      "(((000000000000(",
      "(((0000000000(('",
      "00000000000(('00",
      "000000000(('0000",
      "0000000(('000000",
      "00000(('00000000",
      "000(('0000000000",
      "0(('000000000000",
      "('00000000000000"
    ],
    [
      "   1111111111111",
      "(((1111111111111",
      "(((1111111111111",
      "(((1111111111111",
      "   1111111111111",
      "  $$111111111111",
      "(($$111111,,,,,,",
      "(((1111111,,,,,,",
      "(((       ,,,,,,",
      "          ,,,,,,",
      "          ,,,,,,",
      "          ,,,,,,",
      "          ,,,,,,",
      "          ,,,,,,",
      "          ,,,,,,",
      "                "
    ],
    [
      "   %           $",
      "   %           $",
      "   % )         -",
      "   % *     /   $",
      "   %           $",
      "  $$           $",
      "(($$      $$$$$$",
      "(((%%%%%%%$     ",
      "(((       $     ",
      "          $ &  2",
      "          $     ",
      "          $     ",
      "          $     ",
      "          $     ",
      "          $$$$$$",
      "                "
    ],
    [
      "   %           $",
      "   %           $",
      "   %           .",
      "   %           $",
      "   %           $",
      "  $$           $",
      "  $$      $$$$$$",
      "   %%%%%%%$     ",
      "          $     ",
      "          !     ",
      "          !     ",
      "          $     ",
      "          $     ",
      "          $     ",
      "          $$$$$$",
      "                "
    ],
    [
      "   %  +        $",
      "   %           $",
      "   %           $",
      "   %           $",
      "   %           $",
      "  $$           $",
      "  $$      $$$$$$",
      "   %%%%%%%$     ",
      "          $     ",
      "          !     ",
      "          !     ",
      "          $     ",
      "          $     ",
      "          $     ",
      "          $$$$$$",
      "                "
    ],
    [
      "   %           $",
      "   %  +        $",
      "   %           $",
      "   %           $",
      "   %           $",
      "  $$           $",
      "  $$      $$$$$$",
      "   %%%%%%%$     ",
      "          $     ",
      "          $     ",
      "          $     ",
      "          $     ",
      "          $     ",
      "          $     ",
      "          $$$$$$",
      "                "
    ]
  ],
  "palette": {
    "palette": [
      {
        "char": "!",
        "block": "create:framed_glass"
      },
      {
        "char": "$",
        "block": "immersiveengineering:concrete_leaded"
      },
      {
        "char": "%",
        "block": "immersiveengineering:concrete_reinforced"
      },
      {
        "char": "&",
        "block": "immersiveengineering:metal_barrel"
      },
      {
        "char": "'",
        "block": "minecraft:coarse_dirt"
      },
      {
        "char": "(",
        "block": "minecraft:gravel"
      },
      {
        "char": ")",
        "block": "minecraft:light_blue_bed[facing=south,occupied=false,part=foot]"
      },
      {
        "char": "*",
        "block": "minecraft:light_blue_bed[facing=south,occupied=false,part=head]"
      },
      {
        "char": "+",
        "block": "minecraft:polished_andesite_stairs[facing=south,half=bottom,shape=straight,waterlogged=false]"
      },
      {
        "char": ",",
        "block": "minecraft:polished_deepslate"
      },
      {
        "char": "-",
        "block": "minecraft:spruce_door[facing=east,half=lower,hinge=left,open=false,powered=false]"
      },
      {
        "char": ".",
        "block": "minecraft:spruce_door[facing=east,half=upper,hinge=left,open=false,powered=false]"
      },
      {
        "char": "/",
        "block": "minecraft:water_cauldron[level=3]"
      },
      {
        "char": "0",
        "block": "tfmg:asphalt"
      },
      {
        "char": "1",
        "block": "tfmg:factory_floor"
      },
      {
        "char": "2",
        "block": "tfmg:steel_block"
      }
    ]
  }
}
