{
  "xsize": 16,
  "zsize": 16,
  "slices": [
    [
      " ***''**********",
      " *''%***********",
      " '%*************",
      " ***************",
      " **************'",
      " %***********'''",
      " **********''%**",
      " *%****%***%%***",
      "      *****     ",
      "                ",
      "                ",
      "                ",
      "                ",
      "                ",
      "                ",
      "                "
    ],
    [
      "((&((&((&((&((&(",
      "(&((&((&((&((&((",
      "&((&((&((&((&((&",
      "((&((&((&((&((&(",
      "&&&&         &&&",
      "&&&           &&",
      "&&&           &&",
      "&&&           &&",
      "&&&           &&",
      "                ",
      "                ",
      "                ",
      "                ",
      "                ",
      "                ",
      "                "
    ],
    [
      "((&((&((&((&((&(",
      "(&((&((&((&((&((",
      "&((&((&((&((&((&",
      "&(&((&((&((&((&(",
      "&&&&  )      &&&",
      "&&&           &&",
      "&&&           &&",
      "&&&           &&",
      "&&&           &&",
      "                ",
      "                ",
      "                ",
      "                ",
      "                ",
      "                ",
      "                "
    ],
    [
      "((&((&((&((&((&(",
      "&&((&((&((&((&((",
      "&&& $(&((&((  &&",
      "&&&  &((&((&  &&",
      "&&&&         &&&",
      "&&&           &&",
      "&&&           &&",
      "&&&           &&",
      "&&&           &&",
      "                ",
      "                ",
      "                ",
      "                ",
      "                ",
      "                ",
      "                "
    ],
    [
      "&(&(!!!!!((&((&(",
      "&&& !!!!!(&(  &&",
      "&&& !!!!!     &&",
      "&&&           &&",
      "&&&&         &&&",
      "&&&           &&",
      "&&&           &&",
      "&&&           &&",
      "&&&           &&",
      "                ",
      "                ",
      "                ",
      "                ",
      "                ",
      "                ",
      "                "
    ],
    [
      "&&&      ((&  &&",
      "&&&           &&",
      "&&&           &&",
      "&&&           &&",
      "&&&&         &&&",
      "&&&           &&",
      "&&&           &&",
      "&&&           &&",
      "&&&           &&",
      "                ",
      "                ",
      "                ",
      "                ",
      "                ",
      "                ",
      "                "
    ]
  ],
  "palette": {
    "palette": [
      {
        "char": "!",
        "block": "immersiveengineering:concrete_brick_cracked"
      },
      {
        "char": "$",
        "block": "immersiveengineering:concrete_reinforced"
      },
      {
        "char": "%",
        "block": "minecraft:coarse_dirt"
      },
      {
        "char": "&",
        "block": "minecraft:cobblestone"
      },
      {
        "char": "'",
        "block": "minecraft:gravel"
      },
      {
        "char": "(",
        "block": "minecraft:mossy_cobblestone"
      },
      {
        "char": ")",
        "block": "minecraft:spawner",
        "tag": {
          "id": "minecraft:mob_spawner",
          "Delay": 200,
          "MinSpawnDelay": 240,
          "MaxSpawnDelay": 720,
          "SpawnCount": 2,
          "MaxNearbyEntities": 6,
          "RequiredPlayerRange": 14,
          "SpawnRange": 4,
          "SpawnData": {
            "entity": {
              "id": "minecraft:zombie"
            }
          },
          "SpawnPotentials": [
            {
              "weight": 1,
              "data": {
                "entity": {
                  "id": "minecraft:zombie"
                }
              }
            }
          ]
        }
      },
      {
        "char": "*",
        "block": "tfmg:asphalt"
      }
    ]
  }
}
