{
  "xsize": 16,
  "zsize": 16,
  "slices": [
    [
      "++++++++++&&%+++",
      "++++++++++++++++",
      "&&++++++++++++++",
      "&&++++++++++++++",
      "&&&+++++++++++++",
      "&&%+++++++++++++",
      "%+++++++++++++++",
      "&&+++++++++++++&",
      "&&+++++++++++&&%",
      "&&+++++++++&&%++",
      "+++++++++&&%++++",
      "+++++++&&%++++++",
      "&&+++&&%++++++++",
      "&&+&&%++++++++++",
      "&&&%++++++++++++",
      "&%++++++++++++++"
    ],
    [
      "  !  -----------",
      "  !  -----------",
      "&&!             ",
      "&&!             ",
      "&&!     ((((((((",
      "  !     ((((((((",
      "  !     (&&&((((",
      "&&!     (&&&((((",
      "&&!     (&&&&&&(",
      "&&!     ((((&&&(",
      "  !     ((((&&&&",
      "  !     (((((((&",
      "&&!     (((((((&",
      "&&!     ((((((((",
      "&&!     ((((((((",
      "  !     (((((((("
    ],
    [
      "  !  !          ",
      "  !  !!!!!!!!!!!",
      "&&!             ",
      "&&!             ",
      "&&!     !!      ",
      "  !     !       ",
      "  !     !&&&    ",
      "&&!     !&&&''$ ",
      "&&!     !&&&&&& ",
      "&&!     !  '&&& ",
      "  !     !  '&&&&",
      "  !     !  $''$&",
      "&&!     !      &",
      "&&!     !       ",
      "&&!     !,,,),,,",
      "  !     !       "
    ],
    [
      "  !  !          ",
      "  !  !!!!!!!!!!!",
      "  !             ",
      "  !             ",
      "  !     !!      ",
      "  !     !       ",
      "  !     !&&&    ",
      "&&!     !&&&''' ",
      "&&!     !&&&&&& ",
      "&&!     !  '&&& ",
      "  !     !  '&&& ",
      "  !     !  '''' ",
      "  !     !       ",
      "  !     !       ",
      "  !     !,,,*,,,",
      "  !     !       "
    ],
    [
      "  !  !          ",
      "  !  !!!!!!!!!!!",
      "  !             ",
      "  !             ",
      "  !     !!      ",
      "  !     !       ",
      "  !     !       ",
      "  !     ! !'''' ",
      "  !     !  '&&& ",
      "  !     !  '&&& ",
      "  !     !  '&&& ",
      "  !     !  '''' ",
      "  !     !       ",
      "  !     !       ",
      "  !     !,,,,,,,",
      "  !     !       "
    ],
    [
      "  !  !          ",
      "  !  !!!!!!!!!!!",
      "  !             ",
      "  !             ",
      "  !     !!      ",
      "  !     !       ",
      "  !     !       ",
      "  !     !       ",
      "  !     !   &&& ",
      "  !     !   &&& ",
      "  !     !   &&& ",
      "  !     !       ",
      "  !     !       ",
      "  !     !       ",
      "  !     !,,,,,,,",
      "  !     !       "
    ]
  ],
  "palette": {
    "palette": [
      {
        "char": "!",
        "block": "immersiveengineering:concrete_reinforced"
      },
      {
        "char": "$",
        "block": "minecraft:black_concrete"
      },
      {
        "char": "%",
        "block": "minecraft:coarse_dirt"
      },
      {
        "char": "&",
        "block": "minecraft:gravel"
      },
      {
        "char": "'",
        "block": "minecraft:green_terracotta"
      },
      {
        "char": "(",
        "block": "minecraft:polished_deepslate"
      },
      {
        "char": ")",
        "block": "minecraft:spruce_door[facing=south,half=lower,hinge=left,open=false,powered=false]"
      },
      {
        "char": "*",
        "block": "minecraft:spruce_door[facing=south,half=upper,hinge=left,open=false,powered=false]"
      },
      {
        "char": "+",
        "block": "tfmg:asphalt"
      },
      {
        "char": ",",
        "block": "tfmg:cinder_block"
      },
      {
        "char": "-",
        "block": "tfmg:factory_floor"
      }
    ]
  }
}
