{
  "xsize": 16,
  "zsize": 16,
  "slices": [
    [
      "  !  !          ",
      "  !  !          ",
      "  !  !          ",
      "  !  !          ",
      "  !  !          ",
      "  !  !          ",
      "  !  !          ",
      "  !  !          ",
      "  !  !          ",
      "  !  !          ",
      "  !  !          ",
      "  !  !          ",
      "  !  !          ",
      "  !  !          ",
      "  !  !          ",
      "  !  !          "
    ],
    [
      "     !          ",
      "     !          ",
      "     !          ",
      "     !          ",
      "     !          ",
      "     !          ",
      "     !          ",
      "     !          ",
      "     !          ",
      "     !          ",
      "     !          ",
      "     !          ",
      "     !          ",
      "     !          ",
      "     !          ",
      "     !          "
    ],
    [
      "     !''''''''''",
      "     !''''''''''",
      "     !''''''''''",
      "     !''''''''''",
      "     !''''''''''",
      "     !''''''''''",
      "     !''''''''''",
      "     !''''''''''",
      "     !''''''''''",
      "     !''''''''''",
      "     !''''''''''",
      "     !''''''''''",
      "     !''''''''''",
      "     !''''''''''",
      "     !''''''''''",
      "     !''''''''''"
    ],
    [
      "     !          ",
      "     !          ",
      "     !  **  **  ",
      "     !  +   +   ",
      "     !          ",
      "     !          ",
      "     !,,,,,(,,,,",
      "     !          ",
      "     !          ",
      "     !          ",
      "     !  $       ",
      "     !          ",
      "     !          ",
      "     !     &    ",
      "     !          ",
      "     !          "
    ],
    [
      "     !          ",
      "     !          ",
      "     !          ",
      "     !          ",
      "     !          ",
      "     !          ",
      "     !,,,,,),,,,",
      "     !          ",
      "     !        % ",
      "     !          ",
      "     !          ",
      "     !          ",
      "     !          ",
      "     !          ",
      "     !          ",
      "     !          "
    ],
    [
      "     !          ",
      "     !          ",
      "     !          ",
      "     !          ",
      "     !          ",
      "     !          ",
      "     !,,,,,,,,,,",
      "     !          ",
      "     !        % ",
      "     !          ",
      "     !          ",
      "     !          ",
      "     !          ",
      "     !          ",
      "     !          ",
      "     !          "
    ]
  ],
  "palette": {
    "palette": [
      {
        "char": "!",
        "block": "immersiveengineering:concrete_reinforced"
      },
      {
        "char": "$",
        "block": "minecraft:cartography_table"
      },
      {
        "char": "%",
        "block": "minecraft:ladder[facing=west,waterlogged=false]"
      },
      {
        "char": "&",
        "block": "minecraft:lectern[facing=north,has_book=false,powered=false]"
      },
      {
        "char": "'",
        "block": "minecraft:polished_andesite"
      },
      {
        "char": "(",
        "block": "minecraft:spruce_door[facing=south,half=lower,hinge=left,open=false,powered=false]"
      },
      {
        "char": ")",
        "block": "minecraft:spruce_door[facing=south,half=upper,hinge=left,open=false,powered=false]"
      },
      {
        "char": "*",
        "block": "minecraft:spruce_slab[type=bottom,waterlogged=false]"
      },
      {
        "char": "+",
        "block": "minecraft:spruce_stairs[facing=north,half=bottom,shape=straight,waterlogged=false]"
      },
      {
        "char": ",",
        "block": "tfmg:cinder_block"
      }
    ]
  }
}
