{
  "xsize": 16,
  "zsize": 16,
  "slices": [
    [
      "1111111))'111111",
      "11111))'11111111",
      "111))'1111111111",
      "1))'111111111111",
      ")'11111111111111",
      "1111111111111111",
      "11111111111111))",
      "111111111111))'1",
      "1111111111))'111",
      "11111111))'11111",
      "111111))'1111111",
      "1111))'111111111",
      "11))'11111111111",
      "))'1111111111111",
      "'111111111111111",
      "111111111111111)"
    ],
    [
      "2222222222222222",
      "2222222222222222",
      "2222222222222222",
      "2222222222222222",
      "2222222222222222",
      "2222222222222222",
      "2222222222222222",
      "2222222222222222",
      "2222222222222222",
      "2222222222222222",
      "2222222222222222",
      "2222222222222222",
      "2222222222222222",
      "2222222222222222",
      "2222222222222222",
      "2222222222222222"
    ],
    [
      "           $!  0",
      "           $!   ",
      "  &  &  &  $!   ",
      "           $!  0",
      "           $!   ",
      "  0  0  0  $!!!!",
      "                ",
      "           ,    ",
      "!!!!.!!!!!!    0",
      "           $!   ",
      "  +++++++  $!   ",
      "  +++++++  $!  0",
      "           $!   ",
      "   (   %   $!!!!",
      "       *   $!   ",
      "!!!!.!!!!!!$!   "
    ],
    [
      "           $!   ",
      "           $!   ",
      "           $!   ",
      "           $!   ",
      "           $!   ",
      "           $!!!!",
      "                ",
      "           -    ",
      "!!!!/!!!!!!     ",
      "           $!   ",
      "           $!   ",
      "           $!   ",
      "           $!   ",
      "           $!!!!",
      "           $!   ",
      "!!!!/!!*!!!$!   "
    ],
    [
      "           $!   ",
      "           $!   ",
      "           $!   ",
      "           $!   ",
      "           $!   ",
      "           $!!!!",
      "                ",
      "                ",
      "!!!!!!!!!!!     ",
      "           $!   ",
      "           $!   ",
      "           $!   ",
      "           $!   ",
      "           $!!!!",
      "           $!   ",
      "!!!!!!! !!!$!   "
    ],
    [
      "           $!   ",
      "           $!   ",
      "           $!   ",
      "           $!   ",
      "           $!   ",
      "           $!!!!",
      "                ",
      "                ",
      "!!!!!!!!!!!     ",
      "           $!   ",
      "           $!   ",
      "           $!   ",
      "           $!   ",
      "           $!!!!",
      "           $!   ",
      "!!!!!!! !!!$!   "
    ]
  ],
  "palette": {
    "palette": [
      {
        "char": "!",
        "block": "immersiveengineering:concrete_leaded"
      },
      {
        "char": "$",
        "block": "immersiveengineering:concrete_reinforced"
      },
      {
        "char": "%",
        "block": "minecraft:barrel[facing=up,open=false]"
      },
      {
        "char": "&",
        "block": "kubejs:ruined_brewing_stand"
      },
      {
        "char": "'",
        "block": "minecraft:coarse_dirt"
      },
      {
        "char": "(",
        "block": "kubejs:ruined_furnace[facing=north]"
      },
      {
        "char": ")",
        "block": "minecraft:gravel"
      },
      {
        "char": "*",
        "block": "minecraft:polished_andesite_stairs[facing=south,half=bottom,shape=straight,waterlogged=false]"
      },
      {
        "char": "+",
        "block": "minecraft:smooth_quartz"
      },
      {
        "char": ",",
        "block": "minecraft:spruce_door[facing=east,half=lower,hinge=left,open=false,powered=false]"
      },
      {
        "char": "-",
        "block": "minecraft:spruce_door[facing=east,half=upper,hinge=left,open=false,powered=false]"
      },
      {
        "char": ".",
        "block": "minecraft:spruce_door[facing=south,half=lower,hinge=left,open=false,powered=false]"
      },
      {
        "char": "/",
        "block": "minecraft:spruce_door[facing=south,half=upper,hinge=left,open=false,powered=false]"
      },
      {
        "char": "0",
        "block": "kubejs:ruined_cauldron"
      },
      {
        "char": "1",
        "block": "tfmg:asphalt"
      },
      {
        "char": "2",
        "block": "tfmg:factory_floor"
      }
    ]
  }
}
