{
  "xsize": 16,
  "zsize": 16,
  "slices": [
    [
      "   $            ",
      "   $            ",
      "   $  (         ",
      "   $            ",
      "   $            ",
      "  !!            ",
      "  !!      !!!!!!",
      "   $$$$$$$!     ",
      "          !     ",
      "          !     ",
      "          !     ",
      "          !     ",
      "          !     ",
      "          !     ",
      "          !!!!!!",
      "                "
    ],
    [
      "   $            ",
      "   $            ",
      "   $            ",
      "   $  (         ",
      "   $            ",
      "  !!            ",
      "  !!      !!!!!!",
      "   $$$$$$$!     ",
      "          !     ",
      "          !     ",
      "          !     ",
      "          !     ",
      "          !     ",
      "          !     ",
      "          !!!!!!",
      "                "
    ],
    [
      "   $''''''''''''",
      "   $''''''''''''",
      "   $''''''''''''",
      "   $''''''''''''",
      "   $''''''''''''",
      "  !!''''''''''''",
      "  !!''''''''''''",
      "   $$$$$$$!     ",
      "          !     ",
      "          !     ",
      "          !     ",
      "          !     ",
      "          !     ",
      "          !     ",
      "          !!!!!!",
      "                "
    ],
    [
      "   $           !",
      "   $           !",
      "   $           *",
      "   $   )   %   !",
      "   $           !",
      "   $           !",
      "   $      !!!!!!",
      "   $$$$$$$!     ",
      "          !     ",
      "          !     ",
      "          !     ",
      "          !     ",
      "          !     ",
      "          !     ",
      "          !!!!!!",
      "                "
    ],
    [
      "   $           !",
      "   $           !",
      "   $           +",
      "   $           !",
      "   $           !",
      "   $           !",
      "   $      &&&&&!",
      "   $$$$$$$&&&&&&",
      "          &&&&&&",
      "          &&&&&&",
      "          &&&&&&",
      "          &&&&&&",
      "          &&&&&&",
      "          &&&&&&",
      "          &&&&&&",
      "                "
    ],
    [
      "   $           !",
      "   $           !",
      "   $           !",
      "   $           !",
      "   $           !",
      "   $           !",
      "   $           !",
      "   $$$$$$$$$$$$$",
      "                ",
      "                ",
      "                ",
      "                ",
      "                ",
      "                ",
      "                ",
      "                "
    ]
  ],
  "palette": {
    "palette": [
      {
        "char": "!",
        "block": "immersiveengineering:concrete_leaded"
      },
      {
        "char": "$",
        "block": "immersiveengineering:concrete_reinforced"
      },
      {
        "char": "%",
        "block": "minecraft:barrel[facing=up,open=false]"
      },
      {
        "char": "&",
        "block": "minecraft:oxidized_copper"
      },
      {
        "char": "'",
        "block": "minecraft:polished_andesite"
      },
      {
        "char": "(",
        "block": "minecraft:polished_andesite_stairs[facing=south,half=bottom,shape=straight,waterlogged=false]"
      },
      {
        "char": ")",
        "block": "kubejs:ruined_smoker[facing=north]"
      },
      {
        "char": "*",
        "block": "minecraft:spruce_door[facing=east,half=lower,hinge=left,open=false,powered=false]"
      },
      {
        "char": "+",
        "block": "minecraft:spruce_door[facing=east,half=upper,hinge=left,open=false,powered=false]"
      }
    ]
  }
}
