{
  "xsize": 16,
  "zsize": 16,
  "slices": [
    [
      "------))&----   ",
      "----))&----,,   ",
      "--))&------,,   ",
      "))&--------,,   ",
      "&------------   ",
      "-------------   ",
      "-------------   ",
      "-----------))   ",
      "---------))&-   ",
      "-------))&---   ",
      "-----))&-----   ",
      "---))&-------   ",
      "-))&---------   ",
      "                ",
      "                ",
      "                "
    ],
    [
      "........  !     ",
      "........  !,,   ",
      "........  !,,   ",
      "........  !,,   ",
      "........  !     ",
      "     ++++++     ",
      "     ++++++     ",
      "     ++++++     ",
      "     ++++++     ",
      "     ++++++     ",
      "!!!!!++++++     ",
      "                ",
      "                ",
      "                ",
      "                ",
      "                "
    ],
    [
      "$$  $$ !  !     ",
      "$$  $$ !  !,,   ",
      "     % !  !,,   ",
      "       !  !,,   ",
      "!!!!!!!!  !     ",
      "     !!!!!!     ",
      "     !    !     ",
      "     '    !     ",
      "     !    !     ",
      "     !*   !     ",
      "!!!!!!!!!!!     ",
      "                ",
      "                ",
      "                ",
      "                ",
      "                "
    ],
    [
      "$$  $$ !  !     ",
      "$$  $$ !  !     ",
      "       !  !     ",
      "       !  !     ",
      "!!!!!!!!  !     ",
      "     !!!!!!     ",
      "     !    !     ",
      "     (    !     ",
      "     !    !     ",
      "     !*   !     ",
      "!!!!!!!!!!!     ",
      "                ",
      "                ",
      "                ",
      "                ",
      "                "
    ],
    [
      "       !  !     ",
      "       !  !     ",
      "       !  !     ",
      "       !  !     ",
      "!!!!!!!!  !     ",
      "     !!!!!!     ",
      "     !    !     ",
      "     !    !     ",
      "     !    !     ",
      "     !*   !     ",
      "!!!!!!!!!!!     ",
      "                ",
      "                ",
      "                ",
      "                ",
      "                "
    ],
    [
      "       !  !     ",
      "       !  !     ",
      "       !  !     ",
      "       !  !     ",
      "!!!!!!!!  !     ",
      "     !!!!!!     ",
      "     !    !     ",
      "     !    !     ",
      "     !    !     ",
      "     !*   !     ",
      "!!!!!!!!!!!     ",
      "                ",
      "                ",
      "                ",
      "                ",
      "                "
    ]
  ],
  "palette": {
    "palette": [
      {
        "char": "!",
        "block": "immersiveengineering:concrete_reinforced"
      },
      {
        "char": "$",
        "block": "immersiveengineering:crate"
      },
      {
        "char": "%",
        "block": "minecraft:chest[facing=west,type=single,waterlogged=false]",
        "tag": {
          "id": "minecraft:chest",
          "LootTable": "infinite_domain:chests/wasteland_military"
        }
      },
      {
        "char": "&",
        "block": "minecraft:coarse_dirt"
      },
      {
        "char": "'",
        "block": "minecraft:dark_oak_door[facing=west,half=lower,hinge=left,open=false,powered=false]"
      },
      {
        "char": "(",
        "block": "minecraft:dark_oak_door[facing=west,half=upper,hinge=left,open=false,powered=false]"
      },
      {
        "char": ")",
        "block": "minecraft:gravel"
      },
      {
        "char": "*",
        "block": "minecraft:ladder[facing=north,waterlogged=false]"
      },
      {
        "char": "+",
        "block": "minecraft:polished_andesite"
      },
      {
        "char": ",",
        "block": "minecraft:stone"
      },
      {
        "char": "-",
        "block": "tfmg:asphalt"
      },
      {
        "char": ".",
        "block": "tfmg:factory_floor"
      }
    ]
  }
}
