{
  "xsize": 16,
  "zsize": 16,
  "slices": [
    [
      ",,,,,,,777777777",
      ",,,,,,,777777777",
      "--77777777777777",
      "7777777777777777",
      "7777777777777777",
      "7777777777777777",
      "7777,,'777777777",
      "77,,'77777777777",
      "77'7777777777777",
      "7777777777777777",
      "777777777777777,",
      "7777777777777,,'",
      "77777777777,,'77",
      "777777777,,'7777",
      "7777777,,'777777",
      "77777,,'77777777"
    ],
    [
      "   4444444444444",
      "                ",
      "                ",
      "                ",
      ".....   99999999",
      ".....   99999999",
      ".....   99999999",
      ".....   99999999",
      ".....   99999999",
      ".....   99999999",
      ".....   99999999",
      ".....   99999999",
      ".....   99999999",
      ".....   99999999",
      ".....   99999999",
      ".....   99999999"
    ],
    [
      "   8888888888888",
      "                ",
      "                ",
      "                ",
      "  $$$   $$$$$$$$",
      "    $   $     8 ",
      "    $   $     8 ",
      "%   $   $     8 ",
      "&   $   $ 6   8 ",
      "&   $   $ 55  8 ",
      "&   $   $     8 ",
      "%   $   $     8 ",
      "    $   *     02",
      "    $   $     8 ",
      "2888(   $     8 ",
      "    $   $ /   8 "
    ],
    [
      "   8888888888888",
      "                ",
      "                ",
      "                ",
      "  $$$   $$$$$$$$",
      "    $   $     8 ",
      "    $   $     8 ",
      "&   $   $     8 ",
      "&   $   $     8 ",
      "&   $   $     8 ",
      "&   $   $     8 ",
      "&   $   $     8 ",
      "    $   +     13",
      "    $   $     8 ",
      "3888)   $     8 ",
      "    $   $     8 "
    ],
    [
      "   8888888888888",
      "                ",
      "                ",
      "                ",
      "  $$$   $$$$$$$$",
      "    $   $     8 ",
      "    $   !     8 ",
      "&   $   !     8 ",
      "&   $   $     8 ",
      "&   $   $     8 ",
      "&   $   $     8 ",
      "&   $   $     8 ",
      "    $   $     88",
      "    $   $     8 ",
      "8888$   $     8 ",
      "    $   $     8 "
    ],
    [
      "   8888888888888",
      "                ",
      "                ",
      "                ",
      "  $$$   $$$$$$$$",
      "    $   $     8 ",
      "    $   !     8 ",
      "    $   !     8 ",
      "    $   $     8 ",
      "    $   $     8 ",
      "    $   $     8 ",
      "    $   $     8 ",
      "    $   $     88",
      "    $   $     8 ",
      "8888$   $     8 ",
      "    $   $     8 "
    ]
  ],
  "palette": {
    "palette": [
      {
        "char": "!",
        "block": "create:framed_glass"
      },
      {
        "char": "$",
        "block": "immersiveengineering:concrete_reinforced"
      },
      {
        "char": "%",
        "block": "minecraft:black_concrete"
      },
      {
        "char": "&",
        "block": "minecraft:brown_terracotta"
      },
      {
        "char": "'",
        "block": "minecraft:coarse_dirt"
      },
      {
        "char": "(",
        "block": "minecraft:dark_oak_door[facing=east,half=lower,hinge=left,open=false,powered=false]"
      },
      {
        "char": ")",
        "block": "minecraft:dark_oak_door[facing=east,half=upper,hinge=left,open=false,powered=false]"
      },
      {
        "char": "*",
        "block": "minecraft:dark_oak_door[facing=west,half=lower,hinge=left,open=false,powered=false]"
      },
      {
        "char": "+",
        "block": "minecraft:dark_oak_door[facing=west,half=upper,hinge=left,open=false,powered=false]"
      },
      {
        "char": ",",
        "block": "minecraft:gravel"
      },
      {
        "char": "-",
        "block": "minecraft:polished_andesite"
      },
      {
        "char": ".",
        "block": "minecraft:polished_deepslate"
      },
      {
        "char": "/",
        "block": "kubejs:ruined_smithing_table"
      },
      {
        "char": "0",
        "block": "minecraft:spruce_door[facing=east,half=lower,hinge=left,open=false,powered=false]"
      },
      {
        "char": "1",
        "block": "minecraft:spruce_door[facing=east,half=upper,hinge=left,open=false,powered=false]"
      },
      {
        "char": "2",
        "block": "minecraft:spruce_door[facing=south,half=lower,hinge=left,open=false,powered=false]"
      },
      {
        "char": "3",
        "block": "minecraft:spruce_door[facing=south,half=upper,hinge=left,open=false,powered=false]"
      },
      {
        "char": "4",
        "block": "minecraft:spruce_planks"
      },
      {
        "char": "5",
        "block": "minecraft:spruce_slab[type=bottom,waterlogged=false]"
      },
      {
        "char": "6",
        "block": "minecraft:spruce_stairs[facing=west,half=bottom,shape=straight,waterlogged=false]"
      },
      {
        "char": "7",
        "block": "tfmg:asphalt"
      },
      {
        "char": "8",
        "block": "tfmg:cinder_block"
      },
      {
        "char": "9",
        "block": "tfmg:factory_floor"
      }
    ]
  }
}
