{
  "xsize": 16,
  "zsize": 16,
  "slices": [
    [
      "      22222     ",
      " 2+2222+2222+22+",
      " 222222222222++(",
      " (222222222++(2+",
      " 2222222222(2222",
      " 222222222222222",
      " 2222+2222222222",
      " 22++(2222222222",
      " ++(222222222222",
      " (2222222222222+",
      " 222222222222222",
      " 2222222222222++",
      " 22222222222++(2",
      " 2222222222+(222",
      " 222222222222222",
      " (2222222222222+"
    ],
    [
      "))))         )))",
      ")))           ))",
      ")))           ))",
      ")))           ))",
      ")))           ))",
      "))))         )))",
      ")))           ))",
      ")))           ))",
      ")))           ))",
      ")))           ))",
      "))))         )))",
      "))) $$$$$$$$$ ))",
      "))) $$$$$$$$$ ))",
      ")))      &&&& ))",
      "))) **,**     ))",
      "))))*****    )))"
    ],
    [
      "))))         )))",
      ")))           ))",
      ")))           ))",
      ")))           ))",
      ")))           ))",
      "))))         )))",
      ")))           ))",
      ")))           ))",
      ")))           ))",
      ")))           ))",
      "))))         )))",
      "))) $$$$$$$$$ ))",
      "))) $$$$$$$$$ ))",
      ")))      &&&& ))",
      "))) %%-%%     ))",
      "))))%   %    )))"
    ],
    [
      "))))         )))",
      ")))           ))",
      ")))           ))",
      ")))           ))",
      ")))           ))",
      "))))         )))",
      ")))           ))",
      ")))           ))",
      ")))     1     ))",
      ")))           ))",
      "))))         )))",
      "))) ......... ))",
      "))) ......... ))",
      ")))       '   ))",
      "))) %%%%%     ))",
      "))))%   %    )))"
    ],
    [
      "))))         )))",
      ")))           ))",
      ")))           ))",
      ")))           ))",
      ")))           ))",
      "))))         )))",
      ")))           ))",
      ")))           ))",
      ")))     1     ))",
      ")))           ))",
      "))))         )))",
      ")))           ))",
      ")))           ))",
      ")))           ))",
      "))) !!!!!     ))",
      "))))!!!!!    )))"
    ],
    [
      "))))         )))",
      ")))           ))",
      ")))           ))",
      ")))           ))",
      ")))           ))",
      "))))         )))",
      ")))           ))",
      ")))           ))",
      ")))     /     ))",
      ")))           ))",
      "))))         )))",
      ")))           ))",
      ")))0          ))",
      ")))           ))",
      ")))           ))",
      "))))         )))"
    ]
  ],
  "palette": {
    "palette": [
      {
        "char": "!",
        "block": "immersiveengineering:concrete"
      },
      {
        "char": "$",
        "block": "immersiveengineering:concrete_brick_cracked"
      },
      {
        "char": "%",
        "block": "immersiveengineering:concrete_reinforced"
      },
      {
        "char": "&",
        "block": "minecraft:brown_terracotta"
      },
      {
        "char": "'",
        "block": "minecraft:campfire[facing=north,lit=true,signal_fire=false,waterlogged=false]"
      },
      {
        "char": "(",
        "block": "minecraft:coarse_dirt"
      },
      {
        "char": ")",
        "block": "minecraft:cobblestone"
      },
      {
        "char": "*",
        "block": "minecraft:glass_pane"
      },
      {
        "char": "+",
        "block": "minecraft:gravel"
      },
      {
        "char": ",",
        "block": "minecraft:iron_door[facing=south,half=lower,hinge=left,open=false,powered=false]"
      },
      {
        "char": "-",
        "block": "minecraft:iron_door[facing=south,half=upper,hinge=left,open=false,powered=false]"
      },
      {
        "char": ".",
        "block": "minecraft:orange_concrete"
      },
      {
        "char": "/",
        "block": "minecraft:orange_wool"
      },
      {
        "char": "0",
        "block": "minecraft:oxidized_copper_grate"
      },
      {
        "char": "1",
        "block": "minecraft:stripped_oak_log[axis=y]"
      },
      {
        "char": "2",
        "block": "tfmg:asphalt"
      }
    ]
  }
}
