{
  "xsize": 16,
  "zsize": 16,
  "slices": [
    [
      "                ",
      "                ",
      "    (           ",
      "    (%%%%%%%%%%%",
      "    (           ",
      "    (           ",
      "    (           ",
      "    (           ",
      "    (           ",
      "    (           ",
      "    (           ",
      "    (           ",
      "    (           ",
      "%%!!(%%!!%%%$$$$",
      "    (      %$   ",
      "    (%%%%%%%%%%%"
    ],
    [
      "                ",
      "                ",
      "     (          ",
      "     (%%%%%%%%%%",
      "     (          ",
      "     (          ",
      "     (          ",
      "     (          ",
      "     (          ",
      "     (          ",
      "     (          ",
      "     (          ",
      "     (          ",
      "%%%%%(%%%%%%$$$$",
      "     (     %$   ",
      "     (%%%%%%%%%%"
    ],
    [
      "                ",
      "                ",
      "      (         ",
      "      (%%%%%%%%%",
      "      (         ",
      "      (         ",
      "      (         ",
      "      (         ",
      "      (         ",
      "      (         ",
      "      (         ",
      "      (         ",
      "      (         ",
      "%%%%%%(%%%%%&&&&",
      "      (    %&&&&",
      "      (%%%%%%%%%"
    ],
    [
      "                ",
      "                ",
      "       (       )",
      "       (%%%%%%%)",
      "       (       )",
      "       (       )",
      "       (       )",
      "       (       )",
      "       (       )",
      "       (       )",
      "       (       )",
      "       (       )",
      "       (       )",
      "%%%%%%%(%%%%   )",
      "       (   %   )",
      "       (%%%%%%%)"
    ],
    [
      "                ",
      "                ",
      "        (     ) ",
      "        (%%%%%) ",
      "        (     ) ",
      "        (     ) ",
      "        (     ) ",
      "        (     ) ",
      "        (     ) ",
      "        (     ) ",
      "        (     ) ",
      "        (     ) ",
      "        (     ) ",
      "%%%%%%%%(%%%  ) ",
      "        (  %  ) ",
      "        (%%%%%) "
    ],
    [
      "                ",
      "                ",
      "         (   )  ",
      "         (%%%)  ",
      "         (   )  ",
      "         (   )  ",
      "         (   )  ",
      "         (   )  ",
      "         (   )  ",
      "         (   )  ",
      "         (   )  ",
      "         (   )  ",
      "         (   )  ",
      "'''''''''('' )  ",
      "'''''''''('' )  ",
      "'''''''''(%%%)  "
    ]
  ],
  "palette": {
    "palette": [
      {
        "char": "!",
        "block": "create:framed_glass"
      },
      {
        "char": "$",
        "block": "immersiveengineering:concrete_leaded"
      },
      {
        "char": "%",
        "block": "immersiveengineering:concrete_reinforced"
      },
      {
        "char": "&",
        "block": "minecraft:oxidized_copper"
      },
      {
        "char": "'",
        "block": "minecraft:weathered_cut_copper"
      },
      {
        "char": "(",
        "block": "minecraft:weathered_cut_copper_stairs[facing=east,half=bottom,shape=straight,waterlogged=false]"
      },
      {
        "char": ")",
        "block": "minecraft:weathered_cut_copper_stairs[facing=west,half=bottom,shape=straight,waterlogged=false]"
      }
    ]
  }
}
