{
  "xsize": 16,
  "zsize": 16,
  "slices": [
    [
      " +++**++++++++++",
      " +**'+++++++++++",
      " *'+++++++++++++",
      " +++++++++++++++",
      " ++++++++++++++*",
      " '+++++++++++***",
      " ++++++++++**'++",
      " +'++++'+++''+++",
      "      +++++     ",
      "                ",
      "                ",
      "                ",
      "                ",
      "                ",
      "                ",
      "                "
    ],
    [
      "((( )))))     ((",
      "((( )))))     ((",
      "((( )))))     ((",
      "(((           ((",
      "((((         (((",
      "(((           ((",
      "(((           ((",
      "(((           ((",
      "(((           ((",
      "                ",
      "                ",
      "                ",
      "                ",
      "                ",
      "                ",
      "                "
    ],
    [
      "((( $%  $     ((",
      "((( $  &$     ((",
      "((( $$$$$     ((",
      "(((           ((",
      "((((         (((",
      "(((           ((",
      "(((           ((",
      "(((           ((",
      "(((           ((",
      "                ",
      "                ",
      "                ",
      "                ",
      "                ",
      "                ",
      "                "
    ],
    [
      "((( $   $     ((",
      "((( $   $     ((",
      "((( $$$$$     ((",
      "(((           ((",
      "((((         (((",
      "(((           ((",
      "(((           ((",
      "(((           ((",
      "(((           ((",
      "                ",
      "                ",
      "                ",
      "                ",
      "                ",
      "                ",
      "                "
    ],
    [
      "((( !!!!!     ((",
      "((( !!!!!     ((",
      "((( !!!!!     ((",
      "(((           ((",
      "((((         (((",
      "(((           ((",
      "(((           ((",
      "(((           ((",
      "(((           ((",
      "                ",
      "                ",
      "                ",
      "                ",
      "                ",
      "                ",
      "                "
    ],
    [
      "(((           ((",
      "(((           ((",
      "(((           ((",
      "(((           ((",
      "((((         (((",
      "(((           ((",
      "(((           ((",
      "(((           ((",
      "(((           ((",
      "                ",
      "                ",
      "                ",
      "                ",
      "                ",
      "                ",
      "                "
    ]
  ],
  "palette": {
    "palette": [
      {
        "char": "!",
        "block": "immersiveengineering:concrete"
      },
      {
        "char": "$",
        "block": "immersiveengineering:concrete_reinforced"
      },
      {
        "char": "%",
        "block": "minecraft:barrel[facing=up,open=false]"
      },
      {
        "char": "&",
        "block": "minecraft:chest[facing=west,type=single,waterlogged=false]",
        "tag": {
          "id": "minecraft:chest",
          "LootTable": "infinite_domain:chests/wasteland_roadside"
        }
      },
      {
        "char": "'",
        "block": "minecraft:coarse_dirt"
      },
      {
        "char": "(",
        "block": "minecraft:cobblestone"
      },
      {
        "char": ")",
        "block": "minecraft:glass_pane"
      },
      {
        "char": "*",
        "block": "minecraft:gravel"
      },
      {
        "char": "+",
        "block": "tfmg:asphalt"
      }
    ]
  }
}
