{
  "xsize": 16,
  "zsize": 16,
  "slices": [
    [
      "       $  $     ",
      "       $  $     ",
      "       $  $     ",
      "       $  $     ",
      "$$$$$$$$  $     ",
      "     $$$$$$     ",
      "     $    $     ",
      "     $    $     ",
      "     $    $     ",
      "     $%   $     ",
      "$$$$$$$$$$$     ",
      "                ",
      "                ",
      "                ",
      "                ",
      "                "
    ],
    [
      "       $        ",
      "       $        ",
      "       $        ",
      "       $        ",
      "$$$$$$$$        ",
      "     $$$$$$     ",
      "     $    $     ",
      "     $    $     ",
      "     $    $     ",
      "     $%   $     ",
      "     $$$$$$     ",
      "                ",
      "                ",
      "                ",
      "                ",
      "                "
    ],
    [
      "       $        ",
      "       $        ",
      "       $        ",
      "       $        ",
      "$$$$$$$$        ",
      "     $$$$$$     ",
      "     $''''$     ",
      "     $''''$     ",
      "     $''''$     ",
      "     $%'''$     ",
      "     $$$$$$     ",
      "                ",
      "                ",
      "                ",
      "                ",
      "                "
    ],
    [
      "       $        ",
      "       $        ",
      "       $        ",
      "       $        ",
      "$$$$$$$$        ",
      "     $$$$$$     ",
      "     $    $     ",
      "     $    $     ",
      "     $    $     ",
      "     $%   $     ",
      "     $$$$$$     ",
      "                ",
      "                ",
      "                ",
      "                ",
      "                "
    ],
    [
      "       $        ",
      "       $        ",
      "       $        ",
      "       $        ",
      "$$$$$$$$        ",
      "     $$$$$$     ",
      "     $    $     ",
      "     $    $     ",
      "     $    $     ",
      "     $%   $     ",
      "     $$$$$$     ",
      "                ",
      "                ",
      "                ",
      "                ",
      "                "
    ],
    [
      "&&&&&&&&        ",
      "&&&&&&&&        ",
      "&&&&&&&&        ",
      "&&&&&&&&        ",
      "&&&&&&&&        ",
      "     $!!$$$     ",
      "     $    $     ",
      "     $    $     ",
      "     $    $     ",
      "     $%   $     ",
      "     $!!$$$     ",
      "                ",
      "                ",
      "                ",
      "                ",
      "                "
    ]
  ],
  "palette": {
    "palette": [
      {
        "char": "!",
        "block": "create:framed_glass"
      },
      {
        "char": "$",
        "block": "immersiveengineering:concrete_reinforced"
      },
      {
        "char": "%",
        "block": "minecraft:ladder[facing=north,waterlogged=false]"
      },
      {
        "char": "&",
        "block": "minecraft:oxidized_copper"
      },
      {
        "char": "'",
        "block": "minecraft:polished_andesite"
      }
    ]
  }
}
