{
  "xsize": 16,
  "zsize": 16,
  "slices": [
    [
      "2222))&222222222",
      "22))&22222222222",
      "22&2222222222222",
      "2222222222222222",
      "222222222222222)",
      "2222222222222))&",
      "22222222222))&22",
      "222222222))&2222",
      "2222222))&222222",
      "22222))&22222222",
      "222))&2222222222",
      "22)&222222222222",
      "2222222222222222",
      "2222222222222222",
      "**222222222222))",
      "**2222222222))&2"
    ],
    [
      "                ",
      "                ",
      "  $********$$$$$",
      "   ********     ",
      "   ********     ",
      "   ********     ",
      "   ********     ",
      "   ********     ",
      "   ********     ",
      "   ********     ",
      "   ********     ",
      "                ",
      "                ",
      "   /////////////",
      "   /////////////",
      "   /////////////"
    ],
    [
      "                ",
      "                ",
      "  $$$$$$$$$$$$$$",
      "   $      $     ",
      "   $      $     ",
      "   $00  4 $     ",
      "   $1     $     ",
      "   $      $     ",
      "   $    % $     ",
      "   $      $     ",
      "   $$$'$$$$     ",
      "                ",
      "                ",
      "   333333333+,33",
      "   3         3  ",
      "   3         3  "
    ],
    [
      "                ",
      "                ",
      "  $$$$$$$$$$$$$$",
      "   $      $     ",
      "   $      $     ",
      "   $      $     ",
      "   $      $     ",
      "   $      $     ",
      "   $      $     ",
      "   $      $     ",
      "   $!!($!!$     ",
      "                ",
      "                ",
      "   33!!333!!-.33",
      "   3         3  ",
      "   3         3  "
    ],
    [
      "                ",
      "                ",
      "  $$$$$$$$$$$$$$",
      "   $      $     ",
      "   $      $     ",
      "   $      $     ",
      "   $      $     ",
      "   $      $     ",
      "   $      $     ",
      "   $      $     ",
      "   $!!$$!!$     ",
      "                ",
      "                ",
      "   33!!333!!3333",
      "   3         3  ",
      "   3         3  "
    ],
    [
      "                ",
      "                ",
      "  $$$$$$$$$$$$$$",
      "   $      $     ",
      "   $      $     ",
      "   $      $     ",
      "   $      $     ",
      "   $      $     ",
      "   $      $     ",
      "   $      $     ",
      "   $$$$$$$$     ",
      "                ",
      "                ",
      "   3333333333333",
      "   3         3  ",
      "   3         3  "
    ]
  ],
  "palette": {
    "palette": [
      {
        "char": "!",
        "block": "create:framed_glass"
      },
      {
        "char": "$",
        "block": "immersiveengineering:concrete_reinforced"
      },
      {
        "char": "%",
        "block": "immersiveengineering:crate"
      },
      {
        "char": "&",
        "block": "minecraft:coarse_dirt"
      },
      {
        "char": "'",
        "block": "minecraft:dark_oak_door[facing=south,half=lower,hinge=left,open=false,powered=false]"
      },
      {
        "char": "(",
        "block": "minecraft:dark_oak_door[facing=south,half=upper,hinge=left,open=false,powered=false]"
      },
      {
        "char": ")",
        "block": "minecraft:gravel"
      },
      {
        "char": "*",
        "block": "minecraft:polished_andesite"
      },
      {
        "char": "+",
        "block": "minecraft:spruce_door[facing=north,half=lower,hinge=left,open=false,powered=false]"
      },
      {
        "char": ",",
        "block": "minecraft:spruce_door[facing=north,half=lower,hinge=right,open=false,powered=false]"
      },
      {
        "char": "-",
        "block": "minecraft:spruce_door[facing=north,half=upper,hinge=left,open=false,powered=false]"
      },
      {
        "char": ".",
        "block": "minecraft:spruce_door[facing=north,half=upper,hinge=right,open=false,powered=false]"
      },
      {
        "char": "/",
        "block": "minecraft:spruce_planks"
      },
      {
        "char": "0",
        "block": "minecraft:spruce_slab[type=bottom,waterlogged=false]"
      },
      {
        "char": "1",
        "block": "minecraft:spruce_stairs[facing=north,half=bottom,shape=straight,waterlogged=false]"
      },
      {
        "char": "2",
        "block": "tfmg:asphalt"
      },
      {
        "char": "3",
        "block": "tfmg:cinder_block"
      },
      {
        "char": "4",
        "block": "the_wasteland_reworked:radio"
      }
    ]
  }
}
