{
  "xsize": 16,
  "zsize": 16,
  "slices": [
    [
      "7(('777777777777",
      "('77777777777777",
      "7777777777777777",
      "777777777777777(",
      "7777777777777777",
      "7777777777777777",
      "7777777777777777",
      "777777((77777777",
      "7777(('777777777",
      "77(('77777777777",
      "(('7777777777777",
      "'777777777777777",
      "777777777777777(",
      "777777777777777'",
      "77777777777(('77",
      "777777777(('7777"
    ],
    [
      "                ",
      "                ",
      "                ",
      "   )))))))))))))",
      "   )))))))))))))",
      "   )))))))))))))",
      "   )))))))))))))",
      "   )))))))))))))",
      "   )))))))))))))",
      "   )))))))))))))",
      "   )))))))))))))",
      "   )))))))))))))",
      "   )))))))))))))",
      "888)))))))))))))",
      "888)))))))))))))",
      "888)))))))))))))"
    ],
    [
      "                ",
      "                ",
      "                ",
      "   %%%%%%%,-%%%%",
      "   %     $    $ ",
      "   %     $    $ ",
      "   % 44  *44  * ",
      "   % 5 : $5   $ ",
      "   %     $    $ ",
      "   %$$0$$$$0$$$$",
      "   %       $    ",
      "   % &  &  $  6 ",
      "   %       *    ",
      "%%%%       $9   ",
      "   %   01  $  01",
      "   %%%%   %%%%  "
    ],
    [
      "                ",
      "                ",
      "                ",
      "   %%%%%%%./%%%%",
      "   %     $    $ ",
      "   %     $    $ ",
      "   %     +    + ",
      "   %     $    $ ",
      "   %     $    $ ",
      "   %$$2$$$$2$$$$",
      "   %       $    ",
      "   %       $    ",
      "   %       +    ",
      "%%%%       $    ",
      "   %   23  $  23",
      "   %%%%   %%%%  "
    ],
    [
      "                ",
      "                ",
      "                ",
      "   %%!!%%%!!%%%!",
      "   %     $    $ ",
      "   %     $    $ ",
      "   %     $    $ ",
      "   %     $    $ ",
      "   %     $    $ ",
      "   %$$$$$$$$$$$$",
      "   %       $    ",
      "   %       $    ",
      "   %       $    ",
      "%%!!   !!  $    ",
      "   %       $    ",
      "   %%%%   %%%%  "
    ],
    [
      "                ",
      "                ",
      "                ",
      "   %%!!%%%!!%%%!",
      "   %     $    $ ",
      "   %     $    $ ",
      "   %     $    $ ",
      "   %     $    $ ",
      "   %     $    $ ",
      "   %$$$$$$$$$$$$",
      "   %       $    ",
      "   %       $    ",
      "   %       $    ",
      "%%!!   !!  $    ",
      "   %       $    ",
      "   %%%%   %%%%  "
    ]
  ],
  "palette": {
    "palette": [
      {
        "char": "!",
        "block": "create:framed_glass"
      },
      {
        "char": "$",
        "block": "immersiveengineering:concrete_leaded"
      },
      {
        "char": "%",
        "block": "immersiveengineering:concrete_reinforced"
      },
      {
        "char": "&",
        "block": "minecraft:barrel[facing=up,open=false]"
      },
      {
        "char": "'",
        "block": "minecraft:coarse_dirt"
      },
      {
        "char": "(",
        "block": "minecraft:gravel"
      },
      {
        "char": ")",
        "block": "minecraft:polished_andesite"
      },
      {
        "char": "*",
        "block": "minecraft:spruce_door[facing=east,half=lower,hinge=left,open=false,powered=false]"
      },
      {
        "char": "+",
        "block": "minecraft:spruce_door[facing=east,half=upper,hinge=left,open=false,powered=false]"
      },
      {
        "char": ",",
        "block": "minecraft:spruce_door[facing=north,half=lower,hinge=left,open=false,powered=false]"
      },
      {
        "char": "-",
        "block": "minecraft:spruce_door[facing=north,half=lower,hinge=right,open=false,powered=false]"
      },
      {
        "char": ".",
        "block": "minecraft:spruce_door[facing=north,half=upper,hinge=left,open=false,powered=false]"
      },
      {
        "char": "/",
        "block": "minecraft:spruce_door[facing=north,half=upper,hinge=right,open=false,powered=false]"
      },
      {
        "char": "0",
        "block": "minecraft:spruce_door[facing=south,half=lower,hinge=left,open=false,powered=false]"
      },
      {
        "char": "1",
        "block": "minecraft:spruce_door[facing=south,half=lower,hinge=right,open=false,powered=false]"
      },
      {
        "char": "2",
        "block": "minecraft:spruce_door[facing=south,half=upper,hinge=left,open=false,powered=false]"
      },
      {
        "char": "3",
        "block": "minecraft:spruce_door[facing=south,half=upper,hinge=right,open=false,powered=false]"
      },
      {
        "char": "4",
        "block": "minecraft:spruce_slab[type=bottom,waterlogged=false]"
      },
      {
        "char": "5",
        "block": "minecraft:spruce_stairs[facing=north,half=bottom,shape=straight,waterlogged=false]"
      },
      {
        "char": "6",
        "block": "minecraft:water_cauldron[level=3]"
      },
      {
        "char": "7",
        "block": "tfmg:asphalt"
      },
      {
        "char": "8",
        "block": "tfmg:factory_floor"
      },
      {
        "char": "9",
        "block": "the_wasteland_reworked:radiation_hazard_sign"
      },
      {
        "char": ":",
        "block": "the_wasteland_reworked:radio"
      }
    ]
  }
}
