{
  "xsize": 16,
  "zsize": 16,
  "slices": [
    [
      "           $!   ",
      "           $!   ",
      "       (   $!   ",
      "           $!   ",
      "           $!   ",
      "           $!   ",
      "!!!!!!!!!! $!   ",
      "         !$$!   ",
      "         !  !   ",
      "         !  !   ",
      "         !  !   ",
      "         !  !!!!",
      "         !      ",
      "         !      ",
      "!!!!!!!!!!      ",
      "                "
    ],
    [
      "           $!   ",
      "           $!   ",
      "           $!   ",
      "       (   $!   ",
      "           $!   ",
      "           $!   ",
      "!!!!!!!!!! $!   ",
      "         !$$!   ",
      "         !  !   ",
      "         !  !   ",
      "         !  !   ",
      "         !  !!!!",
      "         !      ",
      "         !      ",
      "!!!!!!!!!!      ",
      "                "
    ],
    [
      "'''''''''''$!   ",
      "'''''''''''$!   ",
      "'''''''''''$!   ",
      "'''''''''''$!   ",
      "'''''''''''$!   ",
      "'''''''''''$!   ",
      "'''''''''''$!   ",
      "         !$$!   ",
      "         !  !   ",
      "         !  !   ",
      "         !  !   ",
      "         !  !!!!",
      "         !      ",
      "         !      ",
      "!!!!!!!!!!      ",
      "                "
    ],
    [
      "           $!   ",
      "           $!   ",
      "           $!   ",
      "      *    $!   ",
      "        %  $!   ",
      "           $!   ",
      "!!!!!!!!!! $!   ",
      "         !$$!   ",
      "         !  !   ",
      "         !  !   ",
      "         !  !   ",
      "         !  !!!!",
      "         !      ",
      "         !      ",
      "!!!!!!!!!!      ",
      "                "
    ],
    [
      "           $!   ",
      "           $!   ",
      "           $!   ",
      "           $!   ",
      "           $!   ",
      "           $!   ",
      "&&&&&&&&&& $))))",
      "&&&&&&&&&&$$))))",
      "&&&&&&&&&&  ))))",
      "&&&&&&&&&&  ))))",
      "&&&&&&&&&&  ))))",
      "&&&&&&&&&&  ))))",
      "&&&&&&&&&&      ",
      "&&&&&&&&&&      ",
      "&&&&&&&&&&      ",
      "                "
    ],
    [
      "           $!   ",
      "           $!   ",
      "           $!   ",
      "           $!   ",
      "           $!   ",
      "           $!   ",
      "           $    ",
      "$$$$$$$$$$$$    ",
      "                ",
      "                ",
      "                ",
      "                ",
      "                ",
      "                ",
      "                ",
      "                "
    ]
  ],
  "palette": {
    "palette": [
      {
        "char": "!",
        "block": "immersiveengineering:concrete_leaded"
      },
      {
        "char": "$",
        "block": "immersiveengineering:concrete_reinforced"
      },
      {
        "char": "%",
        "block": "minecraft:chest[facing=west,type=single,waterlogged=false]",
        "tag": {
          "id": "minecraft:chest",
          "LootTable": "infinite_domain:chests/wasteland_data"
        }
      },
      {
        "char": "&",
        "block": "minecraft:oxidized_copper"
      },
      {
        "char": "'",
        "block": "minecraft:polished_andesite"
      },
      {
        "char": "(",
        "block": "minecraft:polished_andesite_stairs[facing=south,half=bottom,shape=straight,waterlogged=false]"
      },
      {
        "char": ")",
        "block": "minecraft:weathered_cut_copper"
      },
      {
        "char": "*",
        "block": "the_wasteland_reworked:radio"
      }
    ]
  }
}
