{
  "xsize": 16,
  "zsize": 16,
  "slices": [
    [
      "2222222))'222222",
      "22222))'22222222",
      "222))'2222222222",
      "2))'222222222222",
      ")'22222222222222",
      "2222222222222222",
      "22222222222222))",
      "222222222222))'2",
      "2222222222))'222",
      "22222222))'22222",
      "222222))'2222222",
      "2222))'222222222",
      "22))'22222222222",
      "))'2222222222222",
      "'222222222222222",
      "222222222222222)"
    ],
    [
      "33)))33333333333",
      "33)))33333333333",
      "33))))))33333333",
      "33333)))33333333",
      "33333))))))33333",
      "33333333)))33333",
      "33333333)))33333",
      "3333333333333333",
      "3333333333333333",
      "3333333333333333",
      "3333333333333333",
      "3333333333333333",
      "3333333333333333",
      "3333333333333333",
      "3333333333333333",
      "3333333333333333"
    ],
    [
      "  )))      $!  1",
      "  )))      $!   ",
      "  ))))))&  $!   ",
      "     ),)   $!  1",
      "     ))))))$!   ",
      "  1  1  )))$!!!!",
      "        )))     ",
      "           -    ",
      "!!!!/!!!!!!    1",
      "           $!   ",
      "  +++++++  $!   ",
      "  +++++++  $!  1",
      "           $!   ",
      "   (   %   $!!!!",
      "       *   $!   ",
      "!!!!/!!!!!!$!   "
    ],
    [
      "  )))      $!   ",
      "  )))      $!   ",
      "  ))))))   $!   ",
      "     )))   $!   ",
      "     )))   $!   ",
      "         ! $!!!!",
      "                ",
      "           .    ",
      "!!!!0!!!!!!     ",
      "           $!   ",
      "           $!   ",
      "           $!   ",
      "           $!   ",
      "           $!!!!",
      "           $!   ",
      "!!!!0!!*!!!$!   "
    ],
    [
      "           $!   ",
      "   !       $!   ",
      "     )))   $!   ",
      "     )))   $!   ",
      "     )))   $!   ",
      "           $!!!!",
      "                ",
      "                ",
      "!!!!!!!!!!!     ",
      "           $!   ",
      "           $!   ",
      "           $!   ",
      "           $!   ",
      "           $!!!!",
      "           $!   ",
      "!!!!!!! !!!$!   "
    ],
    [
      "           $!   ",
      "           $!   ",
      "     )))   $!   ",
      "     )))   $!   ",
      "     )))   $!   ",
      "           $!!!!",
      "                ",
      "                ",
      "!!!!!!!!!!!     ",
      "           $!   ",
      "           $!   ",
      "           $!   ",
      "           $!   ",
      "           $!!!!",
      "           $!   ",
      "!!!!!!! !!!$!   "
    ]
  ],
  "palette": {
    "palette": [
      {
        "char": "!",
        "block": "immersiveengineering:concrete_leaded"
      },
      {
        "char": "$",
        "block": "immersiveengineering:concrete_reinforced"
      },
      {
        "char": "%",
        "block": "minecraft:barrel[facing=up,open=false]"
      },
      {
        "char": "&",
        "block": "minecraft:brewing_stand[has_bottle_0=false,has_bottle_1=false,has_bottle_2=false]"
      },
      {
        "char": "'",
        "block": "minecraft:coarse_dirt"
      },
      {
        "char": "(",
        "block": "minecraft:furnace[facing=north,lit=false]"
      },
      {
        "char": ")",
        "block": "minecraft:gravel"
      },
      {
        "char": "*",
        "block": "minecraft:polished_andesite_stairs[facing=south,half=bottom,shape=straight,waterlogged=false]"
      },
      {
        "char": "+",
        "block": "minecraft:smooth_quartz"
      },
      {
        "char": ",",
        "block": "minecraft:spawner",
        "tag": {
          "id": "minecraft:mob_spawner",
          "Delay": 200,
          "MinSpawnDelay": 240,
          "MaxSpawnDelay": 720,
          "SpawnCount": 2,
          "MaxNearbyEntities": 7,
          "RequiredPlayerRange": 14,
          "SpawnRange": 4,
          "SpawnData": {
            "entity": {
              "id": "the_wasteland_reworked:irradiated"
            }
          },
          "SpawnPotentials": [
            {
              "weight": 1,
              "data": {
                "entity": {
                  "id": "the_wasteland_reworked:irradiated"
                }
              }
            }
          ]
        }
      },
      {
        "char": "-",
        "block": "minecraft:spruce_door[facing=east,half=lower,hinge=left,open=false,powered=false]"
      },
      {
        "char": ".",
        "block": "minecraft:spruce_door[facing=east,half=upper,hinge=left,open=false,powered=false]"
      },
      {
        "char": "/",
        "block": "minecraft:spruce_door[facing=south,half=lower,hinge=left,open=false,powered=false]"
      },
      {
        "char": "0",
        "block": "minecraft:spruce_door[facing=south,half=upper,hinge=left,open=false,powered=false]"
      },
      {
        "char": "1",
        "block": "minecraft:water_cauldron[level=3]"
      },
      {
        "char": "2",
        "block": "tfmg:asphalt"
      },
      {
        "char": "3",
        "block": "tfmg:factory_floor"
      }
    ]
  }
}
