{
  "xsize": 16,
  "zsize": 16,
  "slices": [
    [
      ")))''&))))))))))",
      "))'&))))))))))))",
      "))))))))))))))))",
      "))))))))))))))))",
      "))))))))))))))''",
      "))))))))))))''&)",
      "))))))))))''&)))",
      "))))))))''&)))))",
      "))))))''&)))))))",
      "))))''&)))))))))",
      "))''&)))))))))))",
      "''&)))))))))))))",
      "&)))))))))))))))",
      "                ",
      "                ",
      "                "
    ],
    [
      "(((((   ++++++++",
      "(((((   ++++++++",
      "(((((   ++++++++",
      "(((((   ++++++++",
      "(((((   ++++++++",
      "                ",
      "                ",
      "                ",
      "                ",
      "                ",
      "$$$$$$$$$$$$$$$$",
      "                ",
      "                ",
      "                ",
      "                ",
      "                "
    ],
    [
      " ,  $   $     * ",
      "    $   $     * ",
      "  % $   $     * ",
      "    $   $     * ",
      "$$$$$   $$$$$$$$",
      "                ",
      "                ",
      "                ",
      "                ",
      "                ",
      "$$$$$$$$$$$$$$$$",
      "                ",
      "                ",
      "                ",
      "                ",
      "                "
    ],
    [
      "    $   $     * ",
      "    $   $     * ",
      "    $   $     * ",
      "    $   $     * ",
      "$$$$$   $$$$$$$$",
      "                ",
      "                ",
      "                ",
      "                ",
      "                ",
      "$$$$$$$$$$$$$$$$",
      "                ",
      "                ",
      "                ",
      "                ",
      "                "
    ],
    [
      "    $   !     * ",
      "    $   !     * ",
      "    $   $     * ",
      "    $   $     * ",
      "$$$$$   $$$$$$$$",
      "                ",
      "                ",
      "                ",
      "                ",
      "                ",
      "$$$$$$$$$$$$$$$$",
      "                ",
      "                ",
      "                ",
      "                ",
      "                "
    ],
    [
      "    $   !     * ",
      "    $   !     * ",
      "    $   $     * ",
      "    $   $     * ",
      "$$$$$   $$$$$$$$",
      "                ",
      "                ",
      "                ",
      "                ",
      "                ",
      "$$$$$$$$$$$$$$$$",
      "                ",
      "                ",
      "                ",
      "                ",
      "                "
    ]
  ],
  "palette": {
    "palette": [
      {
        "char": "!",
        "block": "create:framed_glass"
      },
      {
        "char": "$",
        "block": "immersiveengineering:concrete_reinforced"
      },
      {
        "char": "%",
        "block": "minecraft:chest[facing=west,type=single,waterlogged=false]",
        "tag": {
          "id": "minecraft:chest",
          "LootTable": "infinite_domain:chests/wasteland_industrial"
        }
      },
      {
        "char": "&",
        "block": "minecraft:coarse_dirt"
      },
      {
        "char": "'",
        "block": "minecraft:gravel"
      },
      {
        "char": "(",
        "block": "minecraft:polished_deepslate"
      },
      {
        "char": ")",
        "block": "tfmg:asphalt"
      },
      {
        "char": "*",
        "block": "tfmg:cinder_block"
      },
      {
        "char": "+",
        "block": "tfmg:factory_floor"
      },
      {
        "char": ",",
        "block": "the_wasteland_reworked:rusted_barrel"
      }
    ]
  }
}
