{
  "xsize": 16,
  "zsize": 16,
  "slices": [
    [
      "**'....         ",
      "'...---         ",
      "....---         ",
      "....---         ",
      ".......         ",
      ".......         ",
      "....---         ",
      "....---         ",
      "....---         ",
      ".......         ",
      "*'.....         ",
      ".......         ",
      ".......         ",
      ".......         ",
      ".......         ",
      ".......         "
    ],
    [
      "///!!           ",
      "*//!!--         ",
      "*///---         ",
      "//**---         ",
      "//**            ",
      "////            ",
      "////---         ",
      "////---         ",
      "///!!--         ",
      "///!!           ",
      "////            ",
      "////            ",
      "                ",
      "                ",
      "                ",
      "                "
    ],
    [
      "$  !!           ",
      "*  !!--         ",
      "*  !---         ",
      "$ **---         ",
      "$ **            ",
      "+!!!            ",
      "   !---         ",
      "   (---         ",
      "   !!--         ",
      "&  !!           ",
      "   !            ",
      "!!!!            ",
      "                ",
      "                ",
      "                ",
      "                "
    ],
    [
      "$  !!           ",
      "*  !!           ",
      "*  !            ",
      "$ $!            ",
      "$  !            ",
      ",!!!            ",
      "   !---         ",
      "%  )---         ",
      "%  !!--         ",
      "   !!           ",
      "   !            ",
      "!!!!            ",
      "                ",
      "                ",
      "                ",
      "                "
    ],
    [
      "$  !!           ",
      "*  !!           ",
      "*  !            ",
      "$  !            ",
      "$  !            ",
      "!!!!            ",
      "   !            ",
      "%  !            ",
      "%  !!           ",
      "   !!           ",
      "   !            ",
      "!!!!            ",
      "                ",
      "                ",
      "                ",
      "                "
    ],
    [
      "                ",
      "                ",
      "                ",
      "                ",
      "                ",
      "                ",
      "   !            ",
      "%  !            ",
      "%  !!           ",
      "   !!           ",
      "   !            ",
      "!!!!            ",
      "                ",
      "                ",
      "                ",
      "                "
    ]
  ],
  "palette": {
    "palette": [
      {
        "char": "!",
        "block": "immersiveengineering:concrete_leaded"
      },
      {
        "char": "$",
        "block": "immersiveengineering:sheetmetal_lead"
      },
      {
        "char": "%",
        "block": "immersiveengineering:sheetmetal_steel"
      },
      {
        "char": "&",
        "block": "minecraft:chest[facing=west,type=single,waterlogged=false]",
        "tag": {
          "id": "minecraft:chest",
          "LootTable": "infinite_domain:chests/wasteland_biohazard"
        }
      },
      {
        "char": "'",
        "block": "minecraft:coarse_dirt"
      },
      {
        "char": "(",
        "block": "minecraft:dark_oak_door[facing=east,half=lower,hinge=left,open=false,powered=false]"
      },
      {
        "char": ")",
        "block": "minecraft:dark_oak_door[facing=east,half=upper,hinge=left,open=false,powered=false]"
      },
      {
        "char": "*",
        "block": "minecraft:gravel"
      },
      {
        "char": "+",
        "block": "minecraft:spruce_door[facing=south,half=lower,hinge=left,open=false,powered=false]"
      },
      {
        "char": ",",
        "block": "minecraft:spruce_door[facing=south,half=upper,hinge=left,open=false,powered=false]"
      },
      {
        "char": "-",
        "block": "minecraft:stone"
      },
      {
        "char": ".",
        "block": "tfmg:asphalt"
      },
      {
        "char": "/",
        "block": "tfmg:factory_floor"
      }
    ]
  }
}
