{
  "xsize": 16,
  "zsize": 16,
  "slices": [
    [
      "      .....     ",
      " .'....'....'..'",
      " ............''%",
      " %.........''%.'",
      " ..........%....",
      " ...............",
      " ....'..........",
      " ..''%..........",
      " ''%............",
      " %.............'",
      " ...............",
      " .............''",
      " ...........''%.",
      " ..........'%...",
      " ...............",
      " %.............'"
    ],
    [
      "&&&&         &&&",
      "&&&           &&",
      "&&&           &&",
      "&&&           &&",
      "&&&           &&",
      "&&&&      /  &&&",
      "&&&      $$$  &&",
      "&&&      $$$  &&",
      "&&&      $$$  &&",
      "&))&))&))$$$&))&",
      "))&))&))&))&))&)",
      ")&))!!!!)****&))",
      "&))&!!!!)****))&",
      "))&))&))&))&))&)",
      ")&))&))&))&))&))",
      "&))&))&))&))&))&"
    ],
    [
      "&&&&         &&&",
      "&&&           &&",
      "&&&           &&",
      "&&&           &&",
      "&&&           &&",
      "&&&&         &&&",
      "&&&      $$$  &&",
      "&&&      $$$  &&",
      "&&&      $$$  &&",
      "&))&))&))$$$&))&",
      "&)&))&))&))&))&)",
      ")&))         &))",
      "&))&         ))&",
      "))&))&))&))&))&)",
      ")&))&))&))&))&))",
      "&))&))&))&))&))&"
    ],
    [
      "&&&&         &&&",
      "&&&           &&",
      "&&&           &&",
      "&&&           &&",
      "&&&           &&",
      "&&&&         &&&",
      "&&&           &&",
      "&&&      (((  &&",
      "&&&     -(((  &&",
      "&&&  )&))&))  &&",
      "&&&& &))&))& &&&",
      "&&))         &))",
      "&))&         ))&",
      "))&))&))&))&))&)",
      ")&))&))&))&))&))",
      "&))&))&))&))&))&"
    ],
    [
      "&&&&         &&&",
      "&&&           &&",
      "&&&           &&",
      "&&&           &&",
      "&&&           &&",
      "&&&&         &&&",
      "&&&           &&",
      "&&&           &&",
      "&&&     -     &&",
      "&&&           &&",
      "&&&&         &&&",
      "&&&  ))&))&)  &&",
      "&))&))&))&))&))&",
      "))&))&))&))&))&)",
      ")&))!!!!!)&))&))",
      "&))&!!!!!&))&))&"
    ],
    [
      "&&&&         &&&",
      "&&&           &&",
      "&&&           &&",
      "&&&           &&",
      "&&&           &&",
      "&&&&         &&&",
      "&&&           &&",
      "&&&           &&",
      "&&&     +     &&",
      "&&&           &&",
      "&&&&         &&&",
      "&&&           &&",
      "&&&, )&))&))  &&",
      "&)&))&))&))&))&)",
      ")&))     )&))&))",
      "&))&     &))&))&"
    ]
  ],
  "palette": {
    "palette": [
      {
        "char": "!",
        "block": "immersiveengineering:concrete_brick_cracked"
      },
      {
        "char": "$",
        "block": "minecraft:blue_concrete"
      },
      {
        "char": "%",
        "block": "minecraft:coarse_dirt"
      },
      {
        "char": "&",
        "block": "minecraft:cobblestone"
      },
      {
        "char": "'",
        "block": "minecraft:gravel"
      },
      {
        "char": "(",
        "block": "minecraft:light_blue_stained_glass"
      },
      {
        "char": ")",
        "block": "minecraft:mossy_cobblestone"
      },
      {
        "char": "*",
        "block": "minecraft:orange_concrete"
      },
      {
        "char": "+",
        "block": "minecraft:orange_wool"
      },
      {
        "char": ",",
        "block": "minecraft:oxidized_copper_grate"
      },
      {
        "char": "-",
        "block": "minecraft:stripped_oak_log[axis=y]"
      },
      {
        "char": ".",
        "block": "tfmg:asphalt"
      },
      {
        "char": "/",
        "block": "the_wasteland_reworked:rusted_barrel"
      }
    ]
  }
}
