{
  "xsize": 16,
  "zsize": 16,
  "slices": [
    [
      "                ",
      "                ",
      "$$$$$$$$$$$     ",
      "   $      $     ",
      "   $      $     ",
      "   $      $     ",
      "   $      $     ",
      "   $      $     ",
      "   $      $     ",
      "   $      $     ",
      "   $$$$$$$$     ",
      "                ",
      "                ",
      "$$$$$$$$$$$     ",
      "          $     ",
      "          $     "
    ],
    [
      "                ",
      "                ",
      "   $$$$$$$$&&&&&",
      "   $      $     ",
      "   $      $     ",
      "   $      $     ",
      "   $      $     ",
      "   $      $     ",
      "   $      $     ",
      "   $      $     ",
      "   $$$$$$$$     ",
      "                ",
      "                ",
      "$$$$$$$$$$$     ",
      "          $     ",
      "          $     "
    ],
    [
      "                ",
      "                ",
      "   $$$$$$$$$$$$$",
      "   $      $$$$$$",
      "   $      $$$$$$",
      "   $      $$$$$$",
      "   $      $$$$$$",
      "   $      $$$$$$",
      "   $      $$$$$$",
      "   $      $$$$$$",
      "   $$$$$$$$     ",
      "                ",
      "                ",
      "$$$$$$$$$$$     ",
      "%%%%%%%%%%$     ",
      "%%%%%%%%%%$     "
    ],
    [
      "                ",
      "                ",
      "   $$$$$$$$$$$$$",
      "   $      $$$$$$",
      "   $      $$$$$$",
      "   $      $$$$$$",
      "   $      $$$$$$",
      "   $      $$$$$$",
      "   $      $$$$$$",
      "   $      $$$$$$",
      "   $$$$$$$$     ",
      "                ",
      "                ",
      "$$$$$$$$$$$     ",
      "          $     ",
      "          $     "
    ],
    [
      "                ",
      "                ",
      "   ''''''''     ",
      "   ''''''''     ",
      "   ''''''''     ",
      "   ''''''''     ",
      "   ''''''''     ",
      "   ''''''''     ",
      "   ''''''''     ",
      "   ''''''''     ",
      "   ''''''''     ",
      "                ",
      "                ",
      "$$$!!$$!!$$     ",
      "          $     ",
      "          $     "
    ],
    [
      "                ",
      "                ",
      "                ",
      "                ",
      "                ",
      "                ",
      "                ",
      "                ",
      "                ",
      "                ",
      "                ",
      "                ",
      "                ",
      "$$$!!$$!!$$     ",
      "          $     ",
      "          $     "
    ]
  ],
  "palette": {
    "palette": [
      {
        "char": "!",
        "block": "create:framed_glass"
      },
      {
        "char": "$",
        "block": "immersiveengineering:concrete_reinforced"
      },
      {
        "char": "%",
        "block": "minecraft:polished_andesite"
      },
      {
        "char": "&",
        "block": "minecraft:stripped_dark_oak_log[axis=x]"
      },
      {
        "char": "'",
        "block": "minecraft:weathered_cut_copper"
      }
    ]
  }
}
