{
  "xsize": 16,
  "zsize": 16,
  "slices": [
    [
      ",,,,,,,         ",
      ",,,,,,,         ",
      ",,,,+++         ",
      ",,,,+++         ",
      ",,,,+++         ",
      ",,,((',         ",
      ",((',,,         ",
      "(',,+++         ",
      ",,,,+++         ",
      ",,,,+++         ",
      ",,,,,,,         ",
      ",,,,,,,         ",
      ",,,,+++         ",
      ",,,,+++         ",
      ",,,,+++         ",
      ",,((',,         "
    ],
    [
      "---$$           ",
      "---$$           ",
      "----+++         ",
      "----+++         ",
      "----+++         ",
      "----            ",
      "----            ",
      "----+++         ",
      "---$$++         ",
      "---$$++         ",
      "----            ",
      "----            ",
      "----+++         ",
      "----+++         ",
      "----+++         ",
      "----            "
    ],
    [
      "%% $$           ",
      "   $$           ",
      "   $+++         ",
      "   $+++         ",
      "   $+++         ",
      ")$$$            ",
      "   $            ",
      "   $+++         ",
      "%% $$++         ",
      "   $$++         ",
      "   $            ",
      "   $            ",
      "   $            ",
      ")$$$            ",
      "   $            ",
      "&  $            "
    ],
    [
      "%% $$           ",
      "   $$           ",
      "   $            ",
      "   $            ",
      "   $            ",
      "*$$$            ",
      "   $            ",
      "   $+++         ",
      "%% $$++         ",
      "   $$++         ",
      "   $            ",
      "   $            ",
      "   $            ",
      "*$$$            ",
      "   $            ",
      "&  $            "
    ],
    [
      "%% $$           ",
      "   $$           ",
      "   !            ",
      "   $            ",
      "   $            ",
      "$$$$            ",
      "   $            ",
      "   $            ",
      "%% $$           ",
      "   $$           ",
      "   !            ",
      "   !            ",
      "   $            ",
      "$$$$            ",
      "   $            ",
      "&  $            "
    ],
    [
      "%% $$           ",
      "   $$           ",
      "   !            ",
      "   $            ",
      "   $            ",
      "$$$$            ",
      "   $            ",
      "   $            ",
      "%% $$           ",
      "   $$           ",
      "   !            ",
      "   !            ",
      "   $            ",
      "$$$$            ",
      "   $            ",
      "&  $            "
    ]
  ],
  "palette": {
    "palette": [
      {
        "char": "!",
        "block": "create:framed_glass"
      },
      {
        "char": "$",
        "block": "immersiveengineering:concrete_leaded"
      },
      {
        "char": "%",
        "block": "immersiveengineering:insulating_glass"
      },
      {
        "char": "&",
        "block": "immersiveengineering:sheetmetal_lead"
      },
      {
        "char": "'",
        "block": "minecraft:coarse_dirt"
      },
      {
        "char": "(",
        "block": "minecraft:gravel"
      },
      {
        "char": ")",
        "block": "minecraft:spruce_door[facing=south,half=lower,hinge=left,open=false,powered=false]"
      },
      {
        "char": "*",
        "block": "minecraft:spruce_door[facing=south,half=upper,hinge=left,open=false,powered=false]"
      },
      {
        "char": "+",
        "block": "minecraft:stone"
      },
      {
        "char": ",",
        "block": "tfmg:asphalt"
      },
      {
        "char": "-",
        "block": "tfmg:factory_floor"
      }
    ]
  }
}
