{
  "xsize": 16,
  "zsize": 16,
  "slices": [
    [
      "           %$   ",
      "           %$   ",
      "           %$   ",
      "           %$   ",
      "           %$   ",
      "           %$   ",
      "           %$   ",
      "           %$   ",
      "           %$   ",
      "           %$   ",
      "           %$   ",
      "           %$   ",
      "           %$   ",
      "           %$   ",
      "           %$   ",
      "           %$   "
    ],
    [
      "           %$   ",
      "           %$   ",
      "           %$   ",
      "           %$   ",
      "           %$   ",
      "           %$   ",
      "           %$   ",
      "           %$   ",
      "           %$   ",
      "           %$   ",
      "           %$   ",
      "           %$   ",
      "           %$   ",
      "           %$   ",
      "           %$   ",
      "           %$   "
    ],
    [
      "(((((((((((%$   ",
      "(((((((((((%$   ",
      "(((((((((((%$   ",
      "(((((((((((%$   ",
      "(((((((((((%$   ",
      "(((((((((((%$   ",
      "(((((((((((%$   ",
      "(((((((((((%$   ",
      "(((((((((((%$   ",
      "(((((((((((%$   ",
      "(((((((((((%$   ",
      "(((((((((((%$   ",
      "(((((((((((%$   ",
      "(((((((((((%$   ",
      "(((((((((((%$   ",
      "(((((((((((%$   "
    ],
    [
      "           %$   ",
      "  ++  ++   %$   ",
      "  ,   ,    %$   ",
      "           %$   ",
      "       '   %$   ",
      "           %$   ",
      "           %$   ",
      "           %$   ",
      "$$$$)$$$$$$%$   ",
      "           %$   ",
      "           %$   ",
      "  &   &    %$   ",
      "   -       %$   ",
      "   ++      %$   ",
      "           %$   ",
      "$$$$)$$$$$$%$   "
    ],
    [
      "           %....",
      "           %....",
      "           %....",
      "           %....",
      "           %....",
      "           %$   ",
      "           %$   ",
      "           %$   ",
      "$$$$*$$$$$$%$   ",
      "           %$   ",
      "           %$   ",
      "           %$   ",
      "           %$   ",
      "           %$   ",
      "           %$   ",
      "$$$$*$$$$$$%$   "
    ],
    [
      "   /       %    ",
      "           %    ",
      "           %    ",
      "           %    ",
      "           %    ",
      "           %$   ",
      "           %$   ",
      "           %$   ",
      "$$$$$$$$$$$%$   ",
      "           %$   ",
      "           %$   ",
      "           !$   ",
      "           !$   ",
      "           %$   ",
      "           %$   ",
      "$$$$$$$$$$$%$   "
    ]
  ],
  "palette": {
    "palette": [
      {
        "char": "!",
        "block": "create:framed_glass"
      },
      {
        "char": "$",
        "block": "immersiveengineering:concrete_leaded"
      },
      {
        "char": "%",
        "block": "immersiveengineering:concrete_reinforced"
      },
      {
        "char": "&",
        "block": "minecraft:bookshelf"
      },
      {
        "char": "'",
        "block": "minecraft:cartography_table"
      },
      {
        "char": "(",
        "block": "minecraft:polished_andesite"
      },
      {
        "char": ")",
        "block": "minecraft:spruce_door[facing=south,half=lower,hinge=left,open=false,powered=false]"
      },
      {
        "char": "*",
        "block": "minecraft:spruce_door[facing=south,half=upper,hinge=left,open=false,powered=false]"
      },
      {
        "char": "+",
        "block": "minecraft:spruce_slab[type=bottom,waterlogged=false]"
      },
      {
        "char": ",",
        "block": "minecraft:spruce_stairs[facing=north,half=bottom,shape=straight,waterlogged=false]"
      },
      {
        "char": "-",
        "block": "minecraft:spruce_stairs[facing=south,half=bottom,shape=straight,waterlogged=false]"
      },
      {
        "char": ".",
        "block": "minecraft:weathered_cut_copper"
      },
      {
        "char": "/",
        "block": "minecraft:weathered_cut_copper_stairs[facing=east,half=bottom,shape=straight,waterlogged=false]"
      }
    ]
  }
}
