{
  "xsize": 16,
  "zsize": 16,
  "slices": [
    [
      "2222**)222222222",
      "22**)22222222222",
      "***2222222222222",
      "***2222222222222",
      "***222222222222*",
      "2222222222222**)",
      "22222222222**)22",
      "***222222**)2222",
      "***2222**)222222",
      "***22**)22222222",
      "222**)2222222222",
      "2**)222222222222",
      "***2222222222222",
      "***2222222222222",
      "***22222222222**",
      "222222222222**)2"
    ],
    [
      "  $$333333333333",
      "  $$333333333333",
      "***3333333333333",
      "***3333333333333",
      "***3333333333333",
      "   3333333333333",
      "   3333333333333",
      "**$$333333333333",
      "**$$333333333333",
      "***3333333333333",
      "   3333333333333",
      "   3333333333333",
      "***3333333333333",
      "***3333333333333",
      "**$$333333333333",
      "  $$333333333333"
    ],
    [
      "  $$ &&&&      $",
      "  $$ &&&&      $",
      "   % &&&&      $",
      "   %           $",
      "   %       (   $",
      "   %           ,",
      "   %           $",
      "**$$           $",
      "**$$$$$$.$$$$$$$",
      "***%           $",
      "   % 0    0    $",
      "   % 1    1    $",
      "***%           $",
      "***%   '       $",
      "**$$  +        $",
      "  $$$$$$.$$$$$$$"
    ],
    [
      "  $$ &&&&      $",
      "  $$ &&&&      $",
      "   % &&&&      $",
      "   %           $",
      "   %           $",
      "   %           -",
      "   %           $",
      "  $$           $",
      "  $$$$$$/$$$$$$$",
      "   %           $",
      "   %           $",
      "   %           $",
      "***%           $",
      "***%           $",
      "**$$           $",
      "  $$$$+$/$$$$$$$"
    ],
    [
      "  $$           $",
      "  $$           $",
      "   %           $",
      "   %           $",
      "   %           $",
      "   %           $",
      "   %           $",
      "  $$           $",
      "  $$$$$$$$$$$$$$",
      "   %           $",
      "   %           $",
      "   !           $",
      "   !           $",
      "   %           $",
      "  $$           $",
      "  $$$$ $$$$$$$$$"
    ],
    [
      "  $$           $",
      "  $$           $",
      "   %           $",
      "   %           $",
      "   %           $",
      "   %           $",
      "   %           $",
      "  $$           $",
      "  $$$$$$$$$$$$$$",
      "   %           $",
      "   %           $",
      "   !           $",
      "   !           $",
      "   %           $",
      "  $$           $",
      "  $$$$ $$$$$$$$$"
    ]
  ],
  "palette": {
    "palette": [
      {
        "char": "!",
        "block": "create:framed_glass"
      },
      {
        "char": "$",
        "block": "immersiveengineering:concrete_leaded"
      },
      {
        "char": "%",
        "block": "immersiveengineering:concrete_reinforced"
      },
      {
        "char": "&",
        "block": "immersiveengineering:crate"
      },
      {
        "char": "'",
        "block": "minecraft:brewing_stand[has_bottle_0=false,has_bottle_1=false,has_bottle_2=false]"
      },
      {
        "char": "(",
        "block": "minecraft:cartography_table"
      },
      {
        "char": ")",
        "block": "minecraft:coarse_dirt"
      },
      {
        "char": "*",
        "block": "minecraft:gravel"
      },
      {
        "char": "+",
        "block": "minecraft:polished_andesite_stairs[facing=south,half=bottom,shape=straight,waterlogged=false]"
      },
      {
        "char": ",",
        "block": "minecraft:spruce_door[facing=east,half=lower,hinge=left,open=false,powered=false]"
      },
      {
        "char": "-",
        "block": "minecraft:spruce_door[facing=east,half=upper,hinge=left,open=false,powered=false]"
      },
      {
        "char": ".",
        "block": "minecraft:spruce_door[facing=south,half=lower,hinge=left,open=false,powered=false]"
      },
      {
        "char": "/",
        "block": "minecraft:spruce_door[facing=south,half=upper,hinge=left,open=false,powered=false]"
      },
      {
        "char": "0",
        "block": "minecraft:white_bed[facing=south,occupied=false,part=foot]"
      },
      {
        "char": "1",
        "block": "minecraft:white_bed[facing=south,occupied=false,part=head]"
      },
      {
        "char": "2",
        "block": "tfmg:asphalt"
      },
      {
        "char": "3",
        "block": "tfmg:factory_floor"
      }
    ]
  }
}
