{
  "xsize": 16,
  "zsize": 16,
  "slices": [
    [
      "&(((((((((((((((",
      "((((((((((((((('",
      "(((((((((((((''&",
      "(((((((((((''&((",
      "(((((((((''&((((",
      "(((((((''&((((((",
      "(((((''&((((((((",
      "(((''&((((((((((",
      "'''&((((((((((((",
      "'''(((((((((((((",
      "'''(((((((((((((",
      "((((((((((((((''",
      "((((((((((((''&(",
      "'''(((((((''&(((",
      "'''(((((''&(((((",
      "'''(((''&((((((("
    ],
    [
      "                ",
      "                ",
      "                ",
      "                ",
      "                ",
      "                ",
      "                ",
      "                ",
      "'''             ",
      "'''             ",
      "'''             ",
      "                ",
      "                ",
      "''')))))))))))))",
      "''')))))))))))))",
      "''')))))))))))))"
    ],
    [
      "                ",
      "                ",
      "                ",
      "                ",
      "                ",
      "                ",
      "                ",
      "                ",
      "'''             ",
      "'''             ",
      "'''             ",
      "                ",
      "                ",
      "'''%%%%%%%%%%%%%",
      "'''%           $",
      "'''%           $"
    ],
    [
      "                ",
      "                ",
      "                ",
      "                ",
      "                ",
      "                ",
      "                ",
      "                ",
      "                ",
      "                ",
      "                ",
      "                ",
      "                ",
      "'''%%%%%%%%%%%%%",
      "'''%           $",
      "'''%           $"
    ],
    [
      "                ",
      "                ",
      "                ",
      "                ",
      "                ",
      "                ",
      "                ",
      "                ",
      "                ",
      "                ",
      "                ",
      "                ",
      "                ",
      "   %%!!%%%!!%%%%",
      "   %           $",
      "   %           $"
    ],
    [
      "                ",
      "                ",
      "                ",
      "                ",
      "                ",
      "                ",
      "                ",
      "                ",
      "                ",
      "                ",
      "                ",
      "                ",
      "                ",
      "   %%!!%%%!!%%%%",
      "   %           $",
      "   %           $"
    ]
  ],
  "palette": {
    "palette": [
      {
        "char": "!",
        "block": "create:framed_glass"
      },
      {
        "char": "$",
        "block": "immersiveengineering:concrete_leaded"
      },
      {
        "char": "%",
        "block": "immersiveengineering:concrete_reinforced"
      },
      {
        "char": "&",
        "block": "minecraft:coarse_dirt"
      },
      {
        "char": "'",
        "block": "minecraft:gravel"
      },
      {
        "char": "(",
        "block": "tfmg:asphalt"
      },
      {
        "char": ")",
        "block": "tfmg:factory_floor"
      }
    ]
  }
}
