{
  "xsize": 16,
  "zsize": 16,
  "slices": [
    [
      "----------------",
      "''------------''",
      "''----------''$-",
      "''--------''$---",
      "--------''$-----",
      "------''$-------",
      "----''$---------",
      "--''$-----------",
      "''$-------------",
      "$---------------",
      "---------------'",
      "-------------''$",
      "-----------''$--",
      "                ",
      "                ",
      "                "
    ],
    [
      "  !     ++++++++",
      "''!     ++++++++",
      "''!     ++++++++",
      "''!     ++++++++",
      "  !     ++++++++",
      "  !******       ",
      "  !******       ",
      "  !******       ",
      "  !******       ",
      "  !******       ",
      "  !******!!!!!!!",
      "                ",
      "                ",
      "                ",
      "                ",
      "                "
    ],
    [
      "  !     !       ",
      "''!     ! ,  (  ",
      "''!     !       ",
      "''!     !       ",
      "  !     !!!!!!!!",
      "  !!!!!!!       ",
      "  !!    !       ",
      "  !!    %       ",
      "  !!    !       ",
      "  !!)   !       ",
      "  !!!!!!!!!!!!!!",
      "                ",
      "                ",
      "                ",
      "                ",
      "                "
    ],
    [
      "  !     !       ",
      "''!     !       ",
      "''!     !       ",
      "''!     !       ",
      "  !     !!!!!!!!",
      "  !!!!!!!       ",
      "  !!    !       ",
      "  !!    &       ",
      "  !!    !       ",
      "  !!)   !       ",
      "  !!!!!!!!!!!!!!",
      "                ",
      "                ",
      "                ",
      "                ",
      "                "
    ],
    [
      "  !     !       ",
      "  !     !       ",
      "  !     !       ",
      "  !     !       ",
      "  !     !!!!!!!!",
      "  !!!!!!!       ",
      "  !!    !       ",
      "  !!    !       ",
      "  !!    !       ",
      "  !!)   !       ",
      "  !!!!!!!!!!!!!!",
      "                ",
      "                ",
      "                ",
      "                ",
      "                "
    ],
    [
      "  !     !       ",
      "  !     !       ",
      "  !     !       ",
      "  !     !       ",
      "  !     !!!!!!!!",
      "  !!!!!!!       ",
      "  !!    !       ",
      "  !!    !       ",
      "  !!    !       ",
      "  !!)   !       ",
      "  !!!!!!!!!!!!!!",
      "                ",
      "                ",
      "                ",
      "                ",
      "                "
    ]
  ],
  "palette": {
    "palette": [
      {
        "char": "!",
        "block": "immersiveengineering:concrete_reinforced"
      },
      {
        "char": "$",
        "block": "minecraft:coarse_dirt"
      },
      {
        "char": "%",
        "block": "minecraft:dark_oak_door[facing=east,half=lower,hinge=left,open=false,powered=false]"
      },
      {
        "char": "&",
        "block": "minecraft:dark_oak_door[facing=east,half=upper,hinge=left,open=false,powered=false]"
      },
      {
        "char": "'",
        "block": "minecraft:gravel"
      },
      {
        "char": "(",
        "block": "minecraft:grindstone[face=floor,facing=south]"
      },
      {
        "char": ")",
        "block": "minecraft:ladder[facing=north,waterlogged=false]"
      },
      {
        "char": "*",
        "block": "minecraft:polished_andesite"
      },
      {
        "char": "+",
        "block": "minecraft:polished_deepslate"
      },
      {
        "char": ",",
        "block": "minecraft:smithing_table"
      },
      {
        "char": "-",
        "block": "tfmg:asphalt"
      }
    ]
  }
}
