{
  "xsize": 16,
  "zsize": 16,
  "slices": [
    [
      "................",
      "..............))",
      "................",
      "..........))....",
      "........))(.....",
      "......))(.......",
      "....))(.........",
      "..))(...........",
      "))(.............",
      "(...............",
      "...............)",
      ".............))(",
      "...........))(..",
      ".........))(....",
      ".......))(......",
      ".....))(........"
    ],
    [
      "////////////////",
      "////////////////",
      "////////////////",
      "////////////////",
      "////////////////",
      "////////////////",
      "////////////////",
      "////////////////",
      "////////////////",
      "////////////////",
      "////////////////",
      "////////////////",
      "                ",
      "                ",
      "                ",
      "                "
    ],
    [
      "    !  %        ",
      "    !  %        ",
      "    *  %   0  ' ",
      "    !  %        ",
      "    !  %%%%%%%%%",
      ",!!!!!!!!!,!!!!!",
      "    !           ",
      "    !  0   0   0",
      "    *           ",
      "    !           ",
      "    !           ",
      "!!!!!!!!!!!!!!!!",
      "                ",
      "                ",
      "                ",
      "                "
    ],
    [
      "    !  $        ",
      "    !  $        ",
      "    +  $        ",
      "    !  $        ",
      "    !  %%%%%%%%%",
      "-!!!!!!!!!-!!!!!",
      "    !           ",
      "    !  &&  &&  &",
      "    +  &&  &&  &",
      "    !           ",
      "    !           ",
      "!!!!!!!!!!!!!!!!",
      "                ",
      "                ",
      "                ",
      "                "
    ],
    [
      "    !  $        ",
      "    !  $        ",
      "    !  $        ",
      "    !  $        ",
      "    !  %%%%%%%%%",
      "!!!!!!!!!!!!!!!!",
      "    !           ",
      "    !  &&  &&  &",
      "    !  &&  &&  &",
      "    !           ",
      "    !           ",
      "!!!!!!!!!!!!!!!!",
      "                ",
      "                ",
      "                ",
      "                "
    ],
    [
      "    !  $        ",
      "    !  $        ",
      "    !  $        ",
      "    !  $        ",
      "    !  %%%%%%%%%",
      "!!!!!!!!!!!!!!!!",
      "    !           ",
      "    !  &&  &&  &",
      "    !  &&  &&  &",
      "    !           ",
      "    !           ",
      "!!!!!!!!!!!!!!!!",
      "                ",
      "                ",
      "                ",
      "                "
    ]
  ],
  "palette": {
    "palette": [
      {
        "char": "!",
        "block": "immersiveengineering:concrete_leaded"
      },
      {
        "char": "$",
        "block": "immersiveengineering:insulating_glass"
      },
      {
        "char": "%",
        "block": "immersiveengineering:sheetmetal_lead"
      },
      {
        "char": "&",
        "block": "immersiveengineering:sheetmetal_steel"
      },
      {
        "char": "'",
        "block": "kubejs:ruined_brewing_stand"
      },
      {
        "char": "(",
        "block": "minecraft:coarse_dirt"
      },
      {
        "char": ")",
        "block": "minecraft:gravel"
      },
      {
        "char": "*",
        "block": "minecraft:spruce_door[facing=east,half=lower,hinge=left,open=false,powered=false]"
      },
      {
        "char": "+",
        "block": "minecraft:spruce_door[facing=east,half=upper,hinge=left,open=false,powered=false]"
      },
      {
        "char": ",",
        "block": "minecraft:spruce_door[facing=south,half=lower,hinge=left,open=false,powered=false]"
      },
      {
        "char": "-",
        "block": "minecraft:spruce_door[facing=south,half=upper,hinge=left,open=false,powered=false]"
      },
      {
        "char": ".",
        "block": "tfmg:asphalt"
      },
      {
        "char": "/",
        "block": "tfmg:factory_floor"
      },
      {
        "char": "0",
        "block": "the_wasteland_reworked:waste_barrel"
      }
    ]
  }
}
