{
  "xsize": 16,
  "zsize": 16,
  "slices": [
    [
      "))33333333&&%333",
      "))333333&&%33333",
      "))3333&&%3333333",
      "))33&&%333333333",
      "))&&%33333333333",
      "))%3333333333333",
      "))33333333333333",
      "223333333333333&",
      "))33333333333&&%",
      "))333333333&&%33",
      "))3333333&&%3333",
      "))33333&&%333333",
      "))333&&%33333333",
      "))3&&%3333333333",
      "))&%333333333333",
      "&&&&&&&333333333"
    ],
    [
      "   /////////////",
      "   /////////////",
      "   /////////////",
      "   /////////////",
      "   /////////////",
      "   /////////////",
      "   /////////////",
      "   /////////////",
      "   /////////////",
      "   /////////////",
      "   /////////////",
      "   /////////////",
      "   /////////////",
      "   /////////////",
      "   /////////////",
      "   /////////////"
    ],
    [
      "   4 00  * $ +  ",
      "   4 1       4  ",
      "   4         4  ",
      "   44444-4444444",
      "   4           4",
      "   4           4",
      "   4 '   '     4",
      "   4 (   (     4",
      "   4           4",
      "   4           +",
      "   4           4",
      "   4 '   '     4",
      "   4 (   (     4",
      "   4           4",
      "   4           4",
      "   4           4"
    ],
    [
      "   4         ,  ",
      "   4         4  ",
      "   4         4  ",
      "   44444.4444444",
      "   4           4",
      "   4           4",
      "   4           4",
      "   4           4",
      "   !           4",
      "   !           ,",
      "   4           4",
      "   4           4",
      "   4           4",
      "   4           4",
      "   4           4",
      "   4           4"
    ],
    [
      "   4         4  ",
      "   4         4  ",
      "   4         4  ",
      "   4444444444444",
      "   4           4",
      "   4           4",
      "   4           4",
      "   4           4",
      "   !           4",
      "   !           4",
      "   4           4",
      "   4           4",
      "   4           4",
      "   4           4",
      "   4           4",
      "   4           4"
    ],
    [
      "   4         4  ",
      "   4         4  ",
      "   4         4  ",
      "   4444444444444",
      "   4           4",
      "   4           4",
      "   4           4",
      "   4           4",
      "   4           4",
      "   4           4",
      "   4           4",
      "   4           4",
      "   4           4",
      "   4           4",
      "   4           4",
      "   4           4"
    ]
  ],
  "palette": {
    "palette": [
      {
        "char": "!",
        "block": "create:framed_glass"
      },
      {
        "char": "$",
        "block": "minecraft:barrel[facing=up,open=false]"
      },
      {
        "char": "%",
        "block": "minecraft:coarse_dirt"
      },
      {
        "char": "&",
        "block": "minecraft:gravel"
      },
      {
        "char": "'",
        "block": "minecraft:green_bed[facing=south,occupied=false,part=foot]"
      },
      {
        "char": "(",
        "block": "minecraft:green_bed[facing=south,occupied=false,part=head]"
      },
      {
        "char": ")",
        "block": "minecraft:polished_andesite"
      },
      {
        "char": "*",
        "block": "kubejs:ruined_smoker[facing=south]"
      },
      {
        "char": "+",
        "block": "minecraft:spruce_door[facing=east,half=lower,hinge=left,open=false,powered=false]"
      },
      {
        "char": ",",
        "block": "minecraft:spruce_door[facing=east,half=upper,hinge=left,open=false,powered=false]"
      },
      {
        "char": "-",
        "block": "minecraft:spruce_door[facing=south,half=lower,hinge=left,open=false,powered=false]"
      },
      {
        "char": ".",
        "block": "minecraft:spruce_door[facing=south,half=upper,hinge=left,open=false,powered=false]"
      },
      {
        "char": "/",
        "block": "minecraft:spruce_planks"
      },
      {
        "char": "0",
        "block": "minecraft:spruce_slab[type=bottom,waterlogged=false]"
      },
      {
        "char": "1",
        "block": "minecraft:spruce_stairs[facing=north,half=bottom,shape=straight,waterlogged=false]"
      },
      {
        "char": "2",
        "block": "minecraft:white_concrete"
      },
      {
        "char": "3",
        "block": "tfmg:asphalt"
      },
      {
        "char": "4",
        "block": "tfmg:cinder_block"
      }
    ]
  }
}
