{
  "xsize": 16,
  "zsize": 16,
  "slices": [
    [
      "/))&////////////",
      ")&//////////////",
      "////////////////",
      "////////////////",
      "//////////////./",
      "//////////)/////",
      "////////))&/////",
      "//////))&///////",
      "////))&/////////",
      "//))&///////////",
      "))&///////////./",
      "&///////////////",
      "////////////////",
      "////////////////",
      "///////////*****",
      "/////////))*****"
    ],
    [
      "                ",
      "                ",
      "$$$********     ",
      "   ********     ",
      "   ********     ",
      "   ********     ",
      "   ********     ",
      "   ********     ",
      "   ********     ",
      "   ********     ",
      "   ********     ",
      "                ",
      "                ",
      "00000000000     ",
      "00000000000     ",
      "00000000000     "
    ],
    [
      "                ",
      "                ",
      "$$$$$$$$$$$     ",
      "   $      $     ",
      "   $      $     ",
      "   $,,  1 $     ",
      "   $-     $     ",
      "   $   +  $     ",
      "   $    % $     ",
      "   $      $     ",
      "   $$$'$$$$     ",
      "                ",
      "                ",
      "$$$$$$$$$$$     ",
      "          $     ",
      "          $     "
    ],
    [
      "                ",
      "                ",
      "$$$$$$$$$$$     ",
      "   $      $     ",
      "   $      $     ",
      "   $      $     ",
      "   $      $     ",
      "   $      $     ",
      "   $      $     ",
      "   $      $     ",
      "   $!!($!!$     ",
      "                ",
      "                ",
      "$$$$$$$$$$$     ",
      "          $     ",
      "          $     "
    ],
    [
      "                ",
      "                ",
      "$$$$$$$$$$$     ",
      "   $      $     ",
      "   $      $     ",
      "   $      $     ",
      "   $      $     ",
      "   $      $     ",
      "   $      $     ",
      "   $      $     ",
      "   $!!$$!!$     ",
      "                ",
      "                ",
      "$$$!!$$!!$$     ",
      "          $     ",
      "          $     "
    ],
    [
      "                ",
      "                ",
      "$$$$$$$$$$$     ",
      "   $      $     ",
      "   $      $     ",
      "   $      $     ",
      "   $      $     ",
      "   $      $     ",
      "   $      $     ",
      "   $      $     ",
      "   $$$$$$$$     ",
      "                ",
      "                ",
      "$$$!!$$!!$$     ",
      "          $     ",
      "          $     "
    ]
  ],
  "palette": {
    "palette": [
      {
        "char": "!",
        "block": "create:framed_glass"
      },
      {
        "char": "$",
        "block": "immersiveengineering:concrete_reinforced"
      },
      {
        "char": "%",
        "block": "immersiveengineering:crate"
      },
      {
        "char": "&",
        "block": "minecraft:coarse_dirt"
      },
      {
        "char": "'",
        "block": "minecraft:dark_oak_door[facing=south,half=lower,hinge=left,open=false,powered=false]"
      },
      {
        "char": "(",
        "block": "minecraft:dark_oak_door[facing=south,half=upper,hinge=left,open=false,powered=false]"
      },
      {
        "char": ")",
        "block": "minecraft:gravel"
      },
      {
        "char": "*",
        "block": "minecraft:polished_andesite"
      },
      {
        "char": "+",
        "block": "minecraft:spawner",
        "tag": {
          "id": "minecraft:mob_spawner",
          "Delay": 240,
          "MinSpawnDelay": 240,
          "MaxSpawnDelay": 720,
          "SpawnCount": 2,
          "MaxNearbyEntities": 10,
          "RequiredPlayerRange": 14,
          "SpawnRange": 4,
          "SpawnData": {
            "entity": {
              "id": "minecraft:pillager"
            }
          },
          "SpawnPotentials": [
            {
              "weight": 1,
              "data": {
                "entity": {
                  "id": "minecraft:pillager"
                }
              }
            }
          ]
        }
      },
      {
        "char": ",",
        "block": "minecraft:spruce_slab[type=bottom,waterlogged=false]"
      },
      {
        "char": "-",
        "block": "minecraft:spruce_stairs[facing=north,half=bottom,shape=straight,waterlogged=false]"
      },
      {
        "char": ".",
        "block": "minecraft:yellow_concrete"
      },
      {
        "char": "/",
        "block": "tfmg:asphalt"
      },
      {
        "char": "0",
        "block": "tfmg:factory_floor"
      },
      {
        "char": "1",
        "block": "the_wasteland_reworked:radio"
      }
    ]
  }
}
