{
  "xsize": 16,
  "zsize": 16,
  "slices": [
    [
      ".......((%...   ",
      ".....((%.....   ",
      "...((%.......   ",
      ".((%.........   ",
      "(%...........   ",
      ".............   ",
      ".............   ",
      "............(   ",
      "..........((%   ",
      "........((%,,   ",
      "......((%..,,   ",
      "....((%....,,   ",
      "..((%........   ",
      "((%..........   ",
      "%..........,,   ",
      "...........,,   "
    ],
    [
      "                ",
      "                ",
      "$$$$$$$$$$$     ",
      "     ******     ",
      "     ******     ",
      "     ******     ",
      "     ******     ",
      "     ******     ",
      "     ******     ",
      "          $,,   ",
      "          $,,   ",
      "          $,,   ",
      "          $     ",
      "++++++++  $     ",
      "++++++++  $,,   ",
      "++++++++  $,,   "
    ],
    [
      "                ",
      "                ",
      "$$$$$$$$$$$     ",
      "     $$$$$$     ",
      "     $    $     ",
      "     $    $     ",
      "     &    $     ",
      "     $)   $     ",
      "     $$$$$$     ",
      "          $,,   ",
      "          $,,   ",
      "          $,,   ",
      "          $     ",
      "////////  $     ",
      "       /  $,,   ",
      " -     /  $,,   "
    ],
    [
      "                ",
      "                ",
      "$$$$$$$$$$$     ",
      "     $$$$$$     ",
      "     $    $     ",
      "     $    $     ",
      "     '    $     ",
      "     $)   $     ",
      "     $$$$$$     ",
      "          $     ",
      "          $     ",
      "          $     ",
      "          $     ",
      "/!!//!!/  $     ",
      "       /  $,,   ",
      "       /  $,,   "
    ],
    [
      "                ",
      "                ",
      "$$$$$$$$$$$     ",
      "     $$$$$$     ",
      "     $    $     ",
      "     $    $     ",
      "     $    $     ",
      "     $)   $     ",
      "     $$$$$$     ",
      "          $     ",
      "          $     ",
      "          $     ",
      "          $     ",
      "/!!//!!/  $     ",
      "       /  $     ",
      "       /  $     "
    ],
    [
      "                ",
      "                ",
      "$$$$$$$$$$$     ",
      "     $$$$$$     ",
      "     $    $     ",
      "     $    $     ",
      "     $    $     ",
      "     $)   $     ",
      "     $$$$$$     ",
      "          $     ",
      "          $     ",
      "          $     ",
      "          $     ",
      "////////  $     ",
      "       /  $     ",
      "       /  $     "
    ]
  ],
  "palette": {
    "palette": [
      {
        "char": "!",
        "block": "create:framed_glass"
      },
      {
        "char": "$",
        "block": "immersiveengineering:concrete_reinforced"
      },
      {
        "char": "%",
        "block": "minecraft:coarse_dirt"
      },
      {
        "char": "&",
        "block": "minecraft:dark_oak_door[facing=west,half=lower,hinge=left,open=false,powered=false]"
      },
      {
        "char": "'",
        "block": "minecraft:dark_oak_door[facing=west,half=upper,hinge=left,open=false,powered=false]"
      },
      {
        "char": "(",
        "block": "minecraft:gravel"
      },
      {
        "char": ")",
        "block": "minecraft:ladder[facing=north,waterlogged=false]"
      },
      {
        "char": "*",
        "block": "minecraft:polished_andesite"
      },
      {
        "char": "+",
        "block": "minecraft:spruce_planks"
      },
      {
        "char": ",",
        "block": "minecraft:stone"
      },
      {
        "char": "-",
        "block": "minecraft:white_bed[facing=south,occupied=false,part=foot]"
      },
      {
        "char": ".",
        "block": "tfmg:asphalt"
      },
      {
        "char": "/",
        "block": "tfmg:cinder_block"
      }
    ]
  }
}
