{
  "xsize": 16,
  "zsize": 16,
  "slices": [
    [
      "          !     ",
      "          !     ",
      "          !     ",
      "          !     ",
      "          !     ",
      "          !     ",
      "%%%%%%%%%%!     ",
      "%         !     ",
      "%         !     ",
      "%         !     ",
      "%         !     ",
      "%         !     ",
      "%         !     ",
      "%         !     ",
      "%         !     ",
      "%         !     "
    ],
    [
      "          !     ",
      "          !     ",
      "          !     ",
      "          !     ",
      "          !     ",
      "          !     ",
      "          !     ",
      "          !     ",
      "          !     ",
      "          !     ",
      "          !     ",
      "          !     ",
      "          !     ",
      "          !     ",
      "          !     ",
      "          !     "
    ],
    [
      "          !     ",
      "          !     ",
      "          !     ",
      "          !     ",
      "          !     ",
      "          !     ",
      "          !     ",
      "          !     ",
      "          !     ",
      "          !     ",
      "          !     ",
      "          !     ",
      "          !     ",
      "          !     ",
      "          !     ",
      "          !     "
    ],
    [
      "          !     ",
      "          !     ",
      "          !     ",
      "          !     ",
      "          !     ",
      "          !     ",
      "          !     ",
      "          !     ",
      "          !     ",
      "          !     ",
      "          !     ",
      "          !     ",
      "          !     ",
      "          !     ",
      "          !     ",
      "          !     "
    ],
    [
      "$$$$$$$$$$$     ",
      "$$$$$$$$$$$     ",
      "$$$$$$$$$$$     ",
      "$$$$$$$$$$$     ",
      "$$$$$$$$$$$     ",
      "$$$$$$$$$$$     ",
      "$$$$$$$$$$$     ",
      "$$$$$$$$$$$     ",
      "$$$$$$$$$$$     ",
      "$$$$$$$$$$$     ",
      "$$$$$$$$$$$     ",
      "$$$$$$$$$$$     ",
      "$$$$$$$$$$$     ",
      "$$$$$$$$$$$     ",
      "$$$$$$$$$$$     ",
      "$$$$$$$$$$$     "
    ],
    [
      "                ",
      "                ",
      "                ",
      "                ",
      "                ",
      "                ",
      "                ",
      "                ",
      "                ",
      "                ",
      "                ",
      "                ",
      "                ",
      "                ",
      "                ",
      "                "
    ]
  ],
  "palette": {
    "palette": [
      {
        "char": "!",
        "block": "immersiveengineering:concrete_reinforced"
      },
      {
        "char": "$",
        "block": "minecraft:weathered_cut_copper"
      },
      {
        "char": "%",
        "block": "tfmg:cinder_block"
      }
    ]
  }
}
