{
  "xsize": 16,
  "zsize": 16,
  "slices": [
    [
      "                ",
      "                ",
      "                ",
      "   !!!!!!!!!!!!!",
      "   !            ",
      "   !            ",
      "   !            ",
      "   !            ",
      "   !            ",
      "   !            ",
      "   !            ",
      "   !            ",
      "   !            ",
      "!!!!            ",
      "   !            ",
      "   !!!!!!!!!!!!!"
    ],
    [
      "                ",
      "       %%%%%%%%%",
      "       %%%%%%%%%",
      "   !!!!%%%%%%%%%",
      "   !   %%%%%%%%%",
      "   !            ",
      "   !            ",
      "   !            ",
      "   !            ",
      "   !            ",
      "   !            ",
      "   !            ",
      "   !            ",
      "!               ",
      "                ",
      "             !!!"
    ],
    [
      "                ",
      "                ",
      "                ",
      "   !!!!!!!!!!!!!",
      "   !            ",
      "   !            ",
      "   !            ",
      "   !            ",
      "   !            ",
      "   !            ",
      "   !            ",
      "   !            ",
      "   !            ",
      "!               ",
      "$               ",
      "$            !!!"
    ],
    [
      "                ",
      "                ",
      "                ",
      "   !!!!!!!!!!!!!",
      "   !            ",
      "   !            ",
      "   !            ",
      "   !            ",
      "   !            ",
      "   !            ",
      "   !            ",
      "   !            ",
      "   !            ",
      "!               ",
      "                ",
      "             !!!"
    ],
    [
      "                ",
      "                ",
      "                ",
      "   !!!!!!!!!!!!!",
      "   !            ",
      "   !            ",
      "   !            ",
      "   !            ",
      "   !            ",
      "   !            ",
      "   !            ",
      "   !            ",
      "   !            ",
      "!               ",
      "                ",
      "             !!!"
    ],
    [
      "                ",
      "                ",
      "   &            ",
      "   &!!!!!!!!!!!!",
      "   &            ",
      "   &            ",
      "   &            ",
      "   &            ",
      "   &            ",
      "   &            ",
      "   &            ",
      "   &            ",
      "   &            ",
      "!               ",
      "                ",
      "             !!!"
    ]
  ],
  "palette": {
    "palette": [
      {
        "char": "!",
        "block": "immersiveengineering:concrete_reinforced"
      },
      {
        "char": "$",
        "block": "minecraft:polished_andesite"
      },
      {
        "char": "%",
        "block": "minecraft:smooth_stone_slab[type=top,waterlogged=false]"
      },
      {
        "char": "&",
        "block": "minecraft:weathered_cut_copper_stairs[facing=east,half=bottom,shape=straight,waterlogged=false]"
      }
    ]
  }
}
