{
  "xsize": 16,
  "zsize": 16,
  "slices": [
    [
      ".............(('",
      "...........(('..",
      ".........(('....",
      ".......(('......",
      ".....(('........",
      "...(('..........",
      ".(('............",
      "('..............",
      "................",
      "..............((",
      "............(('.",
      "..........(('...",
      "........(('.....",
      "......(('.......",
      "....(('.........",
      "..(('..........."
    ],
    [
      "((((************",
      "((((((((((((((**",
      "((((((((((((((**",
      "((((((((((((((**",
      "((((((((((((((**",
      "((((((((((((((**",
      "((((((((((((((**",
      "((((((((((((((**",
      "((((((((((((((**",
      "((((((((((((((((",
      "((((((((((((((((",
      "((((((((((((((((",
      "((((((((((((((((",
      "((((((((((((((((",
      "000*******((((((",
      "000*******(((((("
    ],
    [
      "((((  --        ",
      "((((((((((((((  ",
      "((((((((((((((  ",
      "((((((((((((((  ",
      "((((((((((((((  ",
      "((((((((((((((  ",
      "((((((((((((((/+",
      "((((((((((((((  ",
      "((((((((((((((  ",
      "((((((((((((((((",
      "((((((((((((((((",
      "((((((((((((((((",
      "((((((((((((((((",
      "((((((((((((((((",
      "   &  ))))((((((",
      "!!!&  ))))(((((("
    ],
    [
      "((((            ",
      "((((((((((((((  ",
      "((((((((((((((  ",
      "((((((((((((((  ",
      "((((((((((((((  ",
      "((((((((((((((  ",
      "((((((((((((((/,",
      "((((((((((((((  ",
      "((((((((((((((  ",
      "((((((((((((((  ",
      "(((((((((((((())",
      "(((((((((((((())",
      "(((((((((((((())",
      "(((((((((((((())",
      "   &  ))))))))))",
      "!!!&  ))))))))))"
    ],
    [
      "%%$&            ",
      "((((((((((((((  ",
      "((((((((((((((  ",
      "((((((((((((((  ",
      "((((((((((((((  ",
      "((((((((((((((  ",
      "((((((((((((((//",
      "((((((((((((((  ",
      "((((((((((((((  ",
      "((((((((((((((  ",
      "(((((((((((((())",
      "(((((((((((((())",
      "(((((((((((((())",
      "(((((((((((((())",
      "   &  ))))))))))",
      "!!!&  ))))))))))"
    ],
    [
      "$$$&            ",
      "((((((((((((((  ",
      "((((((((((((((  ",
      "((((((((((((((  ",
      "((((((((((((((  ",
      "((((((((((((((  ",
      "((((((((((((((//",
      "((((((((((((((  ",
      "((((((((((((((  ",
      "((((((((((((((  ",
      "(((((((((((((())",
      "(((((((((((((())",
      "(((((((((((((())",
      "(((((((((((((())",
      "   &  ))))))))))",
      "!!!&  ))))))))))"
    ]
  ],
  "palette": {
    "palette": [
      {
        "char": "!",
        "block": "create:fluid_tank"
      },
      {
        "char": "$",
        "block": "immersiveengineering:sheetmetal_steel"
      },
      {
        "char": "%",
        "block": "minecraft:blast_furnace[facing=north,lit=false]"
      },
      {
        "char": "&",
        "block": "minecraft:bricks"
      },
      {
        "char": "'",
        "block": "minecraft:coarse_dirt"
      },
      {
        "char": "(",
        "block": "minecraft:gravel"
      },
      {
        "char": ")",
        "block": "minecraft:scaffolding"
      },
      {
        "char": "*",
        "block": "minecraft:smooth_stone"
      },
      {
        "char": "+",
        "block": "minecraft:spruce_door[facing=south,half=lower,hinge=left,open=false,powered=false]"
      },
      {
        "char": ",",
        "block": "minecraft:spruce_door[facing=south,half=upper,hinge=left,open=false,powered=false]"
      },
      {
        "char": "-",
        "block": "minecraft:spruce_slab[type=bottom,waterlogged=false]"
      },
      {
        "char": ".",
        "block": "tfmg:asphalt"
      },
      {
        "char": "/",
        "block": "tfmg:cinder_block"
      },
      {
        "char": "0",
        "block": "tfmg:factory_floor"
      }
    ]
  }
}
