{
  "xsize": 16,
  "zsize": 16,
  "slices": [
    [
      "((((((((((''&(((",
      "((((((((''&(((((",
      "((((((''&(((((((",
      "((((''&(((((((((",
      "((''&(((((((((((",
      "''&(((((((((((((",
      "&(((((((((((((((",
      "((((((((((((((('",
      "(((((((((((((''&",
      "(((((((((((''&((",
      "(((((((((''&((((",
      "(((((((''&((((((",
      "(((((''&((((((((",
      "(((''&((((((((((",
      "(''&((((((((((((",
      "'&(((((((((((((("
    ],
    [
      "))))))))))))))))",
      "))))))))))))))))",
      "))))))))))))))))",
      "))))))))))))))))",
      "))))))))))))))))",
      "))))))))))))))))",
      "))))))))))))))))",
      "))))))))))))))))",
      "))))))))))))))))",
      "))))))))))))))))",
      "))))))))))))))))",
      "))))))))))))))))",
      "))))))))))))))))",
      "))))))))))))))))",
      "))))))))))))))))",
      "))))))))))))))))"
    ],
    [
      "***   *****   **",
      "***   *****   **",
      "***   *****   **",
      "***   *****   **",
      "***   *****   **",
      "***   *****   **",
      "***   *****   **",
      "***   *****   **",
      "***   *****   **",
      "                ",
      "                ",
      "                ",
      "                ",
      "                ",
      "                ",
      "!!!   !!!!!   !!"
    ],
    [
      "***   *****   **",
      "***   *****   **",
      "***   *****   **",
      "***   *****   **",
      "***   *****   **",
      "***   *****   **",
      "***   *****   **",
      "***   *****   **",
      "***   *****   **",
      "                ",
      "                ",
      "                ",
      "                ",
      "                ",
      "                ",
      "!!!   !!!!!   !!"
    ],
    [
      "%%$   $%%%$   $%",
      "  $   $   $   $ ",
      "  $   $   $   $ ",
      "  $   $   $   $ ",
      "  $   $   $   $ ",
      "  $   $   $   $ ",
      "  $   $   $   $ ",
      "  $   $   $   $ ",
      "$$$   $$$$$   $$",
      "                ",
      "                ",
      "                ",
      "                ",
      "                ",
      "                ",
      "!!!   !!!!!   !!"
    ],
    [
      "$$$   $$$$$   $$",
      "  $   $   $   $ ",
      "  $   $   $   $ ",
      "  $   $   $   $ ",
      "  $   $   $   $ ",
      "  $   $   $   $ ",
      "  $   $   $   $ ",
      "  $   $   $   $ ",
      "$$$   $$$$$   $$",
      "                ",
      "                ",
      "                ",
      "                ",
      "                ",
      "                ",
      "!!!   !!!!!   !!"
    ]
  ],
  "palette": {
    "palette": [
      {
        "char": "!",
        "block": "create:fluid_tank"
      },
      {
        "char": "$",
        "block": "immersiveengineering:sheetmetal_steel"
      },
      {
        "char": "%",
        "block": "minecraft:blast_furnace[facing=north,lit=false]"
      },
      {
        "char": "&",
        "block": "minecraft:coarse_dirt"
      },
      {
        "char": "'",
        "block": "minecraft:gravel"
      },
      {
        "char": "(",
        "block": "tfmg:asphalt"
      },
      {
        "char": ")",
        "block": "tfmg:factory_floor"
      },
      {
        "char": "*",
        "block": "tfmg:steel_block"
      }
    ]
  }
}
