{
  "xsize": 16,
  "zsize": 16,
  "slices": [
    [
      "                ",
      "                ",
      "                ",
      "                ",
      "    !           ",
      "    !           ",
      "    !           ",
      "    !           ",
      "    !     $$$$$ ",
      "    !     $   $ ",
      "    !     $   $ ",
      "    !     $   $ ",
      "    !     $$$$$ ",
      "    !           ",
      "    !           ",
      "    !           "
    ],
    [
      "                ",
      "                ",
      "                ",
      "                ",
      "    !           ",
      "    !           ",
      "    !           ",
      "    !           ",
      "    !     $$$$$ ",
      "    !     $   $ ",
      "    !     $   $ ",
      "    !     $   $ ",
      "    !     $$$$$ ",
      "    !           ",
      "    !           ",
      "    !           "
    ],
    [
      "                ",
      "                ",
      "                ",
      "                ",
      "    !           ",
      "    !           ",
      "    !           ",
      "    !           ",
      "    !     $$$$$ ",
      "    !     $   $ ",
      "    !     $   $ ",
      "    !     $   $ ",
      "    !     $$$$$ ",
      "    !           ",
      "    !           ",
      "    !           "
    ],
    [
      "                ",
      "                ",
      "                ",
      "                ",
      "    !           ",
      "    !           ",
      "    !           ",
      "    !           ",
      "    !     $$$$$ ",
      "    !     $   $ ",
      "    !     $   $ ",
      "    !     $   $ ",
      "    !     $$$$$ ",
      "    !           ",
      "    !           ",
      "    !           "
    ],
    [
      "                ",
      "                ",
      "                ",
      "                ",
      "    !           ",
      "    !           ",
      "    !           ",
      "    !           ",
      "    !     $$$$$ ",
      "    !     $   $ ",
      "    !     $   $ ",
      "    !     $   $ ",
      "    !     $$$$$ ",
      "    !           ",
      "    !           ",
      "    !           "
    ],
    [
      "                ",
      "                ",
      "                ",
      "                ",
      "%%%%%           ",
      "%%%%%           ",
      "%%%%%           ",
      "%%%%%           ",
      "%%%%%     $$$$$ ",
      "%%%%%     $   $ ",
      "%%%%%     $   $ ",
      "%%%%%     $   $ ",
      "%%%%%     $$$$$ ",
      "%%%%%           ",
      "%%%%%           ",
      "%%%%%           "
    ]
  ],
  "palette": {
    "palette": [
      {
        "char": "!",
        "block": "immersiveengineering:sheetmetal_steel"
      },
      {
        "char": "$",
        "block": "minecraft:bricks"
      },
      {
        "char": "%",
        "block": "minecraft:weathered_cut_copper"
      }
    ]
  }
}
