{
  "xsize": 16,
  "zsize": 16,
  "slices": [
    [
      "/////////////(('",
      "///////////(('//",
      "/////////(('////",
      "///////(('//////",
      "/////(('////////",
      "///(('//////////",
      "/(('////////////",
      "('//////////////",
      "////////////////",
      "//////////////((",
      "////////////(('/",
      "//////////(('///",
      "////////(('/////",
      "//////(('///////",
      "////(('/////////",
      "//(('///////////"
    ],
    [
      "111*************",
      "111*************",
      "111*************",
      "111*************",
      "111*************",
      "111*************",
      "111*************",
      "111*************",
      "111*************",
      "111*************",
      "111*************",
      "111*************",
      "111*************",
      "111*************",
      "111*************",
      "111*************"
    ],
    [
      "222&  --        ",
      "222   .         ",
      "222             ",
      "222             ",
      "222             ",
      "222             ",
      "222 0000+000000+",
      "222             ",
      "222             ",
      "                ",
      "      ))))))))))",
      "      ))))))))))",
      "      ))))))))))",
      "      ))))))))))",
      "   &  ))))))))))",
      "!!!&  ))))))))))"
    ],
    [
      "222&            ",
      "222             ",
      "222             ",
      "222             ",
      "222             ",
      "222             ",
      "222 0000,000000,",
      "222             ",
      "222             ",
      "                ",
      "      ))))))))))",
      "      ))))))))))",
      "      ))))))))))",
      "      ))))))))))",
      "   &  ))))))))))",
      "!!!&  ))))))))))"
    ],
    [
      "%%$&            ",
      "  $             ",
      "  $             ",
      "  $             ",
      "  $             ",
      "  $             ",
      "  $ 000000000000",
      "  $             ",
      "$$$             ",
      "                ",
      "      ))))))))))",
      "      ))))))))))",
      "      ))))))))))",
      "      ))))))))))",
      "   &  ))))))))))",
      "!!!&  ))))))))))"
    ],
    [
      "$$$&            ",
      "  $             ",
      "  $             ",
      "  $             ",
      "  $             ",
      "  $             ",
      "  $ 000000000000",
      "  $             ",
      "$$$             ",
      "                ",
      "      ))))))))))",
      "      ))))))))))",
      "      ))))))))))",
      "      ))))))))))",
      "   &  ))))))))))",
      "!!!&  ))))))))))"
    ]
  ],
  "palette": {
    "palette": [
      {
        "char": "!",
        "block": "create:fluid_tank"
      },
      {
        "char": "$",
        "block": "immersiveengineering:sheetmetal_steel"
      },
      {
        "char": "%",
        "block": "kubejs:ruined_blast_furnace[facing=north]"
      },
      {
        "char": "&",
        "block": "minecraft:bricks"
      },
      {
        "char": "'",
        "block": "minecraft:coarse_dirt"
      },
      {
        "char": "(",
        "block": "minecraft:gravel"
      },
      {
        "char": ")",
        "block": "minecraft:scaffolding"
      },
      {
        "char": "*",
        "block": "minecraft:smooth_stone"
      },
      {
        "char": "+",
        "block": "minecraft:spruce_door[facing=south,half=lower,hinge=left,open=false,powered=false]"
      },
      {
        "char": ",",
        "block": "minecraft:spruce_door[facing=south,half=upper,hinge=left,open=false,powered=false]"
      },
      {
        "char": "-",
        "block": "minecraft:spruce_slab[type=bottom,waterlogged=false]"
      },
      {
        "char": ".",
        "block": "minecraft:spruce_stairs[facing=north,half=bottom,shape=straight,waterlogged=false]"
      },
      {
        "char": "/",
        "block": "tfmg:asphalt"
      },
      {
        "char": "0",
        "block": "tfmg:cinder_block"
      },
      {
        "char": "1",
        "block": "tfmg:factory_floor"
      },
      {
        "char": "2",
        "block": "tfmg:steel_block"
      }
    ]
  }
}
