{
  "xsize": 16,
  "zsize": 16,
  "slices": [
    [
      "      &      $$ ",
      "      &     $$  ",
      "      &     $$  ",
      "      &     $$  ",
      "%%%%%%%%%%%%$   ",
      "           %$   ",
      "           $$   ",
      "           %$   ",
      "           %$   ",
      "           %$$  ",
      "           %$$  ",
      "           %$$  ",
      "           % $$ ",
      "           %  $$",
      "           %  $$",
      "           %   $"
    ],
    [
      "      &      $$ ",
      "      &     $$  ",
      "      &     $$  ",
      "      &     $$  ",
      "''''''''''''$   ",
      "''''''''''''$   ",
      "'''''''''''$$   ",
      "''''''''''''$   ",
      "''''''''''''$   ",
      "''''''''''''$$  ",
      "''''''''''''$$  ",
      "''''''''''''$$  ",
      "'''''''''''' $$ ",
      "''''''''''''  $$",
      "''''''''''''  $$",
      "''''''''''''   $"
    ],
    [
      "      &      $$ ",
      "      &     $$  ",
      "      &     $$  ",
      "      &     $$  ",
      "      &     $   ",
      "&&&&&&&     $   ",
      "           $$   ",
      "            $   ",
      "            $   ",
      "            $$  ",
      "            $$  ",
      "            $$  ",
      "             $$ ",
      "              $$",
      "              $$",
      "               $"
    ],
    [
      "      &      $$ ",
      "      &     $$  ",
      "      &     $$  ",
      "      &     $$  ",
      "      &     $   ",
      "&&&&&&&     $   ",
      "           $$   ",
      "            $   ",
      "            $   ",
      "            $$  ",
      "            $$  ",
      "            $$  ",
      "             $$ ",
      "              $$",
      "              $$",
      "               $"
    ],
    [
      "'''''''      $$ ",
      "'''''''     $$  ",
      "'''''''     $$  ",
      "'''''''     $$  ",
      "'''''''     $   ",
      "'''''''     $   ",
      "           $$   ",
      "            $   ",
      "            $   ",
      "            $$  ",
      "            $$  ",
      "            $$  ",
      "             $$ ",
      "              $$",
      "!!!           $$",
      "!!!            $"
    ],
    [
      "             $$ ",
      "            $$  ",
      "            $$  ",
      "            $$  ",
      "            $   ",
      "            $   ",
      "           $$   ",
      "            $   ",
      "            $   ",
      "            $$  ",
      "            $$  ",
      "            $$  ",
      "             $$ ",
      "              $ ",
      "!!!           $ ",
      "!!!             "
    ]
  ],
  "palette": {
    "palette": [
      {
        "char": "!",
        "block": "create:framed_glass"
      },
      {
        "char": "$",
        "block": "createnuclear:reactor_casing"
      },
      {
        "char": "%",
        "block": "minecraft:light_gray_concrete"
      },
      {
        "char": "&",
        "block": "minecraft:smooth_quartz"
      },
      {
        "char": "'",
        "block": "minecraft:smooth_stone"
      }
    ]
  }
}
