{
  "xsize": 16,
  "zsize": 16,
  "slices": [
    [
      ",,,,,,,%%$,,,,,,",
      ",,,,,%%$,,,,,,,,",
      ",,,%%$,,,,,,,,,,",
      ",%%$,,,,,,,,,,,,",
      "%$,,,,,,,,,,,,,,",
      ",,,,,,,,,,,,,,,,",
      ",,,,,,,,,,,,,,%%",
      ",,,,,,,,,,,,%%$,",
      ",,,,,,,,,,%%$,,,",
      ",,,,,,,,%%$,,,,,",
      ",,,,,,%%$,,,,,,,",
      ",,,,%%$,,,,,,,,,",
      ",,%%$,,,,,,,,,,,",
      "%%$,,,,,,,,,,,,,",
      "$,,,,,,,,,,,,,,,",
      ",,,,,,,,,,,,,,,%"
    ],
    [
      "''''''''''''''''",
      "''''''''''''''''",
      "''''''''''''''''",
      "''''''''''''''''",
      "''''''''''''''''",
      "''''''''''''''''",
      "''''''''''''''''",
      "''''''''''''''''",
      "''''''''''''''''",
      "''''''''''''''''",
      "''''''''''''''''",
      "''''''''''''''''",
      "''''''''''''''''",
      "''''''''''''''''",
      "''''''''''''''''",
      "''''''''''''''''"
    ],
    [
      "                ",
      "                ",
      "                ",
      "                ",
      "&&*&&&&&&&&&*&&&",
      "  &          &  ",
      "  &          &  ",
      "  &          &  ",
      "  &          &  ",
      "  &  &&&&&&& &  ",
      "  &  &&&&&&& &  ",
      "  &  &&&&&&& &  ",
      "  &  &&&&&&& &  ",
      "  (  &&&&&&& (  ",
      "  &  &&&&&&& &  ",
      "  &  &&&&&&& &  "
    ],
    [
      "                ",
      "                ",
      "                ",
      "                ",
      "&&+&&&&&&&&&+&&&",
      "  &          &  ",
      "  &          &  ",
      "  &          &  ",
      "  &          &  ",
      "  &          &  ",
      "  &   !      &  ",
      "  &          &  ",
      "  &     !    &  ",
      "  )          )  ",
      "  &       !  &  ",
      "  &          &  "
    ],
    [
      "                ",
      "                ",
      "                ",
      "                ",
      "&&&&&&&&&&&&&&&&",
      "  &          &  ",
      "  &          &  ",
      "  &          &  ",
      "  &          &  ",
      "  &          &  ",
      "  &          &  ",
      "  &          &  ",
      "  &          &  ",
      "  &          &  ",
      "  &          &  ",
      "  &          &  "
    ],
    [
      "                ",
      "                ",
      "                ",
      "                ",
      "&&&&&&&&&&&&&&&&",
      "  &          &  ",
      "  &          &  ",
      "  &          &  ",
      "  &          &  ",
      "  &          &  ",
      "  &          &  ",
      "  &          &  ",
      "  &          &  ",
      "  &          &  ",
      "  &          &  ",
      "  &          &  "
    ]
  ],
  "palette": {
    "palette": [
      {
        "char": "!",
        "block": "kubejs:ruined_brewing_stand"
      },
      {
        "char": "$",
        "block": "minecraft:coarse_dirt"
      },
      {
        "char": "%",
        "block": "minecraft:gravel"
      },
      {
        "char": "&",
        "block": "minecraft:smooth_quartz"
      },
      {
        "char": "'",
        "block": "minecraft:smooth_stone"
      },
      {
        "char": "(",
        "block": "minecraft:spruce_door[facing=east,half=lower,hinge=left,open=false,powered=false]"
      },
      {
        "char": ")",
        "block": "minecraft:spruce_door[facing=east,half=upper,hinge=left,open=false,powered=false]"
      },
      {
        "char": "*",
        "block": "minecraft:spruce_door[facing=south,half=lower,hinge=left,open=false,powered=false]"
      },
      {
        "char": "+",
        "block": "minecraft:spruce_door[facing=south,half=upper,hinge=left,open=false,powered=false]"
      },
      {
        "char": ",",
        "block": "tfmg:asphalt"
      }
    ]
  }
}
