{
  "xsize": 16,
  "zsize": 16,
  "slices": [
    [
      "++++++++++++++++",
      "++++++++++++++&&",
      "++++++++++++&&%+",
      "++++++++++&&%+++",
      "++++++++&&%+++++",
      "++++++&&%+++++++",
      "++++&&%+++++++++",
      "++&&%+++++++++++",
      "&&%+++++++++++++",
      "%+++++++++++++++",
      "+++++++++++++++&",
      "+++++++++++++&&%",
      "+++++++++++&&%++",
      "+++++++++&&%++++",
      "+++++++&&%++++++",
      "+++++&&%++++++++"
    ],
    [
      "*******      $$ ",
      "*******     $$  ",
      "*******     $$  ",
      "*******     $$  ",
      ",,,,,,,,,,,,$   ",
      ",,,,,,,,,,,,$   ",
      ",,,,,,,,,,,$$   ",
      ",,,,,,,,,,,,$   ",
      ",,,,,,,,,,,,$   ",
      ",,,,,,,,,,,,$$  ",
      ",,,,,,,,,,,,$$  ",
      ",,,,,,,,,,,,$$  ",
      ",,,,,,,,,,,, $$ ",
      ",,,,,,,,,,,,  $$",
      ",,,,,,,,,,,,  $$",
      ",,,,,,,,,,,,   $"
    ],
    [
      "      )      $$ ",
      "(     )     $$  ",
      "      )     $$  ",
      "      )     $$  ",
      "''''''''''''$   ",
      "           '$   ",
      "           $$   ",
      "           '$   ",
      "           '$   ",
      "!!!!!!!!   '$$  ",
      "!!!!!!!!   '$$  ",
      "!!!!!!!!   '$$  ",
      "!!!!!!!!   ' $$ ",
      "!!!!!!!!   '  $$",
      "!!!!!!!!   '  $$",
      "!!!!!!!!   '   $"
    ],
    [
      "      )      $$ ",
      "      )     $$  ",
      "(     )     $$  ",
      "      )     $$  ",
      "''''''''''''$   ",
      "           '$   ",
      "           $$   ",
      "           '$   ",
      "           '$   ",
      "!!!!!!!!   '$$  ",
      "!!!!!!!!   '$$  ",
      "!!!!!!!!   '$$  ",
      "!!!!!!!!   ' $$ ",
      "!!!!!!!!   '  $$",
      "!!!!!!!!   '  $$",
      "!!!!!!!!   '   $"
    ],
    [
      "      )      $$ ",
      "      )     $$  ",
      "      )     $$  ",
      "(     )     $$  ",
      "''''''''''''$   ",
      "           '$   ",
      "           $$   ",
      "           '$   ",
      "           '$   ",
      "!!!!!!!!   '$$  ",
      "!!!!!!!!   '$$  ",
      "!!!!!!!!   '$$  ",
      "!!!!!!!!   ' $$ ",
      "!!!!!!!!   '  $$",
      "!!!!!!!!   '  $$",
      "!!!!!!!!   '   $"
    ],
    [
      "      )      $$ ",
      "      )     $$  ",
      "      )     $$  ",
      "      )     $$  ",
      "('''''''''''$   ",
      "           '$   ",
      "           $$   ",
      "           '$   ",
      "           '$   ",
      "!!!!!!!!   '$$  ",
      "!!!!!!!!   '$$  ",
      "!!!!!!!!   '$$  ",
      "!!!!!!!!   ' $$ ",
      "!!!!!!!!   '  $$",
      "!!!!!!!!   '  $$",
      "!!!!!!!!   '   $"
    ]
  ],
  "palette": {
    "palette": [
      {
        "char": "!",
        "block": "create:fluid_tank"
      },
      {
        "char": "$",
        "block": "createnuclear:reactor_casing"
      },
      {
        "char": "%",
        "block": "minecraft:coarse_dirt"
      },
      {
        "char": "&",
        "block": "minecraft:gravel"
      },
      {
        "char": "'",
        "block": "minecraft:light_gray_concrete"
      },
      {
        "char": "(",
        "block": "minecraft:quartz_stairs[facing=south,half=bottom,shape=straight,waterlogged=false]"
      },
      {
        "char": ")",
        "block": "minecraft:smooth_quartz"
      },
      {
        "char": "*",
        "block": "minecraft:smooth_stone"
      },
      {
        "char": "+",
        "block": "tfmg:asphalt"
      },
      {
        "char": ",",
        "block": "tfmg:factory_floor"
      }
    ]
  }
}
