{
  "xsize": 16,
  "zsize": 16,
  "slices": [
    [
      " )))))))))))))))",
      " )))))))))))))$$",
      " )))))))))))$$!)",
      " !))))))))$$!)))",
      " )))))))$$!)))))",
      " )))))$$!)))))))",
      " )))$$!)))))))))",
      " )$$!)))))))))))",
      " $!)))))))))))))",
      " !))))))))))))))",
      " ))))))))))))))$",
      " ))))))))))))$$!",
      " ))))))))))$$!))",
      " )!))))!)$$!!)))",
      "                ",
      "                "
    ],
    [
      "     ***********",
      "     ***********",
      "     ***********",
      "     ***********",
      "     ***********",
      "     ***********",
      "     ***********",
      "     ***********",
      "     ***********",
      "     ***********",
      "                ",
      "                ",
      "                ",
      "                ",
      "                ",
      "                "
    ],
    [
      "     '  ((((((((",
      "     '  ((((((((",
      "     '  ((((((((",
      "     '  ((((((((",
      "     '  ((((((((",
      "     '  ((((((((",
      "     '          ",
      "     '          ",
      "     '          ",
      "     '''''''%'''",
      "                ",
      "                ",
      "                ",
      "                ",
      "                ",
      "                "
    ],
    [
      "     '  ((((((((",
      "     '  ((((((((",
      "     '  ((((((((",
      "     '  ((((((((",
      "     '  ((((((((",
      "     '  ((((((((",
      "     '          ",
      "     '          ",
      "     '          ",
      "     '''''''&'''",
      "                ",
      "                ",
      "                ",
      "                ",
      "                ",
      "                "
    ],
    [
      "     '  ((((((((",
      "     '  ((((((((",
      "     '  ((((((((",
      "     '  ((((((((",
      "     '  ((((((((",
      "     '  ((((((((",
      "     '          ",
      "     '          ",
      "     '          ",
      "     '''''''''''",
      "                ",
      "                ",
      "                ",
      "                ",
      "                ",
      "                "
    ],
    [
      "     '  ((((((((",
      "     '  ((((((((",
      "     '  ((((((((",
      "     '  ((((((((",
      "     '  ((((((((",
      "     '  ((((((((",
      "     '          ",
      "     '          ",
      "     '          ",
      "     '''''''''''",
      "                ",
      "                ",
      "                ",
      "                ",
      "                ",
      "                "
    ]
  ],
  "palette": {
    "palette": [
      {
        "char": "!",
        "block": "minecraft:coarse_dirt"
      },
      {
        "char": "$",
        "block": "minecraft:gravel"
      },
      {
        "char": "%",
        "block": "minecraft:iron_door[facing=south,half=lower,hinge=left,open=false,powered=false]"
      },
      {
        "char": "&",
        "block": "minecraft:iron_door[facing=south,half=upper,hinge=left,open=false,powered=false]"
      },
      {
        "char": "'",
        "block": "minecraft:light_gray_concrete"
      },
      {
        "char": "(",
        "block": "minecraft:scaffolding"
      },
      {
        "char": ")",
        "block": "tfmg:asphalt"
      },
      {
        "char": "*",
        "block": "tfmg:factory_floor"
      }
    ]
  }
}
