{
  "xsize": 16,
  "zsize": 16,
  "slices": [
    [
      "-------%%$------",
      "-----%%$--------",
      "---%%$----------",
      "-%%$------------",
      "%$--------------",
      "----------------",
      "--------------%%",
      "------------%%$-",
      "----------%%$---",
      "--------%%$-----",
      "------%%$-------",
      "----%%$---------",
      "--%%$-----------",
      "%%$-------------",
      "$---------------",
      "---------------%"
    ],
    [
      "''''''''''''''''",
      "''''''''''''''''",
      "''''''''''''''''",
      "''''''''''''''''",
      "''''''''''''''''",
      "''''''''''''''''",
      "''''''''''''''''",
      "''''''''''''''''",
      "''''''''''''''''",
      "''''''''''''''''",
      "''''''''''''''''",
      "''''''''''''''''",
      "''''''''''''''''",
      "''''''''''''''''",
      "''''''''''''''''",
      "''''''''''''''''"
    ],
    [
      "                ",
      "                ",
      "                ",
      "                ",
      "&&+&&&&&&&&&+&&&",
      "  &          &  ",
      "  &          &  ",
      "  &          &  ",
      "  &          &  ",
      "  &  &&&&&&& &  ",
      "  &  &&&&&&& &  ",
      "  &  &&&&&&& &  ",
      "  &  &&&&&(& &  ",
      "  )  &&&&&&& )  ",
      "  &  &&&&&&& &  ",
      "  &  &&&&&&& &  "
    ],
    [
      "                ",
      "                ",
      "                ",
      "                ",
      "&&,&&&&&&&&&,&&&",
      "  &          &  ",
      "  &          &  ",
      "  &          &  ",
      "  &          &  ",
      "  &          &  ",
      "  &   !      &  ",
      "  &          &  ",
      "  &     !    &  ",
      "  *          *  ",
      "  &       !  &  ",
      "  &          &  "
    ],
    [
      "                ",
      "                ",
      "                ",
      "                ",
      "&&&&&&&&&&&&&&&&",
      "  &          &  ",
      "  &          &  ",
      "  &          &  ",
      "  &          &  ",
      "  &          &  ",
      "  &          &  ",
      "  &          &  ",
      "  &          &  ",
      "  &          &  ",
      "  &          &  ",
      "  &          &  "
    ],
    [
      "                ",
      "                ",
      "                ",
      "                ",
      "&&&&&&&&&&&&&&&&",
      "  &          &  ",
      "  &          &  ",
      "  &          &  ",
      "  &          &  ",
      "  &          &  ",
      "  &          &  ",
      "  &          &  ",
      "  &          &  ",
      "  &          &  ",
      "  &          &  ",
      "  &          &  "
    ]
  ],
  "palette": {
    "palette": [
      {
        "char": "!",
        "block": "minecraft:brewing_stand[has_bottle_0=false,has_bottle_1=false,has_bottle_2=false]"
      },
      {
        "char": "$",
        "block": "minecraft:coarse_dirt"
      },
      {
        "char": "%",
        "block": "minecraft:gravel"
      },
      {
        "char": "&",
        "block": "minecraft:smooth_quartz"
      },
      {
        "char": "'",
        "block": "minecraft:smooth_stone"
      },
      {
        "char": "(",
        "block": "minecraft:spawner",
        "tag": {
          "id": "minecraft:mob_spawner",
          "Delay": 200,
          "MinSpawnDelay": 240,
          "MaxSpawnDelay": 720,
          "SpawnCount": 4,
          "MaxNearbyEntities": 9,
          "RequiredPlayerRange": 14,
          "SpawnRange": 4,
          "SpawnData": {
            "entity": {
              "id": "minecraft:pillager"
            }
          },
          "SpawnPotentials": [
            {
              "weight": 1,
              "data": {
                "entity": {
                  "id": "minecraft:pillager"
                }
              }
            }
          ]
        }
      },
      {
        "char": ")",
        "block": "minecraft:spruce_door[facing=east,half=lower,hinge=left,open=false,powered=false]"
      },
      {
        "char": "*",
        "block": "minecraft:spruce_door[facing=east,half=upper,hinge=left,open=false,powered=false]"
      },
      {
        "char": "+",
        "block": "minecraft:spruce_door[facing=south,half=lower,hinge=left,open=false,powered=false]"
      },
      {
        "char": ",",
        "block": "minecraft:spruce_door[facing=south,half=upper,hinge=left,open=false,powered=false]"
      },
      {
        "char": "-",
        "block": "tfmg:asphalt"
      }
    ]
  }
}
