{
  "xsize": 16,
  "zsize": 16,
  "slices": [
    [
      "''&(((((((((((((",
      "&(((((((((((((((",
      "((((((((((((((('",
      "(((((((((((((''&",
      "(((((((((((''&((",
      "(((((((((''&((((",
      "(((((((''&((((((",
      "(((((''&((((((((",
      "(((''&((((((((((",
      "(''&((((((((((((",
      "'&((((((((((((((",
      "((((((((((((((((",
      "((((((((((((((''",
      "((((((((((((''&(",
      "((((((((((''&(((",
      "((((((((''&((((("
    ],
    [
      "                ",
      "   %%%%%%%%%%%  ",
      "   %%%%%%%%%%%  ",
      "   %%%%%%%%%%%  ",
      "   %%%%%%%%%%%  ",
      "   %%%%%%%%%%%  ",
      "   %%%%%%%%%%%  ",
      "   %%%%%%%%%%%  ",
      "   %%%%%%%%%%%  ",
      "   %%%%%%%%%%%  ",
      "   %%%%%%%%%%%  ",
      "   %%%%%%%%%%%  ",
      "                ",
      "                ",
      "                ",
      "!!             !"
    ],
    [
      "                ",
      "   %%%%%%%%%%%  ",
      "   %%%%%%%%%%%  ",
      "   %%%%%%%%%%%  ",
      "   %%%%%%%%%%%  ",
      "   %%%%%%%%%%%  ",
      "   %%%%%%%%%%%  ",
      "   %%%%%%%%%%%  ",
      "   %%%%%%%%%%%  ",
      "   %%%%%%%%%%%  ",
      "   %%%%%%%%%%%  ",
      "   %%%%%%%%%%%  ",
      "                ",
      "                ",
      "                ",
      "!!             !"
    ],
    [
      "                ",
      "   %%%%%%%%%%%  ",
      "   %%%%%%%%%%%  ",
      "   %%%%%%%%%%%  ",
      "   %%%%%%%%%%%  ",
      "   %%%%%%%%%%%  ",
      "   %%%%%%%%%%%  ",
      "   %%%%%%%%%%%  ",
      "   %%%%%%%%%%%  ",
      "   %%%%%%%%%%%  ",
      "   %%%%%%%%%%%  ",
      "   %%%%%%%%%%%  ",
      "                ",
      "                ",
      "                ",
      "!!             !"
    ],
    [
      "                ",
      "                ",
      "                ",
      "     $$$$$$$    ",
      "     $$$$$$$    ",
      "     $$$$$$$    ",
      "     $$$$$$$    ",
      "     $$$$$$$    ",
      "     $$$$$$$    ",
      "     $$$$$$$    ",
      "                ",
      "                ",
      "                ",
      "                ",
      "                ",
      "!!             !"
    ],
    [
      "                ",
      "                ",
      "                ",
      "     $$$$$$$    ",
      "     $$$$$$$    ",
      "     $$$$$$$    ",
      "     $$$$$$$    ",
      "     $$$$$$$    ",
      "     $$$$$$$    ",
      "     $$$$$$$    ",
      "                ",
      "                ",
      "                ",
      "                ",
      "                ",
      "!!             !"
    ]
  ],
  "palette": {
    "palette": [
      {
        "char": "!",
        "block": "createnuclear:reactor_casing"
      },
      {
        "char": "$",
        "block": "createnuclear:reactor_core"
      },
      {
        "char": "%",
        "block": "createnuclear:reactor_frame"
      },
      {
        "char": "&",
        "block": "minecraft:coarse_dirt"
      },
      {
        "char": "'",
        "block": "minecraft:gravel"
      },
      {
        "char": "(",
        "block": "tfmg:asphalt"
      }
    ]
  }
}
