{
  "xsize": 16,
  "zsize": 16,
  "slices": [
    [
      "                ",
      "                ",
      "                ",
      "     %%%%%%%    ",
      "     %%%%%%%    ",
      "     %%%%%%%    ",
      "     %%%%%%%    ",
      "     %%%%%%%    ",
      "     %%%%%%%    ",
      "     %%%%%%%    ",
      "                ",
      "                ",
      "                ",
      "                ",
      "                ",
      "!!             !"
    ],
    [
      "                ",
      "                ",
      "                ",
      "     %%%%%%%    ",
      "     %%%%%%%    ",
      "     %%%%%%%    ",
      "     %%%%%%%    ",
      "     %%%%%%%    ",
      "     %%%%%%%    ",
      "     %%%%%%%    ",
      "                ",
      "                ",
      "                ",
      "                ",
      "                ",
      "!!             !"
    ],
    [
      "                ",
      "                ",
      "                ",
      "     %%%%%%%    ",
      "     %%%%%%%    ",
      "     %%%%%%%    ",
      "     %%%%%%%    ",
      "     %%%%%%%    ",
      "     %%%%%%%    ",
      "     %%%%%%%    ",
      "                ",
      "                ",
      "                ",
      "                ",
      "                ",
      "!!             !"
    ],
    [
      "                ",
      "                ",
      "                ",
      "     %%%%%%%    ",
      "     %%%%%%%    ",
      "     %%%%%%%    ",
      "     %%%%%%%    ",
      "     %%%%%%%    ",
      "     %%%%%%%    ",
      "     %%%%%%%    ",
      "                ",
      "                ",
      "                ",
      "                ",
      "                ",
      "!!             !"
    ],
    [
      "                ",
      "                ",
      "                ",
      "     %%%%%%%    ",
      "     %%%%%%%    ",
      "     %%%%%%%    ",
      "     %%%%%%%    ",
      "     %%%%%%%    ",
      "     %%%%%%%    ",
      "     %%%%%%%    ",
      "                ",
      "                ",
      "                ",
      "                ",
      "                ",
      "!!             !"
    ],
    [
      "                ",
      "                ",
      "                ",
      "                ",
      "                ",
      "                ",
      "        $       ",
      "                ",
      "                ",
      "                ",
      "                ",
      "                ",
      "                ",
      "                ",
      "                ",
      "!!             !"
    ]
  ],
  "palette": {
    "palette": [
      {
        "char": "!",
        "block": "createnuclear:reactor_casing"
      },
      {
        "char": "$",
        "block": "createnuclear:reactor_controller"
      },
      {
        "char": "%",
        "block": "createnuclear:reactor_core"
      }
    ]
  }
}
