{
  "xsize": 16,
  "zsize": 16,
  "slices": [
    [
      "++++++++++&&%+++",
      "++++++++&&%+++++",
      "++++++&&%+++++++",
      "++++&&%+++++++++",
      "++&&%+++++++++++",
      "&&%+++++++++++++",
      "%+++++++++++++++",
      "+++++++++++++++&",
      "+++++++++++++&&%",
      "+++++++++++&&%++",
      "+++++++++&&%++++",
      "+++++++&&%++++++",
      "+++++&&%++++++++",
      "+++&&%++++++++++",
      "+&&%++++++++++++",
      "&%++++++++++++++"
    ],
    [
      "(((((((         ",
      "(((((((         ",
      "(((((((         ",
      "(((((((         ",
      "(((((((         ",
      "(((((((         ",
      "(((((((         ",
      "(((((((         ",
      "(((((((         ",
      "(((((((         ",
      "(((((((         ",
      "(((((((         ",
      "(((((((         ",
      "(((((((        !",
      "(((((((       !!",
      "(((((((       !!"
    ],
    [
      "      '         ",
      "      '         ",
      "      '         ",
      "      '         ",
      "''')'''         ",
      "      '         ",
      "      '         ",
      "      '         ",
      "      '         ",
      "'''''''         ",
      "'''''''         ",
      "'''''''         ",
      "'''''''         ",
      "'''''''        !",
      "'''''''       !!",
      "'''''''       !!"
    ],
    [
      "      '         ",
      "      '         ",
      "      '         ",
      "      '         ",
      "'''*'''         ",
      "      '         ",
      "      '         ",
      "      '         ",
      "      '         ",
      "      '         ",
      " $    '         ",
      "      '         ",
      "   $  '         ",
      "      '        !",
      "     $'       !!",
      "      '       !!"
    ],
    [
      "      '         ",
      "      '         ",
      "      '         ",
      "      '         ",
      "'''''''         ",
      "      '         ",
      "      '         ",
      "      '         ",
      "      '         ",
      "      '         ",
      "      '         ",
      "      '         ",
      "      '         ",
      "      '        !",
      "      '       !!",
      "      '       !!"
    ],
    [
      "      '         ",
      "      '         ",
      "      '         ",
      "      '         ",
      "'''''''         ",
      "      '         ",
      "      '         ",
      "      '         ",
      "      '         ",
      "      '         ",
      "      '         ",
      "      '         ",
      "      '         ",
      "      '        !",
      "      '       !!",
      "      '       !!"
    ]
  ],
  "palette": {
    "palette": [
      {
        "char": "!",
        "block": "createnuclear:reactor_casing"
      },
      {
        "char": "$",
        "block": "minecraft:brewing_stand[has_bottle_0=false,has_bottle_1=false,has_bottle_2=false]"
      },
      {
        "char": "%",
        "block": "minecraft:coarse_dirt"
      },
      {
        "char": "&",
        "block": "minecraft:gravel"
      },
      {
        "char": "'",
        "block": "minecraft:smooth_quartz"
      },
      {
        "char": "(",
        "block": "minecraft:smooth_stone"
      },
      {
        "char": ")",
        "block": "minecraft:spruce_door[facing=south,half=lower,hinge=left,open=false,powered=false]"
      },
      {
        "char": "*",
        "block": "minecraft:spruce_door[facing=south,half=upper,hinge=left,open=false,powered=false]"
      },
      {
        "char": "+",
        "block": "tfmg:asphalt"
      }
    ]
  }
}
