{
  "xsize": 16,
  "zsize": 16,
  "slices": [
    [
      "                ",
      "                ",
      "                ",
      "     $$$$$$$    ",
      "     $$$$$$$    ",
      "     $$$%%%%%%%%",
      "     $$$%%%%%%%%",
      "     $$$%%%%%%%%",
      "     $$$%%%%%%%%",
      "     $$$%%%%%%%%",
      "        %%%%%%%%",
      "        %%%%%%%%",
      "        %%%%%%%%",
      "        %%%%%%%%",
      "        %%%%%%%%",
      "!!      %%%%%%%%"
    ],
    [
      "                ",
      "                ",
      "                ",
      "     $$$$$$$    ",
      "     $$$$$$$    ",
      "     $$$$$$$    ",
      "     $$$$$$$    ",
      "     $$$$$$$    ",
      "     $$$$$$$    ",
      "     $$$$$$$    ",
      "                ",
      "                ",
      "                ",
      "                ",
      "                ",
      "!!             !"
    ],
    [
      "                ",
      "                ",
      "                ",
      "     $$$$$$$    ",
      "     $$$$$$$    ",
      "     $$$$$$$    ",
      "     $$$$$$$    ",
      "     $$$$$$$    ",
      "     $$$$$$$    ",
      "     $$$$$$$    ",
      "                ",
      "                ",
      "                ",
      "                ",
      "                ",
      "!!             !"
    ],
    [
      "                ",
      "                ",
      "&&              ",
      "&&   $$$$$$$    ",
      "&&   $$$$$$$    ",
      "&&   $$$$$$$    ",
      "&&   $$$$$$$    ",
      "&&   $$$$$$$    ",
      "&&   $$$$$$$    ",
      "&&   $$$$$$$    ",
      "&&              ",
      "                ",
      "                ",
      "                ",
      "                ",
      "!!             !"
    ],
    [
      "                ",
      "                ",
      "&&              ",
      "&&   $$$$$$$    ",
      "&&   $$$$$$$    ",
      "&&   $$$$$$$    ",
      "&&   $$$$$$$    ",
      "&&   $$$$$$$    ",
      "&&   $$$$$$$    ",
      "&&   $$$$$$$    ",
      "&&              ",
      "                ",
      "                ",
      "                ",
      "                ",
      "!!             !"
    ],
    [
      "                ",
      "                ",
      "&&              ",
      "&&   $$$$$$$    ",
      "&&   $$$$$$$    ",
      "&&   $$$$$$$    ",
      "&&   $$$$$$$    ",
      "&&   $$$$$$$    ",
      "&&   $$$$$$$    ",
      "&&   $$$$$$$    ",
      "&&              ",
      "                ",
      "                ",
      "                ",
      "                ",
      "!!             !"
    ]
  ],
  "palette": {
    "palette": [
      {
        "char": "!",
        "block": "createnuclear:reactor_casing"
      },
      {
        "char": "$",
        "block": "createnuclear:reactor_core"
      },
      {
        "char": "%",
        "block": "minecraft:gravel"
      },
      {
        "char": "&",
        "block": "minecraft:smooth_stone"
      }
    ]
  }
}
