{
  "xsize": 16,
  "zsize": 16,
  "slices": [
    [
      "                ",
      "                ",
      "     %%%%%%%    ",
      "     %     %    ",
      "     %     %    ",
      "     %     %    ",
      "     %     %    ",
      "     %     %    ",
      "     %     !    ",
      "     %     %    ",
      "     %     %    ",
      "     %     %    ",
      "     %     %    ",
      "     %%%%%%%    ",
      "                ",
      "                "
    ],
    [
      "                ",
      "                ",
      "     %%%%%%%    ",
      "     %     %    ",
      "     %     %    ",
      "     %     %    ",
      "     %     %    ",
      "     %     %    ",
      "     %     $    ",
      "     %     %    ",
      "     %     %    ",
      "     %     %    ",
      "     %     %    ",
      "     %%%%%%%    ",
      "                ",
      "                "
    ],
    [
      "                ",
      "                ",
      "     %%%%%%%    ",
      "     %     %    ",
      "     %     %    ",
      "     %     %    ",
      "     %     %    ",
      "     %     %    ",
      "     %     %    ",
      "     %     %    ",
      "     %     %    ",
      "     %     %    ",
      "     %     %    ",
      "     %%%%%%%    ",
      "                ",
      "                "
    ],
    [
      "                ",
      "                ",
      "     &&&&&&&    ",
      "     &&&&&&&    ",
      "     &&&&&&&    ",
      "     &&&&&&&    ",
      "     &&&&&&&    ",
      "     &&&&&&&    ",
      "     &&&&&&&    ",
      "     &&&&&&&    ",
      "     &&&&&&&    ",
      "     &&&&&&&    ",
      "     &&&&&&&    ",
      "     &&&&&&&    ",
      "                ",
      "                "
    ],
    [
      "                ",
      "                ",
      "                ",
      "                ",
      "                ",
      "                ",
      "                ",
      "                ",
      "                ",
      "                ",
      "                ",
      "                ",
      "                ",
      "                ",
      "                ",
      "                "
    ]
  ],
  "palette": {
    "palette": [
      {
        "char": "!",
        "block": "minecraft:iron_door[facing=east,half=lower,hinge=left,open=false,powered=false]"
      },
      {
        "char": "$",
        "block": "minecraft:iron_door[facing=east,half=upper,hinge=left,open=false,powered=false]"
      },
      {
        "char": "%",
        "block": "minecraft:mud_bricks"
      },
      {
        "char": "&",
        "block": "minecraft:smooth_stone"
      }
    ]
  }
}
