{
  "xsize": 16,
  "zsize": 16,
  "slices": [
    [
      "................",
      "..............&&",
      "............&&%.",
      "..........&&%...",
      "........&&%.....",
      "......&&%.......",
      "....&&%.........",
      "..&&%...........",
      "&&%.............",
      "%...............",
      "...............&",
      ".............&&%",
      "...........&&%..",
      ".........&&%....",
      ".......&&%......",
      ".....&&%........"
    ],
    [
      "----------------",
      "----------------",
      "---0000000000---",
      "---0000000000---",
      "!!-0000000000---",
      "!!-0000000000---",
      "---0000000000---",
      "---0000000000---",
      "---0000000000---",
      "---0000000000---",
      "---0000000000---",
      "---0000000000---",
      "---0000000000---",
      "---0000000000---",
      "!!--------!!----",
      "!!        !!    "
    ],
    [
      "                ",
      "                ",
      "   //////////   ",
      "   /        /   ",
      "!! /        /   ",
      "!! /   ,  ' /   ",
      "   /        /   ",
      "   (        /   ",
      "   )        /   ",
      "   /        /   ",
      "   /  $$$$$ /   ",
      "   /  $$$$$ /   ",
      "   /  $$$$$ /   ",
      "   //////////   ",
      "!!!!!!!!!!!!!!!!",
      "!!        !!    "
    ],
    [
      "                ",
      "                ",
      "   //////////   ",
      "   /        /   ",
      "!! /        /   ",
      "!! /        /   ",
      "   /        /   ",
      "   *        /   ",
      "   +        /   ",
      "   /        /   ",
      "   /  $$$$$ /   ",
      "   /  $$$$$ /   ",
      "   /  $$$$$ /   ",
      "   //////////   ",
      "!!!!!!!!!!!!!!!!",
      "!!        !!    "
    ],
    [
      "                ",
      "                ",
      "   //////////   ",
      "   /        /   ",
      "!! /        /   ",
      "!! /        /   ",
      "   /        /   ",
      "            /   ",
      "            /   ",
      "   /        /   ",
      "   /  $$$$$ /   ",
      "   /  $$$$$ /   ",
      "   /  $$$$$ /   ",
      "   //////////   ",
      "!!        !!    ",
      "!!        !!    "
    ],
    [
      "                ",
      "                ",
      "   //////////   ",
      "   /        /   ",
      "!! /        /   ",
      "!! /        /   ",
      "   /        /   ",
      "   /        /   ",
      "   /        /   ",
      "   /        /   ",
      "   /        /   ",
      "   /        /   ",
      "   /        /   ",
      "   //////////   ",
      "!!        !!    ",
      "!!        !!    "
    ]
  ],
  "palette": {
    "palette": [
      {
        "char": "!",
        "block": "immersiveengineering:concrete_reinforced"
      },
      {
        "char": "$",
        "block": "immersiveengineering:crate"
      },
      {
        "char": "%",
        "block": "minecraft:coarse_dirt"
      },
      {
        "char": "&",
        "block": "minecraft:gravel"
      },
      {
        "char": "'",
        "block": "minecraft:grindstone[face=floor,facing=south]"
      },
      {
        "char": "(",
        "block": "minecraft:iron_door[facing=west,half=lower,hinge=left,open=false,powered=false]"
      },
      {
        "char": ")",
        "block": "minecraft:iron_door[facing=west,half=lower,hinge=right,open=false,powered=false]"
      },
      {
        "char": "*",
        "block": "minecraft:iron_door[facing=west,half=upper,hinge=left,open=false,powered=false]"
      },
      {
        "char": "+",
        "block": "minecraft:iron_door[facing=west,half=upper,hinge=right,open=false,powered=false]"
      },
      {
        "char": ",",
        "block": "minecraft:smithing_table"
      },
      {
        "char": "-",
        "block": "minecraft:smooth_stone"
      },
      {
        "char": ".",
        "block": "tfmg:asphalt"
      },
      {
        "char": "/",
        "block": "tfmg:cinder_block"
      },
      {
        "char": "0",
        "block": "tfmg:factory_floor"
      }
    ]
  }
}
