{
  "xsize": 16,
  "zsize": 16,
  "slices": [
    [
      "                ",
      "                ",
      "        &     & ",
      "         %%%%%% ",
      "    !!          ",
      "    !!      !!  ",
      "                ",
      "                ",
      "                ",
      "                ",
      "                ",
      "                ",
      "                ",
      "                ",
      "    !!      !!  ",
      "    !!      !!  "
    ],
    [
      "                ",
      "        ))))))))",
      "        ))))))))",
      "        ))))))))",
      "    !!  ))))))))",
      "    !!  ))))))))",
      "                ",
      "                ",
      "                ",
      "                ",
      "                ",
      "                ",
      "                ",
      "                ",
      "    !!      !!  ",
      "    !!      !!  "
    ],
    [
      "                ",
      "                ",
      "                ",
      "                ",
      "    !!''''''!!''",
      "    !!''''''!!''",
      "    ''''''''''''",
      "    ''''''''''''",
      "    ''''''''''''",
      "    ''''''''''''",
      "    ''''''''''''",
      "    ''''''''''''",
      "    ''''''''''''",
      "    ''''''''''''",
      "    !!''''''!!''",
      "    !!''''''!!''"
    ],
    [
      "                ",
      "                ",
      "                ",
      "                ",
      "    !!!!!!!!!!!!",
      "    !!      !!  ",
      "    !           ",
      "    !  * $ $ *  ",
      "    !  *+++++*  ",
      "    !  *+++++*  ",
      "    !  *+++++*  ",
      "    !  * $ $ *  ",
      "    !           ",
      "    !           ",
      "    !!      !!  ",
      "    !!      !!  "
    ],
    [
      "                ",
      "                ",
      "                ",
      "                ",
      "    !!!!!!!!!!!!",
      "    !!      !!  ",
      "    !           ",
      "    !           ",
      "    !    (((    ",
      "    !    (((    ",
      "    !    (((    ",
      "    !           ",
      "    !           ",
      "    !           ",
      "    !!      !!  ",
      "    !!      !!  "
    ],
    [
      "                ",
      "                ",
      "                ",
      "                ",
      "    !!      !!  ",
      "    !!      !!  ",
      "                ",
      "                ",
      "                ",
      "                ",
      "                ",
      "                ",
      "                ",
      "                ",
      "    !!      !!  ",
      "    !!      !!  "
    ]
  ],
  "palette": {
    "palette": [
      {
        "char": "!",
        "block": "immersiveengineering:concrete_reinforced"
      },
      {
        "char": "$",
        "block": "minecraft:black_concrete"
      },
      {
        "char": "%",
        "block": "minecraft:lime_terracotta"
      },
      {
        "char": "&",
        "block": "minecraft:polished_blackstone_bricks"
      },
      {
        "char": "'",
        "block": "minecraft:smooth_stone"
      },
      {
        "char": "(",
        "block": "minecraft:tinted_glass"
      },
      {
        "char": ")",
        "block": "minecraft:weathered_cut_copper"
      },
      {
        "char": "*",
        "block": "minecraft:white_carpet"
      },
      {
        "char": "+",
        "block": "minecraft:yellow_terracotta"
      }
    ]
  }
}
