{
  "xsize": 16,
  "zsize": 16,
  "slices": [
    [
      "                ",
      "                ",
      "     '''''''    ",
      "     '     '    ",
      "    !'     '!!  ",
      "    !'     '!!  ",
      "     '     '    ",
      "     '  )  '    ",
      "     '     '    ",
      "     '     '    ",
      "     '     '    ",
      "     '     '    ",
      "     '     '    ",
      "     '''''''    ",
      "    !!      !!  ",
      "    !!      !!  "
    ],
    [
      "                ",
      "                ",
      "     '''''''    ",
      "     '     '    ",
      "    !'     '!!  ",
      "    !'     '!!  ",
      "     '     '    ",
      "     '     '    ",
      "     '  )  '    ",
      "     '     '    ",
      "     '     '    ",
      "     '     '    ",
      "     '     '    ",
      "     '''''''    ",
      "    !!      !!  ",
      "    !!      !!  "
    ],
    [
      "                ",
      "                ",
      "     '''''''    ",
      "     '     '    ",
      "    !'     '!!  ",
      "    !'     '!!  ",
      "     '     '    ",
      "     '     '    ",
      "     '     '    ",
      "     '  )  '    ",
      "     '     '    ",
      "     '     '    ",
      "     '     '    ",
      "     '''''''    ",
      "    !!      !!  ",
      "    !!      !!  "
    ],
    [
      "    ************",
      "    ************",
      "    *'''''''****",
      "    *'((((('****",
      "    !'((((('!!**",
      "    !'((((('!!**",
      "    *'((((('****",
      "    *'((((('****",
      "    *'(( (('****",
      "    *'(( (('****",
      "    *'((((('****",
      "    *'((((('****",
      "    *'((((('****",
      "    *'''''''****",
      "    !!******!!**",
      "    !!      !!  "
    ],
    [
      "    !  + $ $ +  ",
      "    !           ",
      "    !'''''''    ",
      "    !'     '    ",
      "    !'  )  '!!  ",
      "    !'     '!!  ",
      "    !'     '    ",
      "    !'     '    ",
      "    !'     %    ",
      "    !'     '    ",
      "    !'     '    ",
      "    !'     '    ",
      "    !'     '    ",
      "    !'''''''    ",
      "    !!!!!!!!!!!!",
      "    !!      !!  "
    ],
    [
      "    !           ",
      "    !           ",
      "    !'''''''    ",
      "    !'     '    ",
      "    !'     '!!  ",
      "    !'  )  '!!  ",
      "    !'     '    ",
      "    !'     '    ",
      "    !'     &    ",
      "    !'     '    ",
      "    !'     '    ",
      "    !'     '    ",
      "    !'     '    ",
      "    !'''''''    ",
      "    !!!!!!!!!!!!",
      "    !!      !!  "
    ]
  ],
  "palette": {
    "palette": [
      {
        "char": "!",
        "block": "immersiveengineering:concrete_reinforced"
      },
      {
        "char": "$",
        "block": "minecraft:black_concrete"
      },
      {
        "char": "%",
        "block": "minecraft:iron_door[facing=east,half=lower,hinge=left,open=false,powered=false]"
      },
      {
        "char": "&",
        "block": "minecraft:iron_door[facing=east,half=upper,hinge=left,open=false,powered=false]"
      },
      {
        "char": "'",
        "block": "minecraft:mud_bricks"
      },
      {
        "char": "(",
        "block": "minecraft:polished_andesite"
      },
      {
        "char": ")",
        "block": "minecraft:polished_andesite_stairs[facing=south,half=bottom,shape=straight,waterlogged=false]"
      },
      {
        "char": "*",
        "block": "minecraft:smooth_stone"
      },
      {
        "char": "+",
        "block": "minecraft:white_carpet"
      }
    ]
  }
}
