{
  "xsize": 16,
  "zsize": 16,
  "slices": [
    [
      "2222222222&&%222",
      "22222222&&%22222",
      "222222&&%2222222",
      "2222&&%222222222",
      "22&&%22222222222",
      "&&%2222222222222",
      "%222222222222222",
      "222222222222222&",
      "2222222222222&&%",
      "22222222222&&%22",
      "222222222&&%2222",
      "2222222&&%222222",
      "22222&&%22222222",
      "222&&%2222222222",
      "2&&%222222222222",
      "&%22222222222222"
    ],
    [
      "    000000000000",
      "    000000000000",
      "    0.......0000",
      "    0.......0000",
      "    !.......!!00",
      "    !.......!!00",
      "    0.......0000",
      "    0.......0000",
      "    0.......0000",
      "    0.......0000",
      "    0.......0000",
      "    0.......0000",
      "    0.......0000",
      "    0.......0000",
      "    !!000000!!00",
      "    !!      !!  "
    ],
    [
      "    !  1 $ $ 1  ",
      "    !           ",
      "    !-------    ",
      "    !-     -    ",
      "    !-  /  -!!  ",
      "    !-     -!!  ",
      "    !-     -    ",
      "    !-     -    ",
      "    !-     '    ",
      "    !-     -    ",
      "    !-     -    ",
      "    !-     -    ",
      "    !-     -    ",
      "    !--)* --    ",
      "    !!!!!!!!!!!!",
      "    !!      !!  "
    ],
    [
      "    !           ",
      "    !           ",
      "    !-------    ",
      "    !-     -    ",
      "    !-     -!!  ",
      "    !-  /  -!!  ",
      "    !-     -    ",
      "    !-     -    ",
      "    !-     (    ",
      "    !-     -    ",
      "    !-     -    ",
      "    !-     -    ",
      "    !-     -    ",
      "    !--+, --    ",
      "    !!!!!!!!!!!!",
      "    !!      !!  "
    ],
    [
      "                ",
      "                ",
      "     -------    ",
      "     -     -    ",
      "    !-     -!!  ",
      "    !-     -!!  ",
      "     -  /  -    ",
      "     -     -    ",
      "     -     -    ",
      "     -     -    ",
      "     -     -    ",
      "     -     -    ",
      "     -     -    ",
      "     --   --    ",
      "    !!      !!  ",
      "    !!      !!  "
    ],
    [
      "                ",
      "                ",
      "     -------    ",
      "     -     -    ",
      "    !-     -!!  ",
      "    !-     -!!  ",
      "     -     -    ",
      "     -  /  -    ",
      "     -     -    ",
      "     -     -    ",
      "     -     -    ",
      "     -     -    ",
      "     -     -    ",
      "     -------    ",
      "    !!      !!  ",
      "    !!      !!  "
    ]
  ],
  "palette": {
    "palette": [
      {
        "char": "!",
        "block": "immersiveengineering:concrete_reinforced"
      },
      {
        "char": "$",
        "block": "minecraft:black_concrete"
      },
      {
        "char": "%",
        "block": "minecraft:coarse_dirt"
      },
      {
        "char": "&",
        "block": "minecraft:gravel"
      },
      {
        "char": "'",
        "block": "minecraft:iron_door[facing=east,half=lower,hinge=left,open=false,powered=false]"
      },
      {
        "char": "(",
        "block": "minecraft:iron_door[facing=east,half=upper,hinge=left,open=false,powered=false]"
      },
      {
        "char": ")",
        "block": "minecraft:iron_door[facing=south,half=lower,hinge=left,open=false,powered=false]"
      },
      {
        "char": "*",
        "block": "minecraft:iron_door[facing=south,half=lower,hinge=right,open=false,powered=false]"
      },
      {
        "char": "+",
        "block": "minecraft:iron_door[facing=south,half=upper,hinge=left,open=false,powered=false]"
      },
      {
        "char": ",",
        "block": "minecraft:iron_door[facing=south,half=upper,hinge=right,open=false,powered=false]"
      },
      {
        "char": "-",
        "block": "minecraft:mud_bricks"
      },
      {
        "char": ".",
        "block": "minecraft:polished_andesite"
      },
      {
        "char": "/",
        "block": "minecraft:polished_andesite_stairs[facing=south,half=bottom,shape=straight,waterlogged=false]"
      },
      {
        "char": "0",
        "block": "minecraft:smooth_stone"
      },
      {
        "char": "1",
        "block": "minecraft:white_carpet"
      },
      {
        "char": "2",
        "block": "tfmg:asphalt"
      }
    ]
  }
}
