{
  "xsize": 16,
  "zsize": 16,
  "slices": [
    [
      "             (((",
      "             (  ",
      "             (  ",
      "             (  ",
      "             (  ",
      "             (  ",
      "             (  ",
      "             (  ",
      "             (  ",
      "!!        !! (  ",
      "!!        !! (  ",
      "             (  ",
      "             (((",
      "                ",
      "                ",
      "                "
    ],
    [
      "             (((",
      "             (  ",
      "             (  ",
      "             (  ",
      "             (  ",
      "             (  ",
      "             (  ",
      "             (  ",
      "             (  ",
      "!!        !! (  ",
      "!!        !! (  ",
      "             (  ",
      "             (((",
      "                ",
      "                ",
      "                "
    ],
    [
      "+++++++++++++(((",
      "+++++++++++++())",
      "+++++++++++++())",
      "+++++++++++++())",
      "+++++++++++++())",
      "+++++++++++++())",
      "+++++++++++++())",
      "+++++++++++++())",
      "+++++++++++++())",
      "!!++++++++!!+())",
      "!!++++++++!!+())",
      "+++++++++++++())",
      "+++++++++++++(((",
      "++++++++++++++++",
      "++++++++++++++++",
      "++++++++++++++++"
    ],
    [
      "             (((",
      "- $ $ -      (  ",
      "-%%%%%-      (  ",
      "-%%%%%-      (  ",
      "-%%%%%-      (  ",
      "- $ $ -      (  ",
      "             &  ",
      "             (  ",
      "             (  ",
      "!!        !! (  ",
      "!!        !! (  ",
      "             (  ",
      "- $ $ -      (((",
      "-*****-         ",
      "-*****-         ",
      "-*****-         "
    ],
    [
      "             (((",
      "             (  ",
      "  ,,,        (  ",
      "  ,,,        (  ",
      "  ,,,        (  ",
      "             (  ",
      "             '  ",
      "             (  ",
      "             (  ",
      "!!        !! (  ",
      "!!        !! (  ",
      "             (  ",
      "             (((",
      "  ,,,           ",
      "  ,,,           ",
      "  ,,,           "
    ],
    [
      "             (((",
      "             (  ",
      "             (  ",
      "             (  ",
      "             (  ",
      "             (  ",
      "             (  ",
      "             (  ",
      "             (  ",
      "!!        !! (  ",
      "!!        !! (  ",
      "             (  ",
      "             (((",
      "                ",
      "                ",
      "                "
    ]
  ],
  "palette": {
    "palette": [
      {
        "char": "!",
        "block": "immersiveengineering:concrete_reinforced"
      },
      {
        "char": "$",
        "block": "minecraft:black_concrete"
      },
      {
        "char": "%",
        "block": "minecraft:green_terracotta"
      },
      {
        "char": "&",
        "block": "minecraft:iron_door[facing=west,half=lower,hinge=left,open=false,powered=false]"
      },
      {
        "char": "'",
        "block": "minecraft:iron_door[facing=west,half=upper,hinge=left,open=false,powered=false]"
      },
      {
        "char": "(",
        "block": "minecraft:light_gray_concrete"
      },
      {
        "char": ")",
        "block": "minecraft:polished_andesite"
      },
      {
        "char": "*",
        "block": "minecraft:red_terracotta"
      },
      {
        "char": "+",
        "block": "minecraft:smooth_stone"
      },
      {
        "char": ",",
        "block": "minecraft:tinted_glass"
      },
      {
        "char": "-",
        "block": "minecraft:white_carpet"
      }
    ]
  }
}
