{
  "xsize": 16,
  "zsize": 16,
  "slices": [
    [
      "             '''",
      "             '  ",
      "             '  ",
      "             '  ",
      "             '  ",
      "             '  ",
      "             '  ",
      "             '  ",
      "             '  ",
      "$$        $$ '  ",
      "$$        $$ '  ",
      "             '  ",
      "             '''",
      "                ",
      "                ",
      "                "
    ],
    [
      "             '''",
      "             '  ",
      "             '  ",
      "             '  ",
      "             '  ",
      "             '  ",
      "             '  ",
      "             '  ",
      "             '  ",
      "$$        $$ '  ",
      "$$        $$ '  ",
      "             '  ",
      "             '''",
      "                ",
      "                ",
      "                "
    ],
    [
      "*************'''",
      "*************'((",
      "*************'((",
      "*************'((",
      "*************'((",
      "*************'((",
      "                ",
      "                ",
      "                ",
      "                ",
      "                ",
      "                ",
      "                ",
      "                ",
      "                ",
      "                "
    ],
    [
      "             '''",
      "- % % -      '  ",
      "-&&&&&-      '  ",
      "-&&&&&-      '  ",
      "-&&&&&-      '  ",
      "- % % -      '  ",
      "                ",
      "****************",
      "****************",
      "****************",
      "****************",
      "****************",
      "****************",
      "****************",
      "****************",
      "****************"
    ],
    [
      "             '''",
      "             '  ",
      "  ,,,        '  ",
      "  ,,,        '  ",
      "  ,,,        '  ",
      "             '  ",
      "                ",
      "!               ",
      "!               ",
      "                ",
      "                ",
      "                ",
      "   %            ",
      "  )))))         ",
      "  )))))         ",
      "  ))))+         "
    ],
    [
      "             '''",
      "             '  ",
      "             '  ",
      "             '  ",
      "             '  ",
      "             '  ",
      "                ",
      "!               ",
      "!               ",
      "                ",
      "                ",
      "                ",
      "                ",
      "  )))))         ",
      "  )))))         ",
      "  )))))         "
    ]
  ],
  "palette": {
    "palette": [
      {
        "char": "!",
        "block": "immersiveengineering:concrete_brick_cracked"
      },
      {
        "char": "$",
        "block": "immersiveengineering:concrete_reinforced"
      },
      {
        "char": "%",
        "block": "minecraft:black_concrete"
      },
      {
        "char": "&",
        "block": "minecraft:green_terracotta"
      },
      {
        "char": "'",
        "block": "minecraft:light_gray_concrete"
      },
      {
        "char": "(",
        "block": "minecraft:polished_andesite"
      },
      {
        "char": ")",
        "block": "minecraft:red_terracotta"
      },
      {
        "char": "*",
        "block": "minecraft:smooth_stone"
      },
      {
        "char": "+",
        "block": "minecraft:spawner",
        "tag": {
          "id": "minecraft:mob_spawner",
          "Delay": 200,
          "MinSpawnDelay": 240,
          "MaxSpawnDelay": 720,
          "SpawnCount": 2,
          "MaxNearbyEntities": 8,
          "RequiredPlayerRange": 14,
          "SpawnRange": 4,
          "SpawnData": {
            "entity": {
              "id": "minecraft:zombie"
            }
          },
          "SpawnPotentials": [
            {
              "weight": 1,
              "data": {
                "entity": {
                  "id": "minecraft:zombie"
                }
              }
            }
          ]
        }
      },
      {
        "char": ",",
        "block": "minecraft:tinted_glass"
      },
      {
        "char": "-",
        "block": "minecraft:white_carpet"
      }
    ]
  }
}
