{
  "xsize": 16,
  "zsize": 16,
  "slices": [
    [
      "////////////////",
      "//////////////''",
      "////////////''&/",
      "//////////''&///",
      "////////''&/////",
      "//////''&///////",
      "////''&/////////",
      "//''&///////////",
      "''&/////////////",
      "&///////////////",
      "///////////////'",
      "/////////////''&",
      "///////////''&//",
      "/////////''&////",
      "///////''&//////",
      "/////''&////////"
    ],
    [
      "................",
      "................",
      "...1111111111...",
      "...1111111111...",
      "!!.1111111111...",
      "!!.1111111111...",
      "...1111111111...",
      "...1111111111...",
      "...1111111111...",
      "...1111111111...",
      "...1111111111...",
      "...11''''1111...",
      "...11''''1111...",
      "...11''''1111...",
      "!!...''''.!!....",
      "!!        !!    "
    ],
    [
      "                ",
      "                ",
      "   0000000000   ",
      "   0        0   ",
      "!! 0        0   ",
      "!! 0   -  ( 0   ",
      "   0        0   ",
      "   )        0   ",
      "   *        0   ",
      "   0        0   ",
      "   0  $$$$$ 0   ",
      "   0 ''%'$$ 0   ",
      "   0 ''''$$ 0   ",
      "   00''''0000   ",
      "!!!!!''''!!!!!!!",
      "!!        !!    "
    ],
    [
      "                ",
      "                ",
      "   0000000000   ",
      "   0        0   ",
      "!! 0        0   ",
      "!! 0        0   ",
      "   0        0   ",
      "   +        0   ",
      "   ,        0   ",
      "   0        0   ",
      "   0  $$$$$ 0   ",
      "   0 ''''$$ 0   ",
      "   0 ''''$$ 0   ",
      "   00''''0000   ",
      "!!!!!''''!!!!!!!",
      "!!        !!    "
    ],
    [
      "                ",
      "                ",
      "   0000000000   ",
      "   0        0   ",
      "!! 0        0   ",
      "!! 0        0   ",
      "   0        0   ",
      "            0   ",
      "            0   ",
      "   0        0   ",
      "   0  $$$$$ 0   ",
      "   0 ''''$$ 0   ",
      "   0 ''''$$ 0   ",
      "   00''''0000   ",
      "!!   '''' !!    ",
      "!!        !!    "
    ],
    [
      "                ",
      "                ",
      "   0000000000   ",
      "   0        0   ",
      "!! 0        0   ",
      "!! 0        0   ",
      "   0        0   ",
      "   0        0   ",
      "   0        0   ",
      "   0        0   ",
      "   0        0   ",
      "   0 ''''   0   ",
      "   0 ''''   0   ",
      "   00''''0000   ",
      "!!   '''' !!    ",
      "!!        !!    "
    ]
  ],
  "palette": {
    "palette": [
      {
        "char": "!",
        "block": "immersiveengineering:concrete_reinforced"
      },
      {
        "char": "$",
        "block": "immersiveengineering:crate"
      },
      {
        "char": "%",
        "block": "minecraft:chest[facing=north,type=single,waterlogged=false]",
        "tag": {
          "id": "minecraft:chest",
          "LootTable": "infinite_domain:chests/wasteland_industrial"
        }
      },
      {
        "char": "&",
        "block": "minecraft:coarse_dirt"
      },
      {
        "char": "'",
        "block": "minecraft:gravel"
      },
      {
        "char": "(",
        "block": "minecraft:grindstone[face=floor,facing=south]"
      },
      {
        "char": ")",
        "block": "minecraft:iron_door[facing=west,half=lower,hinge=left,open=false,powered=false]"
      },
      {
        "char": "*",
        "block": "minecraft:iron_door[facing=west,half=lower,hinge=right,open=false,powered=false]"
      },
      {
        "char": "+",
        "block": "minecraft:iron_door[facing=west,half=upper,hinge=left,open=false,powered=false]"
      },
      {
        "char": ",",
        "block": "minecraft:iron_door[facing=west,half=upper,hinge=right,open=false,powered=false]"
      },
      {
        "char": "-",
        "block": "minecraft:smithing_table"
      },
      {
        "char": ".",
        "block": "minecraft:smooth_stone"
      },
      {
        "char": "/",
        "block": "tfmg:asphalt"
      },
      {
        "char": "0",
        "block": "tfmg:cinder_block"
      },
      {
        "char": "1",
        "block": "tfmg:factory_floor"
      }
    ]
  }
}
