{
  "xsize": 16,
  "zsize": 16,
  "slices": [
    [
      "                ",
      "                ",
      "                ",
      "  ''''''''''    ",
      "  '        '    ",
      "  '  !!!!  '    ",
      "  '  !!!!  '    ",
      "  '  !!!!  '    ",
      "  $  !!!!  '    ",
      "  '  !!!!  '    ",
      "  '        '    ",
      "  '        '    ",
      "  ''''''''''    ",
      "                ",
      "                ",
      "                "
    ],
    [
      "                ",
      "                ",
      "                ",
      "  ''''''''''    ",
      "  '        '    ",
      "  '  !!!!  '    ",
      "  '  !!!!  '    ",
      "  '  !!!!  '    ",
      "  %  !!!!  '    ",
      "  '  !!!!  '    ",
      "  '        '    ",
      "  '        '    ",
      "  ''''''''''    ",
      "                ",
      "                ",
      "                "
    ],
    [
      "                ",
      "                ",
      "                ",
      "  ''''''''''    ",
      "  '        '    ",
      "  '  !!!!  '    ",
      "  '  !!!!  '    ",
      "  '  !!!!  '    ",
      "  '  !!!!  '    ",
      "  '  !!!!  '    ",
      "  '        '    ",
      "  '        '    ",
      "  ''''''''''    ",
      "                ",
      "                ",
      "                "
    ],
    [
      "                ",
      "                ",
      "                ",
      "  ''''''''''    ",
      "  '        '    ",
      "  '        '    ",
      "  '        '    ",
      "  '        '    ",
      "  '        '    ",
      "  '        '    ",
      "  '        '    ",
      "  '        '    ",
      "  ''''''''''    ",
      "                ",
      "                ",
      "                "
    ],
    [
      "                ",
      "                ",
      "                ",
      "  &&&&&&&&&&    ",
      "  &&&&&&&&&&    ",
      "  &&&&&&&&&&    ",
      "  &&&&&&&&&&    ",
      "  &&&&&&&&&&    ",
      "  &&&&&&&&&&    ",
      "  &&&&&&&&&&    ",
      "  &&&&&&&&&&    ",
      "  &&&&&&&&&&    ",
      "  &&&&&&&&&&    ",
      "                ",
      "                ",
      "                "
    ]
  ],
  "palette": {
    "palette": [
      {
        "char": "!",
        "block": "immersiveengineering:sheetmetal_steel"
      },
      {
        "char": "$",
        "block": "minecraft:iron_door[facing=west,half=lower,hinge=left,open=false,powered=false]"
      },
      {
        "char": "%",
        "block": "minecraft:iron_door[facing=west,half=upper,hinge=left,open=false,powered=false]"
      },
      {
        "char": "&",
        "block": "minecraft:smooth_stone"
      },
      {
        "char": "'",
        "block": "tfmg:cinder_block"
      }
    ]
  }
}
