{
  "xsize": 16,
  "zsize": 16,
  "slices": [
    [
      "                ",
      "                ",
      "                ",
      "                ",
      "!!        !!    ",
      "!! $$$$$$$$$$   ",
      "   $        $   ",
      "   $        $   ",
      "   $        $   ",
      "   $        $   ",
      "   $        $   ",
      "   $        $   ",
      "   $        $   ",
      "   $        $   ",
      "!! $$$$$$$$$$   ",
      "!!        !!    "
    ],
    [
      "                ",
      "                ",
      "                ",
      "                ",
      "!!        !!    ",
      "!! %%%%%%%%%%   ",
      "   %%%%%%%%%%   ",
      "   %%%%%%%%%%   ",
      "   %%%%%%%%%%   ",
      "   %%%%%%%%%%   ",
      "   %%%%%%%%%%   ",
      "   %%%%%%%%%%   ",
      "   %%%%%%%%%%   ",
      "   %%%%%%%%%%   ",
      "!! %%%%%%%%%%   ",
      "!!        !!    "
    ],
    [
      "                ",
      "                ",
      "                ",
      "                ",
      "!!%%%%%%%%!!%%%%",
      "!!%%%%%%%%!!%%%%",
      "%%%%%%%%%%%%%%%%",
      "%%%%%%%%%%%%%%%%",
      "%%%%%%%%%%%%%%%%",
      "%%%%%%%%%%%%%%%%",
      "%%%%%%%%%%%%%%%%",
      "%%%%%%%%%%%%%%%%",
      "%%%%%%%%%%%%%%%%",
      "%%%%%%%%%%%%%%%%",
      "!!%%%%%%%%!!%%%%",
      "!!%%%%%%%%!!%%%%"
    ],
    [
      "                ",
      "                ",
      "                ",
      "                ",
      "!!!!!!!!!!!!!!!!",
      "!!        !!    ",
      "                ",
      "                ",
      "                ",
      "                ",
      "                ",
      "                ",
      "                ",
      "                ",
      "!!        !!    ",
      "!!        !!    "
    ],
    [
      "                ",
      "                ",
      "                ",
      "                ",
      "!!!!!!!!!!!!!!!!",
      "!!        !!    ",
      "                ",
      "                ",
      "                ",
      "                ",
      "                ",
      "                ",
      "                ",
      "                ",
      "!!        !!    ",
      "!!        !!    "
    ],
    [
      "                ",
      "                ",
      "                ",
      "                ",
      "!!        !!    ",
      "!!        !!    ",
      "                ",
      "                ",
      "                ",
      "                ",
      "                ",
      "                ",
      "                ",
      "                ",
      "!!        !!    ",
      "!!        !!    "
    ]
  ],
  "palette": {
    "palette": [
      {
        "char": "!",
        "block": "immersiveengineering:concrete_reinforced"
      },
      {
        "char": "$",
        "block": "minecraft:mud_bricks"
      },
      {
        "char": "%",
        "block": "minecraft:smooth_stone"
      }
    ]
  }
}
