{
  "xsize": 16,
  "zsize": 16,
  "slices": [
    [
      "                ",
      "                ",
      "                ",
      "                ",
      "                ",
      "                ",
      "                ",
      "                ",
      "                ",
      "    !!      !!  ",
      "    !!      !!  ",
      "                ",
      "                ",
      "                ",
      "                ",
      "                "
    ],
    [
      "                ",
      "                ",
      "                ",
      "                ",
      "                ",
      "                ",
      "                ",
      "                ",
      "                ",
      "    !!      !!  ",
      "    !!      !!  ",
      "                ",
      "                ",
      "                ",
      "                ",
      "                "
    ],
    [
      "                ",
      "                ",
      "                ",
      "                ",
      "                ",
      "                ",
      "                ",
      "                ",
      "                ",
      "    !!      !!  ",
      "    !!      !!  ",
      "                ",
      "                ",
      "                ",
      "                ",
      "                "
    ],
    [
      "                ",
      "                ",
      "                ",
      "                ",
      "                ",
      "                ",
      "                ",
      "                ",
      "                ",
      "    !!      !!  ",
      "    !!      !!  ",
      "                ",
      "                ",
      "                ",
      "                ",
      "                "
    ],
    [
      "    &&&&&&&&&&&&",
      "    &&&&&&&&&&&&",
      "    &&&&&&&&&&&&",
      "    &&&&&&&&&&&&",
      "    &&&&&&&&&&&&",
      "    &&&&&&&&&&&&",
      "    &&&&&&&&&&&&",
      "    &&&&&&&&&&&&",
      "    &&&&&&&&&&&&",
      "    !!&&&&&&!!&&",
      "    !!&&&&&&!!&&",
      "    &&&&&&&&&&&&",
      "    &&&&&&&&&&&&",
      "    &&&&&&&&&&&&",
      "    &&&&&&&&&&&&",
      "    &&&&&&&&&&&&"
    ],
    [
      "    !           ",
      "    !           ",
      "    !           ",
      "    !  ' $ $ '  ",
      "    !  '%%%%%'  ",
      "    !  '%%%%%'  ",
      "    !  '%%%%%'  ",
      "    !  ' $ $ '  ",
      "    !           ",
      "    !!      !!  ",
      "    !!      !!  ",
      "    !           ",
      "    !  ' $ $ '  ",
      "    !  '((((('  ",
      "    !  '((((('  ",
      "    !  '((((('  "
    ]
  ],
  "palette": {
    "palette": [
      {
        "char": "!",
        "block": "immersiveengineering:concrete_reinforced"
      },
      {
        "char": "$",
        "block": "minecraft:black_concrete"
      },
      {
        "char": "%",
        "block": "minecraft:blue_terracotta"
      },
      {
        "char": "&",
        "block": "minecraft:smooth_stone"
      },
      {
        "char": "'",
        "block": "minecraft:white_carpet"
      },
      {
        "char": "(",
        "block": "minecraft:yellow_terracotta"
      }
    ]
  }
}
