{
  "xsize": 16,
  "zsize": 16,
  "slices": [
    [
      "                ",
      "                ",
      "   ((((((((((   ",
      "   (        (   ",
      "$$ (        (   ",
      "$$ (        (   ",
      "   (        (   ",
      "   (        (   ",
      "   (        (   ",
      "   (        (   ",
      "   (        (   ",
      "   ( &&&&   (   ",
      "   ( &&&&   (   ",
      "   ((&&&&((((   ",
      "$$   &&&& $$    ",
      "$$        $$    "
    ],
    [
      "                ",
      "                ",
      "   ''''''''''   ",
      "   ''''''''''   ",
      "$$ ''''''''''   ",
      "$$ ''''''''''   ",
      "   ''''''''''   ",
      "   ''''''''''   ",
      "   ''''''''''   ",
      "   ''''''''''   ",
      "   ''''''''''   ",
      "   ''&&&&''''   ",
      "   ''&&&&''''   ",
      "   ''&&&&''''   ",
      "$$   &&&& $$    ",
      "$$        $$    "
    ],
    [
      "                ",
      "                ",
      "                ",
      "                ",
      "                ",
      "                ",
      "                ",
      "                ",
      "                ",
      "                ",
      "                ",
      "                ",
      "      )         ",
      "                ",
      "                ",
      "                "
    ],
    [
      "''''''''''''''''",
      "''''''''''''''''",
      "''''''''''''''''",
      "''''''''''''''''",
      "''''''''''''''''",
      "''''''''''''''''",
      "''''''''''''''''",
      "''''''''''''''''",
      "''''''''''''''''",
      "''''''''''''''''",
      "''''''''''''''''",
      "''''''''''''''''",
      "''''' '''''' '''",
      "''''' '''''' '''",
      "                ",
      "                "
    ],
    [
      "     %          ",
      "                ",
      "                ",
      "                ",
      "                ",
      "                ",
      "                ",
      "                ",
      "                ",
      "                ",
      "                ",
      "         !!     ",
      "         !!     ",
      "                ",
      "                ",
      "                "
    ],
    [
      "                ",
      "                ",
      "                ",
      "                ",
      "                ",
      "                ",
      "                ",
      "                ",
      "                ",
      "                ",
      "                ",
      "         !!     ",
      "         !!     ",
      "                ",
      "                ",
      "                "
    ]
  ],
  "palette": {
    "palette": [
      {
        "char": "!",
        "block": "immersiveengineering:concrete_brick_cracked"
      },
      {
        "char": "$",
        "block": "immersiveengineering:concrete_reinforced"
      },
      {
        "char": "%",
        "block": "minecraft:black_concrete"
      },
      {
        "char": "&",
        "block": "minecraft:gravel"
      },
      {
        "char": "'",
        "block": "minecraft:smooth_stone"
      },
      {
        "char": "(",
        "block": "tfmg:cinder_block"
      },
      {
        "char": ")",
        "block": "wastelands:scrap_pile"
      }
    ]
  }
}
