{
  "xsize": 16,
  "zsize": 16,
  "slices": [
    [
      "1111111111111111",
      "1111111111111111",
      "1111111111111111",
      "1111111111111111",
      "1111111111111111",
      "1111111111111111",
      "1111111111111111",
      "111111111((%1111",
      "1111111((%111111",
      "11111((%11111111",
      "111((%1111111111",
      "1((%111111111111",
      "(%11111111111111",
      "1111111111111111",
      "11111111111111((",
      "111111111111((%1"
    ],
    [
      "                ",
      "                ",
      "                ",
      "                ",
      "$$++++++++$$++++",
      "$$+**********+++",
      "+++**********+++",
      "+++**********+++",
      "+++**********+++",
      "+++**********+++",
      "+++**********+++",
      "+++**********+++",
      "+++**********+++",
      "+++**********+++",
      "$$+**********+++",
      "$$++++++++$$++++"
    ],
    [
      "                ",
      "                ",
      "                ",
      "                ",
      "$$$$$$$$$$$$$$$$",
      "$$ ))))))))))   ",
      "   )    0   )   ",
      "   )  ..0   )   ",
      "   )  / 0   )   ",
      "   )    0   )   ",
      "   &    0   )   ",
      "   )    02  )   ",
      "   )    ,   )   ",
      "   )    0   )   ",
      "$$ ))))))))))   ",
      "$$        $$    "
    ],
    [
      "                ",
      "                ",
      "                ",
      "                ",
      "$$$$$$$$$$$$$$$$",
      "$$ ))))))))))   ",
      "   )    0   )   ",
      "   !    0   )   ",
      "   !    0   )   ",
      "   )    0   )   ",
      "   '    0   )   ",
      "   )    0   )   ",
      "   )    -   )   ",
      "   )    0   )   ",
      "$$ ))))))))))   ",
      "$$        $$    "
    ],
    [
      "                ",
      "                ",
      "                ",
      "                ",
      "$$        $$    ",
      "$$ ))))))))))   ",
      "   )    0   )   ",
      "   !    0   )   ",
      "   !    0   )   ",
      "   )    0   )   ",
      "   )    0   )   ",
      "   )    0   )   ",
      "   )    0   )   ",
      "   )    0   )   ",
      "$$ ))))))))))   ",
      "$$        $$    "
    ],
    [
      "                ",
      "                ",
      "                ",
      "                ",
      "$$        $$    ",
      "$$ ))))))))))   ",
      "   )    0   )   ",
      "   )    0   )   ",
      "   )    0   )   ",
      "   )    0   )   ",
      "   )    0   )   ",
      "   )    0   )   ",
      "   )    0   )   ",
      "   )    0   )   ",
      "$$ ))))))))))   ",
      "$$        $$    "
    ]
  ],
  "palette": {
    "palette": [
      {
        "char": "!",
        "block": "create:framed_glass"
      },
      {
        "char": "$",
        "block": "immersiveengineering:concrete_reinforced"
      },
      {
        "char": "%",
        "block": "minecraft:coarse_dirt"
      },
      {
        "char": "&",
        "block": "minecraft:dark_oak_door[facing=west,half=lower,hinge=left,open=false,powered=false]"
      },
      {
        "char": "'",
        "block": "minecraft:dark_oak_door[facing=west,half=upper,hinge=left,open=false,powered=false]"
      },
      {
        "char": "(",
        "block": "minecraft:gravel"
      },
      {
        "char": ")",
        "block": "minecraft:mud_bricks"
      },
      {
        "char": "*",
        "block": "minecraft:polished_andesite"
      },
      {
        "char": "+",
        "block": "minecraft:smooth_stone"
      },
      {
        "char": ",",
        "block": "minecraft:spruce_door[facing=east,half=lower,hinge=left,open=false,powered=false]"
      },
      {
        "char": "-",
        "block": "minecraft:spruce_door[facing=east,half=upper,hinge=left,open=false,powered=false]"
      },
      {
        "char": ".",
        "block": "minecraft:spruce_slab[type=bottom,waterlogged=false]"
      },
      {
        "char": "/",
        "block": "minecraft:spruce_stairs[facing=north,half=bottom,shape=straight,waterlogged=false]"
      },
      {
        "char": "0",
        "block": "minecraft:stripped_spruce_wood"
      },
      {
        "char": "1",
        "block": "tfmg:asphalt"
      },
      {
        "char": "2",
        "block": "the_wasteland_reworked:radio"
      }
    ]
  }
}
