{
  "xsize": 16,
  "zsize": 16,
  "slices": [
    [
      "                ",
      "       %%%%%%   ",
      "       %%%%%%   ",
      "                ",
      "                ",
      "                ",
      "                ",
      "                ",
      "                ",
      "      $$        ",
      "      $$        ",
      "                ",
      "                ",
      "                ",
      "                ",
      "                "
    ],
    [
      "                ",
      "                ",
      "                ",
      "       %%%%%%   ",
      "       %%%%%%   ",
      "                ",
      "                ",
      "                ",
      "                ",
      "      $$        ",
      "      $$        ",
      "                ",
      "                ",
      "                ",
      "                ",
      "                "
    ],
    [
      "%%%%%%%      %%%",
      "%%%%%%%      %%%",
      "%%%%%%%      %%%",
      "%%%%%%%      %%%",
      "%%%%%%%      %%%",
      "%%%%%%%%%%%%%%%%",
      "%%%%%%%%%%%%%%  ",
      "%%%%%%%%%%%%%%  ",
      "%%%%%%%%%%%%%%  ",
      "%%%%%%$$%%%%%%  ",
      "%%%%%%$$%%%%%%  ",
      "%%%%%%%%%%%%%%  ",
      "%%%%%%%%%%%%%%  ",
      "%%%%%%%%%%%%%%  ",
      "%%%%%%%%%%%%%%  ",
      "%%%%%%%%%%%%%%  "
    ],
    [
      "                ",
      "                ",
      "                ",
      "                ",
      "                ",
      "                ",
      "                ",
      "               %",
      "               %",
      "      $$       %",
      "      $$       %",
      "               %",
      "               %",
      "               %",
      "&              %",
      "               %"
    ],
    [
      "                ",
      "                ",
      "                ",
      "                ",
      "                ",
      "                ",
      "                ",
      "               !",
      "               !",
      "      $$        ",
      "      $$        ",
      "                ",
      "                ",
      "                ",
      "                ",
      "                "
    ],
    [
      "                ",
      "                ",
      "                ",
      "                ",
      "                ",
      "                ",
      "                ",
      "               !",
      "               !",
      "      $$        ",
      "      $$        ",
      "                ",
      "                ",
      "                ",
      "                ",
      "                "
    ]
  ],
  "palette": {
    "palette": [
      {
        "char": "!",
        "block": "immersiveengineering:concrete_brick_cracked"
      },
      {
        "char": "$",
        "block": "immersiveengineering:concrete_reinforced"
      },
      {
        "char": "%",
        "block": "minecraft:smooth_stone"
      },
      {
        "char": "&",
        "block": "minecraft:spawner",
        "tag": {
          "id": "minecraft:mob_spawner",
          "Delay": 200,
          "MinSpawnDelay": 240,
          "MaxSpawnDelay": 720,
          "SpawnCount": 2,
          "MaxNearbyEntities": 7,
          "RequiredPlayerRange": 14,
          "SpawnRange": 4,
          "SpawnData": {
            "entity": {
              "id": "the_wasteland_reworked:ghoul"
            }
          },
          "SpawnPotentials": [
            {
              "weight": 1,
              "data": {
                "entity": {
                  "id": "the_wasteland_reworked:ghoul"
                }
              }
            }
          ]
        }
      }
    ]
  }
}
