{
  "xsize": 16,
  "zsize": 16,
  "slices": [
    [
      "             &&&",
      "             &  ",
      "             &  ",
      "             &  ",
      "             &  ",
      "             &  ",
      "                ",
      "!               ",
      "!               ",
      " (((((((((((((((",
      " (((((((((((((((",
      " (((((((((((((((",
      " (((((((((((((((",
      " (((((((((((((((",
      " (((((((((((((((",
      " ((((((((((((((("
    ],
    [
      "             &&&",
      "             &  ",
      "             &  ",
      "             &  ",
      "             &  ",
      "             &  ",
      "                ",
      "                ",
      "                ",
      " !!             ",
      " !!             ",
      "                ",
      "                ",
      "                ",
      "                ",
      "                "
    ],
    [
      "             &&&",
      "             &  ",
      "             &  ",
      "             &  ",
      "             &  ",
      "             &  ",
      "                ",
      "                ",
      "                ",
      " !!             ",
      " !!             ",
      "                ",
      "                ",
      "                ",
      "                ",
      "                "
    ],
    [
      "(((((((((((((&&&",
      "(((((((((((((&''",
      "(((((((((((((&''",
      "(((((((((((((&''",
      "(((((((((((((&''",
      "(((((((((((((&''",
      "                ",
      "                ",
      "                ",
      " !!             ",
      " !!             ",
      "                ",
      "((((((((((((((((",
      "((((((((((((((((",
      "((((((((((((((((",
      "(((((((((((((((("
    ],
    [
      "             &&&",
      "* $ $ *      &  ",
      "*%%%%%*      &  ",
      "*%%%%%*      &  ",
      "*%%%%%*      &  ",
      "* $ $ *      &  ",
      "                ",
      "                ",
      "     $          ",
      "    +++++       ",
      "    +++++       ",
      "    +++++       ",
      "       $        ",
      "                ",
      "                ",
      "                "
    ],
    [
      "             &&&",
      "             &  ",
      "  )))        &  ",
      "  )))        &  ",
      "  )))        &  ",
      "             &  ",
      "                ",
      "                ",
      "                ",
      "    +++++       ",
      "    +++++       ",
      "    +++++       ",
      "                ",
      "                ",
      "                ",
      "                "
    ]
  ],
  "palette": {
    "palette": [
      {
        "char": "!",
        "block": "immersiveengineering:concrete_brick_cracked"
      },
      {
        "char": "$",
        "block": "minecraft:black_concrete"
      },
      {
        "char": "%",
        "block": "minecraft:blue_terracotta"
      },
      {
        "char": "&",
        "block": "minecraft:light_gray_concrete"
      },
      {
        "char": "'",
        "block": "minecraft:polished_andesite"
      },
      {
        "char": "(",
        "block": "minecraft:smooth_stone"
      },
      {
        "char": ")",
        "block": "minecraft:tinted_glass"
      },
      {
        "char": "*",
        "block": "minecraft:white_carpet"
      },
      {
        "char": "+",
        "block": "minecraft:yellow_terracotta"
      }
    ]
  }
}
