{
  "xsize": 16,
  "zsize": 16,
  "slices": [
    [
      "                ",
      "                ",
      "  $     $       ",
      "  %%%%%%        ",
      "                ",
      "      !!        ",
      "                ",
      "                ",
      "                ",
      "                ",
      "                ",
      "                ",
      "                ",
      "                ",
      "      !         ",
      "      !         "
    ],
    [
      "                ",
      "'''''''''       ",
      "'''''''''       ",
      "'''''''''       ",
      "'''''''''       ",
      "'''''''''       ",
      "                ",
      "                ",
      "                ",
      "                ",
      "                ",
      "                ",
      "                ",
      "                ",
      "      !         ",
      "      !         "
    ],
    [
      "                ",
      "                ",
      "                ",
      "                ",
      "&&&&&&!!&&&&&&&&",
      "&&&&&&!!&&&&&&&&",
      "&&&&&&&&&&&&&&&&",
      "&&&&&&&&&&&&&&&&",
      "&&&&&&&&&&&&&&&&",
      "&&&&&&&      &&&",
      "&&&&&&&      &&&",
      "&&&&&&&      &&&",
      "&&&&&&&      &&&",
      "&&&&&&&      &&&",
      "&&&&&&!      &&&",
      "&&&&&&!      &&&"
    ],
    [
      "                ",
      "                ",
      "                ",
      "                ",
      "!!!!!!!!!!!!!!!!",
      "      !!        ",
      "                ",
      "                ",
      "                ",
      "       &&&&&&   ",
      "       &&&&&&   ",
      "                ",
      "                ",
      "                ",
      "      !!        ",
      "      !!        "
    ],
    [
      "                ",
      "                ",
      "                ",
      "                ",
      "!!!!!!!!!!!!!!!!",
      "      !!        ",
      "                ",
      "                ",
      "                ",
      "                ",
      "                ",
      "       &&&&&&   ",
      "       &&&&&&   ",
      "                ",
      "      !!        ",
      "      !!        "
    ],
    [
      "                ",
      "                ",
      "                ",
      "                ",
      "      !!        ",
      "      !!        ",
      "                ",
      "                ",
      "                ",
      "                ",
      "                ",
      "                ",
      "                ",
      "       &&&&&&   ",
      "      !&&&&&&   ",
      "      !!        "
    ]
  ],
  "palette": {
    "palette": [
      {
        "char": "!",
        "block": "immersiveengineering:concrete_reinforced"
      },
      {
        "char": "$",
        "block": "minecraft:polished_blackstone_bricks"
      },
      {
        "char": "%",
        "block": "minecraft:red_terracotta"
      },
      {
        "char": "&",
        "block": "minecraft:smooth_stone"
      },
      {
        "char": "'",
        "block": "minecraft:weathered_cut_copper"
      }
    ]
  }
}
