{
  "xsize": 16,
  "zsize": 16,
  "slices": [
    [
      "                ",
      " -(----(----(-  ",
      " ------------(  ",
      " '---------(((  ",
      " --------(('--  ",
      " ------(('----  ",
      " ----(('------  ",
      " --(('--------  ",
      " (('----------  ",
      " '-----------(  ",
      " -------------  ",
      " -------------  ",
      " -----------((  ",
      " -'----'--(('-  ",
      "                ",
      "                "
    ],
    [
      "                ",
      "                ",
      "                ",
      "                ",
      "                ",
      "     $$$$((((   ",
      "     $$$$((((   ",
      "     $$$$((((   ",
      "     $$$$((((   ",
      " /////$$$$  2   ",
      " /////          ",
      " /////          ",
      " /////          ",
      " /////          ",
      "                ",
      "                "
    ],
    [
      "                ",
      "                ",
      "                ",
      "                ",
      "                ",
      "     $$$$((((   ",
      "     $$$$((((   ",
      "     $$$$(0((   ",
      "     $$$$((((   ",
      " ..)..$$$$      ",
      " .   .          ",
      " .1,+.          ",
      " .  &.          ",
      " .....          ",
      "                ",
      "                "
    ],
    [
      "                ",
      "                ",
      "                ",
      "                ",
      "                ",
      "                ",
      "      0 0       ",
      "                ",
      "      0 0       ",
      " ..*..          ",
      " .   .          ",
      " !   .          ",
      " !   .          ",
      " .....          ",
      "                ",
      "                "
    ],
    [
      "                ",
      "                ",
      "                ",
      "                ",
      "                ",
      "                ",
      "      0 0       ",
      "                ",
      "      0 0       ",
      " .....          ",
      " .   .          ",
      " !   .          ",
      " !   .          ",
      " .....          ",
      "                ",
      "                "
    ],
    [
      "                ",
      "                ",
      "                ",
      "                ",
      "                ",
      "                ",
      "      %%%       ",
      "      % %       ",
      "      %%%       ",
      " .....          ",
      " .   .          ",
      " .   .          ",
      " .   .          ",
      " .....          ",
      "                ",
      "                "
    ]
  ],
  "palette": {
    "palette": [
      {
        "char": "!",
        "block": "create:framed_glass"
      },
      {
        "char": "$",
        "block": "immersiveengineering:concrete_reinforced"
      },
      {
        "char": "%",
        "block": "immersiveengineering:sheetmetal_steel"
      },
      {
        "char": "&",
        "block": "minecraft:barrel[facing=up,open=false]"
      },
      {
        "char": "'",
        "block": "minecraft:coarse_dirt"
      },
      {
        "char": "(",
        "block": "minecraft:gravel"
      },
      {
        "char": ")",
        "block": "minecraft:iron_door[facing=north,half=lower,hinge=left,open=false,powered=false]"
      },
      {
        "char": "*",
        "block": "minecraft:iron_door[facing=north,half=upper,hinge=left,open=false,powered=false]"
      },
      {
        "char": "+",
        "block": "minecraft:redstone_lamp[lit=false]"
      },
      {
        "char": ",",
        "block": "minecraft:spawner",
        "tag": {
          "id": "minecraft:mob_spawner",
          "Delay": 200,
          "MinSpawnDelay": 240,
          "MaxSpawnDelay": 720,
          "SpawnCount": 1,
          "MaxNearbyEntities": 3,
          "RequiredPlayerRange": 14,
          "SpawnRange": 4,
          "SpawnData": {
            "entity": {
              "id": "minecraft:zombie"
            }
          },
          "SpawnPotentials": [
            {
              "weight": 1,
              "data": {
                "entity": {
                  "id": "minecraft:zombie"
                }
              }
            }
          ]
        }
      },
      {
        "char": "-",
        "block": "tfmg:asphalt"
      },
      {
        "char": ".",
        "block": "tfmg:cinder_block"
      },
      {
        "char": "/",
        "block": "tfmg:factory_floor"
      },
      {
        "char": "0",
        "block": "tfmg:steel_block"
      },
      {
        "char": "1",
        "block": "the_wasteland_reworked:radio"
      },
      {
        "char": "2",
        "block": "wastelands:scrap_pile"
      }
    ]
  }
}
