{
  "xsize": 16,
  "zsize": 16,
  "slices": [
    [
      "                ",
      " ,(,,,,(,,,,(,  ",
      " ,,,,,,,,,,,,(  ",
      " ',,,,,,,,,(((  ",
      " ,,,,,,,,((',,  ",
      " ,,,,,,((',,,,  ",
      " ,,,,((',,,,,,  ",
      " ,,((',,,,,,,,  ",
      " ((',,,,,,,,,,  ",
      " ',,,,,,,,,,,(  ",
      " ,,,,,,,,,,,,,  ",
      " ,,,,,,,,,,,,,  ",
      " ,,,,,,,,,,,((  ",
      " ,',,,,',,((',  ",
      "                ",
      "                "
    ],
    [
      "                ",
      "                ",
      "                ",
      "                ",
      "                ",
      "     $$$$$      ",
      "     $$$$$      ",
      "     $$$$$      ",
      "     $$$$$      ",
      " .....$$$$      ",
      " .....          ",
      " .....          ",
      " .....          ",
      " .....          ",
      "                ",
      "                "
    ],
    [
      "                ",
      "                ",
      "                ",
      "                ",
      "                ",
      "     $$$$$      ",
      "     $$$$$      ",
      "     $$$$$      ",
      "     $$$$$      ",
      " --)--$$$$      ",
      " -   -          ",
      " -0 +-          ",
      " -  &-          ",
      " -----          ",
      "                ",
      "                "
    ],
    [
      "                ",
      "                ",
      "                ",
      "                ",
      "                ",
      "                ",
      "      / /       ",
      "                ",
      "      / /       ",
      " --*--          ",
      " -   -          ",
      " !   -          ",
      " !   -          ",
      " -----          ",
      "                ",
      "                "
    ],
    [
      "                ",
      "                ",
      "                ",
      "                ",
      "                ",
      "                ",
      "      / /       ",
      "                ",
      "      / /       ",
      " -----          ",
      " -   -          ",
      " !   -          ",
      " !   -          ",
      " -----          ",
      "                ",
      "                "
    ],
    [
      "                ",
      "                ",
      "                ",
      "                ",
      "                ",
      "                ",
      "      %%%       ",
      "      % %       ",
      "      %%%       ",
      " -----          ",
      " -   -          ",
      " -   -          ",
      " -   -          ",
      " -----          ",
      "                ",
      "                "
    ]
  ],
  "palette": {
    "palette": [
      {
        "char": "!",
        "block": "create:framed_glass"
      },
      {
        "char": "$",
        "block": "immersiveengineering:concrete_reinforced"
      },
      {
        "char": "%",
        "block": "immersiveengineering:sheetmetal_steel"
      },
      {
        "char": "&",
        "block": "minecraft:barrel[facing=up,open=false]"
      },
      {
        "char": "'",
        "block": "minecraft:coarse_dirt"
      },
      {
        "char": "(",
        "block": "minecraft:gravel"
      },
      {
        "char": ")",
        "block": "minecraft:iron_door[facing=north,half=lower,hinge=left,open=false,powered=false]"
      },
      {
        "char": "*",
        "block": "minecraft:iron_door[facing=north,half=upper,hinge=left,open=false,powered=false]"
      },
      {
        "char": "+",
        "block": "minecraft:redstone_lamp[lit=false]"
      },
      {
        "char": ",",
        "block": "tfmg:asphalt"
      },
      {
        "char": "-",
        "block": "tfmg:cinder_block"
      },
      {
        "char": ".",
        "block": "tfmg:factory_floor"
      },
      {
        "char": "/",
        "block": "tfmg:steel_block"
      },
      {
        "char": "0",
        "block": "the_wasteland_reworked:radio"
      }
    ]
  }
}
