{
  "xsize": 16,
  "zsize": 16,
  "slices": [
    [
      "**********&&%***",
      "********&&%*****",
      "******&&%*******",
      "****&&%*********",
      "**&&%***********",
      "&&%*************",
      "%***************",
      "***************&",
      "*************&&%",
      "***********&&%**",
      "*********&&%****",
      "*******&&%******",
      "*****&&%********",
      "***&&%**********",
      "*&&%************",
      "&%**************"
    ],
    [
      "++++++++++++++ '",
      "++++++++++++++ '",
      "++++++++++++++ '",
      "++++++++++++++ '",
      "++++++++++++++ '",
      "++++++++++++++ '",
      "++++++++++++++ '",
      "++++++++++++++ '",
      "++++++++++++++ '",
      "++++++++++++++ '",
      "++++++++++++++ '",
      "++++++++++++++ '",
      "++++++++++++++ '",
      "++++++++++++++ '",
      "++++++++++++++ '",
      "++++++++++++++  "
    ],
    [
      "   !     !   ( $",
      "             ( $",
      "             ( $",
      "             ( $",
      "   )     )   ( $",
      "   )     )   ( $",
      "   )     )   ( $",
      "   )     )   ( $",
      "   )     )   ( $",
      "   )     )   ( $",
      "   )     )   ( $",
      "   )     )   ( $",
      "   )     )   ( $",
      "   )     )   ( $",
      "   )     )   ( $",
      "   )     )   (  "
    ],
    [
      "             ( $",
      "             ( $",
      "             ( $",
      "             ( $",
      "   )     )   ( $",
      "   )     )   ( $",
      "   )     )   ( $",
      "   )     )   ( $",
      "   )     )   ( $",
      "   )     )   ( $",
      "   )     )   ( $",
      "   )     )   ( $",
      "   )     )   ( $",
      "   )     )   ( $",
      "   )     )   ( $",
      "   )     )   (  "
    ],
    [
      "             ( $",
      "             ( $",
      "             ( $",
      "             ( $",
      "             ( $",
      "             ( $",
      "             ( $",
      "             ( $",
      "             ( $",
      "             ( $",
      "             ( $",
      "             ( $",
      "             ( $",
      "             ( $",
      "             ( $",
      "             (  "
    ],
    [
      "             ( $",
      "             ( $",
      "             ( $",
      "             ( $",
      "             ( $",
      "             ( $",
      "             ( $",
      "             ( $",
      "             ( $",
      "             ( $",
      "             ( $",
      "             ( $",
      "             ( $",
      "             ( $",
      "             ( $",
      "             (  "
    ]
  ],
  "palette": {
    "palette": [
      {
        "char": "!",
        "block": "create:mechanical_saw"
      },
      {
        "char": "$",
        "block": "minecraft:bricks"
      },
      {
        "char": "%",
        "block": "minecraft:coarse_dirt"
      },
      {
        "char": "&",
        "block": "minecraft:gravel"
      },
      {
        "char": "'",
        "block": "minecraft:smooth_stone"
      },
      {
        "char": "(",
        "block": "minecraft:stripped_spruce_log"
      },
      {
        "char": ")",
        "block": "minecraft:stripped_spruce_log[axis=z]"
      },
      {
        "char": "*",
        "block": "tfmg:asphalt"
      },
      {
        "char": "+",
        "block": "tfmg:factory_floor"
      }
    ]
  }
}
