{
  "xsize": 16,
  "zsize": 16,
  "slices": [
    [
      "*******%%$******",
      "*****%%$********",
      "***%%$**********",
      "*%%$************",
      "%$**************",
      "****************",
      "**************%%",
      "************%%$*",
      "**********%%$***",
      "********%%$*****",
      "******%%$*******",
      "****%%$*********",
      "**%%$***********",
      "%%$*************",
      "$***************",
      "***************%"
    ],
    [
      "   +++++++++++++",
      "   +++++++++++++",
      "'  +++++++++++++",
      "   +++++++++++++",
      "   +++++++++++++",
      "   +++++++++++++",
      "   +++++++++++++",
      "'  +++++++++++++",
      "   +++++++++++++",
      "   +++++++++++++",
      "   +++++++++++++",
      "   +++++++++++++",
      "'  +++++++++++++",
      "   +++++++++++++",
      "   +++++++++++++",
      "   +++++++++++++"
    ],
    [
      "   (   !     !  ",
      "   (            ",
      "'  (            ",
      "   (            ",
      "   (   )     )  ",
      "   (   )     )  ",
      "   (   )     )  ",
      "'  (   )     )  ",
      "   (   )     )  ",
      "   (   )     )  ",
      "   (   )     )  ",
      "   (   )     )  ",
      "'  (   )     )  ",
      "   (   )     )  ",
      "   (   )     )  ",
      "   (   )   & )  "
    ],
    [
      "   (            ",
      "   (            ",
      "'  (            ",
      "   (            ",
      "   (   )     )  ",
      "   (   )     )  ",
      "   (   )     )  ",
      "'  (   )     )  ",
      "   (   )     )  ",
      "   (   )     )  ",
      "   (   )     )  ",
      "   (   )     )  ",
      "'  (   )     )  ",
      "   (   )     )  ",
      "   (   )     )  ",
      "   (   )     )  "
    ],
    [
      "   (            ",
      "   (            ",
      "'  (            ",
      "   (            ",
      "   (            ",
      "   (            ",
      "   (            ",
      "'  (            ",
      "   (            ",
      "   (            ",
      "   (            ",
      "   (            ",
      "'  (            ",
      "   (            ",
      "   (            ",
      "   (            "
    ],
    [
      "   (            ",
      "   (            ",
      "   (            ",
      "   (            ",
      "   (            ",
      "   (            ",
      "   (            ",
      "   (            ",
      "   (            ",
      "   (            ",
      "   (            ",
      "   (            ",
      "   (            ",
      "   (            ",
      "   (            ",
      "   (            "
    ]
  ],
  "palette": {
    "palette": [
      {
        "char": "!",
        "block": "create:mechanical_saw"
      },
      {
        "char": "$",
        "block": "minecraft:coarse_dirt"
      },
      {
        "char": "%",
        "block": "minecraft:gravel"
      },
      {
        "char": "&",
        "block": "minecraft:spawner",
        "tag": {
          "id": "minecraft:mob_spawner",
          "Delay": 200,
          "MinSpawnDelay": 240,
          "MaxSpawnDelay": 720,
          "SpawnCount": 2,
          "MaxNearbyEntities": 6,
          "RequiredPlayerRange": 14,
          "SpawnRange": 4,
          "SpawnData": {
            "entity": {
              "id": "minecraft:pillager"
            }
          },
          "SpawnPotentials": [
            {
              "weight": 1,
              "data": {
                "entity": {
                  "id": "minecraft:pillager"
                }
              }
            }
          ]
        }
      },
      {
        "char": "'",
        "block": "minecraft:spruce_log[axis=x]"
      },
      {
        "char": "(",
        "block": "minecraft:stripped_spruce_log"
      },
      {
        "char": ")",
        "block": "minecraft:stripped_spruce_log[axis=z]"
      },
      {
        "char": "*",
        "block": "tfmg:asphalt"
      },
      {
        "char": "+",
        "block": "tfmg:factory_floor"
      }
    ]
  }
}
