{
  "xsize": 16,
  "zsize": 16,
  "slices": [
    [
      "((((((((((((($$!",
      "((((((((((($$!((",
      "((((((((($$!((((",
      "((((((($$!((((((",
      "((((($$!((((((((",
      "((($$!((((((((((",
      "($$!((((((((((((",
      "$!((((((((((((((",
      "((((((((((((((((",
      "(((((((((((((($$",
      "(((((((((((($$!(",
      "(((((((((($$!(((",
      "(((((((($$!(((((",
      "(((((($$!(((((((",
      "(((($$!(((((((((",
      "(($$!((((((((((("
    ],
    [
      "   )))))))))))))",
      "%  )))))))))))))",
      "   )))))))))))))",
      "   )))))))))))))",
      "   )))))))))))))",
      "   )))))))))))))",
      "%  )))))))))))))",
      "   )))))))))))))",
      "   )))))))))))))",
      "   )))))))))))))",
      "   )))))))))))))",
      "%  )))))))))))))",
      "                ",
      "                ",
      "                ",
      "                "
    ],
    [
      "   &   '     '  ",
      "%  &   '     '  ",
      "   &   '     '  ",
      "   &   '     '  ",
      "   &            ",
      "   &            ",
      "%  &            ",
      "   &            ",
      "   &            ",
      "   &            ",
      "   &            ",
      "%  &&&&&        ",
      "                ",
      "                ",
      "                ",
      "                "
    ],
    [
      "   &   '     '  ",
      "%  &   '     '  ",
      "   &   '     '  ",
      "   &   '     '  ",
      "   &            ",
      "   &            ",
      "%  &            ",
      "   &            ",
      "   &            ",
      "   &            ",
      "   &            ",
      "%  &&&&&        ",
      "                ",
      "                ",
      "                ",
      "                "
    ],
    [
      "   &            ",
      "%  &            ",
      "   &            ",
      "   &            ",
      "   &            ",
      "   &            ",
      "%  &            ",
      "   &            ",
      "   &            ",
      "   &            ",
      "   &            ",
      "%  &&&&&        ",
      "                ",
      "                ",
      "                ",
      "                "
    ],
    [
      "   &            ",
      "   &            ",
      "   &            ",
      "   &            ",
      "   &            ",
      "   &            ",
      "   &            ",
      "   &            ",
      "   &            ",
      "   &            ",
      "   &            ",
      "   &&&&&        ",
      "                ",
      "                ",
      "                ",
      "                "
    ]
  ],
  "palette": {
    "palette": [
      {
        "char": "!",
        "block": "minecraft:coarse_dirt"
      },
      {
        "char": "$",
        "block": "minecraft:gravel"
      },
      {
        "char": "%",
        "block": "minecraft:spruce_log[axis=x]"
      },
      {
        "char": "&",
        "block": "minecraft:stripped_spruce_log"
      },
      {
        "char": "'",
        "block": "minecraft:stripped_spruce_log[axis=z]"
      },
      {
        "char": "(",
        "block": "tfmg:asphalt"
      },
      {
        "char": ")",
        "block": "tfmg:factory_floor"
      }
    ]
  }
}
