{
  "xsize": 16,
  "zsize": 16,
  "slices": [
    [
      "))))))))))))))) ",
      "))))%))))%))))) ",
      "))))))))))))))) ",
      ")))))))))))))%) ",
      "))))))))))))))) ",
      "))))))))))))))) ",
      "))))))))))))))) ",
      "))))))))))))))) ",
      "))))))))))%%$)  ",
      "))))))))%%$))%  ",
      "))))))%%$)))))  ",
      "))))%%$)))))))  ",
      "))%%$)))))))))  ",
      "%%$)))))))))))  ",
      "$)))))))))))))  ",
      ")))))))))))))%  "
    ],
    [
      "                ",
      "                ",
      "                ",
      "                ",
      "                ",
      "                ",
      "                ",
      "                ",
      "                ",
      "                ",
      "                ",
      "                ",
      "((((((((((((    ",
      "((((((((((((    ",
      "((((((((((((    ",
      "((((((((((((    "
    ],
    [
      "                ",
      "                ",
      "                ",
      "                ",
      "                ",
      "                ",
      "                ",
      "                ",
      "                ",
      "                ",
      "                ",
      "                ",
      "!!!!&!!!!!!!    ",
      "           !    ",
      "           !    ",
      "           !    "
    ],
    [
      "                ",
      "                ",
      "                ",
      "                ",
      "                ",
      "                ",
      "                ",
      "                ",
      "                ",
      "                ",
      "                ",
      "                ",
      "!!!!'!!!!!!!    ",
      "           !    ",
      "           !    ",
      "           !    "
    ],
    [
      "                ",
      "                ",
      "                ",
      "                ",
      "                ",
      "                ",
      "                ",
      "                ",
      "                ",
      "                ",
      "                ",
      "                ",
      "!!!!!!!!!!!!    ",
      "           !    ",
      "           !    ",
      "           !    "
    ],
    [
      "                ",
      "                ",
      "                ",
      "                ",
      "                ",
      "                ",
      "                ",
      "                ",
      "                ",
      "                ",
      "                ",
      "                ",
      "!!!!!!!!!!!!    ",
      "           !    ",
      "           !    ",
      "           !    "
    ]
  ],
  "palette": {
    "palette": [
      {
        "char": "!",
        "block": "minecraft:bricks"
      },
      {
        "char": "$",
        "block": "minecraft:coarse_dirt"
      },
      {
        "char": "%",
        "block": "minecraft:gravel"
      },
      {
        "char": "&",
        "block": "minecraft:iron_door[facing=north,half=lower,hinge=left,open=false,powered=false]"
      },
      {
        "char": "'",
        "block": "minecraft:iron_door[facing=north,half=upper,hinge=left,open=false,powered=false]"
      },
      {
        "char": "(",
        "block": "minecraft:smooth_stone"
      },
      {
        "char": ")",
        "block": "tfmg:asphalt"
      }
    ]
  }
}
