{
  "xsize": 16,
  "zsize": 16,
  "slices": [
    [
      ")))))))''$))))))",
      ")))))''$))))))))",
      ")))''$))))))))))",
      ")''$))))))))))))",
      "'$))))))))))))))",
      "))))))))))))))))",
      "))))))))))))))''",
      "))))))))))))''$)",
      "))))))))))''$)))",
      "))))))))''$)))))",
      "))))))''$)))))))",
      "))))''$)))))))))",
      "))''$)))))))))))",
      "''$)))))))))))))",
      "$)))))))))))))))",
      ")))))))))))))))'"
    ],
    [
      "%%%%%%%%%%%%%%%%",
      "%%%%%%%%%%%%%%%%",
      "%%%%%%%%%%%%%%%%",
      "%%%%%%%%%%%%%%%%",
      "%%%%%%%%%%%%%%%%",
      "%%%%%%%%%%%%%%%%",
      "%%%%%%%%%%%%%%%%",
      "%%%%%%%%%%%%%%%%",
      "%%%%%%%%%%%%%%%%",
      "%%%%%%%%%%%%%%%%",
      "%%%%%%%%%%%%%%%%",
      "%%%%%%%%%%%%%%%%",
      "%%%%%%%%%%%%%%%%",
      "%%%%%%%%%%%%%'''",
      "%%%%%%%%%%%%%'''",
      "%%%%%%%%%%%%%'''"
    ],
    [
      "(               ",
      "(               ",
      "(               ",
      "( && &&     && &",
      "(               ",
      "(               ",
      "((((((((((((((((",
      "  && &&     && &",
      "                ",
      "                ",
      "                ",
      "  && &&     && &",
      "                ",
      "             '''",
      "             '''",
      "((((((((((((('''"
    ],
    [
      "(               ",
      "(               ",
      "(               ",
      "(               ",
      "(               ",
      "(               ",
      "((((((((((((((((",
      "                ",
      "                ",
      "                ",
      "                ",
      "                ",
      "                ",
      "             '''",
      "             '''",
      "((((((((((((('''"
    ],
    [
      "(               ",
      "(               ",
      "(               ",
      "(               ",
      "(               ",
      "(               ",
      "((((((((((((((((",
      "                ",
      "                ",
      "                ",
      "                ",
      "                ",
      "                ",
      "             '''",
      "             '''",
      "((((((((((((('''"
    ],
    [
      "!               ",
      "(               ",
      "(               ",
      "(               ",
      "(               ",
      "(               ",
      "!(((((((((((((((",
      "!               ",
      "                ",
      "                ",
      "                ",
      "                ",
      "                ",
      "             '''",
      "             '''",
      "!(((((((((((('''"
    ]
  ],
  "palette": {
    "palette": [
      {
        "char": "!",
        "block": "create:framed_glass"
      },
      {
        "char": "$",
        "block": "minecraft:coarse_dirt"
      },
      {
        "char": "%",
        "block": "minecraft:dark_oak_planks"
      },
      {
        "char": "&",
        "block": "minecraft:dark_oak_stairs[facing=south,half=bottom,shape=straight,waterlogged=false]"
      },
      {
        "char": "'",
        "block": "minecraft:gravel"
      },
      {
        "char": "(",
        "block": "minecraft:stone_bricks"
      },
      {
        "char": ")",
        "block": "tfmg:asphalt"
      }
    ]
  }
}
