{
  "xsize": 16,
  "zsize": 16,
  "slices": [
    [
      " ,,$$$$$$$$$$$,,",
      " ,&$$$$$$$$$$$,,",
      " &$$$$$$$$$$$$,,",
      " ,,$$$$$$$$$$$,,",
      " ,,$$$$$$$$$$$,&",
      " $,$$$$$$$$$$$&$",
      " ,,$$$$$$$$$$$,,",
      " ,,$$$$$$$$$$$,,",
      " ,,$$$$$$$$$$$,,",
      " ,,$$$$$$$$$$$,,",
      " ,,$$$$$$$$$$$,,",
      " $&$$$$$$$$$$$,,",
      " $,$$$$$$$$$$$,,",
      " ,,$$$$$$$$$$$,,",
      " ,,$$$$$$$$$$$&&",
      " ,,$$$$$$$$$$$$,"
    ],
    [
      "                ",
      "                ",
      "                ",
      "                ",
      "                ",
      "     **  **     ",
      "        %%%%%%%%",
      "        %%%%%%%%",
      "        %%%%%%%%",
      "        %%%%%%%%",
      "        %%%%%%%%",
      "     ** %**%%%%%",
      "        %%%%%%%%",
      "        %%%%%%%%",
      "        %%%%%%%%",
      "        %%%%%%%%"
    ],
    [
      "                ",
      "                ",
      "                ",
      "                ",
      "                ",
      "     **  **     ",
      "        ********",
      "        *     + ",
      "        *     + ",
      "        * '   + ",
      "        *     + ",
      "     ** ***   ( ",
      "        *     + ",
      "        *     + ",
      "        *     + ",
      "        ********"
    ],
    [
      "                ",
      "                ",
      "                ",
      "                ",
      "                ",
      "     **  **     ",
      "        ********",
      "        *     + ",
      "        *     + ",
      "        *     + ",
      "        *     + ",
      "     ** ***   ) ",
      "        *     + ",
      "        *     + ",
      "        *     + ",
      "        ********"
    ],
    [
      "                ",
      "                ",
      "                ",
      "                ",
      "                ",
      "     !   !      ",
      "        ********",
      "        *     + ",
      "        *     + ",
      "        *     + ",
      "        *     + ",
      "     !  *!    + ",
      "        *     + ",
      "        *     + ",
      "        *     + ",
      "        ********"
    ],
    [
      "                ",
      "                ",
      "                ",
      "                ",
      "                ",
      "                ",
      "        ********",
      "        *     + ",
      "        *     + ",
      "        *     + ",
      "        *     + ",
      "        *     + ",
      "        *     + ",
      "        *     + ",
      "        *     + ",
      "        ********"
    ]
  ],
  "palette": {
    "palette": [
      {
        "char": "!",
        "block": "minecraft:chiseled_stone_bricks"
      },
      {
        "char": "$",
        "block": "minecraft:coarse_dirt"
      },
      {
        "char": "%",
        "block": "minecraft:dark_oak_planks"
      },
      {
        "char": "&",
        "block": "minecraft:gravel"
      },
      {
        "char": "'",
        "block": "minecraft:lectern[facing=east,has_book=false,powered=false]"
      },
      {
        "char": "(",
        "block": "minecraft:spruce_door[facing=east,half=lower,hinge=left,open=false,powered=false]"
      },
      {
        "char": ")",
        "block": "minecraft:spruce_door[facing=east,half=upper,hinge=left,open=false,powered=false]"
      },
      {
        "char": "*",
        "block": "minecraft:stone_bricks"
      },
      {
        "char": "+",
        "block": "minecraft:stripped_dark_oak_wood"
      },
      {
        "char": ",",
        "block": "tfmg:asphalt"
      }
    ]
  }
}
