{
  "xsize": 16,
  "zsize": 16,
  "slices": [
    [
      "  !             ",
      "  %             ",
      "  %             ",
      "  %    $$$$$$$$$",
      "  %    $       $",
      "  !    $       $",
      "  !    $       $",
      "  %    $       $",
      "%%%    $       $",
      "       $       $",
      "       $       $",
      "       $       $",
      "       $       $",
      "       $$$$$$$$$",
      "                ",
      "                "
    ],
    [
      "  %             ",
      "  %             ",
      "  %             ",
      "  %    $$$$$$$$$",
      "  %    $       $",
      "  %    $       $",
      "  %    $       $",
      "  %    $       $",
      "%%%    $       $",
      "       $       $",
      "       $       $",
      "       $       $",
      "       $       $",
      "       $$$$$$$$$",
      "                ",
      "                "
    ],
    [
      "  %             ",
      "  %             ",
      "  %             ",
      "  %    %%%%%%%%%",
      "  %    %%%%%%%%%",
      "  %    %%%%%%%%%",
      "  %    %%%%%%%%%",
      "  %    %%%%%%%%%",
      "%%%    %%%%%%%%%",
      "       %%%%%%%%%",
      "       %%%%%%%%%",
      "       %%%%%%%%%",
      "       %%%%%%%%%",
      "       %%%%%%%%%",
      "                ",
      "                "
    ],
    [
      "  %             ",
      "  %             ",
      "  %             ",
      "  %             ",
      "  %             ",
      "  %             ",
      "  %             ",
      "  %             ",
      "%%%             ",
      "                ",
      "                ",
      "                ",
      "                ",
      "                ",
      "                ",
      "                "
    ],
    [
      "  %             ",
      "  %             ",
      "  %             ",
      "  %             ",
      "  %             ",
      "  %             ",
      "  %             ",
      "  %             ",
      "%%%             ",
      "                ",
      "                ",
      "                ",
      "                ",
      "                ",
      "                ",
      "                "
    ],
    [
      "  %             ",
      "  %             ",
      "  %             ",
      "  %             ",
      "  %             ",
      "  %             ",
      "  %             ",
      "  %             ",
      "%%%             ",
      "                ",
      "                ",
      "                ",
      "                ",
      "                ",
      "                ",
      "                "
    ]
  ],
  "palette": {
    "palette": [
      {
        "char": "!",
        "block": "create:framed_glass"
      },
      {
        "char": "$",
        "block": "minecraft:mossy_stone_bricks"
      },
      {
        "char": "%",
        "block": "minecraft:stone_bricks"
      }
    ]
  }
}
