{
  "xsize": 16,
  "zsize": 16,
  "slices": [
    [
      " --$$$$$$$$$$$--",
      " -&$$$$$$$$$$$--",
      " &$$$$$$$$$$$$--",
      " --$$$$$$$$$$$--",
      " --$$$$$$$$$$$-&",
      " $-$$$$$$$$$$$&$",
      " --$$$$$$$$$$$--",
      " --$$$$$$$$$$$--",
      " --$$$$$$$$$$$--",
      " --$$$$$$$$$$$--",
      " --$$$$$$$$$$$--",
      " $&$$$$$$$$$$$--",
      " $-$$$$$$$$$$$--",
      " --$$$$$$$$$$$--",
      " --$$$$$$$$$$$&&",
      " --$$$$$$$$$$$$-"
    ],
    [
      "                ",
      "                ",
      "                ",
      "                ",
      "                ",
      "     ++  ++     ",
      "        %%%%%%%%",
      "        %%%%%%%%",
      "        %%%%%%%%",
      "        %%%%%%%%",
      "        %%%%%%%%",
      "     ++ %++%%%%%",
      "        %%%%%%%%",
      "        %%%%%%%%",
      "        %%%%%%%%",
      "        %%%%%%%%"
    ],
    [
      "                ",
      "                ",
      "                ",
      "                ",
      "                ",
      "     ++  ++     ",
      "        ++++++++",
      "        +     , ",
      "        +     , ",
      "        + '   , ",
      "        +     , ",
      "     ++ +++   ) ",
      "        + (   , ",
      "        +     , ",
      "        +     , ",
      "        ++++++++"
    ],
    [
      "                ",
      "                ",
      "                ",
      "                ",
      "                ",
      "     ++  ++     ",
      "        ++++++++",
      "        +     , ",
      "        +     , ",
      "        +     , ",
      "        +     , ",
      "     ++ +++   * ",
      "        +     , ",
      "        +     , ",
      "        +     , ",
      "        ++++++++"
    ],
    [
      "                ",
      "                ",
      "                ",
      "                ",
      "                ",
      "     !   !      ",
      "        ++++++++",
      "        +     , ",
      "        +     , ",
      "        +     , ",
      "        +     , ",
      "     !  +!    , ",
      "        +     , ",
      "        +     , ",
      "        +     , ",
      "        ++++++++"
    ],
    [
      "                ",
      "                ",
      "                ",
      "                ",
      "                ",
      "                ",
      "        ++++++++",
      "        +     , ",
      "        +     , ",
      "        +     , ",
      "        +     , ",
      "        +     , ",
      "        +     , ",
      "        +     , ",
      "        +     , ",
      "        ++++++++"
    ]
  ],
  "palette": {
    "palette": [
      {
        "char": "!",
        "block": "minecraft:chiseled_stone_bricks"
      },
      {
        "char": "$",
        "block": "minecraft:coarse_dirt"
      },
      {
        "char": "%",
        "block": "minecraft:dark_oak_planks"
      },
      {
        "char": "&",
        "block": "minecraft:gravel"
      },
      {
        "char": "'",
        "block": "kubejs:ruined_lectern[facing=east]"
      },
      {
        "char": "(",
        "block": "minecraft:spawner",
        "tag": {
          "id": "minecraft:mob_spawner",
          "Delay": 200,
          "MinSpawnDelay": 240,
          "MaxSpawnDelay": 720,
          "SpawnCount": 2,
          "MaxNearbyEntities": 6,
          "RequiredPlayerRange": 14,
          "SpawnRange": 4,
          "SpawnData": {
            "entity": {
              "id": "minecraft:zombie"
            }
          },
          "SpawnPotentials": [
            {
              "weight": 1,
              "data": {
                "entity": {
                  "id": "minecraft:zombie"
                }
              }
            }
          ]
        }
      },
      {
        "char": ")",
        "block": "minecraft:spruce_door[facing=east,half=lower,hinge=left,open=false,powered=false]"
      },
      {
        "char": "*",
        "block": "minecraft:spruce_door[facing=east,half=upper,hinge=left,open=false,powered=false]"
      },
      {
        "char": "+",
        "block": "minecraft:stone_bricks"
      },
      {
        "char": ",",
        "block": "minecraft:stripped_dark_oak_wood"
      },
      {
        "char": "-",
        "block": "tfmg:asphalt"
      }
    ]
  }
}
