{
  "xsize": 16,
  "zsize": 16,
  "slices": [
    [
      "                ",
      "                ",
      "                ",
      "                ",
      "                ",
      "    ''''''''''' ",
      "    '         ' ",
      "   !'         '$",
      "   !'         '$",
      "   !'         '$",
      "   !'         '$",
      "   !'         '$",
      "   !'''''''''''$",
      "   !           $",
      "   !           $",
      "   !           $"
    ],
    [
      "                ",
      "                ",
      "                ",
      "                ",
      "                ",
      "    ''''''''''' ",
      "    '         ' ",
      "    '         ' ",
      "    '         ' ",
      "    '         ' ",
      "    '         ' ",
      "    '         ' ",
      "    ''''''''''' ",
      "    !         $ ",
      "    !         $ ",
      "    !         $ "
    ],
    [
      "                ",
      "                ",
      "                ",
      "                ",
      "                ",
      "    ''''''''''' ",
      "    '         ' ",
      "    '         ' ",
      "    '         ' ",
      "    '         ' ",
      "    '         ' ",
      "    '         ' ",
      "    ''''''''''' ",
      "     !       $  ",
      "     !       $  ",
      "     !       $  "
    ],
    [
      "                ",
      "                ",
      "                ",
      "                ",
      "                ",
      "    ''''''''''' ",
      "    '         ' ",
      "    '         ' ",
      "    '         ' ",
      "    '         ' ",
      "    '         ' ",
      "    '         ' ",
      "    ''''''''''' ",
      "      !     $   ",
      "      !     $   ",
      "      !     $   "
    ],
    [
      "                ",
      "                ",
      "                ",
      "                ",
      "                ",
      "    &&&&&&&&&&& ",
      "    &&&&&&&&&&& ",
      "    &&&&%%%&&&& ",
      "    &&&&%%%&&&& ",
      "    &&&&%%%&&&& ",
      "    &&&&&&&&&&& ",
      "    &&&&&&&&&&& ",
      "    &&&&&&&&&&& ",
      "       !   $    ",
      "       !   $    ",
      "       !   $    "
    ],
    [
      "                ",
      "                ",
      "                ",
      "                ",
      "                ",
      "                ",
      "                ",
      "        %%%     ",
      "        %%%     ",
      "        %%%     ",
      "        ! $     ",
      "        ! $     ",
      "        ! $     ",
      "        ! $     ",
      "        ! $     ",
      "        ! $     "
    ]
  ],
  "palette": {
    "palette": [
      {
        "char": "!",
        "block": "minecraft:dark_oak_stairs[facing=east,half=bottom,shape=straight,waterlogged=false]"
      },
      {
        "char": "$",
        "block": "minecraft:dark_oak_stairs[facing=west,half=bottom,shape=straight,waterlogged=false]"
      },
      {
        "char": "%",
        "block": "minecraft:polished_blackstone_bricks"
      },
      {
        "char": "&",
        "block": "minecraft:smooth_stone"
      },
      {
        "char": "'",
        "block": "minecraft:stone_bricks"
      }
    ]
  }
}
