{
  "xsize": 16,
  "zsize": 16,
  "slices": [
    [
      "+++++++++++++''$",
      "+++++++++++''$++",
      "+++++++++''$++++",
      "+++++++''$++++++",
      "+++++''$++++++++",
      "+++''$++++++++++",
      "+''$++++++++++++",
      "'$++++++++++++++",
      "++++++++++++++++",
      "++++++++++++++''",
      "++++++++++++''$+",
      "++++++++++''$+++",
      "++++++++''$+++++",
      "++++++''$+++++++",
      "++++''$+++++++++",
      "+$''$+$++++$++++"
    ],
    [
      "%%%%%%%%%%%%%%%%",
      "%%%%%%%%%%%%%%%%",
      "%%%%%%%%%%%%%%%%",
      "%%%%%%%%%%%%%%%%",
      "%%%%%%%%%%%%%%%%",
      "%%%%%%%%%%%%%%%%",
      "%%%%%%%%%%%%%%%%",
      "%%%%%%%%%%%%%%%%",
      "%%%%%%%%%%%%%%%%",
      "                ",
      "                ",
      "                ",
      "                ",
      "                ",
      "                ",
      "                "
    ],
    [
      "*               ",
      "*  )))))))))))))",
      "*  )))))))))))))",
      "*  )))))))))))))",
      "*  )))))))))))))",
      "*  )))))))))))))",
      "*  )))))))))))))",
      "*  )))))))))))))",
      "****************",
      "                ",
      "                ",
      "                ",
      "                ",
      "                ",
      "                ",
      "                "
    ],
    [
      "*               ",
      "*  )))))))))))))",
      "*  )))))))))))))",
      "*  )))))))))))))",
      "*  )))))))))))))",
      "*  )))))))))))))",
      "*  )))))))))))))",
      "*  )))))))))))))",
      "****************",
      "                ",
      "                ",
      "                ",
      "                ",
      "                ",
      "                ",
      "                "
    ],
    [
      "*               ",
      "*  )))))))))))))",
      "*  )))))))))))))",
      "*  )))))))))))))",
      "*  )))))))))))))",
      "*  )))))))))))))",
      "*  )))))))))))))",
      "*  )))))))))))))",
      "****************",
      "                ",
      "                ",
      "                ",
      "                ",
      "                ",
      "                ",
      "                "
    ],
    [
      "!               ",
      "*               ",
      "*               ",
      "*               ",
      "*               ",
      "!        (      ",
      "!               ",
      "*     &&&&&&&   ",
      "****************",
      "                ",
      "                ",
      "                ",
      "                ",
      "                ",
      "                ",
      "                "
    ]
  ],
  "palette": {
    "palette": [
      {
        "char": "!",
        "block": "create:framed_glass"
      },
      {
        "char": "$",
        "block": "minecraft:coarse_dirt"
      },
      {
        "char": "%",
        "block": "minecraft:dark_oak_planks"
      },
      {
        "char": "&",
        "block": "minecraft:gold_block"
      },
      {
        "char": "'",
        "block": "minecraft:gravel"
      },
      {
        "char": "(",
        "block": "minecraft:lectern[facing=north,has_book=false,powered=false]"
      },
      {
        "char": ")",
        "block": "minecraft:polished_andesite"
      },
      {
        "char": "*",
        "block": "minecraft:stone_bricks"
      },
      {
        "char": "+",
        "block": "tfmg:asphalt"
      }
    ]
  }
}
