{
  "xsize": 16,
  "zsize": 16,
  "slices": [
    [
      " ''$$$$$$$$$$$''",
      " $'$$$$$$$$$$$''",
      " ''$$$$$$$$$$$''",
      " ''$$$$$$$$$$$''",
      " '%$$$$$$$$$$$''",
      " %$$$$$$$$$$$$''",
      " ''$$$$$$$$$$$''",
      " $'$$$$$$$$$$$'%",
      " ''$$$$$$$$$$$%$",
      " ''$$$$$$$$$$$''",
      " ''$$$$$$$$$$$''",
      " ''$$$$$$$$$$$''",
      " ''$$$$$$$$$$$''",
      " $'$$$$$$$$$$$''",
      " %%$''''''''''''",
      " $$''''$''''$'''"
    ],
    [
      "                ",
      "     &&  &&     ",
      "                ",
      "                ",
      "                ",
      "                ",
      "                ",
      "     &&  &&     ",
      "   (((((((((    ",
      "   (((((((((    ",
      "   (((((((((    ",
      "   (((((((((    ",
      "   (((((((((    ",
      "   (((((((((    ",
      "   (((((((((    ",
      "   (((((((((    "
    ],
    [
      "                ",
      "     &&  &&     ",
      "                ",
      "                ",
      "                ",
      "                ",
      "                ",
      "     &&  &&     ",
      "   (((   (((    ",
      "   (((((((((    ",
      "   (((((((((    ",
      "   (((((((((    ",
      "   (((((((((    ",
      "   (((((((((    ",
      "   (((((((((    ",
      "   (((((((((    "
    ],
    [
      "                ",
      "     &&  &&     ",
      "                ",
      "                ",
      "                ",
      "                ",
      "                ",
      "     &&  &&     ",
      "   (((   (((    ",
      "   (((((((((    ",
      "   (((((((((    ",
      "   (((((((((    ",
      "   (((((((((    ",
      "   (((((((((    ",
      "   (((((((((    ",
      "   (((((((((    "
    ],
    [
      "                ",
      "     !   !      ",
      "                ",
      "                ",
      "                ",
      "                ",
      "                ",
      "     !   !      ",
      "   (((   (((    ",
      "   (((((((((    ",
      "   (((((((((    ",
      "   (((((((((    ",
      "   (((((((((    ",
      "   (((((((((    ",
      "   (((((((((    ",
      "   (((((((((    "
    ],
    [
      "                ",
      "                ",
      "                ",
      "                ",
      "                ",
      "                ",
      "                ",
      "                ",
      "   (((((((((    ",
      "   (((((((((    ",
      "   (((((((((    ",
      "   (((((((((    ",
      "   (((((((((    ",
      "   (((((((((    ",
      "   (((((((((    ",
      "   (((((((((    "
    ]
  ],
  "palette": {
    "palette": [
      {
        "char": "!",
        "block": "minecraft:chiseled_stone_bricks"
      },
      {
        "char": "$",
        "block": "minecraft:coarse_dirt"
      },
      {
        "char": "%",
        "block": "minecraft:gravel"
      },
      {
        "char": "&",
        "block": "minecraft:stone_bricks"
      },
      {
        "char": "'",
        "block": "tfmg:asphalt"
      },
      {
        "char": "(",
        "block": "the_wasteland_reworked:decayed_planks"
      }
    ]
  }
}
