{
  "xsize": 16,
  "zsize": 16,
  "slices": [
    [
      "------%%%%%%%%%%",
      "------%%%%%%%%%%",
      "------%%%%%%%%%%",
      "------%%%%%%%%%%",
      "------%%%%%%%%%%",
      "------%%%%%%%%%%",
      "----''%%%%%%%%%%",
      "--''%-%%%%%%%%%%",
      "''%---%%%%%%%%%%",
      "%-----%%%%%%%%%%",
      "------%%%%%%%%%%",
      "------%%%%%%%%%%",
      "------%%%%%%%%%%",
      "------%%%%%%%%%%",
      "-------''%------",
      "%----%'%--%----%"
    ],
    [
      "&&&             ",
      "&&&     ,,  ,,  ",
      "&&&             ",
      "&&&    +++++++++",
      "&&&    +++++++++",
      "&&&    +++++++++",
      "&&&    +++++++++",
      "&&&    +++++++++",
      "&&&    +++++++++",
      "       +++++++++",
      "       +++++++++",
      "       +++++++++",
      "       +++++++++",
      "       +++++++++",
      "                ",
      "                "
    ],
    [
      "  ,             ",
      "  ,     ,,  ,,  ",
      "  ,             ",
      "  ,    ****(****",
      "  ,    *       *",
      "  ,    *       *",
      "  ,    *       *",
      "  ,    *       *",
      ",,,    *       *",
      "       *       *",
      "       *       *",
      "       *       *",
      "       *       *",
      "       *********",
      "                ",
      "                "
    ],
    [
      "  ,             ",
      "  ,     ,,  ,,  ",
      "  ,             ",
      "  ,    ****)****",
      "  ,    *       *",
      "  ,    *       *",
      "  ,    *       *",
      "  ,    *       *",
      ",,,    *       *",
      "       *       *",
      "       *       *",
      "       *       *",
      "       *       *",
      "       *********",
      "                ",
      "                "
    ],
    [
      "  ,             ",
      "  ,     $   $   ",
      "  ,             ",
      "  ,    *********",
      "  ,    *       *",
      "  ,    *       *",
      "  ,    *       *",
      "  ,    *       *",
      ",,,    *       *",
      "       *       *",
      "       *       *",
      "       *       *",
      "       *       *",
      "       *********",
      "                ",
      "                "
    ],
    [
      "  !             ",
      "  ,             ",
      "  ,             ",
      "  ,    *********",
      "  ,    *       *",
      "  !    *       *",
      "  !    *       *",
      "  ,    *       *",
      ",,,    *       *",
      "       *       *",
      "       *       *",
      "       *       *",
      "       *       *",
      "       *********",
      "                ",
      "                "
    ]
  ],
  "palette": {
    "palette": [
      {
        "char": "!",
        "block": "create:framed_glass"
      },
      {
        "char": "$",
        "block": "minecraft:chiseled_stone_bricks"
      },
      {
        "char": "%",
        "block": "minecraft:coarse_dirt"
      },
      {
        "char": "&",
        "block": "minecraft:dark_oak_planks"
      },
      {
        "char": "'",
        "block": "minecraft:gravel"
      },
      {
        "char": "(",
        "block": "minecraft:iron_door[facing=north,half=lower,hinge=left,open=false,powered=false]"
      },
      {
        "char": ")",
        "block": "minecraft:iron_door[facing=north,half=upper,hinge=left,open=false,powered=false]"
      },
      {
        "char": "*",
        "block": "minecraft:mossy_stone_bricks"
      },
      {
        "char": "+",
        "block": "minecraft:stone"
      },
      {
        "char": ",",
        "block": "minecraft:stone_bricks"
      },
      {
        "char": "-",
        "block": "tfmg:asphalt"
      }
    ]
  }
}
