{
  "xsize": 16,
  "zsize": 16,
  "slices": [
    [
      "                ",
      "                ",
      "                ",
      "                ",
      "    &   ''''''''",
      "        '       ",
      "  %     '       ",
      "$$%$$$$$'       ",
      "  %     '       ",
      "        ''''''''",
      "                ",
      "                ",
      "                ",
      "                ",
      "                ",
      "                "
    ],
    [
      "                ",
      "                ",
      "                ",
      "                ",
      "    &   ''''''''",
      "        '       ",
      "  %     '       ",
      "$$%$$$$$'       ",
      "  %     '       ",
      "        ''''''''",
      "                ",
      "                ",
      "                ",
      "                ",
      "                ",
      "                "
    ],
    [
      "                ",
      "                ",
      "                ",
      "                ",
      "    &   ''''''''",
      "        '       ",
      "  %     '       ",
      "$$%$$$$$'       ",
      "  %     '       ",
      "        ''''''''",
      "                ",
      "                ",
      "                ",
      "                ",
      "                ",
      "                "
    ],
    [
      "                ",
      "                ",
      "                ",
      "    ((((((((((((",
      "    ((((((((((((",
      "    ((((((((((((",
      "  % ((((((((((((",
      "$$%$((((((((((((",
      "  % ((((((((((((",
      "    ((((((((((((",
      "                ",
      "                ",
      "                ",
      "                ",
      "                ",
      "                "
    ],
    [
      "                ",
      "                ",
      "                ",
      "                ",
      "                ",
      "                ",
      "  %             ",
      "$$%$$$$$$$$$$$$$",
      ",,%,,,,,,,,,,,,,",
      ",,,,,,,,,,,,,,,,",
      ",,,,,,,,,,,,,,,,",
      ",,,,,,,,,,,,,,,,",
      ",,,,,,,,,,,,,,,,",
      ",,,,,,,,,,,,,,,,",
      ",,,,,,,,,,,,,,,,",
      ",,,,,,,,,,,,,,,,"
    ],
    [
      "                ",
      "                ",
      "                ",
      "                ",
      "                ",
      "                ",
      "  %             ",
      "$$%$$$$$$$$$$$$$",
      "  %             ",
      "  +             ",
      "  +  ))     !   ",
      "  +  *          ",
      "  +             ",
      "  +             ",
      "  +   *  *  *   ",
      "  +   )  )  )   "
    ]
  ],
  "palette": {
    "palette": [
      {
        "char": "!",
        "block": "minecraft:bookshelf"
      },
      {
        "char": "$",
        "block": "minecraft:bricks"
      },
      {
        "char": "%",
        "block": "minecraft:mud_bricks"
      },
      {
        "char": "&",
        "block": "minecraft:polished_blackstone_bricks"
      },
      {
        "char": "'",
        "block": "minecraft:smooth_stone"
      },
      {
        "char": "(",
        "block": "minecraft:smooth_stone_slab[type=bottom,waterlogged=false]"
      },
      {
        "char": ")",
        "block": "minecraft:spruce_slab[type=bottom,waterlogged=false]"
      },
      {
        "char": "*",
        "block": "minecraft:spruce_stairs[facing=north,half=bottom,shape=straight,waterlogged=false]"
      },
      {
        "char": "+",
        "block": "tfmg:cinder_block"
      },
      {
        "char": ",",
        "block": "tfmg:factory_floor"
      }
    ]
  }
}
