{
  "xsize": 16,
  "zsize": 16,
  "slices": [
    [
      " ///%%$/////////",
      " /%%$///////////",
      " %$/////////////",
      " ///////////////",
      " //////////////%",
      " $///////////%%$",
      " //////////%%$//",
      " ////////%%$////",
      " //////%%$//////",
      " ////%%$////////",
      " //%%$//////////",
      " $%$////////////",
      " $//////////////",
      " ///////////////",
      " /////////////%%",
      " ///////////%%$/"
    ],
    [
      "     (((((((((((",
      "     (((((((((((",
      "     (((((((((((",
      "     (((((((((((",
      "     (((((((((((",
      "     (((((((((((",
      "     (((((((((((",
      "     (((((((((((",
      "     (((((((((((",
      "     (((((((((((",
      "     (((((((((((",
      "     (((((((((((",
      "     (((((((((((",
      "     (((((((((((",
      "     (((((((((((",
      "     ((((((((((("
    ],
    [
      "     '          ",
      "     '          ",
      "     '          ",
      "     '          ",
      "     '          ",
      "     '   &    & ",
      "     '          ",
      "     '          ",
      "     '''''+'''''",
      "     '        ' ",
      "     '        ' ",
      "     '        ' ",
      "     '        ' ",
      "     '  -  !  ) ",
      "     '  .     ' ",
      "     '        ' "
    ],
    [
      "     '          ",
      "     '          ",
      "     '          ",
      "     '          ",
      "     '          ",
      "     '          ",
      "     '          ",
      "     '          ",
      "     ''''','''''",
      "     '        ' ",
      "     '        ' ",
      "     '        ' ",
      "     '        ' ",
      "     '        * ",
      "     '        ' ",
      "     '        ' "
    ],
    [
      "     '          ",
      "     '          ",
      "     '          ",
      "     '          ",
      "     '          ",
      "     '          ",
      "     '          ",
      "     '          ",
      "     '''''''''''",
      "     '        ' ",
      "     '        ' ",
      "     '        ' ",
      "     '        ' ",
      "     '        ' ",
      "     '        ' ",
      "     '        ' "
    ],
    [
      "     '          ",
      "     '          ",
      "     '          ",
      "     '          ",
      "     '          ",
      "     '          ",
      "     '          ",
      "     '          ",
      "     '''''''''''",
      "     '        ' ",
      "     '        ' ",
      "     '        ' ",
      "     '        ' ",
      "     '        ' ",
      "     '        ' ",
      "     '        ' "
    ]
  ],
  "palette": {
    "palette": [
      {
        "char": "!",
        "block": "minecraft:brewing_stand[has_bottle_0=false,has_bottle_1=false,has_bottle_2=false]"
      },
      {
        "char": "$",
        "block": "minecraft:coarse_dirt"
      },
      {
        "char": "%",
        "block": "minecraft:gravel"
      },
      {
        "char": "&",
        "block": "minecraft:quartz_stairs[facing=south,half=bottom,shape=straight,waterlogged=false]"
      },
      {
        "char": "'",
        "block": "minecraft:smooth_quartz"
      },
      {
        "char": "(",
        "block": "minecraft:smooth_stone"
      },
      {
        "char": ")",
        "block": "minecraft:spruce_door[facing=east,half=lower,hinge=left,open=false,powered=false]"
      },
      {
        "char": "*",
        "block": "minecraft:spruce_door[facing=east,half=upper,hinge=left,open=false,powered=false]"
      },
      {
        "char": "+",
        "block": "minecraft:spruce_door[facing=south,half=lower,hinge=left,open=false,powered=false]"
      },
      {
        "char": ",",
        "block": "minecraft:spruce_door[facing=south,half=upper,hinge=left,open=false,powered=false]"
      },
      {
        "char": "-",
        "block": "minecraft:white_bed[facing=south,occupied=false,part=foot]"
      },
      {
        "char": ".",
        "block": "minecraft:white_bed[facing=south,occupied=false,part=head]"
      },
      {
        "char": "/",
        "block": "tfmg:asphalt"
      }
    ]
  }
}
