{
  "xsize": 16,
  "zsize": 16,
  "slices": [
    [
      "................",
      "................",
      "................",
      "................",
      "........%%$.....",
      "......%%$.......",
      "....%%$.........",
      "..%%$...........",
      "%%$.............",
      "$...............",
      "................",
      ".............%%$",
      "...........%%$..",
      ".........%......",
      ".......%%$......",
      ".....%%$........"
    ],
    [
      "000000000 '     ",
      "000000000       ",
      "000000000       ",
      "000000000       ",
      "000000000       ",
      "000000000       ",
      "000000000 ------",
      "000000000 ')))))",
      "000000000  )))))",
      "000000000  )))))",
      "000000000  )))))",
      "000000000  )))))",
      "           )))))",
      "          -)))))",
      "          ')))))",
      "           )))))"
    ],
    [
      "        ! '     ",
      "////*///!       ",
      "        !       ",
      ",       !       ",
      "     1  !       ",
      "        !       ",
      "        !       ",
      "      & ! '///  ",
      "        !  /    ",
      "        !  /    ",
      "        !  /    ",
      "!!!!!!!!!  /    ",
      "           /    ",
      "           /   (",
      "          '/   (",
      "           /   ("
    ],
    [
      "        ! '     ",
      "////+///!       ",
      "        !       ",
      "        !       ",
      "        !       ",
      "        !       ",
      "        !       ",
      "      & ! '///  ",
      "        !  /    ",
      "        !  /    ",
      "        !  /    ",
      "!!!!!!!!!  /    ",
      "           /    ",
      "           /   (",
      "          '/   (",
      "           /   ("
    ],
    [
      "        ! '     ",
      "////////!       ",
      "        !       ",
      "        !       ",
      "        !       ",
      "        !       ",
      "        !       ",
      "      & ! '///  ",
      "        !  /    ",
      "        !  /    ",
      "        !  /    ",
      "!!!!!!!!!  /    ",
      "           /    ",
      "           /   (",
      "          '/   (",
      "           /   ("
    ],
    [
      "        ! '     ",
      "////////!       ",
      "        !       ",
      "        !       ",
      "        !       ",
      "        !       ",
      "        !       ",
      "      & ! '///  ",
      "        !  /    ",
      "        !  /    ",
      "        !  /    ",
      "!!!!!!!!!  /    ",
      "           /    ",
      "           /   (",
      "          '/   (",
      "           /   ("
    ]
  ],
  "palette": {
    "palette": [
      {
        "char": "!",
        "block": "minecraft:bricks"
      },
      {
        "char": "$",
        "block": "minecraft:coarse_dirt"
      },
      {
        "char": "%",
        "block": "minecraft:gravel"
      },
      {
        "char": "&",
        "block": "minecraft:ladder[facing=west,waterlogged=false]"
      },
      {
        "char": "'",
        "block": "minecraft:polished_blackstone_bricks"
      },
      {
        "char": "(",
        "block": "minecraft:scaffolding"
      },
      {
        "char": ")",
        "block": "minecraft:smooth_stone"
      },
      {
        "char": "*",
        "block": "minecraft:spruce_door[facing=south,half=lower,hinge=left,open=false,powered=false]"
      },
      {
        "char": "+",
        "block": "minecraft:spruce_door[facing=south,half=upper,hinge=left,open=false,powered=false]"
      },
      {
        "char": ",",
        "block": "minecraft:spruce_slab[type=bottom,waterlogged=false]"
      },
      {
        "char": "-",
        "block": "minecraft:white_concrete"
      },
      {
        "char": ".",
        "block": "tfmg:asphalt"
      },
      {
        "char": "/",
        "block": "tfmg:cinder_block"
      },
      {
        "char": "0",
        "block": "tfmg:factory_floor"
      },
      {
        "char": "1",
        "block": "the_wasteland_reworked:radio"
      }
    ]
  }
}
