{
  "xsize": 16,
  "zsize": 16,
  "slices": [
    [
      "4444444444444444",
      ",,,,,,,,,,,,,,,,",
      ",,,,,,,,,,,,,,,,",
      ",,,,,,,,,,,,,,,,",
      ",,,,,,,,,,,,,,,,",
      ",,,,,,,,,,,,,,,,",
      ",,,,,,,,,,,,,,,,",
      ",,,,,,,,,,,,,,,,",
      ",,,,,,,,,,,,,,,,",
      ",,,,,,,,,,,,,,,,",
      ",,,,,,,,,,,,,,,,",
      ",,,,,,,,,,,,,,,,",
      ",,,,,,,,,,,,,,,,",
      ",,,,,,,,,,,,,,,,",
      ",,,,,,,,,,,,,,,,",
      ",,,,,,,,,,,,,,,,"
    ],
    [
      "                ",
      "                ",
      "                ",
      "+              +",
      "                ",
      "                ",
      "                ",
      "                ",
      "****************",
      "****************",
      "****************",
      "****************",
      "****************",
      "****************",
      "****************",
      "****************"
    ],
    [
      "                ",
      "                ",
      "                ",
      "+              +",
      "                ",
      "                ",
      "                ",
      "  //      //    ",
      "((((($%(((((((((",
      "           (    ",
      "           (    ",
      "/     //   (    ",
      "      1    ( 5  ",
      "           -    ",
      "           (    ",
      ")   )   )  (  3 "
    ],
    [
      "                ",
      "                ",
      "                ",
      "+              +",
      "                ",
      "                ",
      "                ",
      "                ",
      "(2!!2&'((2!!2((2",
      "           (    ",
      "           (    ",
      "           (    ",
      "           (    ",
      "           .    ",
      "           (    ",
      "           (    "
    ],
    [
      "                ",
      "                ",
      "                ",
      "+              +",
      "                ",
      "                ",
      "                ",
      "                ",
      "(2!!2((((2!!2((2",
      "           (    ",
      "           (    ",
      "           (    ",
      "           (    ",
      "           (    ",
      "           (    ",
      "           (    "
    ],
    [
      "                ",
      "                ",
      "                ",
      "+              +",
      "                ",
      "                ",
      "                ",
      "  00      00    ",
      "((((((((((((((((",
      "           (    ",
      "           (    ",
      "           (    ",
      "           (    ",
      "           (    ",
      "           (    ",
      "           (    "
    ]
  ],
  "palette": {
    "palette": [
      {
        "char": "!",
        "block": "create:framed_glass"
      },
      {
        "char": "$",
        "block": "minecraft:dark_oak_door[facing=north,half=lower,hinge=left,open=false,powered=false]"
      },
      {
        "char": "%",
        "block": "minecraft:dark_oak_door[facing=north,half=lower,hinge=right,open=false,powered=false]"
      },
      {
        "char": "&",
        "block": "minecraft:dark_oak_door[facing=north,half=upper,hinge=left,open=false,powered=false]"
      },
      {
        "char": "'",
        "block": "minecraft:dark_oak_door[facing=north,half=upper,hinge=right,open=false,powered=false]"
      },
      {
        "char": "(",
        "block": "minecraft:light_gray_concrete"
      },
      {
        "char": ")",
        "block": "minecraft:oak_stairs[facing=north,half=bottom,shape=straight,waterlogged=false]"
      },
      {
        "char": "*",
        "block": "minecraft:polished_andesite"
      },
      {
        "char": "+",
        "block": "minecraft:polished_blackstone_bricks"
      },
      {
        "char": ",",
        "block": "minecraft:smooth_stone"
      },
      {
        "char": "-",
        "block": "minecraft:spruce_door[facing=east,half=lower,hinge=left,open=false,powered=false]"
      },
      {
        "char": ".",
        "block": "minecraft:spruce_door[facing=east,half=upper,hinge=left,open=false,powered=false]"
      },
      {
        "char": "/",
        "block": "minecraft:spruce_slab[type=bottom,waterlogged=false]"
      },
      {
        "char": "0",
        "block": "minecraft:spruce_slab[type=top,waterlogged=false]"
      },
      {
        "char": "1",
        "block": "minecraft:spruce_stairs[facing=north,half=bottom,shape=straight,waterlogged=false]"
      },
      {
        "char": "2",
        "block": "minecraft:stripped_spruce_log[axis=y]"
      },
      {
        "char": "3",
        "block": "minecraft:water_cauldron[level=3]"
      },
      {
        "char": "4",
        "block": "tfmg:asphalt"
      },
      {
        "char": "5",
        "block": "the_wasteland_reworked:radio"
      }
    ]
  }
}
