{
  "xsize": 16,
  "zsize": 16,
  "slices": [
    [
      "2222222222222''$",
      "22222222222''$22",
      "222222222''$2222",
      "2222222''$222222",
      "22222''$22222222",
      "222''$2222222222",
      "2''$222222222222",
      "'$22222222222222",
      "2222222222222222",
      "22222222222222''",
      "222222222222''$2",
      "2222222222''$222",
      "22222222''$22222",
      "2$2222$'$22$2222",
      "                ",
      "                "
    ],
    [
      "333333//////////",
      "333333//////////",
      "333333//////////",
      "333333//////////",
      "333333//////////",
      "333333//////////",
      "333333//////////",
      "333333//////////",
      "333333//////////",
      "333333//////////",
      "                ",
      "                ",
      "                ",
      "                ",
      "                ",
      "                "
    ],
    [
      "      !         ",
      "  %   !         ",
      "      ! &&&&&&&&",
      "      ! &&&&&&&&",
      "  0   ! &&&&&&&&",
      "      ! &&&&&&&&",
      "      ! &&&&&&&&",
      "1 .1 .! &&&&&&&&",
      "      ! &&&&&&&&",
      "------!!!!!!!!()",
      "                ",
      "                ",
      "                ",
      "                ",
      "                ",
      "                "
    ],
    [
      "      !         ",
      "      !         ",
      "      ! &&&&&&&&",
      "      ! &&&&&&&&",
      "      ! &&&&&&&&",
      "      ! &&&&&&&&",
      "      ! &&&&&&&&",
      "      ! &&&&&&&&",
      "  ,  ,! &&&&&&&&",
      "------!!!!!!!!*+",
      "                ",
      "                ",
      "                ",
      "                ",
      "                ",
      "                "
    ],
    [
      "      !         ",
      "      !         ",
      "      ! &&&&&&&&",
      "      ! &&&&&&&&",
      "      ! &&&&&&&&",
      "      ! &&&&&&&&",
      "      ! &&&&&&&&",
      "      ! &&&&&&&&",
      "      ! &&&&&&&&",
      "------!!!!!!!!!!",
      "                ",
      "                ",
      "                ",
      "                ",
      "                ",
      "                "
    ],
    [
      "      !         ",
      "      !         ",
      "      !         ",
      "      !         ",
      "      !         ",
      "      !         ",
      "      !         ",
      "      !         ",
      "      !         ",
      "------!!!!!!!!!!",
      "                ",
      "                ",
      "                ",
      "                ",
      "                ",
      "                "
    ]
  ],
  "palette": {
    "palette": [
      {
        "char": "!",
        "block": "minecraft:bricks"
      },
      {
        "char": "$",
        "block": "minecraft:coarse_dirt"
      },
      {
        "char": "%",
        "block": "minecraft:crafting_table"
      },
      {
        "char": "&",
        "block": "minecraft:dark_oak_planks"
      },
      {
        "char": "'",
        "block": "minecraft:gravel"
      },
      {
        "char": "(",
        "block": "minecraft:iron_door[facing=south,half=lower,hinge=left,open=false,powered=false]"
      },
      {
        "char": ")",
        "block": "minecraft:iron_door[facing=south,half=lower,hinge=right,open=false,powered=false]"
      },
      {
        "char": "*",
        "block": "minecraft:iron_door[facing=south,half=upper,hinge=left,open=false,powered=false]"
      },
      {
        "char": "+",
        "block": "minecraft:iron_door[facing=south,half=upper,hinge=right,open=false,powered=false]"
      },
      {
        "char": ",",
        "block": "minecraft:lever[face=wall,facing=south,powered=false]"
      },
      {
        "char": "-",
        "block": "minecraft:mud_bricks"
      },
      {
        "char": ".",
        "block": "minecraft:quartz_stairs[facing=north,half=bottom,shape=straight,waterlogged=false]"
      },
      {
        "char": "/",
        "block": "minecraft:smooth_stone"
      },
      {
        "char": "0",
        "block": "minecraft:spruce_slab[type=bottom,waterlogged=false]"
      },
      {
        "char": "1",
        "block": "minecraft:water_cauldron[level=2]"
      },
      {
        "char": "2",
        "block": "tfmg:asphalt"
      },
      {
        "char": "3",
        "block": "tfmg:factory_floor"
      }
    ]
  }
}
