{
  "xsize": 16,
  "zsize": 16,
  "slices": [
    [
      "        &.      ",
      "        &.      ",
      "        &.      ",
      "        &.      ",
      ",,,,,,,,&.,,,,,,",
      "        &.      ",
      "        &.      ",
      "        &.      ",
      "        &.      ",
      "     '  &.      ",
      "        &.      ",
      "        &.      ",
      "        &.      ",
      "        &.      ",
      "        &.      ",
      "        &.      "
    ],
    [
      "        &.      ",
      "        &.      ",
      "        &.      ",
      "        &.      ",
      "        &.      ",
      "        &.      ",
      "        &.      ",
      "        &.      ",
      "        &.      ",
      "        &.      ",
      "     '  &.      ",
      "        &.      ",
      "        &.      ",
      "        &.      ",
      "        &.      ",
      "        &.      "
    ],
    [
      "        &.      ",
      "        &.      ",
      "        &.      ",
      "        &.      ",
      "        &.      ",
      "        &.      ",
      "        &.      ",
      "        &.      ",
      "        &.      ",
      "        &.      ",
      "        &.      ",
      "     '  &.      ",
      "        &.      ",
      "        &.      ",
      "        &.      ",
      "        &.      "
    ],
    [
      "++++++++&.++++++",
      "++++++++&.++++++",
      "++++++++&.++++++",
      "++++++++&.++++++",
      "++++++++&.++++++",
      "++++++++&.++++++",
      "++++++++&.++++++",
      "++++++++&.++++++",
      "++++++++&.++++++",
      "++++++++&.++++++",
      "+++++ ++&.++++++",
      "+++++ ++&.++++++",
      "+++++'++&.++++++",
      "++++++++&.++++++",
      "++++++++&.++++++",
      "++++++++&.++++++"
    ],
    [
      "        &.      ",
      "        &.      ",
      "        &.      ",
      "        &.      ",
      ",,,,,),,&.,,,,,,",
      "        &.      ",
      "        &.      ",
      "        &.      ",
      "        &.      ",
      "        &.      ",
      "        &.      ",
      "        &.      ",
      "        &.      ",
      "        &.$     ",
      "    - ( &.!    -",
      "        &.      "
    ],
    [
      "        &.      ",
      "        &.      ",
      "        &.      ",
      "        &.      ",
      ",,,,,*,,&.,,,,,,",
      "        &.      ",
      "        &.      ",
      "        &.      ",
      "        &.      ",
      "        &.      ",
      "        &.      ",
      "        &.      ",
      "        &.      ",
      "        &.      ",
      "        &.      ",
      "      % &.      "
    ]
  ],
  "palette": {
    "palette": [
      {
        "char": "!",
        "block": "minecraft:brown_bed[facing=north,occupied=false,part=foot]"
      },
      {
        "char": "$",
        "block": "minecraft:brown_bed[facing=north,occupied=false,part=head]"
      },
      {
        "char": "%",
        "block": "minecraft:lever[face=wall,facing=south,powered=false]"
      },
      {
        "char": "&",
        "block": "minecraft:mud_bricks"
      },
      {
        "char": "'",
        "block": "minecraft:oak_stairs[facing=south,half=bottom,shape=straight,waterlogged=false]"
      },
      {
        "char": "(",
        "block": "minecraft:quartz_stairs[facing=north,half=bottom,shape=straight,waterlogged=false]"
      },
      {
        "char": ")",
        "block": "minecraft:spruce_door[facing=south,half=lower,hinge=left,open=false,powered=false]"
      },
      {
        "char": "*",
        "block": "minecraft:spruce_door[facing=south,half=upper,hinge=left,open=false,powered=false]"
      },
      {
        "char": "+",
        "block": "minecraft:spruce_planks"
      },
      {
        "char": ",",
        "block": "minecraft:stripped_spruce_wood"
      },
      {
        "char": "-",
        "block": "minecraft:water_cauldron[level=2]"
      },
      {
        "char": ".",
        "block": "minecraft:yellow_terracotta"
      }
    ]
  }
}
