{
  "xsize": 16,
  "zsize": 16,
  "slices": [
    [
      "1111111111&&%111",
      "11111111&&%11111",
      "111111&&%1111111",
      "1111&&%111111111",
      "11&&%11111111111",
      "&&%1111111111111",
      "%111111111111111",
      "111111111111111&",
      "1111111111111&&%",
      "11111111111&&%11",
      "111111111&&%1111",
      "1111111&&%111111",
      "11111&&%11111111",
      "111&&%1111111111",
      "1&&%111111111111",
      "&%11111111111111"
    ],
    [
      "3333333333333333",
      "3333333333333333",
      "3333333333333333",
      "3333333333333333",
      "3333333333333333",
      "3333333333333333",
      "3333333333333333",
      "3333333333333333",
      "3333333333333333",
      "3333333333333333",
      "3333333333333333",
      "3333333333333333",
      "3333333333333333",
      "3333333333333333",
      "(((3333333((((((",
      "(((3333333((&&&&"
    ],
    [
      "2          /  2 ",
      "2   .  .  .   2 ",
      "2222-22+22-22222",
      "2             2 ",
      "2             2 ",
      ")             ) ",
      "2             2 ",
      "2             2 ",
      "2222222+22222222",
      "2             2 ",
      "2             2 ",
      "2             2 ",
      "2             2 ",
      "2             2 ",
      "'00       ''''''",
      "' 0$$$$$$$' &&&&"
    ],
    [
      "2             2 ",
      "2             2 ",
      "2222222,22222222",
      "2             2 ",
      "2             2 ",
      "*             * ",
      "2             2 ",
      "2             2 ",
      "2222222,22222222",
      "2             2 ",
      "2             2 ",
      "2             2 ",
      "2             2 ",
      "2             2 ",
      "'00       ''''''",
      "' 0$$$$$$$' &&&&"
    ],
    [
      "2             2 ",
      "2             2 ",
      "2222222222222222",
      "2             2 ",
      "2             2 ",
      "2             2 ",
      "2             2 ",
      "2             2 ",
      "2222222222222222",
      "2             2 ",
      "2             2 ",
      "2             2 ",
      "2             2 ",
      "2             2 ",
      "'00       ''''''",
      "' 0$$$$$$$' &&&&"
    ],
    [
      "2             2 ",
      "2             2 ",
      "2222222222222222",
      "2             2 ",
      "2             2 ",
      "2             2 ",
      "2             2 ",
      "2             2 ",
      "2222222222222222",
      "2             2 ",
      "2             2 ",
      "2             2 ",
      "2             2 ",
      "2             2 ",
      "'00       ''''''",
      "' 0$$$!!$$' &&&&"
    ]
  ],
  "palette": {
    "palette": [
      {
        "char": "!",
        "block": "create:framed_glass"
      },
      {
        "char": "$",
        "block": "minecraft:bricks"
      },
      {
        "char": "%",
        "block": "minecraft:coarse_dirt"
      },
      {
        "char": "&",
        "block": "minecraft:gravel"
      },
      {
        "char": "'",
        "block": "minecraft:mud_bricks"
      },
      {
        "char": "(",
        "block": "minecraft:smooth_stone"
      },
      {
        "char": ")",
        "block": "minecraft:spruce_door[facing=east,half=lower,hinge=left,open=false,powered=false]"
      },
      {
        "char": "*",
        "block": "minecraft:spruce_door[facing=east,half=upper,hinge=left,open=false,powered=false]"
      },
      {
        "char": "+",
        "block": "minecraft:spruce_door[facing=south,half=lower,hinge=left,open=false,powered=false]"
      },
      {
        "char": ",",
        "block": "minecraft:spruce_door[facing=south,half=upper,hinge=left,open=false,powered=false]"
      },
      {
        "char": "-",
        "block": "minecraft:spruce_slab[type=bottom,waterlogged=false]"
      },
      {
        "char": ".",
        "block": "minecraft:spruce_stairs[facing=north,half=bottom,shape=straight,waterlogged=false]"
      },
      {
        "char": "/",
        "block": "minecraft:water_cauldron[level=1]"
      },
      {
        "char": "0",
        "block": "minecraft:yellow_terracotta"
      },
      {
        "char": "1",
        "block": "tfmg:asphalt"
      },
      {
        "char": "2",
        "block": "tfmg:cinder_block"
      },
      {
        "char": "3",
        "block": "tfmg:factory_floor"
      }
    ]
  }
}
