{
  "xsize": 16,
  "zsize": 16,
  "slices": [
    [
      "''''''''''''''''",
      "''''''''''''''$$",
      "''''''''''''$$!'",
      "''''''''''$$!'''",
      "''''''''$$!'''''",
      "''''''$$!'''''''",
      "''''$$!'''''''''",
      "!'$$!!''''!''''!",
      "                ",
      "                ",
      "                ",
      "                ",
      "                ",
      "                ",
      "                ",
      "                "
    ],
    [
      "%%%%$$$$$$$$$$$$",
      "%%%%$$$$$$$$$$$$",
      "%%%%$$$$$$$$$$$$",
      "%%%%$$$$$$$$$$$$",
      "%%%%$$$$$$$$$$$$",
      "    $$$$$$$$$$$$",
      "    $$$$$$$$$$$$",
      "    $$$$$$$$$$$$",
      "                ",
      "                ",
      "                ",
      "                ",
      "                ",
      "                ",
      "                ",
      "                "
    ],
    [
      "   &$$$$$$$$$$$$",
      "   &$$$$$$$$$$$$",
      "   &$$$$$$$$$$$$",
      "   &$$$$$$$$$$$$",
      "&&&&$$$$$$$$$$$$",
      "    $$$$$$$$$$$$",
      "    $$$$$$$$$$$$",
      "    $$$$$$$$$$$$",
      "                ",
      "                ",
      "                ",
      "                ",
      "                ",
      "                ",
      "                ",
      "                "
    ],
    [
      "   &$$$$$$$$$$$$",
      "   &$$$$$$$$$$$$",
      "   &$$$$$$$$$$$$",
      "   &$$$$$$$$$$$$",
      "&&&&$$$$$$$$$$$$",
      "    $$$$$$$$$$$$",
      "    $$$$$$$$$$$$",
      "    $$$$$$$$$$$$",
      "                ",
      "                ",
      "                ",
      "                ",
      "                ",
      "                ",
      "                ",
      "                "
    ],
    [
      "   &$$$$$$$$$$$$",
      "   &$$$$$$$$$$$$",
      "   &$$$$$$$$$$$$",
      "   &$$$$$$$$$$$$",
      "&&&&$$$$$$$$$$$$",
      "    $$$$$$$$$$$$",
      "    $$$$$$$$$$$$",
      "    $$$$$$$$$$$$",
      "                ",
      "                ",
      "                ",
      "                ",
      "                ",
      "                ",
      "                ",
      "                "
    ],
    [
      "   &$$$$$$$$$$$$",
      "   &$$$$$$$$$$$$",
      "   &$$$$$$$$$$$$",
      "   &$$$$$$$$$$$$",
      "&&&&$$$$$$$$$$$$",
      "    $$$$$$$$$$$$",
      "    $$$$$$$$$$$$",
      "    $$$$$$$$$$$$",
      "                ",
      "                ",
      "                ",
      "                ",
      "                ",
      "                ",
      "                ",
      "                "
    ]
  ],
  "palette": {
    "palette": [
      {
        "char": "!",
        "block": "minecraft:coarse_dirt"
      },
      {
        "char": "$",
        "block": "minecraft:gravel"
      },
      {
        "char": "%",
        "block": "minecraft:spruce_planks"
      },
      {
        "char": "&",
        "block": "minecraft:yellow_terracotta"
      },
      {
        "char": "'",
        "block": "tfmg:asphalt"
      }
    ]
  }
}
