{
  "xsize": 16,
  "zsize": 16,
  "slices": [
    [
      "                ",
      "                ",
      "                ",
      "                ",
      "&&&&&&&&&&&&&&& ",
      "              & ",
      "              & ",
      "              & ",
      "              & ",
      "              & ",
      "              & ",
      "              & ",
      "              &&",
      " !!!!!!!!! !!!!!",
      "&&&&&&&&&&&&&&& ",
      "                "
    ],
    [
      "                ",
      "                ",
      "                ",
      "                ",
      "&&&&&&&&&&&&&&& ",
      "              & ",
      "              & ",
      "              & ",
      "              & ",
      "              & ",
      "              & ",
      "              & ",
      "              &&",
      " !!!!!!!!! !!!!!",
      "&&&&&&&&&&&&&&& ",
      "                "
    ],
    [
      "                ",
      "                ",
      "                ",
      "                ",
      "&&&&&&&&&&&&&&& ",
      "((((((((((((((((",
      "((((((((((((((((",
      "((((((((((((((((",
      "((((((((((((((((",
      "((((((((((((((((",
      "((((((((((((((((",
      "((((((((((((((((",
      "((((((((((((((((",
      "              & ",
      "&&&&&&&&&&&&&&& ",
      "                "
    ],
    [
      "                ",
      "                ",
      "                ",
      "                ",
      "''''''''''''''' ",
      "''''''''''''''' ",
      "''''''''''''''' ",
      "''''''''''''''' ",
      "''''''''''''''' ",
      "''''''''''''''' ",
      "''''''''''''''' ",
      "''''''''''''''' ",
      "'''''''''''''''&",
      "''''''''''''''' ",
      "''''''''''''''' ",
      "                "
    ],
    [
      "                ",
      "                ",
      "                ",
      "                ",
      "                ",
      "                ",
      "                ",
      "                ",
      "                ",
      "                ",
      "))))))))))))))))",
      "))))))))))))))))",
      "))))))))))))))))",
      "                ",
      "                ",
      "                "
    ],
    [
      "                ",
      "                ",
      "                ",
      "                ",
      "                ",
      "                ",
      "                ",
      "                ",
      "                ",
      "                ",
      "                ",
      "                ",
      "&&&&&&&&&&&&&&&&",
      " !!!!$!!!! !!!!$",
      "                ",
      "   %  %      %  "
    ]
  ],
  "palette": {
    "palette": [
      {
        "char": "!",
        "block": "create:framed_glass"
      },
      {
        "char": "$",
        "block": "minecraft:dark_oak_door[facing=north,half=lower,hinge=left,open=false,powered=false]"
      },
      {
        "char": "%",
        "block": "minecraft:scaffolding"
      },
      {
        "char": "&",
        "block": "minecraft:smooth_stone"
      },
      {
        "char": "'",
        "block": "minecraft:smooth_stone_slab"
      },
      {
        "char": "(",
        "block": "minecraft:smooth_stone_slab[type=bottom,waterlogged=false]"
      },
      {
        "char": ")",
        "block": "tfmg:factory_floor"
      }
    ]
  }
}
