{
  "xsize": 16,
  "zsize": 16,
  "slices": [
    [
      "----------------",
      "----------------",
      "----------------",
      "----------------",
      "----------------",
      "----------------",
      "----------------",
      "---------%%$----",
      "-------%%$------",
      "-----%%$--------",
      "---%%$----------",
      "-%%$------------",
      "%$--------------",
      "----------------",
      "--------------%%",
      "------------%%$-"
    ],
    [
      "                ",
      "                ",
      "                ",
      "                ",
      "                ",
      "                ",
      "'''''''''       ",
      "'''''''''       ",
      "'''''''''       ",
      "'''''''''       ",
      "'''''''''       ",
      "'''''''''       ",
      "'''''''''       ",
      "'''''''''       ",
      "'''''''''       ",
      "''''''''////////"
    ],
    [
      "                ",
      "                ",
      "                ",
      "                ",
      "                ",
      "**   **         ",
      "&&&&&&&&&       ",
      "        &       ",
      "000000  &       ",
      "     0  &       ",
      "     0  &       ",
      "     0  &       ",
      "     0  &       ",
      "        &       ",
      "(&&&&&&&&       ",
      "        ........"
    ],
    [
      "                ",
      "                ",
      "                ",
      "                ",
      "                ",
      "                ",
      "!!,&,!!,&       ",
      "        &       ",
      "        &       ",
      "        &       ",
      "        &       ",
      "        &       ",
      "        &       ",
      "        &       ",
      ")&&&&&&&&       ",
      "        ........"
    ],
    [
      "                ",
      "                ",
      "                ",
      "                ",
      "                ",
      "                ",
      "!!,&,!!,&       ",
      "        &       ",
      "        &       ",
      "        &       ",
      "        &       ",
      "        &       ",
      "        &       ",
      "        &       ",
      "&&&&&&&&&       ",
      "        ........"
    ],
    [
      "                ",
      "                ",
      "                ",
      "                ",
      "                ",
      "++   ++         ",
      "&&&&&&&&&       ",
      "        &       ",
      "        &       ",
      "        &       ",
      "        &       ",
      "        &       ",
      "        &       ",
      "        &       ",
      "&&&&&&&&&       ",
      "        ........"
    ]
  ],
  "palette": {
    "palette": [
      {
        "char": "!",
        "block": "create:framed_glass"
      },
      {
        "char": "$",
        "block": "minecraft:coarse_dirt"
      },
      {
        "char": "%",
        "block": "minecraft:gravel"
      },
      {
        "char": "&",
        "block": "minecraft:light_gray_concrete"
      },
      {
        "char": "'",
        "block": "minecraft:polished_andesite"
      },
      {
        "char": "(",
        "block": "minecraft:spruce_door[facing=south,half=lower,hinge=left,open=false,powered=false]"
      },
      {
        "char": ")",
        "block": "minecraft:spruce_door[facing=south,half=upper,hinge=left,open=false,powered=false]"
      },
      {
        "char": "*",
        "block": "minecraft:spruce_slab[type=bottom,waterlogged=false]"
      },
      {
        "char": "+",
        "block": "minecraft:spruce_slab[type=top,waterlogged=false]"
      },
      {
        "char": ",",
        "block": "minecraft:stripped_spruce_log[axis=y]"
      },
      {
        "char": "-",
        "block": "tfmg:asphalt"
      },
      {
        "char": ".",
        "block": "tfmg:cinder_block"
      },
      {
        "char": "/",
        "block": "tfmg:factory_floor"
      },
      {
        "char": "0",
        "block": "zvhouses:stone_brick_countertop"
      }
    ]
  }
}
