{
  "xsize": 16,
  "zsize": 16,
  "slices": [
    [
      "          ------",
      "((----(----(----",
      "----------------",
      "----------------",
      "----------------",
      "----------------",
      "--------((------",
      "------((%-------",
      "----((%---------",
      "--((%-----------",
      "((%-------------",
      "%---------------",
      "---------------(",
      "-------------((%",
      "-----------((%--",
      "---------((%----"
    ],
    [
      "                ",
      "                ",
      "                ",
      "                ",
      "           )))))",
      "           )))))",
      "    *      )))))",
      "           )))))",
      "           )))))",
      ".......    )))))",
      ".......    )))))",
      ".......    )))))",
      ".....)))))))))))",
      ".....)))))))))))",
      ".....)))))))))))",
      ".....)))))))))))"
    ],
    [
      "                ",
      "                ",
      "                ",
      "                ",
      "           ,,,,,",
      "           ,    ",
      "    *      ,    ",
      "           ,    ",
      "           ,    ",
      "$$$$$$$    ,    ",
      "      $    ,    ",
      "      $    ,    ",
      "     ,,,,,,,    ",
      "     , !!!!&!!!!",
      "     ,     ,,,,,",
      "     ,   +  +   "
    ],
    [
      "                ",
      "                ",
      "                ",
      "                ",
      "           ,,,,,",
      "           ,    ",
      "    *      ,    ",
      "           ,    ",
      "           ,    ",
      "$$$$$$$    ,    ",
      "      $    ,    ",
      "      $    ,    ",
      "     ,,,,,,,    ",
      "     , !!!!'!!!!",
      "     ,     ,,,,,",
      "     ,   +  +   "
    ],
    [
      "                ",
      "                ",
      "                ",
      "                ",
      "           ,,,,,",
      "           ,    ",
      "    *      ,    ",
      "           ,    ",
      "           ,    ",
      "$$!!$$$    ,    ",
      "      $    ,    ",
      "      $    ,    ",
      "     ,,,,,,,    ",
      "     , !!!!!!!!!",
      "     ,     ,,,,,",
      "     ,   +  +   "
    ],
    [
      "                ",
      "                ",
      "                ",
      "                ",
      "           ,,,,,",
      "           ,    ",
      "    *      ,    ",
      "           ,    ",
      "           ,    ",
      "$$!!$$$    ,    ",
      "      $    ,    ",
      "      $    ,    ",
      "     ,,,,,,,    ",
      "     , !!!!!!!!!",
      "     ,     ,,,,,",
      "     ,          "
    ]
  ],
  "palette": {
    "palette": [
      {
        "char": "!",
        "block": "create:framed_glass"
      },
      {
        "char": "$",
        "block": "minecraft:bricks"
      },
      {
        "char": "%",
        "block": "minecraft:coarse_dirt"
      },
      {
        "char": "&",
        "block": "minecraft:dark_oak_door[facing=north,half=lower,hinge=left,open=false,powered=false]"
      },
      {
        "char": "'",
        "block": "minecraft:dark_oak_door[facing=north,half=upper,hinge=left,open=false,powered=false]"
      },
      {
        "char": "(",
        "block": "minecraft:gravel"
      },
      {
        "char": ")",
        "block": "minecraft:polished_andesite"
      },
      {
        "char": "*",
        "block": "minecraft:polished_blackstone_bricks"
      },
      {
        "char": "+",
        "block": "minecraft:scaffolding"
      },
      {
        "char": ",",
        "block": "minecraft:smooth_stone"
      },
      {
        "char": "-",
        "block": "tfmg:asphalt"
      },
      {
        "char": ".",
        "block": "tfmg:factory_floor"
      }
    ]
  }
}
