{
  "xsize": 16,
  "zsize": 16,
  "slices": [
    [
      "&&%))))))))     ",
      "%))))))))))     ",
      ")))))))))))     ",
      ")))))))))))     ",
      ")))))))))))     ",
      ")))))))))&&     ",
      ")))))))&&%)     ",
      ")))))&&%)))     ",
      ")))))))))))     ",
      ")))))))))))     ",
      ")))))))))))     ",
      ")))))))))))     ",
      ")))))))))))     ",
      ")))))))))))     ",
      ")))))))))))     ",
      "                "
    ],
    [
      "((((((((        ",
      "(((((((&&&      ",
      "(((((((&&&      ",
      "(((((((&&&      ",
      "((((((((        ",
      "((((&&&(        ",
      "((((&&&(        ",
      "((((&&&(        ",
      "&&&             ",
      "&&&             ",
      "&&&             ",
      "                ",
      "                ",
      "                ",
      "                ",
      "                "
    ],
    [
      "$$$$$$$'        ",
      "       &&&      ",
      " !     &&&      ",
      " !     &&&      ",
      " !              ",
      "    &&&         ",
      "    &&&         ",
      " '  &&&         ",
      "&&&             ",
      "&&&             ",
      "&&&             ",
      "                ",
      "                ",
      "                ",
      "                ",
      "                "
    ],
    [
      "$$$$$$$'        ",
      "       '        ",
      "        '       ",
      "                ",
      "                ",
      "    &&&         ",
      "    &&&         ",
      "   '&&&         ",
      "&&&             ",
      "&&&             ",
      "&&&             ",
      "                ",
      "                ",
      "                ",
      "                ",
      "                "
    ],
    [
      "$$$$$$$'        ",
      "       '        ",
      "!               ",
      "!               ",
      "!               ",
      "    &&&         ",
      "    &&&         ",
      "'   &&&         ",
      "&&&             ",
      "&&&             ",
      "&&&             ",
      "                ",
      "                ",
      "                ",
      "                ",
      "                "
    ],
    [
      "$$$$$$$'        ",
      "       '        ",
      "       '        ",
      "       '        ",
      "       '        ",
      "    &&&'        ",
      "    &&&'        ",
      "  ' &&&'        ",
      "&&&             ",
      "&&&             ",
      "&&&             ",
      "                ",
      "                ",
      "                ",
      "                ",
      "                "
    ]
  ],
  "palette": {
    "palette": [
      {
        "char": "!",
        "block": "minecraft:barrel[facing=up,open=false]"
      },
      {
        "char": "$",
        "block": "minecraft:bricks"
      },
      {
        "char": "%",
        "block": "minecraft:coarse_dirt"
      },
      {
        "char": "&",
        "block": "minecraft:gravel"
      },
      {
        "char": "'",
        "block": "minecraft:mud_bricks"
      },
      {
        "char": "(",
        "block": "minecraft:oak_planks"
      },
      {
        "char": ")",
        "block": "tfmg:asphalt"
      }
    ]
  }
}
