{
  "xsize": 16,
  "zsize": 16,
  "slices": [
    [
      "................",
      "................",
      "................",
      "................",
      "................",
      "................",
      "................",
      "................",
      "................",
      "................",
      "................",
      "................",
      "................",
      "................",
      "................",
      "................"
    ],
    [
      "----------------",
      "----------------",
      "----------------",
      "----------------",
      "----------------",
      "----------------",
      "----------------",
      "----------------",
      "----------------",
      "----------------",
      "----------------",
      "----------------",
      "++++++++--------",
      "++++++++--------",
      "++++++++--------",
      "++++++++--------"
    ],
    [
      "           *    ",
      "*1*****1********",
      "  *             ",
      "! *66666  $$$$$$",
      "! *66666        ",
      "! *66%66        ",
      "! *66666        ",
      "! /66666  $$$$$$",
      "! *66666        ",
      "  *          %  ",
      "  *             ",
      "&'******55555555",
      "        5       ",
      "        5       ",
      "      , 5       ",
      "        5  4 3  "
    ],
    [
      "           *    ",
      "*2*****2********",
      "  *             ",
      "! *66666  $$$$$$",
      "! *66666        ",
      "! *66666        ",
      "! *66666        ",
      "! 066666  $$$$$$",
      "! *66666        ",
      "  *             ",
      "  *             ",
      "()******55555555",
      "        5       ",
      "        5       ",
      "        5       ",
      "        5       "
    ],
    [
      "           *    ",
      "****************",
      "  *             ",
      "! *       $$$$$$",
      "! *             ",
      "! *             ",
      "! *             ",
      "! *       $$$$$$",
      "! *             ",
      "  *             ",
      "  *             ",
      "********55555555",
      "        5       ",
      "        5       ",
      "        5       ",
      "        5       "
    ],
    [
      "           *    ",
      "****************",
      "  *             ",
      "  *             ",
      "  *             ",
      "  *             ",
      "  *             ",
      "  *             ",
      "  *             ",
      "  *             ",
      "  *             ",
      "********55555555",
      "        5       ",
      "        5       ",
      "        5       ",
      "        5       "
    ]
  ],
  "palette": {
    "palette": [
      {
        "char": "!",
        "block": "immersiveengineering:sheetmetal_steel"
      },
      {
        "char": "$",
        "block": "minecraft:bookshelf"
      },
      {
        "char": "%",
        "block": "minecraft:brewing_stand"
      },
      {
        "char": "&",
        "block": "minecraft:iron_door[facing=south,half=lower,hinge=left,open=false,powered=false]"
      },
      {
        "char": "'",
        "block": "minecraft:iron_door[facing=south,half=lower,hinge=right,open=false,powered=false]"
      },
      {
        "char": "(",
        "block": "minecraft:iron_door[facing=south,half=upper,hinge=left,open=false,powered=false]"
      },
      {
        "char": ")",
        "block": "minecraft:iron_door[facing=south,half=upper,hinge=right,open=false,powered=false]"
      },
      {
        "char": "*",
        "block": "minecraft:light_gray_concrete"
      },
      {
        "char": "+",
        "block": "minecraft:moss_block"
      },
      {
        "char": ",",
        "block": "minecraft:oak_slab[type=bottom,waterlogged=false]"
      },
      {
        "char": "-",
        "block": "minecraft:polished_andesite"
      },
      {
        "char": ".",
        "block": "minecraft:smooth_stone"
      },
      {
        "char": "/",
        "block": "minecraft:spruce_door[facing=east,half=lower,hinge=left,open=false,powered=false]"
      },
      {
        "char": "0",
        "block": "minecraft:spruce_door[facing=east,half=upper,hinge=left,open=false,powered=false]"
      },
      {
        "char": "1",
        "block": "minecraft:spruce_door[facing=south,half=lower,hinge=left,open=false,powered=false]"
      },
      {
        "char": "2",
        "block": "minecraft:spruce_door[facing=south,half=upper,hinge=left,open=false,powered=false]"
      },
      {
        "char": "3",
        "block": "minecraft:water_cauldron[level=3]"
      },
      {
        "char": "4",
        "block": "minecraft:white_bed[facing=south,occupied=false,part=foot]"
      },
      {
        "char": "5",
        "block": "minecraft:white_concrete"
      },
      {
        "char": "6",
        "block": "zvhouses:stone_brick_countertop"
      }
    ]
  }
}
