{
  "xsize": 16,
  "zsize": 16,
  "slices": [
    [
      " 000&&$000000000",
      " 0&&$00000000000",
      " &$0000000000000",
      " 000000000000000",
      " 00000000000000&",
      " $00000000000&&$",
      " 0000000000&&$00",
      " 00000000&&$0000",
      " 000000&&$000000",
      " 0000&&$00000000",
      " 00&&$0000000000",
      " $&$000000000000",
      " $00000000000000",
      " 000000000000000",
      " 0000000000000&&",
      " 00000000000&&$0"
    ],
    [
      "     ,,,,,,,,,,,",
      "     ,,,,,,,,,,,",
      "     ,,,,,,,,,,,",
      "     ,,,,,,,,,,,",
      "     ,,,,,,,,,,,",
      "     ,,,,,,,,,,,",
      "     ,,,,,,,,,,,",
      "     ,,,,,,,,,,,",
      "     ,,,,,,,,,,,",
      "     ,,,,,,,,,,,",
      "     ,,,,,,,,,,,",
      "     ,,,,,,,,,,,",
      "     ,,,,,,,,,,,",
      "     ,,,,,,,,,,,",
      "     ,,,,,,,,,,,",
      "     ,,,,,,,,,,,"
    ],
    [
      "     1....*.....",
      "     1          ",
      "     1          ",
      "     1          ",
      "     1 %%%      ",
      "     1     2    ",
      "     1          ",
      "     1  -       ",
      "     1          ",
      "     1          ",
      "     1          ",
      "     1 ( )      ",
      "     1 '        ",
      "     1          ",
      "     1          ",
      "     11111111111"
    ],
    [
      "     1....+.....",
      "     1          ",
      "     1          ",
      "     1          ",
      "     1          ",
      "     1     /    ",
      "     1          ",
      "     1          ",
      "     1          ",
      "     1          ",
      "     1          ",
      "     1          ",
      "     1          ",
      "     1          ",
      "     1          ",
      "     11111111111"
    ],
    [
      "     1..........",
      "     1          ",
      "     1          ",
      "     1          ",
      "     1          ",
      "     1          ",
      "     1          ",
      "     !          ",
      "     !          ",
      "     1          ",
      "     1          ",
      "     1          ",
      "     1          ",
      "     !          ",
      "     !          ",
      "     11111111111"
    ],
    [
      "     1..........",
      "     1          ",
      "     1          ",
      "     1          ",
      "     1          ",
      "     1          ",
      "     1          ",
      "     !          ",
      "     !          ",
      "     1          ",
      "     1          ",
      "     1          ",
      "     1          ",
      "     !          ",
      "     !          ",
      "     11111111111"
    ]
  ],
  "palette": {
    "palette": [
      {
        "char": "!",
        "block": "create:framed_glass"
      },
      {
        "char": "$",
        "block": "minecraft:coarse_dirt"
      },
      {
        "char": "%",
        "block": "minecraft:dark_oak_stairs[facing=south,half=bottom,shape=straight,waterlogged=false]"
      },
      {
        "char": "&",
        "block": "minecraft:gravel"
      },
      {
        "char": "'",
        "block": "minecraft:green_bed[facing=north,occupied=false,part=foot]"
      },
      {
        "char": "(",
        "block": "minecraft:green_bed[facing=north,occupied=false,part=head]"
      },
      {
        "char": ")",
        "block": "minecraft:spawner",
        "tag": {
          "id": "minecraft:mob_spawner",
          "Delay": 200,
          "MinSpawnDelay": 240,
          "MaxSpawnDelay": 720,
          "SpawnCount": 1,
          "MaxNearbyEntities": 4,
          "RequiredPlayerRange": 14,
          "SpawnRange": 4,
          "SpawnData": {
            "entity": {
              "id": "minecraft:zombie"
            }
          },
          "SpawnPotentials": [
            {
              "weight": 1,
              "data": {
                "entity": {
                  "id": "minecraft:zombie"
                }
              }
            }
          ]
        }
      },
      {
        "char": "*",
        "block": "minecraft:spruce_door[facing=south,half=lower,hinge=left,open=false,powered=false]"
      },
      {
        "char": "+",
        "block": "minecraft:spruce_door[facing=south,half=upper,hinge=left,open=false,powered=false]"
      },
      {
        "char": ",",
        "block": "minecraft:spruce_planks"
      },
      {
        "char": "-",
        "block": "minecraft:spruce_slab[type=bottom,waterlogged=false]"
      },
      {
        "char": ".",
        "block": "minecraft:stripped_spruce_wood"
      },
      {
        "char": "/",
        "block": "supplementaries:item_shelf"
      },
      {
        "char": "0",
        "block": "tfmg:asphalt"
      },
      {
        "char": "1",
        "block": "the_wasteland_reworked:decayed_planks"
      },
      {
        "char": "2",
        "block": "the_wasteland_reworked:radio"
      }
    ]
  }
}
