{
  "xsize": 16,
  "zsize": 16,
  "slices": [
    [
      "                ",
      "                ",
      "                ",
      "                ",
      "                ",
      "                ",
      "                ",
      "          !!!!!!",
      "          !!!!!!",
      "          !!!!!!",
      "          !!!!!!",
      "          !!!!!!",
      "          !!!!!!",
      "          !!!!!!",
      "          !!!!!!",
      "          !!!!!!"
    ],
    [
      ",,,,,,,,,,,,,,,,",
      ",,,,,,,,,,,,,,,,",
      ",,,,,,,,,,,,,,,,",
      ",,,,,,,,,,,,,,,,",
      ",,,,,,,,,,,,,,,,",
      ",,,,,,,&&,,,,,,,",
      ",,,,,&&%,,,,,,,,",
      ",,,&&%,,,,,,,,,,",
      ",&&%,,,,,,,,,,,,",
      "&%,,,,,,,,,,,,,,",
      ",,,,,,,,,,,,,,,,",
      ",,,,,,,,,,,,,,,,",
      ",,,,,,,,,,,,,,,,",
      ",,,,,,,,,,,,,,,,",
      ",,,,,,,,&,,,,,,,",
      ",,,,,,&&%,,,,,,,"
    ],
    [
      "                ",
      "                ",
      "                ",
      "                ",
      "                ",
      "                ",
      "                ",
      "       ))       ",
      "       ))       ",
      "                ",
      "         +++    ",
      "         +++    ",
      "         +++    ",
      "         +++    ",
      "                ",
      "       ))       "
    ],
    [
      "                ",
      "                ",
      "                ",
      "                ",
      "                ",
      "                ",
      "                ",
      "       ))       ",
      "       ))       ",
      "                ",
      "                ",
      "          $     ",
      "          $     ",
      "                ",
      "                ",
      "       ))       "
    ],
    [
      "                ",
      "                ",
      "                ",
      "                ",
      "                ",
      "                ",
      "                ",
      "       ))       ",
      "       ))       ",
      "                ",
      "          *     ",
      "          $     ",
      "          $     ",
      "          *     ",
      "                ",
      "       ))       "
    ],
    [
      "                ",
      "                ",
      "                ",
      "                ",
      "                ",
      "                ",
      "                ",
      "       ))       ",
      "       ))       ",
      "                ",
      "          '     ",
      "          $     ",
      "          $     ",
      "          (     ",
      "                ",
      "       ))       "
    ]
  ],
  "palette": {
    "palette": [
      {
        "char": "!",
        "block": "immersiveengineering:concrete_reinforced"
      },
      {
        "char": "$",
        "block": "immersiveengineering:sheetmetal_steel"
      },
      {
        "char": "%",
        "block": "minecraft:coarse_dirt"
      },
      {
        "char": "&",
        "block": "minecraft:gravel"
      },
      {
        "char": "'",
        "block": "minecraft:lever[face=wall,facing=north,powered=false]"
      },
      {
        "char": "(",
        "block": "minecraft:lever[face=wall,facing=south,powered=false]"
      },
      {
        "char": ")",
        "block": "minecraft:polished_blackstone_bricks"
      },
      {
        "char": "*",
        "block": "minecraft:red_concrete"
      },
      {
        "char": "+",
        "block": "minecraft:smooth_stone"
      },
      {
        "char": ",",
        "block": "tfmg:asphalt"
      }
    ]
  }
}
