{
  "xsize": 16,
  "zsize": 16,
  "slices": [
    [
      "7777777++'777777",
      "77777++'77777777",
      "777++'7777777777",
      "7++'777777777777",
      "+'77777777777777",
      "7777777777777777",
      "77777777777777++",
      "777777777777++'7",
      "7777777777++'777",
      "77777777++'77777",
      "777777++'7777777",
      "7777++'777777777",
      "77++'77777777777",
      "++'7777777777777",
      "'777777777777777",
      "777777777777777+"
    ],
    [
      "999999999999----",
      "999999999999----",
      "999999999999----",
      "999999999999----",
      "999999999999----",
      "999999999999----",
      "999999999999----",
      "999999999999----",
      "999999999999----",
      "999999999999----",
      "999999999999----",
      "999999999999----",
      "999999999999----",
      "999999999999----",
      "999999999999----",
      "999999999999----"
    ],
    [
      "666         , . ",
      "666         ,   ",
      "666         )   ",
      "666         ,   ",
      "66$         ,   ",
      "666         ,   ",
      "            ,   ",
      "            ,882",
      "            ,   ",
      "288888882888,   ",
      "    8       ,   ",
      " (  8  5  % ,   ",
      "    0       ,   ",
      " &  8       ,   ",
      "::: 8 !!!!! ,   ",
      "   ,8      ,,   "
    ],
    [
      "666         8   ",
      "666         8 . ",
      "666         *   ",
      "666         8   ",
      "666         8   ",
      "666         8   ",
      "            8   ",
      "            8883",
      "            8   ",
      "3888888838888   ",
      "    8       8   ",
      "    8       8   ",
      "    1       8   ",
      "    8       8   ",
      "::: 8 !!!!! 8   ",
      "   ,8      ,8   "
    ],
    [
      "666         8   ",
      "666         8   ",
      "666           . ",
      "666         8   ",
      "666         8   ",
      "666         8   ",
      "            8   ",
      "4           8888",
      "            8   ",
      "8888888888888   ",
      "    8       8   ",
      "    8       8   ",
      "    8       8   ",
      "    8       8   ",
      "    8 !!!!! 8   ",
      "   ,8      ,8   "
    ],
    [
      "//          8   ",
      "//          8   ",
      "            8   ",
      "            8 . ",
      "            8   ",
      "            8   ",
      "            8   ",
      "            8888",
      "            8   ",
      "8888888888888   ",
      "    8       8   ",
      "    8       8   ",
      "    8       8   ",
      "    8       8   ",
      "    8       8   ",
      "   ,8      ,8   "
    ]
  ],
  "palette": {
    "palette": [
      {
        "char": "!",
        "block": "immersiveengineering:sheetmetal_steel"
      },
      {
        "char": "$",
        "block": "minecraft:black_concrete"
      },
      {
        "char": "%",
        "block": "minecraft:cauldron"
      },
      {
        "char": "&",
        "block": "minecraft:chest[facing=north,type=single,waterlogged=false]",
        "tag": {
          "id": "minecraft:chest",
          "LootTable": "infinite_domain:chests/wasteland_industrial"
        }
      },
      {
        "char": "'",
        "block": "minecraft:coarse_dirt"
      },
      {
        "char": "(",
        "block": "minecraft:crafting_table"
      },
      {
        "char": ")",
        "block": "minecraft:dark_oak_door[facing=east,half=lower,hinge=left,open=false,powered=false]"
      },
      {
        "char": "*",
        "block": "minecraft:dark_oak_door[facing=east,half=upper,hinge=left,open=false,powered=false]"
      },
      {
        "char": "+",
        "block": "minecraft:gravel"
      },
      {
        "char": ",",
        "block": "minecraft:mud_bricks"
      },
      {
        "char": "-",
        "block": "minecraft:polished_andesite"
      },
      {
        "char": ".",
        "block": "minecraft:polished_andesite_stairs[facing=south,half=bottom,shape=straight,waterlogged=false]"
      },
      {
        "char": "/",
        "block": "minecraft:red_concrete"
      },
      {
        "char": "0",
        "block": "minecraft:spruce_door[facing=east,half=lower,hinge=left,open=false,powered=false]"
      },
      {
        "char": "1",
        "block": "minecraft:spruce_door[facing=east,half=upper,hinge=left,open=false,powered=false]"
      },
      {
        "char": "2",
        "block": "minecraft:spruce_door[facing=south,half=lower,hinge=left,open=false,powered=false]"
      },
      {
        "char": "3",
        "block": "minecraft:spruce_door[facing=south,half=upper,hinge=left,open=false,powered=false]"
      },
      {
        "char": "4",
        "block": "minecraft:stripped_dark_oak_log[axis=x]"
      },
      {
        "char": "5",
        "block": "minecraft:water_cauldron[level=2]"
      },
      {
        "char": "6",
        "block": "minecraft:white_concrete"
      },
      {
        "char": "7",
        "block": "tfmg:asphalt"
      },
      {
        "char": "8",
        "block": "tfmg:cinder_block"
      },
      {
        "char": "9",
        "block": "tfmg:factory_floor"
      },
      {
        "char": ":",
        "block": "zvhouses:stone_brick_countertop"
      }
    ]
  }
}
