{
  "xsize": 16,
  "zsize": 16,
  "slices": [
    [
      "................",
      "..............$$",
      "............$$!.",
      "..........$$!...",
      "........$$!.....",
      "......$$!.......",
      "....$$!.........",
      "..$$!...........",
      "$$!.............",
      "!...............",
      "...............$",
      ".............$$!",
      "...........$$!..",
      ".........$$!....",
      ".......$$!......",
      ".....$$!........"
    ],
    [
      "////////////////",
      "////////////////",
      "////////////////",
      "////////////////",
      "////////////////",
      "////////////////",
      "////////////////",
      "////////////////",
      "////////////////",
      "////////////////",
      "////////////////",
      "////////////////",
      "////////////////",
      "////////////////",
      "////////////////",
      "////////////////"
    ],
    [
      "                ",
      "                ",
      "))),))))))))),))",
      "    )           ",
      "    )           ",
      "    )           ",
      "    )           ",
      "    )           ",
      "    *   %     % ",
      "    )   &     & ",
      "    )           ",
      "    )           ",
      "    )           ",
      "    )           ",
      "    )           ",
      "''''''''''''''''"
    ],
    [
      "                ",
      "                ",
      ")))-)))))))))-))",
      "    )           ",
      "    )           ",
      "    )           ",
      "    )           ",
      "    )           ",
      "    +           ",
      "    )           ",
      "    )           ",
      "    )           ",
      "    )           ",
      "    )           ",
      "    )           ",
      "''''''''''''''''"
    ],
    [
      "                ",
      "                ",
      "))))))))))))))))",
      "    )           ",
      "    )           ",
      "    )           ",
      "    )           ",
      "    )           ",
      "    )           ",
      "    )           ",
      "    )           ",
      "    )           ",
      "    )           ",
      "    )           ",
      "    )           ",
      "''''''''''''''''"
    ],
    [
      "      ((((((    ",
      "      ((((((    ",
      "))))))))))))))))",
      "    )           ",
      "    )           ",
      "    )           ",
      "    )           ",
      "    )           ",
      "    )           ",
      "    )           ",
      "    )           ",
      "    )           ",
      "    )           ",
      "    )           ",
      "    )           ",
      "''''''''''''''''"
    ]
  ],
  "palette": {
    "palette": [
      {
        "char": "!",
        "block": "minecraft:coarse_dirt"
      },
      {
        "char": "$",
        "block": "minecraft:gravel"
      },
      {
        "char": "%",
        "block": "minecraft:gray_bed[facing=south,occupied=false,part=foot]"
      },
      {
        "char": "&",
        "block": "minecraft:gray_bed[facing=south,occupied=false,part=head]"
      },
      {
        "char": "'",
        "block": "minecraft:light_gray_concrete"
      },
      {
        "char": "(",
        "block": "minecraft:sea_lantern"
      },
      {
        "char": ")",
        "block": "minecraft:smooth_quartz"
      },
      {
        "char": "*",
        "block": "minecraft:spruce_door[facing=east,half=lower,hinge=left,open=false,powered=false]"
      },
      {
        "char": "+",
        "block": "minecraft:spruce_door[facing=east,half=upper,hinge=left,open=false,powered=false]"
      },
      {
        "char": ",",
        "block": "minecraft:spruce_door[facing=south,half=lower,hinge=left,open=false,powered=false]"
      },
      {
        "char": "-",
        "block": "minecraft:spruce_door[facing=south,half=upper,hinge=left,open=false,powered=false]"
      },
      {
        "char": ".",
        "block": "tfmg:asphalt"
      },
      {
        "char": "/",
        "block": "tfmg:factory_floor"
      }
    ]
  }
}
