{
  "xsize": 16,
  "zsize": 16,
  "slices": [
    [
      " '              ",
      " %              ",
      " '              ",
      " '              ",
      "''              ",
      " '              ",
      " '              ",
      " '              ",
      " %              ",
      " '   '          ",
      " '   '          ",
      "''   '          ",
      " '   '       '  ",
      " '   '       '  ",
      " %   &       !  ",
      " '   '       !  "
    ],
    [
      " '              ",
      " '              ",
      " '              ",
      " '              ",
      "''              ",
      " '              ",
      " '              ",
      " '              ",
      " '   '          ",
      " '   '          ",
      " '   '          ",
      "''   ''         ",
      " '   '       '  ",
      " '   '       '  ",
      " '   '       !  ",
      " '   '       !  "
    ],
    [
      " '              ",
      " '              ",
      " '              ",
      " '              ",
      "''              ",
      " '              ",
      " '              ",
      " '              ",
      " '   '          ",
      " '   '          ",
      " '   '          ",
      "''   ''         ",
      " '   '       '  ",
      " '   '       '  ",
      " '   '       '  ",
      " '   '       '  "
    ],
    [
      " '              ",
      " '              ",
      " '              ",
      " '              ",
      " '   '          ",
      " '   '          ",
      " '   '          ",
      " '   '          ",
      " '   '          ",
      " '   '          ",
      " '   '          ",
      " '   '          ",
      " '   '       '  ",
      " '   '       '  ",
      " '   '       '  ",
      " '   '       '  "
    ],
    [
      "                ",
      "                ",
      "                ",
      "                ",
      "                ",
      "                ",
      "                ",
      "                ",
      "                ",
      "                ",
      "                ",
      "                ",
      "             '  ",
      "             '  ",
      "             '  ",
      "             '  "
    ],
    [
      "$$$$$           ",
      "$$$$$           ",
      "$$$$$           ",
      "$$$$$           ",
      "$$$$$$$         ",
      "$$$$$$$         ",
      "$$$$$$$$        ",
      "$$$$$$$$        ",
      "$$$$$$$         ",
      "$$$$$$$$        ",
      "$$$$$$$$        ",
      "$$$$$$$$        ",
      "$$$$$$$$$$$$$$  ",
      "$$$$$$$$$$$$$$  ",
      "$$$$$$$$$$$$$$  ",
      "$$$$$$$$$$$$$$  "
    ]
  ],
  "palette": {
    "palette": [
      {
        "char": "!",
        "block": "create:framed_glass"
      },
      {
        "char": "$",
        "block": "minecraft:smooth_stone"
      },
      {
        "char": "%",
        "block": "minecraft:spruce_door[facing=east,half=upper,hinge=left,open=false,powered=false]"
      },
      {
        "char": "&",
        "block": "minecraft:spruce_door[facing=west,half=upper,hinge=left,open=false,powered=false]"
      },
      {
        "char": "'",
        "block": "minecraft:white_concrete"
      }
    ]
  }
}
