{
  "xsize": 16,
  "zsize": 16,
  "slices": [
    [
      "     '          ",
      "     '          ",
      "     '          ",
      "     ' !!!!!!!!!",
      "     '''''''''''",
      "      $         ",
      "      $         ",
      "      $         ",
      "$$$$$$$         ",
      "                ",
      "                ",
      "                ",
      "                ",
      "                ",
      "                ",
      "                "
    ],
    [
      "     '          ",
      "     '          ",
      "     '          ",
      "     ' !!!!!!!!!",
      "     '''''''''''",
      "      $         ",
      "      $         ",
      "      $         ",
      "$$$$$$$         ",
      "                ",
      "                ",
      "                ",
      "                ",
      "                ",
      "                ",
      "                "
    ],
    [
      "     '          ",
      "     '          ",
      "     '          ",
      "     '          ",
      "     '''''''''''",
      "      $         ",
      "      $         ",
      "      $         ",
      "$$$$$$$         ",
      "                ",
      "                ",
      "                ",
      "                ",
      "                ",
      "                ",
      "                "
    ],
    [
      "     '          ",
      "     '          ",
      "     '          ",
      "     '          ",
      "     '''''''''''",
      "      $         ",
      "      $         ",
      "      $         ",
      "$$$$$$$         ",
      "                ",
      "                ",
      "                ",
      "                ",
      "                ",
      "                ",
      "                "
    ],
    [
      "(((((((         ",
      "(((((((         ",
      "(((((((         ",
      "(((((((         ",
      "((((((((((((((((",
      "((((((((((((((((",
      "((((((((((((((((",
      "((((((((((((((((",
      "$$$$$$$         ",
      "                ",
      "                ",
      "                ",
      "                ",
      "                ",
      "                ",
      "                "
    ],
    [
      "     '   &  &   ",
      "     '   &  &   ",
      "     '          ",
      "     ' !!!!%!!!!",
      "     '''''''''''",
      "      $         ",
      "      $         ",
      "      $         ",
      "$$$$$$$         ",
      "                ",
      "                ",
      "                ",
      "                ",
      "                ",
      "                ",
      "                "
    ]
  ],
  "palette": {
    "palette": [
      {
        "char": "!",
        "block": "create:framed_glass"
      },
      {
        "char": "$",
        "block": "minecraft:bricks"
      },
      {
        "char": "%",
        "block": "minecraft:dark_oak_door[facing=south,half=lower,hinge=left,open=false,powered=false]"
      },
      {
        "char": "&",
        "block": "minecraft:scaffolding"
      },
      {
        "char": "'",
        "block": "minecraft:smooth_stone"
      },
      {
        "char": "(",
        "block": "tfmg:factory_floor"
      }
    ]
  }
}
