{
  "xsize": 16,
  "zsize": 16,
  "slices": [
    [
      "2222222&&%222222",
      "22222&&%22222222",
      "222&&%2222222222",
      "2&&%222222222222",
      "&%22222222222222",
      "2222222222222222",
      "22222222222222&&",
      "222222222222&&%2",
      "2222222222&&%222",
      "22222222&&%22222",
      "222222&&%2222222",
      "2222&&%222222222",
      "22&&%22222222222",
      "&&%2222222222222",
      "%222222222222222",
      "222222222222222&"
    ],
    [
      "................",
      "................",
      "................",
      "................",
      "................",
      "................",
      "................",
      "................",
      "................",
      "................",
      "................",
      "................",
      "................",
      "................",
      "................",
      "................"
    ],
    [
      "        (1      ",
      "        (1      ",
      "        (1      ",
      "        (1      ",
      "/////,//(1//////",
      "        (1      ",
      "     )  (1      ",
      "        (1      ",
      "        (1      ",
      "        (1      ",
      "        (1      ",
      "        (1      ",
      "  +     (1      ",
      "        (1$     ",
      "    0 * (1!    0",
      "        (1      "
    ],
    [
      "        (1      ",
      "        (1      ",
      "        (1      ",
      "        (1      ",
      "/////-//(1//////",
      "        (1      ",
      "        (1      ",
      "     )  (1      ",
      "        (1      ",
      "        (1      ",
      "        (1      ",
      "        (1      ",
      "        (1      ",
      "        (1      ",
      "        (1      ",
      "      ' (1      "
    ],
    [
      "        (1      ",
      "        (1      ",
      "        (1      ",
      "        (1      ",
      "////////(1//////",
      "        (1      ",
      "        (1      ",
      "        (1      ",
      "     )  (1      ",
      "        (1      ",
      "        (1      ",
      "        (1      ",
      "        (1      ",
      "        (1      ",
      "        (1      ",
      "        (1      "
    ],
    [
      "        (1      ",
      "        (1      ",
      "        (1      ",
      "        (1      ",
      "////////(1//////",
      "        (1      ",
      "        (1      ",
      "        (1      ",
      "        (1      ",
      "     )  (1      ",
      "        (1      ",
      "        (1      ",
      "        (1      ",
      "        (1      ",
      "        (1      ",
      "        (1      "
    ]
  ],
  "palette": {
    "palette": [
      {
        "char": "!",
        "block": "minecraft:brown_bed[facing=north,occupied=false,part=foot]"
      },
      {
        "char": "$",
        "block": "minecraft:brown_bed[facing=north,occupied=false,part=head]"
      },
      {
        "char": "%",
        "block": "minecraft:coarse_dirt"
      },
      {
        "char": "&",
        "block": "minecraft:gravel"
      },
      {
        "char": "'",
        "block": "minecraft:lever[face=wall,facing=south,powered=false]"
      },
      {
        "char": "(",
        "block": "minecraft:mud_bricks"
      },
      {
        "char": ")",
        "block": "minecraft:oak_stairs[facing=south,half=bottom,shape=straight,waterlogged=false]"
      },
      {
        "char": "*",
        "block": "minecraft:quartz_stairs[facing=north,half=bottom,shape=straight,waterlogged=false]"
      },
      {
        "char": "+",
        "block": "minecraft:spawner",
        "tag": {
          "id": "minecraft:mob_spawner",
          "Delay": 200,
          "MinSpawnDelay": 240,
          "MaxSpawnDelay": 720,
          "SpawnCount": 2,
          "MaxNearbyEntities": 6,
          "RequiredPlayerRange": 14,
          "SpawnRange": 4,
          "SpawnData": {
            "entity": {
              "id": "minecraft:zombie"
            }
          },
          "SpawnPotentials": [
            {
              "weight": 1,
              "data": {
                "entity": {
                  "id": "minecraft:zombie"
                }
              }
            }
          ]
        }
      },
      {
        "char": ",",
        "block": "minecraft:spruce_door[facing=south,half=lower,hinge=left,open=false,powered=false]"
      },
      {
        "char": "-",
        "block": "minecraft:spruce_door[facing=south,half=upper,hinge=left,open=false,powered=false]"
      },
      {
        "char": ".",
        "block": "minecraft:spruce_planks"
      },
      {
        "char": "/",
        "block": "minecraft:stripped_spruce_wood"
      },
      {
        "char": "0",
        "block": "minecraft:water_cauldron[level=2]"
      },
      {
        "char": "1",
        "block": "minecraft:yellow_terracotta"
      },
      {
        "char": "2",
        "block": "tfmg:asphalt"
      }
    ]
  }
}
