{
  "xsize": 16,
  "zsize": 16,
  "slices": [
    [
      "        )       ",
      "        )       ",
      "        )       ",
      "        )       ",
      "        ))))))))",
      "        )       ",
      "        )       ",
      "        )       ",
      "        )       ",
      "        )       ",
      "        )       ",
      "        ))))))))",
      "        )       ",
      "        )       ",
      "        )       ",
      "        )       "
    ],
    [
      "        )       ",
      "        )       ",
      "        )       ",
      "        )       ",
      "        ))))))))",
      "        )       ",
      "        )       ",
      "        )       ",
      "        )       ",
      "        )       ",
      "        )       ",
      "        ))))))))",
      "        )       ",
      "        )       ",
      "        )       ",
      "        )       "
    ],
    [
      "        )       ",
      "        )       ",
      "        )       ",
      "        )       ",
      "        )       ",
      "        )       ",
      "        )       ",
      "        )       ",
      "        )       ",
      "        )       ",
      "        )       ",
      "        )       ",
      "        )       ",
      "        )       ",
      "        )       ",
      "        )       "
    ],
    [
      "        )       ",
      "        )       ",
      "        )       ",
      "        )       ",
      "        )       ",
      "        )       ",
      "        )       ",
      "        )       ",
      "        )       ",
      "        )       ",
      "        )       ",
      "        )       ",
      "        )       ",
      "        )       ",
      "        )       ",
      "        )       "
    ],
    [
      "        &%%%%%%%",
      "        &%%%%%%%",
      "        &%%%%%%%",
      "        &%%%%%%%",
      "        &%%%%%%%",
      "        &%%%%%%%",
      "        &%%%%%%%",
      "        &%%%%%%%",
      "        &%%%%%%%",
      "        &%%%%%%%",
      "        &%%%%%%%",
      "        &%%%%%%%",
      "        &%%%%%%%",
      "        &%%%%%%%",
      "        &%%%%%%%",
      "        &%%%%%%%"
    ],
    [
      "        )  $    ",
      "        )       ",
      "        )       ",
      "        )       ",
      "        ))))')))",
      "        )       ",
      "        )       ",
      "        )  ! (  ",
      "        )  $    ",
      "        )       ",
      "        )       ",
      "        ))))')))",
      "        )       ",
      "        )       ",
      "        )  ! (  ",
      "        )  $    "
    ]
  ],
  "palette": {
    "palette": [
      {
        "char": "!",
        "block": "minecraft:light_gray_bed[facing=south,occupied=false,part=foot]"
      },
      {
        "char": "$",
        "block": "minecraft:light_gray_bed[facing=south,occupied=false,part=head]"
      },
      {
        "char": "%",
        "block": "minecraft:polished_andesite"
      },
      {
        "char": "&",
        "block": "minecraft:smooth_stone"
      },
      {
        "char": "'",
        "block": "minecraft:spruce_door[facing=south,half=lower,hinge=left,open=false,powered=false]"
      },
      {
        "char": "(",
        "block": "kubejs:ruined_cauldron"
      },
      {
        "char": ")",
        "block": "minecraft:white_concrete"
      }
    ]
  }
}
