{
  "xsize": 16,
  "zsize": 16,
  "slices": [
    [
      " 000000000000000",
      " 0000000000000%%",
      " 00000000000%%$0",
      " $00000000%%$000",
      " 0000000%%$00000",
      " 00000%%$0000000",
      " 000%%$000000000",
      " 0%%$00000000000",
      " %$0000000000000",
      " $00000000000000",
      " 00000000000000%",
      " 000000000000%%$",
      " 0000000000%%$00",
      " 0$0000$0%%$$000",
      "                ",
      "                "
    ],
    [
      "   2222222222222",
      "   2222222222222",
      "   2222222222222",
      "   2222222222222",
      "   2222222222222",
      "   2222222222222",
      "   2222222222222",
      "   2222222222222",
      "   2222222222222",
      "                ",
      "                ",
      "                ",
      "                ",
      "                ",
      "                ",
      "                "
    ],
    [
      "   !            ",
      "   !            ",
      "   !111111,11111",
      "   !          1 ",
      "   !  ..   3  1 ",
      "   !  /       * ",
      "   !          1 ",
      "   !          1 ",
      "   !!!!&'!!!!!!!",
      "                ",
      "                ",
      "                ",
      "                ",
      "                ",
      "                ",
      "                "
    ],
    [
      "   !            ",
      "   !            ",
      "   !111111-11111",
      "   !          1 ",
      "   !          1 ",
      "   !          + ",
      "   !          1 ",
      "   !          1 ",
      "   !!!!()!!!!!!!",
      "                ",
      "                ",
      "                ",
      "                ",
      "                ",
      "                ",
      "                "
    ],
    [
      "   !            ",
      "   !            ",
      "   !111111111111",
      "   !          1 ",
      "   !          1 ",
      "   !          1 ",
      "   !          1 ",
      "   !          1 ",
      "   !!!!!!!!!!!!!",
      "                ",
      "                ",
      "                ",
      "                ",
      "                ",
      "                ",
      "                "
    ],
    [
      "   !            ",
      "   !            ",
      "   !111111111111",
      "   !          1 ",
      "   !          1 ",
      "   !          1 ",
      "   !          1 ",
      "   !          1 ",
      "   !!!!!!!!!!!!!",
      "                ",
      "                ",
      "                ",
      "                ",
      "                ",
      "                ",
      "                "
    ]
  ],
  "palette": {
    "palette": [
      {
        "char": "!",
        "block": "minecraft:bricks"
      },
      {
        "char": "$",
        "block": "minecraft:coarse_dirt"
      },
      {
        "char": "%",
        "block": "minecraft:gravel"
      },
      {
        "char": "&",
        "block": "minecraft:iron_door[facing=south,half=lower,hinge=left,open=false,powered=false]"
      },
      {
        "char": "'",
        "block": "minecraft:iron_door[facing=south,half=lower,hinge=right,open=false,powered=false]"
      },
      {
        "char": "(",
        "block": "minecraft:iron_door[facing=south,half=upper,hinge=left,open=false,powered=false]"
      },
      {
        "char": ")",
        "block": "minecraft:iron_door[facing=south,half=upper,hinge=right,open=false,powered=false]"
      },
      {
        "char": "*",
        "block": "minecraft:spruce_door[facing=east,half=lower,hinge=left,open=false,powered=false]"
      },
      {
        "char": "+",
        "block": "minecraft:spruce_door[facing=east,half=upper,hinge=left,open=false,powered=false]"
      },
      {
        "char": ",",
        "block": "minecraft:spruce_door[facing=south,half=lower,hinge=left,open=false,powered=false]"
      },
      {
        "char": "-",
        "block": "minecraft:spruce_door[facing=south,half=upper,hinge=left,open=false,powered=false]"
      },
      {
        "char": ".",
        "block": "minecraft:spruce_slab[type=bottom,waterlogged=false]"
      },
      {
        "char": "/",
        "block": "minecraft:spruce_stairs[facing=north,half=bottom,shape=straight,waterlogged=false]"
      },
      {
        "char": "0",
        "block": "tfmg:asphalt"
      },
      {
        "char": "1",
        "block": "tfmg:cinder_block"
      },
      {
        "char": "2",
        "block": "tfmg:factory_floor"
      },
      {
        "char": "3",
        "block": "the_wasteland_reworked:radio"
      }
    ]
  }
}
