{
  "xsize": 16,
  "zsize": 16,
  "slices": [
    [
      "     %          ",
      "     %          ",
      "     %          ",
      "     %          ",
      "     %          ",
      "     %          ",
      "     %          ",
      "     %          ",
      "     %          ",
      "     %          ",
      "     %          ",
      "     %          ",
      "     %          ",
      "     %          ",
      "     %          ",
      "     %          "
    ],
    [
      "     %          ",
      "     %          ",
      "     %          ",
      "     %          ",
      "     %          ",
      "     %          ",
      "     %          ",
      "     %          ",
      "     %          ",
      "     %          ",
      "     %          ",
      "     %          ",
      "     %          ",
      "     %          ",
      "     %          ",
      "     %          "
    ],
    [
      "     %          ",
      "     %          ",
      "     %          ",
      "     %          ",
      "     %          ",
      "     %          ",
      "     %          ",
      "     %          ",
      "     %          ",
      "     %          ",
      "     %          ",
      "     %          ",
      "     %          ",
      "     %          ",
      "     %          ",
      "     %          "
    ],
    [
      "     %          ",
      "     %          ",
      "     %          ",
      "     %          ",
      "     %          ",
      "     %          ",
      "     %          ",
      "     %          ",
      "     %          ",
      "     %          ",
      "     %          ",
      "     %          ",
      "     %          ",
      "     %          ",
      "     %          ",
      "     %          "
    ],
    [
      "&&&&&&&         ",
      "&&&&&&&         ",
      "&&&&&&&         ",
      "&&&&&&&         ",
      "&&&&&&&         ",
      "&&&&&&&         ",
      "&&&&&&&         ",
      "&&&&&&&         ",
      "&&&&&&&         ",
      "&&&&&&&         ",
      "&&&&&&&         ",
      "&&&&&&&         ",
      "&&&&&&&         ",
      "&&&&&&&         ",
      "&&&&&&&         ",
      "&&&&&&&         "
    ],
    [
      "$    %          ",
      "$    %          ",
      "$    %          ",
      "$    %          ",
      "$    %          ",
      "$    %          ",
      "$    %          ",
      "$    %          ",
      "$    %          ",
      "$    %  ''''''' ",
      "$    %   !      ",
      "$    %   $  $   ",
      "$    %   $  $   ",
      "$    %   $  $   ",
      "$    %   $  $   ",
      "$    %   $  $   "
    ]
  ],
  "palette": {
    "palette": [
      {
        "char": "!",
        "block": "minecraft:bookshelf"
      },
      {
        "char": "$",
        "block": "minecraft:scaffolding"
      },
      {
        "char": "%",
        "block": "minecraft:smooth_stone"
      },
      {
        "char": "&",
        "block": "tfmg:factory_floor"
      },
      {
        "char": "'",
        "block": "zvhouses:spruce_countertop"
      }
    ]
  }
}
