{
  "xsize": 16,
  "zsize": 16,
  "slices": [
    [
      "+++++++''&++++++",
      "+++++''&++++++++",
      "+++''&++++++++++",
      "+''&++++++++++++",
      "'&++++++++++++++",
      "++++++++++++++++",
      "++++++++++++++''",
      "++++++++++++''&+",
      "++++++++++''&+++",
      "++++++++''&+++++",
      "++++++''&+++++++",
      "++++''&+++++++++",
      "++''&+++++++++++",
      "''&+++++++++++++",
      "&+++++++++++++++",
      "+++++++++++++++'"
    ],
    [
      "((((((((((((((((",
      "((((((((((((((((",
      "((((((((((((((((",
      "((((((((((((((((",
      "((((((((((((((((",
      "((((((((((((((((",
      "((((((((((((((((",
      "((((((((((((((((",
      "((((((((((((((((",
      "((((((((((((((((",
      "((((((((((((((((",
      "((((((((((((((((",
      "((((((((((((((((",
      "((((((((((((((((",
      "((((((((((((((((",
      "(((((((((((((((("
    ],
    [
      "   %       %! !%",
      "   %       %! !%",
      "   % !!!!! %! !%",
      "   % !!!!! %   %",
      "   % !!!!! %   %",
      "-- %       %   %",
      "-- %       %,  %",
      "   %       %   %",
      "%%%%%%%)%%%%%)%%",
      "   %       %   %",
      "   %       %   %",
      "   %  $    %   %",
      "   %       %   %",
      "   %       %   %",
      "   %       %   %",
      "   %       %   %"
    ],
    [
      "   %       %! !%",
      "   %       %! !%",
      "   % !!!!! %! !%",
      "   % !!!!! %   %",
      "   % !!!!! %   %",
      "   %       %   %",
      "   %       %   %",
      "   %       %   %",
      "%%%%%%%*%%%%%*%%",
      "   %       %   %",
      "   %       %   %",
      "   %       %   %",
      "   %       %   %",
      "   %       %   %",
      "   %       %   %",
      "   %       %   %"
    ],
    [
      "   %       %! !%",
      "   %       %! !%",
      "   % !!!!! %! !%",
      "   % !!!!! %   %",
      "   % !!!!! %   %",
      "   %       %   %",
      "   %       %   %",
      "   %       %   %",
      "%%%%%%%%%%%%%%%%",
      "   %       %   %",
      "   %       %   %",
      "   %       %   %",
      "   %       %   %",
      "   %       %   %",
      "   %       %   %",
      "   %       %   %"
    ],
    [
      "   %       %   %",
      "   %       %   %",
      "   %       %   %",
      "   %       %   %",
      "   %       %   %",
      "   %       %   %",
      "   %       %   %",
      "   %       %   %",
      "%%%%%%%%%%%%%%%%",
      "   %       %   %",
      "   %       %   %",
      "   %       %   %",
      "   %       %   %",
      "   %       %   %",
      "   %       %   %",
      "   %       %   %"
    ]
  ],
  "palette": {
    "palette": [
      {
        "char": "!",
        "block": "minecraft:bookshelf"
      },
      {
        "char": "$",
        "block": "kubejs:ruined_brewing_stand"
      },
      {
        "char": "%",
        "block": "minecraft:bricks"
      },
      {
        "char": "&",
        "block": "minecraft:coarse_dirt"
      },
      {
        "char": "'",
        "block": "minecraft:gravel"
      },
      {
        "char": "(",
        "block": "minecraft:oak_planks"
      },
      {
        "char": ")",
        "block": "minecraft:spruce_door[facing=south,half=lower,hinge=left,open=false,powered=false]"
      },
      {
        "char": "*",
        "block": "minecraft:spruce_door[facing=south,half=upper,hinge=left,open=false,powered=false]"
      },
      {
        "char": "+",
        "block": "tfmg:asphalt"
      },
      {
        "char": ",",
        "block": "the_wasteland_reworked:radio"
      },
      {
        "char": "-",
        "block": "zvhouses:spruce_countertop"
      }
    ]
  }
}
