{
  "xsize": 16,
  "zsize": 16,
  "slices": [
    [
      " +++++++++&&%+++",
      " %++++++&&%+++++",
      " +++++&&%+++++++",
      " +++&&%+++++++++",
      " +&&%+++++++++++",
      " &%+++++++++++++",
      " +++++++++++++++",
      " +%++++%++++%++&",
      "                ",
      "                ",
      "                ",
      "                ",
      "                ",
      "                ",
      "                ",
      "                "
    ],
    [
      "   *************",
      "   *************",
      "   *************",
      "   *************",
      "   *************",
      "                ",
      "                ",
      "                ",
      "                ",
      "                ",
      "                ",
      "                ",
      "                ",
      "                ",
      "                ",
      "                "
    ],
    [
      "   $         $' ",
      "   $         $' ",
      "   $         $' ",
      "   $         $' ",
      "   $$$$$($$$$$''",
      "                ",
      "                ",
      "                ",
      "                ",
      "                ",
      "                ",
      "                ",
      "                ",
      "                ",
      "                ",
      "                "
    ],
    [
      "   $         $' ",
      "   $         $' ",
      "   $         $' ",
      "   $         $' ",
      "   $$$$$)$$$$$''",
      "                ",
      "                ",
      "                ",
      "                ",
      "                ",
      "                ",
      "                ",
      "                ",
      "                ",
      "                ",
      "                "
    ],
    [
      "   $         $' ",
      "   $         $' ",
      "   $         $' ",
      "   $         $' ",
      "   $$$$$!!$$$$''",
      "                ",
      "                ",
      "                ",
      "                ",
      "                ",
      "                ",
      "                ",
      "                ",
      "                ",
      "                ",
      "                "
    ],
    [
      "   $         $' ",
      "   $         $' ",
      "   $         $' ",
      "   $         $' ",
      "   $$$$$!!$$$$''",
      "                ",
      "                ",
      "                ",
      "                ",
      "                ",
      "                ",
      "                ",
      "                ",
      "                ",
      "                ",
      "                "
    ]
  ],
  "palette": {
    "palette": [
      {
        "char": "!",
        "block": "create:framed_glass"
      },
      {
        "char": "$",
        "block": "minecraft:bricks"
      },
      {
        "char": "%",
        "block": "minecraft:coarse_dirt"
      },
      {
        "char": "&",
        "block": "minecraft:gravel"
      },
      {
        "char": "'",
        "block": "minecraft:mud_bricks"
      },
      {
        "char": "(",
        "block": "minecraft:spruce_door[facing=south,half=lower,hinge=left,open=false,powered=false]"
      },
      {
        "char": ")",
        "block": "minecraft:spruce_door[facing=south,half=upper,hinge=left,open=false,powered=false]"
      },
      {
        "char": "*",
        "block": "minecraft:spruce_planks"
      },
      {
        "char": "+",
        "block": "tfmg:asphalt"
      }
    ]
  }
}
