{
  "xsize": 16,
  "zsize": 16,
  "slices": [
    [
      " )))%%!)))))))))",
      " )%%!)))))))))))",
      " %!)))))))))))))",
      " )))))))))))))))",
      " ))))))))))))))%",
      " !)))))))))))%%!",
      " ))))))))))%%!))",
      " ))))))))%%!))))",
      " ))))))%%!))))))",
      " ))))%%!))))))))",
      " ))%%!))))))))))",
      " !%!))))))))))))",
      " !))))))))))))))",
      " )))))))))))))))",
      " )))))))))))))%%",
      " )))))))))))%%!)"
    ],
    [
      "    ************",
      "    ************",
      "    ************",
      "    ************",
      "    ************",
      "    ************",
      "    ************",
      "    ************",
      "    ************",
      "    ************",
      "    ************",
      "    ************",
      "    ************",
      "    ************",
      "    ************",
      "    ************"
    ],
    [
      "    '           ",
      "    '           ",
      "    '           ",
      "    '           ",
      "    '  $$$$$$  $",
      "    '  $$$$$$  $",
      "    '  $$$$$$  $",
      "    '  $$&$$$  $",
      "    '  $$$$$$  $",
      "    '  $$$$$$  $",
      "    '  $$$$$$  $",
      "    '  $$$$$$  $",
      "    '           ",
      "    '  (        ",
      "    '           ",
      "    '           "
    ],
    [
      "    '           ",
      "    '           ",
      "    '           ",
      "    '           ",
      "    '           ",
      "    '           ",
      "    '           ",
      "    '           ",
      "    '           ",
      "    '           ",
      "    '           ",
      "    '           ",
      "    '           ",
      "    '           ",
      "    '  (        ",
      "    '           "
    ],
    [
      "    '           ",
      "    '           ",
      "    '           ",
      "    '           ",
      "    '           ",
      "    '           ",
      "    '           ",
      "    '           ",
      "    '           ",
      "    '           ",
      "    '           ",
      "    '           ",
      "    '           ",
      "    '           ",
      "    '           ",
      "    '  (        "
    ],
    [
      "    '           ",
      "    '           ",
      "    '           ",
      "    '           ",
      "    '           ",
      "    '           ",
      "    '           ",
      "    '           ",
      "    '           ",
      "    '           ",
      "    '           ",
      "    '           ",
      "    '           ",
      "    '           ",
      "    '           ",
      "    '           "
    ]
  ],
  "palette": {
    "palette": [
      {
        "char": "!",
        "block": "minecraft:coarse_dirt"
      },
      {
        "char": "$",
        "block": "minecraft:dark_oak_planks"
      },
      {
        "char": "%",
        "block": "minecraft:gravel"
      },
      {
        "char": "&",
        "block": "minecraft:lectern[facing=north,has_book=false,powered=false]"
      },
      {
        "char": "'",
        "block": "minecraft:polished_blackstone_bricks"
      },
      {
        "char": "(",
        "block": "minecraft:stone_brick_stairs[facing=south,half=bottom,shape=straight,waterlogged=false]"
      },
      {
        "char": ")",
        "block": "tfmg:asphalt"
      },
      {
        "char": "*",
        "block": "tfmg:factory_floor"
      }
    ]
  }
}
