{
  "xsize": 16,
  "zsize": 16,
  "slices": [
    [
      "1111111111111))&",
      "11111111111))&11",
      "111111111))&1111",
      "1111111))&111111",
      "11111))&11111111",
      "111))&1111111111",
      "1))&111111111111",
      ")&11111111111111",
      "1111111111111111",
      "1111111111111111",
      "1111111111111111",
      "1111111111111111",
      "1111111111111111",
      "1111111111111111",
      "1111111111111111",
      "                "
    ],
    [
      "++++++++++++++++",
      "++++++++++++++++",
      "++++++++++++++++",
      "++++++++++++++++",
      "++++++++++++++++",
      "++++++++++++++++",
      "++++++++++++++++",
      "++++++++++++++++",
      "                ",
      "                ",
      "     /   /      ",
      "                ",
      "                ",
      "                ",
      "                ",
      "                "
    ],
    [
      "$$$$$$$-$$$$$-$$",
      "   $       $   $",
      "   $ !!!!! $   $",
      "0  $ !!!%! $   $",
      "   $ !!!!! $   $",
      "   $       $ , $",
      "   $       $   $",
      "*******'*****'**",
      "                ",
      "                ",
      "     /   /      ",
      "                ",
      "                ",
      "                ",
      "                ",
      "                "
    ],
    [
      "$$$$$$$.$$$$$.$$",
      "   $       $   $",
      "   $ !!!!! $   $",
      "   $ !!!!! $   $",
      "   $ !!!!! $ , $",
      "   $       $   $",
      "   $       $   $",
      "*******(*****(**",
      "                ",
      "                ",
      "     /   /      ",
      "                ",
      "                ",
      "                ",
      "                ",
      "                "
    ],
    [
      "$$$$$$$$$$$$$$$$",
      "   $       $   $",
      "   $ !!!!! $   $",
      "   $ !!!!! $ , $",
      "   $ !!!!! $   $",
      "   $       $   $",
      "   $       $   $",
      "****************",
      "                ",
      "                ",
      "     /   /      ",
      "                ",
      "                ",
      "                ",
      "                ",
      "                "
    ],
    [
      "$$$$$$$$$$$$$$$$",
      "   $       $   $",
      "   $       $ , $",
      "   $       $   $",
      "   $       $   $",
      "   $       $   $",
      "   $       $   $",
      "****************",
      "                ",
      "                ",
      "     /   /      ",
      "                ",
      "                ",
      "                ",
      "                ",
      "                "
    ]
  ],
  "palette": {
    "palette": [
      {
        "char": "!",
        "block": "immersiveengineering:crate"
      },
      {
        "char": "$",
        "block": "minecraft:bricks"
      },
      {
        "char": "%",
        "block": "minecraft:chest[facing=west,type=single,waterlogged=false]",
        "tag": {
          "id": "minecraft:chest",
          "LootTable": "infinite_domain:chests/wasteland_market"
        }
      },
      {
        "char": "&",
        "block": "minecraft:coarse_dirt"
      },
      {
        "char": "'",
        "block": "minecraft:dark_oak_door[facing=south,half=lower,hinge=left,open=false,powered=false]"
      },
      {
        "char": "(",
        "block": "minecraft:dark_oak_door[facing=south,half=upper,hinge=left,open=false,powered=false]"
      },
      {
        "char": ")",
        "block": "minecraft:gravel"
      },
      {
        "char": "*",
        "block": "minecraft:mud_bricks"
      },
      {
        "char": "+",
        "block": "minecraft:oak_planks"
      },
      {
        "char": ",",
        "block": "minecraft:oak_stairs[facing=north,half=bottom,shape=straight,waterlogged=false]"
      },
      {
        "char": "-",
        "block": "minecraft:spruce_door[facing=south,half=lower,hinge=left,open=false,powered=false]"
      },
      {
        "char": ".",
        "block": "minecraft:spruce_door[facing=south,half=upper,hinge=left,open=false,powered=false]"
      },
      {
        "char": "/",
        "block": "minecraft:stripped_dark_oak_log[axis=y]"
      },
      {
        "char": "0",
        "block": "minecraft:water_cauldron[level=3]"
      },
      {
        "char": "1",
        "block": "tfmg:asphalt"
      }
    ]
  }
}
