{
  "xsize": 16,
  "zsize": 16,
  "slices": [
    [
      "   2222222222222",
      "..2222.2222.2222",
      "2222222222222222",
      "2222222222222222",
      "2222222222222222",
      "2222222222222222",
      "2222222222222222",
      "222222..%2222222",
      "2222..%222222222",
      "22..%22222222222",
      "..%2222222222222",
      "%222222222222222",
      "222222222222222.",
      "2222222222222..%",
      "22222222222..%22",
      "222222222..%2222"
    ],
    [
      "                ",
      "                ",
      "                ",
      "                ",
      "   0000000000000",
      "   0000000000000",
      "   0000000000000",
      "3330000000000000",
      "3330000000000000",
      "3330000000000000",
      "3333333333333333",
      "3333333333333333",
      "3333333333333333",
      "3333333333333333",
      "3333333333333333",
      "3333333333333333"
    ],
    [
      "                ",
      "                ",
      "                ",
      "                ",
      "   111111111&'11",
      "   1            ",
      "   1         /  ",
      "$$$1         /  ",
      "   1         /  ",
      "   111111111*+11",
      "4444            ",
      "                ",
      "                ",
      "                ",
      "                ",
      "                "
    ],
    [
      "                ",
      "                ",
      "                ",
      "                ",
      "   111111111()11",
      "   1            ",
      "   1         /  ",
      "$$$1         /  ",
      "   1         /  ",
      "   111111111,-11",
      "                ",
      "                ",
      "                ",
      "                ",
      "                ",
      "                "
    ],
    [
      "                ",
      "                ",
      "                ",
      "                ",
      "   1111111111111",
      "   1            ",
      "   1         /  ",
      "$$$1  !!     /  ",
      "   1         /  ",
      "   1111111111111",
      "                ",
      "                ",
      "                ",
      "                ",
      "                ",
      "                "
    ],
    [
      "                ",
      "                ",
      "                ",
      "                ",
      "   1111111111111",
      "   1            ",
      "   1         /  ",
      "$$$1  !!     /  ",
      "   1         /  ",
      "   1111111111111",
      "                ",
      "                ",
      "                ",
      "                ",
      "                ",
      "                "
    ]
  ],
  "palette": {
    "palette": [
      {
        "char": "!",
        "block": "create:framed_glass"
      },
      {
        "char": "$",
        "block": "minecraft:bricks"
      },
      {
        "char": "%",
        "block": "minecraft:coarse_dirt"
      },
      {
        "char": "&",
        "block": "minecraft:dark_oak_door[facing=north,half=lower,hinge=left,open=false,powered=false]"
      },
      {
        "char": "'",
        "block": "minecraft:dark_oak_door[facing=north,half=lower,hinge=right,open=false,powered=false]"
      },
      {
        "char": "(",
        "block": "minecraft:dark_oak_door[facing=north,half=upper,hinge=left,open=false,powered=false]"
      },
      {
        "char": ")",
        "block": "minecraft:dark_oak_door[facing=north,half=upper,hinge=right,open=false,powered=false]"
      },
      {
        "char": "*",
        "block": "minecraft:dark_oak_door[facing=south,half=lower,hinge=left,open=false,powered=false]"
      },
      {
        "char": "+",
        "block": "minecraft:dark_oak_door[facing=south,half=lower,hinge=right,open=false,powered=false]"
      },
      {
        "char": ",",
        "block": "minecraft:dark_oak_door[facing=south,half=upper,hinge=left,open=false,powered=false]"
      },
      {
        "char": "-",
        "block": "minecraft:dark_oak_door[facing=south,half=upper,hinge=right,open=false,powered=false]"
      },
      {
        "char": ".",
        "block": "minecraft:gravel"
      },
      {
        "char": "/",
        "block": "minecraft:mud_bricks"
      },
      {
        "char": "0",
        "block": "minecraft:polished_andesite"
      },
      {
        "char": "1",
        "block": "minecraft:smooth_stone"
      },
      {
        "char": "2",
        "block": "tfmg:asphalt"
      },
      {
        "char": "3",
        "block": "tfmg:factory_floor"
      },
      {
        "char": "4",
        "block": "zvhouses:spruce_countertop"
      }
    ]
  }
}
