{
  "xsize": 16,
  "zsize": 16,
  "slices": [
    [
      "  &         &   ",
      "  &         &   ",
      "  &         &   ",
      "  &         &   ",
      "  &         &   ",
      "  &         &   ",
      "  &         &   ",
      "  &         &   ",
      "  &         &   ",
      "  &         &   ",
      "  &         &   ",
      "&&&&&&&&&&&&&   ",
      "                ",
      "                ",
      "                ",
      "                "
    ],
    [
      "            &   ",
      "            &   ",
      "            &   ",
      "            &   ",
      "            &   ",
      "            &   ",
      "            &   ",
      "            &   ",
      "            &   ",
      "            &   ",
      "            &   ",
      "&&&&&&&&&&&&&   ",
      "                ",
      "                ",
      "                ",
      "                "
    ],
    [
      "%%%%%%%%%%%%&   ",
      "%%%%%%%%%%%%&   ",
      "%%%%%%%%%%%%&   ",
      "%%%%%%%%%%%%&   ",
      "%%%%%%%%%%%%&   ",
      "%%%%%%%%%%%%&   ",
      "%%%%%%%%%%%%&   ",
      "%%%%%%%%%%%%&   ",
      "%%%%%%%%%%%%&   ",
      "%%%%%%%%%%%%&   ",
      "%%%%%%%%%%%%&   ",
      "&&&&&&&&&&&&&   ",
      "                ",
      "                ",
      "                ",
      "                "
    ],
    [
      "         !! &   ",
      "         !! &   ",
      "         !! &   ",
      "&'&&&&&&'&&&&   ",
      "            &   ",
      "            &   ",
      "            &   ",
      "&'&&&&&&'&&&&   ",
      "   $$$      &   ",
      "   $$$      &   ",
      "            &   ",
      "&&&&&&&&&&&&&   ",
      "                ",
      "                ",
      "                ",
      "                "
    ],
    [
      "         !! &   ",
      "         !! &   ",
      "         !! &   ",
      "&(&&&&&&(&&&&   ",
      "            &   ",
      "            &   ",
      "            &   ",
      "&(&&&&&&(&&&&   ",
      "            &   ",
      "            &   ",
      "            &   ",
      "&&&&&&&&&&&&&   ",
      "                ",
      "                ",
      "                ",
      "                "
    ],
    [
      "         !! &   ",
      "         !! &   ",
      "         !! &   ",
      "&&&&&&&&&&&&&   ",
      "            &   ",
      "            &   ",
      "            &   ",
      "&&&&&&&&&&&&&   ",
      "            &   ",
      "            &   ",
      "            &   ",
      "&&&&&&&&&&&&&   ",
      "                ",
      "                ",
      "                ",
      "                "
    ]
  ],
  "palette": {
    "palette": [
      {
        "char": "!",
        "block": "immersiveengineering:crate"
      },
      {
        "char": "$",
        "block": "minecraft:dark_oak_slab[type=bottom,waterlogged=false]"
      },
      {
        "char": "%",
        "block": "minecraft:polished_andesite"
      },
      {
        "char": "&",
        "block": "minecraft:polished_deepslate"
      },
      {
        "char": "'",
        "block": "minecraft:spruce_door[facing=south,half=lower,hinge=left,open=false,powered=false]"
      },
      {
        "char": "(",
        "block": "minecraft:spruce_door[facing=south,half=upper,hinge=left,open=false,powered=false]"
      }
    ]
  }
}
