{
  "xsize": 16,
  "zsize": 16,
  "slices": [
    [
      "        !       ",
      "        !       ",
      "        !       ",
      "        !       ",
      "        !       ",
      "        !       ",
      "        !       ",
      "      % !  '''''",
      "        !  '''''",
      "        !  '''''",
      "        !  '''''",
      "!!!!!!!!!  '''''",
      "           '''''",
      "           '''''",
      "           '''''",
      "           '''''"
    ],
    [
      "        !       ",
      "        !       ",
      "        !       ",
      "        !       ",
      "        !       ",
      "        !       ",
      "        !       ",
      "      % !       ",
      "        !       ",
      "        !       ",
      "        !       ",
      "!!!!!!!!!       ",
      "                ",
      "                ",
      "                ",
      "                "
    ],
    [
      "        !       ",
      "        !       ",
      "        !       ",
      "        !       ",
      "        !       ",
      "        !       ",
      "        !       ",
      "      % !       ",
      "        !       ",
      "        !       ",
      "        !       ",
      "!!!!!!!!!       ",
      "                ",
      "                ",
      "                ",
      "                "
    ],
    [
      "        !       ",
      "        !       ",
      "        !       ",
      "        !       ",
      "        !       ",
      "        !       ",
      "        !       ",
      "      % !       ",
      "        !       ",
      "        !       ",
      "        !       ",
      "!!!!!!!!!       ",
      "                ",
      "                ",
      "                ",
      "                "
    ],
    [
      "&&&&&&&&&       ",
      "&&&&&&&&&       ",
      "&&&&&&&&&       ",
      "&&&&&&&&&       ",
      "&&&&&&&&&       ",
      "&&&&&&&&&       ",
      "&&&&&&&&&       ",
      "&&&&&&%&&       ",
      "&&&&&&&&&       ",
      "&&&&&&&&&       ",
      "&&&&&&&&&       ",
      "&&&&&&&&&       ",
      "                ",
      "                ",
      "                ",
      "                "
    ],
    [
      "                ",
      "                ",
      "                ",
      "                ",
      "                ",
      "                ",
      "                ",
      "      $         ",
      "                ",
      "                ",
      "                ",
      "                ",
      "                ",
      "                ",
      "                ",
      "                "
    ]
  ],
  "palette": {
    "palette": [
      {
        "char": "!",
        "block": "minecraft:bricks"
      },
      {
        "char": "$",
        "block": "minecraft:iron_trapdoor[facing=north,half=bottom,open=false,powered=false,waterlogged=false]"
      },
      {
        "char": "%",
        "block": "minecraft:ladder[facing=west,waterlogged=false]"
      },
      {
        "char": "&",
        "block": "minecraft:smooth_stone"
      },
      {
        "char": "'",
        "block": "minecraft:weathered_cut_copper"
      }
    ]
  }
}
