{
  "xsize": 16,
  "zsize": 16,
  "slices": [
    [
      " ///&&$/////////",
      " /&&$///////////",
      " &$/////////////",
      " ///////////////",
      " //////////////&",
      " $///////////&&$",
      " //////////&&$//",
      " ////////&&$////",
      " //////&&$//////",
      " ////&&$////////",
      " //&&$//////////",
      " $&$////////////",
      " $//////////////",
      " ///////////////",
      " /////////////&&",
      " ///////////&&$/"
    ],
    [
      "     +++++++++++",
      "     +++++++++++",
      "     +++++++++++",
      "     +++++++++++",
      "     +++++++++++",
      "     +++++++++++",
      "     +++++++++++",
      "     +++++++++++",
      "     +++++++++++",
      "     +++++++++++",
      "     +++++++++++",
      "     +++++++++++",
      "     +++++++++++",
      "     +++++++++++",
      "     +++++++++++",
      "     +++++++++++"
    ],
    [
      "     0----)-----",
      "     0          ",
      "     0          ",
      "     0          ",
      "     0 %%%      ",
      "     0     1    ",
      "     0          ",
      "     0  ,       ",
      "     0          ",
      "     0          ",
      "     0          ",
      "     0 (        ",
      "     0 '        ",
      "     0          ",
      "     0          ",
      "     00000000000"
    ],
    [
      "     0----*-----",
      "     0          ",
      "     0          ",
      "     0          ",
      "     0          ",
      "     0     .    ",
      "     0          ",
      "     0          ",
      "     0          ",
      "     0          ",
      "     0          ",
      "     0          ",
      "     0          ",
      "     0          ",
      "     0          ",
      "     00000000000"
    ],
    [
      "     0----------",
      "     0          ",
      "     0          ",
      "     0          ",
      "     0          ",
      "     0          ",
      "     0          ",
      "     !          ",
      "     !          ",
      "     0          ",
      "     0          ",
      "     0          ",
      "     0          ",
      "     !          ",
      "     !          ",
      "     00000000000"
    ],
    [
      "     0----------",
      "     0          ",
      "     0          ",
      "     0          ",
      "     0          ",
      "     0          ",
      "     0          ",
      "     !          ",
      "     !          ",
      "     0          ",
      "     0          ",
      "     0          ",
      "     0          ",
      "     !          ",
      "     !          ",
      "     00000000000"
    ]
  ],
  "palette": {
    "palette": [
      {
        "char": "!",
        "block": "create:framed_glass"
      },
      {
        "char": "$",
        "block": "minecraft:coarse_dirt"
      },
      {
        "char": "%",
        "block": "minecraft:dark_oak_stairs[facing=south,half=bottom,shape=straight,waterlogged=false]"
      },
      {
        "char": "&",
        "block": "minecraft:gravel"
      },
      {
        "char": "'",
        "block": "minecraft:green_bed[facing=north,occupied=false,part=foot]"
      },
      {
        "char": "(",
        "block": "minecraft:green_bed[facing=north,occupied=false,part=head]"
      },
      {
        "char": ")",
        "block": "minecraft:spruce_door[facing=south,half=lower,hinge=left,open=false,powered=false]"
      },
      {
        "char": "*",
        "block": "minecraft:spruce_door[facing=south,half=upper,hinge=left,open=false,powered=false]"
      },
      {
        "char": "+",
        "block": "minecraft:spruce_planks"
      },
      {
        "char": ",",
        "block": "minecraft:spruce_slab[type=bottom,waterlogged=false]"
      },
      {
        "char": "-",
        "block": "minecraft:stripped_spruce_wood"
      },
      {
        "char": ".",
        "block": "supplementaries:item_shelf"
      },
      {
        "char": "/",
        "block": "tfmg:asphalt"
      },
      {
        "char": "0",
        "block": "the_wasteland_reworked:decayed_planks"
      },
      {
        "char": "1",
        "block": "the_wasteland_reworked:radio"
      }
    ]
  }
}
