{
  "xsize": 16,
  "zsize": 16,
  "slices": [
    [
      "                ",
      "                ",
      "                ",
      "                ",
      "                ",
      "                ",
      "                ",
      "                ",
      "                ",
      "%%%%%%%%%%%%%%%%",
      "                ",
      "$$$$$           ",
      "$$$$$           ",
      "$$$$$           ",
      "!!!!!!!!!!!!!!!!",
      "                "
    ],
    [
      "                ",
      "                ",
      "                ",
      "                ",
      "                ",
      "                ",
      "                ",
      "                ",
      "                ",
      "%%%%%%%%%%%%%%%%",
      "                ",
      "$$$$$           ",
      "$$$$$           ",
      "$$$$$           ",
      "!!!!!!!!!!!!!!!!",
      "                "
    ],
    [
      "                ",
      "                ",
      "                ",
      "                ",
      "                ",
      "                ",
      "                ",
      "                ",
      "                ",
      "                ",
      "                ",
      "                ",
      "                ",
      "                ",
      "!!!!!!!!!!!!!!!!",
      "                "
    ],
    [
      "                ",
      "                ",
      "                ",
      "                ",
      "                ",
      "                ",
      "                ",
      "                ",
      "                ",
      "                ",
      "                ",
      "                ",
      "                ",
      "                ",
      "          !!!!!!",
      "                "
    ],
    [
      "                ",
      "                ",
      "                ",
      "                ",
      "                ",
      "                ",
      "                ",
      "                ",
      "                ",
      "                ",
      "                ",
      "                ",
      "                ",
      "                ",
      "          !!!!!!",
      "                "
    ],
    [
      "          &&&&&&",
      "          &&&&&&",
      "          &&&&&&",
      "          &&&&&&",
      "          &&&&&&",
      "          &&&&&&",
      "          &&&&&&",
      "          &&&&&&",
      "          &&&&&&",
      "          &&&&&&",
      "          &&&&&&",
      "          &&&&&&",
      "          &&&&&&",
      "          &&&&&&",
      "          !!!!!!",
      "                "
    ]
  ],
  "palette": {
    "palette": [
      {
        "char": "!",
        "block": "minecraft:bricks"
      },
      {
        "char": "$",
        "block": "minecraft:scaffolding"
      },
      {
        "char": "%",
        "block": "tfmg:cinder_block"
      },
      {
        "char": "&",
        "block": "tfmg:factory_floor"
      }
    ]
  }
}
