{
  "xsize": 16,
  "zsize": 16,
  "slices": [
    [
      "    )           ",
      "    )           ",
      "    )           ",
      "    )           ",
      "    )           ",
      "    )           ",
      "    )           ",
      "    )           ",
      "    )     +     ",
      "    )           ",
      "    )           ",
      "    )           ",
      "    ,,,,,,,,,,,,",
      "    ,        ,  ",
      "    ,        ,  ",
      "    ,        ,  "
    ],
    [
      "    )           ",
      "    )           ",
      "    )           ",
      "    )           ",
      "    )           ",
      "    )           ",
      "    )           ",
      "    )           ",
      "    )           ",
      "    )     +     ",
      "    )           ",
      "    )           ",
      "    ,,,,,,,,,,,,",
      "    ,           ",
      "    ,           ",
      "    ,           "
    ],
    [
      "    $**       **",
      "    $****   ****",
      "    $***********",
      "    $***********",
      "    $***********",
      "    $***********",
      "    $***********",
      "    $***********",
      "    $***** *****",
      "    $***********",
      "    $***********",
      "    $***********",
      "    $,,,,,,,,,,,",
      "    $-----------",
      "    $-----------",
      "    $-----------"
    ],
    [
      "    )         ) ",
      "    )         ) ",
      "    )         ) ",
      "    ))))))0)))))",
      "    )     +   ) ",
      "    )         ) ",
      "    )  22     ) ",
      "    )  3      . ",
      "    )         ) ",
      "    )         ) ",
      "    )         ) ",
      "    )         ) ",
      "    ,,,,,,,,, %&",
      "    ,           ",
      "    ,           ",
      "    ,           "
    ],
    [
      "    )         ) ",
      "    )         ) ",
      "    )         ) ",
      "    ))))))1)))))",
      "    )         ) ",
      "    )     +   ) ",
      "    !         ) ",
      "    !         / ",
      "    )         ) ",
      "    )         ) ",
      "    )         ) ",
      "    )         ) ",
      "    ,,,,,,,,, '(",
      "    ,           ",
      "    ,           ",
      "    ,           "
    ],
    [
      "    )         ) ",
      "    )         ) ",
      "    )         ) ",
      "    ))))))))))))",
      "    )         ) ",
      "    )         ) ",
      "    !     +   ) ",
      "    !         ) ",
      "    )         ) ",
      "    )         ) ",
      "    )         ) ",
      "    )         ) ",
      "    ,,,,,,,,,   ",
      "    ,           ",
      "    ,           ",
      "    ,           "
    ]
  ],
  "palette": {
    "palette": [
      {
        "char": "!",
        "block": "create:framed_glass"
      },
      {
        "char": "$",
        "block": "minecraft:blue_concrete"
      },
      {
        "char": "%",
        "block": "minecraft:iron_door[facing=south,half=lower,hinge=left,open=false,powered=false]"
      },
      {
        "char": "&",
        "block": "minecraft:iron_door[facing=south,half=lower,hinge=right,open=false,powered=false]"
      },
      {
        "char": "'",
        "block": "minecraft:iron_door[facing=south,half=upper,hinge=left,open=false,powered=false]"
      },
      {
        "char": "(",
        "block": "minecraft:iron_door[facing=south,half=upper,hinge=right,open=false,powered=false]"
      },
      {
        "char": ")",
        "block": "minecraft:light_gray_concrete"
      },
      {
        "char": "*",
        "block": "minecraft:polished_andesite"
      },
      {
        "char": "+",
        "block": "minecraft:polished_andesite_stairs[facing=south,half=bottom,shape=straight,waterlogged=false]"
      },
      {
        "char": ",",
        "block": "minecraft:polished_deepslate"
      },
      {
        "char": "-",
        "block": "minecraft:smooth_stone"
      },
      {
        "char": ".",
        "block": "minecraft:spruce_door[facing=east,half=lower,hinge=left,open=false,powered=false]"
      },
      {
        "char": "/",
        "block": "minecraft:spruce_door[facing=east,half=upper,hinge=left,open=false,powered=false]"
      },
      {
        "char": "0",
        "block": "minecraft:spruce_door[facing=south,half=lower,hinge=left,open=false,powered=false]"
      },
      {
        "char": "1",
        "block": "minecraft:spruce_door[facing=south,half=upper,hinge=left,open=false,powered=false]"
      },
      {
        "char": "2",
        "block": "minecraft:spruce_slab[type=bottom,waterlogged=false]"
      },
      {
        "char": "3",
        "block": "minecraft:spruce_stairs[facing=north,half=bottom,shape=straight,waterlogged=false]"
      }
    ]
  }
}
