{
  "xsize": 16,
  "zsize": 16,
  "slices": [
    [
      "****************",
      "**************$$",
      "************$$!*",
      "**********$$!***",
      "********$$!*****",
      "******$$!*******",
      "****$$!*********",
      "**$$!***********",
      "$$!*************",
      "!***************",
      "***************$",
      "*************$$!",
      "***********$$!**",
      "*********$$!****",
      "*******$$!******",
      "*****$$!********"
    ],
    [
      "(((       (($$$$",
      "(((       ('$$$$",
      "(((       ('$$$$",
      "(((       ('$$$$",
      "(((       ('$$$$",
      "(((       ('$$$$",
      "(((       ('$$$$",
      "(((       ('$$$$",
      "(((       ('$$$$",
      "(((       ('$$$$",
      "(((       ('$$$$",
      "(((       ('$$$$",
      "(((       ('$$$$",
      "(((       ('$$$$",
      "(((       ('$$$$",
      "(((       ('$$$$"
    ],
    [
      "% )       % $$$$",
      "  )       % $$$$",
      "  )       %&$$$$",
      "  )       % $$$$",
      "  )       % $$$$",
      "  )       % $$$$",
      "  )       %&$$$$",
      "  )       % $$$$",
      "  )       % $$$$",
      "  )       % $$$$",
      "  )       %&$$$$",
      "  )       % $$$$",
      "  )       % $$$$",
      "  )       % $$$$",
      "  )       %&$$$$",
      "  )       % $$$$"
    ],
    [
      "% )       % $$$$",
      "  )       % $$$$",
      "  )       %&$$$$",
      "  )       % $$$$",
      "  )       % $$$$",
      "  )       % $$$$",
      "  )       %&$$$$",
      "  )       % $$$$",
      "  )       % $$$$",
      "  )       % $$$$",
      "  )       %&$$$$",
      "  )       % $$$$",
      "  )       % $$$$",
      "  )       % $$$$",
      "  )       %&$$$$",
      "  )       % $$$$"
    ],
    [
      "% )       % $$$$",
      "  )       % $$$$",
      "  )       %&$$$$",
      "  )       % $$$$",
      "  )       % $$$$",
      "  )       % $$$$",
      "  )       %&$$$$",
      "  )       % $$$$",
      "  )       % $$$$",
      "  )       % $$$$",
      "  )       %&$$$$",
      "  )       % $$$$",
      "  )       % $$$$",
      "  )       % $$$$",
      "  )       %&$$$$",
      "  )       % $$$$"
    ],
    [
      "% )       % $$$$",
      "  )       % $$$$",
      "  )       % $$$$",
      "  )       % $$$$",
      "  )       % $$$$",
      "  )       % $$$$",
      "  )       % $$$$",
      "  )       % $$$$",
      "  )       % $$$$",
      "  )       % $$$$",
      "  )       % $$$$",
      "  )       % $$$$",
      "  )       % $$$$",
      "  )       % $$$$",
      "  )       % $$$$",
      "  )       % $$$$"
    ]
  ],
  "palette": {
    "palette": [
      {
        "char": "!",
        "block": "minecraft:coarse_dirt"
      },
      {
        "char": "$",
        "block": "minecraft:gravel"
      },
      {
        "char": "%",
        "block": "minecraft:mud_bricks"
      },
      {
        "char": "&",
        "block": "minecraft:oak_stairs[facing=east,half=bottom,shape=straight,waterlogged=false]"
      },
      {
        "char": "'",
        "block": "minecraft:orange_terracotta"
      },
      {
        "char": "(",
        "block": "minecraft:smooth_stone"
      },
      {
        "char": ")",
        "block": "minecraft:yellow_terracotta"
      },
      {
        "char": "*",
        "block": "tfmg:asphalt"
      }
    ]
  }
}
