{
  "xsize": 16,
  "zsize": 16,
  "slices": [
    [
      " ///&&%/////////",
      " /&&%///////////",
      " &%/////////////",
      " ///////////////",
      " //////////////&",
      " %///////////&&%",
      " //////////&&%//",
      " ////////&&%////",
      " //////&&%//////",
      " ////&&%////////",
      " //&&%//////////",
      " %&%////////////",
      " %//////////////",
      " ///////////////",
      " /////////////&&",
      " ///////////&&%/"
    ],
    [
      "     11111111111",
      "     11111111111",
      "     11111111111",
      "     11111111111",
      "     11111111111",
      "     11111111111",
      "     11111111111",
      "     11111111111",
      "     11111111111",
      "     11111111111",
      "     11111111111",
      "     11111111111",
      "     11111111111",
      "     11111111111",
      "     (((((((((((",
      "     ((((((((((("
    ],
    [
      "     $          ",
      "     $   ,  ,  ,",
      "     $000+00+00+",
      "     $          ",
      "     $          ",
      "     $          ",
      "     $  -       ",
      "     $          ",
      "     $000000)000",
      "     $          ",
      "     $          ",
      "     $          ",
      "     $          ",
      "     $          ",
      "     '..........",
      "     '          "
    ],
    [
      "     $          ",
      "     $          ",
      "     $000000*000",
      "     $          ",
      "     $          ",
      "     $          ",
      "     $          ",
      "     $  -       ",
      "     $000000*000",
      "     $          ",
      "     $          ",
      "     $          ",
      "     $          ",
      "     $          ",
      "     '..........",
      "     '          "
    ],
    [
      "     $          ",
      "     $          ",
      "     $0000000000",
      "     $          ",
      "     $          ",
      "     $          ",
      "     $          ",
      "     $          ",
      "     $00-0000000",
      "     $          ",
      "     $          ",
      "     $          ",
      "     $          ",
      "     $          ",
      "     '..........",
      "     '          "
    ],
    [
      "     $          ",
      "     $          ",
      "     $0000000000",
      "     $          ",
      "     $          ",
      "     $          ",
      "     $          ",
      "     $          ",
      "     $00 0000000",
      "     $  -       ",
      "     $          ",
      "     $          ",
      "     $          ",
      "     $          ",
      "     '..........",
      "     '     !!   "
    ]
  ],
  "palette": {
    "palette": [
      {
        "char": "!",
        "block": "create:framed_glass"
      },
      {
        "char": "$",
        "block": "minecraft:bricks"
      },
      {
        "char": "%",
        "block": "minecraft:coarse_dirt"
      },
      {
        "char": "&",
        "block": "minecraft:gravel"
      },
      {
        "char": "'",
        "block": "minecraft:mud_bricks"
      },
      {
        "char": "(",
        "block": "minecraft:smooth_stone"
      },
      {
        "char": ")",
        "block": "minecraft:spruce_door[facing=south,half=lower,hinge=left,open=false,powered=false]"
      },
      {
        "char": "*",
        "block": "minecraft:spruce_door[facing=south,half=upper,hinge=left,open=false,powered=false]"
      },
      {
        "char": "+",
        "block": "minecraft:spruce_slab[type=bottom,waterlogged=false]"
      },
      {
        "char": ",",
        "block": "minecraft:spruce_stairs[facing=north,half=bottom,shape=straight,waterlogged=false]"
      },
      {
        "char": "-",
        "block": "minecraft:stone_brick_stairs[facing=south,half=bottom,shape=straight,waterlogged=false]"
      },
      {
        "char": ".",
        "block": "minecraft:yellow_terracotta"
      },
      {
        "char": "/",
        "block": "tfmg:asphalt"
      },
      {
        "char": "0",
        "block": "tfmg:cinder_block"
      },
      {
        "char": "1",
        "block": "tfmg:factory_floor"
      }
    ]
  }
}
