{
  "xsize": 16,
  "zsize": 16,
  "slices": [
    [
      "++++++++++++++++",
      "++++++++++++++++",
      "++++++++++++++++",
      "++++++++++++++++",
      "++++++++++++++++",
      "++++++++++++++++",
      "++++++++++++++++",
      "++++++++++++++++",
      "++++++++++++++++",
      "++++++++++++++++",
      "++++++++++++++++",
      "++++++++++++++++",
      "++++++++++++++++",
      "++++++++++++++++",
      "++++++++++++++++",
      "++++++++++++++++"
    ],
    [
      "00000(((********",
      "00000(((********",
      "00000(((********",
      "00000(((********",
      "00000(((********",
      "00000(((********",
      "00000(((********",
      "((((((((********",
      "((((((((********",
      "((((((((********",
      "((((((((********",
      "((((((((********",
      "666666666*******",
      "666666666*******",
      "666666666*******",
      "666666666*******"
    ],
    [
      "        4  3    ",
      "        4       ",
      "        4       ",
      "        4       ",
      "        4444.444",
      "        4       ",
      "        4       ",
      "        4  2 1  ",
      "        4  3    ",
      "      ) 4       ",
      "        4       ",
      "        4444.444",
      "$%5555555       ",
      " 5      5       ",
      " 5 !!!!    2 1  ",
      " , !!!!    3    "
    ],
    [
      "        4       ",
      "        4       ",
      "        4       ",
      "        4       ",
      "        4444/444",
      "        4       ",
      "        4       ",
      "        4       ",
      "        4       ",
      "        4       ",
      "        4       ",
      "        4444/444",
      "&'5555555       ",
      " 5      5       ",
      " 5 !!!!         ",
      " - !!!!         "
    ],
    [
      "        4       ",
      "        4       ",
      "        4       ",
      "        4       ",
      "        44444444",
      "        4       ",
      "        4       ",
      "        4       ",
      "        4       ",
      "        4       ",
      "        4       ",
      "        44444444",
      "555555555       ",
      " 5      5       ",
      " 5 !!!!         ",
      " 5 !!!!         "
    ],
    [
      "        4       ",
      "        4       ",
      "        4       ",
      "        4       ",
      "        44444444",
      "        4       ",
      "        4       ",
      "        4       ",
      "        4       ",
      "        4       ",
      "        4       ",
      "        44444444",
      "555555555       ",
      " 5      5       ",
      " 5              ",
      " 5              "
    ]
  ],
  "palette": {
    "palette": [
      {
        "char": "!",
        "block": "minecraft:barrel[facing=up,open=false]"
      },
      {
        "char": "$",
        "block": "minecraft:iron_door[facing=south,half=lower,hinge=left,open=false,powered=false]"
      },
      {
        "char": "%",
        "block": "minecraft:iron_door[facing=south,half=lower,hinge=right,open=false,powered=false]"
      },
      {
        "char": "&",
        "block": "minecraft:iron_door[facing=south,half=upper,hinge=left,open=false,powered=false]"
      },
      {
        "char": "'",
        "block": "minecraft:iron_door[facing=south,half=upper,hinge=right,open=false,powered=false]"
      },
      {
        "char": "(",
        "block": "minecraft:moss_block"
      },
      {
        "char": ")",
        "block": "minecraft:oak_slab[type=bottom,waterlogged=false]"
      },
      {
        "char": "*",
        "block": "minecraft:polished_andesite"
      },
      {
        "char": "+",
        "block": "minecraft:smooth_stone"
      },
      {
        "char": ",",
        "block": "minecraft:spruce_door[facing=east,half=lower,hinge=left,open=false,powered=false]"
      },
      {
        "char": "-",
        "block": "minecraft:spruce_door[facing=east,half=upper,hinge=left,open=false,powered=false]"
      },
      {
        "char": ".",
        "block": "minecraft:spruce_door[facing=south,half=lower,hinge=left,open=false,powered=false]"
      },
      {
        "char": "/",
        "block": "minecraft:spruce_door[facing=south,half=upper,hinge=left,open=false,powered=false]"
      },
      {
        "char": "0",
        "block": "minecraft:water"
      },
      {
        "char": "1",
        "block": "kubejs:ruined_cauldron"
      },
      {
        "char": "2",
        "block": "minecraft:white_bed[facing=south,occupied=false,part=foot]"
      },
      {
        "char": "3",
        "block": "minecraft:white_bed[facing=south,occupied=false,part=head]"
      },
      {
        "char": "4",
        "block": "minecraft:white_concrete"
      },
      {
        "char": "5",
        "block": "tfmg:cinder_block"
      },
      {
        "char": "6",
        "block": "tfmg:factory_floor"
      }
    ]
  }
}
