{
  "xsize": 16,
  "zsize": 16,
  "slices": [
    [
      "     $          ",
      "     $          ",
      "     $          ",
      "     $          ",
      "     $          ",
      "     $          ",
      "     $          ",
      "     $          ",
      "     $          ",
      "     $          ",
      "     $          ",
      "     $          ",
      "     $          ",
      "     $          ",
      "     $          ",
      "     $          "
    ],
    [
      "     $          ",
      "     $          ",
      "     $          ",
      "     $          ",
      "     $          ",
      "     $          ",
      "     $          ",
      "     $          ",
      "     $          ",
      "     $          ",
      "     $          ",
      "     $          ",
      "     $          ",
      "     $          ",
      "     $          ",
      "     $          "
    ],
    [
      "     !          ",
      "     !          ",
      "     !          ",
      "     !          ",
      "     !          ",
      "     !          ",
      "     !          ",
      "     !          ",
      "     !          ",
      "     !          ",
      "     !          ",
      "     !          ",
      "     !          ",
      "     !          ",
      "     !          ",
      "     !          "
    ],
    [
      "     !!!!!!!!!!!",
      "     !!!!!!!!!!!",
      "     !!!!!!!!!!!",
      "     !!!!!!!!!!!",
      "     !!!!!!!!!!!",
      "     !!!!!!!!!!!",
      "     !!!!!!!!!!!",
      "     !!!!!!!!!!!",
      "     !!!!!!!!!!!",
      "     !!!!!!!!!!!",
      "     !!!!!!!!!!!",
      "     !!!!!!!!!!!",
      "     !!!!!!!!!!!",
      "     !!!!!!!!!!!",
      "     !!!!!!!!!!!",
      "     !!!!!!!!!!!"
    ],
    [
      "                ",
      "                ",
      "                ",
      "                ",
      "                ",
      "                ",
      "                ",
      "                ",
      "                ",
      "                ",
      "                ",
      "                ",
      "                ",
      "                ",
      "                ",
      "                "
    ],
    [
      "                ",
      "                ",
      "                ",
      "                ",
      "                ",
      "                ",
      "                ",
      "                ",
      "                ",
      "                ",
      "                ",
      "                ",
      "                ",
      "                ",
      "                ",
      "                "
    ]
  ],
  "palette": {
    "palette": [
      {
        "char": "!",
        "block": "minecraft:smooth_stone"
      },
      {
        "char": "$",
        "block": "minecraft:tuff_bricks"
      }
    ]
  }
}
