{
  "xsize": 16,
  "zsize": 16,
  "slices": [
    [
      "                ",
      "                ",
      "                ",
      "                ",
      "                ",
      "                ",
      "                ",
      "                ",
      "!!)%%%)!!))!!)  ",
      "%            %  ",
      "%            %  ",
      "%     $$$$$  %  ",
      "%     $$$$$  !  ",
      "'     $$$$$  !  ",
      "%     $$$$$  %  ",
      "%            %  "
    ],
    [
      "                ",
      "                ",
      "                ",
      "                ",
      "                ",
      "                ",
      "                ",
      "                ",
      "!!)%%%)!!))!!)  ",
      "%            %  ",
      "%            %  ",
      "%     $$$$$  %  ",
      "%     $$$$$  !  ",
      "%     $$$$$  !  ",
      "%     $$$$$  %  ",
      "%            %  "
    ],
    [
      "                ",
      "                ",
      "                ",
      "                ",
      "                ",
      "                ",
      "                ",
      "((     ((  ((   ",
      "%%%%%%%%%%%%%%  ",
      "%            %  ",
      "%            %  ",
      "%            %  ",
      "%            %  ",
      "%            %  ",
      "%            %  ",
      "%            %  "
    ],
    [
      "                ",
      "                ",
      "                ",
      "                ",
      "                ",
      "                ",
      "                ",
      "                ",
      "%%%%%%%%%%%%%%  ",
      "             %  ",
      "             %  ",
      "             %  ",
      "             %  ",
      "             %  ",
      "             %  ",
      "             %  "
    ],
    [
      "                ",
      "                ",
      "                ",
      "                ",
      "                ",
      "                ",
      "                ",
      "                ",
      "%%%%%%%%%%%%%%  ",
      "             %  ",
      "             %  ",
      "             %  ",
      "             %  ",
      "             %  ",
      "             %  ",
      "             %  "
    ],
    [
      "                ",
      "                ",
      "                ",
      "                ",
      "                ",
      "                ",
      "                ",
      "                ",
      "&&&&&&&&&&&&&&  ",
      "&&&&&&&&&&&&&&  ",
      "&&&&&&&&&&&&&&  ",
      "&&&&&&&&&&&&&&  ",
      "&&&&&&&&&&&&&&  ",
      "&&&&&&&&&&&&&&  ",
      "&&&&&&&&&&&&&&  ",
      "&&&&&&&&&&&&&&  "
    ]
  ],
  "palette": {
    "palette": [
      {
        "char": "!",
        "block": "create:framed_glass"
      },
      {
        "char": "$",
        "block": "minecraft:bookshelf"
      },
      {
        "char": "%",
        "block": "minecraft:light_gray_concrete"
      },
      {
        "char": "&",
        "block": "minecraft:smooth_stone"
      },
      {
        "char": "'",
        "block": "minecraft:spruce_door[facing=east,half=upper,hinge=left,open=false,powered=false]"
      },
      {
        "char": "(",
        "block": "minecraft:spruce_slab[type=top,waterlogged=false]"
      },
      {
        "char": ")",
        "block": "minecraft:stripped_spruce_log[axis=y]"
      }
    ]
  }
}
