{
  "xsize": 16,
  "zsize": 16,
  "slices": [
    [
      "                ",
      "                ",
      "                ",
      "                ",
      "                ",
      "                ",
      "                ",
      "                ",
      "                ",
      "                ",
      "                ",
      "                ",
      "                ",
      "                ",
      "                ",
      "                "
    ],
    [
      "3333333333333''&",
      "33333333333''&33",
      "333333333''&3333",
      "3333333''&333333",
      "33333''&33333333",
      "333''&3333333333",
      "3''&333333333333",
      "'&33333333333333",
      "3333333333333333",
      "33333333333333''",
      "333333333333''&3",
      "3333333333''&333",
      "33333333''&33333",
      "                ",
      "                ",
      "                "
    ],
    [
      "555555551   1   ",
      "555555551   1   ",
      "555555551   1   ",
      "555555551   1   ",
      "55'''''''') 1   ",
      "55''''''''' 1   ",
      "55''''''''''1***",
      "55''''''''''1***",
      "55'''''''''' ***",
      "55'''''''''' ***",
      "  '''''''''' ***",
      "  '''''''''' ***",
      "   ''''''' )    ",
      "                ",
      "                ",
      "                "
    ],
    [
      " !    2)        ",
      "4444.44)        ",
      " 4     ))       ",
      " 4 0  +)        ",
      " , ) ''')       ",
      " 4)4'''''')     ",
      " 4)''''''' ' ***",
      " 4''''''''') *  ",
      " 4'''''''''' *  ",
      "4)'''''''''  *  ",
      " ))''''''')  *  ",
      "  ) ''''')   ***",
      "   ')'''')      ",
      "                ",
      "                ",
      "                "
    ],
    [
      "      24        ",
      "4444/444        ",
      " 4     ))       ",
      " 4     4        ",
      " -   )('        ",
      " 444')')        ",
      " 4  )''' )   ***",
      " 4%'''''')   *  ",
      " 4%'''''''') *  ",
      "4)')''''' )  *  ",
      " )  '''' '   *  ",
      "    ) ')     ***",
      "      )         ",
      "                ",
      "                ",
      "                "
    ],
    [
      "       4        ",
      "44444444        ",
      " 4     ))       ",
      " 4     4        ",
      " 4     4        ",
      " 4444444        ",
      " 4    ')        ",
      " 4%%) ')'       ",
      " 4%) ''')       ",
      "4)4$$)'')       ",
      " )   ) )        ",
      "      '         ",
      "                ",
      "                ",
      "                ",
      "                "
    ]
  ],
  "palette": {
    "palette": [
      {
        "char": "!",
        "block": "create:cardboard_block"
      },
      {
        "char": "$",
        "block": "create:framed_glass"
      },
      {
        "char": "%",
        "block": "immersiveengineering:sheetmetal_steel"
      },
      {
        "char": "&",
        "block": "minecraft:coarse_dirt"
      },
      {
        "char": "'",
        "block": "minecraft:gravel"
      },
      {
        "char": "(",
        "block": "minecraft:lever[face=wall,facing=west,powered=false]"
      },
      {
        "char": ")",
        "block": "minecraft:mud_bricks"
      },
      {
        "char": "*",
        "block": "minecraft:oxidized_copper_grate"
      },
      {
        "char": "+",
        "block": "minecraft:quartz_stairs[facing=west,half=bottom,shape=straight,waterlogged=false]"
      },
      {
        "char": ",",
        "block": "minecraft:spruce_door[facing=east,half=lower,hinge=left,open=false,powered=false]"
      },
      {
        "char": "-",
        "block": "minecraft:spruce_door[facing=east,half=upper,hinge=left,open=false,powered=false]"
      },
      {
        "char": ".",
        "block": "minecraft:spruce_door[facing=south,half=lower,hinge=left,open=false,powered=false]"
      },
      {
        "char": "/",
        "block": "minecraft:spruce_door[facing=south,half=upper,hinge=left,open=false,powered=false]"
      },
      {
        "char": "0",
        "block": "minecraft:water_cauldron[level=1]"
      },
      {
        "char": "1",
        "block": "minecraft:white_concrete"
      },
      {
        "char": "2",
        "block": "oritech:cooler_block"
      },
      {
        "char": "3",
        "block": "tfmg:asphalt"
      },
      {
        "char": "4",
        "block": "tfmg:cinder_block"
      },
      {
        "char": "5",
        "block": "tfmg:factory_floor"
      }
    ]
  }
}
