{
  "xsize": 16,
  "zsize": 16,
  "slices": [
    [
      "2222222222222222",
      "2222222222222222",
      "2222222222222222",
      "2222222222222222",
      "2222222222222222",
      "2222222222++&222",
      "22222222++&22222",
      "222222++&2222222",
      "2222++&222222222",
      "22++&22222222222",
      "++&2222222222222",
      "&222222222222222",
      "222222222222222+",
      "2222222222222++&",
      "22222222222++&22",
      "222222222++&2222"
    ],
    [
      "                ",
      "                ",
      "                ",
      "                ",
      "                ",
      "----------------",
      "----------------",
      "----------------",
      "----------------",
      "----------------",
      "----------------",
      "----------------",
      "----------------",
      "----------------",
      "----------------",
      "----------------"
    ],
    [
      "                ",
      "                ",
      "                ",
      "                ",
      "                ",
      "!!!,!!!'!!!,'(,,",
      "   %       %   %",
      "   %       % / %",
      "   %       %   %",
      "/. %       %00 %",
      "   %       %1  %",
      "   %       %   %",
      "   % 33333 %   %",
      "   % 33333 %   %",
      "   %       %   %",
      "/. %       %$ $%"
    ],
    [
      "                ",
      "                ",
      "                ",
      "                ",
      "                ",
      "!!!,!!!)!!!,)*,,",
      "   %       %   %",
      "   %       %   %",
      "   %       % / %",
      "   %       %   %",
      "   %       %   %",
      "   %       %   %",
      "   % 33333 %   %",
      "   % 33333 %   %",
      "   %       %   %",
      "   %       %$ $%"
    ],
    [
      "                ",
      "                ",
      "                ",
      "                ",
      "                ",
      "!!!,!!! !!!,,,,,",
      "   %       %   %",
      "   %       %   %",
      "   %       %   %",
      "   %       % / %",
      "   %       %   %",
      "   %       %   %",
      "   %       %   %",
      "   %       %   %",
      "   %       %   %",
      "   %       %$ $%"
    ],
    [
      "                ",
      "                ",
      "                ",
      "                ",
      "                ",
      "!!!,!!!!!!!,,,,,",
      "   %       %   %",
      "   %       %   %",
      "   %       %   %",
      "   %       %   %",
      "   %       % / %",
      "   %       %   %",
      "   %       %   %",
      "   %       %   %",
      "   %       %   %",
      "   %       %   %"
    ]
  ],
  "palette": {
    "palette": [
      {
        "char": "!",
        "block": "create:framed_glass"
      },
      {
        "char": "$",
        "block": "minecraft:bookshelf"
      },
      {
        "char": "%",
        "block": "minecraft:bricks"
      },
      {
        "char": "&",
        "block": "minecraft:coarse_dirt"
      },
      {
        "char": "'",
        "block": "minecraft:dark_oak_door[facing=north,half=lower,hinge=left,open=false,powered=false]"
      },
      {
        "char": "(",
        "block": "minecraft:dark_oak_door[facing=north,half=lower,hinge=right,open=false,powered=false]"
      },
      {
        "char": ")",
        "block": "minecraft:dark_oak_door[facing=north,half=upper,hinge=left,open=false,powered=false]"
      },
      {
        "char": "*",
        "block": "minecraft:dark_oak_door[facing=north,half=upper,hinge=right,open=false,powered=false]"
      },
      {
        "char": "+",
        "block": "minecraft:gravel"
      },
      {
        "char": ",",
        "block": "minecraft:mud_bricks"
      },
      {
        "char": "-",
        "block": "minecraft:oak_planks"
      },
      {
        "char": ".",
        "block": "minecraft:oak_slab[type=bottom,waterlogged=false]"
      },
      {
        "char": "/",
        "block": "minecraft:oak_stairs[facing=south,half=bottom,shape=straight,waterlogged=false]"
      },
      {
        "char": "0",
        "block": "minecraft:spruce_slab[type=bottom,waterlogged=false]"
      },
      {
        "char": "1",
        "block": "minecraft:spruce_stairs[facing=north,half=bottom,shape=straight,waterlogged=false]"
      },
      {
        "char": "2",
        "block": "tfmg:asphalt"
      },
      {
        "char": "3",
        "block": "zvhouses:stone_brick_countertop"
      }
    ]
  }
}
