{
  "xsize": 16,
  "zsize": 16,
  "slices": [
    [
      "                ",
      "                ",
      "                ",
      "                ",
      "                ",
      "                ",
      "                ",
      "%%%%%%%%%%%%%%% ",
      "              % ",
      "              % ",
      "              % ",
      "              % ",
      "              % ",
      "              % ",
      "              % ",
      "              % "
    ],
    [
      "                ",
      "                ",
      "                ",
      "                ",
      "                ",
      "                ",
      "                ",
      "%%%%%%%%%%%%%%% ",
      "              % ",
      "              % ",
      "              % ",
      ")))))))))     % ",
      ")))))))))     % ",
      ")))))))))     % ",
      ")))))))))     % ",
      ")))))))))     % "
    ],
    [
      "                ",
      "                ",
      "                ",
      "                ",
      "                ",
      "                ",
      "                ",
      "&&&&&&&&&&&&&&& ",
      "&&&&&&&&&&&&&&& ",
      "&&&&&&&&&&&&&&& ",
      "&&&&&&&&&&&&&&& ",
      "$$$$$$$$$&&&&&& ",
      "        $&&&&&& ",
      "        $&&&&&& ",
      " ''  '* $&&&&&& ",
      " (   (  $&&&&&& "
    ],
    [
      "                ",
      "                ",
      "                ",
      "                ",
      "                ",
      "                ",
      "                ",
      "                ",
      "                ",
      "                ",
      "                ",
      "$$$$$$$$$       ",
      "        $       ",
      "        $       ",
      "        $       ",
      "        $       "
    ],
    [
      "                ",
      "                ",
      "                ",
      "                ",
      "                ",
      "                ",
      "                ",
      "                ",
      "                ",
      "                ",
      "                ",
      "!$$$$!!$$       ",
      "        $       ",
      "        $       ",
      "        $       ",
      "        $       "
    ],
    [
      "                ",
      "                ",
      "                ",
      "                ",
      "                ",
      "                ",
      "                ",
      "                ",
      "                ",
      "                ",
      "                ",
      "!$$$$!!$$       ",
      "        $       ",
      "        $       ",
      "        $       ",
      "        $       "
    ]
  ],
  "palette": {
    "palette": [
      {
        "char": "!",
        "block": "create:framed_glass"
      },
      {
        "char": "$",
        "block": "minecraft:light_gray_concrete"
      },
      {
        "char": "%",
        "block": "minecraft:polished_blackstone_bricks"
      },
      {
        "char": "&",
        "block": "minecraft:smooth_stone"
      },
      {
        "char": "'",
        "block": "minecraft:spruce_slab[type=bottom,waterlogged=false]"
      },
      {
        "char": "(",
        "block": "minecraft:spruce_stairs[facing=north,half=bottom,shape=straight,waterlogged=false]"
      },
      {
        "char": ")",
        "block": "tfmg:factory_floor"
      },
      {
        "char": "*",
        "block": "the_wasteland_reworked:radio"
      }
    ]
  }
}
