{
  "xsize": 16,
  "zsize": 16,
  "slices": [
    [
      "                ",
      "                ",
      "                ",
      "                ",
      "                ",
      "             !!!",
      "                ",
      "%               ",
      "                ",
      "$      &&&&&    ",
      "       &&&&&    ",
      "       &&&&&    ",
      "       &&&&&    ",
      "       &&&&&    ",
      "       &&&&&    ",
      "       &&&&&    "
    ],
    [
      "                ",
      "                ",
      "                ",
      "                ",
      "                ",
      "             !!!",
      "                ",
      "                ",
      "                ",
      "       &&&&&    ",
      "       &&&&&    ",
      "       &&&&&    ",
      "       &&&&&    ",
      "       &&&&&    ",
      "       &&&&&    ",
      "       &&&&&    "
    ],
    [
      "                ",
      "                ",
      "                ",
      "                ",
      "                ",
      "                ",
      "                ",
      "                ",
      "                ",
      "       &&&&&    ",
      "       &&&&&    ",
      "       &&&&&    ",
      "       &&&&&    ",
      "       &&&&&    ",
      "       &&&&&    ",
      "       &&&&&    "
    ],
    [
      "                ",
      "                ",
      "                ",
      "                ",
      "                ",
      "                ",
      "                ",
      "                ",
      "                ",
      "       &&&&&    ",
      "       &&&&&    ",
      "       &&&&&    ",
      "       &&&&&    ",
      "       &&&&&    ",
      "       &&&&&    ",
      "       &&&&&    "
    ],
    [
      "                ",
      "                ",
      "                ",
      "                ",
      "                ",
      "                ",
      "                ",
      "                ",
      "                ",
      "       &&&&&    ",
      "       &&&&&    ",
      "       &&&&&    ",
      "       &&&&&    ",
      "       &&&&&    ",
      "       &&&&&    ",
      "       &&&&&    "
    ],
    [
      "                ",
      "                ",
      "                ",
      "                ",
      "                ",
      "                ",
      "                ",
      "                ",
      "                ",
      "       &&&&&    ",
      "       &&&&&    ",
      "       &&&&&    ",
      "       &&&&&    ",
      "       &&&&&    ",
      "       &&&&&    ",
      "       &&&&&    "
    ]
  ],
  "palette": {
    "palette": [
      {
        "char": "!",
        "block": "minecraft:bookshelf"
      },
      {
        "char": "$",
        "block": "minecraft:dark_oak_door[facing=north,half=upper,hinge=left,open=false,powered=false]"
      },
      {
        "char": "%",
        "block": "minecraft:dark_oak_door[facing=south,half=upper,hinge=left,open=false,powered=false]"
      },
      {
        "char": "&",
        "block": "minecraft:polished_blackstone_bricks"
      }
    ]
  }
}
