{
  "xsize": 16,
  "zsize": 16,
  "slices": [
    [
      "((%/////////////",
      "%///////////////",
      "///////////////(",
      "/////////////((%",
      "///////////((%//",
      "/////////((%////",
      "///////((%//////",
      "/////((%////////",
      "///((%//////////",
      "/((%////////////",
      "(%//////////////",
      "////////////////",
      "//////////////((",
      "/%////%////%((%/",
      "                ",
      "                "
    ],
    [
      "11111)))))))))))",
      "11111)))))))))))",
      "11111)))))))))))",
      "11111)))))))))))",
      "11111)))))))))))",
      "1111111         ",
      "1111111         ",
      "1111111         ",
      "1111111         ",
      "                ",
      "                ",
      "                ",
      "                ",
      "                ",
      "                ",
      "                "
    ],
    [
      "     +   *  *   ",
      "     +  ....* ..",
      "0000,00000000000",
      "     + !!!!&!!!!",
      "     +++++++++++",
      "      $         ",
      "      $         ",
      "      $         ",
      "$$$$$$$         ",
      "                ",
      "                ",
      "                ",
      "                ",
      "                ",
      "                ",
      "                "
    ],
    [
      "     +   *  *   ",
      "     +   *  *   ",
      "0000-00000000000",
      "     + !!!!'!!!!",
      "     +++++++++++",
      "      $         ",
      "      $         ",
      "      $         ",
      "$$$$$$$         ",
      "                ",
      "                ",
      "                ",
      "                ",
      "                ",
      "                ",
      "                "
    ],
    [
      "     +   *  *   ",
      "     +   *  *   ",
      "0000000000000000",
      "     + !!!!!!!!!",
      "     +++++++++++",
      "      $         ",
      "      $         ",
      "      $         ",
      "$$$$$$$         ",
      "                ",
      "                ",
      "                ",
      "                ",
      "                ",
      "                ",
      "                "
    ],
    [
      "     +          ",
      "     +          ",
      "0000000000000000",
      "     + !!!!!!!!!",
      "     +++++++++++",
      "      $         ",
      "      $         ",
      "      $         ",
      "$$$$$$$         ",
      "                ",
      "                ",
      "                ",
      "                ",
      "                ",
      "                ",
      "                "
    ]
  ],
  "palette": {
    "palette": [
      {
        "char": "!",
        "block": "create:framed_glass"
      },
      {
        "char": "$",
        "block": "minecraft:bricks"
      },
      {
        "char": "%",
        "block": "minecraft:coarse_dirt"
      },
      {
        "char": "&",
        "block": "minecraft:dark_oak_door[facing=south,half=lower,hinge=left,open=false,powered=false]"
      },
      {
        "char": "'",
        "block": "minecraft:dark_oak_door[facing=south,half=upper,hinge=left,open=false,powered=false]"
      },
      {
        "char": "(",
        "block": "minecraft:gravel"
      },
      {
        "char": ")",
        "block": "minecraft:polished_andesite"
      },
      {
        "char": "*",
        "block": "minecraft:scaffolding"
      },
      {
        "char": "+",
        "block": "minecraft:smooth_stone"
      },
      {
        "char": ",",
        "block": "minecraft:spruce_door[facing=south,half=lower,hinge=left,open=false,powered=false]"
      },
      {
        "char": "-",
        "block": "minecraft:spruce_door[facing=south,half=upper,hinge=left,open=false,powered=false]"
      },
      {
        "char": ".",
        "block": "minecraft:spruce_slab[type=bottom,waterlogged=false]"
      },
      {
        "char": "/",
        "block": "tfmg:asphalt"
      },
      {
        "char": "0",
        "block": "tfmg:cinder_block"
      },
      {
        "char": "1",
        "block": "tfmg:factory_floor"
      }
    ]
  }
}
