{
  "xsize": 16,
  "zsize": 16,
  "slices": [
    [
      "5555555555555&&$",
      "55555555555&&$55",
      "555555555&&$5555",
      "5555555&&$555555",
      "55555&&$55555555",
      "555&&$5555555555",
      "5&&$555555555555",
      "&$55555555555555",
      "5555555555555555",
      "55555555555555&&",
      "555555555555&&$5",
      "5555555555&&$555",
      "55555555&&$55555",
      "555555&&$5555555",
      "5555&&$555555555",
      "55&&$55555555555"
    ],
    [
      "++++++++++++++++",
      "++++++++++++++++",
      "++++++++++++++++",
      "++++++++++++++++",
      "++++++++++++++++",
      "++++++++++++++++",
      "++++++++++++++++",
      "++++++++++++++++",
      "++++++++++++++++",
      "++++++++++++++++",
      "++++++++++++++++",
      "++++++++++++++++",
      "++++++++++++++++",
      "++++++++++++++++",
      "                ",
      "                "
    ],
    [
      "       -   ,    ",
      "       -        ",
      "       -        ",
      "       -        ",
      "------------00--",
      "                ",
      "                ",
      "--------0-------",
      "             -  ",
      "   22        - 2",
      "   3         . 3",
      "             -  ",
      "             -  ",
      "444444444444'(44",
      "                ",
      "                "
    ],
    [
      "       -        ",
      "%%%%   -        ",
      "%%%%   -        ",
      "       -        ",
      "------------11--",
      "                ",
      "                ",
      "--------1-------",
      "             -  ",
      "             -  ",
      "             /  ",
      "             -  ",
      "             -  ",
      "4444!!444444)*44",
      "                ",
      "                "
    ],
    [
      "       -        ",
      "%%%%   -        ",
      "%%%%   -        ",
      "       -        ",
      "----------------",
      "                ",
      "                ",
      "----------------",
      "             -  ",
      "             -  ",
      "             -  ",
      "             -  ",
      "             -  ",
      "4444!!4444444444",
      "                ",
      "                "
    ],
    [
      "       -        ",
      "       -        ",
      "       -        ",
      "       -        ",
      "----------------",
      "                ",
      "                ",
      "----------------",
      "             -  ",
      "             -  ",
      "             -  ",
      "             -  ",
      "             -  ",
      "4444444444444444",
      "                ",
      "                "
    ]
  ],
  "palette": {
    "palette": [
      {
        "char": "!",
        "block": "create:framed_glass"
      },
      {
        "char": "$",
        "block": "minecraft:coarse_dirt"
      },
      {
        "char": "%",
        "block": "minecraft:dark_oak_planks"
      },
      {
        "char": "&",
        "block": "minecraft:gravel"
      },
      {
        "char": "'",
        "block": "minecraft:iron_door[facing=south,half=lower,hinge=left,open=false,powered=false]"
      },
      {
        "char": "(",
        "block": "minecraft:iron_door[facing=south,half=lower,hinge=right,open=false,powered=false]"
      },
      {
        "char": ")",
        "block": "minecraft:iron_door[facing=south,half=upper,hinge=left,open=false,powered=false]"
      },
      {
        "char": "*",
        "block": "minecraft:iron_door[facing=south,half=upper,hinge=right,open=false,powered=false]"
      },
      {
        "char": "+",
        "block": "minecraft:polished_andesite"
      },
      {
        "char": ",",
        "block": "minecraft:polished_andesite_stairs[facing=north,half=bottom,shape=straight,waterlogged=false]"
      },
      {
        "char": "-",
        "block": "minecraft:polished_tuff"
      },
      {
        "char": ".",
        "block": "minecraft:spruce_door[facing=east,half=lower,hinge=left,open=false,powered=false]"
      },
      {
        "char": "/",
        "block": "minecraft:spruce_door[facing=east,half=upper,hinge=left,open=false,powered=false]"
      },
      {
        "char": "0",
        "block": "minecraft:spruce_door[facing=south,half=lower,hinge=left,open=false,powered=false]"
      },
      {
        "char": "1",
        "block": "minecraft:spruce_door[facing=south,half=upper,hinge=left,open=false,powered=false]"
      },
      {
        "char": "2",
        "block": "minecraft:spruce_slab[type=bottom,waterlogged=false]"
      },
      {
        "char": "3",
        "block": "minecraft:spruce_stairs[facing=north,half=bottom,shape=straight,waterlogged=false]"
      },
      {
        "char": "4",
        "block": "minecraft:tuff_bricks"
      },
      {
        "char": "5",
        "block": "tfmg:asphalt"
      }
    ]
  }
}
