{
  "xsize": 16,
  "zsize": 16,
  "slices": [
    [
      "5555555%%$555555",
      "55555%%$55555555",
      "555%%$5555555555",
      "5%%$555555555555",
      "%$55555555555555",
      "5555555555555555",
      "55555555555555%%",
      "555555555555%%$5",
      "5555555555%%$555",
      "55555555%%$55555",
      "555555%%$5555555",
      "5555%%$555555555",
      "55%%$55555555555",
      "%%$5555555555555",
      "$555555555555555",
      "555555555555555%"
    ],
    [
      "/////////////   ",
      "///////////*****",
      "///////////*****",
      "///////////*****",
      "///////////*****",
      "///////////*****",
      "///////////*****",
      "///////////*****",
      "///////////*****",
      "///////////*****",
      "///////////*****",
      "///////////*****",
      "///////////*****",
      "///////////*****",
      "///////////*****",
      "///////////*****"
    ],
    [
      "1111-11111116   ",
      " 1         00000",
      " 1         0    ",
      " 1         0 (((",
      " 1!!!!!!   0 (((",
      " +) 2      0 (((",
      " 1         0 (((",
      " 1         0 (((",
      " 1         0    ",
      " 1         0    ",
      " 1         0    ",
      " 1         0    ",
      " 1 3 '     0    ",
      " 1         0    ",
      " 1         0    ",
      "666666666660    "
    ],
    [
      "1111.11111116   ",
      " 1         00000",
      " 1         0    ",
      " 1         0 (((",
      " 1     4   0 (((",
      " ,         0 (((",
      " 1         0 (((",
      " 1         0 (((",
      " 1         0    ",
      " 1         0    ",
      " 1         0    ",
      " 1         0    ",
      " 1         0    ",
      " 1   &     0    ",
      " 1         0    ",
      "666666666660    "
    ],
    [
      "1111111111116   ",
      " 1         00000",
      " 1         0    ",
      " 1         0 (((",
      " 1         0 (((",
      " 1         0 (((",
      " 1         0 (((",
      " 1         0 (((",
      " 1         0    ",
      " 1         0    ",
      " 1         0    ",
      " 1         0    ",
      " 1         0    ",
      " 1         0    ",
      " 1         0    ",
      "666666666660    "
    ],
    [
      "1111111111116   ",
      " 1         00000",
      " 1         0    ",
      " 1         0 (((",
      " 1         0 (((",
      " 1         0 (((",
      " 1         0 (((",
      " 1         0 (((",
      " 1         0    ",
      " 1         0    ",
      " 1         0    ",
      " 1         0    ",
      " 1         0    ",
      " 1         0    ",
      " 1         0    ",
      "666666666660    "
    ]
  ],
  "palette": {
    "palette": [
      {
        "char": "!",
        "block": "minecraft:barrel[facing=up,open=false]"
      },
      {
        "char": "$",
        "block": "minecraft:coarse_dirt"
      },
      {
        "char": "%",
        "block": "minecraft:gravel"
      },
      {
        "char": "&",
        "block": "minecraft:lever[face=wall,facing=south,powered=false]"
      },
      {
        "char": "'",
        "block": "minecraft:quartz_stairs[facing=north,half=bottom,shape=straight,waterlogged=false]"
      },
      {
        "char": "(",
        "block": "minecraft:scaffolding"
      },
      {
        "char": ")",
        "block": "kubejs:ruined_smoker[facing=north]"
      },
      {
        "char": "*",
        "block": "minecraft:smooth_stone"
      },
      {
        "char": "+",
        "block": "minecraft:spruce_door[facing=east,half=lower,hinge=left,open=false,powered=false]"
      },
      {
        "char": ",",
        "block": "minecraft:spruce_door[facing=east,half=upper,hinge=left,open=false,powered=false]"
      },
      {
        "char": "-",
        "block": "minecraft:spruce_door[facing=south,half=lower,hinge=left,open=false,powered=false]"
      },
      {
        "char": ".",
        "block": "minecraft:spruce_door[facing=south,half=upper,hinge=left,open=false,powered=false]"
      },
      {
        "char": "/",
        "block": "minecraft:spruce_planks"
      },
      {
        "char": "0",
        "block": "minecraft:stripped_spruce_log"
      },
      {
        "char": "1",
        "block": "minecraft:stripped_spruce_wood"
      },
      {
        "char": "2",
        "block": "kubejs:ruined_cauldron"
      },
      {
        "char": "3",
        "block": "kubejs:ruined_cauldron"
      },
      {
        "char": "4",
        "block": "supplementaries:item_shelf"
      },
      {
        "char": "5",
        "block": "tfmg:asphalt"
      },
      {
        "char": "6",
        "block": "the_wasteland_reworked:decayed_planks"
      }
    ]
  }
}
