{
  "xsize": 16,
  "zsize": 16,
  "slices": [
    [
      "                ",
      "'''%''''        ",
      "''''''%%        ",
      "''''%%$%        ",
      "''%%$'''        ",
      "%%$'''''        ",
      "$'''''''        ",
      "''''''''        ",
      "''''''''        ",
      "'''''''%        ",
      "''''''''        ",
      "'''''''%        ",
      "'''''%%$        ",
      "'''%%$''        ",
      "'%%$''''        ",
      "%$'''''%        "
    ],
    [
      "                ",
      "                ",
      "                ",
      "                ",
      "                ",
      "                ",
      "                ",
      "((((((          ",
      "((((((          ",
      "((((((          ",
      "((((((          ",
      "((((((          ",
      "((((((          ",
      "((((((          ",
      "((((((          ",
      "((((((          "
    ],
    [
      "                ",
      "                ",
      "                ",
      "                ",
      "                ",
      "                ",
      "                ",
      "&&&&&&          ",
      "     &          ",
      "     &          ",
      "     &          ",
      "     &          ",
      "     &          ",
      "     &          ",
      "     &          ",
      "     &          "
    ],
    [
      "                ",
      "                ",
      "                ",
      "                ",
      "                ",
      "                ",
      "                ",
      "&&&&&&          ",
      "     &          ",
      "     &          ",
      "     &          ",
      "     &          ",
      "     &          ",
      "     &          ",
      "     &          ",
      "     &          "
    ],
    [
      "                ",
      "                ",
      "                ",
      "                ",
      "                ",
      "                ",
      "                ",
      "&&&!!&          ",
      "     &          ",
      "     &          ",
      "     &          ",
      "     &          ",
      "     &          ",
      "     &          ",
      "     &          ",
      "     &          "
    ],
    [
      "                ",
      "                ",
      "                ",
      "                ",
      "                ",
      "                ",
      "                ",
      "&&&!!&          ",
      "     &          ",
      "     &          ",
      "     &          ",
      "     &          ",
      "     &          ",
      "     &          ",
      "     &          ",
      "     &          "
    ]
  ],
  "palette": {
    "palette": [
      {
        "char": "!",
        "block": "create:framed_glass"
      },
      {
        "char": "$",
        "block": "minecraft:coarse_dirt"
      },
      {
        "char": "%",
        "block": "minecraft:gravel"
      },
      {
        "char": "&",
        "block": "minecraft:mud_bricks"
      },
      {
        "char": "'",
        "block": "tfmg:asphalt"
      },
      {
        "char": "(",
        "block": "tfmg:factory_floor"
      }
    ]
  }
}
