{
  "xsize": 16,
  "zsize": 16,
  "slices": [
    [
      "..........((%...",
      "........((%.....",
      "......((%.......",
      "....((%.........",
      "..((%...........",
      "((%.............",
      "%...............",
      "...............(",
      "................",
      "................",
      "................",
      "................",
      "................",
      "................",
      "................",
      "                "
    ],
    [
      "   *************",
      "   *************",
      "   *************",
      "   *************",
      "   *************",
      "   *************",
      "   *************",
      "   *************",
      "                ",
      "                ",
      "        -   -   ",
      "                ",
      "                ",
      "                ",
      "                ",
      "                "
    ],
    [
      "   )$$$$$$+$$$$$",
      "   )            ",
      "   ) !!!!!!!!   ",
      "   ) !!!!!!!!   ",
      "   ) !!!!!!!!   ",
      "   )            ",
      "   )            ",
      "   )))))))&)))))",
      "                ",
      "                ",
      "        -   -   ",
      "                ",
      "                ",
      "                ",
      "                ",
      "                "
    ],
    [
      "   )$$$$$$,$$$$$",
      "   )            ",
      "   ) !!!!!!!!   ",
      "   ) !!!!!!!!   ",
      "   ) !!!!!!!!   ",
      "   )            ",
      "   )            ",
      "   )))))))')))))",
      "                ",
      "                ",
      "        -   -   ",
      "                ",
      "                ",
      "                ",
      "                ",
      "                "
    ],
    [
      "   )$$$$$$$$$$$$",
      "   )            ",
      "   ) !!!!!!!!   ",
      "   ) !!!!!!!!   ",
      "   ) !!!!!!!!   ",
      "   )            ",
      "   )            ",
      "   )))))))))))))",
      "                ",
      "                ",
      "        -   -   ",
      "                ",
      "                ",
      "                ",
      "                ",
      "                "
    ],
    [
      "   )$$$$$$$$$$$$",
      "   )            ",
      "   )            ",
      "   )            ",
      "   )            ",
      "   )            ",
      "   )            ",
      "   )))))))))))))",
      "                ",
      "                ",
      "        -   -   ",
      "                ",
      "                ",
      "                ",
      "                ",
      "                "
    ]
  ],
  "palette": {
    "palette": [
      {
        "char": "!",
        "block": "immersiveengineering:crate"
      },
      {
        "char": "$",
        "block": "minecraft:bricks"
      },
      {
        "char": "%",
        "block": "minecraft:coarse_dirt"
      },
      {
        "char": "&",
        "block": "minecraft:dark_oak_door[facing=south,half=lower,hinge=left,open=false,powered=false]"
      },
      {
        "char": "'",
        "block": "minecraft:dark_oak_door[facing=south,half=upper,hinge=left,open=false,powered=false]"
      },
      {
        "char": "(",
        "block": "minecraft:gravel"
      },
      {
        "char": ")",
        "block": "minecraft:mud_bricks"
      },
      {
        "char": "*",
        "block": "minecraft:oak_planks"
      },
      {
        "char": "+",
        "block": "minecraft:spruce_door[facing=south,half=lower,hinge=left,open=false,powered=false]"
      },
      {
        "char": ",",
        "block": "minecraft:spruce_door[facing=south,half=upper,hinge=left,open=false,powered=false]"
      },
      {
        "char": "-",
        "block": "minecraft:stripped_dark_oak_log[axis=y]"
      },
      {
        "char": ".",
        "block": "tfmg:asphalt"
      }
    ]
  }
}
