{
  "xsize": 16,
  "zsize": 16,
  "slices": [
    [
      "..........&&%...",
      "........&&%.....",
      "......&&%.......",
      "....&&%.........",
      "..&&%...........",
      "&&%.............",
      "%...............",
      "...............&",
      ".............&&%",
      "...........&&%..",
      ".........&&%....",
      ".......&&%......",
      ".....&&%........",
      "...&&%..........",
      ".&&%............",
      "&%.............."
    ],
    [
      "((((((((((((((((",
      "((((((((((((((((",
      "((((((((((((((((",
      "((((((((((((((((",
      "((((((((((((((((",
      "((((((((((((((((",
      "((((((((((((((((",
      "((((((((((((((((",
      "((((((((((((((((",
      "((((((((((((((((",
      "((((((((((((((((",
      "((((((((((((((((",
      "((((((((((((((((",
      "((((((((((((((((",
      "((((((((((((((((",
      "(((((((((((((((("
    ],
    [
      " ))))))) !      ",
      "         ! $+  $",
      "         !      ",
      "         !      ",
      "         !      ",
      " ))))))) !      ",
      "         ! /////",
      "         !      ",
      "!!!!,!!!!!!!!!!,",
      "         !      ",
      "         !      ",
      " *  '    !      ",
      "         !      ",
      "         !      ",
      "         !      ",
      "         !      "
    ],
    [
      " ))))))) !      ",
      "         !      ",
      "         !      ",
      "         !      ",
      "         !      ",
      " ))))))) !      ",
      "         !      ",
      "         !      ",
      "!!!!-!!!!!!!!!!-",
      "         !      ",
      "         !      ",
      "         !      ",
      "         !      ",
      "         !      ",
      "         !      ",
      "         !      "
    ],
    [
      "         !      ",
      "         !      ",
      "         !      ",
      "         !      ",
      "         !      ",
      "         !      ",
      "         !      ",
      "         !      ",
      "!!!!!!!!!!!!!!!!",
      "         !      ",
      "         !      ",
      "         !      ",
      "         !      ",
      "         !      ",
      "         !      ",
      "         !      "
    ],
    [
      "         !      ",
      "         !      ",
      "         !      ",
      "         !      ",
      "         !      ",
      "         !      ",
      "         !      ",
      "         !      ",
      "!!!!!!!!!!!!!!!!",
      "         !      ",
      "         !      ",
      "         !      ",
      "         !      ",
      "         !      ",
      "         !      ",
      "         !      "
    ]
  ],
  "palette": {
    "palette": [
      {
        "char": "!",
        "block": "minecraft:bricks"
      },
      {
        "char": "$",
        "block": "kubejs:ruined_cauldron"
      },
      {
        "char": "%",
        "block": "minecraft:coarse_dirt"
      },
      {
        "char": "&",
        "block": "minecraft:gravel"
      },
      {
        "char": "'",
        "block": "kubejs:ruined_grindstone[face=floor,facing=south]"
      },
      {
        "char": "(",
        "block": "minecraft:oak_planks"
      },
      {
        "char": ")",
        "block": "minecraft:scaffolding"
      },
      {
        "char": "*",
        "block": "kubejs:ruined_smithing_table"
      },
      {
        "char": "+",
        "block": "kubejs:ruined_smoker[facing=south]"
      },
      {
        "char": ",",
        "block": "minecraft:spruce_door[facing=south,half=lower,hinge=left,open=false,powered=false]"
      },
      {
        "char": "-",
        "block": "minecraft:spruce_door[facing=south,half=upper,hinge=left,open=false,powered=false]"
      },
      {
        "char": ".",
        "block": "tfmg:asphalt"
      },
      {
        "char": "/",
        "block": "zvhouses:spruce_countertop"
      }
    ]
  }
}
