{
  "xsize": 16,
  "zsize": 16,
  "slices": [
    [
      "       !        ",
      "       $        ",
      "       $        ",
      "       $        ",
      "*******$        ",
      "       $        ",
      "       $        ",
      "       $        ",
      "*******$        ",
      "       $        ",
      "       $        ",
      "       $        ",
      "       $$       ",
      "       !        ",
      "+++++++!        ",
      "       $        "
    ],
    [
      "       $'       ",
      "       $'       ",
      "       $        ",
      "       $        ",
      "*******$        ",
      "       $        ",
      "       $        ",
      "       $        ",
      "*******$        ",
      "       $        ",
      "       $        ",
      "       $        ",
      "       $'       ",
      "       $'       ",
      "+++++++$'       ",
      "       $'       "
    ],
    [
      "       $        ",
      "       $        ",
      "       $        ",
      "       $        ",
      "*******$        ",
      "       $        ",
      "       $        ",
      "       $        ",
      "*******$        ",
      "       $        ",
      "       $        ",
      "       $        ",
      "       $        ",
      "       $        ",
      "       $        ",
      "       $        "
    ],
    [
      "       $        ",
      "       $        ",
      "       $        ",
      "       $        ",
      "       $        ",
      "       $        ",
      "       $        ",
      "       $        ",
      "       $        ",
      "       $        ",
      "       $        ",
      "       $        ",
      "       $        ",
      "       $        ",
      "       &&&      ",
      "       &&&      "
    ],
    [
      "%%%%%%%$        ",
      "%%%%%%%$        ",
      "%%%%%%%$        ",
      "%%%%%%%$        ",
      "%%%%%%%$        ",
      "%%%%%%%$        ",
      "%%%%%%%$        ",
      "%%%%%%%$        ",
      "%%%%%%%$        ",
      "%%%%%%%$        ",
      "%%%%%%%$        ",
      "%%%%%%%$        ",
      "%%%%%%%$        ",
      "%%%%%%%$        ",
      "%%%%%%%$ )      ",
      "%%%%%%%$        "
    ],
    [
      "       $        ",
      "       $        ",
      "       $        ",
      "       $        ",
      "*******$        ",
      "       $        ",
      "       $        ",
      "       $        ",
      "*******$        ",
      "       $        ",
      "       $        ",
      "       $        ",
      "       $$       ",
      "       $        ",
      "(++++++$        ",
      "       $        "
    ]
  ],
  "palette": {
    "palette": [
      {
        "char": "!",
        "block": "create:framed_glass"
      },
      {
        "char": "$",
        "block": "minecraft:mud_bricks"
      },
      {
        "char": "%",
        "block": "minecraft:oak_planks"
      },
      {
        "char": "&",
        "block": "minecraft:oak_slab[type=top,waterlogged=false]"
      },
      {
        "char": "'",
        "block": "minecraft:smooth_stone"
      },
      {
        "char": "(",
        "block": "minecraft:spruce_door[facing=south,half=lower,hinge=left,open=false,powered=false]"
      },
      {
        "char": ")",
        "block": "minecraft:stripped_oak_log[axis=y]"
      },
      {
        "char": "*",
        "block": "minecraft:stripped_oak_wood"
      },
      {
        "char": "+",
        "block": "minecraft:stripped_spruce_wood"
      }
    ]
  }
}
