{
  "xsize": 16,
  "zsize": 16,
  "slices": [
    [
      "1111111111''$111",
      "11111111''$11111",
      "111111''$1111111",
      "1111''$111111111",
      "11''$11111111111",
      "''$1111111111111",
      "$111111111111111",
      "111111111111111'",
      "1111111111111''$",
      "11111111111''$11",
      "111111111''$1111",
      "1111111''$111111",
      "11111''$11111111",
      "111''$1111111111",
      "1''$111111111111",
      "'$11111111111111"
    ],
    [
      "     ***********",
      "     ***********",
      "     ***********",
      "     ***********",
      "     ***********",
      "     ***********",
      "     ***********",
      "     ***********",
      "     ***********",
      "     ***********",
      "     ***********",
      "     ***********",
      "     ***********",
      "     ***********",
      "                ",
      "                "
    ],
    [
      "     0          ",
      "     0          ",
      "     0          ",
      "     0          ",
      "     0++++++.+++",
      "     0          ",
      "     0          ",
      "     0+++.+++.++",
      "     0     +   +",
      "     0     +   +",
      "     0 (   ,(  ,",
      "     0 )   +)  +",
      "     0     +   +",
      "     00000000000",
      "                ",
      "                "
    ],
    [
      "     !          ",
      "     0   %%%%%%%",
      "     0   %%%%%%%",
      "     0          ",
      "     0++++++/+++",
      "     0          ",
      "     0          ",
      "     !+++/+++/++",
      "     !     +   +",
      "     0     +   +",
      "     0     -   -",
      "     !     +   +",
      "     !     +   +",
      "     000!!0000!!",
      "                ",
      "                "
    ],
    [
      "     !          ",
      "     0   %%%%%%%",
      "     0   %%%%%%%",
      "     0          ",
      "     0++++++++++",
      "     0          ",
      "     0          ",
      "     !+++!++++!+",
      "     !     +   +",
      "     0     +   +",
      "     0     +   +",
      "     !     +   +",
      "     !     +   +",
      "     000!!0000!!",
      "                ",
      "                "
    ],
    [
      "     0          ",
      "     0          ",
      "     0        & ",
      "     0          ",
      "     0++++++++++",
      "     0          ",
      "     0          ",
      "     0+++!++++!+",
      "     0     +   +",
      "     0     +   +",
      "     0     +   +",
      "     0     +   +",
      "     0     +   +",
      "     00000000000",
      "                ",
      "                "
    ]
  ],
  "palette": {
    "palette": [
      {
        "char": "!",
        "block": "create:framed_glass"
      },
      {
        "char": "$",
        "block": "minecraft:coarse_dirt"
      },
      {
        "char": "%",
        "block": "minecraft:dark_oak_planks"
      },
      {
        "char": "&",
        "block": "minecraft:gold_block"
      },
      {
        "char": "'",
        "block": "minecraft:gravel"
      },
      {
        "char": "(",
        "block": "minecraft:gray_bed[facing=south,occupied=false,part=foot]"
      },
      {
        "char": ")",
        "block": "minecraft:gray_bed[facing=south,occupied=false,part=head]"
      },
      {
        "char": "*",
        "block": "minecraft:polished_andesite"
      },
      {
        "char": "+",
        "block": "minecraft:polished_tuff"
      },
      {
        "char": ",",
        "block": "minecraft:spruce_door[facing=east,half=lower,hinge=left,open=false,powered=false]"
      },
      {
        "char": "-",
        "block": "minecraft:spruce_door[facing=east,half=upper,hinge=left,open=false,powered=false]"
      },
      {
        "char": ".",
        "block": "minecraft:spruce_door[facing=south,half=lower,hinge=left,open=false,powered=false]"
      },
      {
        "char": "/",
        "block": "minecraft:spruce_door[facing=south,half=upper,hinge=left,open=false,powered=false]"
      },
      {
        "char": "0",
        "block": "minecraft:tuff_bricks"
      },
      {
        "char": "1",
        "block": "tfmg:asphalt"
      }
    ]
  }
}
