{
  "xsize": 16,
  "zsize": 16,
  "slices": [
    [
      "     )          ",
      "     )          ",
      "     )          ",
      "     )          ",
      "     )          ",
      "     )          ",
      "     )          ",
      "     )          ",
      "     )          ",
      "     )          ",
      "     )          ",
      "     )          ",
      "     )          ",
      "     )))))))))))",
      "                ",
      "                "
    ],
    [
      "     )          ",
      "     )          ",
      "     )          ",
      "     )          ",
      "     )          ",
      "     )          ",
      "     )          ",
      "     )          ",
      "     )          ",
      "     )          ",
      "     )          ",
      "     )          ",
      "     )          ",
      "     )))))))))))",
      "                ",
      "                "
    ],
    [
      "     )          ",
      "     )          ",
      "     )          ",
      "     )          ",
      "     )          ",
      "     )          ",
      "     )          ",
      "     )          ",
      "     )          ",
      "     )          ",
      "     )          ",
      "     )          ",
      "     )          ",
      "     )))))))))))",
      "                ",
      "                "
    ],
    [
      "     )          ",
      "     )          ",
      "     )          ",
      "     )          ",
      "     )          ",
      "     )          ",
      "     )          ",
      "     )          ",
      "     )          ",
      "     )          ",
      "     )          ",
      "     )          ",
      "     )          ",
      "     )))))))))))",
      "                ",
      "                "
    ],
    [
      "     %!!!!!!!!!!",
      "     %!!!!!!!!!!",
      "     %!!!!!!!!!!",
      "     %!!!!!!!!!!",
      "     %!!!!!!!!!!",
      "     %!!!!!!!!!!",
      "     %!!!!!!!!!!",
      "     %!!!!!!!!!!",
      "     %!!!!!!!!!!",
      "     %!!!!!!!!!!",
      "     %!!!!!!!!!!",
      "     %!!!!!!!!!!",
      "     %!!!!!!!!!!",
      "     %%%%%%%%%%%",
      "                ",
      "                "
    ],
    [
      "     )          ",
      "     )          ",
      "     )          ",
      "     )          ",
      "     )$$$$$$&$$$",
      "     )          ",
      "     )          ",
      "     )  ''      ",
      "     )  (       ",
      "     )          ",
      "     )          ",
      "     )          ",
      "     )          ",
      "     )))))))))))",
      "                ",
      "                "
    ]
  ],
  "palette": {
    "palette": [
      {
        "char": "!",
        "block": "minecraft:polished_andesite"
      },
      {
        "char": "$",
        "block": "minecraft:polished_tuff"
      },
      {
        "char": "%",
        "block": "minecraft:smooth_stone"
      },
      {
        "char": "&",
        "block": "minecraft:spruce_door[facing=south,half=lower,hinge=left,open=false,powered=false]"
      },
      {
        "char": "'",
        "block": "minecraft:spruce_slab[type=bottom,waterlogged=false]"
      },
      {
        "char": "(",
        "block": "minecraft:spruce_stairs[facing=north,half=bottom,shape=straight,waterlogged=false]"
      },
      {
        "char": ")",
        "block": "minecraft:tuff_bricks"
      }
    ]
  }
}
