{
  "xsize": 16,
  "zsize": 16,
  "slices": [
    [
      " ---------''%---",
      " %------''%-----",
      " -----''%-------",
      " ---''%---------",
      " -''%-----------",
      " '%-------------",
      " ---------------",
      " %-------------'",
      " ------------''%",
      " ----------''%--",
      " --------''%----",
      " ------''%------",
      " ----''%--------",
      " -%''%-%----%---",
      "                ",
      "                "
    ],
    [
      "    ............",
      "    ............",
      "    ............",
      "    ............",
      "    ............",
      "    ............",
      "    ............",
      "    ............",
      "    ............",
      "    ............",
      "                ",
      "                ",
      "                ",
      "                ",
      "                ",
      "                "
    ],
    [
      "    (           ",
      "    ( &   &   & ",
      "    (           ",
      "    (           ",
      "    ( *   *   * ",
      "    (           ",
      "    (           ",
      "    ( $$$$$$$$  ",
      "    ( ) +       ",
      "    ((((((((((((",
      "                ",
      "                ",
      "                ",
      "                ",
      "                ",
      "                "
    ],
    [
      "    (           ",
      "    (           ",
      "    (           ",
      "    (           ",
      "    (           ",
      "    (           ",
      "    (           ",
      "    (        ,  ",
      "    (           ",
      "    ((((((((((((",
      "                ",
      "                ",
      "                ",
      "                ",
      "                ",
      "                "
    ],
    [
      "    (           ",
      "    (           ",
      "    !           ",
      "    !           ",
      "    (           ",
      "    (           ",
      "    (           ",
      "    (           ",
      "    (           ",
      "    ((((((((((((",
      "                ",
      "                ",
      "                ",
      "                ",
      "                ",
      "                "
    ],
    [
      "    (           ",
      "    (           ",
      "    !           ",
      "    !           ",
      "    (           ",
      "    !           ",
      "    !           ",
      "    (           ",
      "    (           ",
      "    ((((((((((((",
      "                ",
      "                ",
      "                ",
      "                ",
      "                ",
      "                "
    ]
  ],
  "palette": {
    "palette": [
      {
        "char": "!",
        "block": "create:framed_glass"
      },
      {
        "char": "$",
        "block": "minecraft:barrel[facing=up,open=false]"
      },
      {
        "char": "%",
        "block": "minecraft:coarse_dirt"
      },
      {
        "char": "&",
        "block": "minecraft:crafting_table"
      },
      {
        "char": "'",
        "block": "minecraft:gravel"
      },
      {
        "char": "(",
        "block": "minecraft:mud_bricks"
      },
      {
        "char": ")",
        "block": "minecraft:smoker[facing=north,lit=false]"
      },
      {
        "char": "*",
        "block": "minecraft:spruce_slab[type=bottom,waterlogged=false]"
      },
      {
        "char": "+",
        "block": "minecraft:water_cauldron[level=1]"
      },
      {
        "char": ",",
        "block": "supplementaries:item_shelf"
      },
      {
        "char": "-",
        "block": "tfmg:asphalt"
      },
      {
        "char": ".",
        "block": "tfmg:factory_floor"
      }
    ]
  }
}
