{
  "xsize": 16,
  "zsize": 16,
  "slices": [
    [
      "    !           ",
      "    !           ",
      "    !           ",
      "    !           ",
      "    !   %       ",
      "    !           ",
      "    !           ",
      "    !           ",
      "    !           ",
      "    !           ",
      "    !           ",
      "    !           ",
      "    !           ",
      "    !           ",
      "    !!!!!!!!!!!!",
      "                "
    ],
    [
      "    !           ",
      "    !           ",
      "    !           ",
      "    !           ",
      "    !           ",
      "    !   %       ",
      "    !           ",
      "    !           ",
      "    !           ",
      "    !           ",
      "    !           ",
      "    !           ",
      "    !           ",
      "    !           ",
      "    !!!!!!!!!!!!",
      "                "
    ],
    [
      "    !           ",
      "    !           ",
      "    !           ",
      "    !           ",
      "    !           ",
      "    !           ",
      "    !   %       ",
      "    !           ",
      "    !           ",
      "    !           ",
      "    !           ",
      "    !           ",
      "    !'''''''''''",
      "    !'''''''''''",
      "    !'''''''''''",
      "     '''''''''''"
    ],
    [
      "    !,,,,,,,,,,,",
      "    !,,,,,,,,,,,",
      "    !,,,,,,,,,,,",
      "    !,,,,,,,,,,,",
      "    !,,,,,,,,,,,",
      "    !,,, ,,,,,,,",
      "    !,,, ,,,,,,,",
      "    !,,,,,,,,,,,",
      "    !,,,,,,,,,,,",
      "    !,,,,,,,,,,,",
      "    !,,,,,,,,,,,",
      "    !,,,,,,,,,,,",
      "    !,,,,,,,,,,,",
      "    !,,,,,,,,,,,",
      "    !!!!!!!!!!!!",
      "                "
    ],
    [
      "    !   %       ",
      "    !           ",
      "    !           ",
      "    !    *****  ",
      "    !    *****  ",
      "    !    *****  ",
      "    !    *****  ",
      "    !    *****  ",
      "    !    *****  ",
      "    !++++++(++++",
      "    !           ",
      "    !  &&&&&&&&&",
      "    !  &&&&&&&&&",
      "    !  &&&&&&&&&",
      "    !!!!!!!!!!!!",
      "                "
    ],
    [
      "    !           ",
      "    !   %       ",
      "    !           ",
      "    !           ",
      "    !           ",
      "    !     $     ",
      "    !           ",
      "    !           ",
      "    !           ",
      "    !++++++)++++",
      "    !           ",
      "    !  &&&&&&&&&",
      "    !  &&&&&&&&&",
      "    !  &&&&&&&&&",
      "    !!!!!!!!!!!!",
      "                "
    ]
  ],
  "palette": {
    "palette": [
      {
        "char": "!",
        "block": "minecraft:bricks"
      },
      {
        "char": "$",
        "block": "minecraft:loom[facing=north]"
      },
      {
        "char": "%",
        "block": "minecraft:quartz_stairs[facing=south,half=bottom,shape=straight,waterlogged=false]"
      },
      {
        "char": "&",
        "block": "minecraft:scaffolding"
      },
      {
        "char": "'",
        "block": "minecraft:smooth_stone_slab[type=bottom,waterlogged=false]"
      },
      {
        "char": "(",
        "block": "minecraft:spruce_door[facing=south,half=lower,hinge=left,open=false,powered=false]"
      },
      {
        "char": ")",
        "block": "minecraft:spruce_door[facing=south,half=upper,hinge=left,open=false,powered=false]"
      },
      {
        "char": "*",
        "block": "minecraft:spruce_planks"
      },
      {
        "char": "+",
        "block": "tfmg:cinder_block"
      },
      {
        "char": ",",
        "block": "tfmg:factory_floor"
      }
    ]
  }
}
