{
  "xsize": 16,
  "zsize": 16,
  "slices": [
    [
      "    !           ",
      "    !           ",
      "    !           ",
      "    !    (((((  ",
      "    !    (((((  ",
      "    !    (((((  ",
      "    !    (((((  ",
      "    !    (((((  ",
      "    !    (((((  ",
      "    !))))))&))))",
      "    !           ",
      "    !  %%%%%%%%%",
      "    !  %%%%%%%%%",
      "    !  %%%%%%%%%",
      "    !!!!!!!!!!!!",
      "                "
    ],
    [
      "    !           ",
      "    !           ",
      "    !           ",
      "    !           ",
      "    !           ",
      "    !     $     ",
      "    !           ",
      "    !           ",
      "    !           ",
      "    !))))))'))))",
      "    !           ",
      "    !  %%%%%%%%%",
      "    !  %%%%%%%%%",
      "    !  %%%%%%%%%",
      "    !!!!!!!!!!!!",
      "                "
    ],
    [
      "    !           ",
      "    !           ",
      "    !           ",
      "    !           ",
      "    !           ",
      "    !           ",
      "    !           ",
      "    !           ",
      "    !           ",
      "    !)))))))))))",
      "    !           ",
      "    !  %%%%%%%%%",
      "    !  %%%%%%%%%",
      "    !  %%%%%%%%%",
      "    !!!!!!!!!!!!",
      "                "
    ],
    [
      "    !           ",
      "    !           ",
      "    !           ",
      "    !           ",
      "    !           ",
      "    !           ",
      "    !           ",
      "    !           ",
      "    !           ",
      "    !)))))))))))",
      "    !           ",
      "    !  %%%%%%%%%",
      "    !  %%%%%%%%%",
      "    !  %%%%%%%%%",
      "    !!!!!!!!!!!!",
      "                "
    ],
    [
      "    !           ",
      "    !           ",
      "    !           ",
      "    !           ",
      "    !           ",
      "    !           ",
      "    !           ",
      "    !           ",
      "    !           ",
      "    !           ",
      "    !           ",
      "    !           ",
      "    !           ",
      "    !           ",
      "    !!!!!!!!!!!!",
      "                "
    ],
    [
      "    !           ",
      "    !           ",
      "    !           ",
      "    !           ",
      "    !           ",
      "    !           ",
      "    !           ",
      "    !           ",
      "    !           ",
      "    !           ",
      "    !           ",
      "    !           ",
      "    !           ",
      "    !           ",
      "    !!!!!!!!!!!!",
      "                "
    ]
  ],
  "palette": {
    "palette": [
      {
        "char": "!",
        "block": "minecraft:bricks"
      },
      {
        "char": "$",
        "block": "minecraft:loom[facing=north]"
      },
      {
        "char": "%",
        "block": "minecraft:scaffolding"
      },
      {
        "char": "&",
        "block": "minecraft:spruce_door[facing=south,half=lower,hinge=left,open=false,powered=false]"
      },
      {
        "char": "'",
        "block": "minecraft:spruce_door[facing=south,half=upper,hinge=left,open=false,powered=false]"
      },
      {
        "char": "(",
        "block": "minecraft:spruce_planks"
      },
      {
        "char": ")",
        "block": "tfmg:cinder_block"
      }
    ]
  }
}
