{
  "xsize": 16,
  "zsize": 16,
  "slices": [
    [
      "   $         $% ",
      "   $         $% ",
      "   $         $% ",
      "   $         $% ",
      "   $$$$$!!$$$$%%",
      "                ",
      "                ",
      "                ",
      "                ",
      "                ",
      "                ",
      "                ",
      "                ",
      "                ",
      "                ",
      "                "
    ],
    [
      "   $         $% ",
      "   $         $% ",
      "   $         $% ",
      "   $         $% ",
      "   $$$$$!!$$$$%%",
      "                ",
      "                ",
      "                ",
      "                ",
      "                ",
      "                ",
      "                ",
      "                ",
      "                ",
      "                ",
      "                "
    ],
    [
      "   $         $% ",
      "   $         $% ",
      "   $         $% ",
      "   $         $% ",
      "   $$$$$$$$$$$%%",
      "                ",
      "                ",
      "                ",
      "                ",
      "                ",
      "                ",
      "                ",
      "                ",
      "                ",
      "                ",
      "                "
    ],
    [
      "   $         $% ",
      "   $         $% ",
      "   $         $% ",
      "   $         $% ",
      "   $$$$$$$$$$$%%",
      "                ",
      "                ",
      "                ",
      "                ",
      "                ",
      "                ",
      "                ",
      "                ",
      "                ",
      "                ",
      "                "
    ],
    [
      "   &&&&&&&&&&&&&",
      "   &&&&&&&&&&&&&",
      "   &&&&&&&&&&&&&",
      "   &&&&&&&&&&&&&",
      "   &&&&&&&&&&&&&",
      "                ",
      "                ",
      "                ",
      "                ",
      "                ",
      "                ",
      "                ",
      "                ",
      "                ",
      "                ",
      "                "
    ],
    [
      "    '''''''''   ",
      "    '''''''''   ",
      "    '''''''''   ",
      "    '''''''''   ",
      "                ",
      "                ",
      "                ",
      "                ",
      "                ",
      "                ",
      "                ",
      "                ",
      "                ",
      "                ",
      "                ",
      "                "
    ]
  ],
  "palette": {
    "palette": [
      {
        "char": "!",
        "block": "create:framed_glass"
      },
      {
        "char": "$",
        "block": "minecraft:bricks"
      },
      {
        "char": "%",
        "block": "minecraft:mud_bricks"
      },
      {
        "char": "&",
        "block": "minecraft:smooth_stone"
      },
      {
        "char": "'",
        "block": "minecraft:smooth_stone_slab[type=bottom,waterlogged=false]"
      }
    ]
  }
}
