{
  "xsize": 16,
  "zsize": 16,
  "slices": [
    [
      "1111111111111111",
      "1-1111-1111-1111",
      "1111111111111111",
      "1111111111111111",
      "1111111111111111",
      "1111111111111111",
      "1111111111111111",
      "1111111111111111",
      "1111111111111111",
      "11--$11111111111",
      "--$1111111111111",
      "$111111111111111",
      "111111111111111-",
      "1111111111111--$",
      "11111111111--$11",
      "111111111--$1111"
    ],
    [
      "                ",
      "                ",
      "                ",
      "                ",
      "                ",
      "////////////////",
      "////////////////",
      "////////////////",
      "////////////////",
      "////////////////",
      "////////////////",
      "2222222222222222",
      "2222222222222222",
      "2222222222222222",
      "2222222222222222",
      "2222222222222222"
    ],
    [
      "                ",
      "                ",
      "                ",
      "                ",
      "                ",
      "00000%&000000000",
      "               0",
      "               0",
      "               0",
      "               0",
      "00000)*000000000",
      "                ",
      "                ",
      "33333333        ",
      "33333333        ",
      "33333333        "
    ],
    [
      "                ",
      "                ",
      "                ",
      "                ",
      "                ",
      "00000'(000000000",
      "               0",
      "               0",
      "               0",
      "               0",
      "00000+,000000000",
      "                ",
      "                ",
      "                ",
      "                ",
      "  .   .         "
    ],
    [
      "                ",
      "                ",
      "                ",
      "                ",
      "                ",
      "0000000000000000",
      "               0",
      "               0",
      "!           !! 0",
      "               0",
      "0000000000000000",
      "                ",
      "                ",
      "                ",
      "                ",
      "                "
    ],
    [
      "                ",
      "                ",
      "                ",
      "                ",
      "                ",
      "0000000000000000",
      "               0",
      "               0",
      "!           !! 0",
      "               0",
      "0000000000000000",
      "                ",
      "                ",
      "                ",
      "                ",
      "                "
    ]
  ],
  "palette": {
    "palette": [
      {
        "char": "!",
        "block": "create:framed_glass"
      },
      {
        "char": "$",
        "block": "minecraft:coarse_dirt"
      },
      {
        "char": "%",
        "block": "minecraft:dark_oak_door[facing=north,half=lower,hinge=left,open=false,powered=false]"
      },
      {
        "char": "&",
        "block": "minecraft:dark_oak_door[facing=north,half=lower,hinge=right,open=false,powered=false]"
      },
      {
        "char": "'",
        "block": "minecraft:dark_oak_door[facing=north,half=upper,hinge=left,open=false,powered=false]"
      },
      {
        "char": "(",
        "block": "minecraft:dark_oak_door[facing=north,half=upper,hinge=right,open=false,powered=false]"
      },
      {
        "char": ")",
        "block": "minecraft:dark_oak_door[facing=south,half=lower,hinge=left,open=false,powered=false]"
      },
      {
        "char": "*",
        "block": "minecraft:dark_oak_door[facing=south,half=lower,hinge=right,open=false,powered=false]"
      },
      {
        "char": "+",
        "block": "minecraft:dark_oak_door[facing=south,half=upper,hinge=left,open=false,powered=false]"
      },
      {
        "char": ",",
        "block": "minecraft:dark_oak_door[facing=south,half=upper,hinge=right,open=false,powered=false]"
      },
      {
        "char": "-",
        "block": "minecraft:gravel"
      },
      {
        "char": ".",
        "block": "minecraft:iron_trapdoor[facing=south,half=top,open=false,powered=false,waterlogged=false]"
      },
      {
        "char": "/",
        "block": "minecraft:polished_andesite"
      },
      {
        "char": "0",
        "block": "minecraft:smooth_stone"
      },
      {
        "char": "1",
        "block": "tfmg:asphalt"
      },
      {
        "char": "2",
        "block": "tfmg:factory_floor"
      },
      {
        "char": "3",
        "block": "zvhouses:spruce_countertop"
      }
    ]
  }
}
