{
  "xsize": 16,
  "zsize": 16,
  "slices": [
    [
      "        +       ",
      "        +       ",
      "        +       ",
      "        +       ",
      "        +       ",
      "        +       ",
      "        +       ",
      "        +       ",
      "  %     +       ",
      "        +       ",
      "        +       ",
      "        +       ",
      "!!!!!!!!+       ",
      "        +       ",
      "        +       ",
      "        +       "
    ],
    [
      "        +       ",
      "        +       ",
      "        +       ",
      "        +       ",
      "        +       ",
      "        +       ",
      "        +       ",
      "        +       ",
      "        +       ",
      "  %     +       ",
      "        +       ",
      "        +       ",
      "!!!!!!!!+       ",
      "        +       ",
      "        +       ",
      "        +       "
    ],
    [
      "$$$$$$$$+       ",
      "$$$$$$$$+       ",
      "$$$$$$$$+       ",
      "$$$$$$$$+       ",
      "$$$$$$$$+       ",
      "$$$$$$$$+       ",
      "$$$$$$$$+       ",
      "$$$$$$$$+       ",
      "$$ $$$$$+       ",
      "$$$$$$$$+       ",
      "$$$$$$$$+       ",
      "$$$$$$$$+       ",
      "!!!!!!!!+       ",
      "        +       ",
      "        +       ",
      "        +       "
    ],
    [
      "        +       ",
      "        +       ",
      "        +       ",
      "!!&!!!!!+       ",
      "        +       ",
      "        +       ",
      "((      +       ",
      ")       +       ",
      "        +       ",
      "        +       ",
      "        +       ",
      "        +       ",
      "!!!!!!!!+       ",
      "        +       ",
      "        +       ",
      "        +       "
    ],
    [
      "        +       ",
      "        +       ",
      "        +       ",
      "!!'!!!!!+       ",
      "        +       ",
      "        +       ",
      "        +       ",
      "        +       ",
      "        +       ",
      "        +       ",
      "        +       ",
      "        +       ",
      "!!!!!!!!+       ",
      "        +       ",
      "        +       ",
      "        +       "
    ],
    [
      "        ********",
      "        ********",
      "        ********",
      "!!!!!!!!********",
      "        ********",
      "        ********",
      "        ********",
      "        ********",
      "        ********",
      "        ********",
      "        ********",
      "        ********",
      "!!!!!!!!********",
      "        ********",
      "        ********",
      "        ********"
    ]
  ],
  "palette": {
    "palette": [
      {
        "char": "!",
        "block": "minecraft:light_gray_concrete"
      },
      {
        "char": "$",
        "block": "minecraft:polished_andesite"
      },
      {
        "char": "%",
        "block": "minecraft:polished_andesite_stairs[facing=south,half=bottom,shape=straight,waterlogged=false]"
      },
      {
        "char": "&",
        "block": "minecraft:spruce_door[facing=south,half=lower,hinge=left,open=false,powered=false]"
      },
      {
        "char": "'",
        "block": "minecraft:spruce_door[facing=south,half=upper,hinge=left,open=false,powered=false]"
      },
      {
        "char": "(",
        "block": "minecraft:spruce_slab[type=bottom,waterlogged=false]"
      },
      {
        "char": ")",
        "block": "minecraft:spruce_stairs[facing=north,half=bottom,shape=straight,waterlogged=false]"
      },
      {
        "char": "*",
        "block": "minecraft:weathered_cut_copper"
      },
      {
        "char": "+",
        "block": "tfmg:cinder_block"
      }
    ]
  }
}
