{
  "xsize": 16,
  "zsize": 16,
  "slices": [
    [
      "**********      ",
      "**********      ",
      "*********%      ",
      "*******%%$      ",
      "*****%%$**      ",
      "***%%$***%      ",
      "*%%$******      ",
      "%$********      ",
      "**********      ",
      "**********      ",
      "**********      ",
      "*********%      ",
      "********%%      ",
      "******%%$*      ",
      "****%%$***      ",
      "**%%$*****      "
    ],
    [
      "))))))          ",
      "))))))          ",
      "))))))          ",
      "))))))          ",
      "))))))          ",
      "))))))          ",
      "))))))          ",
      "))))))          ",
      "))))))          ",
      "++++++          ",
      "++++++          ",
      "++++++          ",
      "++++++          ",
      "++++++          ",
      "++++++          ",
      "++++++          "
    ],
    [
      "!!!  (          ",
      "!!!  (          ",
      "     (          ",
      "     (          ",
      "'''  (          ",
      "'''  (          ",
      "'''  (          ",
      "     (          ",
      "((((((          ",
      "     &          ",
      "     &          ",
      "     &          ",
      "     &          ",
      "     &          ",
      "     &          ",
      "     &          "
    ],
    [
      "!!!  (          ",
      "!!!  (          ",
      "     (          ",
      "     (          ",
      "'''  (          ",
      "'''  (          ",
      "'''  (          ",
      "     (          ",
      "((((((          ",
      "     &          ",
      "     &          ",
      "     &          ",
      "     &          ",
      "     &          ",
      "     &          ",
      "     &          "
    ],
    [
      "!!!  (          ",
      "!!!  (          ",
      "     (          ",
      "     (          ",
      "'''  (          ",
      "'''  (          ",
      "'''  (          ",
      "     (          ",
      "((((((          ",
      "     &          ",
      "     &          ",
      "     &          ",
      "     &          ",
      "     &          ",
      "     &          ",
      "     &          "
    ],
    [
      "!!!  (          ",
      "!!!  (          ",
      "     (          ",
      "     (          ",
      "'''  (          ",
      "'''  (          ",
      "'''  (          ",
      "     (          ",
      "((((((          ",
      "     &          ",
      "     &          ",
      "     &          ",
      "     &          ",
      "     &          ",
      "     &          ",
      "     &          "
    ]
  ],
  "palette": {
    "palette": [
      {
        "char": "!",
        "block": "ae2:drive"
      },
      {
        "char": "$",
        "block": "minecraft:coarse_dirt"
      },
      {
        "char": "%",
        "block": "minecraft:gravel"
      },
      {
        "char": "&",
        "block": "minecraft:light_gray_concrete"
      },
      {
        "char": "'",
        "block": "minecraft:scaffolding"
      },
      {
        "char": "(",
        "block": "minecraft:smooth_quartz"
      },
      {
        "char": ")",
        "block": "minecraft:smooth_stone"
      },
      {
        "char": "*",
        "block": "tfmg:asphalt"
      },
      {
        "char": "+",
        "block": "tfmg:factory_floor"
      }
    ]
  }
}
