{
  "xsize": 16,
  "zsize": 16,
  "slices": [
    [
      "&&&      0      ",
      "&&&      0      ",
      "&&&      0      ",
      "&&&      0      ",
      "&&&      0      ",
      "&&&      0      ",
      "&&&      0      ",
      "&&&      0      ",
      "&&&      0      ",
      "&&&      0      ",
      "&&&   (  0      ",
      "&&&      0      ",
      "&&&      0      ",
      "&&&      0      ",
      "&&&      0      ",
      "&&&      0      "
    ],
    [
      "&&&      0      ",
      "&&&      0      ",
      "&&&      0      ",
      "&&&      0      ",
      "&&&      0      ",
      "&&&      0      ",
      "&&&      0      ",
      "&&&      0      ",
      "&&&      0      ",
      "&&&      0      ",
      "&&&      0      ",
      "&&&   (  0      ",
      "&&&      0      ",
      "&&&      0      ",
      "&&&      0      ",
      "&&&      0      "
    ],
    [
      "&&&------0      ",
      "&&&------0      ",
      "&&&------0      ",
      "&&&------0      ",
      "&&&------0      ",
      "&&&------0      ",
      "&&&------0      ",
      "&&&------0      ",
      "&&&------0      ",
      "&&&------0      ",
      "&&&--- --0      ",
      "&&&--- --0      ",
      "&&&---(--0      ",
      "&&&------0      ",
      "&&&------0      ",
      "&&&------0      "
    ],
    [
      "         0      ",
      "         0      ",
      "         0      ",
      "         0      ",
      "......+..0      ",
      "         0      ",
      "      (  0      ",
      "         0      ",
      "         0      ",
      "         0      ",
      "         0      ",
      "         0      ",
      "     *   0      ",
      "%        0      ",
      "$    / ) 0      ",
      "         0      "
    ],
    [
      "         0      ",
      "         0      ",
      "         0      ",
      "         0      ",
      "......,..0      ",
      "         0      ",
      "         0      ",
      "      (  0      ",
      "         0      ",
      "         0      ",
      "         0      ",
      "         0      ",
      "         0      ",
      "         0      ",
      "         0      ",
      "       ' 0      "
    ],
    [
      "         0      ",
      "         0      ",
      "         0      ",
      "         0      ",
      ".........0      ",
      "         0      ",
      "         0      ",
      "         0      ",
      "      (  0      ",
      "         0      ",
      "         0      ",
      "         0      ",
      "         !      ",
      "         !      ",
      "         0      ",
      "         0      "
    ]
  ],
  "palette": {
    "palette": [
      {
        "char": "!",
        "block": "create:framed_glass"
      },
      {
        "char": "$",
        "block": "minecraft:brown_bed[facing=north,occupied=false,part=foot]"
      },
      {
        "char": "%",
        "block": "minecraft:brown_bed[facing=north,occupied=false,part=head]"
      },
      {
        "char": "&",
        "block": "minecraft:gravel"
      },
      {
        "char": "'",
        "block": "minecraft:lever[face=wall,facing=south,powered=false]"
      },
      {
        "char": "(",
        "block": "minecraft:oak_stairs[facing=south,half=bottom,shape=straight,waterlogged=false]"
      },
      {
        "char": ")",
        "block": "minecraft:quartz_stairs[facing=north,half=bottom,shape=straight,waterlogged=false]"
      },
      {
        "char": "*",
        "block": "minecraft:spawner",
        "tag": {
          "id": "minecraft:mob_spawner",
          "Delay": 200,
          "MinSpawnDelay": 240,
          "MaxSpawnDelay": 720,
          "SpawnCount": 2,
          "MaxNearbyEntities": 6,
          "RequiredPlayerRange": 14,
          "SpawnRange": 4,
          "SpawnData": {
            "entity": {
              "id": "minecraft:pillager"
            }
          },
          "SpawnPotentials": [
            {
              "weight": 1,
              "data": {
                "entity": {
                  "id": "minecraft:pillager"
                }
              }
            }
          ]
        }
      },
      {
        "char": "+",
        "block": "minecraft:spruce_door[facing=south,half=lower,hinge=left,open=false,powered=false]"
      },
      {
        "char": ",",
        "block": "minecraft:spruce_door[facing=south,half=upper,hinge=left,open=false,powered=false]"
      },
      {
        "char": "-",
        "block": "minecraft:spruce_planks"
      },
      {
        "char": ".",
        "block": "minecraft:stripped_spruce_wood"
      },
      {
        "char": "/",
        "block": "kubejs:ruined_cauldron"
      },
      {
        "char": "0",
        "block": "the_wasteland_reworked:decayed_planks"
      }
    ]
  }
}
