{
  "xsize": 16,
  "zsize": 16,
  "slices": [
    [
      "!!!!!!!!!&&&&&& ",
      "!!!!!!!!!&&&&&& ",
      "!!!!!!!!!&&&&&& ",
      "&&&&&&&&&&&&&&& ",
      "&&&&&&&&&&&&&&& ",
      "&&&&&&&&&&&&&&& ",
      "&&&&&&&&&&&&%&& ",
      "&&&&&&&&&&&&&&& ",
      "&&&&&&&&&&&&&&& ",
      "&&&&&&&&&&&&&&& ",
      "                ",
      "                ",
      "                ",
      "                ",
      "                ",
      "                "
    ],
    [
      "!!!!!!!!!       ",
      "!!!!!!!!!       ",
      "!!!!!!!!!       ",
      "                ",
      "                ",
      "                ",
      "            $   ",
      "                ",
      "                ",
      "                ",
      "                ",
      "                ",
      "                ",
      "                ",
      "                ",
      "                "
    ],
    [
      "!!!!!!!!!       ",
      "!!!!!!!!!       ",
      "!!!!!!!!!       ",
      "                ",
      "                ",
      "                ",
      "                ",
      "                ",
      "                ",
      "                ",
      "                ",
      "                ",
      "                ",
      "                ",
      "                ",
      "                "
    ]
  ],
  "palette": {
    "palette": [
      {
        "char": "!",
        "block": "create:framed_glass"
      },
      {
        "char": "$",
        "block": "minecraft:iron_trapdoor[facing=north,half=bottom,open=false,powered=false,waterlogged=false]"
      },
      {
        "char": "%",
        "block": "minecraft:ladder[facing=west,waterlogged=false]"
      },
      {
        "char": "&",
        "block": "minecraft:weathered_cut_copper"
      }
    ]
  }
}
