{
  "xsize": 16,
  "zsize": 16,
  "slices": [
    [
      "           !    ",
      "           !    ",
      "           !    ",
      "           !    ",
      "           !    ",
      "           !    ",
      "           !    ",
      "           !    ",
      "           !    ",
      "           !    ",
      "      )    !    ",
      "           !    ",
      "           !    ",
      "           !    ",
      "%%%%%%%%%%%%%%  ",
      "$$$$$$$$$$$$$$$$"
    ],
    [
      "           !    ",
      "           !    ",
      "           !    ",
      "           !    ",
      "           !    ",
      "           !    ",
      "           !    ",
      "           !    ",
      "           !    ",
      "           !    ",
      "           !    ",
      "      )    !    ",
      "           !    ",
      "           !    ",
      "%%%%%%%%%%%%%%  ",
      "$$$$$$$$$$$$$$$$"
    ],
    [
      "           !    ",
      "           !    ",
      "           !    ",
      "           !    ",
      "           !    ",
      "           !    ",
      "           !    ",
      "           !    ",
      "           !    ",
      "           !    ",
      "           !    ",
      "           !    ",
      "      )    !    ",
      "           !    ",
      "%%%%%%%%%%%%%%  ",
      "           % %  "
    ],
    [
      "           !    ",
      "           !    ",
      "           !    ",
      "           !    ",
      "           !    ",
      "           !    ",
      "           !    ",
      "           !    ",
      "           !    ",
      "           !    ",
      "           !    ",
      "           !    ",
      "           !    ",
      "      )    !    ",
      "%%%%%%%%%%%%%%  ",
      "           % %  "
    ],
    [
      ",,,,,,,,,,,!    ",
      ",,,,,,,,,,,!    ",
      ",,,,,,,,,,,!    ",
      ",,,,,,,,,,,!    ",
      ",,,,,,,,,,,!    ",
      ",,,,,,,,,,,!    ",
      ",,,,,,,,,,,!    ",
      ",,,,,,,,,,,!    ",
      ",,,,,,,,,,,!    ",
      ",,,,,,,,,,,!    ",
      ",,,,,,,,,,,!    ",
      ",,,,,,,,,,,!    ",
      ",,,,,, ,,,,!    ",
      ",,,,,, ,,,,!    ",
      ",,,,,,),,,,%%%  ",
      "           % %  "
    ],
    [
      "         * !    ",
      "  (  (  (  !    ",
      "++'++&++'++!    ",
      "           !    ",
      "           !    ",
      "           !    ",
      "           !    ",
      "           !    ",
      "+++++&+++++!    ",
      "           !    ",
      "           !    ",
      "           !    ",
      "           !    ",
      "           !    ",
      "%%%%%% %%%%%%%  ",
      "           % %  "
    ]
  ],
  "palette": {
    "palette": [
      {
        "char": "!",
        "block": "minecraft:bricks"
      },
      {
        "char": "$",
        "block": "minecraft:gravel"
      },
      {
        "char": "%",
        "block": "minecraft:mud_bricks"
      },
      {
        "char": "&",
        "block": "minecraft:spruce_door[facing=south,half=lower,hinge=left,open=false,powered=false]"
      },
      {
        "char": "'",
        "block": "minecraft:spruce_slab[type=bottom,waterlogged=false]"
      },
      {
        "char": "(",
        "block": "minecraft:spruce_stairs[facing=north,half=bottom,shape=straight,waterlogged=false]"
      },
      {
        "char": ")",
        "block": "minecraft:stone_brick_stairs[facing=south,half=bottom,shape=straight,waterlogged=false]"
      },
      {
        "char": "*",
        "block": "minecraft:water_cauldron[level=1]"
      },
      {
        "char": "+",
        "block": "tfmg:cinder_block"
      },
      {
        "char": ",",
        "block": "tfmg:factory_floor"
      }
    ]
  }
}
