{
  "xsize": 16,
  "zsize": 16,
  "slices": [
    [
      "    !  %%%%%%%%%",
      "    !  %%%%%%%%%",
      "    !  %%%%%%%%%",
      "$$$$!  %%%%%%%%%",
      "    !  %%%%%%%%%",
      "    !  %%%%%%%%%",
      "    !  %%%%%%%%%",
      "    !  %%%%%%%%%",
      "    !  %%%%%%%%%",
      "    !  %%%%%%%%%",
      "    !  %%%%%%%%%",
      "    !  %%%%%%%%%",
      "    !  %%%%%%%%%",
      "    !           ",
      "    !           ",
      "    !!!!!!!!!!!!"
    ],
    [
      "%%%%!  %%%%%%%%%",
      "%%%%!  %%%%%%%%%",
      "%%%%!  %%%%%%%%%",
      "%%%%!  %%%%%%%%%",
      "    !  %%%%%%%%%",
      "    !  %%%%%%%%%",
      "    !  %%%%%%%%%",
      "    !  %%%%%%%%%",
      "    !  %%%%%%%%%",
      "    !  %%%%%%%%%",
      "    !  %%%%%%%%%",
      "    !  %%%%%%%%%",
      "    !  %%%%%%%%%",
      "    !           ",
      "    !           ",
      "    !!!!!!!!!!!!"
    ],
    [
      "    !           ",
      "    !           ",
      "    !           ",
      "    !           ",
      "    !           ",
      "    !           ",
      "    !           ",
      "    !           ",
      "    !           ",
      "    !           ",
      "    !           ",
      "    !           ",
      "    !           ",
      "    !           ",
      "    !           ",
      "    !!!!!!!!!!!!"
    ],
    [
      "    !           ",
      "    !           ",
      "    !           ",
      "    !           ",
      "    !           ",
      "    !           ",
      "    !           ",
      "    !           ",
      "    !           ",
      "    !           ",
      "    !           ",
      "    !           ",
      "    !           ",
      "    !           ",
      "    !           ",
      "    !!!!!!!!!!!!"
    ],
    [
      "    !           ",
      "    !           ",
      "    !           ",
      "    !           ",
      "    !           ",
      "    !           ",
      "    !           ",
      "    !           ",
      "    !           ",
      "    !           ",
      "    !           ",
      "    !           ",
      "    !           ",
      "    !           ",
      "    !           ",
      "    !!!!!!!!!!!!"
    ],
    [
      "    !           ",
      "    !           ",
      "    !           ",
      "    !           ",
      "    !           ",
      "    !           ",
      "    !           ",
      "    !           ",
      "    !           ",
      "    !           ",
      "    !           ",
      "    !           ",
      "    !           ",
      "    !           ",
      "    !           ",
      "    !!!!!!!!!!!!"
    ]
  ],
  "palette": {
    "palette": [
      {
        "char": "!",
        "block": "minecraft:light_gray_concrete"
      },
      {
        "char": "$",
        "block": "minecraft:smooth_quartz"
      },
      {
        "char": "%",
        "block": "minecraft:smooth_stone"
      }
    ]
  }
}
