{
  "xsize": 16,
  "zsize": 16,
  "slices": [
    [
      ";;;;;;;;;;;;;;;;",
      "333333333333333;",
      "333333333333333;",
      "333333333333333;",
      "333333333333333;",
      "333333333333333;",
      "333333333333333;",
      "333333333333333;",
      "333333333333333;",
      ";;++%;;;;;;;;;;;",
      "++%;;;;;;;;;;;;;",
      "%;;;;;;;;;;;;;;;",
      ";;;;;;;;;;;;;;;+",
      ";;;;;;;;;;;;;++%",
      ";;;;;;;;;;;++%;;",
      ";;;;;;;;;++%;;;;"
    ],
    [
      "                ",
      "2            2  ",
      "                ",
      " $              ",
      "+               ",
      " $$             ",
      "1+1$111111111111",
      "+$$1111111111111",
      "+++$111111111111",
      "++1+111111111111",
      "++++111111111111",
      "$1+1111111111111",
      "++1$111111111111",
      "111$111111111111",
      "1$$1111111111111",
      "1111111111111111"
    ],
    [
      "                ",
      "2            2  ",
      "                ",
      "                ",
      "$               ",
      " 77        77   ",
      " + 00&'000000000",
      "+            0  ",
      "$++   *   *  0  ",
      "++ $         0  ",
      "+$$+         5  ",
      "  $77   477  0  ",
      "$+ 9     9   0  ",
      "             0  ",
      "00000,-000000000",
      "                "
    ],
    [
      "                ",
      "2            2  ",
      "                ",
      "                ",
      "                ",
      "                ",
      " $ :0()000:!!:0:",
      "$            0  ",
      " $$          0  ",
      "$+           0  ",
      "+  $         6  ",
      "             0  ",
      " $           0  ",
      "             0  ",
      "00000./000000000",
      "                "
    ],
    [
      "                ",
      "2            2  ",
      "                ",
      "                ",
      "                ",
      "                ",
      "   :000000:!!:0:",
      "             0  ",
      "             0  ",
      " $           0  ",
      "$            0  ",
      "             0  ",
      "             0  ",
      "             0  ",
      "0000000000000000",
      "                "
    ],
    [
      "                ",
      "2            2  ",
      "                ",
      "                ",
      "                ",
      " 88        88   ",
      "   0000000000000",
      "             0  ",
      "             0  ",
      "             0  ",
      "             0  ",
      "             0  ",
      "             0  ",
      "             0  ",
      "0000000000000000",
      "                "
    ]
  ],
  "palette": {
    "palette": [
      {
        "char": "!",
        "block": "create:framed_glass"
      },
      {
        "char": "$",
        "block": "immersiveengineering:concrete_brick_cracked"
      },
      {
        "char": "%",
        "block": "minecraft:coarse_dirt"
      },
      {
        "char": "&",
        "block": "minecraft:dark_oak_door[facing=north,half=lower,hinge=left,open=false,powered=false]"
      },
      {
        "char": "'",
        "block": "minecraft:dark_oak_door[facing=north,half=lower,hinge=right,open=false,powered=false]"
      },
      {
        "char": "(",
        "block": "minecraft:dark_oak_door[facing=north,half=upper,hinge=left,open=false,powered=false]"
      },
      {
        "char": ")",
        "block": "minecraft:dark_oak_door[facing=north,half=upper,hinge=right,open=false,powered=false]"
      },
      {
        "char": "*",
        "block": "minecraft:dark_oak_stairs[facing=south,half=bottom,shape=straight,waterlogged=false]"
      },
      {
        "char": "+",
        "block": "minecraft:gravel"
      },
      {
        "char": ",",
        "block": "minecraft:iron_door[facing=south,half=lower,hinge=left,open=false,powered=false]"
      },
      {
        "char": "-",
        "block": "minecraft:iron_door[facing=south,half=lower,hinge=right,open=false,powered=false]"
      },
      {
        "char": ".",
        "block": "minecraft:iron_door[facing=south,half=upper,hinge=left,open=false,powered=false]"
      },
      {
        "char": "/",
        "block": "minecraft:iron_door[facing=south,half=upper,hinge=right,open=false,powered=false]"
      },
      {
        "char": "0",
        "block": "minecraft:light_gray_concrete"
      },
      {
        "char": "1",
        "block": "minecraft:polished_andesite"
      },
      {
        "char": "2",
        "block": "minecraft:polished_blackstone_bricks"
      },
      {
        "char": "3",
        "block": "minecraft:smooth_stone"
      },
      {
        "char": "4",
        "block": "minecraft:spawner",
        "tag": {
          "id": "minecraft:mob_spawner",
          "Delay": 200,
          "MinSpawnDelay": 240,
          "MaxSpawnDelay": 720,
          "SpawnCount": 2,
          "MaxNearbyEntities": 8,
          "RequiredPlayerRange": 14,
          "SpawnRange": 4,
          "SpawnData": {
            "entity": {
              "id": "minecraft:zombie"
            }
          },
          "SpawnPotentials": [
            {
              "weight": 1,
              "data": {
                "entity": {
                  "id": "minecraft:zombie"
                }
              }
            }
          ]
        }
      },
      {
        "char": "5",
        "block": "minecraft:spruce_door[facing=east,half=lower,hinge=left,open=false,powered=false]"
      },
      {
        "char": "6",
        "block": "minecraft:spruce_door[facing=east,half=upper,hinge=left,open=false,powered=false]"
      },
      {
        "char": "7",
        "block": "minecraft:spruce_slab[type=bottom,waterlogged=false]"
      },
      {
        "char": "8",
        "block": "minecraft:spruce_slab[type=top,waterlogged=false]"
      },
      {
        "char": "9",
        "block": "minecraft:spruce_stairs[facing=north,half=bottom,shape=straight,waterlogged=false]"
      },
      {
        "char": ":",
        "block": "minecraft:stripped_spruce_log[axis=y]"
      },
      {
        "char": ";",
        "block": "tfmg:asphalt"
      }
    ]
  }
}
