{
  "xsize": 16,
  "zsize": 16,
  "slices": [
    [
      "'''''''         ",
      "$''''''         ",
      "'''''''         ",
      "'''''$'         ",
      "'''''''         ",
      "'''''''         ",
      "'''''''         ",
      "''''''          ",
      "''''''          ",
      "'''''$          ",
      "'''$$!          ",
      "'$$!''          ",
      "$!''''          ",
      "''''''          ",
      "''''''          ",
      "'''''$          "
    ],
    [
      "                ",
      "                ",
      "                ",
      "                ",
      "                ",
      "                ",
      "$$$$$$$         ",
      "$$$$$$$         ",
      "$$$$$$$         ",
      "$$$$$$$         ",
      "$$$$$$$         ",
      "$$$$$$$         ",
      "$$$$$$$         ",
      "$$$$$$$         ",
      "$$$$$$$         ",
      "$$$$$$$         "
    ],
    [
      "                ",
      "                ",
      "                ",
      "                ",
      "                ",
      "                ",
      "$$$$$$$         ",
      "$$$$$$$         ",
      "$$$$$$$         ",
      "$$$$$$$         ",
      "$$$$$$$         ",
      "$$$$$$$         ",
      "$$$$$$$         ",
      "$$$$$$$         ",
      "$$$$$$$         ",
      "$$$$$$$         "
    ],
    [
      "                ",
      "                ",
      "                ",
      "                ",
      "                ",
      "                ",
      "$$$$$$$         ",
      "$$$$$$$         ",
      "$$$$$$$         ",
      "$$$$$$$         ",
      "$$$$$$$         ",
      "$$$$$$$         ",
      "$$$$$$$         ",
      "$$$$$$$         ",
      "$$$$$$$         ",
      "$$$$$$$         "
    ],
    [
      "                ",
      "                ",
      "                ",
      "                ",
      "                ",
      "                ",
      "$$$$$$$         ",
      "$$$$$$$         ",
      "$$$$$$$         ",
      "$$$$$$$         ",
      "$$$$$$$         ",
      "$$$$$$$         ",
      "$$$$$$$         ",
      "$$$$$$$         ",
      "$$$$$$$         ",
      "$$$$$$$         "
    ],
    [
      "                ",
      "                ",
      "                ",
      "                ",
      "                ",
      "                ",
      "  %             ",
      "&&%             ",
      "  &             ",
      "  &             ",
      "  &             ",
      "  &             ",
      "& &             ",
      "  &             ",
      "  &             ",
      "  &             "
    ]
  ],
  "palette": {
    "palette": [
      {
        "char": "!",
        "block": "minecraft:coarse_dirt"
      },
      {
        "char": "$",
        "block": "minecraft:gravel"
      },
      {
        "char": "%",
        "block": "minecraft:mud_bricks"
      },
      {
        "char": "&",
        "block": "minecraft:red_terracotta"
      },
      {
        "char": "'",
        "block": "tfmg:asphalt"
      }
    ]
  }
}
