{
  "xsize": 16,
  "zsize": 16,
  "slices": [
    [
      "1111))))))))))))",
      "11&&))))))))))))",
      "&&%1))))))))))))",
      "%111))))))))))))",
      "1111))))))))))))",
      "1111))))))))))))",
      "1111))))))))))))",
      "1111))))))))))))",
      "1111))))))))))))",
      "1111))))))))))))",
      "111&))))))))))))",
      "1&&%))))))))))))",
      "&%11))))))))))))",
      "1111))))))))))))",
      "1111))))))))))))",
      "1111))))))))))))"
    ],
    [
      "     (((((((((((",
      "     (((((((((((",
      "     (((((((((((",
      "     (((((((((((",
      "     (((((((((((",
      "     (((((((((((",
      "     (((((((((((",
      "     (((((((((((",
      "     (((((((((((",
      "     (((((((((((",
      "     (((((((((((",
      "     (((((((((((",
      "     (((((((((((",
      "     (((((((((((",
      "     (((((((((((",
      "     ((((((((((("
    ],
    [
      "     '          ",
      "     '''''''+'''",
      "     '          ",
      "     '          ",
      "     '  . *  . $",
      "     '  /    /  ",
      "     '          ",
      "     '          ",
      "     '  . $  . $",
      "     '  /    /  ",
      "     '          ",
      "     000000000  ",
      "     0       0  ",
      "     0       0  ",
      "     0       0  ",
      "     0  . -  0  "
    ],
    [
      "     '          ",
      "     ''''''','''",
      "     '          ",
      "     '          ",
      "     !          ",
      "     !          ",
      "     '          ",
      "     '          ",
      "     '          ",
      "     '          ",
      "     '          ",
      "     000000000  ",
      "     0       0  ",
      "     0       0  ",
      "     0       0  ",
      "     !       0  "
    ],
    [
      "     '          ",
      "     '''''''''''",
      "     '          ",
      "     '          ",
      "     !          ",
      "     !          ",
      "     '          ",
      "     '          ",
      "     '          ",
      "     '          ",
      "     '          ",
      "     000000000  ",
      "     0       0  ",
      "     0       0  ",
      "     0       0  ",
      "     !       0  "
    ],
    [
      "     '          ",
      "     '''''''''''",
      "     '          ",
      "     '          ",
      "     '          ",
      "     '          ",
      "     '          ",
      "     '          ",
      "     '          ",
      "     '          ",
      "     '          ",
      "     000000000  ",
      "     0       0  ",
      "     0       0  ",
      "     0       0  ",
      "     0       0  "
    ]
  ],
  "palette": {
    "palette": [
      {
        "char": "!",
        "block": "create:framed_glass"
      },
      {
        "char": "$",
        "block": "minecraft:brewing_stand"
      },
      {
        "char": "%",
        "block": "minecraft:coarse_dirt"
      },
      {
        "char": "&",
        "block": "minecraft:gravel"
      },
      {
        "char": "'",
        "block": "minecraft:light_gray_concrete"
      },
      {
        "char": "(",
        "block": "minecraft:polished_andesite"
      },
      {
        "char": ")",
        "block": "minecraft:smooth_stone"
      },
      {
        "char": "*",
        "block": "minecraft:spawner",
        "tag": {
          "id": "minecraft:mob_spawner",
          "Delay": 200,
          "MinSpawnDelay": 240,
          "MaxSpawnDelay": 720,
          "SpawnCount": 2,
          "MaxNearbyEntities": 8,
          "RequiredPlayerRange": 14,
          "SpawnRange": 4,
          "SpawnData": {
            "entity": {
              "id": "minecraft:zombie"
            }
          },
          "SpawnPotentials": [
            {
              "weight": 1,
              "data": {
                "entity": {
                  "id": "minecraft:zombie"
                }
              }
            }
          ]
        }
      },
      {
        "char": "+",
        "block": "minecraft:spruce_door[facing=south,half=lower,hinge=left,open=false,powered=false]"
      },
      {
        "char": ",",
        "block": "minecraft:spruce_door[facing=south,half=upper,hinge=left,open=false,powered=false]"
      },
      {
        "char": "-",
        "block": "minecraft:water_cauldron[level=3]"
      },
      {
        "char": ".",
        "block": "minecraft:white_bed[facing=south,occupied=false,part=foot]"
      },
      {
        "char": "/",
        "block": "minecraft:white_bed[facing=south,occupied=false,part=head]"
      },
      {
        "char": "0",
        "block": "minecraft:white_concrete"
      },
      {
        "char": "1",
        "block": "tfmg:asphalt"
      }
    ]
  }
}
