{
  "xsize": 16,
  "zsize": 16,
  "slices": [
    [
      "++++++++++++++++",
      "++++++++++++++++",
      "++++++++++++++++",
      "++++++++++++++++",
      "++++++++++++++++",
      "++++++++++++++++",
      "++++++++++++++++",
      "++++++++++++++++",
      "++++++++++++++++",
      "++++++++++++++++",
      "++++++++++++++++",
      "++++++++++++++++",
      "++++++++++++++++",
      "++++++++++++++++",
      "++++++++++++++++",
      "++++++++++++++++"
    ],
    [
      "))))))))))))))))",
      "))))))))))))))))",
      "))))))))))))))))",
      "))))))))))))))))",
      "))))))))))))))))",
      "))))))))))))))))",
      "))))))))))))))))",
      "))))))))))))))))",
      "))))))))))))))))",
      "))))))))))))))))",
      "))))))))))))))))",
      "))))))))))))))))",
      ")))))))))))'''''",
      ")))))))))))'''''",
      ")))))))))))'''''",
      ")))))))))))'''''"
    ],
    [
      "           &    ",
      "&&&&&&&&.&&&&&&&",
      "    &           ",
      "    &222222 !!!!",
      "    &222222 !!!!",
      "    &222022 !!%!",
      "    ,222222 !!!!",
      "    &222222 !!!!",
      "    &222222 !!!!",
      "    &        $  ",
      "    &           ",
      "   22222222&&&&&",
      " 2        2     ",
      " 2        2     ",
      "*2        2 (   ",
      " 2  1 0   2     "
    ],
    [
      "           &    ",
      "&&&&&&&&/&&&&&&&",
      "    &           ",
      "    &222222 !!!!",
      "    &222222 !!!!",
      "    &222222 !!!!",
      "    -222222 !!!!",
      "    &222222 !!!!",
      "    &222222 !!!!",
      "    &           ",
      "    &           ",
      "   22222222&&&&&",
      " 2        2     ",
      " 2        2     ",
      " 2        2     ",
      "*2        2     "
    ],
    [
      "           &    ",
      "&&&&&&&&&&&&&&&&",
      "    &           ",
      "    &       !!!!",
      "    &       !!!!",
      "    &       !!!!",
      "    &       !!!!",
      "    &       !!!!",
      "    &       !!!!",
      "    &           ",
      "    &           ",
      "   22222222&&&&&",
      " 2        2     ",
      " 2        2     ",
      " 2        2     ",
      " 2        2     "
    ],
    [
      "           &    ",
      "&&&&&&&&&&&&&&&&",
      "    &           ",
      "    &           ",
      "    &           ",
      "    &           ",
      "    &           ",
      "    &           ",
      "    &           ",
      "    &           ",
      "    &           ",
      "   22222222&&&&&",
      " 2        2     ",
      " 2        2     ",
      " 2        2     ",
      " 2        2     "
    ]
  ],
  "palette": {
    "palette": [
      {
        "char": "!",
        "block": "immersiveengineering:sheetmetal_steel"
      },
      {
        "char": "$",
        "block": "kubejs:ruined_brewing_stand"
      },
      {
        "char": "%",
        "block": "kubejs:ruined_cartography_table"
      },
      {
        "char": "&",
        "block": "minecraft:light_gray_concrete"
      },
      {
        "char": "'",
        "block": "minecraft:moss_block"
      },
      {
        "char": "(",
        "block": "minecraft:oak_slab[type=bottom,waterlogged=false]"
      },
      {
        "char": ")",
        "block": "minecraft:polished_andesite"
      },
      {
        "char": "*",
        "block": "minecraft:polished_andesite_stairs[facing=south,half=bottom,shape=straight,waterlogged=false]"
      },
      {
        "char": "+",
        "block": "minecraft:smooth_stone"
      },
      {
        "char": ",",
        "block": "minecraft:spruce_door[facing=east,half=lower,hinge=left,open=false,powered=false]"
      },
      {
        "char": "-",
        "block": "minecraft:spruce_door[facing=east,half=upper,hinge=left,open=false,powered=false]"
      },
      {
        "char": ".",
        "block": "minecraft:spruce_door[facing=south,half=lower,hinge=left,open=false,powered=false]"
      },
      {
        "char": "/",
        "block": "minecraft:spruce_door[facing=south,half=upper,hinge=left,open=false,powered=false]"
      },
      {
        "char": "0",
        "block": "kubejs:ruined_cauldron"
      },
      {
        "char": "1",
        "block": "minecraft:white_bed[facing=south,occupied=false,part=foot]"
      },
      {
        "char": "2",
        "block": "minecraft:white_concrete"
      }
    ]
  }
}
