{
  "xsize": 16,
  "zsize": 16,
  "slices": [
    [
      "        22222222",
      "**2222*2222*2222",
      "2222222222222222",
      "2222222222222222",
      "2222222222222222",
      "2222222222222222",
      "2222222222222222",
      "222222**%2222222",
      "2222**%222222222",
      "22**%22222222222",
      "**%2222222222222",
      "%222222222222222",
      "222222222222222*",
      "2222222222222**%",
      "22222222222**%22",
      "222222222**%2222"
    ],
    [
      "                ",
      "                ",
      "                ",
      "                ",
      "    -   ,,,,,,,,",
      "        ,,,,,,,,",
      "        ,,,,,,,,",
      "44444444,,,,,,,,",
      "44444444,,,,,,,,",
      "44444444,,,,,,,,",
      "4444444444444444",
      "4444444444444444",
      "4444444444444444",
      "4444444444444444",
      "4444444444444444",
      "4444444444444444"
    ],
    [
      "                ",
      "                ",
      "                ",
      "                ",
      "    -   ///////&",
      "        /       ",
      "  +     /       ",
      "$$+$$$$$/       ",
      "  +     /       ",
      "  3     ///////(",
      "  3  00     !   ",
      "  3  1   00     ",
      "  3      1      ",
      "  3             ",
      "  3   1  1..... ",
      "  3   0  0  0   "
    ],
    [
      "                ",
      "                ",
      "                ",
      "                ",
      "    -   ///////'",
      "        /       ",
      "  +     /       ",
      "$$+$$$$$/       ",
      "  +     /       ",
      "  3     ///////)",
      "  3             ",
      "  3             ",
      "  3             ",
      "  3             ",
      "  3       ..... ",
      "  3             "
    ],
    [
      "                ",
      "                ",
      "                ",
      "                ",
      "    -   ////////",
      "        /       ",
      "  +     /       ",
      "$$+$$$$$/       ",
      "  +     /       ",
      "  3     ////////",
      "  3             ",
      "  3             ",
      "  3             ",
      "  3             ",
      "  3       ..... ",
      "  3             "
    ],
    [
      "                ",
      "                ",
      "                ",
      "                ",
      "    -   ////////",
      "        /       ",
      "  +     /       ",
      "$$+$$$$$/       ",
      "  +     /       ",
      "  3     ////////",
      "  3             ",
      "  3             ",
      "  3             ",
      "  3             ",
      "  3             ",
      "  3             "
    ]
  ],
  "palette": {
    "palette": [
      {
        "char": "!",
        "block": "minecraft:bookshelf"
      },
      {
        "char": "$",
        "block": "minecraft:bricks"
      },
      {
        "char": "%",
        "block": "minecraft:coarse_dirt"
      },
      {
        "char": "&",
        "block": "minecraft:dark_oak_door[facing=north,half=lower,hinge=left,open=false,powered=false]"
      },
      {
        "char": "'",
        "block": "minecraft:dark_oak_door[facing=north,half=upper,hinge=left,open=false,powered=false]"
      },
      {
        "char": "(",
        "block": "minecraft:dark_oak_door[facing=south,half=lower,hinge=left,open=false,powered=false]"
      },
      {
        "char": ")",
        "block": "minecraft:dark_oak_door[facing=south,half=upper,hinge=left,open=false,powered=false]"
      },
      {
        "char": "*",
        "block": "minecraft:gravel"
      },
      {
        "char": "+",
        "block": "minecraft:mud_bricks"
      },
      {
        "char": ",",
        "block": "minecraft:polished_andesite"
      },
      {
        "char": "-",
        "block": "minecraft:polished_blackstone_bricks"
      },
      {
        "char": ".",
        "block": "minecraft:scaffolding"
      },
      {
        "char": "/",
        "block": "minecraft:smooth_stone"
      },
      {
        "char": "0",
        "block": "minecraft:spruce_slab[type=bottom,waterlogged=false]"
      },
      {
        "char": "1",
        "block": "minecraft:spruce_stairs[facing=north,half=bottom,shape=straight,waterlogged=false]"
      },
      {
        "char": "2",
        "block": "tfmg:asphalt"
      },
      {
        "char": "3",
        "block": "tfmg:cinder_block"
      },
      {
        "char": "4",
        "block": "tfmg:factory_floor"
      }
    ]
  }
}
