{
  "xsize": 16,
  "zsize": 16,
  "slices": [
    [
      " +++++++++%%$+++",
      " $++++++%%$+++++",
      " +++++%%$+++++++",
      " +++%%$+++++++++",
      " +%%$+++++++++++",
      " %$+++++++++++++",
      " +++++++++++++++",
      " $+++++++++++++%",
      " ++++++++++++%%$",
      " ++++++++++%%$++",
      " ++++++++%%$++++",
      " ++++++%%$++++++",
      " ++++%%$++++++++",
      " $+%%$++++++++++",
      " %%$++++++++++++",
      " $++++++++++++++"
    ],
    [
      "     '''''''''''",
      "     '''''''''''",
      "     '''''''''''",
      "     '''''''''''",
      "     '''''''''''",
      "     '''''''''''",
      "     '''''''''''",
      "     '''''''''''",
      "     '''''''''''",
      "     '''''''''''",
      "     '''''''''''",
      "     '''''''''''",
      "     '''''''''''",
      "     '''''''''''",
      "     '''''''''''",
      "     '''''''''''"
    ],
    [
      "     &          ",
      "     )          ",
      "     )          ",
      "     )  ((( ((( ",
      "     )  ((( ((( ",
      "     )  ((( ((( ",
      "     )  ((( ((( ",
      "     )  ((( ((( ",
      "     )  ((( ((( ",
      "     )  ((( ((( ",
      "     )  ((( ((( ",
      "     )  ((( ((( ",
      "     )  ((( ((( ",
      "     )          ",
      "     )          ",
      "     ) !!!!!!!!!"
    ],
    [
      "     &          ",
      "     )          ",
      "     )          ",
      "     )          ",
      "     )          ",
      "     )          ",
      "     )          ",
      "     )          ",
      "     )          ",
      "     )          ",
      "     )          ",
      "     )          ",
      "     )          ",
      "     )          ",
      "     )          ",
      "     )         *"
    ],
    [
      "     &          ",
      "     )          ",
      "     )          ",
      "     )          ",
      "     )          ",
      "     )          ",
      "     )          ",
      "     )          ",
      "     )          ",
      "     )          ",
      "     )          ",
      "     )          ",
      "     )          ",
      "     )          ",
      "     )          ",
      "     )          "
    ],
    [
      "     &          ",
      "     )          ",
      "     )          ",
      "     )          ",
      "     )          ",
      "     )          ",
      "     )          ",
      "     )          ",
      "     )          ",
      "     )          ",
      "     )          ",
      "     )          ",
      "     )          ",
      "     )          ",
      "     )          ",
      "     )          "
    ]
  ],
  "palette": {
    "palette": [
      {
        "char": "!",
        "block": "minecraft:barrel[facing=up,open=false]"
      },
      {
        "char": "$",
        "block": "minecraft:coarse_dirt"
      },
      {
        "char": "%",
        "block": "minecraft:gravel"
      },
      {
        "char": "&",
        "block": "minecraft:mud_bricks"
      },
      {
        "char": "'",
        "block": "minecraft:smooth_stone"
      },
      {
        "char": "(",
        "block": "minecraft:spruce_slab[type=bottom,waterlogged=false]"
      },
      {
        "char": ")",
        "block": "minecraft:yellow_terracotta"
      },
      {
        "char": "*",
        "block": "supplementaries:item_shelf"
      },
      {
        "char": "+",
        "block": "tfmg:asphalt"
      }
    ]
  }
}
