{
  "xsize": 16,
  "zsize": 16,
  "slices": [
    [
      "222222222222    ",
      "2&2222&2222&2222",
      "2222222222222222",
      "22222222222222&&",
      "222222222222&&%2",
      "222222222222%222",
      "2222222222222222",
      "222222&&%2222222",
      "2222&&%222222222",
      "22&&%22222222222",
      "&&%2222222222222",
      "%222222222222222",
      "222222222222222&",
      "2222222222222&&%",
      "22222222222&&%22",
      "222222222&&%2222"
    ],
    [
      "                ",
      "                ",
      "                ",
      "                ",
      "//////          ",
      "/////1///////1  ",
      "//////////////  ",
      "//////////////  ",
      "//////////////  ",
      "//////////////  ",
      "/////////////   ",
      "/////////////   ",
      "/////////////   ",
      "/////////////   ",
      "/////////////   ",
      "/////////////   "
    ],
    [
      "                ",
      "                ",
      "                ",
      "                ",
      "'(0000          ",
      "     1       1  ",
      "     0          ",
      "     03333333   ",
      "     0      3   ",
      "+,0000      3   ",
      "    $$$$$$$ 3   ",
      "    $$$$$$$ 3   ",
      "    $$$$$$$ 3   ",
      "    $$$$$$$ 3   ",
      "    $$$$$$$ 3   ",
      "            3   "
    ],
    [
      "                ",
      "                ",
      "                ",
      "                ",
      ")*0000          ",
      "     1       1  ",
      "     0          ",
      "     03333333   ",
      "     0      3   ",
      "-.0000      3   ",
      "    $$$$$$$ 3   ",
      "    $$$$$$$ 3   ",
      "    $$$$$$$ 3   ",
      "    $$$$$$$ 3   ",
      "    $$$$$$$ 3   ",
      "            3   "
    ],
    [
      "                ",
      "                ",
      "                ",
      "                ",
      "000000          ",
      "     1       1  ",
      "     0          ",
      "     033!!333   ",
      "     0      3   ",
      "000000      3   ",
      "    $$$$$$$ 3   ",
      "    $$$$$$$ 3   ",
      "    $$$$$$$ 3   ",
      "    $$$$$$$ 3   ",
      "    $$$$$$$ 3   ",
      "            3   "
    ],
    [
      "                ",
      "                ",
      "                ",
      "                ",
      "000000          ",
      "     1       1  ",
      "     0          ",
      "     033!!333   ",
      "     0      3   ",
      "000000      3   ",
      "    $$$$$$$ 3   ",
      "    $$$$$$$ 3   ",
      "    $$$$$$$ 3   ",
      "    $$$$$$$ 3   ",
      "    $$$$$$$ 3   ",
      "            3   "
    ]
  ],
  "palette": {
    "palette": [
      {
        "char": "!",
        "block": "create:framed_glass"
      },
      {
        "char": "$",
        "block": "minecraft:bookshelf"
      },
      {
        "char": "%",
        "block": "minecraft:coarse_dirt"
      },
      {
        "char": "&",
        "block": "minecraft:gravel"
      },
      {
        "char": "'",
        "block": "minecraft:spruce_door[facing=north,half=lower,hinge=left,open=false,powered=false]"
      },
      {
        "char": "(",
        "block": "minecraft:spruce_door[facing=north,half=lower,hinge=right,open=false,powered=false]"
      },
      {
        "char": ")",
        "block": "minecraft:spruce_door[facing=north,half=upper,hinge=left,open=false,powered=false]"
      },
      {
        "char": "*",
        "block": "minecraft:spruce_door[facing=north,half=upper,hinge=right,open=false,powered=false]"
      },
      {
        "char": "+",
        "block": "minecraft:spruce_door[facing=south,half=lower,hinge=left,open=false,powered=false]"
      },
      {
        "char": ",",
        "block": "minecraft:spruce_door[facing=south,half=lower,hinge=right,open=false,powered=false]"
      },
      {
        "char": "-",
        "block": "minecraft:spruce_door[facing=south,half=upper,hinge=left,open=false,powered=false]"
      },
      {
        "char": ".",
        "block": "minecraft:spruce_door[facing=south,half=upper,hinge=right,open=false,powered=false]"
      },
      {
        "char": "/",
        "block": "minecraft:spruce_planks"
      },
      {
        "char": "0",
        "block": "minecraft:stripped_spruce_log"
      },
      {
        "char": "1",
        "block": "minecraft:stripped_spruce_log[axis=y]"
      },
      {
        "char": "2",
        "block": "tfmg:asphalt"
      },
      {
        "char": "3",
        "block": "the_wasteland_reworked:decayed_planks"
      }
    ]
  }
}
