{
  "xsize": 16,
  "zsize": 16,
  "slices": [
    [
      "1111111111**!111",
      "11111111**!11111",
      "111111**!1111111",
      "1111**!111111111",
      "11**!11111111111",
      "**!1111111111111",
      "!111111111111111",
      "111111111111111*",
      "1111111111111**!",
      "11111111111**!11",
      "111111111**!1111",
      "1111111**!111111",
      "11111**!11111111",
      "111**!1111111111",
      "1**!111111111111",
      "*!11111111111111"
    ],
    [
      ",,,,,,,,,,,,,*,,",
      ",,,,,,,,,,,,*00*",
      ",,,,,,,,,,,0,,**",
      ",,,,,,,,,,,00**,",
      ",,,,,,,,,,,,****",
      ",,,,,,,,,,,**,**",
      ",,,,,,,,,,,*****",
      ",,,,,,,,,,,,****",
      ",,,,,,,,,,,*****",
      ",,,,,,,,,,,*****",
      ",,,,,,,,,,,*****",
      ",,,,,,,,,,,*****",
      ",,,,,,,,,,,*****",
      ",,,,,,,,,,,*****",
      ",,,,,,,,,,,*****",
      ",,,,,,,,,,,,,***"
    ],
    [
      "        -    0  ",
      "        -   0  *",
      "------------. *0",
      "   -         ** ",
      "   -        *00*",
      "   - ))))))00 **",
      "   $       00***",
      "   -        ****",
      "   - ))))))**0**",
      "   -       *****",
      "   -       0****",
      "   - ))))) *****",
      "   -       *****",
      "   %       0****",
      "   -    (((**0**",
      "   -  + (((  ***"
    ],
    [
      "        -       ",
      "        -      0",
      "------------/ 0 ",
      "   -         00 ",
      "   -        0  *",
      "   -          *0",
      "   &         **0",
      "   -        *00*",
      "   -       00 **",
      "   -       00***",
      "   -        ****",
      "   -       **0**",
      "   -       00***",
      "   '        ****",
      "   -       00 **",
      "   -         **0"
    ],
    [
      "        -       ",
      "        -       ",
      "------------    ",
      "   -            ",
      "   -           0",
      "   -          0 ",
      "   -         00 ",
      "   -        0  *",
      "   -          *0",
      "   -         **0",
      "   -        *00*",
      "   -       00 **",
      "   -         **0",
      "   -        *00*",
      "   -          *0",
      "   -         00 "
    ],
    [
      "        -       ",
      "        -       ",
      "------------    ",
      "   -            ",
      "   -            ",
      "   -            ",
      "   -            ",
      "   -           0",
      "   -          0 ",
      "   -         00 ",
      "   -        0  *",
      "   -          *0",
      "   -         00 ",
      "   -        0  *",
      "   -          0 ",
      "   -            "
    ]
  ],
  "palette": {
    "palette": [
      {
        "char": "!",
        "block": "minecraft:coarse_dirt"
      },
      {
        "char": "$",
        "block": "minecraft:dark_oak_door[facing=east,half=lower,hinge=left,open=false,powered=false]"
      },
      {
        "char": "%",
        "block": "minecraft:dark_oak_door[facing=east,half=lower,hinge=right,open=false,powered=false]"
      },
      {
        "char": "&",
        "block": "minecraft:dark_oak_door[facing=east,half=upper,hinge=left,open=false,powered=false]"
      },
      {
        "char": "'",
        "block": "minecraft:dark_oak_door[facing=east,half=upper,hinge=right,open=false,powered=false]"
      },
      {
        "char": "(",
        "block": "minecraft:dark_oak_slab[type=bottom,waterlogged=false]"
      },
      {
        "char": ")",
        "block": "minecraft:dark_oak_stairs[facing=south,half=bottom,shape=straight,waterlogged=false]"
      },
      {
        "char": "*",
        "block": "minecraft:gravel"
      },
      {
        "char": "+",
        "block": "minecraft:lectern[facing=south,has_book=false,powered=false]"
      },
      {
        "char": ",",
        "block": "minecraft:polished_andesite"
      },
      {
        "char": "-",
        "block": "minecraft:polished_tuff"
      },
      {
        "char": ".",
        "block": "minecraft:spruce_door[facing=south,half=lower,hinge=left,open=false,powered=false]"
      },
      {
        "char": "/",
        "block": "minecraft:spruce_door[facing=south,half=upper,hinge=left,open=false,powered=false]"
      },
      {
        "char": "0",
        "block": "minecraft:tuff_bricks"
      },
      {
        "char": "1",
        "block": "tfmg:asphalt"
      }
    ]
  }
}
