{
  "xsize": 16,
  "zsize": 16,
  "slices": [
    [
      "2222222222222222",
      "222222222222222)",
      "222222222222222)",
      "222222222222222)",
      "222222222222222)",
      "222222222222222)",
      "222222222222222)",
      "222%%$222222222)",
      "2%%$22222222222)",
      "%$22222222222222",
      "2222222222222222",
      "22222222222222%%",
      "222222222222%%$2",
      "2222222222%%$222",
      "22222222%%$22222",
      "222222%%$2222222"
    ],
    [
      "                ",
      "                ",
      "                ",
      "                ",
      "                ",
      "                ",
      "    ((((((((((((",
      "    ((((((((((((",
      "    ((((((((((((",
      "    ((((((((((((",
      "    ((((((((((((",
      "    ((((((((((((",
      "    ((((((((((((",
      "    ((((((((((((",
      "    ((((((((((((",
      "    (((((((((((("
    ],
    [
      "                ",
      "                ",
      "                ",
      "                ",
      "                ",
      "       ..   ..  ",
      "    ''''''''''''",
      "    '          '",
      "    '          '",
      "    '   &      '",
      "    '          *",
      "    '       1  '",
      "    '          '",
      "    '          '",
      "    '''''''','''",
      "    '           "
    ],
    [
      "                ",
      "                ",
      "                ",
      "                ",
      "                ",
      "                ",
      "    ''0!!0'0!!0'",
      "    '          '",
      "    '          '",
      "    '          '",
      "    !          +",
      "    !          '",
      "    '          '",
      "    '          '",
      "    ''''''''-'''",
      "    '           "
    ],
    [
      "                ",
      "                ",
      "                ",
      "                ",
      "                ",
      "                ",
      "    ''0!!0'0!!0'",
      "    '          '",
      "    '          '",
      "    '          '",
      "    !          '",
      "    !          '",
      "    '          '",
      "    '          '",
      "    ''''''''''''",
      "    '           "
    ],
    [
      "                ",
      "                ",
      "                ",
      "                ",
      "                ",
      "       //   //  ",
      "    ''''''''''''",
      "    '          '",
      "    '          '",
      "    '          '",
      "    '          '",
      "    '          '",
      "    '          '",
      "    '          '",
      "    ''''''''''''",
      "    '           "
    ]
  ],
  "palette": {
    "palette": [
      {
        "char": "!",
        "block": "create:framed_glass"
      },
      {
        "char": "$",
        "block": "minecraft:coarse_dirt"
      },
      {
        "char": "%",
        "block": "minecraft:gravel"
      },
      {
        "char": "&",
        "block": "kubejs:ruined_lectern[facing=south]"
      },
      {
        "char": "'",
        "block": "minecraft:light_gray_concrete"
      },
      {
        "char": "(",
        "block": "minecraft:polished_andesite"
      },
      {
        "char": ")",
        "block": "minecraft:smooth_stone"
      },
      {
        "char": "*",
        "block": "minecraft:spruce_door[facing=east,half=lower,hinge=left,open=false,powered=false]"
      },
      {
        "char": "+",
        "block": "minecraft:spruce_door[facing=east,half=upper,hinge=left,open=false,powered=false]"
      },
      {
        "char": ",",
        "block": "minecraft:spruce_door[facing=south,half=lower,hinge=left,open=false,powered=false]"
      },
      {
        "char": "-",
        "block": "minecraft:spruce_door[facing=south,half=upper,hinge=left,open=false,powered=false]"
      },
      {
        "char": ".",
        "block": "minecraft:spruce_slab[type=bottom,waterlogged=false]"
      },
      {
        "char": "/",
        "block": "minecraft:spruce_slab[type=top,waterlogged=false]"
      },
      {
        "char": "0",
        "block": "minecraft:stripped_spruce_log[axis=y]"
      },
      {
        "char": "1",
        "block": "kubejs:ruined_cauldron"
      },
      {
        "char": "2",
        "block": "tfmg:asphalt"
      }
    ]
  }
}
