{
  "xsize": 16,
  "zsize": 16,
  "slices": [
    [
      "                ",
      "                ",
      "                ",
      "                ",
      "             !!!",
      "    $       $!  ",
      "             !  ",
      "     ''''''''!  ",
      "     '       !  ",
      "     '       !!!",
      "     '          ",
      "     '          ",
      "     '          ",
      "     '          ",
      "     '          ",
      "     '          "
    ],
    [
      "                ",
      "                ",
      "                ",
      "                ",
      "             %%%",
      "    $       $%%%",
      "             %%%",
      "     ''''''''%%%",
      "     '       %%%",
      "     '       %%%",
      "     '          ",
      "     '          ",
      "     '          ",
      "     '          ",
      "     '          ",
      "     '          "
    ],
    [
      "                ",
      "                ",
      "                ",
      "                ",
      "    &&&&&&&&&&&&",
      "    &&&&&&&&&&&&",
      "    &&&&&&&&&&&&",
      "    &&&&&&&&&&&&",
      "    &&&&&&&&&&&&",
      "    &&&&&&&&&&&&",
      "     '          ",
      "     '          ",
      "     '          ",
      "     '          ",
      "     '          ",
      "     '          "
    ],
    [
      "                ",
      "                ",
      "                ",
      "                ",
      "                ",
      "                ",
      "                ",
      "     '''''''''''",
      "     '          ",
      "     '          ",
      "     '          ",
      "     '          ",
      "     '          ",
      "     '          ",
      "     '          ",
      "     '          "
    ],
    [
      "                ",
      "                ",
      "                ",
      "                ",
      "                ",
      "                ",
      "                ",
      "     '''''''''''",
      "     '          ",
      "     '          ",
      "     '          ",
      "     '          ",
      "     '          ",
      "     '          ",
      "     '          ",
      "     '          "
    ],
    [
      "                ",
      "                ",
      "                ",
      "                ",
      "                ",
      "                ",
      "                ",
      "     '''''''''''",
      "     '          ",
      "     '          ",
      "     '          ",
      "     '          ",
      "     '          ",
      "     '          ",
      "     '          ",
      "     '          "
    ]
  ],
  "palette": {
    "palette": [
      {
        "char": "!",
        "block": "minecraft:stripped_spruce_log"
      },
      {
        "char": "$",
        "block": "minecraft:stripped_spruce_log[axis=y]"
      },
      {
        "char": "%",
        "block": "minecraft:weathered_cut_copper_slab"
      },
      {
        "char": "&",
        "block": "minecraft:weathered_cut_copper_slab[type=bottom,waterlogged=false]"
      },
      {
        "char": "'",
        "block": "the_wasteland_reworked:decayed_planks"
      }
    ]
  }
}
