{
  "xsize": 16,
  "zsize": 16,
  "slices": [
    [
      "9999999999999999",
      "2222222222222229",
      "2222222222222229",
      "2222222222222229",
      "2222222222222229",
      "2222222222222229",
      "2222222222222229",
      "2222222222222229",
      "2222222222222229",
      "99**$99999999999",
      "**$9999999999999",
      "$999999999999999",
      "999999999999999*",
      "9999999999999**$",
      "99999999999**$99",
      "999999999**$9999"
    ],
    [
      "                ",
      "1            1  ",
      "                ",
      "                ",
      "                ",
      "                ",
      "0000000000000000",
      "0000000000000000",
      "0000000000000000",
      "0000000000000000",
      "0000000000000000",
      "0000000000000000",
      "0000000000000000",
      "0000000000000000",
      "0000000000000000",
      "0000000000000000"
    ],
    [
      "                ",
      "1            1  ",
      "                ",
      "                ",
      "                ",
      " 55        55   ",
      "/////%&/////////",
      "             /  ",
      "  )   )   )  /  ",
      "             /  ",
      "             3  ",
      "   55    55  /  ",
      "   7     7   /  ",
      "             /  ",
      "/////+,/////////",
      "                "
    ],
    [
      "                ",
      "1            1  ",
      "                ",
      "                ",
      "                ",
      "                ",
      "8!!8/'(///8!!8/8",
      "             /  ",
      "             /  ",
      "             /  ",
      "             4  ",
      "             /  ",
      "             /  ",
      "             /  ",
      "/////-./////////",
      "                "
    ],
    [
      "                ",
      "1            1  ",
      "                ",
      "                ",
      "                ",
      "                ",
      "8!!8//////8!!8/8",
      "             /  ",
      "             /  ",
      "             /  ",
      "             /  ",
      "             /  ",
      "             /  ",
      "             /  ",
      "////////////////",
      "                "
    ],
    [
      "                ",
      "1            1  ",
      "                ",
      "                ",
      "                ",
      " 66        66   ",
      "////////////////",
      "             /  ",
      "             /  ",
      "             /  ",
      "             /  ",
      "             /  ",
      "             /  ",
      "             /  ",
      "////////////////",
      "                "
    ]
  ],
  "palette": {
    "palette": [
      {
        "char": "!",
        "block": "create:framed_glass"
      },
      {
        "char": "$",
        "block": "minecraft:coarse_dirt"
      },
      {
        "char": "%",
        "block": "minecraft:dark_oak_door[facing=north,half=lower,hinge=left,open=false,powered=false]"
      },
      {
        "char": "&",
        "block": "minecraft:dark_oak_door[facing=north,half=lower,hinge=right,open=false,powered=false]"
      },
      {
        "char": "'",
        "block": "minecraft:dark_oak_door[facing=north,half=upper,hinge=left,open=false,powered=false]"
      },
      {
        "char": "(",
        "block": "minecraft:dark_oak_door[facing=north,half=upper,hinge=right,open=false,powered=false]"
      },
      {
        "char": ")",
        "block": "minecraft:dark_oak_stairs[facing=south,half=bottom,shape=straight,waterlogged=false]"
      },
      {
        "char": "*",
        "block": "minecraft:gravel"
      },
      {
        "char": "+",
        "block": "minecraft:iron_door[facing=south,half=lower,hinge=left,open=false,powered=false]"
      },
      {
        "char": ",",
        "block": "minecraft:iron_door[facing=south,half=lower,hinge=right,open=false,powered=false]"
      },
      {
        "char": "-",
        "block": "minecraft:iron_door[facing=south,half=upper,hinge=left,open=false,powered=false]"
      },
      {
        "char": ".",
        "block": "minecraft:iron_door[facing=south,half=upper,hinge=right,open=false,powered=false]"
      },
      {
        "char": "/",
        "block": "minecraft:light_gray_concrete"
      },
      {
        "char": "0",
        "block": "minecraft:polished_andesite"
      },
      {
        "char": "1",
        "block": "minecraft:polished_blackstone_bricks"
      },
      {
        "char": "2",
        "block": "minecraft:smooth_stone"
      },
      {
        "char": "3",
        "block": "minecraft:spruce_door[facing=east,half=lower,hinge=left,open=false,powered=false]"
      },
      {
        "char": "4",
        "block": "minecraft:spruce_door[facing=east,half=upper,hinge=left,open=false,powered=false]"
      },
      {
        "char": "5",
        "block": "minecraft:spruce_slab[type=bottom,waterlogged=false]"
      },
      {
        "char": "6",
        "block": "minecraft:spruce_slab[type=top,waterlogged=false]"
      },
      {
        "char": "7",
        "block": "minecraft:spruce_stairs[facing=north,half=bottom,shape=straight,waterlogged=false]"
      },
      {
        "char": "8",
        "block": "minecraft:stripped_spruce_log[axis=y]"
      },
      {
        "char": "9",
        "block": "tfmg:asphalt"
      }
    ]
  }
}
