{
  "xsize": 16,
  "zsize": 16,
  "slices": [
    [
      "2222222222222222",
      "2222222222222222",
      "**********222222",
      "**********222222",
      "**********222222",
      "**********222222",
      "**********222222",
      "**********222222",
      "**********222222",
      "**********222222",
      "222&&$2222222222",
      "2&&$222222222222",
      "&$22222222222222",
      "2222222222222222",
      "22222222222222&&",
      "222222222222&&$2"
    ],
    [
      "                ",
      "                ",
      "                ",
      "                ",
      "   )   )        ",
      "                ",
      "*********       ",
      "********        ",
      "''''''''''''''''",
      "''''''''''''''''",
      "''''''''''''''''",
      "''''''''''''''''",
      "''''''''''''''''",
      "''''''''''''''''",
      "''''''''''''''''",
      "''''''''''''''''"
    ],
    [
      "                ",
      "                ",
      "                ",
      "                ",
      "***)***)***     ",
      "**********      ",
      "                ",
      "           --  -",
      "1111111111111111",
      "        (       ",
      "        (       ",
      "-       ( --   -",
      "        ( /    /",
      "        (       ",
      "        +       ",
      "  %     (       "
    ],
    [
      "                ",
      "                ",
      "                ",
      "                ",
      "   )   )        ",
      "                ",
      "                ",
      "                ",
      "11111111110!!00!",
      "        (       ",
      "        (       ",
      "        (       ",
      "        (       ",
      "        (       ",
      "        ,       ",
      "        (       "
    ],
    [
      "                ",
      "                ",
      "                ",
      "                ",
      "   )   )        ",
      "                ",
      "                ",
      "                ",
      "11111111110!!00!",
      "        (       ",
      "        (       ",
      "        (       ",
      "        (       ",
      "        (       ",
      "        (       ",
      "        (       "
    ],
    [
      "                ",
      "                ",
      "                ",
      "                ",
      "   )   )        ",
      "                ",
      "                ",
      "           ..  .",
      "1111111111111111",
      "        (       ",
      "        (       ",
      "        (       ",
      "        (       ",
      "        (       ",
      "        (       ",
      "        (       "
    ]
  ],
  "palette": {
    "palette": [
      {
        "char": "!",
        "block": "create:framed_glass"
      },
      {
        "char": "$",
        "block": "minecraft:coarse_dirt"
      },
      {
        "char": "%",
        "block": "minecraft:dark_oak_stairs[facing=north,half=bottom,shape=straight,waterlogged=false]"
      },
      {
        "char": "&",
        "block": "minecraft:gravel"
      },
      {
        "char": "'",
        "block": "minecraft:polished_andesite"
      },
      {
        "char": "(",
        "block": "minecraft:polished_tuff"
      },
      {
        "char": ")",
        "block": "minecraft:quartz_pillar[axis=y]"
      },
      {
        "char": "*",
        "block": "minecraft:smooth_stone"
      },
      {
        "char": "+",
        "block": "minecraft:spruce_door[facing=east,half=lower,hinge=left,open=false,powered=false]"
      },
      {
        "char": ",",
        "block": "minecraft:spruce_door[facing=east,half=upper,hinge=left,open=false,powered=false]"
      },
      {
        "char": "-",
        "block": "minecraft:spruce_slab[type=bottom,waterlogged=false]"
      },
      {
        "char": ".",
        "block": "minecraft:spruce_slab[type=top,waterlogged=false]"
      },
      {
        "char": "/",
        "block": "minecraft:spruce_stairs[facing=north,half=bottom,shape=straight,waterlogged=false]"
      },
      {
        "char": "0",
        "block": "minecraft:stripped_spruce_log[axis=y]"
      },
      {
        "char": "1",
        "block": "minecraft:tuff_bricks"
      },
      {
        "char": "2",
        "block": "tfmg:asphalt"
      }
    ]
  }
}
