{
  "xsize": 16,
  "zsize": 16,
  "slices": [
    [
      "6666666666666&&%",
      "66666666666&&%66",
      "666666666&&%6666",
      "6666666&&%666666",
      "66666&&%66666666",
      "666&&%6666666666",
      "6&&%666666666666",
      "&%66666666666666",
      "6666666666666666",
      "66666666666666&&",
      "666666666666&&%6",
      "6666666666&&%666",
      "66666666&&%66666",
      "666666&&%6666666",
      "6666&&%666666666",
      "66&&%66666666666"
    ],
    [
      "11//////////0666",
      "11//////////0666",
      "11//////////0666",
      "11//////////0666",
      "11//////////0666",
      "11//////////0666",
      "11//////////0666",
      "11//////////0666",
      "11//////////0666",
      "11//////////0666",
      "11//////////0666",
      "////////////0000",
      "                ",
      "                ",
      "                ",
      "                "
    ],
    [
      "  00000002000   ",
      "  ' !       0   ",
      "  0 !       '   ",
      "  0000000200(   ",
      "  '         0   ",
      "  0 44      0   ",
      "  00500002000   ",
      "  0         0   ",
      "  '       $ 0   ",
      "  0       $ 0   ",
      "  0         0   ",
      "0000+,0000000000",
      "                ",
      "                ",
      "                ",
      "                "
    ],
    [
      "  00000003000   ",
      "  ) !       0   ",
      "  0 !       )   ",
      "  0000000300*   ",
      "  )         0   ",
      "  0         0   ",
      "  00000003000   ",
      "  0         0   ",
      "  )       $ 0   ",
      "  0       $ 0   ",
      "  0         0   ",
      "0000-.0000000000",
      "                ",
      "                ",
      "                ",
      "                "
    ],
    [
      "  00000000000   ",
      "  0 !       0   ",
      "  0 !           ",
      "  0000000000    ",
      "  0         0   ",
      "  0         0   ",
      "  00000000000   ",
      "  0         0   ",
      "  0       $ 0   ",
      "  0       $ 0   ",
      "  0         0   ",
      "0000000000000000",
      "                ",
      "                ",
      "                ",
      "                "
    ],
    [
      "  00000000000   ",
      "  0         0   ",
      "  0             ",
      "  0000000000    ",
      "  0         0   ",
      "  0         0   ",
      "  00000000000   ",
      "  0         0   ",
      "  0         0   ",
      "  0         0   ",
      "  0         0   ",
      "0000000000000   ",
      "                ",
      "                ",
      "                ",
      "                "
    ]
  ],
  "palette": {
    "palette": [
      {
        "char": "!",
        "block": "immersiveengineering:crate"
      },
      {
        "char": "$",
        "block": "minecraft:bookshelf"
      },
      {
        "char": "%",
        "block": "minecraft:coarse_dirt"
      },
      {
        "char": "&",
        "block": "minecraft:gravel"
      },
      {
        "char": "'",
        "block": "minecraft:iron_door[facing=east,half=lower,hinge=left,open=false,powered=false]"
      },
      {
        "char": "(",
        "block": "minecraft:iron_door[facing=east,half=lower,hinge=right,open=false,powered=false]"
      },
      {
        "char": ")",
        "block": "minecraft:iron_door[facing=east,half=upper,hinge=left,open=false,powered=false]"
      },
      {
        "char": "*",
        "block": "minecraft:iron_door[facing=east,half=upper,hinge=right,open=false,powered=false]"
      },
      {
        "char": "+",
        "block": "minecraft:iron_door[facing=south,half=lower,hinge=left,open=false,powered=false]"
      },
      {
        "char": ",",
        "block": "minecraft:iron_door[facing=south,half=lower,hinge=right,open=false,powered=false]"
      },
      {
        "char": "-",
        "block": "minecraft:iron_door[facing=south,half=upper,hinge=left,open=false,powered=false]"
      },
      {
        "char": ".",
        "block": "minecraft:iron_door[facing=south,half=upper,hinge=right,open=false,powered=false]"
      },
      {
        "char": "/",
        "block": "minecraft:polished_andesite"
      },
      {
        "char": "0",
        "block": "minecraft:polished_deepslate"
      },
      {
        "char": "1",
        "block": "minecraft:smooth_stone"
      },
      {
        "char": "2",
        "block": "minecraft:spruce_door[facing=south,half=lower,hinge=left,open=false,powered=false]"
      },
      {
        "char": "3",
        "block": "minecraft:spruce_door[facing=south,half=upper,hinge=left,open=false,powered=false]"
      },
      {
        "char": "4",
        "block": "minecraft:spruce_slab[type=bottom,waterlogged=false]"
      },
      {
        "char": "5",
        "block": "minecraft:spruce_stairs[facing=north,half=bottom,shape=straight,waterlogged=false]"
      },
      {
        "char": "6",
        "block": "tfmg:asphalt"
      }
    ]
  }
}
