{
  "xsize": 16,
  "zsize": 16,
  "slices": [
    [
      ",,,,,,,''%,,,,,,",
      ",,,,,''%,,,,,,,,",
      ",,,''%,,,,,,,,,,",
      ",''%,,,,,,,,,,,,",
      "'%,,,,,,,,,,,,,,",
      ",,,,,,,,,,,,,,,,",
      ",,,,,,,,,,,,,,''",
      ",,,,,,,,,,,,''%,",
      ",,,,,,,,,,''%,,,",
      ",,,,,,,,''%,,,,,",
      ",,,,,,''%,,,,,,,",
      ",,,,''%,,,,,,,,,",
      ",,''%,,,,,,,,,,,",
      "''%,,,,,,,,,,,,,",
      "%,,,,,,,,,,,,,,,",
      ",,,,,,,,,,,,,,,'"
    ],
    [
      "......((((((((((",
      "......((((((((((",
      "......((((((((((",
      "......((((((((((",
      "......((((((((((",
      "......((((((((((",
      "......((((((((((",
      "......((((((((((",
      "......((((((((((",
      "......((((((((((",
      "......((((((((((",
      "......((((((((((",
      "......((((((((((",
      "......((((((((((",
      "......((((((((((",
      "......(((((((((("
    ],
    [
      ")-----$         ",
      "      $         ",
      "      $         ",
      " !    $         ",
      " !    $  &   &  ",
      " !    $         ",
      " !    $         ",
      " !    $         ",
      " !    $  &   &  ",
      "      $         ",
      "      $         ",
      "      $         ",
      ")-----$  &   &  ",
      "++++  $         ",
      "++++  $         ",
      "++++  $         "
    ],
    [
      "*-----$         ",
      "      $         ",
      "      $         ",
      " !    $         ",
      " !    $         ",
      " !    $         ",
      " !    $         ",
      " !    $         ",
      " !    $         ",
      "      $         ",
      "      $         ",
      "      $         ",
      "*-----$         ",
      "      $         ",
      "      $         ",
      "      $         "
    ],
    [
      "------$         ",
      "      $         ",
      "      $         ",
      " !    $         ",
      " !    $         ",
      " !    $         ",
      " !    $         ",
      " !    $         ",
      " !    $         ",
      "      $         ",
      "      $         ",
      "      $         ",
      "------$         ",
      "      $         ",
      "      $         ",
      "      $         "
    ],
    [
      "------$         ",
      "      $         ",
      "      $         ",
      "      $         ",
      "      $         ",
      "      $         ",
      "      $         ",
      "      $         ",
      "      $         ",
      "      $         ",
      "      $         ",
      "      $         ",
      "------$         ",
      "      $         ",
      "      $         ",
      "      $         "
    ]
  ],
  "palette": {
    "palette": [
      {
        "char": "!",
        "block": "minecraft:bookshelf"
      },
      {
        "char": "$",
        "block": "minecraft:bricks"
      },
      {
        "char": "%",
        "block": "minecraft:coarse_dirt"
      },
      {
        "char": "&",
        "block": "minecraft:dark_oak_stairs[facing=south,half=bottom,shape=straight,waterlogged=false]"
      },
      {
        "char": "'",
        "block": "minecraft:gravel"
      },
      {
        "char": "(",
        "block": "minecraft:smooth_stone"
      },
      {
        "char": ")",
        "block": "minecraft:spruce_door[facing=south,half=lower,hinge=left,open=false,powered=false]"
      },
      {
        "char": "*",
        "block": "minecraft:spruce_door[facing=south,half=upper,hinge=left,open=false,powered=false]"
      },
      {
        "char": "+",
        "block": "minecraft:yellow_wool"
      },
      {
        "char": ",",
        "block": "tfmg:asphalt"
      },
      {
        "char": "-",
        "block": "tfmg:cinder_block"
      },
      {
        "char": ".",
        "block": "tfmg:factory_floor"
      }
    ]
  }
}
