{
  "xsize": 16,
  "zsize": 16,
  "slices": [
    [
      "                ",
      "                ",
      "                ",
      "                ",
      "11    11        ",
      "****************",
      "   4       2   2",
      "   4       2   2",
      "   4       2   2",
      "   4       2   2",
      "   4       2 , 2",
      "   4       2   2",
      "   4       2   2",
      "   4       2   2",
      "4444       2   2",
      "   4       2   2"
    ],
    [
      "                ",
      "                ",
      "                ",
      "                ",
      "                ",
      "****************",
      "           2   2",
      "           2   2",
      "           2   2",
      "           2   2",
      "           2   2",
      "           2 , 2",
      "           2   2",
      "           2   2",
      "           2   2",
      "           2   2"
    ],
    [
      "                ",
      "                ",
      "                ",
      "                ",
      "                ",
      "****************",
      "                ",
      "                ",
      "                ",
      "                ",
      "                ",
      "                ",
      "             ,  ",
      "                ",
      "                ",
      "                "
    ],
    [
      "                ",
      "                ",
      "                ",
      "                ",
      "----------------",
      "----------------",
      "++++++++++++++++",
      "++++++++++++++++",
      "++++++++++++++++",
      "++++++++++++++++",
      "++++++++++++++++",
      "+++++++++++++ ++",
      "+++++++++++++ ++",
      "++++++++++++++++",
      "++++++++++++++++",
      "++++++++++++++++"
    ],
    [
      "                ",
      "                ",
      "                ",
      "                ",
      "00    00        ",
      "****************",
      "   4       2   2",
      "   4       2 , 2",
      "   4 $     2   2",
      "   4 %     2   2",
      "   4       2   2",
      "   4       2   2",
      "   .       2   2",
      "   4       2   2",
      "4444       &   (",
      "   4       2   2"
    ],
    [
      "                ",
      "                ",
      "                ",
      "                ",
      "                ",
      "!!3**3!!3*******",
      "   4       2   2",
      "   4       2   2",
      "   4       2 , 2",
      "   4       2   2",
      "   4       2   2",
      "   4       2   2",
      "   /       2   2",
      "   4       2   2",
      "4444       '   )",
      "   4       2   2"
    ]
  ],
  "palette": {
    "palette": [
      {
        "char": "!",
        "block": "create:framed_glass"
      },
      {
        "char": "$",
        "block": "minecraft:brown_bed[facing=south,occupied=false,part=foot]"
      },
      {
        "char": "%",
        "block": "minecraft:brown_bed[facing=south,occupied=false,part=head]"
      },
      {
        "char": "&",
        "block": "minecraft:dark_oak_door[facing=east,half=lower,hinge=left,open=false,powered=false]"
      },
      {
        "char": "'",
        "block": "minecraft:dark_oak_door[facing=east,half=upper,hinge=left,open=false,powered=false]"
      },
      {
        "char": "(",
        "block": "minecraft:dark_oak_door[facing=west,half=lower,hinge=left,open=false,powered=false]"
      },
      {
        "char": ")",
        "block": "minecraft:dark_oak_door[facing=west,half=upper,hinge=left,open=false,powered=false]"
      },
      {
        "char": "*",
        "block": "minecraft:mud_bricks"
      },
      {
        "char": "+",
        "block": "minecraft:oak_planks"
      },
      {
        "char": ",",
        "block": "minecraft:oak_stairs[facing=south,half=bottom,shape=straight,waterlogged=false]"
      },
      {
        "char": "-",
        "block": "minecraft:smooth_stone_slab[type=top,waterlogged=false]"
      },
      {
        "char": ".",
        "block": "minecraft:spruce_door[facing=east,half=lower,hinge=left,open=false,powered=false]"
      },
      {
        "char": "/",
        "block": "minecraft:spruce_door[facing=east,half=upper,hinge=left,open=false,powered=false]"
      },
      {
        "char": "0",
        "block": "minecraft:spruce_slab[type=bottom,waterlogged=false]"
      },
      {
        "char": "1",
        "block": "minecraft:spruce_slab[type=top,waterlogged=false]"
      },
      {
        "char": "2",
        "block": "minecraft:stripped_oak_wood"
      },
      {
        "char": "3",
        "block": "minecraft:stripped_spruce_log[axis=y]"
      },
      {
        "char": "4",
        "block": "minecraft:stripped_spruce_wood"
      }
    ]
  }
}
