{
  "xsize": 16,
  "zsize": 16,
  "slices": [
    [
      "****************",
      "**************''",
      "************''%*",
      "**********''%***",
      "********''%*****",
      "******''%*******",
      "****''%*********",
      "**''%***********",
      "''%*************",
      "%***************",
      "***************'",
      "*************''%",
      "***********''%**",
      "%****%***'%%***%",
      "                ",
      "                "
    ],
    [
      "))))))))))))))) ",
      "))))))))))))))) ",
      "))))))))))))))) ",
      "))))))))))))))) ",
      "))))))))))))))) ",
      "))))))))))))))) ",
      "))))))))))))))) ",
      "))))))))))))))) ",
      "))))))))))))))) ",
      "))))))))))))))) ",
      "                ",
      "                ",
      "                ",
      "                ",
      "                ",
      "                "
    ],
    [
      "              $ ",
      "              $ ",
      "&&&&&&&&&&&&& $ ",
      "&&&&&&&&&&&&& $ ",
      "&&&&&&&&&&&&& $ ",
      "&&&&&&&&&&&&& $ ",
      "&&&&&&&&&&&&( $ ",
      "&&&&&&&&&&&&& $ ",
      "&&&&&&&&&&&&& $ ",
      "$$$$$$$$$$$$$$$ ",
      "                ",
      "                ",
      "                ",
      "                ",
      "                ",
      "                "
    ],
    [
      "              $ ",
      "              $ ",
      "&&&&&&&&&&&&& $ ",
      "&&&&&&&&&&&&& $ ",
      "&&&&&&&&&&&&& $ ",
      "&&&&&&&&&&&&& $ ",
      "&&&&&&&&&&&&( $ ",
      "&&&&&&&&&&&&& $ ",
      "&&&&&&&&&&&&& $ ",
      "$$$$$$$$$$$$$$$ ",
      "                ",
      "                ",
      "                ",
      "                ",
      "                ",
      "                "
    ],
    [
      "              $ ",
      "              $ ",
      "&&&&&&&&&&&&& $ ",
      "&&&&&&&&&&&&& $ ",
      "&&&&&&&&&&&&& $ ",
      "&&&&&&&&&&&&& $ ",
      "&&&&&&&&&&&&( $ ",
      "&&&&&&&&&&&&& $ ",
      "&&&&&&&&&&&&& $ ",
      "$$$$$$$$$$$$$$$ ",
      "                ",
      "                ",
      "                ",
      "                ",
      "                ",
      "                "
    ],
    [
      "              $ ",
      "              $ ",
      "              ! ",
      "              ! ",
      "              $ ",
      "              $ ",
      "            ( $ ",
      "              $ ",
      "              $ ",
      "$$$$$$$$$$$$$$$ ",
      "                ",
      "                ",
      "                ",
      "                ",
      "                ",
      "                "
    ]
  ],
  "palette": {
    "palette": [
      {
        "char": "!",
        "block": "create:framed_glass"
      },
      {
        "char": "$",
        "block": "minecraft:bricks"
      },
      {
        "char": "%",
        "block": "minecraft:coarse_dirt"
      },
      {
        "char": "&",
        "block": "minecraft:dark_oak_planks"
      },
      {
        "char": "'",
        "block": "minecraft:gravel"
      },
      {
        "char": "(",
        "block": "minecraft:ladder[facing=west,waterlogged=false]"
      },
      {
        "char": ")",
        "block": "minecraft:smooth_stone"
      },
      {
        "char": "*",
        "block": "tfmg:asphalt"
      }
    ]
  }
}
