{
  "xsize": 16,
  "zsize": 16,
  "slices": [
    [
      "0000))))))))))))",
      "00&&))))))))))))",
      "&&%0))))))))))))",
      "%000))))))))))))",
      "0000))))))))))))",
      "0000))))))))))))",
      "0000))))))))))))",
      "0000))))))))))))",
      "0000))))))))))))",
      "0000))))))))))))",
      "000&))))))))))))",
      "0&&%))))))))))))",
      "&%00))))))))))))",
      "0000))))))))))))",
      "0000))))))))))))",
      "0000))))))))))))"
    ],
    [
      "     (((((((((((",
      "     (((((((((((",
      "     (((((((((((",
      "     (((((((((((",
      "     (((((((((((",
      "     (((((((((((",
      "     (((((((((((",
      "     (((((((((((",
      "     (((((((((((",
      "     (((((((((((",
      "     (((((((((((",
      "     (((((((((((",
      "     (((((((((((",
      "     (((((((((((",
      "     (((((((((((",
      "     ((((((((((("
    ],
    [
      "     '          ",
      "     '''''''*'''",
      "     '          ",
      "     '          ",
      "     '  - $  - $",
      "     '  .    .  ",
      "     '          ",
      "     '          ",
      "     '  - $  - $",
      "     '  .    .  ",
      "     '          ",
      "     /////////  ",
      "     /       /  ",
      "     /       /  ",
      "     /       /  ",
      "     /  - ,  /  "
    ],
    [
      "     '          ",
      "     '''''''+'''",
      "     '          ",
      "     '          ",
      "     !          ",
      "     !          ",
      "     '          ",
      "     '          ",
      "     '          ",
      "     '          ",
      "     '          ",
      "     /////////  ",
      "     /       /  ",
      "     /       /  ",
      "     /       /  ",
      "     !       /  "
    ],
    [
      "     '          ",
      "     '''''''''''",
      "     '          ",
      "     '          ",
      "     !          ",
      "     !          ",
      "     '          ",
      "     '          ",
      "     '          ",
      "     '          ",
      "     '          ",
      "     /////////  ",
      "     /       /  ",
      "     /       /  ",
      "     /       /  ",
      "     !       /  "
    ],
    [
      "     '          ",
      "     '''''''''''",
      "     '          ",
      "     '          ",
      "     '          ",
      "     '          ",
      "     '          ",
      "     '          ",
      "     '          ",
      "     '          ",
      "     '          ",
      "     /////////  ",
      "     /       /  ",
      "     /       /  ",
      "     /       /  ",
      "     /       /  "
    ]
  ],
  "palette": {
    "palette": [
      {
        "char": "!",
        "block": "create:framed_glass"
      },
      {
        "char": "$",
        "block": "minecraft:brewing_stand"
      },
      {
        "char": "%",
        "block": "minecraft:coarse_dirt"
      },
      {
        "char": "&",
        "block": "minecraft:gravel"
      },
      {
        "char": "'",
        "block": "minecraft:light_gray_concrete"
      },
      {
        "char": "(",
        "block": "minecraft:polished_andesite"
      },
      {
        "char": ")",
        "block": "minecraft:smooth_stone"
      },
      {
        "char": "*",
        "block": "minecraft:spruce_door[facing=south,half=lower,hinge=left,open=false,powered=false]"
      },
      {
        "char": "+",
        "block": "minecraft:spruce_door[facing=south,half=upper,hinge=left,open=false,powered=false]"
      },
      {
        "char": ",",
        "block": "minecraft:water_cauldron[level=3]"
      },
      {
        "char": "-",
        "block": "minecraft:white_bed[facing=south,occupied=false,part=foot]"
      },
      {
        "char": ".",
        "block": "minecraft:white_bed[facing=south,occupied=false,part=head]"
      },
      {
        "char": "/",
        "block": "minecraft:white_concrete"
      },
      {
        "char": "0",
        "block": "tfmg:asphalt"
      }
    ]
  }
}
