{
  "xsize": 16,
  "zsize": 16,
  "slices": [
    [
      "       %%%%%%%!$",
      "       %%%%%%%!!",
      "       %%%%%%%%%",
      "       %%%%%%%%%",
      "       %%%%%%%%%",
      "       %%%%%%%%%",
      "       %%%%%%%%%",
      "       %%%%%%%%%",
      "       %%%%%%%%%",
      "       %%%%%%%%%",
      "       %%%%%%%%%",
      "       %%%%%%%%%",
      "                ",
      "                ",
      "                ",
      "                "
    ]
  ],
  "palette": {
    "palette": [
      {
        "char": "!",
        "block": "minecraft:polished_blackstone_bricks"
      },
      {
        "char": "$",
        "block": "minecraft:redstone_lamp[lit=false]"
      },
      {
        "char": "%",
        "block": "minecraft:smooth_stone"
      }
    ]
  }
}
