{
  "xsize": 16,
  "zsize": 16,
  "slices": [
    [
      "2222222''$222222",
      "22222''$22222222",
      "222''$2222222222",
      "2''$222222222222",
      "'$22222222222222",
      "2222222222222222",
      "22222222222222''",
      "222222222222''$2",
      "2222222222''$222",
      "22222222''$22222",
      "222222''$2222222",
      "2222''$222222222",
      "22''$22222222222",
      "''$2222222222222",
      "$222222222222222",
      "222222222222222'"
    ],
    [
      ",,,,,,,,,,,,,,,,",
      ",,,,,,,,,,,,,,,,",
      ",,,,,,,,,,,,,,,,",
      ",,,,,,,,,,,,,,,,",
      ",,,,,,,,,,,,,,,,",
      ",,,,,,,,,,,,,,,,",
      ",,,,333333333333",
      ",,,,333333333333",
      ",,,,333333333333",
      ",,,,333333333333",
      ",,,,333333333333",
      ",,,,333333333333",
      ",,,,333333333333",
      ",,,,333333333333",
      ",,,,333333333333",
      ",,,,333333333333"
    ],
    [
      "                ",
      "                ",
      "                ",
      "                ",
      "                ",
      "         )    ) ",
      "    ((((((((((((",
      "    (           ",
      "++.+++++++++.+++",
      "       )  +     ",
      "          +     ",
      "          +     ",
      "          +     ",
      "  0  !   %&  0  ",
      "  1       +  1  ",
      "          +     "
    ],
    [
      "                ",
      "                ",
      "                ",
      "                ",
      "                ",
      "                ",
      "    ((((((((((((",
      "    (           ",
      "++/+++++++++/+++",
      "          +     ",
      "       )  +     ",
      "          +     ",
      "          +     ",
      "          -     ",
      "          +     ",
      "          +     "
    ],
    [
      "                ",
      "                ",
      "                ",
      "                ",
      "                ",
      "                ",
      "    ((((((((((((",
      "    (           ",
      "++++++++++++++++",
      "          +     ",
      "          +     ",
      "       )  +     ",
      "          +     ",
      "          +     ",
      "          +     ",
      "          +     "
    ],
    [
      "                ",
      "                ",
      "                ",
      "                ",
      "                ",
      "                ",
      "    ((((((((((((",
      "    (           ",
      "++++++++++++++++",
      "          +     ",
      "          +     ",
      "         ****** ",
      "       ) ****** ",
      "         ****** ",
      "         ****** ",
      "         ****** "
    ]
  ],
  "palette": {
    "palette": [
      {
        "char": "!",
        "block": "kubejs:ruined_brewing_stand"
      },
      {
        "char": "$",
        "block": "minecraft:coarse_dirt"
      },
      {
        "char": "%",
        "block": "minecraft:cyan_bed[facing=east,occupied=false,part=foot]"
      },
      {
        "char": "&",
        "block": "minecraft:cyan_bed[facing=east,occupied=false,part=head]"
      },
      {
        "char": "'",
        "block": "minecraft:gravel"
      },
      {
        "char": "(",
        "block": "minecraft:light_gray_concrete"
      },
      {
        "char": ")",
        "block": "minecraft:quartz_stairs[facing=south,half=bottom,shape=straight,waterlogged=false]"
      },
      {
        "char": "*",
        "block": "minecraft:sea_lantern"
      },
      {
        "char": "+",
        "block": "minecraft:smooth_quartz"
      },
      {
        "char": ",",
        "block": "minecraft:smooth_stone"
      },
      {
        "char": "-",
        "block": "minecraft:spruce_door[facing=east,half=upper,hinge=left,open=false,powered=false]"
      },
      {
        "char": ".",
        "block": "minecraft:spruce_door[facing=south,half=lower,hinge=left,open=false,powered=false]"
      },
      {
        "char": "/",
        "block": "minecraft:spruce_door[facing=south,half=upper,hinge=left,open=false,powered=false]"
      },
      {
        "char": "0",
        "block": "minecraft:white_bed[facing=south,occupied=false,part=foot]"
      },
      {
        "char": "1",
        "block": "minecraft:white_bed[facing=south,occupied=false,part=head]"
      },
      {
        "char": "2",
        "block": "tfmg:asphalt"
      },
      {
        "char": "3",
        "block": "tfmg:factory_floor"
      }
    ]
  }
}
