{
  "xsize": 16,
  "zsize": 16,
  "slices": [
    [
      "++++++++++&&$+++",
      "++++++++&&$+++++",
      "++++++&&$+++++++",
      "++++&&$+++++++++",
      "++&&$+++++++++++",
      "&&$+++++++++++++",
      "$+++++++++++++++",
      "+++++++++++++++&",
      "+++++++++++++&&$",
      "+++++++++++&&$++",
      "+++++++++&&$++++",
      "+++++++&&$++++++",
      "+++++&&$++++++++",
      "+++&&$++++++++++",
      "+&&$++++++++++++",
      "&$++++++++++++++"
    ],
    [
      "''''''''''''''''",
      "''''''''''''''''",
      "''''''''''''''''",
      "''''''''''''''''",
      "''''''''''''''''",
      "''''''''''''''''",
      "''''''''''''''''",
      "''''''''''''''''",
      "''''''''''''''''",
      "''''''''''''''''",
      "''''''''''''''''",
      "''''''''''''''''",
      "''''''''''''''''",
      "''''''''''''''''",
      "''''''''''''''''",
      "''''''''''''''''"
    ],
    [
      "   )  )      )  ",
      "   )  )      )  ",
      "   )  )      )  ",
      "   )  )      )  ",
      "   )  )      )  ",
      "   )  )      )  ",
      "   !         %  ",
      "  ,,,,,,,   ,,,,",
      "                ",
      "                ",
      "                ",
      "                ",
      "                ",
      "                ",
      "                ",
      "   *            "
    ],
    [
      "   )  )      )  ",
      "   )  )      )  ",
      "   )  )      )  ",
      "   )  )      )  ",
      "   )  )      )  ",
      "   )  )      )  ",
      "                ",
      "  ,,,,,,,   ,,,,",
      "                ",
      "                ",
      "                ",
      "                ",
      "                ",
      "                ",
      "                ",
      "                "
    ],
    [
      "   )  )      )  ",
      "   )  )      )  ",
      "   )  )      )  ",
      "   )  )      )  ",
      "   )  )      )  ",
      "   )  )      )  ",
      "                ",
      "  ,,,,,,,   ,,,,",
      "                ",
      "                ",
      "                ",
      "                ",
      "                ",
      "                ",
      "                ",
      "              ( "
    ],
    [
      "                ",
      "                ",
      "                ",
      "                ",
      "                ",
      "                ",
      "                ",
      "                ",
      "                ",
      "                ",
      "                ",
      "                ",
      "                ",
      "                ",
      "              ( ",
      "                "
    ]
  ],
  "palette": {
    "palette": [
      {
        "char": "!",
        "block": "minecraft:bookshelf"
      },
      {
        "char": "$",
        "block": "minecraft:coarse_dirt"
      },
      {
        "char": "%",
        "block": "kubejs:ruined_crafting_table"
      },
      {
        "char": "&",
        "block": "minecraft:gravel"
      },
      {
        "char": "'",
        "block": "minecraft:polished_andesite"
      },
      {
        "char": "(",
        "block": "minecraft:quartz_stairs[facing=north,half=bottom,shape=straight,waterlogged=false]"
      },
      {
        "char": ")",
        "block": "minecraft:scaffolding"
      },
      {
        "char": "*",
        "block": "minecraft:spawner",
        "tag": {
          "id": "minecraft:mob_spawner",
          "Delay": 200,
          "MinSpawnDelay": 240,
          "MaxSpawnDelay": 720,
          "SpawnCount": 3,
          "MaxNearbyEntities": 9,
          "RequiredPlayerRange": 14,
          "SpawnRange": 4,
          "SpawnData": {
            "entity": {
              "id": "minecraft:zombie"
            }
          },
          "SpawnPotentials": [
            {
              "weight": 1,
              "data": {
                "entity": {
                  "id": "minecraft:zombie"
                }
              }
            }
          ]
        }
      },
      {
        "char": "+",
        "block": "tfmg:asphalt"
      },
      {
        "char": ",",
        "block": "zvhouses:spruce_countertop"
      }
    ]
  }
}
