{
  "xsize": 16,
  "zsize": 16,
  "slices": [
    [
      "000000000000    ",
      "00000000000'    ",
      "000000000''&    ",
      "0000000''&00    ",
      "00000''&0000    ",
      "000''&00000'    ",
      "0''&00000000    ",
      "'&0000000000    ",
      "000000000000    ",
      "000000000000    ",
      "000000000000    ",
      "0000000000''    ",
      "00000000''&0    ",
      "000000''&000    ",
      "0000''&00000    ",
      "00''&0000000    "
    ],
    [
      "----------      ",
      "----------      ",
      "----------      ",
      "----------      ",
      "----------      ",
      "----------      ",
      "----------      ",
      "----------      ",
      "----------      ",
      "----------      ",
      "----------      ",
      "----------      ",
      "----------      ",
      "----------      ",
      "----------      ",
      "----------      "
    ],
    [
      "         1      ",
      "         1      ",
      "         1      ",
      "         1      ",
      "......+..1      ",
      "         1      ",
      "      )  1      ",
      "         1      ",
      "         1      ",
      "         1      ",
      "         1      ",
      "         1      ",
      "         1      ",
      "%        1      ",
      "$    / * 1      ",
      "         1      "
    ],
    [
      "         1      ",
      "         1      ",
      "         1      ",
      "         1      ",
      "......,..1      ",
      "         1      ",
      "         1      ",
      "      )  1      ",
      "         1      ",
      "         1      ",
      "         1      ",
      "         1      ",
      "         1      ",
      "         1      ",
      "         1      ",
      "       ( 1      "
    ],
    [
      "         1      ",
      "         1      ",
      "         1      ",
      "         1      ",
      ".........1      ",
      "         1      ",
      "         1      ",
      "         1      ",
      "      )  1      ",
      "         1      ",
      "         1      ",
      "         1      ",
      "         !      ",
      "         !      ",
      "         1      ",
      "         1      "
    ],
    [
      "         1      ",
      "         1      ",
      "         1      ",
      "         1      ",
      ".........1      ",
      "         1      ",
      "         1      ",
      "         1      ",
      "         1      ",
      "      )  1      ",
      "         1      ",
      "         1      ",
      "         !      ",
      "         !      ",
      "         1      ",
      "         1      "
    ]
  ],
  "palette": {
    "palette": [
      {
        "char": "!",
        "block": "create:framed_glass"
      },
      {
        "char": "$",
        "block": "minecraft:brown_bed[facing=north,occupied=false,part=foot]"
      },
      {
        "char": "%",
        "block": "minecraft:brown_bed[facing=north,occupied=false,part=head]"
      },
      {
        "char": "&",
        "block": "minecraft:coarse_dirt"
      },
      {
        "char": "'",
        "block": "minecraft:gravel"
      },
      {
        "char": "(",
        "block": "minecraft:lever[face=wall,facing=south,powered=false]"
      },
      {
        "char": ")",
        "block": "minecraft:oak_stairs[facing=south,half=bottom,shape=straight,waterlogged=false]"
      },
      {
        "char": "*",
        "block": "minecraft:quartz_stairs[facing=north,half=bottom,shape=straight,waterlogged=false]"
      },
      {
        "char": "+",
        "block": "minecraft:spruce_door[facing=south,half=lower,hinge=left,open=false,powered=false]"
      },
      {
        "char": ",",
        "block": "minecraft:spruce_door[facing=south,half=upper,hinge=left,open=false,powered=false]"
      },
      {
        "char": "-",
        "block": "minecraft:spruce_planks"
      },
      {
        "char": ".",
        "block": "minecraft:stripped_spruce_wood"
      },
      {
        "char": "/",
        "block": "kubejs:ruined_cauldron"
      },
      {
        "char": "0",
        "block": "tfmg:asphalt"
      },
      {
        "char": "1",
        "block": "the_wasteland_reworked:decayed_planks"
      }
    ]
  }
}
