{
  "xsize": 16,
  "zsize": 16,
  "slices": [
    [
      "                ",
      "                ",
      "                ",
      "   '            ",
      "   '            ",
      "   '            ",
      "   '            ",
      "   '            ",
      "   '            ",
      "   '            ",
      "   '            ",
      "   '            ",
      "   '            ",
      "   '            ",
      "   '            ",
      "   '            "
    ],
    [
      "                ",
      "                ",
      "                ",
      "   '            ",
      "   '            ",
      "   '            ",
      "   '            ",
      "   '            ",
      "   '            ",
      "   '            ",
      "   '            ",
      "   '            ",
      "   '            ",
      "   '            ",
      "   '            ",
      "   '            "
    ],
    [
      "                ",
      "                ",
      "                ",
      "   '            ",
      "   '            ",
      "   '            ",
      "   '            ",
      "   '            ",
      "   '            ",
      "   '            ",
      "   '            ",
      "   '            ",
      "   '            ",
      "   '            ",
      "   '            ",
      "   '            "
    ],
    [
      "                ",
      "                ",
      "                ",
      "                ",
      "                ",
      "                ",
      "                ",
      "                ",
      "                ",
      "                ",
      "                ",
      "                ",
      "                ",
      "                ",
      "                ",
      "                "
    ],
    [
      "&&&&&&&&&&&&&&&&",
      "&&&&&&&&&&&&&&&&",
      "&&&&&&&&&&&&&&&&",
      "&&&&&&&&&&&&&&&&",
      "&&&&&&&&&&&&&&&&",
      "&&&&&&&&&&&&&&&&",
      "&&&&&&&&&&&&&&&&",
      "&&&&&&&&&&&&&&&&",
      "&&&&&&&&&&&&&&&&",
      "&&&&&&&&&&&&&&&&",
      "&&&&&&&&&&&&&&&&",
      "&&&&&&&&&&&&&&&&",
      "&&&&&&&&&&&&&&&&",
      "&&&&&&&&&&&&&&&&",
      "&&&&&&&&&&&&&&&&",
      "&&&&&&&&&&&&&&&&"
    ],
    [
      "!!!!!     (   !!",
      "!!!!!     '   !!",
      "          '     ",
      "          '     ",
      "          '     ",
      "'''''''''''''')'",
      "'               ",
      "'               ",
      "'               ",
      "' %%%%%%%%%%%%%%",
      "$               ",
      "'               ",
      "' %%%%%%%%%%%%%%",
      "'               ",
      "'               ",
      "' %%%%%%%%%%%%%%"
    ]
  ],
  "palette": {
    "palette": [
      {
        "char": "!",
        "block": "minecraft:bookshelf"
      },
      {
        "char": "$",
        "block": "minecraft:dark_oak_door[facing=east,half=lower,hinge=left,open=false,powered=false]"
      },
      {
        "char": "%",
        "block": "minecraft:dark_oak_stairs[facing=south,half=bottom,shape=straight,waterlogged=false]"
      },
      {
        "char": "&",
        "block": "minecraft:polished_andesite"
      },
      {
        "char": "'",
        "block": "minecraft:polished_tuff"
      },
      {
        "char": "(",
        "block": "minecraft:spruce_door[facing=east,half=lower,hinge=left,open=false,powered=false]"
      },
      {
        "char": ")",
        "block": "minecraft:spruce_door[facing=south,half=lower,hinge=left,open=false,powered=false]"
      }
    ]
  }
}
