{
  "xsize": 16,
  "zsize": 16,
  "slices": [
    [
      " ,,,,,,,,,%%$,,,",
      " $,,,,,,%%$,,,,,",
      " ,,,,,%%$,,,,,,,",
      " ,,,%%$,,,,,,,,,",
      " ,%%$,,,,,,,,,,,",
      " %$,,,,,,,,,,,,,",
      " ,,,,,,,,,,,,,,,",
      " $,,,,,,,,,,,,,%",
      " ,,,,,,,,,,,,%%$",
      " ,,,,,,,,,,%%$,,",
      " ,,,,,,,,%%$,,,,",
      " ,,,,,,%%$,,,,,,",
      " ,,,,%%$,,,,,,,,",
      " $,%%$,,,,,,,,,,",
      " %%$,,,,,,,,,,,,",
      " $$,,,,$,,,,$,,,"
    ],
    [
      "     -----------",
      "     -----------",
      "     -----------",
      "     -----------",
      "     -----------",
      "     -----------",
      "     -----------",
      "     -----------",
      "     -----------",
      "     -----------",
      "     -----------",
      "     -----------",
      "     -----------",
      "                ",
      "    ************",
      "                "
    ],
    [
      "     ! +++++++++",
      "     ! +++++++++",
      "     ! +++++++++",
      "     ! +++++++++",
      "     ! +++++++++",
      "     ! +++++++++",
      "     ! +++++++++",
      "     ! +++++++++",
      "     ! +++++++++",
      "     ! +++++++++",
      "     !          ",
      "     !          ",
      "     !!!!!&'!!!!",
      "                ",
      "                ",
      "                "
    ],
    [
      "     ! +++++++++",
      "     ! +++++++++",
      "     ! +++++++++",
      "     ! +++++++++",
      "     ! +++++++++",
      "     ! +++++++++",
      "     ! +++++++++",
      "     ! +++++++++",
      "     ! +++++++++",
      "     ! +++++++++",
      "     !          ",
      "     !          ",
      "     !!!!!()!!!!",
      "                ",
      "                ",
      "                "
    ],
    [
      "     ! +++++++++",
      "     ! +++++++++",
      "     ! +++++++++",
      "     ! +++++++++",
      "     ! +++++++++",
      "     ! +++++++++",
      "     ! +++++++++",
      "     ! +++++++++",
      "     ! +++++++++",
      "     ! +++++++++",
      "     !          ",
      "     !          ",
      "     !!!!!!!!!!!",
      "                ",
      "                ",
      "                "
    ],
    [
      "     ! +++++++++",
      "     ! +++++++++",
      "     ! +++++++++",
      "     ! +++++++++",
      "     ! +++++++++",
      "     ! +++++++++",
      "     ! +++++++++",
      "     ! +++++++++",
      "     ! +++++++++",
      "     ! +++++++++",
      "     !          ",
      "     !          ",
      "     !!!!!!!!!!!",
      "                ",
      "                ",
      "                "
    ]
  ],
  "palette": {
    "palette": [
      {
        "char": "!",
        "block": "minecraft:bricks"
      },
      {
        "char": "$",
        "block": "minecraft:coarse_dirt"
      },
      {
        "char": "%",
        "block": "minecraft:gravel"
      },
      {
        "char": "&",
        "block": "minecraft:iron_door[facing=south,half=lower,hinge=left,open=false,powered=false]"
      },
      {
        "char": "'",
        "block": "minecraft:iron_door[facing=south,half=lower,hinge=right,open=false,powered=false]"
      },
      {
        "char": "(",
        "block": "minecraft:iron_door[facing=south,half=upper,hinge=left,open=false,powered=false]"
      },
      {
        "char": ")",
        "block": "minecraft:iron_door[facing=south,half=upper,hinge=right,open=false,powered=false]"
      },
      {
        "char": "*",
        "block": "minecraft:rail[shape=east_west,waterlogged=false]"
      },
      {
        "char": "+",
        "block": "minecraft:scaffolding"
      },
      {
        "char": ",",
        "block": "tfmg:asphalt"
      },
      {
        "char": "-",
        "block": "tfmg:factory_floor"
      }
    ]
  }
}
