{
  "xsize": 16,
  "zsize": 16,
  "slices": [
    [
      "                ",
      "                ",
      "                ",
      "                ",
      "                ",
      "                ",
      "%$$%%%%         ",
      "&&&&&&&&&       ",
      "        &       ",
      "        &       ",
      "        &       ",
      "        &       ",
      "        &       ",
      "        &       ",
      "        &       ",
      "        &       "
    ],
    [
      "                ",
      "                ",
      "                ",
      "                ",
      "                ",
      "!!!!            ",
      "$$$$$           ",
      "&&&&&&&&&       ",
      "        &       ",
      "        &       ",
      "        &       ",
      "        &       ",
      "        &       ",
      "        &       ",
      "        &       ",
      "        &       "
    ],
    [
      "                ",
      "                ",
      "                ",
      "                ",
      "                ",
      "!!!!            ",
      "$$$$$           ",
      "&&&&&&&&&       ",
      "        &       ",
      "        &       ",
      "        &       ",
      "        &       ",
      "        &       ",
      "        &       ",
      "        &       ",
      "        &       "
    ],
    [
      "                ",
      "                ",
      "                ",
      "                ",
      "                ",
      "                ",
      "$$$$$           ",
      "&&&&&&&&&       ",
      "        &       ",
      "        &       ",
      "        &       ",
      "        &       ",
      "        &       ",
      "        &       ",
      "        &       ",
      "        &       "
    ],
    [
      "                ",
      "                ",
      "                ",
      "                ",
      "                ",
      "                ",
      "                ",
      "&&&&&&&&&       ",
      "        &       ",
      "        &       ",
      "        &       ",
      "        &       ",
      "        &       ",
      "        &       ",
      "        &       ",
      "        &       "
    ],
    [
      "                ",
      "                ",
      "                ",
      "                ",
      "                ",
      "                ",
      "                ",
      "$$$$$$$$$       ",
      "$$$$$$$$$       ",
      "$$$$$$$$$       ",
      "$$$$$$$$$       ",
      "$$$$$$$$$       ",
      "$$$$$$$$$       ",
      "$$$$$$$$$       ",
      "$$$$$$$$$       ",
      "$$$$$$$$$       "
    ]
  ],
  "palette": {
    "palette": [
      {
        "char": "!",
        "block": "minecraft:red_terracotta"
      },
      {
        "char": "$",
        "block": "minecraft:smooth_stone"
      },
      {
        "char": "%",
        "block": "minecraft:spruce_slab[type=top,waterlogged=false]"
      },
      {
        "char": "&",
        "block": "tfmg:cinder_block"
      }
    ]
  }
}
