{
  "xsize": 16,
  "zsize": 16,
  "slices": [
    [
      "%%%  $          ",
      "%%%  $          ",
      "%%%  $          ",
      "%%%  $          ",
      "%%%  $          ",
      "%%%  $          ",
      "%%%  $          ",
      "%%%  $          ",
      "%%%  $          ",
      "%%%  $          ",
      "%%%  $          ",
      "%%%  $          ",
      "%%%  $          ",
      "     $          ",
      "     $          ",
      "$$$$$$          "
    ],
    [
      "%%%  $          ",
      "%%%  $          ",
      "%%%  $          ",
      "%%%  $          ",
      "!!%  $          ",
      "!!%  $          ",
      "!!%  $          ",
      "!!%  $          ",
      "!!%  $          ",
      "!!%  $          ",
      "!!%  $          ",
      "%%%  $          ",
      "%%%  $          ",
      "     $          ",
      "     $          ",
      "$$$$$$          "
    ],
    [
      "     $          ",
      "     $          ",
      "     $          ",
      "     $          ",
      "!!   $          ",
      "!!   $          ",
      "!!   $          ",
      "!!   $          ",
      "!!   $          ",
      "!!   $          ",
      "!!   $          ",
      "     $          ",
      "     $          ",
      "     $          ",
      "     $          ",
      "$$$$$$          "
    ],
    [
      "     $          ",
      "     $          ",
      "     $          ",
      "     $          ",
      "!!   $          ",
      "!!   $          ",
      "!!   $          ",
      "!!   $          ",
      "!!   $          ",
      "!!   $          ",
      "!!   $          ",
      "     $          ",
      "     $          ",
      "     $          ",
      "     $          ",
      "$$$$$$          "
    ],
    [
      "     $          ",
      "     $          ",
      "     $          ",
      "     $          ",
      "!!   $          ",
      "!!   $          ",
      "!!   $          ",
      "!!   $          ",
      "!!   $          ",
      "!!   $          ",
      "!!   $          ",
      "     $          ",
      "     $          ",
      "     $          ",
      "     $          ",
      "$$$$$$          "
    ],
    [
      "     $          ",
      "     $          ",
      "     $          ",
      "     $          ",
      "!!   $          ",
      "!!   $          ",
      "!!   $          ",
      "!!   $          ",
      "!!   $          ",
      "!!   $          ",
      "!!   $          ",
      "     $          ",
      "     $          ",
      "     $          ",
      "     $          ",
      "$$$$$$          "
    ]
  ],
  "palette": {
    "palette": [
      {
        "char": "!",
        "block": "ae2:controller"
      },
      {
        "char": "$",
        "block": "minecraft:light_gray_concrete"
      },
      {
        "char": "%",
        "block": "minecraft:smooth_stone"
      }
    ]
  }
}
