{
  "xsize": 16,
  "zsize": 16,
  "slices": [
    [
      "               $",
      "                ",
      "                ",
      "                ",
      "                ",
      "(((((! !        ",
      ")))))!)!        ",
      "       )        ",
      "       !!       ",
      "       )        ",
      "       )        ",
      "       )        ",
      "       )        ",
      "       !!       ",
      "       )        ",
      "       )        "
    ],
    [
      "                ",
      "                ",
      "                ",
      "                ",
      "                ",
      "     ! !        ",
      ")))))!)!        ",
      "       )        ",
      "       !!       ",
      "       )        ",
      "       )        ",
      "       )        ",
      "       )        ",
      "       !!       ",
      "       )        ",
      "       )        "
    ],
    [
      "                ",
      "                ",
      "                ",
      "                ",
      "                ",
      "     ! !        ",
      ")))))!)!        ",
      "       )'       ",
      "       !'       ",
      "       )'       ",
      "       )'       ",
      "       )'       ",
      "       )'       ",
      "       !'       ",
      "       )'       ",
      "       )'       "
    ],
    [
      "&&&&&&&&&       ",
      "&&&&&&&&&       ",
      "                ",
      "                ",
      "                ",
      "     ! !        ",
      ")))))!)!        ",
      "       )        ",
      "       !!       ",
      "       )        ",
      "       )        ",
      "       )        ",
      "       )        ",
      "       !!       ",
      "       )        ",
      "       )        "
    ],
    [
      "       %%       ",
      "%%%%%%%%%       ",
      "                ",
      "                ",
      "                ",
      "     ! !        ",
      ")))))!)!        ",
      "       )        ",
      "       !!       ",
      "       )        ",
      "       )        ",
      "       )        ",
      "       )        ",
      "       !!       ",
      "       )        ",
      "       )        "
    ],
    [
      "                ",
      "                ",
      "                ",
      "                ",
      "                ",
      "                ",
      "&&&&&&&&        ",
      "&&&&&&&&        ",
      "&&&&&&&&        ",
      "&&&&&&&&        ",
      "&&&&&&&&        ",
      "&&&&&&&&        ",
      "&&&&&&&&        ",
      "&&&&&&&&        ",
      "&&&&&&&&        ",
      "&&&&&&&&        "
    ]
  ],
  "palette": {
    "palette": [
      {
        "char": "!",
        "block": "minecraft:mud_bricks"
      },
      {
        "char": "$",
        "block": "minecraft:polished_blackstone_bricks"
      },
      {
        "char": "%",
        "block": "minecraft:red_concrete"
      },
      {
        "char": "&",
        "block": "minecraft:smooth_stone"
      },
      {
        "char": "'",
        "block": "minecraft:smooth_stone_slab[type=bottom,waterlogged=false]"
      },
      {
        "char": "(",
        "block": "minecraft:spruce_slab[type=top,waterlogged=false]"
      },
      {
        "char": ")",
        "block": "tfmg:cinder_block"
      }
    ]
  }
}
