{
  "xsize": 16,
  "zsize": 16,
  "slices": [
    [
      "&&&&&&&&&&&&&&&&",
      "&&&&&&&&&&&&&&&&",
      "&&&&&&&&&&&&&&&&",
      "&&&&&&&&&&&&&&&&",
      "&&&&&&&&&&&&&&&&",
      "&&&&&&&&&&&&&&&&",
      "&&&&&&&&&&&&&&&&",
      "&&&&&&&&&&&&&&&&",
      "&&&&&&&&&&&&&&&&",
      "&&&&&&&&&&&&&&&&",
      "&&&&&&&&&&&&&&&&",
      "&&&&&&&&&&&&&&&&",
      "&&&&&&&&&&&&&&&&",
      "                ",
      "                ",
      "$$$$$$$$$$$$$$$$"
    ],
    [
      "&&&&%&&&&&&&&&&&",
      "&&&&%&&&&&&&&&&&",
      "&&&&'&&&&&&&&&&&",
      "&&&&%&&&&&&&&&&&",
      "&&&&%&&!!!!!!!!!",
      "&&&&%&&!!!!!!!!!",
      "&&&&%&&!!!!!!!!!",
      "&&&&%&&!!!!!!!!!",
      "&&&&%&&!!!!!!!!!",
      "&&&&%&&!!!!!!!!!",
      "&&&&%&&!!!!!!!!!",
      "&&&&%&&&&&&&&&&&",
      "&&&&%&&&&&&&&&&&",
      "    %           ",
      "                ",
      "$$$$$$$$$$$$$$$$"
    ],
    [
      "    %           ",
      "    %           ",
      "    (           ",
      "    %           ",
      "    %  !!!!!!!!!",
      "    %  !!!!!!!!!",
      "    %  !!!!!!!!!",
      "    %  !!!!!!!!!",
      "    %  !!!!!!!!!",
      "    %  !!!!!!!!!",
      "    %  !!!!!!!!!",
      "    %           ",
      "    %           ",
      "    %           ",
      "                ",
      "$$$$$$$$$$$$$$$$"
    ],
    [
      "    %           ",
      "    %           ",
      "    %           ",
      "    %           ",
      "    %  !!!!!!!!!",
      "    %  !!!!!!!!!",
      "    %  !!!!!!!!!",
      "    %  !!!!!!!!!",
      "    %  !!!!!!!!!",
      "    %  !!!!!!!!!",
      "    %  !!!!!!!!!",
      "    %           ",
      "    %           ",
      "    %           ",
      "                ",
      "$$$$$$$$$$$$$$$$"
    ],
    [
      "    %           ",
      "    %           ",
      "    %           ",
      "    %           ",
      "    %  !!!!!!!!!",
      "    %  !!!!!!!!!",
      "    %  !!!!!!!!!",
      "    %  !!!!!!!!!",
      "    %  !!!!!!!!!",
      "    %  !!!!!!!!!",
      "    %  !!!!!!!!!",
      "    %           ",
      "    %           ",
      "    %           ",
      "                ",
      "$$$$$$$$$$$$$$$$"
    ],
    [
      "                ",
      "                ",
      "                ",
      "                ",
      "       !!!!!!!!!",
      "       !!!!!!!!!",
      "       !!!!!!!!!",
      "       !!!!!!!!!",
      "       !!!!!!!!!",
      "       !!!!!!!!!",
      "       !!!!!!!!!",
      "                ",
      "                ",
      "                ",
      "                ",
      "$$$$$$$$$$$$$$$$"
    ]
  ],
  "palette": {
    "palette": [
      {
        "char": "!",
        "block": "ae2:controller"
      },
      {
        "char": "$",
        "block": "minecraft:light_gray_concrete"
      },
      {
        "char": "%",
        "block": "minecraft:smooth_quartz"
      },
      {
        "char": "&",
        "block": "minecraft:smooth_stone"
      },
      {
        "char": "'",
        "block": "minecraft:spruce_door[facing=east,half=lower,hinge=left,open=false,powered=false]"
      },
      {
        "char": "(",
        "block": "minecraft:spruce_door[facing=east,half=upper,hinge=left,open=false,powered=false]"
      }
    ]
  }
}
