{
  "xsize": 16,
  "zsize": 16,
  "slices": [
    [
      "8888888888888''&",
      "88888888888''&88",
      "888888888''&8888",
      "8888888''&888888",
      "88888''&88888888",
      "888''&8888888888",
      "8''&888888888888",
      "'&88888888888888",
      "8888888888888888",
      "88888888888888''",
      "888888888888''&8",
      "8888888888''&888",
      "88888888''&88888",
      "888888''&8888888",
      "8888''&888888888",
      "88''&88888888888"
    ],
    [
      "2200000000001888",
      "2200000000001888",
      "2200000000001888",
      "2200000000001888",
      "2200000000001888",
      "2200000000001888",
      "2200000000001888",
      "2200000000001888",
      "2200000000001888",
      "2200000000001888",
      "2200000000001888",
      "0000000000001111",
      "                ",
      "                ",
      "                ",
      "                "
    ],
    [
      "  11111114111   ",
      "  ( !  %    1   ",
      "  1 !       (   ",
      "  1111111411)   ",
      "3 (         1   ",
      "  1 66      1   ",
      "  11711114111   ",
      "  1         1   ",
      "  (       $ 1   ",
      "  1       $ 1   ",
      "  1         1   ",
      "1111,-1111111111",
      "                ",
      "                ",
      "                ",
      "                "
    ],
    [
      "  11111115111   ",
      "  * !       1   ",
      "  1 !       *   ",
      "  1111111511+   ",
      "  *         1   ",
      "  1         1   ",
      "  11111115111   ",
      "  1         1   ",
      "  *       $ 1   ",
      "  1       $ 1   ",
      "  1         1   ",
      "1111./1111111111",
      "                ",
      "                ",
      "                ",
      "                "
    ],
    [
      "  11111111111   ",
      "  1 !       1   ",
      "  1 !           ",
      "  1111111111    ",
      "  1         1   ",
      "  1         1   ",
      "  11111111111   ",
      "  1         1   ",
      "  1       $ 1   ",
      "  1       $ 1   ",
      "  1         1   ",
      "1111111111111111",
      "                ",
      "                ",
      "                ",
      "                "
    ],
    [
      "  11111111111   ",
      "  1         1   ",
      "  1             ",
      "  1111111111    ",
      "  1         1   ",
      "  1         1   ",
      "  11111111111   ",
      "  1         1   ",
      "  1         1   ",
      "  1         1   ",
      "  1         1   ",
      "1111111111111   ",
      "                ",
      "                ",
      "                ",
      "                "
    ]
  ],
  "palette": {
    "palette": [
      {
        "char": "!",
        "block": "immersiveengineering:crate"
      },
      {
        "char": "$",
        "block": "minecraft:bookshelf"
      },
      {
        "char": "%",
        "block": "minecraft:chest[facing=south,type=single,waterlogged=false]",
        "tag": {
          "id": "minecraft:chest",
          "LootTable": "infinite_domain:chests/wasteland_data"
        }
      },
      {
        "char": "&",
        "block": "minecraft:coarse_dirt"
      },
      {
        "char": "'",
        "block": "minecraft:gravel"
      },
      {
        "char": "(",
        "block": "minecraft:iron_door[facing=east,half=lower,hinge=left,open=false,powered=false]"
      },
      {
        "char": ")",
        "block": "minecraft:iron_door[facing=east,half=lower,hinge=right,open=false,powered=false]"
      },
      {
        "char": "*",
        "block": "minecraft:iron_door[facing=east,half=upper,hinge=left,open=false,powered=false]"
      },
      {
        "char": "+",
        "block": "minecraft:iron_door[facing=east,half=upper,hinge=right,open=false,powered=false]"
      },
      {
        "char": ",",
        "block": "minecraft:iron_door[facing=south,half=lower,hinge=left,open=false,powered=false]"
      },
      {
        "char": "-",
        "block": "minecraft:iron_door[facing=south,half=lower,hinge=right,open=false,powered=false]"
      },
      {
        "char": ".",
        "block": "minecraft:iron_door[facing=south,half=upper,hinge=left,open=false,powered=false]"
      },
      {
        "char": "/",
        "block": "minecraft:iron_door[facing=south,half=upper,hinge=right,open=false,powered=false]"
      },
      {
        "char": "0",
        "block": "minecraft:polished_andesite"
      },
      {
        "char": "1",
        "block": "minecraft:polished_deepslate"
      },
      {
        "char": "2",
        "block": "minecraft:smooth_stone"
      },
      {
        "char": "3",
        "block": "minecraft:spawner",
        "tag": {
          "id": "minecraft:mob_spawner",
          "Delay": 200,
          "MinSpawnDelay": 240,
          "MaxSpawnDelay": 720,
          "SpawnCount": 2,
          "MaxNearbyEntities": 8,
          "RequiredPlayerRange": 14,
          "SpawnRange": 4,
          "SpawnData": {
            "entity": {
              "id": "the_wasteland_reworked:ghoul"
            }
          },
          "SpawnPotentials": [
            {
              "weight": 1,
              "data": {
                "entity": {
                  "id": "the_wasteland_reworked:ghoul"
                }
              }
            }
          ]
        }
      },
      {
        "char": "4",
        "block": "minecraft:spruce_door[facing=south,half=lower,hinge=left,open=false,powered=false]"
      },
      {
        "char": "5",
        "block": "minecraft:spruce_door[facing=south,half=upper,hinge=left,open=false,powered=false]"
      },
      {
        "char": "6",
        "block": "minecraft:spruce_slab[type=bottom,waterlogged=false]"
      },
      {
        "char": "7",
        "block": "minecraft:spruce_stairs[facing=north,half=bottom,shape=straight,waterlogged=false]"
      },
      {
        "char": "8",
        "block": "tfmg:asphalt"
      }
    ]
  }
}
