{
  "xsize": 16,
  "zsize": 16,
  "slices": [
    [
      "                ",
      "                ",
      "                ",
      "                ",
      "                ",
      "                ",
      "                ",
      "                ",
      "                ",
      "                ",
      "                ",
      "                ",
      "                ",
      "                ",
      "&,,       &&&&&&",
      "& ,$$$!!$$& %%%%"
    ],
    [
      "                ",
      "                ",
      "                ",
      "                ",
      "                ",
      "                ",
      "                ",
      "                ",
      "                ",
      "                ",
      "                ",
      "                ",
      "                ",
      "                ",
      "&,,       &&&&&&",
      "& ,$$$$$$$& %%%%"
    ],
    [
      "                ",
      "                ",
      "                ",
      "                ",
      "                ",
      "                ",
      "                ",
      "                ",
      "                ",
      "                ",
      "                ",
      "                ",
      "                ",
      "                ",
      "&,,       &&&&&&",
      "& ,$$$$$$$&   & "
    ],
    [
      "                ",
      "                ",
      "                ",
      "                ",
      "                ",
      "                ",
      "                ",
      "                ",
      "                ",
      "                ",
      "                ",
      "                ",
      "                ",
      "                ",
      "&,,       &&&&&&",
      "& ,$$$$$$$&   & "
    ],
    [
      "................",
      "................",
      "................",
      "................",
      "................",
      "................",
      "................",
      "................",
      "................",
      "................",
      "................",
      "................",
      "................",
      "................",
      "&.............&.",
      "& ,$$$$$$$&   & "
    ],
    [
      "-          +  - ",
      "-   *  *  *   - ",
      "----)--(--)-----",
      "-             - ",
      "-             - ",
      "'             ' ",
      "-             - ",
      "-             - ",
      "-------(--------",
      "-             - ",
      "-             - ",
      "-             - ",
      "-             - ",
      "-             - ",
      "&,,       &&&&&&",
      "& ,$$$$$$$&   & "
    ]
  ],
  "palette": {
    "palette": [
      {
        "char": "!",
        "block": "create:framed_glass"
      },
      {
        "char": "$",
        "block": "minecraft:bricks"
      },
      {
        "char": "%",
        "block": "minecraft:gravel"
      },
      {
        "char": "&",
        "block": "minecraft:mud_bricks"
      },
      {
        "char": "'",
        "block": "minecraft:spruce_door[facing=east,half=lower,hinge=left,open=false,powered=false]"
      },
      {
        "char": "(",
        "block": "minecraft:spruce_door[facing=south,half=lower,hinge=left,open=false,powered=false]"
      },
      {
        "char": ")",
        "block": "minecraft:spruce_slab[type=bottom,waterlogged=false]"
      },
      {
        "char": "*",
        "block": "minecraft:spruce_stairs[facing=north,half=bottom,shape=straight,waterlogged=false]"
      },
      {
        "char": "+",
        "block": "kubejs:ruined_cauldron"
      },
      {
        "char": ",",
        "block": "minecraft:yellow_terracotta"
      },
      {
        "char": "-",
        "block": "tfmg:cinder_block"
      },
      {
        "char": ".",
        "block": "tfmg:factory_floor"
      }
    ]
  }
}
