{
  "xsize": 16,
  "zsize": 16,
  "slices": [
    [
      "0000((%000000000",
      "00((%00000000000",
      "((%0000000000000",
      "%000000000000000",
      "000000000000000(",
      "0000000000000((%",
      "00000000000((%00",
      "000000000((%0000",
      "0000000((%000000",
      "00000((%00000000",
      "000((%0000000000",
      "0((%000000000000",
      "(%00000000000000",
      "0000000000000000",
      "00000000000000((",
      "000000000000((%0"
    ],
    [
      "     ***********",
      "     ***********",
      "     ***********",
      "     ***********",
      "     ***********",
      "     ***********",
      "     ***********",
      "     ***********",
      "     ***********",
      "     ***********",
      "     ***********",
      "     ***********",
      "     ***********",
      "     ***********",
      "     ***********",
      "     ***********"
    ],
    [
      "     / $$$$$$$$$",
      "     /          ",
      "     /++++++++-+",
      "     /          ",
      "     /          ",
      "     / '''''''''",
      "     /          ",
      "     /          ",
      "     / '''''''''",
      "     /          ",
      "     /          ",
      "     / '''''''''",
      "     /         ,",
      "     /          ",
      "     /    &&&& &",
      "     /  ) &&&& &"
    ],
    [
      "     / $$$$$$$$$",
      "     !          ",
      "     !++++++++.+",
      "     /          ",
      "     /          ",
      "     /          ",
      "     /          ",
      "     /          ",
      "     !          ",
      "     !          ",
      "     /          ",
      "     /          ",
      "     /          ",
      "     /          ",
      "     /          ",
      "     !          "
    ],
    [
      "     /          ",
      "     !          ",
      "     !++++++++++",
      "     /          ",
      "     /          ",
      "     /          ",
      "     /          ",
      "     /          ",
      "     !          ",
      "     !          ",
      "     /          ",
      "     /          ",
      "     /          ",
      "     /          ",
      "     /          ",
      "     !          "
    ],
    [
      "     /          ",
      "     /          ",
      "     /++++++++++",
      "     /          ",
      "     /          ",
      "     /          ",
      "     /          ",
      "     /          ",
      "     /          ",
      "     /          ",
      "     /          ",
      "     /          ",
      "     /          ",
      "     /          ",
      "     /          ",
      "     /          "
    ]
  ],
  "palette": {
    "palette": [
      {
        "char": "!",
        "block": "create:framed_glass"
      },
      {
        "char": "$",
        "block": "minecraft:bookshelf"
      },
      {
        "char": "%",
        "block": "minecraft:coarse_dirt"
      },
      {
        "char": "&",
        "block": "minecraft:dark_oak_slab[type=bottom,waterlogged=false]"
      },
      {
        "char": "'",
        "block": "minecraft:dark_oak_stairs[facing=south,half=bottom,shape=straight,waterlogged=false]"
      },
      {
        "char": "(",
        "block": "minecraft:gravel"
      },
      {
        "char": ")",
        "block": "kubejs:ruined_lectern[facing=south]"
      },
      {
        "char": "*",
        "block": "minecraft:polished_andesite"
      },
      {
        "char": "+",
        "block": "minecraft:polished_tuff"
      },
      {
        "char": ",",
        "block": "minecraft:spawner",
        "tag": {
          "id": "minecraft:mob_spawner",
          "Delay": 200,
          "MinSpawnDelay": 240,
          "MaxSpawnDelay": 720,
          "SpawnCount": 2,
          "MaxNearbyEntities": 8,
          "RequiredPlayerRange": 14,
          "SpawnRange": 4,
          "SpawnData": {
            "entity": {
              "id": "the_wasteland_reworked:ghoul"
            }
          },
          "SpawnPotentials": [
            {
              "weight": 1,
              "data": {
                "entity": {
                  "id": "the_wasteland_reworked:ghoul"
                }
              }
            }
          ]
        }
      },
      {
        "char": "-",
        "block": "minecraft:spruce_door[facing=south,half=lower,hinge=left,open=false,powered=false]"
      },
      {
        "char": ".",
        "block": "minecraft:spruce_door[facing=south,half=upper,hinge=left,open=false,powered=false]"
      },
      {
        "char": "/",
        "block": "minecraft:tuff_bricks"
      },
      {
        "char": "0",
        "block": "tfmg:asphalt"
      }
    ]
  }
}
