{
  "xsize": 16,
  "zsize": 16,
  "slices": [
    [
      "////////////////",
      "////////////////",
      "////////////////",
      "////////////////",
      "////////////////",
      "////////////////",
      "////////////////",
      "////////////////",
      "////////////////",
      "////////////////",
      "////////////////",
      "////////////////",
      "////////////////",
      "////////////////",
      "////////////////",
      "////////////////"
    ],
    [
      "................",
      "................",
      "................",
      "................",
      "................",
      "................",
      "................",
      "................",
      "................",
      "................",
      "................",
      "................",
      ",,,,,,,,........",
      ",,,,,,,,........",
      ",,,,,,,,........",
      ",,,,,,,,........"
    ],
    [
      "           +    ",
      "+2+++++2++++++++",
      "  +             ",
      "! +77777  $$$$$$",
      "! +77777        ",
      "! +77%77    &   ",
      "! +77777        ",
      "! 077777  $$$$$$",
      "! +77777        ",
      "  +          %  ",
      "  +             ",
      "'(++++++66666666",
      "        6       ",
      "        6       ",
      "      - 6       ",
      "        6  5 4  "
    ],
    [
      "           +    ",
      "+3+++++3++++++++",
      "  +             ",
      "! +77777  $$$$$$",
      "! +77777        ",
      "! +77777        ",
      "! +77777        ",
      "! 177777  $$$$$$",
      "! +77777        ",
      "  +             ",
      "  +             ",
      ")*++++++66666666",
      "        6       ",
      "        6       ",
      "        6       ",
      "        6       "
    ],
    [
      "           +    ",
      "++++++++++++++++",
      "  +             ",
      "! +       $$$$$$",
      "! +             ",
      "! +             ",
      "! +             ",
      "! +       $$$$$$",
      "! +             ",
      "  +             ",
      "  +             ",
      "++++++++66666666",
      "        6       ",
      "        6       ",
      "        6       ",
      "        6       "
    ],
    [
      "           +    ",
      "++++++++++++++++",
      "  +             ",
      "  +             ",
      "  +             ",
      "  +             ",
      "  +             ",
      "  +             ",
      "  +             ",
      "  +             ",
      "  +             ",
      "++++++++66666666",
      "        6       ",
      "        6       ",
      "        6       ",
      "        6       "
    ]
  ],
  "palette": {
    "palette": [
      {
        "char": "!",
        "block": "immersiveengineering:sheetmetal_steel"
      },
      {
        "char": "$",
        "block": "minecraft:bookshelf"
      },
      {
        "char": "%",
        "block": "kubejs:ruined_brewing_stand"
      },
      {
        "char": "&",
        "block": "minecraft:chest[facing=west,type=single,waterlogged=false]",
        "tag": {
          "id": "minecraft:chest",
          "LootTable": "infinite_domain:chests/wasteland_biohazard"
        }
      },
      {
        "char": "'",
        "block": "minecraft:iron_door[facing=south,half=lower,hinge=left,open=false,powered=false]"
      },
      {
        "char": "(",
        "block": "minecraft:iron_door[facing=south,half=lower,hinge=right,open=false,powered=false]"
      },
      {
        "char": ")",
        "block": "minecraft:iron_door[facing=south,half=upper,hinge=left,open=false,powered=false]"
      },
      {
        "char": "*",
        "block": "minecraft:iron_door[facing=south,half=upper,hinge=right,open=false,powered=false]"
      },
      {
        "char": "+",
        "block": "minecraft:light_gray_concrete"
      },
      {
        "char": ",",
        "block": "minecraft:moss_block"
      },
      {
        "char": "-",
        "block": "minecraft:oak_slab[type=bottom,waterlogged=false]"
      },
      {
        "char": ".",
        "block": "minecraft:polished_andesite"
      },
      {
        "char": "/",
        "block": "minecraft:smooth_stone"
      },
      {
        "char": "0",
        "block": "minecraft:spruce_door[facing=east,half=lower,hinge=left,open=false,powered=false]"
      },
      {
        "char": "1",
        "block": "minecraft:spruce_door[facing=east,half=upper,hinge=left,open=false,powered=false]"
      },
      {
        "char": "2",
        "block": "minecraft:spruce_door[facing=south,half=lower,hinge=left,open=false,powered=false]"
      },
      {
        "char": "3",
        "block": "minecraft:spruce_door[facing=south,half=upper,hinge=left,open=false,powered=false]"
      },
      {
        "char": "4",
        "block": "kubejs:ruined_cauldron"
      },
      {
        "char": "5",
        "block": "minecraft:white_bed[facing=south,occupied=false,part=foot]"
      },
      {
        "char": "6",
        "block": "minecraft:white_concrete"
      },
      {
        "char": "7",
        "block": "zvhouses:stone_brick_countertop"
      }
    ]
  }
}
