{
  "xsize": 16,
  "zsize": 16,
  "slices": [
    [
      "5555555555555555",
      "5/5555/5555/5555",
      "5555555555555555",
      "5555555555555555",
      "5555555555555555",
      "5555555555555555",
      "5555555555555555",
      "555555//$5555555",
      "5555//$555555555",
      "55//$55555555555",
      "//$5555555555555",
      "$555555555555555",
      "555555555555555/",
      "5555555555555//$",
      "55555555555//$55",
      "555555555//$5555"
    ],
    [
      "                ",
      "                ",
      "                ",
      "                ",
      "11111111        ",
      "11111111        ",
      "11111111        ",
      "1111111133333333",
      "1111111133333333",
      "3333333333333333",
      "3333333333333333",
      "3333333333333333",
      "3333333333333333",
      "3333333333333333",
      "3333333333333333",
      "3333333333333333"
    ],
    [
      "                ",
      "                ",
      "                ",
      "                ",
      "33%&3333        ",
      "       3        ",
      "       30       ",
      "       302222222",
      "33)*3333        ",
      "                ",
      "                ",
      "                ",
      "         -4.  -4",
      "                ",
      "                ",
      "                "
    ],
    [
      "                ",
      "                ",
      "                ",
      "                ",
      "33'(3333        ",
      "       3        ",
      "       30       ",
      "       302!!2!!2",
      "33+,3333        ",
      "                ",
      "                ",
      "                ",
      "                ",
      "                ",
      "                ",
      "                "
    ],
    [
      "                ",
      "                ",
      "                ",
      "                ",
      "33333333        ",
      "       3        ",
      "       30       ",
      "       302!!2!!2",
      "33333333        ",
      "                ",
      "                ",
      "                ",
      "                ",
      "                ",
      "                ",
      "                "
    ],
    [
      "                ",
      "                ",
      "                ",
      "                ",
      "33333333        ",
      "       3        ",
      "       30       ",
      "       302222222",
      "33333333        ",
      "                ",
      "                ",
      "                ",
      "                ",
      "                ",
      "                ",
      "                "
    ]
  ],
  "palette": {
    "palette": [
      {
        "char": "!",
        "block": "create:framed_glass"
      },
      {
        "char": "$",
        "block": "minecraft:coarse_dirt"
      },
      {
        "char": "%",
        "block": "minecraft:dark_oak_door[facing=north,half=lower,hinge=left,open=false,powered=false]"
      },
      {
        "char": "&",
        "block": "minecraft:dark_oak_door[facing=north,half=lower,hinge=right,open=false,powered=false]"
      },
      {
        "char": "'",
        "block": "minecraft:dark_oak_door[facing=north,half=upper,hinge=left,open=false,powered=false]"
      },
      {
        "char": "(",
        "block": "minecraft:dark_oak_door[facing=north,half=upper,hinge=right,open=false,powered=false]"
      },
      {
        "char": ")",
        "block": "minecraft:dark_oak_door[facing=south,half=lower,hinge=left,open=false,powered=false]"
      },
      {
        "char": "*",
        "block": "minecraft:dark_oak_door[facing=south,half=lower,hinge=right,open=false,powered=false]"
      },
      {
        "char": "+",
        "block": "minecraft:dark_oak_door[facing=south,half=upper,hinge=left,open=false,powered=false]"
      },
      {
        "char": ",",
        "block": "minecraft:dark_oak_door[facing=south,half=upper,hinge=right,open=false,powered=false]"
      },
      {
        "char": "-",
        "block": "minecraft:dark_oak_stairs[facing=east,half=bottom,shape=straight,waterlogged=false]"
      },
      {
        "char": ".",
        "block": "minecraft:dark_oak_stairs[facing=west,half=bottom,shape=straight,waterlogged=false]"
      },
      {
        "char": "/",
        "block": "minecraft:gravel"
      },
      {
        "char": "0",
        "block": "minecraft:mud_bricks"
      },
      {
        "char": "1",
        "block": "minecraft:polished_andesite"
      },
      {
        "char": "2",
        "block": "minecraft:red_terracotta"
      },
      {
        "char": "3",
        "block": "minecraft:smooth_stone"
      },
      {
        "char": "4",
        "block": "minecraft:smooth_stone_slab[type=bottom,waterlogged=false]"
      },
      {
        "char": "5",
        "block": "tfmg:asphalt"
      }
    ]
  }
}
