{
  "xsize": 16,
  "zsize": 16,
  "slices": [
    [
      "***************3",
      "***************3",
      "***************&",
      "***************%",
      "***************3",
      "***************3",
      "***************3",
      "***************3",
      "***************3",
      "***************3",
      "***************3",
      "***************3",
      "***************&",
      "***************3",
      "***************3",
      "***************3"
    ],
    [
      "((((((((&(&&&& &",
      "(((('&'&'&&&&(&&",
      "(((((((&&&&&&(& ",
      "(((((((((&(&'&& ",
      "((((((&(&(&&(& '",
      "((((((((&$&'&& &",
      "((((((((((&(&($&",
      "(((((((&((((&(& ",
      "(((((((((&'&((& ",
      "(((((((((((&($  ",
      "((((((((&((((&  ",
      "((((((((((&(&( $",
      "((((((((((((((  ",
      "((((((((((((((  ",
      "((((((((((((((  ",
      "((((((((((((((  "
    ],
    [
      " 2      & &'&& &",
      " +   & & &&&& &&",
      " 2     &'&$&& & ",
      " 2   2   & & '& ",
      "22   2&2& && &  ",
      " 2   2  & & && '",
      " 2   2    & &  '",
      " 2   2 $    & ' ",
      " +   - 1 & &  & ",
      " 2   2     &    ",
      " 2   2  '    '  ",
      "22   2222 & '   ",
      " 2   2       2  ",
      " 2   2       2  ",
      " +   - 0 /   2  ",
      " 2   2 1     2  "
    ],
    [
      " 2   2  & & && '",
      " ,   $ ' $&'& '&",
      " 2   2 & & && & ",
      " 2   2   & &  & ",
      "22   2' $ '& '  ",
      " 2   2  & & '&  ",
      " 2   2    & '   ",
      " 2   2      &   ",
      " ,   .   ' '  ' ",
      " 2   2     '    ",
      " 2   2          ",
      "22   222  '     ",
      " 2   2       2  ",
      " 2   2       2  ",
      " ,   .       !  ",
      " 2   2       !  "
    ],
    [
      " 2)  2  & & $&  ",
      " 2   4    & &  '",
      " 2   2 ' ' '& $ ",
      " 2   2   ' $  ' ",
      "22   2     &    ",
      " 2   2  ' '  $  ",
      " 2   2    $     ",
      " 2   2      '   ",
      " 2   2          ",
      " 2   2          ",
      " 2   2          ",
      "22   22         ",
      " 2   2       2  ",
      " 2   2       2  ",
      " 2   2       !  ",
      " 2   2       !  "
    ],
    [
      " 2   2  $ '  '  ",
      " 2)  2    & '   ",
      " 2   2 4    &   ",
      " 2   2   4      ",
      "22   2     '    ",
      " 2   2       4  ",
      " 2   2          ",
      " 2   2          ",
      " 2   2          ",
      " 2   2          ",
      " 2   2          ",
      "22   22         ",
      " 2   2       2  ",
      " 2   2       2  ",
      " 2   2       2  ",
      " 2   2       2  "
    ]
  ],
  "palette": {
    "palette": [
      {
        "char": "!",
        "block": "create:framed_glass"
      },
      {
        "char": "$",
        "block": "immersiveengineering:concrete_brick_cracked"
      },
      {
        "char": "%",
        "block": "minecraft:coarse_dirt"
      },
      {
        "char": "&",
        "block": "minecraft:gravel"
      },
      {
        "char": "'",
        "block": "minecraft:light_gray_concrete"
      },
      {
        "char": "(",
        "block": "minecraft:polished_andesite"
      },
      {
        "char": ")",
        "block": "minecraft:polished_andesite_stairs[facing=south,half=bottom,shape=straight,waterlogged=false]"
      },
      {
        "char": "*",
        "block": "minecraft:smooth_stone"
      },
      {
        "char": "+",
        "block": "minecraft:spruce_door[facing=east,half=lower,hinge=left,open=false,powered=false]"
      },
      {
        "char": ",",
        "block": "minecraft:spruce_door[facing=east,half=upper,hinge=left,open=false,powered=false]"
      },
      {
        "char": "-",
        "block": "minecraft:spruce_door[facing=west,half=lower,hinge=left,open=false,powered=false]"
      },
      {
        "char": ".",
        "block": "minecraft:spruce_door[facing=west,half=upper,hinge=left,open=false,powered=false]"
      },
      {
        "char": "/",
        "block": "minecraft:water_cauldron[level=3]"
      },
      {
        "char": "0",
        "block": "minecraft:white_bed[facing=south,occupied=false,part=foot]"
      },
      {
        "char": "1",
        "block": "minecraft:white_bed[facing=south,occupied=false,part=head]"
      },
      {
        "char": "2",
        "block": "minecraft:white_concrete"
      },
      {
        "char": "3",
        "block": "tfmg:asphalt"
      },
      {
        "char": "4",
        "block": "wastelands:scrap_pile"
      }
    ]
  }
}
