{
  "xsize": 16,
  "zsize": 16,
  "slices": [
    [
      "***********     ",
      "***********     ",
      "*********&&     ",
      "*******&&%*     ",
      "*****&&%***     ",
      "***&&%*****     ",
      "*&&%*******     ",
      "&%*********     ",
      "***********     ",
      "***********     ",
      "***********     ",
      "**********&     ",
      "********&&%     ",
      "******&&%**     ",
      "****&&%****     ",
      "**&&%******     "
    ],
    [
      "((((((((        ",
      "((((((((        ",
      "((((((((        ",
      "((((((((        ",
      "((((((((        ",
      "((((((((        ",
      "((((((((        ",
      "((((((((        ",
      "((((((((        ",
      "((((((((        ",
      "((((((((        ",
      "((((((((        ",
      "((((((((        ",
      "((((((((        ",
      "((((((((        ",
      "((((((((        "
    ],
    [
      "       '        ",
      ")  $)  '        ",
      "       '        ",
      "       '        ",
      "       '        ",
      "       '        ",
      "+++++  '        ",
      "       '        ",
      "!!!!!!!'        ",
      "       '        ",
      "       '        ",
      "       '        ",
      "       '        ",
      "       '        ",
      "       '        ",
      "       '        "
    ],
    [
      "       '        ",
      "       '        ",
      "       '        ",
      "       '        ",
      "       '        ",
      "       '        ",
      "       '        ",
      "       '        ",
      "!!!!!!!'        ",
      "       '        ",
      "       '        ",
      "       '        ",
      "       '        ",
      "       '        ",
      "       '        ",
      "       '        "
    ],
    [
      "       '        ",
      "       '        ",
      "       '        ",
      "       '        ",
      "       '        ",
      "       '        ",
      "       '        ",
      "       '        ",
      "!!!!!!!'        ",
      "       '        ",
      "       '        ",
      "       '        ",
      "       '        ",
      "       '        ",
      "       '        ",
      "       '        "
    ],
    [
      "       '        ",
      "       '        ",
      "       '        ",
      "       '        ",
      "       '        ",
      "       '        ",
      "       '        ",
      "       '        ",
      "!!!!!!!'        ",
      "       '        ",
      "       '        ",
      "       '        ",
      "       '        ",
      "       '        ",
      "       '        ",
      "       '        "
    ]
  ],
  "palette": {
    "palette": [
      {
        "char": "!",
        "block": "minecraft:bricks"
      },
      {
        "char": "$",
        "block": "kubejs:ruined_cauldron"
      },
      {
        "char": "%",
        "block": "minecraft:coarse_dirt"
      },
      {
        "char": "&",
        "block": "minecraft:gravel"
      },
      {
        "char": "'",
        "block": "minecraft:mud_bricks"
      },
      {
        "char": "(",
        "block": "minecraft:oak_planks"
      },
      {
        "char": ")",
        "block": "kubejs:ruined_smoker[facing=south]"
      },
      {
        "char": "*",
        "block": "tfmg:asphalt"
      },
      {
        "char": "+",
        "block": "zvhouses:spruce_countertop"
      }
    ]
  }
}
