{
  "xsize": 16,
  "zsize": 16,
  "slices": [
    [
      "3333333//$333333",
      "33333//$33333333",
      "333//$3333333333",
      "3//$333333333333",
      "/$33333333333333",
      "3333333333333333",
      "33333333333333//",
      "333333333333//$3",
      "3333333333//$333",
      "33333333//$33333",
      "333333//$3333333",
      "3333//$333333333",
      "33//$33333333333",
      "//$3333333333333",
      "$333333333333333",
      "333333333333333/"
    ],
    [
      "0000000000000000",
      "0000000000000000",
      "0000000000000000",
      "0000000000000000",
      "0000000000000000",
      "0000000000000000",
      "0000000000000000",
      "0000000000000000",
      "0000000000000000",
      "0000000000000000",
      "0000000000000000",
      "0000000000000000",
      "0000000000000000",
      "0000000000000000",
      "0000000000000000",
      "0000000000000000"
    ],
    [
      "! 2             ",
      "  2             ",
      "222222222222%&22",
      "       2        ",
      "       2        ",
      "...... 2        ",
      "       )        ",
      "       2        ",
      "...... 2        ",
      "       2        ",
      "       2        ",
      "...... 2        ",
      "       2        ",
      "       *        ",
      "---    2        ",
      "---    2        "
    ],
    [
      "! 2             ",
      "  2             ",
      "222222222222'(22",
      "       2        ",
      "       2        ",
      "       2        ",
      "       +        ",
      "       2        ",
      "       2        ",
      "       2        ",
      "       2        ",
      "       2        ",
      "       2        ",
      "       ,        ",
      "       2        ",
      "       2   1    "
    ],
    [
      "  2             ",
      "  2             ",
      "2222222222222222",
      "       2        ",
      "       2        ",
      "       2        ",
      "       2        ",
      "       2        ",
      "       2        ",
      "       2        ",
      "       2        ",
      "       2        ",
      "       2        ",
      "       2        ",
      "       2   1    ",
      "       2        "
    ],
    [
      "  2             ",
      "  2             ",
      "2222222222222222",
      "       2        ",
      "       2        ",
      "       2        ",
      "       2        ",
      "       2        ",
      "       2        ",
      "       2        ",
      "       2        ",
      "       2        ",
      "       2        ",
      "       2   1    ",
      "       2        ",
      "       2        "
    ]
  ],
  "palette": {
    "palette": [
      {
        "char": "!",
        "block": "minecraft:bookshelf"
      },
      {
        "char": "$",
        "block": "minecraft:coarse_dirt"
      },
      {
        "char": "%",
        "block": "minecraft:dark_oak_door[facing=south,half=lower,hinge=left,open=false,powered=false]"
      },
      {
        "char": "&",
        "block": "minecraft:dark_oak_door[facing=south,half=lower,hinge=right,open=false,powered=false]"
      },
      {
        "char": "'",
        "block": "minecraft:dark_oak_door[facing=south,half=upper,hinge=left,open=false,powered=false]"
      },
      {
        "char": "(",
        "block": "minecraft:dark_oak_door[facing=south,half=upper,hinge=right,open=false,powered=false]"
      },
      {
        "char": ")",
        "block": "minecraft:dark_oak_door[facing=west,half=lower,hinge=left,open=false,powered=false]"
      },
      {
        "char": "*",
        "block": "minecraft:dark_oak_door[facing=west,half=lower,hinge=right,open=false,powered=false]"
      },
      {
        "char": "+",
        "block": "minecraft:dark_oak_door[facing=west,half=upper,hinge=left,open=false,powered=false]"
      },
      {
        "char": ",",
        "block": "minecraft:dark_oak_door[facing=west,half=upper,hinge=right,open=false,powered=false]"
      },
      {
        "char": "-",
        "block": "minecraft:dark_oak_slab[type=bottom,waterlogged=false]"
      },
      {
        "char": ".",
        "block": "minecraft:dark_oak_stairs[facing=south,half=bottom,shape=straight,waterlogged=false]"
      },
      {
        "char": "/",
        "block": "minecraft:gravel"
      },
      {
        "char": "0",
        "block": "minecraft:polished_andesite"
      },
      {
        "char": "1",
        "block": "minecraft:polished_andesite_stairs[facing=north,half=bottom,shape=straight,waterlogged=false]"
      },
      {
        "char": "2",
        "block": "minecraft:polished_tuff"
      },
      {
        "char": "3",
        "block": "tfmg:asphalt"
      }
    ]
  }
}
