{
  "xsize": 16,
  "zsize": 16,
  "slices": [
    [
      "                ",
      "                ",
      "                ",
      "                ",
      "                ",
      "                ",
      "  ++++++        ",
      "  ++++++!+      ",
      "         +      ",
      "         +      ",
      "         +      ",
      "         +      ",
      "         +      ",
      "         +      ",
      "         +      ",
      "         +      "
    ],
    [
      "                ",
      "                ",
      "                ",
      "                ",
      "                ",
      "                ",
      "  ++++++        ",
      "  ++++++++      ",
      "         +      ",
      "         +      ",
      "         +      ",
      "         +      ",
      "         +      ",
      "         +      ",
      "         +      ",
      "         +      "
    ],
    [
      "                ",
      "                ",
      "                ",
      "                ",
      "                ",
      "                ",
      "  ++++++        ",
      "  ++++++++      ",
      "         +      ",
      "         +      ",
      "         +      ",
      "         +      ",
      "         +      ",
      "         +      ",
      "         +      ",
      "         +      "
    ],
    [
      "                ",
      "                ",
      "                ",
      "                ",
      "                ",
      "  &&&&&&&       ",
      "  &&&&&&&       ",
      "  &&&&&&&+      ",
      "  &&&&&&&+      ",
      "  '''''''+      ",
      "  '''''''+      ",
      "  '''''''+      ",
      "  '''''''+      ",
      "  '''''''+      ",
      "  '''''''+      ",
      "  '''''''+      "
    ],
    [
      "                ",
      "                ",
      "                ",
      "                ",
      "                ",
      "                ",
      "  ++++++        ",
      "  ++++++++      ",
      "         +      ",
      "         +      ",
      "  $$     +      ",
      "  ) %%%  +      ",
      "        ,+      ",
      "         +      ",
      "     (   +      ",
      "         +      "
    ],
    [
      "                ",
      "                ",
      "                ",
      "                ",
      "                ",
      "                ",
      "  ++++++        ",
      "  ++++++++      ",
      "         +      ",
      "         +      ",
      "   *     +      ",
      "         +      ",
      "        *+      ",
      "         +      ",
      "         +      ",
      "         +      "
    ]
  ],
  "palette": {
    "palette": [
      {
        "char": "!",
        "block": "create:framed_glass"
      },
      {
        "char": "$",
        "block": "minecraft:barrel[facing=up,open=false]"
      },
      {
        "char": "%",
        "block": "minecraft:dark_oak_stairs[facing=south,half=bottom,shape=straight,waterlogged=false]"
      },
      {
        "char": "&",
        "block": "minecraft:smooth_stone_slab[type=bottom,waterlogged=false]"
      },
      {
        "char": "'",
        "block": "minecraft:spruce_planks"
      },
      {
        "char": "(",
        "block": "minecraft:spruce_slab[type=bottom,waterlogged=false]"
      },
      {
        "char": ")",
        "block": "kubejs:ruined_cauldron"
      },
      {
        "char": "*",
        "block": "supplementaries:item_shelf"
      },
      {
        "char": "+",
        "block": "the_wasteland_reworked:decayed_planks"
      },
      {
        "char": ",",
        "block": "the_wasteland_reworked:radio"
      }
    ]
  }
}
