{
  "xsize": 16,
  "zsize": 16,
  "slices": [
    [
      "!!!!!!!!!       ",
      "!!!!!!!!!       ",
      "!!!!!!!!!       ",
      "!!!!!!!!!       ",
      "!!!!!!!!!       ",
      "!!!!!!!!!       ",
      "!!!!!!!!!       ",
      "!!!!!!!!!       ",
      "     $          ",
      "     $          ",
      "     $          ",
      "     $          ",
      "     $          ",
      "     $          ",
      "     $          ",
      "     $          "
    ],
    [
      "!!!!!!!!!       ",
      "!!!!!!!!!       ",
      "!!!!!!!!!       ",
      "!!!!!!!!!       ",
      "!!!!!!!!!       ",
      "!!!!!!!!!       ",
      "!!!!!!!!!       ",
      "!!!!!!!!!       ",
      "     $          ",
      "     $          ",
      "     $          ",
      "     $          ",
      "     $          ",
      "     $          ",
      "     $          ",
      "     $          "
    ],
    [
      "!!!!!!!!!       ",
      "!!!!!!!!!       ",
      "!!!!!!!!!       ",
      "!!!!!!!!!       ",
      "!!!!!!!!!       ",
      "!!!!!!!!!       ",
      "!!!!!!!!!       ",
      "!!!!!!!!!       ",
      "     $          ",
      "     $          ",
      "     $          ",
      "     $          ",
      "     $          ",
      "     $          ",
      "     $          ",
      "     $          "
    ],
    [
      "!!!!!!!!!       ",
      "!!!!!!!!!       ",
      "!!!!!!!!!       ",
      "!!!!!!!!!       ",
      "!!!!!!!!!       ",
      "!!!!!!!!!       ",
      "!!!!!!!!!       ",
      "!!!!!!!!!       ",
      "     $          ",
      "     $          ",
      "     $          ",
      "     $          ",
      "     $          ",
      "     $          ",
      "     $          ",
      "     $          "
    ],
    [
      "!!!!!!!!!       ",
      "!!!!!!!!!       ",
      "!!!!!!!!!       ",
      "!!!!!!!!!       ",
      "!!!!!!!!!       ",
      "!!!!!!!!!       ",
      "!!!!!!!!!       ",
      "!!!!!!!!!       ",
      "&&&&&$          ",
      "&&&&&$          ",
      "&&&&&$          ",
      "&&&&&$          ",
      "&&&&&$          ",
      "&&&&&$          ",
      "&&&&&$          ",
      "&&&&&$          "
    ],
    [
      "%    $          ",
      "%    $          ",
      "%    $          ",
      "%    $          ",
      "%    $          ",
      "%    $          ",
      "%    $          ",
      "%    $          ",
      "%    $          ",
      "%    $          ",
      "%    $          ",
      "%    $          ",
      "%    $          ",
      "%    $          ",
      "%    $          ",
      "%    $          "
    ]
  ],
  "palette": {
    "palette": [
      {
        "char": "!",
        "block": "minecraft:gravel"
      },
      {
        "char": "$",
        "block": "minecraft:mud_bricks"
      },
      {
        "char": "%",
        "block": "minecraft:scaffolding"
      },
      {
        "char": "&",
        "block": "tfmg:factory_floor"
      }
    ]
  }
}
