{
  "xsize": 16,
  "zsize": 16,
  "slices": [
    [
      "    )        )  ",
      "    )        )  ",
      "    )        )  ",
      "    )        )  ",
      "    )        )  ",
      "    )        )  ",
      "    )        )  ",
      "    )        )  ",
      "    )        )  ",
      "    )        )  ",
      "    )        )  ",
      "    ))))))))))))",
      "                ",
      "                ",
      "                ",
      "                "
    ],
    [
      "    )           ",
      "    )           ",
      "    )           ",
      "    )           ",
      "    )           ",
      "    )           ",
      "    )           ",
      "    )           ",
      "    )           ",
      "    )           ",
      "    )           ",
      "    ))))))))))))",
      "                ",
      "                ",
      "                ",
      "                "
    ],
    [
      "    %(((((((((((",
      "    %(((((((((((",
      "    %(((((((((((",
      "    %(((((((((((",
      "    %(((((((((((",
      "    %(((((((((((",
      "    %(((((((((((",
      "    %(((((((((((",
      "    %(((((((((((",
      "    %(((((((((((",
      "    %(((((((((((",
      "    %)))))))))))",
      "                ",
      "                ",
      "                ",
      "                "
    ],
    [
      "    ) &&        ",
      "    ) &&        ",
      "    ) &&        ",
      "    ))))))*)))))",
      "    )           ",
      "    ) $$$$$$$   ",
      "    )           ",
      "    ))))))*)))))",
      "    )      '''  ",
      "    )      '''  ",
      "    )           ",
      "    ))))))))))))",
      "                ",
      "                ",
      "                ",
      "                "
    ],
    [
      "    ) &&        ",
      "    ! &&        ",
      "    ! &&        ",
      "    ))))))+)))))",
      "    )           ",
      "    ) $$$$$$$   ",
      "    )           ",
      "    !)))))+)))))",
      "    !           ",
      "    )           ",
      "    )           ",
      "    ))))))))))))",
      "                ",
      "                ",
      "                ",
      "                "
    ],
    [
      "    ) &&        ",
      "    ! &&        ",
      "    ! &&        ",
      "    ))))))))))))",
      "    )           ",
      "    ) $$$$$$$   ",
      "    )           ",
      "    !)))))))))))",
      "    !           ",
      "    )           ",
      "    )           ",
      "    ))))))))))))",
      "                ",
      "                ",
      "                ",
      "                "
    ]
  ],
  "palette": {
    "palette": [
      {
        "char": "!",
        "block": "create:framed_glass"
      },
      {
        "char": "$",
        "block": "immersiveengineering:sheetmetal_steel"
      },
      {
        "char": "%",
        "block": "minecraft:blue_concrete"
      },
      {
        "char": "&",
        "block": "minecraft:bookshelf"
      },
      {
        "char": "'",
        "block": "minecraft:dark_oak_slab[type=bottom,waterlogged=false]"
      },
      {
        "char": "(",
        "block": "minecraft:polished_andesite"
      },
      {
        "char": ")",
        "block": "minecraft:polished_deepslate"
      },
      {
        "char": "*",
        "block": "minecraft:spruce_door[facing=south,half=lower,hinge=left,open=false,powered=false]"
      },
      {
        "char": "+",
        "block": "minecraft:spruce_door[facing=south,half=upper,hinge=left,open=false,powered=false]"
      }
    ]
  }
}
