{
  "xsize": 16,
  "zsize": 16,
  "slices": [
    [
      "&&&&&&&&&&$$!&&&",
      "&&&&&&&&$$!&&&&&",
      "&&&&&&$$!&&&&&&&",
      "&&&&$$!&&&&&&&&&",
      "&&$$!&&&&&&&&&&&",
      "$$!&&&&&&&&&&&&&",
      "!&&&&&&&&&&&&&&&",
      "&&&&&&&&&&&&&&&$",
      "&&&&&&&&&&&&&$$!",
      "&&&&&&&&&&&$$!&&",
      "&&&&&&&&&$$!&&&&",
      "&&&&&&&$$!&&&&&&",
      "&&&&&$$!&&&&&&&&",
      "&&&$$!&&&&&&&&&&",
      "&$$!&&&&&&&&&&&&",
      "$!&&&&&&&&&&&&&&"
    ],
    [
      "''''''''''''''''",
      "''''''''''''''''",
      "''''''''''''''''",
      "''''''''''''''''",
      "''''''''''''''''",
      "''''''''''''''''",
      "''''''''''''''''",
      "''''''''''''''''",
      "''''''''''''''''",
      "''''''''''''''''",
      "''''''''''''''''",
      "''''''''''''''''",
      "''''''''''''''''",
      "''''''''''''''''",
      "''''''''''''''''",
      "''''''''''''''''"
    ],
    [
      "       %%%     %",
      "       %%%     %",
      "       %%%     %",
      "       %%%     %",
      "       %%%     %",
      "       %%%     %",
      "       %%%     %",
      "       %%%     %",
      "       %%%     %",
      "       %%%     %",
      "       %%%     %",
      "       %%%     %",
      "       %%%     %",
      "       %%%     %",
      "       %%%     %",
      "       %%%     %"
    ],
    [
      "       %%%     %",
      "       %%%     %",
      "       %%%     %",
      "       %%%     %",
      "       %%%     %",
      "       %%%     %",
      "       %%%     %",
      "       %%%     %",
      "       %%%     %",
      "       %%%     %",
      "       %%%     %",
      "       %%%     %",
      "       %%%     %",
      "       %%%     %",
      "       %%%     %",
      "       %%%     %"
    ],
    [
      "       %%%     %",
      "       %%%     %",
      "       %%%     %",
      "       %%%     %",
      "       %%%     %",
      "       %%%     %",
      "       %%%     %",
      "       %%%     %",
      "       %%%     %",
      "       %%%     %",
      "       %%%     %",
      "       %%%     %",
      "       %%%     %",
      "       %%%     %",
      "       %%%     %",
      "       %%%     %"
    ],
    [
      "       %%%     %",
      "       %%%     %",
      "       %%%     %",
      "       %%%     %",
      "       %%%     %",
      "       %%%     %",
      "       %%%     %",
      "       %%%     %",
      "       %%%     %",
      "       %%%     %",
      "       %%%     %",
      "       %%%     %",
      "       %%%     %",
      "       %%%     %",
      "       %%%     %",
      "       %%%     %"
    ]
  ],
  "palette": {
    "palette": [
      {
        "char": "!",
        "block": "minecraft:coarse_dirt"
      },
      {
        "char": "$",
        "block": "minecraft:gravel"
      },
      {
        "char": "%",
        "block": "minecraft:scaffolding"
      },
      {
        "char": "&",
        "block": "tfmg:asphalt"
      },
      {
        "char": "'",
        "block": "tfmg:factory_floor"
      }
    ]
  }
}
