{
  "xsize": 16,
  "zsize": 16,
  "slices": [
    [
      "                ",
      "                ",
      "                ",
      "                ",
      "      ..   ..   ",
      "   $$$$$$$$$$$$$",
      "   $            ",
      "  )$            ",
      "  )$            ",
      "  )$            ",
      "  )$            ",
      "   $            ",
      "   $            ",
      "   $            ",
      "  )$111111111111",
      "  )$            "
    ],
    [
      "                ",
      "                ",
      "                ",
      "                ",
      "                ",
      "   $$$$$$$$$$$$$",
      "   $            ",
      "   $            ",
      "   $            ",
      "   $            ",
      "   $            ",
      "   $            ",
      "   $            ",
      "   $            ",
      "   $            ",
      "   $            "
    ],
    [
      "                ",
      "                ",
      "                ",
      "      &&&&&&&&&&",
      "      &&&&&&&&&&",
      "   $$$&&&&&&&&&&",
      "   $            ",
      "   $            ",
      " &&&            ",
      " &&&            ",
      " &&&            ",
      " &&&            ",
      " &&&            ",
      " &&&            ",
      "   $            ",
      "   $            "
    ],
    [
      "                ",
      "                ",
      "                ",
      "      /        /",
      "  **************",
      "  **************",
      "   $%%%%%%%%%%%%",
      "   $%%%%%%%%%%%%",
      " / $%%%%%%%%%%%%",
      "   $%%%%%%%%%%%%",
      "   $%%%%%%%%%%%%",
      "   $%%%%%%%%%%%%",
      "   $%%%%%%%%%%%%",
      " / $%%%%%%%%%%%%",
      "   $%%%%%%%%%%%%",
      "   $%%%%%%%%%%%%"
    ],
    [
      "                ",
      "                ",
      "                ",
      "                ",
      "      --   --   ",
      "   $$$$$$$$$$$$$",
      "   $            ",
      "  $$            ",
      "   $  (         ",
      "   $            ",
      "   $     '      ",
      "   $            ",
      "   $            ",
      "   $            ",
      "  $$111111+11111",
      "   $            "
    ],
    [
      "                ",
      "                ",
      "                ",
      "                ",
      "                ",
      "   $$0!!0$0!!0$0",
      "   $            ",
      "  $$            ",
      "   !            ",
      "   !            ",
      "   $            ",
      "   $            ",
      "   $            ",
      "   $            ",
      "  $$111111,11111",
      "   !            "
    ]
  ],
  "palette": {
    "palette": [
      {
        "char": "!",
        "block": "create:framed_glass"
      },
      {
        "char": "$",
        "block": "minecraft:mud_bricks"
      },
      {
        "char": "%",
        "block": "minecraft:oak_planks"
      },
      {
        "char": "&",
        "block": "minecraft:oak_slab[type=top,waterlogged=false]"
      },
      {
        "char": "'",
        "block": "minecraft:oak_stairs[facing=east,half=bottom,shape=straight,waterlogged=false]"
      },
      {
        "char": "(",
        "block": "minecraft:smoker[facing=south,lit=false]"
      },
      {
        "char": ")",
        "block": "minecraft:smooth_stone"
      },
      {
        "char": "*",
        "block": "minecraft:smooth_stone_slab[type=top,waterlogged=false]"
      },
      {
        "char": "+",
        "block": "minecraft:spruce_door[facing=south,half=lower,hinge=left,open=false,powered=false]"
      },
      {
        "char": ",",
        "block": "minecraft:spruce_door[facing=south,half=upper,hinge=left,open=false,powered=false]"
      },
      {
        "char": "-",
        "block": "minecraft:spruce_slab[type=bottom,waterlogged=false]"
      },
      {
        "char": ".",
        "block": "minecraft:spruce_slab[type=top,waterlogged=false]"
      },
      {
        "char": "/",
        "block": "minecraft:stripped_oak_log[axis=y]"
      },
      {
        "char": "0",
        "block": "minecraft:stripped_spruce_log[axis=y]"
      },
      {
        "char": "1",
        "block": "minecraft:stripped_spruce_wood"
      }
    ]
  }
}
