{
  "xsize": 16,
  "zsize": 16,
  "slices": [
    [
      "       (        ",
      "       (        ",
      "       (        ",
      "       (        ",
      "''''''''''''''''",
      "                ",
      "                ",
      "                ",
      "''''''''''''''''",
      "       (        ",
      "       (        ",
      "       (        ",
      "       &        ",
      "       (        ",
      "       (((((((((",
      "       (        "
    ],
    [
      "       (        ",
      "       (        ",
      "       (        ",
      "       (        ",
      "''''''''''''''''",
      "                ",
      "                ",
      "                ",
      "''''''''''''''''",
      "       (        ",
      "       (        ",
      "       (        ",
      "       (        ",
      "       (        ",
      "       (((((((((",
      "       (        "
    ],
    [
      "       (        ",
      "       (        ",
      "       (        ",
      "       (        ",
      "''''''''''''''''",
      "                ",
      "                ",
      "                ",
      "''''''''''''''''",
      "       (        ",
      "       (        ",
      "       (        ",
      "       (        ",
      "       (        ",
      "       (((((((((",
      "       (        "
    ],
    [
      "                ",
      "                ",
      "                ",
      "                ",
      "''''''''''''''''",
      "                ",
      "                ",
      "                ",
      "''''''''''''''''",
      "                ",
      "                ",
      "                ",
      "                ",
      "                ",
      "                ",
      "                "
    ],
    [
      "                ",
      "                ",
      "                ",
      "                ",
      "                ",
      "                ",
      "                ",
      "                ",
      "                ",
      "                ",
      "                ",
      "                ",
      "                ",
      "                ",
      "                ",
      "                "
    ],
    [
      "$$$$$$$$$$$$$$$$",
      "$$$$$$$$$$$!!$$$",
      "$$$$$$$$$$$!!$$$",
      "$$$$$$$$$$$!!$$$",
      "$$$$$$$$$$$!!$$$",
      "$$$$$$$$$$$!!$$$",
      "$$$$$$$$$$$!!$$$",
      "$$$$$$$$$$$!!$$$",
      "$$$$$$$$$$$$$$$$",
      "$$$$$$$$$$$$$$$$",
      "$$$$$$$$$$$$$$$$",
      "%%%%$$$$$$$$$$$$",
      "%%%%$$$$$$$$$$$$",
      "%%%%$$$$$$$$$$$$",
      "%%%%$$$$$$$$$$$$",
      "%%%%$$$$$$$$$$$$"
    ]
  ],
  "palette": {
    "palette": [
      {
        "char": "!",
        "block": "create:framed_glass"
      },
      {
        "char": "$",
        "block": "minecraft:dark_prismarine"
      },
      {
        "char": "%",
        "block": "minecraft:oak_planks"
      },
      {
        "char": "&",
        "block": "minecraft:spruce_door[facing=east,half=upper,hinge=left,open=false,powered=false]"
      },
      {
        "char": "'",
        "block": "minecraft:stripped_oak_wood"
      },
      {
        "char": "(",
        "block": "minecraft:stripped_spruce_wood"
      }
    ]
  }
}
