{
  "xsize": 16,
  "zsize": 16,
  "slices": [
    [
      "   +       *   *",
      "   +       *   *",
      "   +       * ( *",
      "   +       *   *",
      "   +       *   *",
      "   +       *   *",
      "   +       *   *",
      "&&&&&&&&&&&&&&&&",
      "                ",
      "                ",
      "                ",
      "                ",
      "                ",
      "                ",
      "                ",
      "                "
    ],
    [
      "           *   *",
      "           * ( *",
      "           *   *",
      "           *   *",
      "           *   *",
      "           *   *",
      "           *   *",
      "&&&&&&&&&&&&&&&&",
      "                ",
      "                ",
      "                ",
      "                ",
      "                ",
      "                ",
      "                ",
      "                "
    ],
    [
      "             (  ",
      "                ",
      "                ",
      "                ",
      "                ",
      "                ",
      "                ",
      "&&&&&&&&&&&&&&&&",
      "                ",
      "                ",
      "                ",
      "                ",
      "                ",
      "                ",
      "                ",
      "                "
    ],
    [
      "''''''''''''' ''",
      "''''''''''''' ''",
      "''''''''''''''''",
      "''''''''''''''''",
      "''''''''''''''''",
      "''''''''''''''''",
      "''''''''''''''''",
      "))))))))))))))))",
      "))))))))))))))))",
      "                ",
      "                ",
      "                ",
      "                ",
      "                ",
      "                ",
      "                "
    ],
    [
      "   +       *   *",
      "   + %     *   *",
      "   + $     *   *",
      "   +       *   *",
      "   +       *   *",
      "   +       * ( *",
      "   +       *   *",
      "&&&&&&&&&&&&&&&&",
      "                ",
      "                ",
      "                ",
      "                ",
      "                ",
      "                ",
      "                ",
      "                "
    ],
    [
      "   +       *   *",
      "   +       *   *",
      "   +       *   *",
      "   +       *   *",
      "   +       * ( *",
      "   +       *   *",
      "   +       *   *",
      "!!&&&&!!&&&&&&&&",
      "                ",
      "                ",
      "                ",
      "                ",
      "                ",
      "                ",
      "                ",
      "                "
    ]
  ],
  "palette": {
    "palette": [
      {
        "char": "!",
        "block": "create:framed_glass"
      },
      {
        "char": "$",
        "block": "minecraft:gray_bed[facing=north,occupied=false,part=foot]"
      },
      {
        "char": "%",
        "block": "minecraft:gray_bed[facing=north,occupied=false,part=head]"
      },
      {
        "char": "&",
        "block": "minecraft:mud_bricks"
      },
      {
        "char": "'",
        "block": "minecraft:oak_planks"
      },
      {
        "char": "(",
        "block": "minecraft:oak_stairs[facing=north,half=bottom,shape=straight,waterlogged=false]"
      },
      {
        "char": ")",
        "block": "minecraft:smooth_stone_slab[type=top,waterlogged=false]"
      },
      {
        "char": "*",
        "block": "minecraft:stripped_oak_wood"
      },
      {
        "char": "+",
        "block": "minecraft:stripped_spruce_wood"
      }
    ]
  }
}
