{
  "xsize": 16,
  "zsize": 16,
  "slices": [
    [
      "+++++++++++     ",
      "+++++++++++     ",
      "+++++++++''     ",
      "+++++++''$+     ",
      "+++++''$+++     ",
      "+++''$+++++     ",
      "+''$+++++++     ",
      "'$+++++++++     ",
      "+++++++++++     ",
      "+++++++++++     ",
      "+++++++++++     ",
      "++++++++++'     ",
      "++++++++''$     ",
      "++++++''$++     ",
      "++++''$++++     ",
      "++''$++++++     "
    ],
    [
      "((((((          ",
      "((((((          ",
      "((((((          ",
      "((((((          ",
      "((((((          ",
      "((((((          ",
      "((((((          ",
      "((((((          ",
      "((((((          ",
      "((((((          ",
      "((((((          ",
      "((((((          ",
      "((((((          ",
      "((((((          ",
      "((((((          ",
      "((((((          "
    ],
    [
      "     *          ",
      "     *          ",
      ")))))*          ",
      "     *          ",
      "     *          ",
      "&&&& *          ",
      "     *          ",
      "     *          ",
      "&&&& *          ",
      "     *          ",
      "     *          ",
      "&&&& *          ",
      "     *          ",
      "     *          ",
      "%    *          ",
      "%    *          "
    ],
    [
      "     *          ",
      "     !          ",
      ")))))!          ",
      "     *          ",
      "     *          ",
      "     *          ",
      "     *          ",
      "     *          ",
      "     !          ",
      "     !          ",
      "     *          ",
      "     *          ",
      "     *          ",
      "     *          ",
      "     *          ",
      "     !          "
    ],
    [
      "     *          ",
      "     !          ",
      ")))))!          ",
      "     *          ",
      "     *          ",
      "     *          ",
      "     *          ",
      "     *          ",
      "     !          ",
      "     !          ",
      "     *          ",
      "     *          ",
      "     *          ",
      "     *          ",
      "     *          ",
      "     !          "
    ],
    [
      "     *          ",
      "     *          ",
      ")))))*          ",
      "     *          ",
      "     *          ",
      "     *          ",
      "     *          ",
      "     *          ",
      "     *          ",
      "     *          ",
      "     *          ",
      "     *          ",
      "     *          ",
      "     *          ",
      "     *          ",
      "     *          "
    ]
  ],
  "palette": {
    "palette": [
      {
        "char": "!",
        "block": "create:framed_glass"
      },
      {
        "char": "$",
        "block": "minecraft:coarse_dirt"
      },
      {
        "char": "%",
        "block": "minecraft:dark_oak_slab[type=bottom,waterlogged=false]"
      },
      {
        "char": "&",
        "block": "minecraft:dark_oak_stairs[facing=south,half=bottom,shape=straight,waterlogged=false]"
      },
      {
        "char": "'",
        "block": "minecraft:gravel"
      },
      {
        "char": "(",
        "block": "minecraft:polished_andesite"
      },
      {
        "char": ")",
        "block": "minecraft:polished_tuff"
      },
      {
        "char": "*",
        "block": "minecraft:tuff_bricks"
      },
      {
        "char": "+",
        "block": "tfmg:asphalt"
      }
    ]
  }
}
