{
  "xsize": 16,
  "zsize": 16,
  "slices": [
    [
      "....''%.........",
      "..''%...........",
      "''%.............",
      "%...............",
      "...............'",
      ".............''%",
      "...........''%..",
      ".........''%....",
      ".......''%......",
      ".....''%........",
      "...''%..........",
      ".''%............",
      "'%..............",
      "................",
      "..............''",
      "............''%."
    ],
    [
      "   )))))))))))))",
      "   )))))))))))))",
      "   )))))))))))))",
      "   )))))))))))))",
      "   )))))))))))))",
      "   )))))))))))))",
      "   )))))))))))))",
      "   )))))))))))))",
      "   )))))))))))))",
      "   )))))))))))))",
      "   )))))))))))))",
      "   )))))))))))))",
      "   )))))))))))))",
      "   )))))))))))))",
      "   )))))))))))))",
      "   )))))))))))))"
    ],
    [
      "   (            ",
      "   (            ",
      "   (        +   ",
      "   (            ",
      "   (            ",
      "   ( ///////////",
      "   ( ///////////",
      "   (            ",
      "   ($$$$$$,$$$$$",
      "   (            ",
      "   (            ",
      "   (  *  &   !  ",
      "   (            ",
      "   (            ",
      "   (            ",
      "   (            "
    ],
    [
      "   (            ",
      "   (            ",
      "   (            ",
      "   (            ",
      "   (            ",
      "   (            ",
      "   (            ",
      "   (            ",
      "   ($$$$$$-$$$$$",
      "   (            ",
      "   (            ",
      "   (            ",
      "   (            ",
      "   (            ",
      "   (            ",
      "   (            "
    ],
    [
      "   (            ",
      "   (            ",
      "   (            ",
      "   (            ",
      "   (            ",
      "   (            ",
      "   (            ",
      "   (            ",
      "   ($$$$$$$$$$$$",
      "   (            ",
      "   (            ",
      "   (            ",
      "   (            ",
      "   (            ",
      "   (            ",
      "   (            "
    ],
    [
      "   (            ",
      "   (            ",
      "   (            ",
      "   (            ",
      "   (            ",
      "   (            ",
      "   (            ",
      "   (            ",
      "   ($$$$$$$$$$$$",
      "   (            ",
      "   (            ",
      "   (            ",
      "   (            ",
      "   (            ",
      "   (            ",
      "   (            "
    ]
  ],
  "palette": {
    "palette": [
      {
        "char": "!",
        "block": "minecraft:barrel[facing=up,open=false]"
      },
      {
        "char": "$",
        "block": "minecraft:bricks"
      },
      {
        "char": "%",
        "block": "minecraft:coarse_dirt"
      },
      {
        "char": "&",
        "block": "minecraft:furnace[facing=south,lit=false]"
      },
      {
        "char": "'",
        "block": "minecraft:gravel"
      },
      {
        "char": "(",
        "block": "minecraft:mud_bricks"
      },
      {
        "char": ")",
        "block": "minecraft:oak_planks"
      },
      {
        "char": "*",
        "block": "minecraft:smoker[facing=south,lit=false]"
      },
      {
        "char": "+",
        "block": "minecraft:spawner",
        "tag": {
          "id": "minecraft:mob_spawner",
          "Delay": 200,
          "MinSpawnDelay": 240,
          "MaxSpawnDelay": 720,
          "SpawnCount": 2,
          "MaxNearbyEntities": 6,
          "RequiredPlayerRange": 14,
          "SpawnRange": 4,
          "SpawnData": {
            "entity": {
              "id": "the_wasteland_reworked:ghoul"
            }
          },
          "SpawnPotentials": [
            {
              "weight": 1,
              "data": {
                "entity": {
                  "id": "the_wasteland_reworked:ghoul"
                }
              }
            }
          ]
        }
      },
      {
        "char": ",",
        "block": "minecraft:spruce_door[facing=south,half=lower,hinge=left,open=false,powered=false]"
      },
      {
        "char": "-",
        "block": "minecraft:spruce_door[facing=south,half=upper,hinge=left,open=false,powered=false]"
      },
      {
        "char": ".",
        "block": "tfmg:asphalt"
      },
      {
        "char": "/",
        "block": "zvhouses:spruce_countertop"
      }
    ]
  }
}
