{
  "xsize": 16,
  "zsize": 16,
  "slices": [
    [
      "7777&&%777777777",
      "77&&%77777777777",
      "&&%7777777777777",
      "%777777777777777",
      "777777777777777&",
      "7777777777777&&%",
      "77777777777&&%77",
      "777777777&&%7777",
      "7777777&&%777777",
      "77777&&%77777777",
      "777&&%7777777777",
      "7&&%777777777777",
      "&%77777777777777",
      "7777777777777777",
      "77777777777777&&",
      "777777777777&&%7"
    ],
    [
      "    /22&$&&2&&2$",
      "    /2$2$&$&&22$",
      "    /22222222222",
      "    ////////////",
      "    ////////////",
      "    ////////////",
      "    ////////////",
      "    ////////////",
      "    ////////////",
      "    ////////////",
      "    ////////////",
      "    ////////////",
      "    ////////////",
      "    //////////22",
      "    //////////22",
      "    //////////22"
    ],
    [
      "    .  & && $&  ",
      "    .    & $$   ",
      "    .           ",
      "    ......3.....",
      "    .     0     ",
      "    .  55  55 8 ",
      "    .  6   6    ",
      "    .           ",
      "    .           ",
      "    .  55  55   ",
      "    .  6   6    ",
      "    .           ",
      "    111111111 *+",
      "    1        1  ",
      "    1        (  ",
      "    1  '     1  "
    ],
    [
      "    .  $ $&  $  ",
      "    .    $      ",
      "    .           ",
      "    ......4.....",
      "    .           ",
      "    .     0     ",
      "    !           ",
      "    !           ",
      "    .           ",
      "    .           ",
      "    .           ",
      "    .           ",
      "    111111111 ,-",
      "    1        1  ",
      "    1        )  ",
      "    1        1  "
    ],
    [
      "    .     $     ",
      "    .           ",
      "    .           ",
      "    ............",
      "    .           ",
      "    .           ",
      "    !     0     ",
      "    !           ",
      "    .           ",
      "    .           ",
      "    .           ",
      "    .           ",
      "    111111111   ",
      "    1        1  ",
      "    1        1  ",
      "    1        !  "
    ],
    [
      "    .           ",
      "    .           ",
      "    .           ",
      "    ............",
      "    .           ",
      "    .           ",
      "    .           ",
      "    .     0     ",
      "    .           ",
      "    .           ",
      "    .           ",
      "    .           ",
      "    111111111   ",
      "    1        1  ",
      "    1        1  ",
      "    1        !  "
    ]
  ],
  "palette": {
    "palette": [
      {
        "char": "!",
        "block": "create:framed_glass"
      },
      {
        "char": "$",
        "block": "immersiveengineering:concrete_brick_cracked"
      },
      {
        "char": "%",
        "block": "minecraft:coarse_dirt"
      },
      {
        "char": "&",
        "block": "minecraft:gravel"
      },
      {
        "char": "'",
        "block": "minecraft:gray_bed[facing=south,occupied=false,part=foot]"
      },
      {
        "char": "(",
        "block": "minecraft:iron_door[facing=east,half=lower,hinge=left,open=false,powered=false]"
      },
      {
        "char": ")",
        "block": "minecraft:iron_door[facing=east,half=upper,hinge=left,open=false,powered=false]"
      },
      {
        "char": "*",
        "block": "minecraft:iron_door[facing=south,half=lower,hinge=left,open=false,powered=false]"
      },
      {
        "char": "+",
        "block": "minecraft:iron_door[facing=south,half=lower,hinge=right,open=false,powered=false]"
      },
      {
        "char": ",",
        "block": "minecraft:iron_door[facing=south,half=upper,hinge=left,open=false,powered=false]"
      },
      {
        "char": "-",
        "block": "minecraft:iron_door[facing=south,half=upper,hinge=right,open=false,powered=false]"
      },
      {
        "char": ".",
        "block": "minecraft:light_gray_concrete"
      },
      {
        "char": "/",
        "block": "minecraft:polished_andesite"
      },
      {
        "char": "0",
        "block": "minecraft:polished_andesite_stairs[facing=south,half=bottom,shape=straight,waterlogged=false]"
      },
      {
        "char": "1",
        "block": "minecraft:polished_deepslate"
      },
      {
        "char": "2",
        "block": "minecraft:smooth_stone"
      },
      {
        "char": "3",
        "block": "minecraft:spruce_door[facing=south,half=lower,hinge=left,open=false,powered=false]"
      },
      {
        "char": "4",
        "block": "minecraft:spruce_door[facing=south,half=upper,hinge=left,open=false,powered=false]"
      },
      {
        "char": "5",
        "block": "minecraft:spruce_slab[type=bottom,waterlogged=false]"
      },
      {
        "char": "6",
        "block": "minecraft:spruce_stairs[facing=north,half=bottom,shape=straight,waterlogged=false]"
      },
      {
        "char": "7",
        "block": "tfmg:asphalt"
      },
      {
        "char": "8",
        "block": "the_wasteland_reworked:radio"
      }
    ]
  }
}
