{
  "xsize": 16,
  "zsize": 16,
  "slices": [
    [
      "...........     ",
      "...........     ",
      "...........     ",
      "..........+     ",
      "........++&     ",
      "......++&..     ",
      "....++&....     ",
      "..++&......     ",
      "..&........     ",
      "                ",
      "                ",
      "                ",
      "                ",
      "                ",
      "                ",
      "                "
    ],
    [
      "----------      ",
      "   -------      ",
      "   -------      ",
      "$$ -------      ",
      "$$ -------      ",
      "$$ -------      ",
      "$$ -------      ",
      "$$ -------      ",
      "                ",
      "                ",
      "                ",
      "                ",
      "                ",
      "                ",
      "                ",
      "                "
    ],
    [
      "///%%'(%%%      ",
      "   %     %      ",
      "   %     %      ",
      "$$ %     %      ",
      "$$ %    ,%      ",
      "$$ %     %      ",
      "$$ %     %      ",
      "$$ %%%%%%%      ",
      "                ",
      "                ",
      "                ",
      "                ",
      "                ",
      "                ",
      "                ",
      "                "
    ],
    [
      "///%%)*%%%      ",
      "   %     %      ",
      "   %     %      ",
      "$$ %     %      ",
      "$$ %    ,%      ",
      "$$ %     %      ",
      "$$ %     %      ",
      "$$ %%%%%%%      ",
      "                ",
      "                ",
      "                ",
      "                ",
      "                ",
      "                ",
      "                ",
      "                "
    ],
    [
      "///%%  %%%      ",
      "   %     %      ",
      "   %     %      ",
      "   %     %      ",
      "   %    ,%      ",
      "   %     %      ",
      "   %     %      ",
      "   %%%%%%%      ",
      "                ",
      "                ",
      "                ",
      "                ",
      "                ",
      "                ",
      "                ",
      "                "
    ],
    [
      "///%%%%%%%      ",
      "   %     %      ",
      "   %     %      ",
      "   !     !      ",
      "   !    ,!      ",
      "   %     %      ",
      "   %     %      ",
      "   %%%%%%%      ",
      "                ",
      "                ",
      "                ",
      "                ",
      "                ",
      "                ",
      "                ",
      "                "
    ]
  ],
  "palette": {
    "palette": [
      {
        "char": "!",
        "block": "create:framed_glass"
      },
      {
        "char": "$",
        "block": "immersiveengineering:sheetmetal_steel"
      },
      {
        "char": "%",
        "block": "minecraft:bricks"
      },
      {
        "char": "&",
        "block": "minecraft:coarse_dirt"
      },
      {
        "char": "'",
        "block": "minecraft:dark_oak_door[facing=south,half=lower,hinge=left,open=false,powered=false]"
      },
      {
        "char": "(",
        "block": "minecraft:dark_oak_door[facing=south,half=lower,hinge=right,open=false,powered=false]"
      },
      {
        "char": ")",
        "block": "minecraft:dark_oak_door[facing=south,half=upper,hinge=left,open=false,powered=false]"
      },
      {
        "char": "*",
        "block": "minecraft:dark_oak_door[facing=south,half=upper,hinge=right,open=false,powered=false]"
      },
      {
        "char": "+",
        "block": "minecraft:gravel"
      },
      {
        "char": ",",
        "block": "minecraft:ladder[facing=west,waterlogged=false]"
      },
      {
        "char": "-",
        "block": "minecraft:polished_andesite"
      },
      {
        "char": ".",
        "block": "tfmg:asphalt"
      },
      {
        "char": "/",
        "block": "tfmg:cinder_block"
      }
    ]
  }
}
