{
  "xsize": 16,
  "zsize": 16,
  "slices": [
    [
      "................",
      "..'....'....'...",
      "................",
      ".$..............",
      "................",
      "................",
      "................",
      " ..''$..........",
      " ''$............",
      " $..............",
      " ...............",
      " .............''",
      " ...........''$.",
      " .........''$...",
      " .......''$.....",
      " $....''$......."
    ],
    [
      "                ",
      "                ",
      "                ",
      "                ",
      "               )",
      "  **           )",
      "  **           )",
      "    ,,,,,,,,,,,)",
      "    ,,,,,,,,,,,)",
      "    ,,,,,,,,,,,,",
      "    ,,,,,,,,,,,,",
      "    ,,,,,,,,,,,,",
      "    ,,,,,,,,,,,,",
      "    ,,,,,,,,,,,,",
      "    ,,,,,,,,,,,,",
      "    ,,,,,,,,,,,,"
    ],
    [
      "                ",
      "                ",
      "                ",
      "                ",
      "               ,",
      "  **           ,",
      "  **(         (,",
      "    (+++++++++(,",
      "    +          ,",
      "    +           ",
      "    +           ",
      "    +           ",
      "    +  %-&  %-& ",
      "    +           ",
      "    +           ",
      "    +           "
    ],
    [
      "                ",
      "                ",
      "                ",
      "                ",
      "               ,",
      "  **           ,",
      "  **(         (,",
      "    (+!!+!!+!!(,",
      "    +          ,",
      "    +           ",
      "    +           ",
      "    !           ",
      "    !           ",
      "    +           ",
      "    +           ",
      "    +           "
    ],
    [
      "                ",
      "                ",
      "                ",
      "                ",
      "               ,",
      "  **           ,",
      "  **(         (,",
      "    (+!!+!!+!!(,",
      "    +          ,",
      "    +           ",
      "    +           ",
      "    !           ",
      "    !           ",
      "    +           ",
      "    +           ",
      "    +           "
    ],
    [
      "                ",
      "                ",
      "                ",
      "                ",
      "               ,",
      "  **           ,",
      "  **(         (,",
      "    (+++++++++(,",
      "    +          ,",
      "    +           ",
      "    +           ",
      "    +           ",
      "    +           ",
      "    +           ",
      "    +           ",
      "    +           "
    ]
  ],
  "palette": {
    "palette": [
      {
        "char": "!",
        "block": "create:framed_glass"
      },
      {
        "char": "$",
        "block": "minecraft:coarse_dirt"
      },
      {
        "char": "%",
        "block": "minecraft:dark_oak_stairs[facing=east,half=bottom,shape=straight,waterlogged=false]"
      },
      {
        "char": "&",
        "block": "minecraft:dark_oak_stairs[facing=west,half=bottom,shape=straight,waterlogged=false]"
      },
      {
        "char": "'",
        "block": "minecraft:gravel"
      },
      {
        "char": "(",
        "block": "minecraft:mud_bricks"
      },
      {
        "char": ")",
        "block": "minecraft:polished_andesite"
      },
      {
        "char": "*",
        "block": "minecraft:polished_blackstone_bricks"
      },
      {
        "char": "+",
        "block": "minecraft:red_terracotta"
      },
      {
        "char": ",",
        "block": "minecraft:smooth_stone"
      },
      {
        "char": "-",
        "block": "minecraft:smooth_stone_slab[type=bottom,waterlogged=false]"
      },
      {
        "char": ".",
        "block": "tfmg:asphalt"
      }
    ]
  }
}
