{
  "xsize": 16,
  "zsize": 16,
  "slices": [
    [
      "            %   ",
      "           $$$$$",
      "           $    ",
      "           $    ",
      "           $    ",
      "           $    ",
      "           $    ",
      "           $    ",
      "           $    ",
      "           $    ",
      "           $    ",
      "           $    ",
      "           $    ",
      "           $    ",
      "           $    ",
      "%%%%%%%%%%%$    "
    ],
    [
      "            %   ",
      "           $$$$$",
      "           $    ",
      "           $    ",
      "           $    ",
      "           $    ",
      "           $    ",
      "           $    ",
      "           $    ",
      "           $    ",
      "           $    ",
      "           $    ",
      "           $    ",
      "           $    ",
      "           $    ",
      "%%%%%%%%%%%$    "
    ],
    [
      "            %   ",
      "           $$$$$",
      "           $    ",
      "           $    ",
      "           $    ",
      "           $    ",
      "           $    ",
      "           $    ",
      "           $    ",
      "           $    ",
      "           $    ",
      "           $    ",
      "           $    ",
      "           $    ",
      "           $    ",
      "%%%%%%%%%%%$    "
    ],
    [
      "            %   ",
      "           $$$$$",
      "           $    ",
      "           $    ",
      "           $    ",
      "           $    ",
      "           $    ",
      "           $    ",
      "           $    ",
      "           $    ",
      "           $    ",
      "           $    ",
      "           $    ",
      "           $    ",
      "           $    ",
      "%%%%%%%%%%%$    "
    ],
    [
      "            %   ",
      "           $$$$$",
      "           $    ",
      "           $    ",
      "           $    ",
      "           $    ",
      "           $    ",
      "           $    ",
      "           $    ",
      "           $    ",
      "           $    ",
      "           $    ",
      "           $    ",
      "           $    ",
      "           $    ",
      "%%%%%%%%%%%$    "
    ],
    [
      "            %   ",
      "           !!!!!",
      "           !!!!!",
      "           !!!!!",
      "           !!!!!",
      "           !!!!!",
      "           !!!!!",
      "           !!!!!",
      "           !!!!!",
      "           !!!!!",
      "           !!!!!",
      "           !!!!!",
      "           !!!!!",
      "           !!!!!",
      "           !!!!!",
      "%%%%%%%%%%%!!!!!"
    ]
  ],
  "palette": {
    "palette": [
      {
        "char": "!",
        "block": "minecraft:dark_oak_planks"
      },
      {
        "char": "$",
        "block": "minecraft:stripped_spruce_log"
      },
      {
        "char": "%",
        "block": "the_wasteland_reworked:decayed_planks"
      }
    ]
  }
}
