{
  "xsize": 16,
  "zsize": 16,
  "slices": [
    [
      "    %           ",
      "    %           ",
      "    %           ",
      "    %           ",
      "    %           ",
      "    %           ",
      "    %           ",
      "    %           ",
      "    %           ",
      "    %           ",
      "    %           ",
      "    %           ",
      "                ",
      "                ",
      "                ",
      "                "
    ],
    [
      "    %     ((((((",
      "    %     ((((((",
      "    %     ((((((",
      "    %     ((((((",
      "    %     ((((((",
      "    %     ((((((",
      "    %     ((((((",
      "    %     ((((((",
      "    %     ((((((",
      "    %     ((((((",
      "    %     ((((((",
      "    %     ((((((",
      "                ",
      "                ",
      "                ",
      "                "
    ],
    [
      "    &&&&&&$     ",
      "    &&&&&&$     ",
      "    &&&&&&$     ",
      "    &&&&&&$     ",
      "    &&&&&&$     ",
      "    &&&&&&$ !!!!",
      "    &&&&&&$     ",
      "    &&&&&&$     ",
      "    &&&&&&$     ",
      "    &&&&&&$     ",
      "    &&&&&&$     ",
      "    &&&&&&$ ''  ",
      "                ",
      "                ",
      "                ",
      "                "
    ],
    [
      "          $     ",
      "          $     ",
      "          $     ",
      "          $     ",
      "          $     ",
      "          $ !!!!",
      "          $     ",
      "          $     ",
      "          $     ",
      "          $     ",
      "          $     ",
      "          $     ",
      "                ",
      "                ",
      "                ",
      "                "
    ],
    [
      "          $     ",
      "          $     ",
      "          $     ",
      "          $     ",
      "          $     ",
      "          $ !!!!",
      "          $     ",
      "          $     ",
      "          $     ",
      "          $     ",
      "          $     ",
      "          $     ",
      "                ",
      "                ",
      "                ",
      "                "
    ],
    [
      "          $     ",
      "          $     ",
      "          $     ",
      "          $     ",
      "          $     ",
      "          $     ",
      "          $     ",
      "          $     ",
      "          $     ",
      "          $     ",
      "          $     ",
      "          $     ",
      "                ",
      "                ",
      "                ",
      "                "
    ]
  ],
  "palette": {
    "palette": [
      {
        "char": "!",
        "block": "minecraft:bookshelf"
      },
      {
        "char": "$",
        "block": "minecraft:light_gray_concrete"
      },
      {
        "char": "%",
        "block": "minecraft:polished_blackstone_bricks"
      },
      {
        "char": "&",
        "block": "minecraft:smooth_stone"
      },
      {
        "char": "'",
        "block": "minecraft:spruce_slab[type=bottom,waterlogged=false]"
      },
      {
        "char": "(",
        "block": "tfmg:factory_floor"
      }
    ]
  }
}
