{
  "xsize": 16,
  "zsize": 16,
  "slices": [
    [
      "(((((((((((((((3",
      "(((((((((((((((3",
      "(((((((((((((((%",
      "((((((((((((((($",
      "(((((((((((((((3",
      "(((((((((((((((3",
      "(((((((((((((((3",
      "(((((((((((((((3",
      "(((((((((((((((3",
      "(((((((((((((((3",
      "(((((((((((((((3",
      "(((((((((((((((3",
      "(((((((((((((((%",
      "(((((((((((((((3",
      "(((((((((((((((3",
      "(((((((((((((((3"
    ],
    [
      "&&&&&&&&&&&&&&  ",
      "&&&&&&&&&&&&&&  ",
      "&&&&&&&&&&&&&&  ",
      "&&&&&&&&&&&&&&  ",
      "&&&&&&&&&&&&&&  ",
      "&&&&&&&&&&&&&&  ",
      "&&&&&&&&&&&&&&  ",
      "&&&&&&&&&&&&&&  ",
      "&&&&&&&&&&&&&&  ",
      "&&&&&&&&&&&&&&  ",
      "&&&&&&&&&&&&&&  ",
      "&&&&&&&&&&&&&&  ",
      "&&&&&&&&&&&&&&  ",
      "&&&&&&&&&&&&&&  ",
      "&&&&&&&&&&&&&&  ",
      "&&&&&&&&&&&&&&  "
    ],
    [
      " 2   2 1     2  ",
      " )   -       2  ",
      " 2   2       2  ",
      " 2   2       2  ",
      "22   2222+2222  ",
      " 2   2       2  ",
      " 2   2       2  ",
      " 2   2 0 /   2  ",
      " )   - 1     2  ",
      " 2   2       2  ",
      " 2   2       2  ",
      "22   2222+2222  ",
      " 2   2       2  ",
      " 2   2       2  ",
      " )   - 0 /   2  ",
      " 2   2 1     2  "
    ],
    [
      " 2   2       !  ",
      " *   .       2  ",
      " 2   2       2  ",
      " 2   2       2  ",
      "22   2222,2222  ",
      " 2   2       2  ",
      " 2   2       2  ",
      " 2   2       !  ",
      " *   .       !  ",
      " 2   2       2  ",
      " 2   2       2  ",
      "22   2222,2222  ",
      " 2   2       2  ",
      " 2   2       2  ",
      " *   .       !  ",
      " 2   2       !  "
    ],
    [
      " 2'  2       !  ",
      " 2   2       2  ",
      " 2   2       2  ",
      " 2   2       2  ",
      "22   222222222  ",
      " 2   2       2  ",
      " 2   2       2  ",
      " 2   2       !  ",
      " 2   2       !  ",
      " 2   2       2  ",
      " 2   2       2  ",
      "22   222222222  ",
      " 2   2       2  ",
      " 2   2       2  ",
      " 2   2       !  ",
      " 2   2       !  "
    ],
    [
      " 2   2       2  ",
      " 2'  2       2  ",
      " 2   2       2  ",
      " 2   2       2  ",
      "22   222222222  ",
      " 2   2       2  ",
      " 2   2       2  ",
      " 2   2       2  ",
      " 2   2       2  ",
      " 2   2       2  ",
      " 2   2       2  ",
      "22   222222222  ",
      " 2   2       2  ",
      " 2   2       2  ",
      " 2   2       2  ",
      " 2   2       2  "
    ]
  ],
  "palette": {
    "palette": [
      {
        "char": "!",
        "block": "create:framed_glass"
      },
      {
        "char": "$",
        "block": "minecraft:coarse_dirt"
      },
      {
        "char": "%",
        "block": "minecraft:gravel"
      },
      {
        "char": "&",
        "block": "minecraft:polished_andesite"
      },
      {
        "char": "'",
        "block": "minecraft:polished_andesite_stairs[facing=south,half=bottom,shape=straight,waterlogged=false]"
      },
      {
        "char": "(",
        "block": "minecraft:smooth_stone"
      },
      {
        "char": ")",
        "block": "minecraft:spruce_door[facing=east,half=lower,hinge=left,open=false,powered=false]"
      },
      {
        "char": "*",
        "block": "minecraft:spruce_door[facing=east,half=upper,hinge=left,open=false,powered=false]"
      },
      {
        "char": "+",
        "block": "minecraft:spruce_door[facing=south,half=lower,hinge=left,open=false,powered=false]"
      },
      {
        "char": ",",
        "block": "minecraft:spruce_door[facing=south,half=upper,hinge=left,open=false,powered=false]"
      },
      {
        "char": "-",
        "block": "minecraft:spruce_door[facing=west,half=lower,hinge=left,open=false,powered=false]"
      },
      {
        "char": ".",
        "block": "minecraft:spruce_door[facing=west,half=upper,hinge=left,open=false,powered=false]"
      },
      {
        "char": "/",
        "block": "kubejs:ruined_cauldron"
      },
      {
        "char": "0",
        "block": "minecraft:white_bed[facing=south,occupied=false,part=foot]"
      },
      {
        "char": "1",
        "block": "minecraft:white_bed[facing=south,occupied=false,part=head]"
      },
      {
        "char": "2",
        "block": "minecraft:white_concrete"
      },
      {
        "char": "3",
        "block": "tfmg:asphalt"
      }
    ]
  }
}
