{
  "xsize": 16,
  "zsize": 16,
  "slices": [
    [
      "                ",
      "                ",
      "                ",
      "                ",
      "                ",
      "                ",
      "%               ",
      "%               ",
      "%               ",
      "%               ",
      "%               ",
      "%               ",
      "%               ",
      "%               ",
      "%               ",
      "%               "
    ],
    [
      "                ",
      "                ",
      "                ",
      "                ",
      "                ",
      "                ",
      "                ",
      "                ",
      "                ",
      "                ",
      "                ",
      "                ",
      "                ",
      "                ",
      "                ",
      "                "
    ],
    [
      "                ",
      "                ",
      "                ",
      "                ",
      "                ",
      "                ",
      "                ",
      "                ",
      "                ",
      "                ",
      "                ",
      "                ",
      "                ",
      "                ",
      "                ",
      "                "
    ],
    [
      "$$$$&&&&&&&&&&&&",
      "$$$$&&&&&&&&&&&&",
      "$$$$&&&&&&&&&&&&",
      "$$$$&&&&&&&&&&&&",
      "$$$$&&&&&&&&&&&&",
      "$$$$&&&&&&&&&&&&",
      "$$$$&&&&&&&&&&&&",
      "$$$$&&&&&&&&&&&&",
      "$$$$&&&&&&&&&&&&",
      "$$$$&&&&&&&&&&&&",
      "$$$$&&&&&&&&&&&&",
      "$$$$&&&&&&&&&&&&",
      "$$$$&&&&&&&&&&&&",
      "$$$$&&&&&&&&&&&&",
      "$$$$&&&&&&&&&&&&",
      "$$$$&&&&&&&&&&&&"
    ],
    [
      "   '            ",
      "   '            ",
      "   '            ",
      "   '            ",
      "   '            ",
      "   '            ",
      "   '            ",
      "!! '            ",
      "!! '            ",
      "!! '            ",
      "   '            ",
      "   '            ",
      "   '            ",
      "   '            ",
      "   '            ",
      "!! '            "
    ],
    [
      "   '            ",
      "   '            ",
      "   '            ",
      "   '            ",
      "   '            ",
      "   '            ",
      "   '            ",
      "!! '            ",
      "!! '            ",
      "!! '            ",
      "   '            ",
      "   '            ",
      "   '            ",
      "   '            ",
      "   '            ",
      "!! '            "
    ]
  ],
  "palette": {
    "palette": [
      {
        "char": "!",
        "block": "minecraft:oxidized_cut_copper"
      },
      {
        "char": "$",
        "block": "minecraft:polished_andesite"
      },
      {
        "char": "%",
        "block": "minecraft:polished_tuff"
      },
      {
        "char": "&",
        "block": "minecraft:smooth_stone"
      },
      {
        "char": "'",
        "block": "minecraft:stone_bricks"
      }
    ]
  }
}
