{
  "xsize": 16,
  "zsize": 16,
  "slices": [
    [
      "1111111111$$!111",
      "11111111$$!11111",
      "111111$$!1111111",
      "1111$$!111111111",
      "11$$!11111111111",
      "$$!1111111111111",
      "!111111111111111",
      "111111111111111$",
      "1111111111111$$!",
      "11111111111$$!11",
      "111111111$$!1111",
      "1111111$$!111111",
      "11111$$!11111111",
      "111$$!1111111111",
      "1$$!111111111111",
      "$!11111111111111"
    ],
    [
      ",,,,,,,,,,,,,,,,",
      ",,,,,,,,,,,,,,,,",
      ",,,,,,,,,,,,,,,,",
      ",,,,,,,,,,,,,,,,",
      ",,,,,,,,,,,,,,,,",
      ",,,,,,,,,,,,,,,,",
      ",,,,,,,,,,,,,,,,",
      ",,,,,,,,,,,,,,,,",
      ",,,,,,,,,,,,,,,,",
      ",,,,,,,,,,,,,,,,",
      ",,,,,,,,,,,,,,,,",
      ",,,,,,,,,,,,,,,,",
      ",,,,,,,,,,,,,,,,",
      ",,,,,,,,,,,,,,,,",
      ",,,,,,,,,,,,,,,,",
      ",,,,,,,,,,,,,,,,"
    ],
    [
      "   0-         -2",
      "   0-         -2",
      "   0-         -2",
      "   0-         -2",
      "*..0-......*..-2",
      "   0-         -2",
      "(  0-      (  -2",
      "   0-         -2",
      "   0-         -2",
      "   0-         -2",
      "   0-         -2",
      "   0-         -2",
      "   0-         -2",
      "   0-&        -2",
      " ) 0-%    / ) -2",
      "   0-         -2"
    ],
    [
      "   0-         -2",
      "   0-         -2",
      "   0-         -2",
      "   0-         -2",
      "+..0-......+..-2",
      "   0-         -2",
      "   0-         -2",
      "(  0-      (  -2",
      "   0-         -2",
      "   0-         -2",
      "   0-         -2",
      "   0-         -2",
      "   0-         -2",
      "   0-         -2",
      "   0-         -2",
      " ' 0-       ' -2"
    ],
    [
      "   0-         -2",
      "   0-         -2",
      "   0-         -2",
      "   0-         -2",
      "...0-.........-2",
      "   0-         -2",
      "   0-         -2",
      "   0-         -2",
      "(  0-      (  -2",
      "   0-         -2",
      "   0-         -2",
      "   0-         -2",
      "   0-         -2",
      "   0-         -2",
      "   0-         -2",
      "   0-         -2"
    ],
    [
      "   0-         -2",
      "   0-         -2",
      "   0-         -2",
      "   0-         -2",
      "...0-.........-2",
      "   0-         -2",
      "   0-         -2",
      "   0-         -2",
      "   0-         -2",
      "(  0-      (  -2",
      "   0-         -2",
      "   0-         -2",
      "   0-         -2",
      "   0-         -2",
      "   0-         -2",
      "   0-         -2"
    ]
  ],
  "palette": {
    "palette": [
      {
        "char": "!",
        "block": "minecraft:coarse_dirt"
      },
      {
        "char": "$",
        "block": "minecraft:gravel"
      },
      {
        "char": "%",
        "block": "minecraft:gray_bed[facing=north,occupied=false,part=foot]"
      },
      {
        "char": "&",
        "block": "minecraft:gray_bed[facing=north,occupied=false,part=head]"
      },
      {
        "char": "'",
        "block": "minecraft:lever[face=wall,facing=south,powered=false]"
      },
      {
        "char": "(",
        "block": "minecraft:oak_stairs[facing=south,half=bottom,shape=straight,waterlogged=false]"
      },
      {
        "char": ")",
        "block": "minecraft:quartz_stairs[facing=north,half=bottom,shape=straight,waterlogged=false]"
      },
      {
        "char": "*",
        "block": "minecraft:spruce_door[facing=south,half=lower,hinge=left,open=false,powered=false]"
      },
      {
        "char": "+",
        "block": "minecraft:spruce_door[facing=south,half=upper,hinge=left,open=false,powered=false]"
      },
      {
        "char": ",",
        "block": "minecraft:spruce_planks"
      },
      {
        "char": "-",
        "block": "minecraft:stone_bricks"
      },
      {
        "char": ".",
        "block": "minecraft:stripped_spruce_wood"
      },
      {
        "char": "/",
        "block": "minecraft:water_cauldron[level=2]"
      },
      {
        "char": "0",
        "block": "minecraft:yellow_terracotta"
      },
      {
        "char": "1",
        "block": "tfmg:asphalt"
      },
      {
        "char": "2",
        "block": "the_wasteland_reworked:decayed_planks"
      }
    ]
  }
}
