{
  "xsize": 16,
  "zsize": 16,
  "slices": [
    [
      "((((((((((((((((",
      "((((((((((((((%%",
      "((((((((((((%%$(",
      "((((((((((%%$(((",
      "((((((((%%$(((((",
      "((((((%%$(((((((",
      "((((%%$(((((((((",
      "((%%$(((((((((((",
      "%%$(((((((((((((",
      "$(((((((((((((((",
      "(((((((((((((((%",
      "(((((((((((((%%$",
      "(((((((((((%%$((",
      "(((((((((%%$((((",
      "(((((((%%$((((((",
      "(((((%%$(((((((("
    ],
    [
      "(((((((('*******",
      "(((((((('*******",
      "(((((((('*******",
      "(((((((('*******",
      "(((((((('*******",
      "(((((((('*******",
      "(((((((('*******",
      "(((((((('*******",
      "(((((((('*******",
      "(((((((('*******",
      "(((((((('*******",
      "'    ''''*******",
      "                ",
      "                ",
      "                ",
      "                "
    ],
    [
      "        '       ",
      "        '       ",
      "           &&&& ",
      "           &&&& ",
      "           &&&& ",
      "           &&&& ",
      "        '  &&&& ",
      "        '  &&&& ",
      "        '  &&&& ",
      "        '       ",
      "        '       ",
      "'    '''')   )  ",
      "                ",
      "                ",
      "                ",
      "                "
    ],
    [
      "        '       ",
      "        '       ",
      "           &&&& ",
      "           &&&& ",
      "           &&&& ",
      "           &&&& ",
      "        '  &&&& ",
      "        '  &&&& ",
      "        '  &&&& ",
      "        '       ",
      "        '       ",
      "'    '''')   )  ",
      "                ",
      "                ",
      "                ",
      "                "
    ],
    [
      "        '       ",
      "        '       ",
      "                ",
      "            !!  ",
      "            !!  ",
      "            !!  ",
      "        '   !!  ",
      "        '       ",
      "        '       ",
      "        '       ",
      "        '       ",
      "'    '''')   )  ",
      "                ",
      "                ",
      "                ",
      "                "
    ],
    [
      "        )       ",
      "        )       ",
      "                ",
      "                ",
      "                ",
      "                ",
      "        )       ",
      "        )       ",
      "        )       ",
      "        )       ",
      "        )       ",
      "        ))   )  ",
      "                ",
      "                ",
      "                ",
      "                "
    ]
  ],
  "palette": {
    "palette": [
      {
        "char": "!",
        "block": "create:framed_glass"
      },
      {
        "char": "$",
        "block": "minecraft:coarse_dirt"
      },
      {
        "char": "%",
        "block": "minecraft:gravel"
      },
      {
        "char": "&",
        "block": "minecraft:gray_concrete"
      },
      {
        "char": "'",
        "block": "minecraft:polished_deepslate"
      },
      {
        "char": "(",
        "block": "tfmg:asphalt"
      },
      {
        "char": ")",
        "block": "tfmg:cinder_block"
      },
      {
        "char": "*",
        "block": "tfmg:factory_floor"
      }
    ]
  }
}
