{
  "xsize": 16,
  "zsize": 16,
  "slices": [
    [
      " ,,,&&%,,,,,,,,,",
      " ,&&%,,,,,,,,,,,",
      " &%,,,,,,,,,,,,,",
      " ,,,,,,,,,,,,,,,",
      " ,,,,,,,,,,,,,,&",
      " %,,,,,,,,,,,&&%",
      " ,,,,,,,,,,&&%,,",
      " ,,,,,,,,&&%,,,,",
      " ,,,,,,&&%,,,,,,",
      " ,,,,&&%,,,,,,,,",
      " ,,&&%,,,,,,,,,,",
      " %&%,,,,,,,,,,,,",
      " %,,,,,,,,,,,,,,",
      " ,,,,,,,,,,,,,,,",
      " ,,,,,,,,,,,,,&&",
      " ,,,,,,,,,,,&&%,"
    ],
    [
      "    ............",
      "    ............",
      "    ............",
      "    ............",
      "    ............",
      "    ............",
      "    ............",
      "    ............",
      "    ............",
      "    ............",
      "    ............",
      "    ............",
      "    ............",
      "    ............",
      "    ............",
      "    ............"
    ],
    [
      "    (----)------",
      "    (       -   ",
      "    (       -   ",
      "    ( $  $  - $ ",
      "    ( $  $  - $ ",
      "    ( $  $  - $ ",
      "    ( $  $  - $ ",
      "    ( $  $  - $ ",
      "    ( $  $  - $ ",
      "    (       -   ",
      "    (       -   ",
      "    (       -   ",
      "    (----)------",
      "    ( ''''''  ++",
      "    ( ''''''  ++",
      "    ( ''''''  ++"
    ],
    [
      "    (----*------",
      "    (       -   ",
      "    (       -   ",
      "    ( $  $  - $ ",
      "    ( $  $  - $ ",
      "    ( $  $  - $ ",
      "    ( $  $  - $ ",
      "    ( $  $  - $ ",
      "    ( $  $  - $ ",
      "    (       -   ",
      "    (       -   ",
      "    (       -   ",
      "    (----*------",
      "    (           ",
      "    (           ",
      "    (           "
    ],
    [
      "    (-----------",
      "    (       -   ",
      "    (       -   ",
      "    ( $  $  - $ ",
      "    ( $  $  - $ ",
      "    ( $  $  - $ ",
      "    ! $  $  - $ ",
      "    ! $  $  - $ ",
      "    ( $  $  - $ ",
      "    (       -   ",
      "    (       -   ",
      "    (       -   ",
      "    (-----------",
      "    (           ",
      "    (           ",
      "    (           "
    ],
    [
      "    (-----------",
      "    (       -   ",
      "    (       -   ",
      "    !       -   ",
      "    !       -   ",
      "    (       -   ",
      "    !       -   ",
      "    !       -   ",
      "    (       -   ",
      "    (       -   ",
      "    (       -   ",
      "    (       -   ",
      "    (-----------",
      "    !           ",
      "    !           ",
      "    (           "
    ]
  ],
  "palette": {
    "palette": [
      {
        "char": "!",
        "block": "create:framed_glass"
      },
      {
        "char": "$",
        "block": "minecraft:bookshelf"
      },
      {
        "char": "%",
        "block": "minecraft:coarse_dirt"
      },
      {
        "char": "&",
        "block": "minecraft:gravel"
      },
      {
        "char": "'",
        "block": "minecraft:green_wool"
      },
      {
        "char": "(",
        "block": "minecraft:mud_bricks"
      },
      {
        "char": ")",
        "block": "minecraft:spruce_door[facing=south,half=lower,hinge=left,open=false,powered=false]"
      },
      {
        "char": "*",
        "block": "minecraft:spruce_door[facing=south,half=upper,hinge=left,open=false,powered=false]"
      },
      {
        "char": "+",
        "block": "minecraft:yellow_wool"
      },
      {
        "char": ",",
        "block": "tfmg:asphalt"
      },
      {
        "char": "-",
        "block": "tfmg:cinder_block"
      },
      {
        "char": ".",
        "block": "tfmg:factory_floor"
      }
    ]
  }
}
