{
  "xsize": 16,
  "zsize": 16,
  "slices": [
    [
      "''%))))))       ",
      "%))))))))       ",
      ")))))))))       ",
      ")))))))))       ",
      ")))))))))       ",
      ")))))))))       ",
      ")))))))''       ",
      ")))))''%)       ",
      ")))''%)))       ",
      ")''%)))))       ",
      "'%)))))))       ",
      ")))))))))       ",
      ")))))))))       ",
      ")))))))))       ",
      ")))))))))       ",
      "))))))))'       "
    ],
    [
      "++++++          ",
      "++++++          ",
      "++++++          ",
      "++++++          ",
      "++++++          ",
      "++++++          ",
      "++++++          ",
      "++++++          ",
      "++++++          ",
      "++++++          ",
      "++++++          ",
      "++++++          ",
      "                ",
      "                ",
      "                ",
      "                "
    ],
    [
      "  &  *          ",
      "(    *          ",
      "     *          ",
      "     *          ",
      "     *          ",
      "     *          ",
      "     *          ",
      "!!!! *          ",
      "!$!! *          ",
      "!!!! *          ",
      "     *          ",
      " *   *          ",
      "                ",
      "                ",
      "                ",
      "                "
    ],
    [
      "     *          ",
      "     *          ",
      "     *          ",
      "     *          ",
      "     *          ",
      "     *          ",
      "     *          ",
      "!!!! *          ",
      "!!!! *          ",
      "!!!! *          ",
      "     *          ",
      " *   *          ",
      "                ",
      "                ",
      "                ",
      "                "
    ],
    [
      "     *          ",
      "     *          ",
      "     *          ",
      "     *          ",
      "     *          ",
      "     *          ",
      "     *          ",
      "!!!! *          ",
      "!!!! *          ",
      "!!!! *          ",
      "     *          ",
      " *   *          ",
      "                ",
      "                ",
      "                ",
      "                "
    ],
    [
      "     *          ",
      "     *          ",
      "     *          ",
      "     *          ",
      "     *          ",
      "     *          ",
      "     *          ",
      "     *          ",
      "     *          ",
      "     *          ",
      "     *          ",
      " *   *          ",
      "                ",
      "                ",
      "                ",
      "                "
    ]
  ],
  "palette": {
    "palette": [
      {
        "char": "!",
        "block": "immersiveengineering:crate"
      },
      {
        "char": "$",
        "block": "minecraft:chest[facing=west,type=single,waterlogged=false]",
        "tag": {
          "id": "minecraft:chest",
          "LootTable": "infinite_domain:chests/wasteland_military"
        }
      },
      {
        "char": "%",
        "block": "minecraft:coarse_dirt"
      },
      {
        "char": "&",
        "block": "minecraft:crafting_table"
      },
      {
        "char": "'",
        "block": "minecraft:gravel"
      },
      {
        "char": "(",
        "block": "minecraft:spawner",
        "tag": {
          "id": "minecraft:mob_spawner",
          "Delay": 200,
          "MinSpawnDelay": 240,
          "MaxSpawnDelay": 720,
          "SpawnCount": 1,
          "MaxNearbyEntities": 8,
          "RequiredPlayerRange": 14,
          "SpawnRange": 4,
          "SpawnData": {
            "entity": {
              "id": "mutantmonsters:mutant_zombie"
            }
          },
          "SpawnPotentials": [
            {
              "weight": 1,
              "data": {
                "entity": {
                  "id": "mutantmonsters:mutant_zombie"
                }
              }
            }
          ]
        }
      },
      {
        "char": ")",
        "block": "tfmg:asphalt"
      },
      {
        "char": "*",
        "block": "tfmg:cinder_block"
      },
      {
        "char": "+",
        "block": "tfmg:factory_floor"
      }
    ]
  }
}
