{
  "xsize": 16,
  "zsize": 16,
  "slices": [
    [
      "                ",
      "                ",
      "                ",
      "                ",
      "                ",
      "/$/!!/$$        ",
      "       $        ",
      "       $$       ",
      "       !        ",
      "       !        ",
      "       $        ",
      "       $        ",
      "       $        ",
      "       $        ",
      "0000000$$       ",
      "       !        "
    ],
    [
      "                ",
      "                ",
      "                ",
      "                ",
      "   --           ",
      "$$$$$$$$        ",
      "       $        ",
      "       $)       ",
      "       $)       ",
      "       $)       ",
      "       $)       ",
      "       $        ",
      "       $        ",
      "       $        ",
      "0000000$)       ",
      "       $)       "
    ],
    [
      "                ",
      "                ",
      "                ",
      "                ",
      "                ",
      "$$$$$$$$        ",
      "       $        ",
      "       $        ",
      "       $        ",
      "       $        ",
      "       $        ",
      "       $        ",
      "       $        ",
      "       $        ",
      "       $        ",
      "       $        "
    ],
    [
      "                ",
      "                ",
      "                ",
      "&&&&&           ",
      "&&&&&           ",
      "&&&&&$$$        ",
      "       $        ",
      "       $        ",
      "       &&&      ",
      "       &&&      ",
      "       &&&      ",
      "       &&&      ",
      "       &&&      ",
      "       &&&      ",
      "       $        ",
      "       $        "
    ],
    [
      "                ",
      "                ",
      "                ",
      "    .           ",
      "*********       ",
      "*********       ",
      "%%%%%%%$        ",
      "%%%%%%%$        ",
      "%%%%%%%$ .      ",
      "%%%%%%%$        ",
      "%%%%%%%$        ",
      "%%%%%%%$        ",
      "%%%%%%%$        ",
      "%%%%%%%$ .      ",
      "%%%%%%%$        ",
      "%%%%%%%$        "
    ],
    [
      "                ",
      "                ",
      "                ",
      "                ",
      "   ,,           ",
      "$$$$$$$$        ",
      "       $        ",
      "       $$       ",
      "    (  $        ",
      "       $        ",
      "'      $        ",
      "       $        ",
      "       $        ",
      "       $        ",
      "+000000$$       ",
      "       $        "
    ]
  ],
  "palette": {
    "palette": [
      {
        "char": "!",
        "block": "create:framed_glass"
      },
      {
        "char": "$",
        "block": "minecraft:mud_bricks"
      },
      {
        "char": "%",
        "block": "minecraft:oak_planks"
      },
      {
        "char": "&",
        "block": "minecraft:oak_slab[type=top,waterlogged=false]"
      },
      {
        "char": "'",
        "block": "minecraft:oak_stairs[facing=west,half=bottom,shape=straight,waterlogged=false]"
      },
      {
        "char": "(",
        "block": "minecraft:smoker[facing=south,lit=false]"
      },
      {
        "char": ")",
        "block": "minecraft:smooth_stone"
      },
      {
        "char": "*",
        "block": "minecraft:smooth_stone_slab[type=top,waterlogged=false]"
      },
      {
        "char": "+",
        "block": "minecraft:spruce_door[facing=south,half=lower,hinge=left,open=false,powered=false]"
      },
      {
        "char": ",",
        "block": "minecraft:spruce_slab[type=bottom,waterlogged=false]"
      },
      {
        "char": "-",
        "block": "minecraft:spruce_slab[type=top,waterlogged=false]"
      },
      {
        "char": ".",
        "block": "minecraft:stripped_oak_log[axis=y]"
      },
      {
        "char": "/",
        "block": "minecraft:stripped_spruce_log[axis=y]"
      },
      {
        "char": "0",
        "block": "minecraft:stripped_spruce_wood"
      }
    ]
  }
}
