{
  "xsize": 16,
  "zsize": 16,
  "slices": [
    [
      "        %       ",
      "        %       ",
      "        %       ",
      "        %       ",
      "        %       ",
      "        %       ",
      "        %       ",
      "        %       ",
      "        %       ",
      "        %       ",
      "        %       ",
      "        %%   %  ",
      "                ",
      "                ",
      "                ",
      "                "
    ],
    [
      "        %       ",
      "        %       ",
      "        %       ",
      "        %       ",
      "        %       ",
      "        %       ",
      "        %       ",
      "        %       ",
      "        %       ",
      "        %       ",
      "        %       ",
      "        %%   %  ",
      "                ",
      "                ",
      "                ",
      "                "
    ],
    [
      "        %       ",
      "        %       ",
      "        %       ",
      "        %       ",
      "        %       ",
      "        %       ",
      "        %       ",
      "        %       ",
      "        %       ",
      "        %       ",
      "        % !!! !!",
      "        %%!!!%!!",
      "                ",
      "                ",
      "                ",
      "                "
    ],
    [
      "        %       ",
      "        %       ",
      "        %       ",
      "        %       ",
      "        %       ",
      "        %       ",
      "        %       ",
      "        %       ",
      "        %       ",
      "        %       ",
      "        %       ",
      "        %%%%%%%%",
      "                ",
      "                ",
      "                ",
      "                "
    ],
    [
      "        %       ",
      "        %       ",
      "        %       ",
      "        %       ",
      "        %       ",
      "        %       ",
      "        %       ",
      "        %       ",
      "        %       ",
      "        %       ",
      "        %       ",
      "        %%%%%%%%",
      "                ",
      "                ",
      "                ",
      "                "
    ],
    [
      "        $$$$$$$$",
      "        $$$$$$$$",
      "        $$$$$$$$",
      "        $$$$$$$$",
      "        $$$$$$$$",
      "        $$$$$$$$",
      "        $$$$$$$$",
      "        $$$$$$$$",
      "        $$$$$$$$",
      "        $$$$$$$$",
      "        $$$$$$$$",
      "        $$$$$$$$",
      "                ",
      "                ",
      "                ",
      "                "
    ]
  ],
  "palette": {
    "palette": [
      {
        "char": "!",
        "block": "minecraft:blue_concrete"
      },
      {
        "char": "$",
        "block": "minecraft:weathered_cut_copper"
      },
      {
        "char": "%",
        "block": "tfmg:cinder_block"
      }
    ]
  }
}
