{
  "xsize": 16,
  "zsize": 16,
  "slices": [
    [
      ")))))))))))))))$",
      ")))))))))))))))/",
      ")))))))))))))))/",
      ")))))))))))))))/",
      ")))))))))))))))/",
      ")))))))))))))))/",
      ")))))))))))))))/",
      ")))))))))))))))/",
      ")))))))))))))))/",
      ")))))))))))))))%",
      ")))))))))))))))/",
      ")))))))))))))))/",
      ")))))))))))))))/",
      ")))))))))))))))/",
      ")))))))))))))))/",
      ")))))))))))))))/"
    ],
    [
      "''''''%'%'%%%%%%",
      "'''''%&%%%%%%%%%",
      "''''%%%%%%%%%%%%",
      "''''%&%%%%%%%%%%",
      "''''%'%%%%%%%%%%",
      "''''%%%%%%%%%%%%",
      "''''%%%%%%%%%%%%",
      "''''%%%%%%%%%%%%",
      "''''%%%%%%%%%%%%",
      "''''%%%%%%%%%%%%",
      "''''&%%%%%%%%%%%",
      "''''%%%%%%%%%%%%",
      "''''%%%%%%%%%%%%",
      "''''%'%%%%%%%%% ",
      "''''%&%&%%%%%%%%",
      "''''''%%%%%%%% %"
    ],
    [
      "      % % %%%%&%",
      "&&&&,% %%%%%%%%%",
      "&   %%%%%%%%%%%%",
      "&   % %%%%%%%%%!",
      "&   % %&%%%%%%%%",
      "&   &%%%%%%%%%%%",
      "*   %%%%%%%%%%%%",
      "&   %%%%%%%%%%%%",
      "&  .%&%%%%%%%%%%",
      "&  .%%%%%%%%%%%%",
      "&    %%%%%%%%%%%",
      "    &%&%%%%%%%%%",
      " .  %%%%%%%%%%%%",
      " .  % %%%%%%%%% ",
      " .( % % %%%%%%%&",
      " .    %!%&%%%% %"
    ],
    [
      "      % % %%%% &",
      "&&&&-! &%!%&%%&%",
      "&   &%!%&%%%%&%%",
      "&   % %%%%%%%%% ",
      "&   % % %%%%%%%&",
      "&    %%%%%%%%%%%",
      "+   &%!%%%%%%%%%",
      "&   %%%%%%%%%%%%",
      "&   % %%%%%%%%%&",
      "&   %!%&%%%%%%%%",
      "&    &%&%&%%%%!%",
      "     % %%%%%%%%%",
      " .  !%&%!%%%%&%%",
      " .  & &%&%&%%!% ",
      " .  % % %%%%&%% ",
      " .(   % % %%%% !"
    ],
    [
      "      % % %%!%  ",
      "&&&     % % %% &",
      "&    % % %%%% %%",
      "&   & &%&%&%%&% ",
      "&   % % %%%%!%% ",
      "&    !%&%!%%%%&%",
      "&    % %%%%%%%%%",
      "&   &%&%&%%%%&%%",
      "&   % %%%%%%%%% ",
      "&   % % %%%%%%%&",
      "&     % % %%%% &",
      "     & !%&%!%%&%",
      " .   % %0%%%% %%",
      " .     % %0%% % ",
      " .  & ! &%!%0&% ",
      " .    % % %%&%  "
    ],
    [
      "      & ! &% &  ",
      "&&&     % % &%  ",
      "&    & & &%&% !%",
      "&      % % %% % ",
      "&   ! & !%&% &% ",
      "&     %0% %%%% &",
      "&    & &%&%&%%!%",
      "&    % % %%%% %%",
      "&   ! &%!%&%%&% ",
      "&   % % %%%%&%%0",
      "&     % % %%&%  ",
      "        % % %% !",
      " .   & & &%&% &%",
      " .     & ! &% & ",
      " .       % %  % ",
      " .    & & &% &  "
    ]
  ],
  "palette": {
    "palette": [
      {
        "char": "!",
        "block": "immersiveengineering:concrete_brick_cracked"
      },
      {
        "char": "$",
        "block": "minecraft:coarse_dirt"
      },
      {
        "char": "%",
        "block": "minecraft:gravel"
      },
      {
        "char": "&",
        "block": "minecraft:light_gray_concrete"
      },
      {
        "char": "'",
        "block": "minecraft:polished_andesite"
      },
      {
        "char": "(",
        "block": "minecraft:polished_andesite_stairs[facing=south,half=bottom,shape=straight,waterlogged=false]"
      },
      {
        "char": ")",
        "block": "minecraft:smooth_stone"
      },
      {
        "char": "*",
        "block": "minecraft:spruce_door[facing=east,half=lower,hinge=left,open=false,powered=false]"
      },
      {
        "char": "+",
        "block": "minecraft:spruce_door[facing=east,half=upper,hinge=left,open=false,powered=false]"
      },
      {
        "char": ",",
        "block": "minecraft:spruce_door[facing=south,half=lower,hinge=left,open=false,powered=false]"
      },
      {
        "char": "-",
        "block": "minecraft:spruce_door[facing=south,half=upper,hinge=left,open=false,powered=false]"
      },
      {
        "char": ".",
        "block": "minecraft:white_concrete"
      },
      {
        "char": "/",
        "block": "tfmg:asphalt"
      },
      {
        "char": "0",
        "block": "wastelands:scrap_pile"
      }
    ]
  }
}
