{
  "xsize": 16,
  "zsize": 16,
  "slices": [
    [
      "        33333333",
      "**3333*3333*3333",
      "3333333333333333",
      "3333333333333333",
      "3333333333333333",
      "3333333333333333",
      "3333333333333333",
      "333333**%3333333",
      "3333**%333333333",
      "33**%33333333333",
      "**%3333333333333",
      "%333333333333333",
      "333333333333333*",
      "3333333333333**%",
      "33333333333**%33",
      "333333333**%3333"
    ],
    [
      "                ",
      "                ",
      "                ",
      "                ",
      "    -   ,,,,,,,,",
      "        ,,,,,,,,",
      "        ,,,,,,,,",
      "55555555,,,,,,,,",
      "55555555,,,,,,,,",
      "55555555,,,,,,,,",
      "5555555555555555",
      "5555555555555555",
      "5555555555555555",
      "5555555555555555",
      "5555555555555555",
      "5555555555555555"
    ],
    [
      "                ",
      "                ",
      "                ",
      "                ",
      "    -   ///////&",
      "        /       ",
      "  +     /       ",
      "$$+$$$$$/       ",
      "  +     /       ",
      "  4     ///////(",
      "  4  11     !   ",
      "  4  2   11     ",
      "  4      2      ",
      "  4             ",
      "  4   2  2..... ",
      "  4   1  0  1   "
    ],
    [
      "                ",
      "                ",
      "                ",
      "                ",
      "    -   ///////'",
      "        /       ",
      "  +     /       ",
      "$$+$$$$$/       ",
      "  +     /       ",
      "  4     ///////)",
      "  4             ",
      "  4             ",
      "  4             ",
      "  4             ",
      "  4       ..... ",
      "  4             "
    ],
    [
      "                ",
      "                ",
      "                ",
      "                ",
      "    -   ////////",
      "        /       ",
      "  +     /       ",
      "$$+$$$$$/       ",
      "  +     /       ",
      "  4     ////////",
      "  4             ",
      "  4             ",
      "  4             ",
      "  4             ",
      "  4       ..... ",
      "  4             "
    ],
    [
      "                ",
      "                ",
      "                ",
      "                ",
      "    -   ////////",
      "        /       ",
      "  +     /       ",
      "$$+$$$$$/       ",
      "  +     /       ",
      "  4     ////////",
      "  4             ",
      "  4             ",
      "  4             ",
      "  4             ",
      "  4             ",
      "  4             "
    ]
  ],
  "palette": {
    "palette": [
      {
        "char": "!",
        "block": "minecraft:bookshelf"
      },
      {
        "char": "$",
        "block": "minecraft:bricks"
      },
      {
        "char": "%",
        "block": "minecraft:coarse_dirt"
      },
      {
        "char": "&",
        "block": "minecraft:dark_oak_door[facing=north,half=lower,hinge=left,open=false,powered=false]"
      },
      {
        "char": "'",
        "block": "minecraft:dark_oak_door[facing=north,half=upper,hinge=left,open=false,powered=false]"
      },
      {
        "char": "(",
        "block": "minecraft:dark_oak_door[facing=south,half=lower,hinge=left,open=false,powered=false]"
      },
      {
        "char": ")",
        "block": "minecraft:dark_oak_door[facing=south,half=upper,hinge=left,open=false,powered=false]"
      },
      {
        "char": "*",
        "block": "minecraft:gravel"
      },
      {
        "char": "+",
        "block": "minecraft:mud_bricks"
      },
      {
        "char": ",",
        "block": "minecraft:polished_andesite"
      },
      {
        "char": "-",
        "block": "minecraft:polished_blackstone_bricks"
      },
      {
        "char": ".",
        "block": "minecraft:scaffolding"
      },
      {
        "char": "/",
        "block": "minecraft:smooth_stone"
      },
      {
        "char": "0",
        "block": "minecraft:spawner",
        "tag": {
          "id": "minecraft:mob_spawner",
          "Delay": 200,
          "MinSpawnDelay": 240,
          "MaxSpawnDelay": 720,
          "SpawnCount": 2,
          "MaxNearbyEntities": 7,
          "RequiredPlayerRange": 14,
          "SpawnRange": 4,
          "SpawnData": {
            "entity": {
              "id": "minecraft:zombie"
            }
          },
          "SpawnPotentials": [
            {
              "weight": 1,
              "data": {
                "entity": {
                  "id": "minecraft:zombie"
                }
              }
            }
          ]
        }
      },
      {
        "char": "1",
        "block": "minecraft:spruce_slab[type=bottom,waterlogged=false]"
      },
      {
        "char": "2",
        "block": "minecraft:spruce_stairs[facing=north,half=bottom,shape=straight,waterlogged=false]"
      },
      {
        "char": "3",
        "block": "tfmg:asphalt"
      },
      {
        "char": "4",
        "block": "tfmg:cinder_block"
      },
      {
        "char": "5",
        "block": "tfmg:factory_floor"
      }
    ]
  }
}
