{
  "xsize": 16,
  "zsize": 16,
  "slices": [
    [
      " .        .     ",
      " .        .     ",
      "$.        .     ",
      " .        .     ",
      " .        .     ",
      " .        .     ",
      " .        .     ",
      " .        .     ",
      " .        .     ",
      " .        .     ",
      " .        .     ",
      " .        .     ",
      " .        //////",
      " .        /     ",
      " .        /     ",
      " .        /     "
    ],
    [
      "          .     ",
      "          .     ",
      "          .     ",
      "$         .     ",
      "          .     ",
      "          .     ",
      "          .     ",
      "          .     ",
      "          .     ",
      "          .     ",
      "          .     ",
      "          .     ",
      "          //////",
      "          /     ",
      "          /     ",
      "          /     "
    ],
    [
      "!!!!!!!!!!%     ",
      "!!!!!!!!!!%     ",
      " !!!!!!!!!%     ",
      " !!!!!!!!!%     ",
      "!!!!!!!!!!%     ",
      "!!!!!!!!!!%     ",
      "!!!!!!!!!!%     ",
      "!!!!!!!!!!%     ",
      "!!!!!!!!!!%     ",
      "!!!!!!!!!!%     ",
      "!!!!!!!!!!%     ",
      "!!!!!!!!!!%     ",
      "!!!!!!!!!!%/////",
      "!!!!!!!!!!%00000",
      "!!!!!!!!!!%00000",
      "!!!!!!!!!!%00000"
    ],
    [
      " .  -     .     ",
      " )        .     ",
      " .        .     ",
      " .        .     ",
      " ....'.....     ",
      " .        .     ",
      " .        .     ",
      " .  , +&  .     ",
      " )  -     .     ",
      " .        .     ",
      " .        .     ",
      " ....'.....     ",
      " .        //////",
      " .        /     ",
      " )  , +         ",
      " .  -           "
    ],
    [
      " .        .     ",
      " *        .     ",
      " .        .     ",
      " .        .     ",
      " ....(.....     ",
      " .        .     ",
      " .        .     ",
      " .        .     ",
      " *        .     ",
      " .        .     ",
      " .        .     ",
      " ....(.....     ",
      " .        //////",
      " .        /     ",
      " *              ",
      " .              "
    ],
    [
      "$.        .     ",
      " .        .     ",
      " .        .     ",
      " .        .     ",
      " ..........     ",
      " .        .     ",
      " .        .     ",
      " .        .     ",
      " .        .     ",
      " .        .     ",
      " .        .     ",
      " ..........     ",
      " .        //////",
      " .        /     ",
      " .              ",
      " .              "
    ]
  ],
  "palette": {
    "palette": [
      {
        "char": "!",
        "block": "minecraft:polished_andesite"
      },
      {
        "char": "$",
        "block": "minecraft:polished_andesite_stairs[facing=south,half=bottom,shape=straight,waterlogged=false]"
      },
      {
        "char": "%",
        "block": "minecraft:smooth_stone"
      },
      {
        "char": "&",
        "block": "minecraft:spawner",
        "tag": {
          "id": "minecraft:mob_spawner",
          "Delay": 200,
          "MinSpawnDelay": 240,
          "MaxSpawnDelay": 720,
          "SpawnCount": 2,
          "MaxNearbyEntities": 8,
          "RequiredPlayerRange": 14,
          "SpawnRange": 4,
          "SpawnData": {
            "entity": {
              "id": "the_wasteland_reworked:ghoul"
            }
          },
          "SpawnPotentials": [
            {
              "weight": 1,
              "data": {
                "entity": {
                  "id": "the_wasteland_reworked:ghoul"
                }
              }
            }
          ]
        }
      },
      {
        "char": "'",
        "block": "minecraft:spruce_door[facing=south,half=lower,hinge=left,open=false,powered=false]"
      },
      {
        "char": "(",
        "block": "minecraft:spruce_door[facing=south,half=upper,hinge=left,open=false,powered=false]"
      },
      {
        "char": ")",
        "block": "minecraft:spruce_door[facing=west,half=lower,hinge=left,open=false,powered=false]"
      },
      {
        "char": "*",
        "block": "minecraft:spruce_door[facing=west,half=upper,hinge=left,open=false,powered=false]"
      },
      {
        "char": "+",
        "block": "minecraft:water_cauldron[level=3]"
      },
      {
        "char": ",",
        "block": "minecraft:white_bed[facing=south,occupied=false,part=foot]"
      },
      {
        "char": "-",
        "block": "minecraft:white_bed[facing=south,occupied=false,part=head]"
      },
      {
        "char": ".",
        "block": "minecraft:white_concrete"
      },
      {
        "char": "/",
        "block": "tfmg:cinder_block"
      },
      {
        "char": "0",
        "block": "tfmg:factory_floor"
      }
    ]
  }
}
