{
  "xsize": 16,
  "zsize": 16,
  "slices": [
    [
      " 777((%777777777",
      " 7((%77777777777",
      " (%7777777777777",
      " 777777777777777",
      " 77777777777777(",
      " %77777777777((%",
      " 7777777777((%77",
      " 77777777((%7777",
      " 777777((%777777",
      " 7777((%77777777",
      " 77((%7777777777",
      " %(%777777777777",
      " %77777777777777",
      " 777777777777777",
      " 7777777777777((",
      " 7%7777%7777%(%7"
    ],
    [
      "    ////////////",
      "    ////////////",
      "    ////////////",
      "    ////////////",
      "    ////////////",
      "    ////////////",
      "    ////////////",
      "    ////////////",
      "    ////////////",
      "    ////////////",
      "    ////////////",
      "    ////////////",
      "    ////////////",
      "    ////////////",
      "                ",
      "                "
    ],
    [
      "    -           ",
      "    -           ",
      "    -  &0'  &0' ",
      "    -           ",
      "    -           ",
      "    -      5  5 ",
      "    -           ",
      "    -     999999",
      "    -88883888888",
      "    -         8 ",
      "    -  $  .  68 ",
      "    - :  :  : 1 ",
      "    -         8 ",
      "    ---)*-------",
      "                ",
      "                "
    ],
    [
      "    !           ",
      "    !           ",
      "    -           ",
      "    -           ",
      "    -           ",
      "    !           ",
      "    !           ",
      "    -           ",
      "    -88884888888",
      "    -         8 ",
      "    -         8 ",
      "    -         2 ",
      "    -         8 ",
      "    ---+,-------",
      "                ",
      "                "
    ],
    [
      "    !           ",
      "    !           ",
      "    -           ",
      "    -           ",
      "    -           ",
      "    !           ",
      "    !           ",
      "    -           ",
      "    -88888888888",
      "    -         8 ",
      "    -         8 ",
      "    -         8 ",
      "    -         8 ",
      "    ------------",
      "                ",
      "                "
    ],
    [
      "    -           ",
      "    -           ",
      "    -           ",
      "    -           ",
      "    -           ",
      "    -           ",
      "    -           ",
      "    -           ",
      "    -88888888888",
      "    -         8 ",
      "    -         8 ",
      "    -         8 ",
      "    -         8 ",
      "    ------------",
      "                ",
      "                "
    ]
  ],
  "palette": {
    "palette": [
      {
        "char": "!",
        "block": "create:framed_glass"
      },
      {
        "char": "$",
        "block": "farmersdelight:stove[facing=north,lit=false]"
      },
      {
        "char": "%",
        "block": "minecraft:coarse_dirt"
      },
      {
        "char": "&",
        "block": "minecraft:dark_oak_stairs[facing=east,half=bottom,shape=straight,waterlogged=false]"
      },
      {
        "char": "'",
        "block": "minecraft:dark_oak_stairs[facing=west,half=bottom,shape=straight,waterlogged=false]"
      },
      {
        "char": "(",
        "block": "minecraft:gravel"
      },
      {
        "char": ")",
        "block": "minecraft:iron_door[facing=south,half=lower,hinge=left,open=false,powered=false]"
      },
      {
        "char": "*",
        "block": "minecraft:iron_door[facing=south,half=lower,hinge=right,open=false,powered=false]"
      },
      {
        "char": "+",
        "block": "minecraft:iron_door[facing=south,half=upper,hinge=left,open=false,powered=false]"
      },
      {
        "char": ",",
        "block": "minecraft:iron_door[facing=south,half=upper,hinge=right,open=false,powered=false]"
      },
      {
        "char": "-",
        "block": "minecraft:red_terracotta"
      },
      {
        "char": ".",
        "block": "minecraft:smoker[facing=north,lit=false]"
      },
      {
        "char": "/",
        "block": "minecraft:smooth_stone"
      },
      {
        "char": "0",
        "block": "minecraft:smooth_stone_slab[type=bottom,waterlogged=false]"
      },
      {
        "char": "1",
        "block": "minecraft:spruce_door[facing=east,half=lower,hinge=left,open=false,powered=false]"
      },
      {
        "char": "2",
        "block": "minecraft:spruce_door[facing=east,half=upper,hinge=left,open=false,powered=false]"
      },
      {
        "char": "3",
        "block": "minecraft:spruce_door[facing=south,half=lower,hinge=left,open=false,powered=false]"
      },
      {
        "char": "4",
        "block": "minecraft:spruce_door[facing=south,half=upper,hinge=left,open=false,powered=false]"
      },
      {
        "char": "5",
        "block": "minecraft:spruce_stairs[facing=south,half=bottom,shape=straight,waterlogged=false]"
      },
      {
        "char": "6",
        "block": "minecraft:water_cauldron[level=2]"
      },
      {
        "char": "7",
        "block": "tfmg:asphalt"
      },
      {
        "char": "8",
        "block": "tfmg:cinder_block"
      },
      {
        "char": "9",
        "block": "zvhouses:spruce_countertop"
      },
      {
        "char": ":",
        "block": "zvhouses:stone_brick_countertop"
      }
    ]
  }
}
