{
  "xsize": 16,
  "zsize": 16,
  "slices": [
    [
      "0000000000**!000",
      "00000000**!00000",
      "000000**!0000000",
      "0000**!000000000",
      "00**!00000000000",
      "**!0000000000000",
      "!000000000000000",
      "000000000000000*",
      "0000000000000**!",
      "00000000000**!00",
      "000000000**!0000",
      "0000000**!000000",
      "00000**!00000000",
      "000**!0000000000",
      "0**!000000000000",
      "*!00000000000000"
    ],
    [
      ",,,,,,,,,,,,,,,,",
      ",,,,,,,,,,,,,,,,",
      ",,,,,,,,,,,,,,,,",
      ",,,,,,,,,,,,,,,,",
      ",,,,,,,,,,,,,,,,",
      ",,,,,,,,,,,,,,,,",
      ",,,,,,,,,,,,,,,,",
      ",,,,,,,,,,,,,,,,",
      ",,,,,,,,,,,,,,,,",
      ",,,,,,,,,,,,,,,,",
      ",,,,,,,,,,,,,,,,",
      ",,,,,,,,,,,,,,,,",
      ",,,,,,,,,,,,,,,,",
      ",,,,,,,,,,,,,,,,",
      ",,,,,,,,,,,,,,,,",
      ",,,,,,,,,,,,,,,,"
    ],
    [
      "        -       ",
      "        -       ",
      "------------.---",
      "   -            ",
      "   -            ",
      "   - )))))))))))",
      "   $            ",
      "   -            ",
      "   - )))))))))))",
      "   -            ",
      "   -            ",
      "   - )))))))))))",
      "   -            ",
      "   %            ",
      "   -    (((( (((",
      "   -  + (((( ((("
    ],
    [
      "        -       ",
      "        -       ",
      "------------/---",
      "   -            ",
      "   -            ",
      "   -            ",
      "   &            ",
      "   -            ",
      "   -            ",
      "   -            ",
      "   -            ",
      "   -            ",
      "   -            ",
      "   '            ",
      "   -            ",
      "   -            "
    ],
    [
      "        -       ",
      "        -       ",
      "----------------",
      "   -            ",
      "   -            ",
      "   -            ",
      "   -            ",
      "   -            ",
      "   -            ",
      "   -            ",
      "   -            ",
      "   -            ",
      "   -            ",
      "   -            ",
      "   -            ",
      "   -            "
    ],
    [
      "        -       ",
      "        -       ",
      "----------------",
      "   -            ",
      "   -            ",
      "   -            ",
      "   -            ",
      "   -            ",
      "   -            ",
      "   -            ",
      "   -            ",
      "   -            ",
      "   -            ",
      "   -            ",
      "   -            ",
      "   -            "
    ]
  ],
  "palette": {
    "palette": [
      {
        "char": "!",
        "block": "minecraft:coarse_dirt"
      },
      {
        "char": "$",
        "block": "minecraft:dark_oak_door[facing=east,half=lower,hinge=left,open=false,powered=false]"
      },
      {
        "char": "%",
        "block": "minecraft:dark_oak_door[facing=east,half=lower,hinge=right,open=false,powered=false]"
      },
      {
        "char": "&",
        "block": "minecraft:dark_oak_door[facing=east,half=upper,hinge=left,open=false,powered=false]"
      },
      {
        "char": "'",
        "block": "minecraft:dark_oak_door[facing=east,half=upper,hinge=right,open=false,powered=false]"
      },
      {
        "char": "(",
        "block": "minecraft:dark_oak_slab[type=bottom,waterlogged=false]"
      },
      {
        "char": ")",
        "block": "minecraft:dark_oak_stairs[facing=south,half=bottom,shape=straight,waterlogged=false]"
      },
      {
        "char": "*",
        "block": "minecraft:gravel"
      },
      {
        "char": "+",
        "block": "kubejs:ruined_lectern[facing=south]"
      },
      {
        "char": ",",
        "block": "minecraft:polished_andesite"
      },
      {
        "char": "-",
        "block": "minecraft:polished_tuff"
      },
      {
        "char": ".",
        "block": "minecraft:spruce_door[facing=south,half=lower,hinge=left,open=false,powered=false]"
      },
      {
        "char": "/",
        "block": "minecraft:spruce_door[facing=south,half=upper,hinge=left,open=false,powered=false]"
      },
      {
        "char": "0",
        "block": "tfmg:asphalt"
      }
    ]
  }
}
