{
  "xsize": 16,
  "zsize": 16,
  "slices": [
    [
      "2222''&222222222",
      "22''&22222222222",
      "''&2222222222222",
      "&222222222222222",
      "222222222222222'",
      "2222222222222''&",
      "22222222222''&22",
      "222222222''&2222",
      "2222222''&222222",
      "22222''&22222222",
      "222''&2222222222",
      "2''&222222222222",
      "'&22222222222222",
      "2222222222222222",
      "22222222222222''",
      "222222222222''&2"
    ],
    [
      " ''''''''''''''4",
      " ''''''''''''''4",
      " ''''''''''''''4",
      " ''''''''''''''4",
      " ''''''''''''''4",
      " ''''''''''''''4",
      " '''''''''''''44",
      "  '''''''''''4(4",
      " (('''''''''4((4",
      " ('''''''''4((44",
      "  '44'''''4((444",
      "   4444444444444",
      "   4444444444444",
      "   4444444444444",
      "   4444444444444",
      "   4444444444444"
    ],
    [
      " ''''''''''''''1",
      " ''''''''''''''1",
      " ''''''''''''''1",
      " ''''''''''''''1",
      " ''''''''''''''1",
      " ' '''''''''''11",
      "   ('''''''''   ",
      "  ((''''''''    ",
      "   '' ''''' 5   ",
      "   (33('.'333333",
      "   ( ((''   3   ",
      "   ( ! ! ! !3  $",
      "   (        ,   ",
      "   (        3   ",
      "   (        3 66",
      "   (       (3   "
    ],
    [
      " '''''''''''''11",
      "  ''''''''''' (1",
      " ((''''''''' ((1",
      " (''''''''' ((11",
      "  '% ''''')(( 11",
      "   %((''')((  11",
      "   %(''')((     ",
      "   % '  ((      ",
      "   %   ((       ",
      "   %333(/3333333",
      "   %        3   ",
      "   % ! ! ! !3   ",
      "   %        -   ",
      "   %        3   ",
      "   %        3 66",
      "   (       (3   "
    ],
    [
      "   (''''''''' 11",
      "  ((''''''''  11",
      "   '' '''''   11",
      "   %  (''')   11",
      "   % ((''))   11",
      "   %  '')))   11",
      "   %  )))))     ",
      "   %   000000000",
      "   %            ",
      "   %333333333333",
      "   %        3   ",
      "   % ! ! ! !3   ",
      "   %        3   ",
      "   %        3   ",
      "   %        3   ",
      "   (       (3   "
    ],
    [
      "   %('''*((    )",
      "   % ' *((     )",
      "   %   ((+      ",
      "   %   (++      ",
      "   %   +++      ",
      "   %   +++      ",
      "   %            ",
      "   %            ",
      "   %            ",
      "   %333333333333",
      "   %        3   ",
      "   %        3   ",
      "   %        3   ",
      "   %        3   ",
      "   %        3   ",
      "   (       (3   "
    ]
  ],
  "palette": {
    "palette": [
      {
        "char": "!",
        "block": "immersiveengineering:sheetmetal_steel"
      },
      {
        "char": "$",
        "block": "kubejs:ruined_blast_furnace[facing=south]"
      },
      {
        "char": "%",
        "block": "minecraft:bricks"
      },
      {
        "char": "&",
        "block": "minecraft:coarse_dirt"
      },
      {
        "char": "'",
        "block": "minecraft:gravel"
      },
      {
        "char": "(",
        "block": "minecraft:mud_bricks"
      },
      {
        "char": ")",
        "block": "minecraft:red_concrete"
      },
      {
        "char": "*",
        "block": "minecraft:red_terracotta"
      },
      {
        "char": "+",
        "block": "minecraft:smooth_stone"
      },
      {
        "char": ",",
        "block": "minecraft:spruce_door[facing=east,half=lower,hinge=left,open=false,powered=false]"
      },
      {
        "char": "-",
        "block": "minecraft:spruce_door[facing=east,half=upper,hinge=left,open=false,powered=false]"
      },
      {
        "char": ".",
        "block": "minecraft:spruce_door[facing=south,half=lower,hinge=left,open=false,powered=false]"
      },
      {
        "char": "/",
        "block": "minecraft:spruce_door[facing=south,half=upper,hinge=left,open=false,powered=false]"
      },
      {
        "char": "0",
        "block": "minecraft:stripped_dark_oak_log[axis=x]"
      },
      {
        "char": "1",
        "block": "minecraft:white_concrete"
      },
      {
        "char": "2",
        "block": "tfmg:asphalt"
      },
      {
        "char": "3",
        "block": "tfmg:cinder_block"
      },
      {
        "char": "4",
        "block": "tfmg:factory_floor"
      },
      {
        "char": "5",
        "block": "the_wasteland_reworked:garbage_bag"
      },
      {
        "char": "6",
        "block": "zvhouses:stone_brick_countertop"
      }
    ]
  }
}
