{
  "xsize": 16,
  "zsize": 16,
  "slices": [
    [
      "111111111111111 ",
      "-1111-1111-1111-",
      "1111111111111111",
      "1111111111111111",
      "111111111111111-",
      "111111111111111$",
      "1111111111111111",
      "1111111111111111",
      "1111111--$111111",
      "11111--$11111111",
      "111--$1111111111",
      "1--$111111111111",
      "-$11111111111111",
      "1111111111111111",
      "11111111111111--",
      "111111111111--$1"
    ],
    [
      "                ",
      "                ",
      "                ",
      "                ",
      "............... ",
      "............... ",
      "............... ",
      "............... ",
      "............... ",
      "............... ",
      "............... ",
      "............... ",
      "................",
      "................",
      "................",
      "................"
    ],
    [
      "                ",
      "                ",
      "                ",
      "                ",
      "000%&0000000000 ",
      "              0 ",
      "              0 ",
      "              0 ",
      "              0 ",
      "              0 ",
      "              0 ",
      "              0 ",
      "              00",
      " !!!!%!!!! !!!!%",
      "000)*0000000000 ",
      "   /  /      /  "
    ],
    [
      "                ",
      "                ",
      "                ",
      "                ",
      "000'(0000000000 ",
      "              0 ",
      "              0 ",
      "              0 ",
      "              0 ",
      "              0 ",
      "              0 ",
      "              0 ",
      "              00",
      " !!!!'!!!! !!!!'",
      "000+,0000000000 ",
      "   /  /      /  "
    ],
    [
      "                ",
      "                ",
      "                ",
      "                ",
      "000000000000000 ",
      "              0 ",
      "              0 ",
      "              0 ",
      "              0 ",
      "              0 ",
      "              0 ",
      "              0 ",
      "              00",
      " !!!!!!!!! !!!!!",
      "000000000000000 ",
      "   /  /      /  "
    ],
    [
      "                ",
      "                ",
      "                ",
      "                ",
      "000000000000000 ",
      "              0 ",
      "              0 ",
      "              0 ",
      "              0 ",
      "              0 ",
      "              0 ",
      "              0 ",
      "              00",
      " !!!!!!!!! !!!!!",
      "000000000000000 ",
      "                "
    ]
  ],
  "palette": {
    "palette": [
      {
        "char": "!",
        "block": "create:framed_glass"
      },
      {
        "char": "$",
        "block": "minecraft:coarse_dirt"
      },
      {
        "char": "%",
        "block": "minecraft:dark_oak_door[facing=north,half=lower,hinge=left,open=false,powered=false]"
      },
      {
        "char": "&",
        "block": "minecraft:dark_oak_door[facing=north,half=lower,hinge=right,open=false,powered=false]"
      },
      {
        "char": "'",
        "block": "minecraft:dark_oak_door[facing=north,half=upper,hinge=left,open=false,powered=false]"
      },
      {
        "char": "(",
        "block": "minecraft:dark_oak_door[facing=north,half=upper,hinge=right,open=false,powered=false]"
      },
      {
        "char": ")",
        "block": "minecraft:dark_oak_door[facing=south,half=lower,hinge=left,open=false,powered=false]"
      },
      {
        "char": "*",
        "block": "minecraft:dark_oak_door[facing=south,half=lower,hinge=right,open=false,powered=false]"
      },
      {
        "char": "+",
        "block": "minecraft:dark_oak_door[facing=south,half=upper,hinge=left,open=false,powered=false]"
      },
      {
        "char": ",",
        "block": "minecraft:dark_oak_door[facing=south,half=upper,hinge=right,open=false,powered=false]"
      },
      {
        "char": "-",
        "block": "minecraft:gravel"
      },
      {
        "char": ".",
        "block": "minecraft:polished_andesite"
      },
      {
        "char": "/",
        "block": "minecraft:scaffolding"
      },
      {
        "char": "0",
        "block": "minecraft:smooth_stone"
      },
      {
        "char": "1",
        "block": "tfmg:asphalt"
      }
    ]
  }
}
