{
  "xsize": 16,
  "zsize": 16,
  "slices": [
    [
      "1111111111111111",
      "'1111'1111'1111'",
      "1111111111111111",
      "1111111111111111",
      "1111111111111111",
      "1111111111111111",
      "1111111111111111",
      "1111111111111111",
      "1111111''%111111",
      "11111''%11111111",
      "111''%1111111111",
      "1''%111111111111",
      "'%11111111111111",
      "1111111111111111",
      "11111111111111''",
      "111111111111''%1"
    ],
    [
      "                ",
      "                ",
      "                ",
      "                ",
      "-      -----    ",
      "-      -----    ",
      "-      -----    ",
      "-++++++-----++++",
      "++++++++++++++++",
      "++++++++++++++++",
      "++++++++++++++++",
      "++++++++++++++++",
      "++++++++++++++++",
      "++++++++++++++++",
      "++++++++++++++++",
      "++++++++++++++++"
    ],
    [
      "                ",
      "                ",
      "                ",
      "                ",
      "                ",
      "                ",
      "                ",
      "////-----)-----2",
      "   /-         -2",
      "   /-         -2",
      "   /-$$$$     -2",
      "&  /-( . &&&  -2",
      "  3/-        3-2",
      "   /-         -2",
      "   /-     ,   -2",
      "   /-         -2"
    ],
    [
      "                ",
      "                ",
      "                ",
      "                ",
      "                ",
      "                ",
      "                ",
      "////-----*-----2",
      "   /-         -2",
      "   /-         -2",
      "   /-   0     -2",
      "   /-         -2",
      "  0/-        0-2",
      "   /-         -2",
      "   /-         -2",
      "   /-         -2"
    ],
    [
      "                ",
      "                ",
      "                ",
      "                ",
      "                ",
      "                ",
      "                ",
      "/!!/--!!----!!-2",
      "   /-         -2",
      "   /-         -2",
      "   /-         -2",
      "   /-         -2",
      "   /-         -2",
      "   /-         -2",
      "   /-         -2",
      "   /-         -2"
    ],
    [
      "                ",
      "                ",
      "                ",
      "                ",
      "                ",
      "                ",
      "                ",
      "/!!/--!!----!!-2",
      "   /-         -2",
      "   /-         -2",
      "   /-         -2",
      "   /-         -2",
      "   /-         -2",
      "   /-         -2",
      "   /-         -2",
      "   /-         -2"
    ]
  ],
  "palette": {
    "palette": [
      {
        "char": "!",
        "block": "create:framed_glass"
      },
      {
        "char": "$",
        "block": "minecraft:barrel[facing=up,open=false]"
      },
      {
        "char": "%",
        "block": "minecraft:coarse_dirt"
      },
      {
        "char": "&",
        "block": "minecraft:dark_oak_stairs[facing=south,half=bottom,shape=straight,waterlogged=false]"
      },
      {
        "char": "'",
        "block": "minecraft:gravel"
      },
      {
        "char": "(",
        "block": "minecraft:smoker[facing=north,lit=false]"
      },
      {
        "char": ")",
        "block": "minecraft:spruce_door[facing=north,half=lower,hinge=left,open=false,powered=false]"
      },
      {
        "char": "*",
        "block": "minecraft:spruce_door[facing=north,half=upper,hinge=left,open=false,powered=false]"
      },
      {
        "char": "+",
        "block": "minecraft:spruce_planks"
      },
      {
        "char": ",",
        "block": "minecraft:spruce_slab[type=bottom,waterlogged=false]"
      },
      {
        "char": "-",
        "block": "minecraft:stone_bricks"
      },
      {
        "char": ".",
        "block": "minecraft:water_cauldron[level=1]"
      },
      {
        "char": "/",
        "block": "minecraft:yellow_terracotta"
      },
      {
        "char": "0",
        "block": "supplementaries:item_shelf"
      },
      {
        "char": "1",
        "block": "tfmg:asphalt"
      },
      {
        "char": "2",
        "block": "the_wasteland_reworked:decayed_planks"
      },
      {
        "char": "3",
        "block": "the_wasteland_reworked:radio"
      }
    ]
  }
}
