{
  "xsize": 16,
  "zsize": 16,
  "slices": [
    [
      "    &           ",
      "&&&&&&&&&&&&&&&&",
      "    &           ",
      "    &           ",
      "    &           ",
      "    &           ",
      "    &           ",
      "    &           ",
      "    &           ",
      "    &           ",
      "    &           ",
      "   --------&&&&&",
      " -        -     ",
      " -        -     ",
      " -        -     ",
      " -        -     "
    ],
    [
      "    &           ",
      "&&&&&&&&&&&&&&&&",
      "    &           ",
      "    &           ",
      "    &           ",
      "    &           ",
      "    &           ",
      "    &           ",
      "    &           ",
      "    &           ",
      "    &           ",
      "   --------&&&&&",
      " -        -     ",
      " -        -     ",
      " -        -     ",
      " -        -     "
    ],
    [
      "                ",
      "                ",
      "                ",
      "                ",
      "                ",
      "                ",
      "                ",
      "                ",
      "                ",
      "                ",
      "                ",
      "-----------&&&&&",
      " -        -     ",
      " -        -     ",
      " -        -     ",
      " -        -     "
    ],
    [
      "                ",
      "                ",
      "                ",
      "                ",
      "                ",
      "                ",
      "                ",
      "                ",
      "                ",
      "                ",
      "                ",
      "-----------&&&&&",
      "          -     ",
      "          -     ",
      "          -     ",
      "          -     "
    ],
    [
      "''''''''''''''''",
      "''''''''''''''''",
      "''''''''''''''''",
      "''''''''''''''''",
      "''''''''''''''''",
      "''''''''''''''''",
      "''''''''''''''''",
      "''''''''''''''''",
      "''''''''''''''''",
      "''''''''''''''''",
      "''''''''''''''''",
      "-----------&&&&&",
      "''''''''''(     ",
      "''''''''''(     ",
      "''''''''''(     ",
      "''''''''''(     "
    ],
    [
      "    &           ",
      "&&&&&&&&+&&&&&&&",
      "    &           ",
      "    &           ",
      "    &          )",
      "    &           ",
      "    *         $!",
      "    &           ",
      "    &           ",
      "    &           ",
      "    &           ",
      "   --------&&&&&",
      " -        -     ",
      " -        -     ",
      " -        -     ",
      " -  % ,   -     "
    ]
  ],
  "palette": {
    "palette": [
      {
        "char": "!",
        "block": "minecraft:brewing_stand"
      },
      {
        "char": "$",
        "block": "minecraft:chest[facing=north,type=single,waterlogged=false]",
        "tag": {
          "id": "minecraft:chest",
          "LootTable": "infinite_domain:chests/wasteland_office"
        }
      },
      {
        "char": "%",
        "block": "minecraft:light_gray_bed[facing=south,occupied=false,part=foot]"
      },
      {
        "char": "&",
        "block": "minecraft:light_gray_concrete"
      },
      {
        "char": "'",
        "block": "minecraft:polished_andesite"
      },
      {
        "char": "(",
        "block": "minecraft:smooth_stone"
      },
      {
        "char": ")",
        "block": "minecraft:spawner",
        "tag": {
          "id": "minecraft:mob_spawner",
          "Delay": 200,
          "MinSpawnDelay": 240,
          "MaxSpawnDelay": 720,
          "SpawnCount": 2,
          "MaxNearbyEntities": 8,
          "RequiredPlayerRange": 14,
          "SpawnRange": 4,
          "SpawnData": {
            "entity": {
              "id": "the_wasteland_reworked:ghoul"
            }
          },
          "SpawnPotentials": [
            {
              "weight": 1,
              "data": {
                "entity": {
                  "id": "the_wasteland_reworked:ghoul"
                }
              }
            }
          ]
        }
      },
      {
        "char": "*",
        "block": "minecraft:spruce_door[facing=east,half=lower,hinge=left,open=false,powered=false]"
      },
      {
        "char": "+",
        "block": "minecraft:spruce_door[facing=south,half=lower,hinge=left,open=false,powered=false]"
      },
      {
        "char": ",",
        "block": "minecraft:water_cauldron[level=3]"
      },
      {
        "char": "-",
        "block": "minecraft:white_concrete"
      }
    ]
  }
}
