{
  "xsize": 16,
  "zsize": 16,
  "slices": [
    [
      "  44444444444444",
      "--4444-4444-4444",
      "4444444444444444",
      "4444444444444444",
      "4444444444444444",
      "4444444444444444",
      "4444444444444444",
      "444444--$4444444",
      "4444--$444444444",
      "44--$44444444444",
      "--$4444444444444",
      "$444444444444444",
      "444444444444444-",
      "4444444444444--$",
      "44444444444--$44",
      "444444444--$4444"
    ],
    [
      "                ",
      "                ",
      "                ",
      "                ",
      "  //////////////",
      "  //////////////",
      "  //////////////",
      "55//////////////",
      "55//////////////",
      "55//////////////",
      "5555555555555555",
      "5555555555555555",
      "5555555555555555",
      "5555555555555555",
      "5555555555555555",
      "5555551111111111"
    ],
    [
      "                ",
      "                ",
      "                ",
      "                ",
      "  111111%&111111",
      "  1             ",
      "  1  0          ",
      "..1  0          ",
      "  1  0          ",
      "  111111)*111111",
      "                ",
      "  22            ",
      "  3             ",
      "                ",
      "                ",
      "      !!!!!!!!!!"
    ],
    [
      "                ",
      "                ",
      "                ",
      "                ",
      "  111111'(111111",
      "  1             ",
      "  1  0          ",
      "..1  0          ",
      "  1  0          ",
      "  111111+,111111",
      "                ",
      "                ",
      "                ",
      "                ",
      "                ",
      "      !!!!!!!!!!"
    ],
    [
      "                ",
      "                ",
      "                ",
      "                ",
      "  11111111111111",
      "  1             ",
      "  1  0          ",
      "..1  0          ",
      "  1  0          ",
      "  11111111111111",
      "                ",
      "                ",
      "                ",
      "                ",
      "                ",
      "      !!!!!!!!!!"
    ],
    [
      "                ",
      "                ",
      "                ",
      "                ",
      "  11111111111111",
      "  1             ",
      "  1  0          ",
      "..1  0          ",
      "  1  0          ",
      "  11111111111111",
      "                ",
      "                ",
      "                ",
      "                ",
      "                ",
      "      !!!!!!!!!!"
    ]
  ],
  "palette": {
    "palette": [
      {
        "char": "!",
        "block": "minecraft:bricks"
      },
      {
        "char": "$",
        "block": "minecraft:coarse_dirt"
      },
      {
        "char": "%",
        "block": "minecraft:dark_oak_door[facing=north,half=lower,hinge=left,open=false,powered=false]"
      },
      {
        "char": "&",
        "block": "minecraft:dark_oak_door[facing=north,half=lower,hinge=right,open=false,powered=false]"
      },
      {
        "char": "'",
        "block": "minecraft:dark_oak_door[facing=north,half=upper,hinge=left,open=false,powered=false]"
      },
      {
        "char": "(",
        "block": "minecraft:dark_oak_door[facing=north,half=upper,hinge=right,open=false,powered=false]"
      },
      {
        "char": ")",
        "block": "minecraft:dark_oak_door[facing=south,half=lower,hinge=left,open=false,powered=false]"
      },
      {
        "char": "*",
        "block": "minecraft:dark_oak_door[facing=south,half=lower,hinge=right,open=false,powered=false]"
      },
      {
        "char": "+",
        "block": "minecraft:dark_oak_door[facing=south,half=upper,hinge=left,open=false,powered=false]"
      },
      {
        "char": ",",
        "block": "minecraft:dark_oak_door[facing=south,half=upper,hinge=right,open=false,powered=false]"
      },
      {
        "char": "-",
        "block": "minecraft:gravel"
      },
      {
        "char": ".",
        "block": "minecraft:mud_bricks"
      },
      {
        "char": "/",
        "block": "minecraft:polished_andesite"
      },
      {
        "char": "0",
        "block": "minecraft:polished_blackstone_bricks"
      },
      {
        "char": "1",
        "block": "minecraft:smooth_stone"
      },
      {
        "char": "2",
        "block": "minecraft:spruce_slab[type=bottom,waterlogged=false]"
      },
      {
        "char": "3",
        "block": "minecraft:spruce_stairs[facing=north,half=bottom,shape=straight,waterlogged=false]"
      },
      {
        "char": "4",
        "block": "tfmg:asphalt"
      },
      {
        "char": "5",
        "block": "tfmg:factory_floor"
      }
    ]
  }
}
