{
  "xsize": 16,
  "zsize": 16,
  "slices": [
    [
      "++++++++++++++++",
      "+++++++++++++++(",
      "+++++++++++++++(",
      "+++++++++++++++(",
      "+++++++++++++++(",
      "+++++++++++++++(",
      "+++++++++++++++(",
      "+++%%$+++++++++(",
      "+%%$+++++++++++(",
      "%$++++++++++++++",
      "++++++++++++++++",
      "++++++++++++++%%",
      "++++++++++++%%$+",
      "++++++++++%%$+++",
      "++++++++%%$+++++",
      "++++++%%$+++++++"
    ],
    [
      "                ",
      "                ",
      "   ! ! !%%%%% !%",
      "     %  % %%!%  ",
      "    % %%%%%%%%!%",
      "   % %%%%%%%% %%",
      "   !'%%%%%%%%%%%",
      "   %%'%%%%%%%%'%",
      "   %%%%%%%%%%%%%",
      "   %%%%%%%%%%%%%",
      "   %%%%%%%%%%%%%",
      "   %!%%%%%%%%%%%",
      "   !%%'%%%%%%%%'",
      "   !'!%%%%%%%%!%",
      "   %''%'%%%%%%'%",
      "    '%'%%%%%!%%'"
    ],
    [
      "                ",
      "                ",
      "        !%!%%  !",
      "     !  % %% !  ",
      "    ! !%!%%%%% !",
      "   ! !%!%%%%%)!%",
      "     %!%%%%%%%%!",
      "   !% %%%%%%%% %",
      "   %!%%%%%%%%%%%",
      "   !%%%%%%%%%%%%",
      "   %%%%%%%%%%%%%",
      "   % %%%%%%%%%%%",
      "    !% %%%%%%%% ",
      "    & !%!%%%%% !",
      "   !&&%&%%%%%!&%",
      "    &! !%!%% !! "
    ],
    [
      "                ",
      "                ",
      "         % !!   ",
      "        ! !%    ",
      "       % %%!!%  ",
      "      ! !%!%%  !",
      "     % %%%%%!%% ",
      "    ! !%!%%%%% !",
      "   % %%%%%%%%%%%",
      "    !%!%%%%%%%%!",
      "   !%!%%%%%%%%!%",
      "   ! !%!%%%%%!!%",
      "    &% %%%%%!%% ",
      "    &  % %%!!% &",
      "    &&!&!%!%%&&!",
      "    &   ! !%    "
    ],
    [
      "                ",
      "                ",
      "         !      ",
      "           !    ",
      "       ! !%  !  ",
      "         % !!   ",
      "     ! !%!%% !! ",
      "       % %%!!%  ",
      "   ! !%!%%%%%!!%",
      "     % %%%%%!%% ",
      "    ! !%!%%%%% !",
      "      ! !,!%%  !",
      "     ! !%!%% !! ",
      "    &  ! !%  !  ",
      "    &&&  % !! &&",
      "    &      !    "
    ],
    [
      "                ",
      "                ",
      "                ",
      "                ",
      "          !     ",
      "       **!  **  ",
      "        ! !%    ",
      "       ! !%  !  ",
      "      ! !%!%%  !",
      "     ! !%!%% !! ",
      "       % %%!!%  ",
      "         % !!   ",
      "        ! !%    ",
      "    &     !     ",
      "    &&&  !    &&",
      "    &           "
    ]
  ],
  "palette": {
    "palette": [
      {
        "char": "!",
        "block": "immersiveengineering:concrete_brick_cracked"
      },
      {
        "char": "$",
        "block": "minecraft:coarse_dirt"
      },
      {
        "char": "%",
        "block": "minecraft:gravel"
      },
      {
        "char": "&",
        "block": "minecraft:light_gray_concrete"
      },
      {
        "char": "'",
        "block": "minecraft:polished_andesite"
      },
      {
        "char": "(",
        "block": "minecraft:smooth_stone"
      },
      {
        "char": ")",
        "block": "minecraft:spruce_slab[type=bottom,waterlogged=false]"
      },
      {
        "char": "*",
        "block": "minecraft:spruce_slab[type=top,waterlogged=false]"
      },
      {
        "char": "+",
        "block": "tfmg:asphalt"
      },
      {
        "char": ",",
        "block": "wastelands:scrap_pile"
      }
    ]
  }
}
