{
  "xsize": 16,
  "zsize": 16,
  "slices": [
    [
      "'''&&%''''''''''",
      "'&&%''''''''''''",
      "&%''''''''''''''",
      "''''''''''''''''",
      "''''''''''''''&&",
      "''''''''''''&&%'",
      "''''''''''&&%'''",
      "''''''''&&%'''''",
      "''''''&&%'''''''",
      "''''&&%'''''''''",
      "''&&%'''''''''''",
      "&&%'''''''''''''",
      "%'''''''''''''''",
      "'''''''''''''''&",
      "'''''''''''''&&%",
      "%''''%''''%&&%'%"
    ],
    [
      "$$$$$$$$$$$$$$$$",
      "$$$$$$$$$$$$$$$$",
      "$$$$$$$$$$$$$$$$",
      "$$$$$$$$$$$$$$$$",
      "$$$$$$$$$$$$$$$$",
      "$$$$$$$$$$$$$$$$",
      "$$$$$$$$$$$$$$$$",
      "$$$$$$$$$$$$$$$$",
      "$$$$$$$$$$$$$$$$",
      "$$$$$$$$$$$$$$$$",
      "$$$$$$$$$$$$$$$$",
      "$$$$$$$$$$$$$$$$",
      "$$$$$$$$$$$$$$$$",
      "$$$$$$$$$$$$$$$$",
      "                ",
      "                "
    ],
    [
      "$$$$$$$$$$$$$$$$",
      "$$$$$$$$$$$$$$$$",
      "$$$$$$$$$$$$$$$$",
      "$$$$$$$$$$$$$$$$",
      "$$$$$$$$$$$$$$$$",
      "$$$$$$$$$$$$$$$$",
      "$$$$$$$$$$$$$$$$",
      "$$$$$$$$$$$$$$$$",
      "$$$$$$$$$$$$$$$$",
      "$$$$$$$$$$$$$$$$",
      "$$$$$$$$$$$$$$$$",
      "$$$$$$$$$$$$$$$$",
      "$$$$$$$$$$$$$$$$",
      "$$$$$$$$$$$$$$$$",
      "                ",
      "                "
    ],
    [
      "!!!!!!!&&&&&&&&&",
      "   !   &&&&&&&&&",
      "       &&&&&&&&&",
      "              &&",
      "              &&",
      "              &&",
      "              &&",
      "              &&",
      "              &&",
      "              &&",
      "                ",
      "                ",
      "                ",
      "                ",
      "                ",
      "                "
    ],
    [
      "!!!!!!!&&&&&&&&&",
      "   !   &&&&&&&&&",
      "       &&&&&&&&&",
      "              &&",
      "              &&",
      "              &&",
      "              &&",
      "              &&",
      "              &&",
      "              &&",
      "                ",
      "                ",
      "                ",
      "                ",
      "                ",
      "                "
    ],
    [
      "!!!!!!!&&&&&&&&&",
      "   !   &&&&&&&&&",
      "       &&&&&&&&&",
      "              &&",
      "              &&",
      "              &&",
      "              &&",
      "              &&",
      "              &&",
      "              &&",
      "                ",
      "                ",
      "                ",
      "                ",
      "                ",
      "                "
    ]
  ],
  "palette": {
    "palette": [
      {
        "char": "!",
        "block": "immersiveengineering:sheetmetal_steel"
      },
      {
        "char": "$",
        "block": "minecraft:black_concrete"
      },
      {
        "char": "%",
        "block": "minecraft:coarse_dirt"
      },
      {
        "char": "&",
        "block": "minecraft:gravel"
      },
      {
        "char": "'",
        "block": "tfmg:asphalt"
      }
    ]
  }
}
