{
  "xsize": 16,
  "zsize": 16,
  "slices": [
    [
      "                ",
      "                ",
      "                ",
      "                ",
      "                ",
      "                ",
      "    %%%%%%%%%%%%",
      "    %           ",
      "    %           ",
      "    %           ",
      "    %           ",
      "    %           ",
      "    %           ",
      "    %           ",
      "    %           ",
      "    %           "
    ],
    [
      "                ",
      "                ",
      "                ",
      "                ",
      "                ",
      "                ",
      "    %%%%%%%%%%%%",
      "    %           ",
      "    %           ",
      "    %           ",
      "    %           ",
      "    %           ",
      "    %           ",
      "    %           ",
      "    %           ",
      "    %           "
    ],
    [
      "                ",
      "                ",
      "                ",
      "                ",
      "                ",
      "                ",
      "    $$$$$$$$$$$$",
      "    $&&&&&&&&&&&",
      "    $&&&&&&&&&&&",
      "    $&&&&&&&&&&&",
      "    $&&&&&&&&&&&",
      "    $&&&&&&&&&&&",
      "    $&&&&&&&&&&&",
      "    $&&&&&&&&&&&",
      "    $&&&&&&&&&&&",
      "    $&&&&&&&&&&&"
    ],
    [
      "                ",
      "                ",
      "                ",
      "                ",
      "                ",
      "       ))   ))  ",
      "    %%%%%%%%%%%%",
      "    %         % ",
      "    %         % ",
      "    %  )) ))  % ",
      "    %  *  *   % ",
      "    %         % ",
      "    %         % ",
      "    %         ' ",
      "    %         % ",
      "    %         % "
    ],
    [
      "                ",
      "                ",
      "                ",
      "                ",
      "                ",
      "                ",
      "    %%+!!+%+!!+%",
      "    %         % ",
      "    %         % ",
      "    %         % ",
      "    !         % ",
      "    !         % ",
      "    %         % ",
      "    %         ( ",
      "    %         % ",
      "    %         % "
    ],
    [
      "                ",
      "                ",
      "                ",
      "                ",
      "                ",
      "                ",
      "    %%+!!+%+!!+%",
      "    %         % ",
      "    %         % ",
      "    %         % ",
      "    !         % ",
      "    !         % ",
      "    %         % ",
      "    %         % ",
      "    %         % ",
      "    %         % "
    ]
  ],
  "palette": {
    "palette": [
      {
        "char": "!",
        "block": "create:framed_glass"
      },
      {
        "char": "$",
        "block": "minecraft:blue_concrete"
      },
      {
        "char": "%",
        "block": "minecraft:light_gray_concrete"
      },
      {
        "char": "&",
        "block": "minecraft:polished_andesite"
      },
      {
        "char": "'",
        "block": "minecraft:spruce_door[facing=east,half=lower,hinge=left,open=false,powered=false]"
      },
      {
        "char": "(",
        "block": "minecraft:spruce_door[facing=east,half=upper,hinge=left,open=false,powered=false]"
      },
      {
        "char": ")",
        "block": "minecraft:spruce_slab[type=bottom,waterlogged=false]"
      },
      {
        "char": "*",
        "block": "minecraft:spruce_stairs[facing=north,half=bottom,shape=straight,waterlogged=false]"
      },
      {
        "char": "+",
        "block": "minecraft:stripped_spruce_log[axis=y]"
      }
    ]
  }
}
