{
  "xsize": 16,
  "zsize": 16,
  "slices": [
    [
      "0000000%%$000000",
      "00000%%$00000000",
      "000%%$0000000000",
      "0%%$000000000000",
      "%$00000000000000",
      "0000000000000000",
      "00000000000000%%",
      "000000000000%%$0",
      "0000000000%%$000",
      "00000000%%$00000",
      "000000%%$0000000",
      "0000%%$000000000",
      "00%%$00000000000",
      "%%$0000000000000",
      "$000000000000000",
      "000000000000000%"
    ],
    [
      "2222222222222222",
      "2222222222222222",
      "2222222222222222",
      "2222222222222222",
      "2222222222222222",
      "2222222222222222",
      "2222222222222222",
      "2222222222222222",
      "2222222222222222",
      "2222222222222222",
      "2222222222222222",
      "2222222222222222",
      "2222222222222222",
      "2222222222222222",
      "''''''''''''''''",
      "''''''''''''''''"
    ],
    [
      ". 1          .  ",
      "  1   -  -  -   ",
      "111111,11,*1,111",
      "  1             ",
      "  1             ",
      "  (             ",
      "  1             ",
      "  1             ",
      "1111111111*11111",
      "  1             ",
      "  1             ",
      "  1             ",
      "  1             ",
      "  1             ",
      "//&/////////////",
      "  &             "
    ],
    [
      "  1             ",
      "  1             ",
      "1111111111+11111",
      "  1             ",
      "  1             ",
      "  )             ",
      "  1             ",
      "  1             ",
      "1111111111+11111",
      "  1             ",
      "  1             ",
      "  1             ",
      "  1             ",
      "  1             ",
      "//&/////////////",
      "  &             "
    ],
    [
      "  1             ",
      "  1             ",
      "1111111111111111",
      "  1             ",
      "  1             ",
      "  1             ",
      "  1             ",
      "  1             ",
      "1111111111111111",
      "  1             ",
      "  1             ",
      "  1             ",
      "  1             ",
      "  1             ",
      "//&/////////////",
      "  &             "
    ],
    [
      "  1             ",
      "  1             ",
      "1111111111111111",
      "  1             ",
      "  1             ",
      "  1             ",
      "  1             ",
      "  1             ",
      "1111111111111111",
      "  1             ",
      "  1             ",
      "  1             ",
      "  1             ",
      "  1             ",
      "//&/////////////",
      "  &     !!      "
    ]
  ],
  "palette": {
    "palette": [
      {
        "char": "!",
        "block": "create:framed_glass"
      },
      {
        "char": "$",
        "block": "minecraft:coarse_dirt"
      },
      {
        "char": "%",
        "block": "minecraft:gravel"
      },
      {
        "char": "&",
        "block": "minecraft:mud_bricks"
      },
      {
        "char": "'",
        "block": "minecraft:smooth_stone"
      },
      {
        "char": "(",
        "block": "minecraft:spruce_door[facing=east,half=lower,hinge=left,open=false,powered=false]"
      },
      {
        "char": ")",
        "block": "minecraft:spruce_door[facing=east,half=upper,hinge=left,open=false,powered=false]"
      },
      {
        "char": "*",
        "block": "minecraft:spruce_door[facing=south,half=lower,hinge=left,open=false,powered=false]"
      },
      {
        "char": "+",
        "block": "minecraft:spruce_door[facing=south,half=upper,hinge=left,open=false,powered=false]"
      },
      {
        "char": ",",
        "block": "minecraft:spruce_slab[type=bottom,waterlogged=false]"
      },
      {
        "char": "-",
        "block": "minecraft:spruce_stairs[facing=north,half=bottom,shape=straight,waterlogged=false]"
      },
      {
        "char": ".",
        "block": "kubejs:ruined_cauldron"
      },
      {
        "char": "/",
        "block": "minecraft:yellow_terracotta"
      },
      {
        "char": "0",
        "block": "tfmg:asphalt"
      },
      {
        "char": "1",
        "block": "tfmg:cinder_block"
      },
      {
        "char": "2",
        "block": "tfmg:factory_floor"
      }
    ]
  }
}
