{
  "xsize": 16,
  "zsize": 16,
  "slices": [
    [
      "&&$''''''       ",
      "$''''''''       ",
      "'''''''''       ",
      "'''''''''       ",
      "'''''''''       ",
      "'''''''''       ",
      "'''''''&&       ",
      "'''''&&$'       ",
      "'''&&$'''       ",
      "'&&$'''''       ",
      "&$'''''''       ",
      "'''''''''       ",
      "'''''''''       ",
      "'''''''''       ",
      "'''''''''       ",
      "''''''''&       "
    ],
    [
      "))))))          ",
      "))))))          ",
      "))))))          ",
      "))))))          ",
      "))))))          ",
      "))))))          ",
      "))))))          ",
      "))))))          ",
      "))))))          ",
      "))))))          ",
      "))))))          ",
      "))))))          ",
      "                ",
      "                ",
      "                ",
      "                "
    ],
    [
      "  %  (          ",
      "     (          ",
      "     (          ",
      "     (          ",
      "     (          ",
      "     (          ",
      "     (          ",
      "!!!! (          ",
      "!!!! (          ",
      "!!!! (          ",
      "     (          ",
      " (   (          ",
      "                ",
      "                ",
      "                ",
      "                "
    ],
    [
      "     (          ",
      "     (          ",
      "     (          ",
      "     (          ",
      "     (          ",
      "     (          ",
      "     (          ",
      "!!!! (          ",
      "!!!! (          ",
      "!!!! (          ",
      "     (          ",
      " (   (          ",
      "                ",
      "                ",
      "                ",
      "                "
    ],
    [
      "     (          ",
      "     (          ",
      "     (          ",
      "     (          ",
      "     (          ",
      "     (          ",
      "     (          ",
      "!!!! (          ",
      "!!!! (          ",
      "!!!! (          ",
      "     (          ",
      " (   (          ",
      "                ",
      "                ",
      "                ",
      "                "
    ],
    [
      "     (          ",
      "     (          ",
      "     (          ",
      "     (          ",
      "     (          ",
      "     (          ",
      "     (          ",
      "     (          ",
      "     (          ",
      "     (          ",
      "     (          ",
      " (   (          ",
      "                ",
      "                ",
      "                ",
      "                "
    ]
  ],
  "palette": {
    "palette": [
      {
        "char": "!",
        "block": "immersiveengineering:crate"
      },
      {
        "char": "$",
        "block": "minecraft:coarse_dirt"
      },
      {
        "char": "%",
        "block": "kubejs:ruined_crafting_table"
      },
      {
        "char": "&",
        "block": "minecraft:gravel"
      },
      {
        "char": "'",
        "block": "tfmg:asphalt"
      },
      {
        "char": "(",
        "block": "tfmg:cinder_block"
      },
      {
        "char": ")",
        "block": "tfmg:factory_floor"
      }
    ]
  }
}
