{
  "xsize": 16,
  "zsize": 16,
  "slices": [
    [
      "----''%---------",
      "--''%-----------",
      "''%-------------",
      "%---------------",
      "---------------'",
      "-------------''%",
      "-----------''%--",
      "---------''%----",
      "-------''%------",
      "-----''%--------",
      "---''%----------",
      "-''%------------",
      "'%--------------",
      "----------------",
      "--------------''",
      "------------''%-"
    ],
    [
      "   )))))))))))))",
      "   )))))))))))))",
      "   )))))))))))))",
      "   )))))))))))))",
      "   )))))))))))))",
      "   )))))))))))))",
      "   )))))))))))))",
      "   )))))))))))))",
      "   )))))))))))))",
      "   )))))))))))))",
      "   )))))))))))))",
      "   )))))))))))))",
      "   )))))))))))))",
      "   )))))))))))))",
      "   )))))))))))))",
      "   )))))))))))))"
    ],
    [
      "   (            ",
      "   (            ",
      "   (            ",
      "   (            ",
      "   (            ",
      "   ( ...........",
      "   ( ...........",
      "   (            ",
      "   ($$$$$$+$$$$$",
      "   (            ",
      "   (            ",
      "   (  *  &   !  ",
      "   (            ",
      "   (            ",
      "   (            ",
      "   (            "
    ],
    [
      "   (            ",
      "   (            ",
      "   (            ",
      "   (            ",
      "   (            ",
      "   (            ",
      "   (            ",
      "   (            ",
      "   ($$$$$$,$$$$$",
      "   (            ",
      "   (            ",
      "   (            ",
      "   (            ",
      "   (            ",
      "   (            ",
      "   (            "
    ],
    [
      "   (            ",
      "   (            ",
      "   (            ",
      "   (            ",
      "   (            ",
      "   (            ",
      "   (            ",
      "   (            ",
      "   ($$$$$$$$$$$$",
      "   (            ",
      "   (            ",
      "   (            ",
      "   (            ",
      "   (            ",
      "   (            ",
      "   (            "
    ],
    [
      "   (            ",
      "   (            ",
      "   (            ",
      "   (            ",
      "   (            ",
      "   (            ",
      "   (            ",
      "   (            ",
      "   ($$$$$$$$$$$$",
      "   (            ",
      "   (            ",
      "   (            ",
      "   (            ",
      "   (            ",
      "   (            ",
      "   (            "
    ]
  ],
  "palette": {
    "palette": [
      {
        "char": "!",
        "block": "minecraft:barrel[facing=up,open=false]"
      },
      {
        "char": "$",
        "block": "minecraft:bricks"
      },
      {
        "char": "%",
        "block": "minecraft:coarse_dirt"
      },
      {
        "char": "&",
        "block": "kubejs:ruined_furnace[facing=south]"
      },
      {
        "char": "'",
        "block": "minecraft:gravel"
      },
      {
        "char": "(",
        "block": "minecraft:mud_bricks"
      },
      {
        "char": ")",
        "block": "minecraft:oak_planks"
      },
      {
        "char": "*",
        "block": "kubejs:ruined_smoker[facing=south]"
      },
      {
        "char": "+",
        "block": "minecraft:spruce_door[facing=south,half=lower,hinge=left,open=false,powered=false]"
      },
      {
        "char": ",",
        "block": "minecraft:spruce_door[facing=south,half=upper,hinge=left,open=false,powered=false]"
      },
      {
        "char": "-",
        "block": "tfmg:asphalt"
      },
      {
        "char": ".",
        "block": "zvhouses:spruce_countertop"
      }
    ]
  }
}
