{
  "xsize": 16,
  "zsize": 16,
  "slices": [
    [
      "$$$$$$$$$$$     ",
      "$$$$$$$$$$$     ",
      "$$$$$$$$$$$     ",
      "$$$$$$$$$$$     ",
      "$$$$$$$$$$$     ",
      "$$$$$$$$$$$     ",
      "$$$$$$$$$$$     ",
      "$$$$$$$$$$$     ",
      "$$$$$$$$$$$     ",
      "$$$$$$$$$$$     ",
      "$$$$$$$$$$$     ",
      "$$$$$$$$$$$     ",
      "$$$$$$$$$$$     ",
      "$$$$$$$$$$$     ",
      "$$$$$$$$$$$!!!!!",
      "$$$$$$$$$$$     "
    ],
    [
      "$$$$$$$$$$$     ",
      "$$$$$$$$$$$     ",
      "$$$$$$$$$$$     ",
      "$$$$$$$$$$$     ",
      "$$$$$$$$$$$     ",
      "$$$$$$$$$$$     ",
      "$$$$$$$$$$$     ",
      "$$$$$$$$$$$     ",
      "$$$$$$$$$$$     ",
      "$$$$$$$$$$$     ",
      "$$$$$$$$$$$     ",
      "$$$$$$$$$$$     ",
      "$$$$$$$$$$$     ",
      "$$$$$$$$$$$     ",
      "$$$$$$$$$$$!!!!!",
      "$$$$$$$$$$$     "
    ],
    [
      "$$$$$$$$$$$     ",
      "$$$$$$$$$$$     ",
      "$$$$$$$$$$$     ",
      "$$$$$$$$$$$     ",
      "$$$$$$$$$$$     ",
      "$$$$$$$$$$$     ",
      "$$$$$$$$$$$     ",
      "$$$$$$$$$$$     ",
      "$$$$$$$$$$$     ",
      "$$$$$$$$$$$     ",
      "$$$$$$$$$$$     ",
      "$$$$$$$$$$$     ",
      "$$$$$$$$$$$     ",
      "$$$$$$$$$$$     ",
      "$$$$$$$$$$$!!!!!",
      "$$$$$$$$$$$     "
    ],
    [
      "$$$$$$$$$$$,,,,,",
      "$$$$$$$$$$$,,,,,",
      "$$$$$$$$$$$,,,,,",
      "$$$$$$$$$$$,,,,,",
      "$$$$$$$$$$$,,,,,",
      "$$$$$$$$$$$,,,,,",
      "$$$$$$$$$$$,,,,,",
      "$$$$$$$$$$$,,,,,",
      "$$$$$$$$$$$,,,,,",
      "$$$$$$$$$$$,,,,,",
      "$$$$$$$$$$$,,,,,",
      "$$$$$$$$$$$,,,,,",
      "$$$$$$$$$$$,,,,,",
      "$$$$$$$$$$$,,,,,",
      "$$$$$$$$$$$!!!!!",
      "$$$$$$$$$$$     "
    ],
    [
      "                ",
      "                ",
      "             '  ",
      " *****          ",
      " *****          ",
      " *****          ",
      " *****          ",
      " *****          ",
      " *****          ",
      "++++++++++++(+++",
      "                ",
      "&&&&&           ",
      "&&&&&           ",
      "&&&&&           ",
      "!!!!!!!!!!!!!!!!",
      "                "
    ],
    [
      "                ",
      "                ",
      "                ",
      "                ",
      "                ",
      "  %             ",
      "                ",
      "                ",
      "                ",
      "++++++++++++)+++",
      "                ",
      "&&&&&           ",
      "&&&&&           ",
      "&&&&&           ",
      "!!!!!!!!!!!!!!!!",
      "                "
    ]
  ],
  "palette": {
    "palette": [
      {
        "char": "!",
        "block": "minecraft:bricks"
      },
      {
        "char": "$",
        "block": "minecraft:gravel"
      },
      {
        "char": "%",
        "block": "minecraft:loom[facing=north]"
      },
      {
        "char": "&",
        "block": "minecraft:scaffolding"
      },
      {
        "char": "'",
        "block": "minecraft:spawner",
        "tag": {
          "id": "minecraft:mob_spawner",
          "Delay": 200,
          "MinSpawnDelay": 240,
          "MaxSpawnDelay": 720,
          "SpawnCount": 2,
          "MaxNearbyEntities": 7,
          "RequiredPlayerRange": 14,
          "SpawnRange": 4,
          "SpawnData": {
            "entity": {
              "id": "the_wasteland_reworked:ghoul"
            }
          },
          "SpawnPotentials": [
            {
              "weight": 1,
              "data": {
                "entity": {
                  "id": "the_wasteland_reworked:ghoul"
                }
              }
            }
          ]
        }
      },
      {
        "char": "(",
        "block": "minecraft:spruce_door[facing=south,half=lower,hinge=left,open=false,powered=false]"
      },
      {
        "char": ")",
        "block": "minecraft:spruce_door[facing=south,half=upper,hinge=left,open=false,powered=false]"
      },
      {
        "char": "*",
        "block": "minecraft:spruce_planks"
      },
      {
        "char": "+",
        "block": "tfmg:cinder_block"
      },
      {
        "char": ",",
        "block": "tfmg:factory_floor"
      }
    ]
  }
}
