{
  "xsize": 16,
  "zsize": 16,
  "slices": [
    [
      "              ) ",
      "              ) ",
      "              ) ",
      "              ) ",
      "              ) ",
      "              ) ",
      "              ) ",
      "              ) ",
      "              ) ",
      "              ) ",
      "              ) ",
      "              ) ",
      "              ) ",
      "              ) ",
      "              ) ",
      "              ) "
    ],
    [
      ".........     ) ",
      ".........     ) ",
      ".........     ) ",
      ".........     ) ",
      ".........     ) ",
      ".........     ) ",
      ".........     ) ",
      ".........     ) ",
      ".........     ) ",
      ".........     ) ",
      ".........     ) ",
      ".........     ) ",
      ".........     ) ",
      ".........     ) ",
      ".........     ) ",
      "..... ...     ) "
    ],
    [
      "        (****** ",
      "        (****** ",
      "        (****** ",
      "        (****** ",
      "        (****** ",
      "!       (****** ",
      "        (****** ",
      " &      (****** ",
      "        (****** ",
      " $      (****** ",
      "        (****** ",
      " ++  +/ (****** ",
      " ,   ,  (****** ",
      "        (****** ",
      "        (****** ",
      "        (****** "
    ],
    [
      "        (       ",
      "        (       ",
      "        (       ",
      "        (       ",
      "        (       ",
      "!       (       ",
      "        (       ",
      " '      (       ",
      "        (       ",
      " %      (       ",
      "        (       ",
      "        (       ",
      "        (       ",
      "        (       ",
      "        (       ",
      "        (       "
    ],
    [
      "        (       ",
      "        (       ",
      "        (       ",
      "        (       ",
      "        (       ",
      "!       (       ",
      "        (       ",
      "        (       ",
      "        (       ",
      "        (       ",
      "        (       ",
      "        (       ",
      "        (       ",
      "     -  (       ",
      "        (       ",
      "        (       "
    ],
    [
      "        (       ",
      "        (       ",
      "        (       ",
      "        (       ",
      "        (       ",
      "        (       ",
      "        (       ",
      "        (       ",
      "        (       ",
      "        (       ",
      "        (       ",
      "        (       ",
      "        (       ",
      "        (       ",
      "     -  (       ",
      "        (       "
    ]
  ],
  "palette": {
    "palette": [
      {
        "char": "!",
        "block": "minecraft:bookshelf"
      },
      {
        "char": "$",
        "block": "minecraft:dark_oak_door[facing=north,half=lower,hinge=left,open=false,powered=false]"
      },
      {
        "char": "%",
        "block": "minecraft:dark_oak_door[facing=north,half=upper,hinge=left,open=false,powered=false]"
      },
      {
        "char": "&",
        "block": "minecraft:dark_oak_door[facing=south,half=lower,hinge=left,open=false,powered=false]"
      },
      {
        "char": "'",
        "block": "minecraft:dark_oak_door[facing=south,half=upper,hinge=left,open=false,powered=false]"
      },
      {
        "char": "(",
        "block": "minecraft:light_gray_concrete"
      },
      {
        "char": ")",
        "block": "minecraft:polished_blackstone_bricks"
      },
      {
        "char": "*",
        "block": "minecraft:smooth_stone"
      },
      {
        "char": "+",
        "block": "minecraft:spruce_slab[type=bottom,waterlogged=false]"
      },
      {
        "char": ",",
        "block": "minecraft:spruce_stairs[facing=north,half=bottom,shape=straight,waterlogged=false]"
      },
      {
        "char": "-",
        "block": "minecraft:stone_brick_stairs[facing=south,half=bottom,shape=straight,waterlogged=false]"
      },
      {
        "char": ".",
        "block": "tfmg:factory_floor"
      },
      {
        "char": "/",
        "block": "the_wasteland_reworked:radio"
      }
    ]
  }
}
