{
  "xsize": 16,
  "zsize": 16,
  "slices": [
    [
      "   &%         %'",
      "   &%         %'",
      "   &%         %'",
      "   &%         %'",
      "&&&&%%%%%!!%%%%'",
      "                ",
      "                ",
      "                ",
      "                ",
      "                ",
      "                ",
      "                ",
      "                ",
      "                ",
      "                ",
      "                "
    ],
    [
      "   &%         %'",
      "   &%         %'",
      "   &%         %'",
      "   &%         %'",
      "&&&&%%%%%%%%%%%'",
      "                ",
      "                ",
      "                ",
      "                ",
      "                ",
      "                ",
      "                ",
      "                ",
      "                ",
      "                ",
      "                "
    ],
    [
      "   &%         %'",
      "   &%         %'",
      "   &%         %'",
      "   &%         %'",
      "&&&&%%%%%%%%%%%'",
      "                ",
      "                ",
      "                ",
      "                ",
      "                ",
      "                ",
      "                ",
      "                ",
      "                ",
      "                ",
      "                "
    ],
    [
      "$$$&%$$$$$$$$$%'",
      "$$$&%$$$$$$$$$%'",
      "$$$&%$$$$$$$$$%'",
      "$$$&%$$$$$$$$$%'",
      "&&&&%%%%%%%%%%%'",
      "                ",
      "                ",
      "                ",
      "                ",
      "                ",
      "                ",
      "                ",
      "                ",
      "                ",
      "                ",
      "                "
    ],
    [
      "   &%         %'",
      "   &%         %'",
      "   &%         %'",
      "   &%         %'",
      "&&&&%%%%%%%%%%%'",
      "                ",
      "                ",
      "                ",
      "                ",
      "                ",
      "                ",
      "                ",
      "                ",
      "                ",
      "                ",
      "                "
    ],
    [
      "   &%         %'",
      "   &%         %'",
      "   &%         %'",
      "   &%         %'",
      "&&&&%%%%%%%%%%%'",
      "                ",
      "                ",
      "                ",
      "                ",
      "                ",
      "                ",
      "                ",
      "                ",
      "                ",
      "                ",
      "                "
    ]
  ],
  "palette": {
    "palette": [
      {
        "char": "!",
        "block": "create:framed_glass"
      },
      {
        "char": "$",
        "block": "minecraft:spruce_planks"
      },
      {
        "char": "%",
        "block": "minecraft:stone_bricks"
      },
      {
        "char": "&",
        "block": "minecraft:yellow_terracotta"
      },
      {
        "char": "'",
        "block": "the_wasteland_reworked:decayed_planks"
      }
    ]
  }
}
