{
  "xsize": 16,
  "zsize": 16,
  "slices": [
    [
      "000000%%$0000000",
      "0000%%$000000000",
      "00%%$00000000000",
      "%%$0000000000000",
      "$000000000000000",
      "000000000000000%",
      "0000000000000%%$",
      "00000000000%%$00",
      "000000000%%$0000",
      "0000000%%$000000",
      "00000%%$00000000",
      "000%%$0000000000",
      "0%%$000000000000",
      "%$00$0000$0000$0",
      "                ",
      "                "
    ],
    [
      "+++++22222222222",
      "+++++22222222222",
      "+++++22222222222",
      "+++++22222222222",
      "+++++22222222222",
      "   2222222222222",
      "   2222222222222",
      "   2222222222222",
      "                ",
      "                ",
      "                ",
      "                ",
      "                ",
      "                ",
      "                ",
      "                "
    ],
    [
      ",   -           ",
      ",   -           ",
      "111111111.111111",
      "!!!!-       1   ",
      "-----  ,,,,,,,,,",
      "   *   ,,,,,,,,,",
      "   *   ,,,,,,,,,",
      "   **********&'*",
      "                ",
      "                ",
      "                ",
      "                ",
      "                ",
      "                ",
      "                ",
      "                "
    ],
    [
      ",   -           ",
      ",   -           ",
      "111111111/111111",
      "!!!!-       1   ",
      "-----  ,,,,,,,,,",
      "   *   ,,,,,,,,,",
      "   *   ,,,,,,,,,",
      "   **********()*",
      "                ",
      "                ",
      "                ",
      "                ",
      "                ",
      "                ",
      "                ",
      "                "
    ],
    [
      ",   -           ",
      ",   -           ",
      "1111111111111111",
      "!!!!-       1   ",
      "-----  ,,,,,,,,,",
      "   *   ,,,,,,,,,",
      "   *   ,,,,,,,,,",
      "   *************",
      "                ",
      "                ",
      "                ",
      "                ",
      "                ",
      "                ",
      "                ",
      "                "
    ],
    [
      "    -           ",
      "    -           ",
      "1111111111111111",
      "!!!!-       1   ",
      "-----  ,,,,,,,,,",
      "   *   ,,,,,,,,,",
      "   *   ,,,,,,,,,",
      "   *************",
      "                ",
      "                ",
      "                ",
      "                ",
      "                ",
      "                ",
      "                ",
      "                "
    ]
  ],
  "palette": {
    "palette": [
      {
        "char": "!",
        "block": "create:framed_glass"
      },
      {
        "char": "$",
        "block": "minecraft:coarse_dirt"
      },
      {
        "char": "%",
        "block": "minecraft:gravel"
      },
      {
        "char": "&",
        "block": "minecraft:iron_door[facing=south,half=lower,hinge=left,open=false,powered=false]"
      },
      {
        "char": "'",
        "block": "minecraft:iron_door[facing=south,half=lower,hinge=right,open=false,powered=false]"
      },
      {
        "char": "(",
        "block": "minecraft:iron_door[facing=south,half=upper,hinge=left,open=false,powered=false]"
      },
      {
        "char": ")",
        "block": "minecraft:iron_door[facing=south,half=upper,hinge=right,open=false,powered=false]"
      },
      {
        "char": "*",
        "block": "minecraft:mud_bricks"
      },
      {
        "char": "+",
        "block": "minecraft:polished_andesite"
      },
      {
        "char": ",",
        "block": "minecraft:scaffolding"
      },
      {
        "char": "-",
        "block": "minecraft:smooth_stone"
      },
      {
        "char": ".",
        "block": "minecraft:spruce_door[facing=south,half=lower,hinge=left,open=false,powered=false]"
      },
      {
        "char": "/",
        "block": "minecraft:spruce_door[facing=south,half=upper,hinge=left,open=false,powered=false]"
      },
      {
        "char": "0",
        "block": "tfmg:asphalt"
      },
      {
        "char": "1",
        "block": "tfmg:cinder_block"
      },
      {
        "char": "2",
        "block": "tfmg:factory_floor"
      }
    ]
  }
}
