{
  "xsize": 16,
  "zsize": 16,
  "slices": [
    [
      " 000000000%%$000",
      " $000000%%$00000",
      " 00000%%$0000000",
      " 000%%$000000000",
      " 0%%$00000000000",
      " %$0000000000000",
      " 000000000000000",
      " $0000000000000%",
      " 000000000000%%$",
      " 0000000000%%$00",
      " 00000000%%$0000",
      " 000000%%$000000",
      " 0000%%$00000000",
      " $0%%$0000000000",
      " %%$000000000000",
      " $00000000000000"
    ],
    [
      "    222222222222",
      "    222222222222",
      "    222222222222",
      "    222222222222",
      "    222222222222",
      "    222222222222",
      "    222222222222",
      "    222222222222",
      "    222222222222",
      "    222222222222",
      "    222222222222",
      "    222222222222",
      "    222222222222",
      "    222222222222",
      "    222222222222",
      "                "
    ],
    [
      "    !   +       ",
      "    !           ",
      "    !           ",
      "    !    /////  ",
      "    !    /////  ",
      "    !    /////  ",
      "    !    /////  ",
      "    !    /////  ",
      "    !    /////  ",
      "    !111111-1111",
      "    !           ",
      "    !  ,,,,,,,,,",
      "    !  ,,,,,,,,,",
      "    !  ,,,,,,,,,",
      "    !!!!!!&'!!!!",
      "                "
    ],
    [
      "    !           ",
      "    !   +       ",
      "    !           ",
      "    !           ",
      "    !           ",
      "    !     *     ",
      "    !           ",
      "    !           ",
      "    !           ",
      "    !111111.1111",
      "    !           ",
      "    !  ,,,,,,,,,",
      "    !  ,,,,,,,,,",
      "    !  ,,,,,,,,,",
      "    !!!!!!()!!!!",
      "                "
    ],
    [
      "    !           ",
      "    !           ",
      "    !   +       ",
      "    !           ",
      "    !           ",
      "    !           ",
      "    !           ",
      "    !           ",
      "    !           ",
      "    !11111111111",
      "    !           ",
      "    !  ,,,,,,,,,",
      "    !  ,,,,,,,,,",
      "    !  ,,,,,,,,,",
      "    !!!!!!!!!!!!",
      "                "
    ],
    [
      "    !           ",
      "    !           ",
      "    !           ",
      "    !   +       ",
      "    !           ",
      "    !           ",
      "    !           ",
      "    !           ",
      "    !           ",
      "    !11111111111",
      "    !           ",
      "    !  ,,,,,,,,,",
      "    !  ,,,,,,,,,",
      "    !  ,,,,,,,,,",
      "    !!!!!!!!!!!!",
      "                "
    ]
  ],
  "palette": {
    "palette": [
      {
        "char": "!",
        "block": "minecraft:bricks"
      },
      {
        "char": "$",
        "block": "minecraft:coarse_dirt"
      },
      {
        "char": "%",
        "block": "minecraft:gravel"
      },
      {
        "char": "&",
        "block": "minecraft:iron_door[facing=south,half=lower,hinge=left,open=false,powered=false]"
      },
      {
        "char": "'",
        "block": "minecraft:iron_door[facing=south,half=lower,hinge=right,open=false,powered=false]"
      },
      {
        "char": "(",
        "block": "minecraft:iron_door[facing=south,half=upper,hinge=left,open=false,powered=false]"
      },
      {
        "char": ")",
        "block": "minecraft:iron_door[facing=south,half=upper,hinge=right,open=false,powered=false]"
      },
      {
        "char": "*",
        "block": "kubejs:ruined_loom[facing=north]"
      },
      {
        "char": "+",
        "block": "minecraft:quartz_stairs[facing=south,half=bottom,shape=straight,waterlogged=false]"
      },
      {
        "char": ",",
        "block": "minecraft:scaffolding"
      },
      {
        "char": "-",
        "block": "minecraft:spruce_door[facing=south,half=lower,hinge=left,open=false,powered=false]"
      },
      {
        "char": ".",
        "block": "minecraft:spruce_door[facing=south,half=upper,hinge=left,open=false,powered=false]"
      },
      {
        "char": "/",
        "block": "minecraft:spruce_planks"
      },
      {
        "char": "0",
        "block": "tfmg:asphalt"
      },
      {
        "char": "1",
        "block": "tfmg:cinder_block"
      },
      {
        "char": "2",
        "block": "tfmg:factory_floor"
      }
    ]
  }
}
