{
  "xsize": 16,
  "zsize": 16,
  "slices": [
    [
      "        5       ",
      "        5       ",
      "        5       ",
      "        5       ",
      "        5       ",
      "        5       ",
      "        5       ",
      "        5       ",
      "        5       ",
      "        5       ",
      "        5       ",
      "        5       ",
      "        5       ",
      "        5       ",
      "        5       ",
      "        5       "
    ],
    [
      "********5       ",
      "********5       ",
      "********5       ",
      "********5       ",
      "********5       ",
      "********5       ",
      "********5       ",
      "********5       ",
      "********5       ",
      "********5       ",
      "********5       ",
      "********5       ",
      "********5       ",
      "********5       ",
      "********5       ",
      "********5       "
    ],
    [
      "$ 5,  ( 5       ",
      "  5-  ) 5       ",
      "  /     5       ",
      "  5     5       ",
      "665     5       ",
      " '5%  3 5       ",
      "  5&  4 5       ",
      "555551555       ",
      "        5       ",
      "        5       ",
      "        5       ",
      "+    $  5       ",
      "     .  5       ",
      "        5       ",
      "        5       ",
      "        5       "
    ],
    [
      "  5     5       ",
      "  5     5       ",
      "  0     5       ",
      "  5     5       ",
      "  5     5       ",
      "  5     5       ",
      "  5     5       ",
      "555552555       ",
      "        5       ",
      "        5       ",
      "        5       ",
      "        5       ",
      "        5       ",
      "        5       ",
      "        5       ",
      "        5       "
    ],
    [
      "  5     5       ",
      "  5     !       ",
      "  5     !       ",
      "  5     5       ",
      "  5     5       ",
      "  5     5       ",
      "  5     5       ",
      "555555555       ",
      "        5       ",
      "        !       ",
      "        !       ",
      "        5       ",
      "        5       ",
      "        5       ",
      "        5       ",
      "        5       "
    ],
    [
      "  5     5       ",
      "  5     !       ",
      "  5     !       ",
      "  5     5       ",
      "  5     5       ",
      "  5     5       ",
      "  5     5       ",
      "555555555       ",
      "        5       ",
      "        !       ",
      "        !       ",
      "        5       ",
      "        5       ",
      "        5       ",
      "        5       ",
      "        5       "
    ]
  ],
  "palette": {
    "palette": [
      {
        "char": "!",
        "block": "create:framed_glass"
      },
      {
        "char": "$",
        "block": "minecraft:barrel[facing=up,open=false]"
      },
      {
        "char": "%",
        "block": "minecraft:brown_bed[facing=south,occupied=false,part=foot]"
      },
      {
        "char": "&",
        "block": "minecraft:brown_bed[facing=south,occupied=false,part=head]"
      },
      {
        "char": "'",
        "block": "minecraft:dark_oak_stairs[facing=south,half=bottom,shape=straight,waterlogged=false]"
      },
      {
        "char": "(",
        "block": "minecraft:gray_bed[facing=south,occupied=false,part=foot]"
      },
      {
        "char": ")",
        "block": "minecraft:gray_bed[facing=south,occupied=false,part=head]"
      },
      {
        "char": "*",
        "block": "minecraft:polished_andesite"
      },
      {
        "char": "+",
        "block": "minecraft:quartz_stairs[facing=north,half=bottom,shape=straight,waterlogged=false]"
      },
      {
        "char": ",",
        "block": "minecraft:red_bed[facing=south,occupied=false,part=foot]"
      },
      {
        "char": "-",
        "block": "minecraft:red_bed[facing=south,occupied=false,part=head]"
      },
      {
        "char": ".",
        "block": "minecraft:spawner",
        "tag": {
          "id": "minecraft:mob_spawner",
          "Delay": 200,
          "MinSpawnDelay": 240,
          "MaxSpawnDelay": 720,
          "SpawnCount": 2,
          "MaxNearbyEntities": 6,
          "RequiredPlayerRange": 14,
          "SpawnRange": 4,
          "SpawnData": {
            "entity": {
              "id": "minecraft:pillager"
            }
          },
          "SpawnPotentials": [
            {
              "weight": 1,
              "data": {
                "entity": {
                  "id": "minecraft:pillager"
                }
              }
            }
          ]
        }
      },
      {
        "char": "/",
        "block": "minecraft:spruce_door[facing=east,half=lower,hinge=left,open=false,powered=false]"
      },
      {
        "char": "0",
        "block": "minecraft:spruce_door[facing=east,half=upper,hinge=left,open=false,powered=false]"
      },
      {
        "char": "1",
        "block": "minecraft:spruce_door[facing=south,half=lower,hinge=left,open=false,powered=false]"
      },
      {
        "char": "2",
        "block": "minecraft:spruce_door[facing=south,half=upper,hinge=left,open=false,powered=false]"
      },
      {
        "char": "3",
        "block": "minecraft:white_bed[facing=south,occupied=false,part=foot]"
      },
      {
        "char": "4",
        "block": "minecraft:white_bed[facing=south,occupied=false,part=head]"
      },
      {
        "char": "5",
        "block": "tfmg:cinder_block"
      },
      {
        "char": "6",
        "block": "zvhouses:spruce_countertop"
      }
    ]
  }
}
