{
  "xsize": 16,
  "zsize": 16,
  "slices": [
    [
      "       !!       ",
      "       !!       ",
      "    $$$!!       ",
      "    $  !!       ",
      "    $  !!       ",
      "    $  !!       ",
      "    $  !!       ",
      "    $  !!       ",
      "    $  !!       ",
      "    $  !!       ",
      "    $  !!       ",
      "    $  !!       ",
      "    $  !!       ",
      "    $  !!       ",
      "    $  !!       ",
      "    $  !!       "
    ],
    [
      "       !!!!!!!!!",
      "       !!!!!!!!!",
      "    $$$!!!!!!!!!",
      "    $  !!!!!!!!!",
      "    $  !!!!!!!!!",
      "    $  !!!!!!!!!",
      "    $  !!!!!!!!!",
      "    $  !!!!!!!!!",
      "    $  !!!!!!!!!",
      "    $  !!!!!!!!!",
      "    $  !!!!!!!!!",
      "    $  !!!!!!!!!",
      "    $  !!!!!!!!!",
      "    $  !!!!!!!!!",
      "    $  !!!!!!!!!",
      "    $  !!!!!!!!!"
    ],
    [
      "                ",
      "                ",
      "    %%%%%%%%%%% ",
      "    %%%%&&&&&&&&",
      "    %%%%&&&&&&&&",
      "    %%%%&&&&&&&&",
      "    %%%%&&&&&&&&",
      "    %%%%%%%%%%% ",
      "    %%%%%%%%%%% ",
      "    %%%%%%%%%%% ",
      "    %%%%%%%%%%% ",
      "    %%%%%%%%%%% ",
      "    %%%%%%%%%%% ",
      "    %%%%%%%%%%% ",
      "    %%%%%%%%%%% ",
      "    %%%%%%%%%%% "
    ],
    [
      "                ",
      "                ",
      "                ",
      "        &&&&&&&&",
      "        &&&&&&&&",
      "        &&&&&&&&",
      "        &&&&&&&&",
      "                ",
      "                ",
      "                ",
      "                ",
      "                ",
      "                ",
      "                ",
      "                ",
      "                "
    ],
    [
      "                ",
      "                ",
      "                ",
      "        &&&&&&&&",
      "        &&&&&&&&",
      "        &&&&&&&&",
      "        &&&&&&&&",
      "                ",
      "                ",
      "                ",
      "                ",
      "                ",
      "                ",
      "                ",
      "                ",
      "                "
    ]
  ],
  "palette": {
    "palette": [
      {
        "char": "!",
        "block": "immersiveengineering:sheetmetal_steel"
      },
      {
        "char": "$",
        "block": "minecraft:light_gray_concrete"
      },
      {
        "char": "%",
        "block": "minecraft:smooth_stone"
      },
      {
        "char": "&",
        "block": "tfmg:steel_block"
      }
    ]
  }
}
