{
  "xsize": 16,
  "zsize": 16,
  "slices": [
    [
      " 444(('444444444",
      " 4(('44444444444",
      " ('4444444444444",
      " 444444444444444",
      " 44444444444444(",
      " '44444444444(('",
      " 4444444444(('44",
      " 44444444(('4444",
      " 444444(('444444",
      " 4444(('44444444",
      " 44(('4444444444",
      " '('444444444444",
      " '44444444444444",
      " 444444444444444",
      " 4444444444444((",
      " 44444444444(('4"
    ],
    [
      "   1111111111111",
      "   1111111111111",
      "   1111111111111",
      "   1111111111111",
      "   1111111111111",
      "   1111111111111",
      "   1111111111111",
      "   1111111111111",
      "   1111111111111",
      "   1111111111111",
      "   1111111111111",
      "   1111111111111",
      "   1111111111111",
      "   1111111111111",
      "   1111111111111",
      "   1111111111111"
    ],
    [
      "   $         $, ",
      "   $         $, ",
      "   $         $, ",
      "   $         $, ",
      "   $222222/22$,2",
      "   $         $, ",
      "   $      -  $, ",
      "   $         $, ",
      "   $         $, ",
      "   $         $, ",
      "   $         $, ",
      "   $         $, ",
      "   $         $, ",
      "   $&        $,*",
      "   $%    3 . $,)",
      "   $         $, "
    ],
    [
      "   $         $, ",
      "   $         $, ",
      "   $         $, ",
      "   $         $, ",
      "   $222222022$,2",
      "   $         $, ",
      "   $         $, ",
      "   $      -  $, ",
      "   $         $, ",
      "   $         $, ",
      "   $         $, ",
      "   $         $, ",
      "   $         $, ",
      "   $         $, ",
      "   $         $, ",
      "   $       + $, "
    ],
    [
      "   !         $, ",
      "   $         $, ",
      "   $         $, ",
      "   $         $, ",
      "   $222222222$,2",
      "   $         $, ",
      "   $         $, ",
      "   $         $, ",
      "   $      -  $, ",
      "   $         $, ",
      "   $         $, ",
      "   $         $, ",
      "   $         $, ",
      "   $         $, ",
      "   $         $, ",
      "   $         $, "
    ],
    [
      "   !         $, ",
      "   $         $, ",
      "   $         $, ",
      "   $         $, ",
      "   $222222222$,2",
      "   $         $, ",
      "   $         $, ",
      "   $         $, ",
      "   $         $, ",
      "   $      -  $, ",
      "   $         $, ",
      "   $         $, ",
      "   $         $, ",
      "   $         $, ",
      "   $         $, ",
      "   $         $, "
    ]
  ],
  "palette": {
    "palette": [
      {
        "char": "!",
        "block": "create:framed_glass"
      },
      {
        "char": "$",
        "block": "minecraft:bricks"
      },
      {
        "char": "%",
        "block": "minecraft:brown_bed[facing=north,occupied=false,part=foot]"
      },
      {
        "char": "&",
        "block": "minecraft:brown_bed[facing=north,occupied=false,part=head]"
      },
      {
        "char": "'",
        "block": "minecraft:coarse_dirt"
      },
      {
        "char": "(",
        "block": "minecraft:gravel"
      },
      {
        "char": ")",
        "block": "minecraft:gray_bed[facing=north,occupied=false,part=foot]"
      },
      {
        "char": "*",
        "block": "minecraft:gray_bed[facing=north,occupied=false,part=head]"
      },
      {
        "char": "+",
        "block": "minecraft:lever[face=wall,facing=south,powered=false]"
      },
      {
        "char": ",",
        "block": "minecraft:mud_bricks"
      },
      {
        "char": "-",
        "block": "minecraft:oak_stairs[facing=south,half=bottom,shape=straight,waterlogged=false]"
      },
      {
        "char": ".",
        "block": "minecraft:quartz_stairs[facing=north,half=bottom,shape=straight,waterlogged=false]"
      },
      {
        "char": "/",
        "block": "minecraft:spruce_door[facing=south,half=lower,hinge=left,open=false,powered=false]"
      },
      {
        "char": "0",
        "block": "minecraft:spruce_door[facing=south,half=upper,hinge=left,open=false,powered=false]"
      },
      {
        "char": "1",
        "block": "minecraft:spruce_planks"
      },
      {
        "char": "2",
        "block": "minecraft:stripped_spruce_wood"
      },
      {
        "char": "3",
        "block": "kubejs:ruined_cauldron"
      },
      {
        "char": "4",
        "block": "tfmg:asphalt"
      }
    ]
  }
}
