{
  "xsize": 16,
  "zsize": 16,
  "slices": [
    [
      "2222222222''$222",
      "22222222''$22222",
      "222222''$2222222",
      "2222''$222222222",
      "22''$22222222222",
      "''$2222222222222",
      "$222222222222222",
      "222222222222222'",
      "2222222222222''$",
      "22222222222''$22",
      "222222222''$2222",
      "2222222''$222222",
      "22222''$22222222",
      "222''$2222222222",
      "2''$222222222222",
      "'$22222222222222"
    ],
    [
      "     ***********",
      "     ***********",
      "     ***********",
      "     ***********",
      "     ***********",
      "     ***********",
      "     ***********",
      "     ***********",
      "     ***********",
      "     ***********",
      "     ***********",
      "     ***********",
      "     ***********",
      "     ***********",
      "                ",
      "                "
    ],
    [
      "     1          ",
      "     1          ",
      "     1          ",
      "     1          ",
      "     1++++++/+++",
      "     1          ",
      "     1          ",
      "     1+++/+++/++",
      "     1     +   +",
      "     1     +,  +",
      "     1 (   -(  -",
      "     1 )   +)  +",
      "     1     +   +",
      "     11111111111",
      "                ",
      "                "
    ],
    [
      "     !          ",
      "     1   %%%%%%%",
      "     1   %%%%%%%",
      "     1          ",
      "     1++++++0+++",
      "     1          ",
      "     1          ",
      "     !+++0+++0++",
      "     !     +   +",
      "     1     +   +",
      "     1     .   .",
      "     !     +   +",
      "     !     +   +",
      "     111!!1111!!",
      "                ",
      "                "
    ],
    [
      "     !          ",
      "     1   %%%%%%%",
      "     1   %%%%%%%",
      "     1          ",
      "     1++++++++++",
      "     1          ",
      "     1          ",
      "     !+++!++++!+",
      "     !     +   +",
      "     1     +   +",
      "     1     +   +",
      "     !     +   +",
      "     !     +   +",
      "     111!!1111!!",
      "                ",
      "                "
    ],
    [
      "     1          ",
      "     1          ",
      "     1        & ",
      "     1          ",
      "     1++++++++++",
      "     1          ",
      "     1          ",
      "     1+++!++++!+",
      "     1     +   +",
      "     1     +   +",
      "     1     +   +",
      "     1     +   +",
      "     1     +   +",
      "     11111111111",
      "                ",
      "                "
    ]
  ],
  "palette": {
    "palette": [
      {
        "char": "!",
        "block": "create:framed_glass"
      },
      {
        "char": "$",
        "block": "minecraft:coarse_dirt"
      },
      {
        "char": "%",
        "block": "minecraft:dark_oak_planks"
      },
      {
        "char": "&",
        "block": "minecraft:gold_block"
      },
      {
        "char": "'",
        "block": "minecraft:gravel"
      },
      {
        "char": "(",
        "block": "minecraft:gray_bed[facing=south,occupied=false,part=foot]"
      },
      {
        "char": ")",
        "block": "minecraft:gray_bed[facing=south,occupied=false,part=head]"
      },
      {
        "char": "*",
        "block": "minecraft:polished_andesite"
      },
      {
        "char": "+",
        "block": "minecraft:polished_tuff"
      },
      {
        "char": ",",
        "block": "minecraft:spawner",
        "tag": {
          "id": "minecraft:mob_spawner",
          "Delay": 200,
          "MinSpawnDelay": 240,
          "MaxSpawnDelay": 720,
          "SpawnCount": 2,
          "MaxNearbyEntities": 8,
          "RequiredPlayerRange": 14,
          "SpawnRange": 4,
          "SpawnData": {
            "entity": {
              "id": "minecraft:pillager"
            }
          },
          "SpawnPotentials": [
            {
              "weight": 1,
              "data": {
                "entity": {
                  "id": "minecraft:pillager"
                }
              }
            }
          ]
        }
      },
      {
        "char": "-",
        "block": "minecraft:spruce_door[facing=east,half=lower,hinge=left,open=false,powered=false]"
      },
      {
        "char": ".",
        "block": "minecraft:spruce_door[facing=east,half=upper,hinge=left,open=false,powered=false]"
      },
      {
        "char": "/",
        "block": "minecraft:spruce_door[facing=south,half=lower,hinge=left,open=false,powered=false]"
      },
      {
        "char": "0",
        "block": "minecraft:spruce_door[facing=south,half=upper,hinge=left,open=false,powered=false]"
      },
      {
        "char": "1",
        "block": "minecraft:tuff_bricks"
      },
      {
        "char": "2",
        "block": "tfmg:asphalt"
      }
    ]
  }
}
