{
  "xsize": 16,
  "zsize": 16,
  "slices": [
    [
      "................",
      "................",
      "................",
      "................",
      "................",
      ".............))&",
      "...........))&..",
      ".........))&....",
      ".......))&......",
      ".....))&........",
      "...))&..........",
      ".))&............",
      ")&..............",
      "................",
      "..............))",
      "............))&."
    ],
    [
      "                ",
      "                ",
      "                ",
      "                ",
      "                ",
      "++++++++++++++++",
      "++++++++++++++++",
      "++++++++++++++++",
      "++++++++++++++++",
      "++++++++++++++++",
      "++++++++++++++++",
      "++++++++++++++++",
      "++++++++++++++++",
      "++++++++++++++++",
      "++++++++++++++++",
      "++++++++++++++++"
    ],
    [
      "                ",
      "                ",
      "                ",
      "                ",
      "                ",
      "!!!!'!!!!*!!!!!'",
      "         $      ",
      "         $      ",
      "         $      ",
      "         $      ",
      "         $      ",
      " ,,,,,,, $ %-  %",
      "         $      ",
      "         $      ",
      "         $      ",
      "         $      "
    ],
    [
      "                ",
      "                ",
      "                ",
      "                ",
      "                ",
      "!!!!(!!!!*!!!!!(",
      "         $      ",
      "         $      ",
      "         $      ",
      "         $      ",
      "         $      ",
      " ,,,,,,, $      ",
      "         $      ",
      "         $      ",
      "         $      ",
      "         $      "
    ],
    [
      "                ",
      "                ",
      "                ",
      "                ",
      "                ",
      "!!!! !!!!*!!!!! ",
      "         $      ",
      "         $      ",
      "         $      ",
      "         $      ",
      "         $      ",
      "         $      ",
      "         $      ",
      "         $      ",
      "         $      ",
      "         $      "
    ],
    [
      "                ",
      "                ",
      "                ",
      "                ",
      "                ",
      "!!!!!!!!!*!!!!!!",
      "         $      ",
      "         $      ",
      "         $      ",
      "         $      ",
      "         $      ",
      "         $      ",
      "         $      ",
      "         $      ",
      "         $      ",
      "         $      "
    ]
  ],
  "palette": {
    "palette": [
      {
        "char": "!",
        "block": "create:framed_glass"
      },
      {
        "char": "$",
        "block": "minecraft:bricks"
      },
      {
        "char": "%",
        "block": "minecraft:cauldron"
      },
      {
        "char": "&",
        "block": "minecraft:coarse_dirt"
      },
      {
        "char": "'",
        "block": "minecraft:dark_oak_door[facing=north,half=lower,hinge=left,open=false,powered=false]"
      },
      {
        "char": "(",
        "block": "minecraft:dark_oak_door[facing=north,half=upper,hinge=left,open=false,powered=false]"
      },
      {
        "char": ")",
        "block": "minecraft:gravel"
      },
      {
        "char": "*",
        "block": "minecraft:mud_bricks"
      },
      {
        "char": "+",
        "block": "minecraft:oak_planks"
      },
      {
        "char": ",",
        "block": "minecraft:scaffolding"
      },
      {
        "char": "-",
        "block": "minecraft:smoker[facing=south,lit=false]"
      },
      {
        "char": ".",
        "block": "tfmg:asphalt"
      }
    ]
  }
}
