{
  "xsize": 16,
  "zsize": 16,
  "slices": [
    [
      "8888888888888888",
      "8888888888888888",
      "8///////////////",
      "8///////////////",
      "8///////////////",
      "8///////////////",
      "8///////////////",
      "8///////////////",
      "8///////////////",
      "8///////////////",
      "++%8888888888888",
      "%888888888888888",
      "888888888888888+",
      "8888888888888++%",
      "88888888888++%88",
      "888888888++%8888"
    ],
    [
      "                ",
      "                ",
      "                ",
      "                ",
      "   .   .   .   .",
      "                ",
      "  //////////////",
      "   /////////////",
      ",,,,,,,,,,,,,,,,",
      ",,,,,,,,,,,,,,,,",
      ",,,,,,,,,,,,,,,,",
      ",,,,,,,,,,,,,,,,",
      ",,,,,,,,,,,,,,,,",
      ",,,,,,,,,,,,,,,,",
      ",,,,,,,,,,,,,,,,",
      ",,,,,,,,,,,,,,,,"
    ],
    [
      "                ",
      "                ",
      "                ",
      "                ",
      "///.///.///.///.",
      " ///////////////",
      "                ",
      "3               ",
      "777777777777&'77",
      "  -             ",
      "  -             ",
      "  -      33    3",
      "  -      5     5",
      "  -             ",
      "  1          0  ",
      "$ -    *    *   "
    ],
    [
      "                ",
      "                ",
      "                ",
      "                ",
      "   .   .   .   .",
      "                ",
      "                ",
      "                ",
      "!67777777777()77",
      "  -             ",
      "  -             ",
      "  -             ",
      "  -             ",
      "  -             ",
      "  2             ",
      "$ -             "
    ],
    [
      "                ",
      "                ",
      "                ",
      "                ",
      "   .   .   .   .",
      "                ",
      "                ",
      "                ",
      "!677777777777777",
      "  -             ",
      "  -             ",
      "  -             ",
      "  -             ",
      "  -             ",
      "  -             ",
      "  -             "
    ],
    [
      "                ",
      "                ",
      "                ",
      "                ",
      "   .   .   .   .",
      "                ",
      "                ",
      "4               ",
      "7777777777777777",
      "  -             ",
      "  -             ",
      "  -             ",
      "  -             ",
      "  -             ",
      "  -             ",
      "  -             "
    ]
  ],
  "palette": {
    "palette": [
      {
        "char": "!",
        "block": "create:framed_glass"
      },
      {
        "char": "$",
        "block": "minecraft:bookshelf"
      },
      {
        "char": "%",
        "block": "minecraft:coarse_dirt"
      },
      {
        "char": "&",
        "block": "minecraft:dark_oak_door[facing=north,half=lower,hinge=left,open=false,powered=false]"
      },
      {
        "char": "'",
        "block": "minecraft:dark_oak_door[facing=north,half=lower,hinge=right,open=false,powered=false]"
      },
      {
        "char": "(",
        "block": "minecraft:dark_oak_door[facing=north,half=upper,hinge=left,open=false,powered=false]"
      },
      {
        "char": ")",
        "block": "minecraft:dark_oak_door[facing=north,half=upper,hinge=right,open=false,powered=false]"
      },
      {
        "char": "*",
        "block": "minecraft:dark_oak_stairs[facing=north,half=bottom,shape=straight,waterlogged=false]"
      },
      {
        "char": "+",
        "block": "minecraft:gravel"
      },
      {
        "char": ",",
        "block": "minecraft:polished_andesite"
      },
      {
        "char": "-",
        "block": "minecraft:polished_tuff"
      },
      {
        "char": ".",
        "block": "minecraft:quartz_pillar[axis=y]"
      },
      {
        "char": "/",
        "block": "minecraft:smooth_stone"
      },
      {
        "char": "0",
        "block": "minecraft:spawner",
        "tag": {
          "id": "minecraft:mob_spawner",
          "Delay": 200,
          "MinSpawnDelay": 240,
          "MaxSpawnDelay": 720,
          "SpawnCount": 2,
          "MaxNearbyEntities": 8,
          "RequiredPlayerRange": 14,
          "SpawnRange": 4,
          "SpawnData": {
            "entity": {
              "id": "minecraft:zombie"
            }
          },
          "SpawnPotentials": [
            {
              "weight": 1,
              "data": {
                "entity": {
                  "id": "minecraft:zombie"
                }
              }
            }
          ]
        }
      },
      {
        "char": "1",
        "block": "minecraft:spruce_door[facing=east,half=lower,hinge=left,open=false,powered=false]"
      },
      {
        "char": "2",
        "block": "minecraft:spruce_door[facing=east,half=upper,hinge=left,open=false,powered=false]"
      },
      {
        "char": "3",
        "block": "minecraft:spruce_slab[type=bottom,waterlogged=false]"
      },
      {
        "char": "4",
        "block": "minecraft:spruce_slab[type=top,waterlogged=false]"
      },
      {
        "char": "5",
        "block": "minecraft:spruce_stairs[facing=north,half=bottom,shape=straight,waterlogged=false]"
      },
      {
        "char": "6",
        "block": "minecraft:stripped_spruce_log[axis=y]"
      },
      {
        "char": "7",
        "block": "minecraft:tuff_bricks"
      },
      {
        "char": "8",
        "block": "tfmg:asphalt"
      }
    ]
  }
}
