{
  "xsize": 16,
  "zsize": 16,
  "slices": [
    [
      " )))))))))$$!)))",
      " !))))))$$!)))))",
      " )))))$$!)))))))",
      " )))$$!)))))))))",
      " )$$!)))))))))))",
      " $!)))))))))))))",
      " )))))))))))))))",
      " !)))))))))))))$",
      " ))))))))))))$$!",
      " ))))))))))$$!))",
      " ))))))))$$!))))",
      " ))))))$$!))))))",
      " ))))$$!))))))))",
      " )!$$!)!))))!)))",
      "                ",
      "                "
    ],
    [
      "    ************",
      "    ************",
      "    ************",
      "    ************",
      "    ************",
      "    ************",
      "    ************",
      "    ************",
      "    ************",
      "    ************",
      "                ",
      "                ",
      "                ",
      "                ",
      "                ",
      "                "
    ],
    [
      "    %           ",
      "    %  +++++++++",
      "    %  ++++++++'",
      "    %  ++&++++++",
      "    %  +++++++++",
      "    %  +++++++++",
      "    %  +++++++++",
      "    %  +++++++++",
      "    %           ",
      "    %%%%%%%%%%%%",
      "                ",
      "                ",
      "                ",
      "                ",
      "                ",
      "                "
    ],
    [
      "    %           ",
      "    %           ",
      "    %           ",
      "    %           ",
      "    %           ",
      "    %           ",
      "    %           ",
      "    %           ",
      "    %           ",
      "    %%%%%%%%%%%%",
      "                ",
      "                ",
      "                ",
      "                ",
      "                ",
      "                "
    ],
    [
      "    %           ",
      "    %           ",
      "    %           ",
      "    %           ",
      "    %           ",
      "    %           ",
      "    %           ",
      "    %           ",
      "    %           ",
      "    %%%%%%%%%%%%",
      "                ",
      "                ",
      "                ",
      "                ",
      "                ",
      "                "
    ],
    [
      "    %  (        ",
      "    %           ",
      "    %           ",
      "    %           ",
      "    %           ",
      "    %           ",
      "    %           ",
      "    %           ",
      "    %           ",
      "    %%%%%%%%%%%%",
      "                ",
      "                ",
      "                ",
      "                ",
      "                ",
      "                "
    ]
  ],
  "palette": {
    "palette": [
      {
        "char": "!",
        "block": "minecraft:coarse_dirt"
      },
      {
        "char": "$",
        "block": "minecraft:gravel"
      },
      {
        "char": "%",
        "block": "minecraft:polished_blackstone_bricks"
      },
      {
        "char": "&",
        "block": "kubejs:ruined_smoker[facing=north]"
      },
      {
        "char": "'",
        "block": "minecraft:spawner",
        "tag": {
          "id": "minecraft:mob_spawner",
          "Delay": 200,
          "MinSpawnDelay": 240,
          "MaxSpawnDelay": 720,
          "SpawnCount": 2,
          "MaxNearbyEntities": 7,
          "RequiredPlayerRange": 14,
          "SpawnRange": 4,
          "SpawnData": {
            "entity": {
              "id": "minecraft:pillager"
            }
          },
          "SpawnPotentials": [
            {
              "weight": 1,
              "data": {
                "entity": {
                  "id": "minecraft:pillager"
                }
              }
            }
          ]
        }
      },
      {
        "char": "(",
        "block": "minecraft:stone_brick_stairs[facing=south,half=bottom,shape=straight,waterlogged=false]"
      },
      {
        "char": ")",
        "block": "tfmg:asphalt"
      },
      {
        "char": "*",
        "block": "tfmg:factory_floor"
      },
      {
        "char": "+",
        "block": "zvhouses:stone_brick_countertop"
      }
    ]
  }
}
