{
  "xsize": 16,
  "zsize": 16,
  "slices": [
    [
      "****************",
      "****************",
      "****************",
      "****************",
      "********%%$*****",
      "******%%$*******",
      "****%%$*********",
      "**%%$***********",
      "%%$*************",
      "$***************",
      "****************",
      "*************%%$",
      "***********%%$**",
      "*********%******",
      "*******%%$******",
      "*****%%$********"
    ],
    [
      ",,,,,,,,%%%%%%%%",
      ",,,,,,,,%%%%%%%%",
      ",,,,,,,,%%%%%%%%",
      ",,,,,,,,%%%%%%%%",
      ",,,,,,,,%%%%%%%%",
      ",,,,,,,,%%%%%%%%",
      ",,,,,,,,%%%%%%%%",
      ",,,,,,,,%%%%%%%%",
      ",,,,,,,,%%%%%%%%",
      ",,,,,,,,%%%%%%%%",
      ",,,,,,,,%%%%%%%%",
      ",,,,,,,,%%%%%%%%",
      "        %%%%%%%%",
      "        %%%%%%%%",
      "        %%%%%%%%",
      "        %%%%%%%%"
    ],
    [
      "        %%%%%%%%",
      "++++'+++%%%%%%%%",
      "        %%%%%%%%",
      ")       %%%%%%%%",
      "     -  %%%%%%%%",
      "        %%%%%%%%",
      "        %%%%%%%%",
      "      & %%%%%%%%",
      "        %%%%%%%%",
      "        %%%%%%%%",
      "        %%%%%%%%",
      "!!!!!!!!%%%%%%%%",
      "        %%%%%%%%",
      "        %%%%%%%%",
      "        %%%%%%%%",
      "        %%%%%%%%"
    ],
    [
      "        %%%%%%%%",
      "++++(+++%%%%%%%%",
      "        %%%%%%%%",
      "        %%%%%%%%",
      "        %%%%%%%%",
      "        %%%%%%%%",
      "        %%%%%%%%",
      "      & %%%%%%%%",
      "        %%%%%%%%",
      "        %%%%%%%%",
      "        %%%%%%%%",
      "!!!!!!!!%%%%%%%%",
      "        %%%%%%%%",
      "        %%%%%%%%",
      "        %%%%%%%%",
      "        %%%%%%%%"
    ],
    [
      "        %%%%%%%%",
      "++++++++%%%%%%%%",
      "        %%%%%%%%",
      "        %%%%%%%%",
      "        %%%%%%%%",
      "        %%%%%%%%",
      "        %%%%%%%%",
      "      & %%%%%%%%",
      "        %%%%%%%%",
      "        %%%%%%%%",
      "        %%%%%%%%",
      "!!!!!!!!%%%%%%%%",
      "        %%%%%%%%",
      "        %%%%%%%%",
      "        %%%%%%%%",
      "        %%%%%%%%"
    ],
    [
      "        %%%%%%%%",
      "++++++++%%%%%%%%",
      "        %%%%%%%%",
      "        %%%%%%%%",
      "        %%%%%%%%",
      "        %%%%%%%%",
      "        %%%%%%%%",
      "      & %%%%%%%%",
      "        %%%%%%%%",
      "        %%%%%%%%",
      "        %%%%%%%%",
      "!!!!!!!!%%%%%%%%",
      "        %%%%%%%%",
      "        %%%%%%%%",
      "        %%%%%%%%",
      "        %%%%%%%%"
    ]
  ],
  "palette": {
    "palette": [
      {
        "char": "!",
        "block": "minecraft:bricks"
      },
      {
        "char": "$",
        "block": "minecraft:coarse_dirt"
      },
      {
        "char": "%",
        "block": "minecraft:gravel"
      },
      {
        "char": "&",
        "block": "minecraft:ladder[facing=west,waterlogged=false]"
      },
      {
        "char": "'",
        "block": "minecraft:spruce_door[facing=south,half=lower,hinge=left,open=false,powered=false]"
      },
      {
        "char": "(",
        "block": "minecraft:spruce_door[facing=south,half=upper,hinge=left,open=false,powered=false]"
      },
      {
        "char": ")",
        "block": "minecraft:spruce_slab[type=bottom,waterlogged=false]"
      },
      {
        "char": "*",
        "block": "tfmg:asphalt"
      },
      {
        "char": "+",
        "block": "tfmg:cinder_block"
      },
      {
        "char": ",",
        "block": "tfmg:factory_floor"
      },
      {
        "char": "-",
        "block": "the_wasteland_reworked:radio"
      }
    ]
  }
}
