{
  "xsize": 16,
  "zsize": 16,
  "slices": [
    [
      "2222222222222222",
      "2'2222'2222'2222",
      "2222222222222222",
      "2222222222222222",
      "2222222222222222",
      "2222222222222222",
      "2222222222222222",
      "2222222222222222",
      "2222''%222222222",
      "22''%22222222222",
      "''%2222222222222",
      "%222222222222222",
      "222222222222222'",
      "2222222222222''%",
      "22222222222''%22",
      "222222222''%2222"
    ],
    [
      "                ",
      "                ",
      "                ",
      "                ",
      " .....      ....",
      " .....      ....",
      " .....      ....",
      ",.....,,,,,,....",
      ",,,,,,,,,,,,,,,,",
      ",,,,,,,,,,,,,,,,",
      ",,,,,,,,,,,,,,,,",
      ",,,,,,,,,,,,,,,,",
      ",,,,,,,,,,,,,,,,",
      ",,,,,,,,,,,,,,,,",
      ",,,,,,,,,,,,,,,,",
      ",,,,,,,,,,,,,,,,"
    ],
    [
      "                ",
      "                ",
      "                ",
      "                ",
      "                ",
      "                ",
      "                ",
      "(((*(((((00000*0",
      "        (0      ",
      "        (0      ",
      "$$$     (0$$$$  ",
      " / &&&  (0) / &&",
      "       3(0      ",
      "        (0      ",
      "    -   (0     -",
      "        (0      "
    ],
    [
      "                ",
      "                ",
      "                ",
      "                ",
      "                ",
      "                ",
      "                ",
      "(((+(((((00000+0",
      "        (0      ",
      "        (0      ",
      "  1     (0   1  ",
      "        (0      ",
      "       1(0      ",
      "        (0      ",
      "        (0      ",
      "        (0      "
    ],
    [
      "                ",
      "                ",
      "                ",
      "                ",
      "                ",
      "                ",
      "                ",
      "!!((((!!(00!!000",
      "        (0      ",
      "        (0      ",
      "        (0      ",
      "        (0      ",
      "        (0      ",
      "        (0      ",
      "        (0      ",
      "        (0      "
    ],
    [
      "                ",
      "                ",
      "                ",
      "                ",
      "                ",
      "                ",
      "                ",
      "!!((((!!(00!!000",
      "        (0      ",
      "        (0      ",
      "        (0      ",
      "        (0      ",
      "        (0      ",
      "        (0      ",
      "        (0      ",
      "        (0      "
    ]
  ],
  "palette": {
    "palette": [
      {
        "char": "!",
        "block": "create:framed_glass"
      },
      {
        "char": "$",
        "block": "minecraft:barrel[facing=up,open=false]"
      },
      {
        "char": "%",
        "block": "minecraft:coarse_dirt"
      },
      {
        "char": "&",
        "block": "minecraft:dark_oak_stairs[facing=south,half=bottom,shape=straight,waterlogged=false]"
      },
      {
        "char": "'",
        "block": "minecraft:gravel"
      },
      {
        "char": "(",
        "block": "minecraft:mud_bricks"
      },
      {
        "char": ")",
        "block": "kubejs:ruined_smoker[facing=north]"
      },
      {
        "char": "*",
        "block": "minecraft:spruce_door[facing=north,half=lower,hinge=left,open=false,powered=false]"
      },
      {
        "char": "+",
        "block": "minecraft:spruce_door[facing=north,half=upper,hinge=left,open=false,powered=false]"
      },
      {
        "char": ",",
        "block": "minecraft:spruce_planks"
      },
      {
        "char": "-",
        "block": "minecraft:spruce_slab[type=bottom,waterlogged=false]"
      },
      {
        "char": ".",
        "block": "minecraft:stone_bricks"
      },
      {
        "char": "/",
        "block": "kubejs:ruined_cauldron"
      },
      {
        "char": "0",
        "block": "minecraft:yellow_terracotta"
      },
      {
        "char": "1",
        "block": "supplementaries:item_shelf"
      },
      {
        "char": "2",
        "block": "tfmg:asphalt"
      },
      {
        "char": "3",
        "block": "the_wasteland_reworked:radio"
      }
    ]
  }
}
