{
  "xsize": 16,
  "zsize": 16,
  "slices": [
    [
      "$$$$$$$$$$$$$   ",
      "$$$$$$$$$$$$$   ",
      "                ",
      "                ",
      "                ",
      "                ",
      "                ",
      "                ",
      "                ",
      "                ",
      "                ",
      "                ",
      "                ",
      "                ",
      "                ",
      "                "
    ],
    [
      "2222222222222222",
      "2222222222222222",
      "2222222222222222",
      "2222222222222222",
      "2222222222222222",
      "2222222222222222",
      "22222222222222''",
      "222222222222''&2",
      "2222222222''&222",
      "22222222''&22222",
      "222222''&2222222",
      "2222''&222222222",
      "22''&22222222222",
      "''&2222222222222",
      "&222222222222222",
      "222222222222222'"
    ],
    [
      "               +",
      "         5      ",
      "                ",
      "   ***   ***%%  ",
      "---***-- ***%%  ",
      "--------        ",
      "44444444        ",
      "44444444        ",
      "444444440   0   ",
      "444444440   0   ",
      "444444440   0   ",
      "444444440   0   ",
      "444444440   0   ",
      "444444440   0   ",
      "444444440   0   ",
      "444444440   0   "
    ],
    [
      "               +",
      "                ",
      "                ",
      "          %(%%  ",
      "          %%%%  ",
      ".....) )        ",
      "))))))))        ",
      "       )        ",
      "77     ))       ",
      " 7     )        ",
      " 7    1)        ",
      "  ,    )        ",
      "  ,   1)        ",
      "       ))       ",
      "  ,   1)        ",
      "  ,    )        "
    ],
    [
      "               +",
      "                ",
      "                ",
      "          %%%%  ",
      "          %%%%  ",
      "     ) )        ",
      "!!!!!/3)        ",
      "       3        ",
      "6      ))       ",
      "       !        ",
      "      1!        ",
      "  ,    3        ",
      "  ,   13        ",
      "       ))       ",
      "  ,   13        ",
      "  ,    3        "
    ],
    [
      "               +",
      "                ",
      "                ",
      "                ",
      "                ",
      "     ) )        ",
      "!!!!!/3)        ",
      "       3        ",
      "       ))       ",
      "       !        ",
      "       !        ",
      "       3        ",
      "       3        ",
      "       ))       ",
      "       3        ",
      "       3        "
    ]
  ],
  "palette": {
    "palette": [
      {
        "char": "!",
        "block": "create:framed_glass"
      },
      {
        "char": "$",
        "block": "immersiveengineering:concrete_reinforced"
      },
      {
        "char": "%",
        "block": "immersiveengineering:sheetmetal_steel"
      },
      {
        "char": "&",
        "block": "minecraft:coarse_dirt"
      },
      {
        "char": "'",
        "block": "minecraft:gravel"
      },
      {
        "char": "(",
        "block": "minecraft:lever[face=wall,facing=north,powered=false]"
      },
      {
        "char": ")",
        "block": "minecraft:mud_bricks"
      },
      {
        "char": "*",
        "block": "minecraft:polished_andesite"
      },
      {
        "char": "+",
        "block": "minecraft:polished_blackstone_bricks"
      },
      {
        "char": ",",
        "block": "minecraft:scaffolding"
      },
      {
        "char": "-",
        "block": "minecraft:smooth_stone"
      },
      {
        "char": ".",
        "block": "minecraft:spruce_slab[type=bottom,waterlogged=false]"
      },
      {
        "char": "/",
        "block": "minecraft:stripped_spruce_log[axis=y]"
      },
      {
        "char": "0",
        "block": "minecraft:white_concrete"
      },
      {
        "char": "1",
        "block": "oritech:cooler_block"
      },
      {
        "char": "2",
        "block": "tfmg:asphalt"
      },
      {
        "char": "3",
        "block": "tfmg:cinder_block"
      },
      {
        "char": "4",
        "block": "tfmg:factory_floor"
      },
      {
        "char": "5",
        "block": "the_wasteland_reworked:garbage_bag"
      },
      {
        "char": "6",
        "block": "the_wasteland_reworked:radio"
      },
      {
        "char": "7",
        "block": "zvhouses:spruce_countertop"
      }
    ]
  }
}
