{
  "xsize": 16,
  "zsize": 16,
  "slices": [
    [
      "++++++          ",
      "++++++          ",
      "++++++          ",
      "++++&&          ",
      "++&&$+          ",
      "&&$++&          ",
      "$+++++          ",
      "++++++          ",
      "++++++          ",
      "++++++          ",
      "++++++          ",
      "+++++&          ",
      "+++++&          ",
      "+++&&$          ",
      "+&&$++          ",
      "$$++++          "
    ],
    [
      "***             ",
      "***             ",
      "***             ",
      "***             ",
      "***             ",
      "***             ",
      "***             ",
      "***             ",
      "***             ",
      "***             ",
      "***             ",
      "***             ",
      "***             ",
      "***             ",
      "                ",
      "                "
    ],
    [
      "  )             ",
      "  )             ",
      "% )             ",
      "  )             ",
      "  )             ",
      "  )             ",
      "  )             ",
      "  )             ",
      ",,)             ",
      "  )             ",
      " ()             ",
      "  )             ",
      "  )             ",
      ")))             ",
      "                ",
      "                "
    ],
    [
      "  !             ",
      "  !             ",
      "  )             ",
      "  )             ",
      "  )             ",
      "  !             ",
      "  !             ",
      "  )             ",
      ",,)             ",
      "  )             ",
      "  )             ",
      "  )             ",
      " ')             ",
      ")))             ",
      "                ",
      "                "
    ],
    [
      "  !             ",
      "  !             ",
      "  )             ",
      "  )             ",
      "  )             ",
      "  !             ",
      "  !             ",
      "  )             ",
      ",,)             ",
      "  )             ",
      "  )             ",
      "  )             ",
      "  )             ",
      ")))             ",
      "                ",
      "                "
    ],
    [
      "  )             ",
      "  )             ",
      "  )             ",
      "  )             ",
      "  )             ",
      "  )             ",
      "  )             ",
      "  )             ",
      ",,)             ",
      "  )             ",
      "  )             ",
      "  )             ",
      "  )             ",
      ")))             ",
      "                ",
      "                "
    ]
  ],
  "palette": {
    "palette": [
      {
        "char": "!",
        "block": "create:framed_glass"
      },
      {
        "char": "$",
        "block": "minecraft:coarse_dirt"
      },
      {
        "char": "%",
        "block": "minecraft:dark_oak_stairs[facing=west,half=bottom,shape=straight,waterlogged=false]"
      },
      {
        "char": "&",
        "block": "minecraft:gravel"
      },
      {
        "char": "'",
        "block": "minecraft:lever[face=wall,facing=south,powered=false]"
      },
      {
        "char": "(",
        "block": "minecraft:quartz_stairs[facing=south,half=bottom,shape=straight,waterlogged=false]"
      },
      {
        "char": ")",
        "block": "minecraft:red_terracotta"
      },
      {
        "char": "*",
        "block": "minecraft:smooth_stone"
      },
      {
        "char": "+",
        "block": "tfmg:asphalt"
      },
      {
        "char": ",",
        "block": "tfmg:cinder_block"
      }
    ]
  }
}
