{
  "xsize": 16,
  "zsize": 16,
  "slices": [
    [
      "*************$$!",
      "***********$$!**",
      "*********$$!****",
      "*******$$!******",
      "*****$$!********",
      "***$$!**********",
      "*$$!************",
      "$!**************",
      "****************",
      "**************$$",
      "************$$!*",
      "**********$$!***",
      "********$$!*****",
      "******$$!*******",
      "****$$!*********",
      "**$$!***********"
    ],
    [
      "+++++&&&&&&&&&&&",
      "+++++&&&&&&&&&&&",
      "+++++&&&&&&&&&&&",
      "+++++&&&&&&&&&&&",
      "+++++&&&&&&&&&&&",
      "+++++&&&&&&&&&&&",
      "+++++&&&&&&&&&&&",
      "+++++&&&&&&&&&&&",
      "+++++&&&&&&&&&&&",
      "+++++&&&&&&&&&&&",
      "+++++&&&&&&&&&&&",
      "+++++&&&&&&&&&&&",
      "+++++&&&&&&&&&&&",
      "+++++&&&&&&&&&&&",
      "+++++&&&&&&&&&&&",
      "+++++&&&&&&&&&&&"
    ],
    [
      "'    )          ",
      "'    )          ",
      "'    )          ",
      "'    )          ",
      "'    )          ",
      "'    )          ",
      "'    )          ",
      "'    )          ",
      "'    )          ",
      "'    )  ,,,,,,, ",
      "'    )   %      ",
      "'    )   '  '   ",
      "'    )   '  '   ",
      "'    )   '  '   ",
      "'    )   '  '   ",
      "'    )   (  '  ("
    ],
    [
      "'    )          ",
      "'    )          ",
      "'    )          ",
      "'    )          ",
      "'    )          ",
      "'    )          ",
      "'    )          ",
      "'    )          ",
      "'    )          ",
      "'    )  ,,,,,,, ",
      "'    )          ",
      "'    )   '  '   ",
      "'    )   '  '   ",
      "'    )   '  '   ",
      "'    )   '  '   ",
      "'    )   '  '   "
    ],
    [
      "'    )          ",
      "'    )          ",
      "'    )          ",
      "'    )          ",
      "'    )          ",
      "'    )          ",
      "'    )          ",
      "'    )          ",
      "'    )          ",
      "'    )  ,,,,,,, ",
      "'    )          ",
      "'    )   '  '   ",
      "'    )   '  '   ",
      "'    )   '  '   ",
      "'    )   '  '   ",
      "'    )   '  '   "
    ],
    [
      "'    )          ",
      "'    )          ",
      "'    )          ",
      "'    )          ",
      "'    )          ",
      "'    )          ",
      "'    )          ",
      "'    )          ",
      "'    )          ",
      "'    )          ",
      "'    )          ",
      "'    )          ",
      "'    )          ",
      "'    )          ",
      "'    )          ",
      "'    )          "
    ]
  ],
  "palette": {
    "palette": [
      {
        "char": "!",
        "block": "minecraft:coarse_dirt"
      },
      {
        "char": "$",
        "block": "minecraft:gravel"
      },
      {
        "char": "%",
        "block": "minecraft:loom[facing=north]"
      },
      {
        "char": "&",
        "block": "minecraft:polished_andesite"
      },
      {
        "char": "'",
        "block": "minecraft:scaffolding"
      },
      {
        "char": "(",
        "block": "minecraft:smoker[facing=north,lit=false]"
      },
      {
        "char": ")",
        "block": "minecraft:smooth_stone"
      },
      {
        "char": "*",
        "block": "tfmg:asphalt"
      },
      {
        "char": "+",
        "block": "tfmg:factory_floor"
      },
      {
        "char": ",",
        "block": "zvhouses:spruce_countertop"
      }
    ]
  }
}
