{
  "xsize": 16,
  "zsize": 16,
  "slices": [
    [
      "4444444''$444444",
      "44444''$44444444",
      "444''$4444444444",
      "4''$444444444444",
      "'$44444444444444",
      "4444444444444444",
      "44444444444444''",
      "444444444444''$4",
      "4444444444''$444",
      "44444444''$44444",
      "444444''$4444444",
      "4444''$444444444",
      "44''$44444444444",
      "''$4444444444444",
      "$444444444444444",
      "444444444444444'"
    ],
    [
      "----------------",
      "----------------",
      "----------------",
      "++++++++++++++++",
      "++++++++++++++++",
      "++++++++++++++++",
      "++++++++++++++++",
      "++++++++++++++++",
      "++++++++++++++++",
      "++++++++++++++++",
      "++++++++++++++++",
      "++++++++++++++++",
      "++++++++++++,+++",
      "--++++++++++,444",
      "--++++++++++,444",
      "--++++++++++,444"
    ],
    [
      "                ",
      "                ",
      "                ",
      "******0*********",
      " *            * ",
      " * %%%%%%%%%  * ",
      " * %%%%%%%%%  * ",
      " .            . ",
      " *            * ",
      " * &   &   &  * ",
      " *            * ",
      " *            * ",
      "  ,,,,,,,,,,,***",
      "  ,         ,   ",
      "  ( 22  !   ,   ",
      "  , 3       ,   "
    ],
    [
      "                ",
      "                ",
      "                ",
      "******1*********",
      " *            * ",
      " *            * ",
      " *            * ",
      " /            / ",
      " *            * ",
      " *            * ",
      " *            * ",
      " *            * ",
      "  ,,,,,,,,,,,***",
      "  ,         ,   ",
      "  )         ,   ",
      "  ,         ,   "
    ],
    [
      "                ",
      "                ",
      "                ",
      "****************",
      " *            * ",
      " *            * ",
      " *            * ",
      " *            * ",
      " *            * ",
      " *            * ",
      " *            * ",
      " *            * ",
      "  ,,,,,,,,,,,***",
      "  ,         ,   ",
      "  ,         ,   ",
      "  ,         ,   "
    ],
    [
      "                ",
      "                ",
      "                ",
      "****************",
      " *            * ",
      " *            * ",
      " *            * ",
      " *            * ",
      " *            * ",
      " *            * ",
      " *            * ",
      " *            * ",
      "  ,,,,,,,,,,,***",
      "  ,         ,   ",
      "  ,         ,   ",
      "  ,         ,   "
    ]
  ],
  "palette": {
    "palette": [
      {
        "char": "!",
        "block": "kubejs:ruined_brewing_stand"
      },
      {
        "char": "$",
        "block": "minecraft:coarse_dirt"
      },
      {
        "char": "%",
        "block": "minecraft:dark_oak_slab[type=bottom,waterlogged=false]"
      },
      {
        "char": "&",
        "block": "minecraft:dark_oak_stairs[facing=north,half=bottom,shape=straight,waterlogged=false]"
      },
      {
        "char": "'",
        "block": "minecraft:gravel"
      },
      {
        "char": "(",
        "block": "minecraft:iron_door[facing=east,half=lower,hinge=left,open=false,powered=false]"
      },
      {
        "char": ")",
        "block": "minecraft:iron_door[facing=east,half=upper,hinge=left,open=false,powered=false]"
      },
      {
        "char": "*",
        "block": "minecraft:light_gray_concrete"
      },
      {
        "char": "+",
        "block": "minecraft:polished_andesite"
      },
      {
        "char": ",",
        "block": "minecraft:polished_deepslate"
      },
      {
        "char": "-",
        "block": "minecraft:smooth_stone"
      },
      {
        "char": ".",
        "block": "minecraft:spruce_door[facing=east,half=lower,hinge=left,open=false,powered=false]"
      },
      {
        "char": "/",
        "block": "minecraft:spruce_door[facing=east,half=upper,hinge=left,open=false,powered=false]"
      },
      {
        "char": "0",
        "block": "minecraft:spruce_door[facing=south,half=lower,hinge=left,open=false,powered=false]"
      },
      {
        "char": "1",
        "block": "minecraft:spruce_door[facing=south,half=upper,hinge=left,open=false,powered=false]"
      },
      {
        "char": "2",
        "block": "minecraft:spruce_slab[type=bottom,waterlogged=false]"
      },
      {
        "char": "3",
        "block": "minecraft:spruce_stairs[facing=north,half=bottom,shape=straight,waterlogged=false]"
      },
      {
        "char": "4",
        "block": "tfmg:asphalt"
      }
    ]
  }
}
