{
  "xsize": 16,
  "zsize": 16,
  "slices": [
    [
      "   %$         $ ",
      "    $         $ ",
      "    $         $ ",
      "    $         $ ",
      "    $         $ ",
      "    $         $ ",
      "    $         $ ",
      "    $$$$$$$$$$$ ",
      "        !       ",
      "        !       ",
      "        !       ",
      "        !       ",
      "!!!!!!!!!       ",
      "                ",
      "                ",
      "                "
    ],
    [
      "    $         $ ",
      "   %$         $ ",
      "    $         $ ",
      "    $         $ ",
      "    $         $ ",
      "    $         $ ",
      "    $         $ ",
      "    $$$$$$$$$$$ ",
      "        !       ",
      "        !       ",
      "        !       ",
      "        !       ",
      "!!!!!!!!!       ",
      "                ",
      "                ",
      "                "
    ],
    [
      "    $         $ ",
      "    $         $ ",
      "   %$         $ ",
      "    $         $ ",
      "    $         $ ",
      "    $         $ ",
      "    $         $ ",
      "    $$$$$$$$$$$ ",
      "        !       ",
      "        !       ",
      "        !       ",
      "        !       ",
      "!!!!!!!!!       ",
      "                ",
      "                ",
      "                "
    ],
    [
      "    $         $ ",
      "    $         $ ",
      "    $         $ ",
      "   %$         $ ",
      "    $         $ ",
      "    $         $ ",
      "    $         $ ",
      "    $$$$$$$$$$$ ",
      "        !       ",
      "        !       ",
      "        !       ",
      "        !       ",
      "!!!!!!!!!       ",
      "                ",
      "                ",
      "                "
    ],
    [
      "    $         $ ",
      "    $         $ ",
      "    $         $ ",
      "    $         $ ",
      "   %$         $ ",
      "    $         $ ",
      "    $         $ ",
      "    $$$$$$$$$$$ ",
      "        !       ",
      "        !       ",
      "        !       ",
      "        !       ",
      "!!!!!!!!!       ",
      "                ",
      "                ",
      "                "
    ],
    [
      "    $         $ ",
      "    $         $ ",
      "    $         $ ",
      "    $         $ ",
      "    $         $ ",
      "    $         $ ",
      "    $         $ ",
      "    $$$$$$$$$$$ ",
      "        !       ",
      "        !       ",
      "        !       ",
      "        !       ",
      "!!!!!!!!!       ",
      "                ",
      "                ",
      "                "
    ]
  ],
  "palette": {
    "palette": [
      {
        "char": "!",
        "block": "minecraft:bricks"
      },
      {
        "char": "$",
        "block": "minecraft:light_gray_concrete"
      },
      {
        "char": "%",
        "block": "minecraft:stone_brick_stairs[facing=south,half=bottom,shape=straight,waterlogged=false]"
      }
    ]
  }
}
