{
  "xsize": 16,
  "zsize": 16,
  "slices": [
    [
      "5555555''$555555",
      "55555''$55555555",
      "555''$5555555555",
      "5''$555555555555",
      "'$55555555555555",
      "5555555555555555",
      "55555555555555''",
      "555555555555''$5",
      "5555555555''$555",
      "55555555''$55555",
      "555555''$5555555",
      "5555''$555555555",
      "55''$55555555555",
      "''$5555555555555",
      "$555555555555555",
      "5$5555$5555$555'"
    ],
    [
      ",,,,,,,,,,,,,,,,",
      ",,,,,,,,,,,,,,,,",
      ",,,,,,,,,,,,,,,,",
      ",,,,,,,,,,,,,,,,",
      ",,,,,,,,,,,,,,,,",
      ",,,,,,,,,,,,,,,,",
      ",,,,,,,,,,,,,,,,",
      ",,,,,,,,,,,,,,,,",
      ",,,,,,,,,,,,,,,,",
      ",,,,,,,,,,,,,,,,",
      ",,,,,,,,,,,,,,,,",
      ",,,,,,,,,,,,,,,,",
      ",,,,,,,,,,,,,,,,",
      ",,,,,,,,,,,,,,,,",
      "                ",
      "                "
    ],
    [
      "                ",
      "                ",
      "         %-&  %-",
      "                ",
      "                ",
      " 4  4  4  4     ",
      "                ",
      "7777777777777   ",
      "6660666666666066",
      "         6    6 ",
      "++++!++  622  6)",
      "8  8  8  .3   . ",
      "         6    6 ",
      "****************",
      "                ",
      "                "
    ],
    [
      "                ",
      "                ",
      "                ",
      "                ",
      "                ",
      "                ",
      "                ",
      "                ",
      "6661666666666166",
      "         6    6 ",
      "+++++++  6    6 ",
      "         /    / ",
      "         6    6(",
      "****************",
      "                ",
      "                "
    ],
    [
      "                ",
      "                ",
      "                ",
      "                ",
      "                ",
      "                ",
      "                ",
      "                ",
      "6666666666666666",
      "         6    6 ",
      "+++++++  6    6 ",
      "         6    6 ",
      "         6    6 ",
      "****************",
      "                ",
      "                "
    ],
    [
      "                ",
      "                ",
      "                ",
      "                ",
      "                ",
      "                ",
      "                ",
      "                ",
      "6666666666666666",
      "         6    6 ",
      "         6    6 ",
      "         6    6 ",
      "         6    6 ",
      "****************",
      "                ",
      "                "
    ]
  ],
  "palette": {
    "palette": [
      {
        "char": "!",
        "block": "minecraft:chest[facing=south,type=single,waterlogged=false]",
        "tag": {
          "id": "minecraft:chest",
          "LootTable": "infinite_domain:chests/wasteland_roadside"
        }
      },
      {
        "char": "$",
        "block": "minecraft:coarse_dirt"
      },
      {
        "char": "%",
        "block": "minecraft:dark_oak_stairs[facing=east,half=bottom,shape=straight,waterlogged=false]"
      },
      {
        "char": "&",
        "block": "minecraft:dark_oak_stairs[facing=west,half=bottom,shape=straight,waterlogged=false]"
      },
      {
        "char": "'",
        "block": "minecraft:gravel"
      },
      {
        "char": "(",
        "block": "minecraft:lever[face=wall,facing=south,powered=false]"
      },
      {
        "char": ")",
        "block": "minecraft:quartz_stairs[facing=south,half=bottom,shape=straight,waterlogged=false]"
      },
      {
        "char": "*",
        "block": "minecraft:red_terracotta"
      },
      {
        "char": "+",
        "block": "minecraft:scaffolding"
      },
      {
        "char": ",",
        "block": "minecraft:smooth_stone"
      },
      {
        "char": "-",
        "block": "minecraft:smooth_stone_slab[type=bottom,waterlogged=false]"
      },
      {
        "char": ".",
        "block": "minecraft:spruce_door[facing=east,half=lower,hinge=left,open=false,powered=false]"
      },
      {
        "char": "/",
        "block": "minecraft:spruce_door[facing=east,half=upper,hinge=left,open=false,powered=false]"
      },
      {
        "char": "0",
        "block": "minecraft:spruce_door[facing=south,half=lower,hinge=left,open=false,powered=false]"
      },
      {
        "char": "1",
        "block": "minecraft:spruce_door[facing=south,half=upper,hinge=left,open=false,powered=false]"
      },
      {
        "char": "2",
        "block": "minecraft:spruce_slab[type=bottom,waterlogged=false]"
      },
      {
        "char": "3",
        "block": "minecraft:spruce_stairs[facing=north,half=bottom,shape=straight,waterlogged=false]"
      },
      {
        "char": "4",
        "block": "minecraft:spruce_stairs[facing=south,half=bottom,shape=straight,waterlogged=false]"
      },
      {
        "char": "5",
        "block": "tfmg:asphalt"
      },
      {
        "char": "6",
        "block": "tfmg:cinder_block"
      },
      {
        "char": "7",
        "block": "zvhouses:spruce_countertop"
      },
      {
        "char": "8",
        "block": "zvhouses:stone_brick_countertop"
      }
    ]
  }
}
