{
  "xsize": 16,
  "zsize": 16,
  "slices": [
    [
      "33333333333     ",
      "33333333333     ",
      "33333333333     ",
      "33333333333     ",
      "33333333333     ",
      "33333333333     ",
      "33333333333     ",
      "3333333333)     ",
      "33333333333     ",
      "33333))$333     ",
      "333))$33333     ",
      "3))$3333333     ",
      ")$333333333     ",
      "33333333333     ",
      "33333333333     ",
      "33333333333     "
    ],
    [
      "                ",
      "                ",
      "                ",
      "                ",
      "++++1           ",
      "++++            ",
      "++++            ",
      "*********       ",
      "*********       ",
      "*********       ",
      "*********       ",
      "*********       ",
      "*********       ",
      "*********       ",
      "*********       ",
      "*********       "
    ],
    [
      "                ",
      "                ",
      "                ",
      "                ",
      "    1           ",
      "                ",
      "   ....         ",
      "%&4444444       ",
      "        4       ",
      "    ..  4       ",
      "    0   4       ",
      "        4       ",
      "        4       ",
      "        4       ",
      "44444,444       ",
      "  4     4       "
    ],
    [
      "                ",
      "                ",
      "                ",
      "                ",
      "    1           ",
      "                ",
      "                ",
      "'(2!!!!24       ",
      "        4       ",
      "        4       ",
      "        !       ",
      "        !       ",
      "        4       ",
      "        4       ",
      "44444-444       ",
      "  4     4       "
    ],
    [
      "                ",
      "                ",
      "                ",
      "                ",
      "    1           ",
      "                ",
      "                ",
      "  2!!!!24       ",
      "        4       ",
      "        4       ",
      "        !       ",
      "        !       ",
      "        4       ",
      "        4       ",
      "444444444       ",
      "  4     4       "
    ],
    [
      "                ",
      "                ",
      "                ",
      "                ",
      "    1           ",
      "                ",
      "   ////         ",
      "444444444       ",
      "        4       ",
      "        4       ",
      "        4       ",
      "        4       ",
      "        4       ",
      "        4       ",
      "444444444       ",
      "  4     4       "
    ]
  ],
  "palette": {
    "palette": [
      {
        "char": "!",
        "block": "create:framed_glass"
      },
      {
        "char": "$",
        "block": "minecraft:coarse_dirt"
      },
      {
        "char": "%",
        "block": "minecraft:dark_oak_door[facing=north,half=lower,hinge=left,open=false,powered=false]"
      },
      {
        "char": "&",
        "block": "minecraft:dark_oak_door[facing=north,half=lower,hinge=right,open=false,powered=false]"
      },
      {
        "char": "'",
        "block": "minecraft:dark_oak_door[facing=north,half=upper,hinge=left,open=false,powered=false]"
      },
      {
        "char": "(",
        "block": "minecraft:dark_oak_door[facing=north,half=upper,hinge=right,open=false,powered=false]"
      },
      {
        "char": ")",
        "block": "minecraft:gravel"
      },
      {
        "char": "*",
        "block": "minecraft:polished_andesite"
      },
      {
        "char": "+",
        "block": "minecraft:smooth_stone"
      },
      {
        "char": ",",
        "block": "minecraft:spruce_door[facing=south,half=lower,hinge=left,open=false,powered=false]"
      },
      {
        "char": "-",
        "block": "minecraft:spruce_door[facing=south,half=upper,hinge=left,open=false,powered=false]"
      },
      {
        "char": ".",
        "block": "minecraft:spruce_slab[type=bottom,waterlogged=false]"
      },
      {
        "char": "/",
        "block": "minecraft:spruce_slab[type=top,waterlogged=false]"
      },
      {
        "char": "0",
        "block": "minecraft:spruce_stairs[facing=north,half=bottom,shape=straight,waterlogged=false]"
      },
      {
        "char": "1",
        "block": "minecraft:stripped_dark_oak_log[axis=y]"
      },
      {
        "char": "2",
        "block": "minecraft:stripped_spruce_log[axis=y]"
      },
      {
        "char": "3",
        "block": "tfmg:asphalt"
      },
      {
        "char": "4",
        "block": "tfmg:cinder_block"
      }
    ]
  }
}
