{
  "xsize": 16,
  "zsize": 16,
  "slices": [
    [
      "&+        +     ",
      " +        +     ",
      " +        +     ",
      " +        +     ",
      " ++++++++++     ",
      " +        +     ",
      " +        +     ",
      " +        +     ",
      " +        +     ",
      " +        +     ",
      " +        +     ",
      " ++++++++++     ",
      " +        +     ",
      " +        +     ",
      " +        +     ",
      " +        +     "
    ],
    [
      " +        +     ",
      "&+        +     ",
      " +        +     ",
      " +        +     ",
      " ++++++++++     ",
      " +        +     ",
      " +        +     ",
      " +        +     ",
      " +        +     ",
      " +        +     ",
      " +        +     ",
      " ++++++++++     ",
      " +        +     ",
      " +        +     ",
      " +        +     ",
      " +        +     "
    ],
    [
      " +        +     ",
      " +        +     ",
      "&+        +     ",
      " +        +     ",
      " +        +     ",
      " +        +     ",
      " +        +     ",
      " +        +     ",
      " +        +     ",
      " +        +     ",
      " +        +     ",
      " +        +     ",
      " +        +     ",
      " +        +     ",
      " +        +     ",
      " +        +     "
    ],
    [
      "          +     ",
      "          +     ",
      "          +     ",
      "&         +     ",
      "          +     ",
      "          +     ",
      "          +     ",
      "          +     ",
      "          +     ",
      "          +     ",
      "          +     ",
      "          +     ",
      "          +     ",
      "          +     ",
      "          +     ",
      "          +     "
    ],
    [
      "%%%%%%%%%%'     ",
      "%%%%%%%%%%'     ",
      " %%%%%%%%%'     ",
      " %%%%%%%%%'     ",
      "%%%%%%%%%%'     ",
      "%%%%%%%%%%'     ",
      "%%%%%%%%%%'     ",
      "%%%%%%%%%%'     ",
      "%%%%%%%%%%'     ",
      "%%%%%%%%%%'     ",
      "%%%%%%%%%%'     ",
      "%%%%%%%%%%'     ",
      "%%%%%%%%%%'     ",
      "%%%%%%%%%%'     ",
      "%%%%%%%%%%'     ",
      "%%%%%%%%%%'     "
    ],
    [
      " +  $     +     ",
      " )        +     ",
      " +        +     ",
      " +        +     ",
      " ++++(+++++     ",
      " +        +     ",
      " +        +     ",
      " +  ! *   +     ",
      " )  $     +     ",
      " +        +     ",
      " +        +     ",
      " ++++(+++++     ",
      " +        +     ",
      " +        +     ",
      " )  ! *   +     ",
      " +  $     +     "
    ]
  ],
  "palette": {
    "palette": [
      {
        "char": "!",
        "block": "minecraft:light_gray_bed[facing=south,occupied=false,part=foot]"
      },
      {
        "char": "$",
        "block": "minecraft:light_gray_bed[facing=south,occupied=false,part=head]"
      },
      {
        "char": "%",
        "block": "minecraft:polished_andesite"
      },
      {
        "char": "&",
        "block": "minecraft:polished_andesite_stairs[facing=south,half=bottom,shape=straight,waterlogged=false]"
      },
      {
        "char": "'",
        "block": "minecraft:smooth_stone"
      },
      {
        "char": "(",
        "block": "minecraft:spruce_door[facing=south,half=lower,hinge=left,open=false,powered=false]"
      },
      {
        "char": ")",
        "block": "minecraft:spruce_door[facing=west,half=lower,hinge=left,open=false,powered=false]"
      },
      {
        "char": "*",
        "block": "minecraft:water_cauldron[level=3]"
      },
      {
        "char": "+",
        "block": "minecraft:white_concrete"
      }
    ]
  }
}
