{
  "xsize": 16,
  "zsize": 16,
  "slices": [
    [
      "2222222222222222",
      "22222222222222((",
      "222222222222((&2",
      "2222222222((&222",
      "22222222((&22222",
      "222222((&2222222",
      "2222((&222222222",
      "22((&22222222222",
      "((&2222222222222",
      "&222222222222222",
      "222222222222222(",
      "2222222222222((&",
      "22222222222((&22",
      "222222222((&2222",
      "2222222((&222222",
      "22222((&22222222"
    ],
    [
      ")))))))))))1((((",
      "))))))))))))(1((",
      ")))))))))))1)(((",
      "))))))))))))((((",
      "))))))))))))))))",
      "))))))))))))))))",
      "))))))))))))))))",
      "))))))))))))))))",
      "))))))))))))))))",
      "))))))))))))))))",
      "))))))))))))))))",
      "))))))))))))))))",
      "))))))))))))))))",
      "))))))))))))))))",
      "                ",
      "                "
    ],
    [
      "   +        ((((",
      "   +        1 ((",
      "   +         ((1",
      "   +        (11(",
      "++++++++++++++.+",
      "                ",
      "                ",
      "++.+++++++++.+++",
      "         +$    +",
      "0        +$ %  +",
      "         ,$    ,",
      "         +$    *",
      "         +     +",
      "1111111111111111",
      "                ",
      "                "
    ],
    [
      "   +        (11(",
      "   +   '''''  (1",
      "   +   ''''' 11 ",
      "   +        1  (",
      "++++++++++++++/+",
      "                ",
      "                ",
      "++/+++++++++/+++",
      "         +$    +",
      "         +$    +",
      "         -$    -",
      "         +$     ",
      "         +     +",
      "111111!!1111!!11",
      "                ",
      "                "
    ],
    [
      "   +        1  (",
      "   +   ''''   1 ",
      "   +   ''''     ",
      "   +           1",
      "++++++++++++++++",
      "                ",
      "                ",
      "++++++++++++++++",
      "         +$    +",
      "         +$    *",
      "         +$     ",
      "         +$     ",
      "         +     +",
      "111111!!1111!!11",
      "                ",
      "                "
    ],
    [
      "   +           1",
      "   +            ",
      "   +            ",
      "   +            ",
      "++++++++++++++++",
      "                ",
      "                ",
      "++++++++++++++++",
      "         +     *",
      "         +      ",
      "         +      ",
      "         +     +",
      "         +     +",
      "1111111111111111",
      "                ",
      "                "
    ]
  ],
  "palette": {
    "palette": [
      {
        "char": "!",
        "block": "create:framed_glass"
      },
      {
        "char": "$",
        "block": "immersiveengineering:crate"
      },
      {
        "char": "%",
        "block": "minecraft:chest[facing=west,type=single,waterlogged=false]",
        "tag": {
          "id": "minecraft:chest",
          "LootTable": "infinite_domain:chests/wasteland_data"
        }
      },
      {
        "char": "&",
        "block": "minecraft:coarse_dirt"
      },
      {
        "char": "'",
        "block": "minecraft:dark_oak_planks"
      },
      {
        "char": "(",
        "block": "minecraft:gravel"
      },
      {
        "char": ")",
        "block": "minecraft:polished_andesite"
      },
      {
        "char": "*",
        "block": "minecraft:polished_andesite_stairs[facing=north,half=bottom,shape=straight,waterlogged=false]"
      },
      {
        "char": "+",
        "block": "minecraft:polished_tuff"
      },
      {
        "char": ",",
        "block": "minecraft:spruce_door[facing=east,half=lower,hinge=left,open=false,powered=false]"
      },
      {
        "char": "-",
        "block": "minecraft:spruce_door[facing=east,half=upper,hinge=left,open=false,powered=false]"
      },
      {
        "char": ".",
        "block": "minecraft:spruce_door[facing=south,half=lower,hinge=left,open=false,powered=false]"
      },
      {
        "char": "/",
        "block": "minecraft:spruce_door[facing=south,half=upper,hinge=left,open=false,powered=false]"
      },
      {
        "char": "0",
        "block": "minecraft:spruce_slab[type=bottom,waterlogged=false]"
      },
      {
        "char": "1",
        "block": "minecraft:tuff_bricks"
      },
      {
        "char": "2",
        "block": "tfmg:asphalt"
      }
    ]
  }
}
