{
  "xsize": 16,
  "zsize": 16,
  "slices": [
    [
      "----------------",
      "--------------%%",
      "------------%%$-",
      "----------%%$---",
      "--------%%$-----",
      "------%%$-------",
      "----%%$---------",
      "--%%$-----------",
      "%%$-------------",
      "$---------------",
      "---------------%",
      "-------------%%$",
      "-----------%%$--",
      "---------%%$----",
      "-------%%$------",
      "-----%%$--------"
    ],
    [
      "////////////////",
      "////////////////",
      "////////////////",
      "////////////////",
      "////////////////",
      "////////////////",
      "////////////////",
      "////////////////",
      "////////////////",
      "////////////////",
      "////////////////",
      "////////////////",
      "////////////////",
      "////////////////",
      "////////////////",
      "                "
    ],
    [
      "             '  ",
      "                ",
      "                ",
      "       *****   *",
      "       *****   *",
      "       *****   *",
      "       *****   *",
      "       *****   *",
      "       *****   *",
      "..............(.",
      "                ",
      "      ++ 0      ",
      "      ,         ",
      "                ",
      "!!!!!!!!!!!!!!!!",
      "                "
    ],
    [
      "                ",
      "             '  ",
      "                ",
      "                ",
      "                ",
      "        &       ",
      "                ",
      "                ",
      "                ",
      "..............).",
      "                ",
      "                ",
      "                ",
      "                ",
      "!!!!!!!!!!!!!!!!",
      "                "
    ],
    [
      "                ",
      "                ",
      "             '  ",
      "                ",
      "                ",
      "                ",
      "                ",
      "                ",
      "                ",
      "................",
      "                ",
      "                ",
      "                ",
      "                ",
      "!!!!!!!!!!!!!!!!",
      "                "
    ],
    [
      "                ",
      "                ",
      "                ",
      "             '  ",
      "                ",
      "                ",
      "                ",
      "                ",
      "                ",
      "................",
      "                ",
      "                ",
      "                ",
      "                ",
      "!!!!!!!!!!!!!!!!",
      "                "
    ]
  ],
  "palette": {
    "palette": [
      {
        "char": "!",
        "block": "minecraft:bricks"
      },
      {
        "char": "$",
        "block": "minecraft:coarse_dirt"
      },
      {
        "char": "%",
        "block": "minecraft:gravel"
      },
      {
        "char": "&",
        "block": "minecraft:loom[facing=north]"
      },
      {
        "char": "'",
        "block": "minecraft:quartz_stairs[facing=south,half=bottom,shape=straight,waterlogged=false]"
      },
      {
        "char": "(",
        "block": "minecraft:spruce_door[facing=south,half=lower,hinge=left,open=false,powered=false]"
      },
      {
        "char": ")",
        "block": "minecraft:spruce_door[facing=south,half=upper,hinge=left,open=false,powered=false]"
      },
      {
        "char": "*",
        "block": "minecraft:spruce_planks"
      },
      {
        "char": "+",
        "block": "minecraft:spruce_slab[type=bottom,waterlogged=false]"
      },
      {
        "char": ",",
        "block": "minecraft:spruce_stairs[facing=north,half=bottom,shape=straight,waterlogged=false]"
      },
      {
        "char": "-",
        "block": "tfmg:asphalt"
      },
      {
        "char": ".",
        "block": "tfmg:cinder_block"
      },
      {
        "char": "/",
        "block": "tfmg:factory_floor"
      },
      {
        "char": "0",
        "block": "the_wasteland_reworked:radio"
      }
    ]
  }
}
