{
  "xsize": 16,
  "zsize": 16,
  "slices": [
    [
      "2222222222222222",
      "2222222222222222",
      "2222222222222222",
      "2222222222222222",
      "2222222222222222",
      "2222222222222222",
      "2222222222222222",
      "2222---222222222",
      "2%%$---222222222",
      "%$22------------",
      "2222------------",
      "2222------------",
      "2222------------",
      "2222------------",
      "2222------------",
      "2222------------"
    ],
    [
      "                ",
      "                ",
      "        ,       ",
      "                ",
      "                ",
      "                ",
      "                ",
      "                ",
      "     +++++++++++",
      "     +++++++++++",
      "     +++++++++++",
      "     +++++++++++",
      "     +++++++++++",
      "     +++++++++++",
      "     +++++++++++",
      "     +++++++++++"
    ],
    [
      "                ",
      "                ",
      "        ,       ",
      "                ",
      "                ",
      "                ",
      "                ",
      "       ..  ..   ",
      "     *********&'",
      "     *          ",
      "     *          ",
      "     *  ..      ",
      "     *  0       ",
      "     *          ",
      "     *          ",
      "     *          "
    ],
    [
      "                ",
      "                ",
      "        ,       ",
      "                ",
      "                ",
      "                ",
      "                ",
      "                ",
      "     *1!!11!!1()",
      "     *          ",
      "     *          ",
      "     *          ",
      "     !          ",
      "     !          ",
      "     *          ",
      "     *          "
    ],
    [
      "                ",
      "                ",
      "        ,       ",
      "                ",
      "                ",
      "                ",
      "                ",
      "                ",
      "     *1!!11!!1**",
      "     *          ",
      "     *          ",
      "     *          ",
      "     !          ",
      "     !          ",
      "     *          ",
      "     *          "
    ],
    [
      "                ",
      "                ",
      "        ,       ",
      "                ",
      "                ",
      "                ",
      "                ",
      "       //  //   ",
      "     ***********",
      "     *          ",
      "     *          ",
      "     *          ",
      "     *          ",
      "     *          ",
      "     *          ",
      "     *          "
    ]
  ],
  "palette": {
    "palette": [
      {
        "char": "!",
        "block": "create:framed_glass"
      },
      {
        "char": "$",
        "block": "minecraft:coarse_dirt"
      },
      {
        "char": "%",
        "block": "minecraft:gravel"
      },
      {
        "char": "&",
        "block": "minecraft:iron_door[facing=north,half=lower,hinge=left,open=false,powered=false]"
      },
      {
        "char": "'",
        "block": "minecraft:iron_door[facing=north,half=lower,hinge=right,open=false,powered=false]"
      },
      {
        "char": "(",
        "block": "minecraft:iron_door[facing=north,half=upper,hinge=left,open=false,powered=false]"
      },
      {
        "char": ")",
        "block": "minecraft:iron_door[facing=north,half=upper,hinge=right,open=false,powered=false]"
      },
      {
        "char": "*",
        "block": "minecraft:light_gray_concrete"
      },
      {
        "char": "+",
        "block": "minecraft:polished_andesite"
      },
      {
        "char": ",",
        "block": "minecraft:polished_blackstone_bricks"
      },
      {
        "char": "-",
        "block": "minecraft:smooth_stone"
      },
      {
        "char": ".",
        "block": "minecraft:spruce_slab[type=bottom,waterlogged=false]"
      },
      {
        "char": "/",
        "block": "minecraft:spruce_slab[type=top,waterlogged=false]"
      },
      {
        "char": "0",
        "block": "minecraft:spruce_stairs[facing=north,half=bottom,shape=straight,waterlogged=false]"
      },
      {
        "char": "1",
        "block": "minecraft:stripped_spruce_log[axis=y]"
      },
      {
        "char": "2",
        "block": "tfmg:asphalt"
      }
    ]
  }
}
