{
  "xsize": 16,
  "zsize": 16,
  "slices": [
    [
      "''%--------     ",
      "%----------     ",
      "-----------     ",
      "-----------     ",
      "-----------     ",
      "---------''     ",
      "-------''%-     ",
      "-----''%---     ",
      "---''%-----     ",
      "-''%-------     ",
      "'%---------     ",
      "-----------     ",
      "-----------     ",
      "-----------     ",
      "----------'     ",
      "--------''%     "
    ],
    [
      "((((((          ",
      "((((((          ",
      "((((((          ",
      "((((((          ",
      "((((((          ",
      "((((((          ",
      "((((((          ",
      "((((((          ",
      "((((((          ",
      "((((((          ",
      "((((((          ",
      "((((((          ",
      "((((((          ",
      "((((((          ",
      "                ",
      "                "
    ],
    [
      "     ,          ",
      "     ,          ",
      "     ,          ",
      "     ,          ",
      "))))),          ",
      "     ,          ",
      "     ,          ",
      ")*))),          ",
      "   $ ,          ",
      "   $ ,          ",
      "   $ ,          ",
      "   $ ,          ",
      "     ,          ",
      ",,,,,,          ",
      "                ",
      "                "
    ],
    [
      "     !          ",
      "&&   ,          ",
      "&&   ,          ",
      "     ,          ",
      "))))),          ",
      "     ,          ",
      "     ,          ",
      ")+)))!          ",
      "   $ !          ",
      "   $ ,          ",
      "   $ ,          ",
      "   $ !          ",
      "     !          ",
      ",,!!,,          ",
      "                ",
      "                "
    ],
    [
      "     !          ",
      "&&   ,          ",
      "&&   ,          ",
      "     ,          ",
      "))))),          ",
      "     ,          ",
      "     ,          ",
      ")))))!          ",
      "   $ !          ",
      "   $ ,          ",
      "   $ ,          ",
      "   $ !          ",
      "     !          ",
      ",,!!,,          ",
      "                ",
      "                "
    ],
    [
      "     ,          ",
      "     ,          ",
      "     ,          ",
      "     ,          ",
      "))))),          ",
      "     ,          ",
      "     ,          ",
      "))))),          ",
      "     ,          ",
      "     ,          ",
      "     ,          ",
      "     ,          ",
      "     ,          ",
      ",,,,,,          ",
      "                ",
      "                "
    ]
  ],
  "palette": {
    "palette": [
      {
        "char": "!",
        "block": "create:framed_glass"
      },
      {
        "char": "$",
        "block": "minecraft:bookshelf"
      },
      {
        "char": "%",
        "block": "minecraft:coarse_dirt"
      },
      {
        "char": "&",
        "block": "minecraft:dark_oak_planks"
      },
      {
        "char": "'",
        "block": "minecraft:gravel"
      },
      {
        "char": "(",
        "block": "minecraft:polished_andesite"
      },
      {
        "char": ")",
        "block": "minecraft:polished_tuff"
      },
      {
        "char": "*",
        "block": "minecraft:spruce_door[facing=south,half=lower,hinge=left,open=false,powered=false]"
      },
      {
        "char": "+",
        "block": "minecraft:spruce_door[facing=south,half=upper,hinge=left,open=false,powered=false]"
      },
      {
        "char": ",",
        "block": "minecraft:tuff_bricks"
      },
      {
        "char": "-",
        "block": "tfmg:asphalt"
      }
    ]
  }
}
