{
  "xsize": 16,
  "zsize": 16,
  "slices": [
    [
      "5555555555555555",
      "5555555555555555",
      "5555555555555555",
      "5555555555555555",
      "5555555555555'55",
      "5555555555555555",
      "5555555555555555",
      "5555555555555555",
      "5555555555555555",
      "55''&55555555555",
      "''&5555555555555",
      "&555555555555555",
      "555555555555555'",
      "5555555555555''&",
      "55555555555''&55",
      "555555555''&5555"
    ],
    [
      "    4       4   ",
      "    4       4   ",
      "    4       4   ",
      "    4       4   ",
      "    4       4 2,",
      "    4       4 ,,",
      "    4       4 ,,",
      "777777777777****",
      "777777777777****",
      "777777777777****",
      "777777777777****",
      "777777777777****",
      "777777777777****",
      "777777777777****",
      "777777777777****",
      "777777777777****"
    ],
    [
      "                ",
      "                ",
      "                ",
      "                ",
      "              2 ",
      "                ",
      "   ))      ) // ",
      "   ))      ))666",
      "   ))      ))   ",
      "            ) //",
      "            ) 1 ",
      "            )   ",
      "            )   ",
      "444         )   ",
      "44$         )66-",
      "444         )   "
    ],
    [
      "                ",
      "                ",
      "                ",
      "                ",
      "              2 ",
      "                ",
      "   ))      )    ",
      "   ))      )3!!3",
      "   ))      )6   ",
      "            6  8",
      "            6   ",
      "            6   ",
      "            6   ",
      "444         6   ",
      "444         666.",
      "444         6   "
    ],
    [
      "                ",
      "                ",
      "                ",
      "                ",
      "              2 ",
      "                ",
      "   ))      )    ",
      "   ))      )3!!3",
      "   ))      )6   ",
      "            6   ",
      "            6   ",
      "            6   ",
      "            6   ",
      "444         6   ",
      "444         6666",
      "444         6   "
    ],
    [
      "                ",
      "                ",
      "                ",
      "                ",
      "              2 ",
      "                ",
      "   ))      ) 00 ",
      "   ))      )6666",
      "   ))      )6   ",
      "            6   ",
      "            6   ",
      "            6   ",
      "%           6   ",
      "(((         6   ",
      "++          6666",
      "++          6   "
    ]
  ],
  "palette": {
    "palette": [
      {
        "char": "!",
        "block": "create:framed_glass"
      },
      {
        "char": "$",
        "block": "minecraft:black_concrete"
      },
      {
        "char": "%",
        "block": "minecraft:blue_concrete"
      },
      {
        "char": "&",
        "block": "minecraft:coarse_dirt"
      },
      {
        "char": "'",
        "block": "minecraft:gravel"
      },
      {
        "char": "(",
        "block": "minecraft:light_blue_stained_glass"
      },
      {
        "char": ")",
        "block": "minecraft:mud_bricks"
      },
      {
        "char": "*",
        "block": "minecraft:polished_andesite"
      },
      {
        "char": "+",
        "block": "minecraft:red_concrete"
      },
      {
        "char": ",",
        "block": "minecraft:smooth_stone"
      },
      {
        "char": "-",
        "block": "minecraft:spruce_door[facing=south,half=lower,hinge=left,open=false,powered=false]"
      },
      {
        "char": ".",
        "block": "minecraft:spruce_door[facing=south,half=upper,hinge=left,open=false,powered=false]"
      },
      {
        "char": "/",
        "block": "minecraft:spruce_slab[type=bottom,waterlogged=false]"
      },
      {
        "char": "0",
        "block": "minecraft:spruce_slab[type=top,waterlogged=false]"
      },
      {
        "char": "1",
        "block": "minecraft:spruce_stairs[facing=north,half=bottom,shape=straight,waterlogged=false]"
      },
      {
        "char": "2",
        "block": "minecraft:stripped_dark_oak_log[axis=y]"
      },
      {
        "char": "3",
        "block": "minecraft:stripped_spruce_log[axis=y]"
      },
      {
        "char": "4",
        "block": "minecraft:white_concrete"
      },
      {
        "char": "5",
        "block": "tfmg:asphalt"
      },
      {
        "char": "6",
        "block": "tfmg:cinder_block"
      },
      {
        "char": "7",
        "block": "tfmg:factory_floor"
      },
      {
        "char": "8",
        "block": "the_wasteland_reworked:radio"
      }
    ]
  }
}
