{
  "xsize": 16,
  "zsize": 16,
  "slices": [
    [
      "    &         & ",
      "    &         & ",
      "    &         & ",
      "    &&&&&&&&&&&&",
      "    &         & ",
      "    &         & ",
      "    &         & ",
      "    &     (   & ",
      "    &         & ",
      "    &         & ",
      "    &         & ",
      "    &         & ",
      "    )))))))))   ",
      "    )           ",
      "    )           ",
      "    )           "
    ],
    [
      "    &           ",
      "    &           ",
      "    &           ",
      "    &           ",
      "    &           ",
      "    &           ",
      "    &           ",
      "    &           ",
      "    &     (     ",
      "    &           ",
      "    &           ",
      "    &           ",
      "    ))))))))))))",
      "    )           ",
      "    )           ",
      "    )           "
    ],
    [
      "    &           ",
      "    &           ",
      "    &           ",
      "    &           ",
      "    &           ",
      "    &           ",
      "    &           ",
      "    &           ",
      "    &           ",
      "    &     (     ",
      "    &           ",
      "    &           ",
      "    ))))))))))))",
      "    )           ",
      "    )           ",
      "    )           "
    ],
    [
      "    !  '''''''''",
      "    !  '''''''''",
      "    !  '''''''''",
      "    !  '''''''''",
      "    !  '''''''''",
      "    !  '''''''''",
      "    !  '''''''''",
      "    !  '''''''''",
      "    !  ''' '''''",
      "    !  '''''''''",
      "    !  '''''''''",
      "    !  '''''''''",
      "    !)))))))))))",
      "    !           ",
      "    !           ",
      "    !           "
    ],
    [
      "    &  %%%%%%-%%",
      "    &  %       %",
      "    &  % //  //%",
      "    &  % 0   0 +",
      "    &  %       %",
      "    &  %       $",
      "    &  %       $",
      "    &  %       %",
      "    &  %        ",
      "    &  %        ",
      "    &  %        ",
      "    &  %%%%%%%%%",
      "    ))))))))))))",
      "    )           ",
      "    )           ",
      "    )           "
    ],
    [
      "    ***%%%%%%.%%",
      "    ***%       %",
      "    ***%       %",
      "    ***%       ,",
      "    ***%       %",
      "    ***%       $",
      "    ***%       $",
      "    ***%       %",
      "    ***%        ",
      "    ***%        ",
      "    ***%        ",
      "    ***%%%%%%%%%",
      "    ************",
      "    ************",
      "    ************",
      "    ************"
    ]
  ],
  "palette": {
    "palette": [
      {
        "char": "!",
        "block": "minecraft:blue_concrete"
      },
      {
        "char": "$",
        "block": "minecraft:bookshelf"
      },
      {
        "char": "%",
        "block": "minecraft:gray_concrete"
      },
      {
        "char": "&",
        "block": "minecraft:light_gray_concrete"
      },
      {
        "char": "'",
        "block": "minecraft:polished_andesite"
      },
      {
        "char": "(",
        "block": "minecraft:polished_andesite_stairs[facing=south,half=bottom,shape=straight,waterlogged=false]"
      },
      {
        "char": ")",
        "block": "minecraft:polished_deepslate"
      },
      {
        "char": "*",
        "block": "minecraft:smooth_stone"
      },
      {
        "char": "+",
        "block": "minecraft:spruce_door[facing=east,half=lower,hinge=left,open=false,powered=false]"
      },
      {
        "char": ",",
        "block": "minecraft:spruce_door[facing=east,half=upper,hinge=left,open=false,powered=false]"
      },
      {
        "char": "-",
        "block": "minecraft:spruce_door[facing=south,half=lower,hinge=left,open=false,powered=false]"
      },
      {
        "char": ".",
        "block": "minecraft:spruce_door[facing=south,half=upper,hinge=left,open=false,powered=false]"
      },
      {
        "char": "/",
        "block": "minecraft:spruce_slab[type=bottom,waterlogged=false]"
      },
      {
        "char": "0",
        "block": "minecraft:spruce_stairs[facing=north,half=bottom,shape=straight,waterlogged=false]"
      }
    ]
  }
}
