{
  "xsize": 16,
  "zsize": 16,
  "slices": [
    [
      "       (        ",
      "       (        ",
      "       (        ",
      "       (        ",
      "       (        ",
      "       (        ",
      "       (        ",
      "%%!!%%%%!!%%%%!!",
      "                ",
      "                ",
      "                ",
      "                ",
      "                ",
      "                ",
      "                ",
      "                "
    ],
    [
      "       (        ",
      "       (        ",
      "       (        ",
      "       (        ",
      "       (        ",
      "       (        ",
      "       (        ",
      "%%!!%%%%!!%%%%!!",
      "                ",
      "                ",
      "                ",
      "                ",
      "                ",
      "                ",
      "                ",
      "                "
    ],
    [
      "       (        ",
      "       (        ",
      "       (        ",
      "       (        ",
      "       (        ",
      "       (        ",
      "       (        ",
      "%%%%%%%%%%%%%%%%",
      "                ",
      "                ",
      "                ",
      "                ",
      "                ",
      "                ",
      "                ",
      "                "
    ],
    [
      "                ",
      "                ",
      "                ",
      "                ",
      "                ",
      "                ",
      "                ",
      "%%%%%%%%%%%%%%%%",
      "                ",
      "                ",
      "                ",
      "                ",
      "                ",
      "                ",
      "                ",
      "                "
    ],
    [
      "                ",
      "                ",
      "                ",
      "                ",
      "                ",
      "                ",
      "                ",
      "%%%%%%%%%%%%%%%%",
      "                ",
      "                ",
      "                ",
      "                ",
      "                ",
      "                ",
      "                ",
      "                "
    ],
    [
      "&&&&$$$$$$$$$$$$",
      "&&&&$$$$$$$$$$$$",
      "&&&&$$$$$$$$$$$$",
      "&&&&$$$$$$$$$$$$",
      "&&&&$$$$$$$$$$$$",
      "&&&&$$$$$$$$$$$$",
      "$$$$$$$$$$$$$$$$",
      "''''''''''''''''",
      "''''''''''''''''",
      "                ",
      "                ",
      "                ",
      "                ",
      "                ",
      "                ",
      "                "
    ]
  ],
  "palette": {
    "palette": [
      {
        "char": "!",
        "block": "create:framed_glass"
      },
      {
        "char": "$",
        "block": "minecraft:dark_prismarine"
      },
      {
        "char": "%",
        "block": "minecraft:mud_bricks"
      },
      {
        "char": "&",
        "block": "minecraft:oak_planks"
      },
      {
        "char": "'",
        "block": "minecraft:smooth_stone_slab[type=top,waterlogged=false]"
      },
      {
        "char": "(",
        "block": "minecraft:stripped_spruce_wood"
      }
    ]
  }
}
