{
  "xsize": 16,
  "zsize": 16,
  "slices": [
    [
      "++++++++++      ",
      "++++++++''      ",
      "++++++''%+      ",
      "++++''%+++      ",
      "++''%+++++      ",
      "''%++++++'      ",
      "%+++++++++      ",
      "++++++++++      ",
      "++++++++++      ",
      "++++++++++      ",
      "+++++++++'      ",
      "+++++++'''      ",
      "+++++''%++      ",
      "+++''%++++      ",
      "+''%++++++      ",
      "'%++++++++      "
    ],
    [
      "                ",
      "))))))))        ",
      "))))))))        ",
      "))))))))        ",
      "))))))))        ",
      "))))))))        ",
      "))))))))        ",
      "))))))))        ",
      "))))))))        ",
      "))))))))        ",
      "))))))))        ",
      "))))))))        ",
      "))))))))        ",
      "))))))))        ",
      "))))))))        ",
      "))))))))        "
    ],
    [
      "                ",
      "********        ",
      "       *        ",
      "(((((( *        ",
      "(((((( *        ",
      "(((($( *        ",
      "(((((( *        ",
      "(((((( *        ",
      "       *        ",
      "       *        ",
      "       *        ",
      "       *        ",
      "&  !   *        ",
      "       *        ",
      "       *        ",
      "       *        "
    ],
    [
      "                ",
      "********        ",
      "       *        ",
      "(((((( *        ",
      "(((((( *        ",
      "(((((( *        ",
      "(((((( *        ",
      "(((((( *        ",
      "       *        ",
      "       *        ",
      "       *        ",
      "       *        ",
      "       *        ",
      "       *        ",
      "       *        ",
      "       *        "
    ],
    [
      "                ",
      "********        ",
      "       *        ",
      "(((((( *        ",
      "(((((( *        ",
      "(((((( *        ",
      "(((((( *        ",
      "(((((( *        ",
      "       *        ",
      "       *        ",
      "       *        ",
      "       *        ",
      "       *        ",
      "       *        ",
      "       *        ",
      "       *        "
    ],
    [
      "                ",
      "********        ",
      "       *        ",
      "(((((( *        ",
      "(((((( *        ",
      "(((((( *        ",
      "(((((( *        ",
      "(((((( *        ",
      "       *        ",
      "       *        ",
      "       *        ",
      "       *        ",
      "       *        ",
      "       *        ",
      "       *        ",
      "       *        "
    ]
  ],
  "palette": {
    "palette": [
      {
        "char": "!",
        "block": "kubejs:ruined_blast_furnace[facing=north]"
      },
      {
        "char": "$",
        "block": "minecraft:chest[facing=north,type=single,waterlogged=false]",
        "tag": {
          "id": "minecraft:chest",
          "LootTable": "infinite_domain:chests/wasteland_roadside"
        }
      },
      {
        "char": "%",
        "block": "minecraft:coarse_dirt"
      },
      {
        "char": "&",
        "block": "kubejs:ruined_crafting_table"
      },
      {
        "char": "'",
        "block": "minecraft:gravel"
      },
      {
        "char": "(",
        "block": "minecraft:scaffolding"
      },
      {
        "char": ")",
        "block": "minecraft:smooth_stone"
      },
      {
        "char": "*",
        "block": "minecraft:stripped_spruce_log"
      },
      {
        "char": "+",
        "block": "tfmg:asphalt"
      }
    ]
  }
}
