{
  "xsize": 16,
  "zsize": 16,
  "slices": [
    [
      ".............$$!",
      "...........$$!..",
      ".........$$!....",
      ".......$$!......",
      ".....$$!........",
      "...$$!..........",
      ".$$!............",
      "$!..............",
      "................",
      "..............$$",
      "............$$!.",
      "..........$$!...",
      "........$$!.....",
      "......$$!.......",
      "....$$!.........",
      "..$$!..........."
    ],
    [
      "****////////////",
      "****////////////",
      "****////////////",
      "****////////////",
      "    ////////////",
      "    ////////////",
      "    ////////////",
      "    ////////////",
      "    ////////////",
      "    ////////////",
      "    ////////////",
      "    ////////////",
      "    ////////////",
      "    ////////////",
      "    ////////////",
      "    ////////////"
    ],
    [
      "          )     ",
      "    '     )     ",
      "    ')))),))))))",
      "))))'           ",
      "    '           ",
      "    '           ",
      "    '           ",
      "    '       +   ",
      "    '   %     % ",
      "    '   &     & ",
      "    '           ",
      "    '           ",
      "    '           ",
      "    '           ",
      "    '           ",
      "    ''''''''''''"
    ],
    [
      "          )     ",
      "    '     )     ",
      "    '))))-))))))",
      "))))'           ",
      "    '           ",
      "    '           ",
      "    '           ",
      "    '           ",
      "    '           ",
      "    '           ",
      "    '           ",
      "    '           ",
      "    '           ",
      "    '           ",
      "    '           ",
      "    ''''''''''''"
    ],
    [
      "          )     ",
      "    '     )     ",
      "    ')))))))))))",
      "))))'           ",
      "    '           ",
      "    '           ",
      "    '           ",
      "    '           ",
      "    '           ",
      "    '           ",
      "    '           ",
      "    '           ",
      "    '           ",
      "    '           ",
      "    '           ",
      "    ''''''''''''"
    ],
    [
      "         (((((( ",
      "    '    (((((( ",
      "    ')))))))))))",
      "))))'           ",
      "    '           ",
      "    '           ",
      "    '           ",
      "    '           ",
      "    '           ",
      "    '           ",
      "    '           ",
      "    '           ",
      "    '           ",
      "    '           ",
      "    '           ",
      "    ''''''''''''"
    ]
  ],
  "palette": {
    "palette": [
      {
        "char": "!",
        "block": "minecraft:coarse_dirt"
      },
      {
        "char": "$",
        "block": "minecraft:gravel"
      },
      {
        "char": "%",
        "block": "minecraft:gray_bed[facing=south,occupied=false,part=foot]"
      },
      {
        "char": "&",
        "block": "minecraft:gray_bed[facing=south,occupied=false,part=head]"
      },
      {
        "char": "'",
        "block": "minecraft:light_gray_concrete"
      },
      {
        "char": "(",
        "block": "minecraft:sea_lantern"
      },
      {
        "char": ")",
        "block": "minecraft:smooth_quartz"
      },
      {
        "char": "*",
        "block": "minecraft:smooth_stone"
      },
      {
        "char": "+",
        "block": "minecraft:spawner",
        "tag": {
          "id": "minecraft:mob_spawner",
          "Delay": 200,
          "MinSpawnDelay": 240,
          "MaxSpawnDelay": 720,
          "SpawnCount": 3,
          "MaxNearbyEntities": 8,
          "RequiredPlayerRange": 14,
          "SpawnRange": 4,
          "SpawnData": {
            "entity": {
              "id": "minecraft:pillager"
            }
          },
          "SpawnPotentials": [
            {
              "weight": 1,
              "data": {
                "entity": {
                  "id": "minecraft:pillager"
                }
              }
            }
          ]
        }
      },
      {
        "char": ",",
        "block": "minecraft:spruce_door[facing=south,half=lower,hinge=left,open=false,powered=false]"
      },
      {
        "char": "-",
        "block": "minecraft:spruce_door[facing=south,half=upper,hinge=left,open=false,powered=false]"
      },
      {
        "char": ".",
        "block": "tfmg:asphalt"
      },
      {
        "char": "/",
        "block": "tfmg:factory_floor"
      }
    ]
  }
}
