{
  "xsize": 16,
  "zsize": 16,
  "slices": [
    [
      "*********       ",
      "*********       ",
      "*********       ",
      "*******&&       ",
      "*****&&%*       ",
      "***&&%***       ",
      "*&&%*****       ",
      "&%*******       ",
      "*********       ",
      "*********       ",
      "*********       ",
      "*********       ",
      "********&       ",
      "******&&%       ",
      "****&&%**       ",
      "**&&%****       "
    ],
    [
      ",,,,,,          ",
      ",,,,,,          ",
      ",,,,,,          ",
      ",,,,,,          ",
      ",,,,,,          ",
      ",,,,,,          ",
      ",,,,,,          ",
      ",,,,,,          ",
      ",,,,,,          ",
      ",,,,,,          ",
      ",,,,,,          ",
      ",,,,,,          ",
      ",,,,,,          ",
      ",,,,,,          ",
      ",,,,,,          ",
      ",,,,,,          "
    ],
    [
      "     +          ",
      "     +          ",
      "  $  +          ",
      "     +          ",
      "     +          ",
      "     +          ",
      "     +          ",
      ")))) +          ",
      ")))) +          ",
      ")))) +          ",
      ")))) +          ",
      ")))) +          ",
      ")))) +          ",
      ")))) +          ",
      "'+++++          ",
      "     +          "
    ],
    [
      "     +          ",
      "     +          ",
      "     +          ",
      "     +          ",
      "     +          ",
      "     +          ",
      "     +          ",
      ")))) +          ",
      ")))) +          ",
      ")))) +          ",
      ")))) +          ",
      ")))) +          ",
      ")))) +          ",
      ")))) +          ",
      "(+++++          ",
      "     +          "
    ],
    [
      "     +          ",
      "     +          ",
      "     +          ",
      "     +          ",
      "     +          ",
      "     +          ",
      "     +          ",
      "     +          ",
      " !!  +          ",
      " !!  +          ",
      " !!  +          ",
      " !!  +          ",
      "     +          ",
      "     +          ",
      "++++++          ",
      "     +          "
    ],
    [
      "     +          ",
      "     +          ",
      "     +          ",
      "     +          ",
      "     +          ",
      "     +          ",
      "     +          ",
      "     +          ",
      "     +          ",
      "     +          ",
      "     +          ",
      "     +          ",
      "     +          ",
      "     +          ",
      "++++++          ",
      "     +          "
    ]
  ],
  "palette": {
    "palette": [
      {
        "char": "!",
        "block": "create:framed_glass"
      },
      {
        "char": "$",
        "block": "minecraft:blast_furnace[facing=south,lit=false]"
      },
      {
        "char": "%",
        "block": "minecraft:coarse_dirt"
      },
      {
        "char": "&",
        "block": "minecraft:gravel"
      },
      {
        "char": "'",
        "block": "minecraft:spruce_door[facing=south,half=lower,hinge=left,open=false,powered=false]"
      },
      {
        "char": "(",
        "block": "minecraft:spruce_door[facing=south,half=upper,hinge=left,open=false,powered=false]"
      },
      {
        "char": ")",
        "block": "minecraft:white_concrete"
      },
      {
        "char": "*",
        "block": "tfmg:asphalt"
      },
      {
        "char": "+",
        "block": "tfmg:cinder_block"
      },
      {
        "char": ",",
        "block": "tfmg:factory_floor"
      }
    ]
  }
}
