{
  "xsize": 16,
  "zsize": 16,
  "slices": [
    [
      "0000000000000   ",
      "0000'0000'000   ",
      "0000000000000   ",
      "00000000000'0   ",
      "0000000000000   ",
      "0000000000000   ",
      "0000000000000   ",
      "0000000000000   ",
      "0000000000''    ",
      "00000000''%'    ",
      "000000''%000    ",
      "0000''%00000    ",
      "00''%0000000    ",
      "''%000000000    ",
      "%00000000000    ",
      "00000000000'    "
    ],
    [
      "                ",
      "                ",
      "                ",
      "                ",
      "  -----         ",
      "  -----         ",
      "  -----         ",
      "++-----+++      ",
      "++++++++++      ",
      "++++++++++      ",
      "++++++++++      ",
      "++++++++++      ",
      "++++++++++      ",
      "++++++++++      ",
      "++++++++++      ",
      "++++++++++      "
    ],
    [
      "                ",
      "                ",
      "                ",
      "                ",
      "                ",
      "                ",
      "                ",
      "1111)11111      ",
      "         1      ",
      "         1      ",
      "$$$$     1      ",
      "( . &&&  1      ",
      "        21      ",
      "         1      ",
      "     ,   1      ",
      "         1      "
    ],
    [
      "                ",
      "                ",
      "                ",
      "                ",
      "                ",
      "                ",
      "                ",
      "1111*11111      ",
      "         1      ",
      "         1      ",
      "   /     1      ",
      "         1      ",
      "        /1      ",
      "         1      ",
      "         1      ",
      "         1      "
    ],
    [
      "                ",
      "                ",
      "                ",
      "                ",
      "                ",
      "                ",
      "                ",
      "1!!1111!!1      ",
      "         1      ",
      "         1      ",
      "         1      ",
      "         1      ",
      "         1      ",
      "         1      ",
      "         1      ",
      "         1      "
    ],
    [
      "                ",
      "                ",
      "                ",
      "                ",
      "                ",
      "                ",
      "                ",
      "1!!1111!!1      ",
      "         1      ",
      "         1      ",
      "         1      ",
      "         1      ",
      "         1      ",
      "         1      ",
      "         1      ",
      "         1      "
    ]
  ],
  "palette": {
    "palette": [
      {
        "char": "!",
        "block": "create:framed_glass"
      },
      {
        "char": "$",
        "block": "minecraft:barrel[facing=up,open=false]"
      },
      {
        "char": "%",
        "block": "minecraft:coarse_dirt"
      },
      {
        "char": "&",
        "block": "minecraft:dark_oak_stairs[facing=south,half=bottom,shape=straight,waterlogged=false]"
      },
      {
        "char": "'",
        "block": "minecraft:gravel"
      },
      {
        "char": "(",
        "block": "kubejs:ruined_smoker[facing=north]"
      },
      {
        "char": ")",
        "block": "minecraft:spruce_door[facing=north,half=lower,hinge=left,open=false,powered=false]"
      },
      {
        "char": "*",
        "block": "minecraft:spruce_door[facing=north,half=upper,hinge=left,open=false,powered=false]"
      },
      {
        "char": "+",
        "block": "minecraft:spruce_planks"
      },
      {
        "char": ",",
        "block": "minecraft:spruce_slab[type=bottom,waterlogged=false]"
      },
      {
        "char": "-",
        "block": "minecraft:stone_bricks"
      },
      {
        "char": ".",
        "block": "kubejs:ruined_cauldron"
      },
      {
        "char": "/",
        "block": "supplementaries:item_shelf"
      },
      {
        "char": "0",
        "block": "tfmg:asphalt"
      },
      {
        "char": "1",
        "block": "the_wasteland_reworked:decayed_planks"
      },
      {
        "char": "2",
        "block": "the_wasteland_reworked:radio"
      }
    ]
  }
}
