{
  "xsize": 16,
  "zsize": 16,
  "slices": [
    [
      " ***''&*********",
      " *''&***********",
      " '&*************",
      " ***************",
      " **************'",
      " &***********''&",
      " **********''&**",
      " ********''&****",
      " ******''&******",
      " ****''&********",
      " **''&**********",
      " &'&************",
      " &**************",
      " ***************",
      " *************''",
      " ***********''&*"
    ],
    [
      "     (((((((((((",
      "                ",
      "                ",
      "     +++++++++++",
      "     +++++++++++",
      "     +++++++++++",
      "     +++++++++++",
      "     +++++++++++",
      "     +++++++++++",
      "     +++++++++++",
      "     +++++++++++",
      "     +++++++++++",
      "     +++++++++++",
      "     +++++++++++",
      "     +++++++++++",
      "     +++++++++++"
    ],
    [
      "     (((((((((((",
      "                ",
      "                ",
      "     $$$$$$$$$$$",
      "     $          ",
      "     $          ",
      "     $     )))))",
      "     $          ",
      "     $          ",
      "     $      %   ",
      "     $      %   ",
      "     $      %   ",
      "     $      %   ",
      "     $          ",
      "     $          ",
      "     $          "
    ],
    [
      "                ",
      "                ",
      "                ",
      "     $$$$$$$$$$$",
      "     $          ",
      "     $          ",
      "     $      !   ",
      "     $          ",
      "     $          ",
      "     $      %   ",
      "     $      %   ",
      "     $      %   ",
      "     $      %   ",
      "     $          ",
      "     $          ",
      "     $          "
    ],
    [
      "                ",
      "                ",
      "                ",
      "     $$$$$$$$$$$",
      "     $          ",
      "     $          ",
      "     $          ",
      "     $          ",
      "     $          ",
      "     $          ",
      "     $          ",
      "     $          ",
      "     $          ",
      "     $          ",
      "     $          ",
      "     $          "
    ],
    [
      "                ",
      "                ",
      "                ",
      "     $$$$$$$$$$$",
      "     $          ",
      "     $          ",
      "     $          ",
      "     $          ",
      "     $          ",
      "     $          ",
      "     $          ",
      "     $          ",
      "     $          ",
      "     $          ",
      "     $          ",
      "     $          "
    ]
  ],
  "palette": {
    "palette": [
      {
        "char": "!",
        "block": "create:mechanical_press"
      },
      {
        "char": "$",
        "block": "minecraft:bricks"
      },
      {
        "char": "%",
        "block": "minecraft:brown_wool"
      },
      {
        "char": "&",
        "block": "minecraft:coarse_dirt"
      },
      {
        "char": "'",
        "block": "minecraft:gravel"
      },
      {
        "char": "(",
        "block": "minecraft:smooth_stone"
      },
      {
        "char": ")",
        "block": "minecraft:smooth_stone_slab[type=bottom,waterlogged=false]"
      },
      {
        "char": "*",
        "block": "tfmg:asphalt"
      },
      {
        "char": "+",
        "block": "tfmg:factory_floor"
      }
    ]
  }
}
