{
  "xsize": 16,
  "zsize": 16,
  "slices": [
    [
      "   !!!!!!!      ",
      "   !     !      ",
      "   !     !      ",
      "   !     !      ",
      "   !    $!      ",
      "   !     !      ",
      "   !     !      ",
      "   !!!!!!!      ",
      "                ",
      "                ",
      "                ",
      "                ",
      "                ",
      "                ",
      "                ",
      "                "
    ],
    [
      "   !!!!!!!      ",
      "   !     !      ",
      "   !     !      ",
      "   !     !      ",
      "   !     !      ",
      "   !     !      ",
      "   !     !      ",
      "   !!!!!!!      ",
      "                ",
      "                ",
      "                ",
      "                ",
      "                ",
      "                ",
      "                ",
      "                "
    ],
    [
      "   %%%%%%%      ",
      "   %%%%%%%      ",
      "   %%%%%%%      ",
      "   %%%%%%%      ",
      "   %%%%%%%      ",
      "   %%%%%%%      ",
      "   %%%%%%%      ",
      "   %%%%%%%      ",
      "                ",
      "                ",
      "                ",
      "                ",
      "                ",
      "                ",
      "                ",
      "                "
    ]
  ],
  "palette": {
    "palette": [
      {
        "char": "!",
        "block": "minecraft:bricks"
      },
      {
        "char": "$",
        "block": "minecraft:ladder[facing=west,waterlogged=false]"
      },
      {
        "char": "%",
        "block": "minecraft:smooth_stone"
      }
    ]
  }
}
