{
  "xsize": 16,
  "zsize": 16,
  "slices": [
    [
      "         !      ",
      "         !      ",
      "         !      ",
      "         !      ",
      "         !      ",
      "         !      ",
      "         !      ",
      "         !      ",
      "         !      ",
      "         !      ",
      "         !      ",
      "         !      ",
      "         !      ",
      "         !      ",
      "         !      ",
      "         !      "
    ],
    [
      "         !      ",
      "         !      ",
      "         !      ",
      "         !      ",
      "         !      ",
      "         !      ",
      "         !      ",
      "         !      ",
      "         !      ",
      "         !      ",
      "         !      ",
      "         !      ",
      "         !      ",
      "         !      ",
      "         !      ",
      "         !      "
    ],
    [
      "$$$$$$$$$$$$$$$$",
      "$$$$$$$$$$$$$$$$",
      "$$$$$$$$$$$$$$$$",
      "$$$$$$$$$$$$$$$$",
      "$$$$$$$$$$$$$$$$",
      "$$$$$$$$$$$$$$$$",
      "$$$$$$$$$$$$$$$$",
      "$$$$$$$$$$$$$$$$",
      "$$$$$$$$$$$$$$$$",
      "$$$$$$$$$$$$$$$$",
      "$$$$$$$$$$$$$$$$",
      "$$$$$$$$$$$$$$$$",
      "$$$$$$$$$$$$$$$$",
      "$$$$$$$$$$$$$$$$",
      "$$$$$$$$$$$$$$$$",
      "$$$$$$$$$$$$$$$$"
    ],
    [
      "  )    (        ",
      "       (        ",
      "       (        ",
      "       (        ",
      "''''''''''''''''",
      "                ",
      "                ",
      "                ",
      "''''''''''''''''",
      "       (        ",
      "       (        ",
      "  )    (        ",
      "       %        ",
      "       (        ",
      "       (((((((((",
      "       (        "
    ],
    [
      "       (        ",
      "       (        ",
      "       (        ",
      "       (        ",
      "''''''''''''''''",
      "                ",
      "                ",
      "                ",
      "''''''''''''''''",
      "       (        ",
      "       (        ",
      "       (        ",
      "       &        ",
      "       (        ",
      "       (((((((((",
      "       (        "
    ],
    [
      "       (        ",
      "       (        ",
      "       (        ",
      "       (        ",
      "''''''''''''''''",
      "                ",
      "                ",
      "                ",
      "''''''''''''''''",
      "       (        ",
      "       (        ",
      "       (        ",
      "       (        ",
      "       (        ",
      "       (((((((((",
      "       (        "
    ]
  ],
  "palette": {
    "palette": [
      {
        "char": "!",
        "block": "minecraft:bricks"
      },
      {
        "char": "$",
        "block": "minecraft:oak_planks"
      },
      {
        "char": "%",
        "block": "minecraft:spruce_door[facing=east,half=lower,hinge=left,open=false,powered=false]"
      },
      {
        "char": "&",
        "block": "minecraft:spruce_door[facing=east,half=upper,hinge=left,open=false,powered=false]"
      },
      {
        "char": "'",
        "block": "minecraft:stripped_oak_wood"
      },
      {
        "char": "(",
        "block": "minecraft:stripped_spruce_wood"
      },
      {
        "char": ")",
        "block": "kubejs:ruined_cauldron"
      }
    ]
  }
}
