{
  "xsize": 16,
  "zsize": 16,
  "slices": [
    [
      "..........%     ",
      "........%%$     ",
      "......%%$..     ",
      "....%%$....     ",
      "..%%$......     ",
      "%%$........     ",
      "$..........     ",
      "...........     ",
      "...........     ",
      "...........     ",
      ".........%%     ",
      ".......%%$.     ",
      ".....%%$...     ",
      "...%%$.....     ",
      ".%%$.......     ",
      "%$.........     "
    ],
    [
      "&&&&&&&&&       ",
      "&&&&&&&&&       ",
      "&&&&&&&&&       ",
      "&&&&&&&&&       ",
      "&&&&&&&&&       ",
      "&&&&&&&&&       ",
      "&&&&&&&&&       ",
      "&&&&&&&&&       ",
      "&&&&&&&&&       ",
      "&&&&&&&&&       ",
      "&&&&&&&&&       ",
      "&&&&&&&&&       ",
      "&&&&&&&&&       ",
      "&&&&&&&&&       ",
      "&&&&&&&&&       ",
      "&&&&&&&&&       "
    ],
    [
      "  / 0000/       ",
      "  /     /       ",
      "  /     /       ",
      "  (     /       ",
      "  / , ' /       ",
      "  /     /       ",
      "  /     /       ",
      "/////*///       ",
      "  /     /       ",
      "  /     /       ",
      "  /     /       ",
      "  /     /       ",
      "  /     /       ",
      "  /     /       ",
      "  /     /       ",
      "  /     /       "
    ],
    [
      "  /   - /       ",
      "  /     !       ",
      "  /     !       ",
      "  )     /       ",
      "  /     /       ",
      "  /     /       ",
      "  /     /       ",
      "/////+///       ",
      "  /     /       ",
      "  /     !       ",
      "  /     !       ",
      "  /     /       ",
      "  /     /       ",
      "  /     /       ",
      "  /     /       ",
      "  /     /       "
    ],
    [
      "  /     /       ",
      "  /     !       ",
      "  /     !       ",
      "  /     /       ",
      "  /     /       ",
      "  /     /       ",
      "  /     /       ",
      "/////////       ",
      "  /     /       ",
      "  /     !       ",
      "  /     !       ",
      "  /     /       ",
      "  /     /       ",
      "  /     /       ",
      "  /     /       ",
      "  /     /       "
    ],
    [
      "  /     /       ",
      "  /     /       ",
      "  /     /       ",
      "  /     /       ",
      "  /     /       ",
      "  /     /       ",
      "  /     /       ",
      "/////////       ",
      "  /     /       ",
      "  /     /       ",
      "  /     /       ",
      "  /     /       ",
      "  /     /       ",
      "  /     /       ",
      "  /     /       ",
      "  /     /       "
    ]
  ],
  "palette": {
    "palette": [
      {
        "char": "!",
        "block": "create:framed_glass"
      },
      {
        "char": "$",
        "block": "minecraft:coarse_dirt"
      },
      {
        "char": "%",
        "block": "minecraft:gravel"
      },
      {
        "char": "&",
        "block": "minecraft:polished_andesite"
      },
      {
        "char": "'",
        "block": "minecraft:quartz_stairs[facing=west,half=bottom,shape=straight,waterlogged=false]"
      },
      {
        "char": "(",
        "block": "minecraft:spruce_door[facing=east,half=lower,hinge=left,open=false,powered=false]"
      },
      {
        "char": ")",
        "block": "minecraft:spruce_door[facing=east,half=upper,hinge=left,open=false,powered=false]"
      },
      {
        "char": "*",
        "block": "minecraft:spruce_door[facing=south,half=lower,hinge=left,open=false,powered=false]"
      },
      {
        "char": "+",
        "block": "minecraft:spruce_door[facing=south,half=upper,hinge=left,open=false,powered=false]"
      },
      {
        "char": ",",
        "block": "minecraft:water_cauldron[level=1]"
      },
      {
        "char": "-",
        "block": "supplementaries:item_shelf"
      },
      {
        "char": ".",
        "block": "tfmg:asphalt"
      },
      {
        "char": "/",
        "block": "tfmg:cinder_block"
      },
      {
        "char": "0",
        "block": "zvhouses:spruce_countertop"
      }
    ]
  }
}
