{
  "xsize": 16,
  "zsize": 16,
  "slices": [
    [
      "                ",
      "                ",
      "                ",
      "                ",
      "                ",
      "                ",
      "           &    ",
      "%%%%!!%%%%%&    ",
      "           &    ",
      "           %    ",
      "           %    ",
      "           %    ",
      "           %    ",
      "           %    ",
      "           %    ",
      "           %    "
    ],
    [
      "                ",
      "                ",
      "                ",
      "                ",
      "                ",
      "                ",
      "           &    ",
      "%%%%%%%%%%%&    ",
      "           &    ",
      "           %    ",
      "           %    ",
      "           %    ",
      "           %    ",
      "           %    ",
      "           %    ",
      "           %    "
    ],
    [
      "                ",
      "                ",
      "                ",
      "                ",
      "                ",
      "                ",
      "           &    ",
      "%%%%%%%%%%%&    ",
      "           &    ",
      "           %    ",
      "           %    ",
      "           %    ",
      "           %    ",
      "           %    ",
      "           %    ",
      "           %    "
    ],
    [
      "                ",
      "                ",
      "                ",
      "                ",
      "                ",
      "                ",
      "           &    ",
      "%%%%%%%%%%%&    ",
      "           &    ",
      "           %    ",
      "           %    ",
      "           %    ",
      "           %    ",
      "           %    ",
      "           %    ",
      "           %    "
    ],
    [
      "                ",
      "                ",
      "                ",
      "                ",
      "                ",
      "                ",
      "           &    ",
      "%%%%%%%%%%%&    ",
      ")))))))))))&    ",
      ")))))))))))%    ",
      ")))))))))))%    ",
      ")))))))))))%    ",
      ")))))))))))%    ",
      ")))))))))))%    ",
      ")))))))))))%    ",
      ")))))))))))%    "
    ],
    [
      "                ",
      "                ",
      "                ",
      "                ",
      "                ",
      "                ",
      "           &    ",
      "%%%%%%%%%%%&    ",
      "           &    ",
      "           %    ",
      " ''     $  %    ",
      " (         %    ",
      "           %    ",
      "           %    ",
      "  (  (  (  %    ",
      "  '  '  '  %    "
    ]
  ],
  "palette": {
    "palette": [
      {
        "char": "!",
        "block": "create:framed_glass"
      },
      {
        "char": "$",
        "block": "minecraft:bookshelf"
      },
      {
        "char": "%",
        "block": "minecraft:bricks"
      },
      {
        "char": "&",
        "block": "minecraft:mud_bricks"
      },
      {
        "char": "'",
        "block": "minecraft:spruce_slab[type=bottom,waterlogged=false]"
      },
      {
        "char": "(",
        "block": "minecraft:spruce_stairs[facing=north,half=bottom,shape=straight,waterlogged=false]"
      },
      {
        "char": ")",
        "block": "tfmg:factory_floor"
      }
    ]
  }
}
