{
  "xsize": 16,
  "zsize": 16,
  "slices": [
    [
      "7777777777))(777",
      "77777777))(77777",
      "777777))(7777777",
      "7777))(777777777",
      "77))(77777777777",
      "))(7777777777777",
      "(777777777777777",
      "777777777777777)",
      "7777777777777))(",
      "77777777777))(77",
      "777777777))(7777",
      "7777777))(777777",
      "77777))(77777777",
      "777))(7777777777",
      "7))(777777777777",
      ")(77777777777777"
    ],
    [
      "3333333399999999",
      "3333333399999999",
      "3333333399999999",
      "////////99999999",
      "////////99999999",
      "////////99999999",
      "////////99999999",
      "////////99999999",
      "////////99999999",
      "////////99999999",
      "////////99999999",
      "////////99999999",
      "////////19999999",
      "7777777719999999",
      "7777777719999999",
      "7777777719999999"
    ],
    [
      "        8       ",
      "        8       ",
      "        8       ",
      "..5.....8  &&&& ",
      "  0     8  &&&& ",
      "        8  &&&& ",
      "        *  &&&& ",
      "    42  +  &&&& ",
      "        8  &&&& ",
      "%%% $$$ 8  &&&& ",
      "%%% $$' 8       ",
      "        8       ",
      "........1       ",
      "        1       ",
      "        18885888",
      "        1       "
    ],
    [
      "        8       ",
      "        8       ",
      "        8       ",
      "..6.....8  &&&& ",
      "        8  &&&& ",
      "  0     8  &&&& ",
      "        ,  &&&& ",
      "        -  &&&& ",
      "        8  &&&& ",
      "%%% $$$ 8  &&&& ",
      "%%% $$$ 8       ",
      "        8       ",
      "........1       ",
      "        1       ",
      "        18886888",
      "        1       "
    ],
    [
      "        8       ",
      "        8       ",
      "        8       ",
      "........8       ",
      "        8   !!  ",
      "        8   !!  ",
      "  0         !!  ",
      "            !!  ",
      "        8       ",
      "%%% $$$ 8       ",
      "%%% $$$ 8       ",
      "        8       ",
      "........1       ",
      "        1       ",
      "        18888888",
      "        1       "
    ],
    [
      "        8       ",
      "        8       ",
      "        8       ",
      "........8       ",
      "        8       ",
      "        8       ",
      "        8       ",
      "  0     8       ",
      "        8       ",
      "%%%     8       ",
      "%%%     8       ",
      "        8       ",
      "........8       ",
      "        8       ",
      "        88888888",
      "        8       "
    ]
  ],
  "palette": {
    "palette": [
      {
        "char": "!",
        "block": "create:framed_glass"
      },
      {
        "char": "$",
        "block": "immersiveengineering:crate"
      },
      {
        "char": "%",
        "block": "immersiveengineering:sheetmetal_steel"
      },
      {
        "char": "&",
        "block": "minecraft:blue_concrete"
      },
      {
        "char": "'",
        "block": "minecraft:chest[facing=west,type=single,waterlogged=false]",
        "tag": {
          "id": "minecraft:chest",
          "LootTable": "infinite_domain:chests/wasteland_military"
        }
      },
      {
        "char": "(",
        "block": "minecraft:coarse_dirt"
      },
      {
        "char": ")",
        "block": "minecraft:gravel"
      },
      {
        "char": "*",
        "block": "minecraft:iron_door[facing=east,half=lower,hinge=left,open=false,powered=false]"
      },
      {
        "char": "+",
        "block": "minecraft:iron_door[facing=east,half=lower,hinge=right,open=false,powered=false]"
      },
      {
        "char": ",",
        "block": "minecraft:iron_door[facing=east,half=upper,hinge=left,open=false,powered=false]"
      },
      {
        "char": "-",
        "block": "minecraft:iron_door[facing=east,half=upper,hinge=right,open=false,powered=false]"
      },
      {
        "char": ".",
        "block": "minecraft:light_gray_concrete"
      },
      {
        "char": "/",
        "block": "minecraft:polished_andesite"
      },
      {
        "char": "0",
        "block": "minecraft:polished_andesite_stairs[facing=south,half=bottom,shape=straight,waterlogged=false]"
      },
      {
        "char": "1",
        "block": "minecraft:polished_deepslate"
      },
      {
        "char": "2",
        "block": "minecraft:smithing_table"
      },
      {
        "char": "3",
        "block": "minecraft:smooth_stone"
      },
      {
        "char": "4",
        "block": "minecraft:spawner",
        "tag": {
          "id": "minecraft:mob_spawner",
          "Delay": 200,
          "MinSpawnDelay": 240,
          "MaxSpawnDelay": 720,
          "SpawnCount": 2,
          "MaxNearbyEntities": 8,
          "RequiredPlayerRange": 14,
          "SpawnRange": 4,
          "SpawnData": {
            "entity": {
              "id": "minecraft:pillager"
            }
          },
          "SpawnPotentials": [
            {
              "weight": 1,
              "data": {
                "entity": {
                  "id": "minecraft:pillager"
                }
              }
            }
          ]
        }
      },
      {
        "char": "5",
        "block": "minecraft:spruce_door[facing=south,half=lower,hinge=left,open=false,powered=false]"
      },
      {
        "char": "6",
        "block": "minecraft:spruce_door[facing=south,half=upper,hinge=left,open=false,powered=false]"
      },
      {
        "char": "7",
        "block": "tfmg:asphalt"
      },
      {
        "char": "8",
        "block": "tfmg:cinder_block"
      },
      {
        "char": "9",
        "block": "tfmg:factory_floor"
      }
    ]
  }
}
