{
  "xsize": 16,
  "zsize": 16,
  "slices": [
    [
      "))))))))))&&$)))",
      "))))))))&&))))))",
      "))))))&&$)))))))",
      "))))&&$)))))))))",
      "))&&$)))))))))))",
      "&&$)))))))))))))",
      "$)))))))))))))))",
      ")))))))))))))))&",
      "))))))))))))))))",
      "))))))))))))))))",
      ")))))))))&))))))",
      ")))))))&&$))))))",
      ")))))&&$))))))))",
      ")))&&$))))))))))",
      ")&&$))))))))))))",
      "&$))))))))))))))"
    ],
    [
      "*********       ",
      "********* ((((((",
      "********* '     ",
      "*********       ",
      "*********       ",
      "*********       ",
      "*********       ",
      "*********       ",
      "********* ((((((",
      "********* '     ",
      "*********       ",
      "*********       ",
      "*********       ",
      "*********       ",
      "*********       ",
      "********* (((((("
    ],
    [
      "        !       ",
      "        !       ",
      "        ! '     ",
      "        !       ",
      "        !       ",
      "%       !       ",
      "        !       ",
      "        !       ",
      "        !       ",
      "        ! '     ",
      "        !       ",
      "%       !       ",
      "        !       ",
      "        !       ",
      "        !       ",
      "        !       "
    ],
    [
      "        !       ",
      "        !       ",
      "        ! '     ",
      "        !       ",
      "        !       ",
      "        !       ",
      "        !       ",
      "        !       ",
      "        !       ",
      "        ! '     ",
      "        !       ",
      "        !       ",
      "        !       ",
      "        !       ",
      "        !       ",
      "        !       "
    ],
    [
      "        !       ",
      "        !       ",
      "        ! '     ",
      "        !       ",
      "        !       ",
      "        !       ",
      "        !       ",
      "        !       ",
      "        !       ",
      "        ! '     ",
      "        !       ",
      "        !       ",
      "        !       ",
      "        !       ",
      "        !       ",
      "        !       "
    ],
    [
      "        !       ",
      "        !       ",
      "        ! '     ",
      "        !       ",
      "        !       ",
      "        !       ",
      "        !       ",
      "        !       ",
      "        !       ",
      "        ! '     ",
      "        !       ",
      "        !       ",
      "        !       ",
      "        !       ",
      "        !       ",
      "        !       "
    ]
  ],
  "palette": {
    "palette": [
      {
        "char": "!",
        "block": "minecraft:bricks"
      },
      {
        "char": "$",
        "block": "minecraft:coarse_dirt"
      },
      {
        "char": "%",
        "block": "minecraft:dark_oak_stairs[facing=south,half=bottom,shape=straight,waterlogged=false]"
      },
      {
        "char": "&",
        "block": "minecraft:gravel"
      },
      {
        "char": "'",
        "block": "minecraft:polished_blackstone_bricks"
      },
      {
        "char": "(",
        "block": "minecraft:white_concrete"
      },
      {
        "char": ")",
        "block": "tfmg:asphalt"
      },
      {
        "char": "*",
        "block": "tfmg:factory_floor"
      }
    ]
  }
}
