{
  "xsize": 16,
  "zsize": 16,
  "slices": [
    [
      "0000''''''''''''",
      "0000''''''''''''",
      "0000''''''''''''",
      "0000''''''''''''",
      "00%%''''''''''''",
      "%%$0''''''''''''",
      "$000''''''''''''",
      "0000''''''''''''",
      "0000''''''''''''",
      "0000''''''''''''",
      "0000''''''''''''",
      "0000''''''''''''",
      "0000''''''''''''",
      "000%''''''''''''",
      "0%%$''''''''''''",
      "%$00''''''''''''"
    ],
    [
      "     &&&&&&&&&&&",
      "     &&&&&&&&&&&",
      "     &&&&&&&&&&&",
      "     &&&&&&&&&&&",
      "     &&&&&&&&&&&",
      "     &&&&&&&&&&&",
      "     &&&&&&&&&&&",
      "     &&&&&&&&&&&",
      "     &&&&&&&&&&&",
      "     &&&&&&&&&&&",
      "     &&&&&&&&&&&",
      "     &&&&&&&&&&&",
      "     &&&&&&&&&&&",
      "     &&&&&&&&&&&",
      "     &&&&&&&&&&&",
      "     &&&&&&&&&&&"
    ],
    [
      "     /  .    /  ",
      "     /       (  ",
      "     /       /  ",
      "     /       /  ",
      "     ////*////  ",
      "     /       /  ",
      "     /       /  ",
      "     /  - ,  /  ",
      "     /  .    (  ",
      "     /       /  ",
      "     /       /  ",
      "     ////*////  ",
      "     /       /  ",
      "     /       /  ",
      "     /  - ,  (  ",
      "     /  .    /  "
    ],
    [
      "     !       /  ",
      "     /       )  ",
      "     /       /  ",
      "     /       /  ",
      "     ////+////  ",
      "     /       /  ",
      "     /       /  ",
      "     !       /  ",
      "     !       )  ",
      "     /       /  ",
      "     /       /  ",
      "     ////+////  ",
      "     /       /  ",
      "     /       /  ",
      "     !       )  ",
      "     !       /  "
    ],
    [
      "     !       /  ",
      "     /       /  ",
      "     /       /  ",
      "     /       /  ",
      "     /////////  ",
      "     /       /  ",
      "     /       /  ",
      "     !       /  ",
      "     !       /  ",
      "     /       /  ",
      "     /       /  ",
      "     /////////  ",
      "     /       /  ",
      "     /       /  ",
      "     !       /  ",
      "     !       /  "
    ],
    [
      "     /       /  ",
      "     /       /  ",
      "     /       /  ",
      "     /       /  ",
      "     /////////  ",
      "     /       /  ",
      "     /       /  ",
      "     /       /  ",
      "     /       /  ",
      "     /       /  ",
      "     /       /  ",
      "     /////////  ",
      "     /       /  ",
      "     /       /  ",
      "     /       /  ",
      "     /       /  "
    ]
  ],
  "palette": {
    "palette": [
      {
        "char": "!",
        "block": "create:framed_glass"
      },
      {
        "char": "$",
        "block": "minecraft:coarse_dirt"
      },
      {
        "char": "%",
        "block": "minecraft:gravel"
      },
      {
        "char": "&",
        "block": "minecraft:polished_andesite"
      },
      {
        "char": "'",
        "block": "minecraft:smooth_stone"
      },
      {
        "char": "(",
        "block": "minecraft:spruce_door[facing=east,half=lower,hinge=left,open=false,powered=false]"
      },
      {
        "char": ")",
        "block": "minecraft:spruce_door[facing=east,half=upper,hinge=left,open=false,powered=false]"
      },
      {
        "char": "*",
        "block": "minecraft:spruce_door[facing=south,half=lower,hinge=left,open=false,powered=false]"
      },
      {
        "char": "+",
        "block": "minecraft:spruce_door[facing=south,half=upper,hinge=left,open=false,powered=false]"
      },
      {
        "char": ",",
        "block": "kubejs:ruined_cauldron"
      },
      {
        "char": "-",
        "block": "minecraft:white_bed[facing=south,occupied=false,part=foot]"
      },
      {
        "char": ".",
        "block": "minecraft:white_bed[facing=south,occupied=false,part=head]"
      },
      {
        "char": "/",
        "block": "minecraft:white_concrete"
      },
      {
        "char": "0",
        "block": "tfmg:asphalt"
      }
    ]
  }
}
