{
  "xsize": 16,
  "zsize": 16,
  "slices": [
    [
      "   ***********  ",
      "&&****&****&****",
      "****************",
      "**************&&",
      "**************%*",
      "****************",
      "****************",
      "****************",
      "****************",
      "**&*************",
      "&&%*************",
      "%***************",
      "***************&",
      "**************&%",
      "****************",
      "****************"
    ],
    [
      "                ",
      "                ",
      "  (           ( ",
      "                ",
      "                ",
      ",,              ",
      ",,              ",
      ",,              ",
      ",,              ",
      ",,              ",
      ",,              ",
      ",,              ",
      ",,  )))))))))   ",
      ",,  )))))))))   ",
      ",,  )))))))))   ",
      ",,  )))))))))   "
    ],
    [
      "                ",
      "                ",
      "''(           ('",
      "                ",
      "                ",
      "$$              ",
      " $              ",
      " $              ",
      " $              ",
      " $              ",
      " $              ",
      "+$              ",
      " $              ",
      " $              ",
      " $              ",
      " $              "
    ],
    [
      "                ",
      "                ",
      "  (           ( ",
      "                ",
      "                ",
      "!$              ",
      " $              ",
      " $              ",
      " $              ",
      " $              ",
      " $              ",
      "+$              ",
      " !              ",
      " !              ",
      " $              ",
      " $              "
    ],
    [
      "                ",
      "                ",
      "  (           ( ",
      "                ",
      "                ",
      "!$              ",
      " $              ",
      " $              ",
      " $              ",
      " $              ",
      " $              ",
      "+$              ",
      " !              ",
      " !              ",
      " $              ",
      " $              "
    ],
    [
      "                ",
      "                ",
      "  (           ( ",
      "                ",
      "                ",
      "$$              ",
      " $              ",
      " $              ",
      " $              ",
      " $              ",
      " $              ",
      "+$              ",
      " $              ",
      " $              ",
      " $              ",
      " $              "
    ]
  ],
  "palette": {
    "palette": [
      {
        "char": "!",
        "block": "create:framed_glass"
      },
      {
        "char": "$",
        "block": "minecraft:bricks"
      },
      {
        "char": "%",
        "block": "minecraft:coarse_dirt"
      },
      {
        "char": "&",
        "block": "minecraft:gravel"
      },
      {
        "char": "'",
        "block": "minecraft:oxidized_copper_grate"
      },
      {
        "char": "(",
        "block": "minecraft:polished_blackstone_bricks"
      },
      {
        "char": ")",
        "block": "minecraft:smooth_stone"
      },
      {
        "char": "*",
        "block": "tfmg:asphalt"
      },
      {
        "char": "+",
        "block": "tfmg:cinder_block"
      },
      {
        "char": ",",
        "block": "tfmg:factory_floor"
      }
    ]
  }
}
