{
  "xsize": 16,
  "zsize": 16,
  "slices": [
    [
      " '''%%$'''''''''",
      " '%%$'''''''''''",
      " %$'''''''''''''",
      " '''''''''''''''",
      " ''''''''''''''%",
      " $'''''''''''%%$",
      " ''''''''''%%$''",
      " ''''''''%%$''''",
      " ''''''%%$''''''",
      " ''''%%$''''''''",
      " ''%%$''''''''''",
      " $%$''''''''''''",
      " $''''''''''''''",
      " '''''''''''''''",
      " '''''''''''''%%",
      " '''''''''''%%$'"
    ],
    [
      "     )))))))))))",
      "     )))))))))))",
      "                ",
      "                ",
      "                ",
      "                ",
      "                ",
      "      ++++      ",
      "      ++++      ",
      "      ++++  ++++",
      "      ++++  ++++",
      "            ++++",
      "            ++++",
      "                ",
      "                ",
      "                "
    ],
    [
      "  &  !     (    ",
      "  &  !!!!!!!!!!!",
      "  &             ",
      "  &             ",
      "  &             ",
      "  &             ",
      "  &             ",
      "  &   ++++      ",
      "  &   ++++      ",
      "  &   ++++  ++++",
      "  &   ++++  ++++",
      "  &         ++++",
      "  &         ++++",
      "  &             ",
      "  &             ",
      "  &             "
    ],
    [
      "     !     (    ",
      "     !!!!!!!!!!!",
      "                ",
      "                ",
      "                ",
      "                ",
      "                ",
      "      ++++      ",
      "      +*++      ",
      "      ++++  ++++",
      "      ++++  +*++",
      "            ++++",
      "            ++++",
      "                ",
      "                ",
      "                "
    ],
    [
      "     !     (    ",
      "     !!!!!!!!!!!",
      "                ",
      "                ",
      "                ",
      "                ",
      "                ",
      "      ++++      ",
      "      ++++      ",
      "      ++++      ",
      "      ++++      ",
      "                ",
      "                ",
      "                ",
      "                ",
      "                "
    ],
    [
      "     !     (    ",
      "     !!!!!!!!!!!",
      "                ",
      "                ",
      "                ",
      "                ",
      "                ",
      "                ",
      "                ",
      "                ",
      "                ",
      "                ",
      "                ",
      "                ",
      "                ",
      "                "
    ]
  ],
  "palette": {
    "palette": [
      {
        "char": "!",
        "block": "minecraft:bricks"
      },
      {
        "char": "$",
        "block": "minecraft:coarse_dirt"
      },
      {
        "char": "%",
        "block": "minecraft:gravel"
      },
      {
        "char": "&",
        "block": "minecraft:oxidized_copper_grate"
      },
      {
        "char": "'",
        "block": "tfmg:asphalt"
      },
      {
        "char": "(",
        "block": "tfmg:cinder_block"
      },
      {
        "char": ")",
        "block": "tfmg:factory_floor"
      },
      {
        "char": "*",
        "block": "the_wasteland_reworked:rusted_barrel"
      },
      {
        "char": "+",
        "block": "wastelands:scrap_pile"
      }
    ]
  }
}
