{
  "xsize": 16,
  "zsize": 16,
  "slices": [
    [
      "))))))))))''&)))",
      "))))))))''&)))))",
      "))))))''&)))))))",
      "))))''&)))))))))",
      "))''&)))))))))))",
      "''&))))))))))))'",
      "&)))))))))))))))",
      ")))))))))))))))'",
      ")))))))))))))''&",
      ")))))))))))''&))",
      ")))))))))''&))))",
      ")))))))''&)))))'",
      ")))))''&))))))))",
      ")))''&))))))))))",
      ")''&))))))))))))",
      "'&))))))))))))))"
    ],
    [
      "                ",
      "$$$$$$$$$$$$$   ",
      "$$$$$$$$$$$$$   ",
      "$$$$$$$$$$$$$   ",
      "$$$$$$$$$$$$$   ",
      "$$$$$$$$$$$$$   ",
      "$$$$$$$$$$$$$   ",
      "$$$$$$$$$$$$$   ",
      "$$$$$$$$$$$$$   ",
      "                ",
      "                ",
      "   ++++         ",
      "   ++++         ",
      "   ++++         ",
      "   ++++         ",
      "         ++++   "
    ],
    [
      "              ( ",
      "$$$$$$$$$$$$$ ( ",
      "$$$$$$$$$$$$$ ( ",
      "$$$$$$$$$$$$$ ( ",
      "$$$$$$$$$$$$$ ( ",
      "$$$$$$$$$$$$$ ( ",
      "$$$$$$$$$$$$$ ( ",
      "$$$$$$$$$$$$$ ( ",
      "$$$$$$$$$$$$$ ( ",
      "              ( ",
      "              ( ",
      "   ++++       ( ",
      "   ++++       ( ",
      "   ++++       ( ",
      "   ++++       ( ",
      "         ++++ ( "
    ],
    [
      "                ",
      "                ",
      "    !           ",
      "  %%%%%%%%      ",
      "  %%%%%%%%      ",
      "  %%%%%%%%      ",
      "  %%%%%%%%      ",
      "                ",
      "                ",
      "                ",
      "                ",
      "   ++++         ",
      "   +*++         ",
      "   ++++         ",
      "   ++++         ",
      "                "
    ],
    [
      "                ",
      "                ",
      "                ",
      "  %%%%%%%%      ",
      "  %%%%%%%%      ",
      "  %%%%%%%%      ",
      "  %%%%%%%%      ",
      "                ",
      "                ",
      "                ",
      "                ",
      "   ++++         ",
      "   ++++         ",
      "   ++++         ",
      "   ++++         ",
      "                "
    ],
    [
      "                ",
      "                ",
      "                ",
      "  %%%%%%%%      ",
      "  %%%%%%%%      ",
      "  %%%%%%%%      ",
      "  %%%%%%%%      ",
      "                ",
      "                ",
      "                ",
      "                ",
      "                ",
      "                ",
      "                ",
      "                ",
      "                "
    ]
  ],
  "palette": {
    "palette": [
      {
        "char": "!",
        "block": "create:mechanical_press"
      },
      {
        "char": "$",
        "block": "immersiveengineering:concrete_reinforced"
      },
      {
        "char": "%",
        "block": "immersiveengineering:sheetmetal_steel"
      },
      {
        "char": "&",
        "block": "minecraft:coarse_dirt"
      },
      {
        "char": "'",
        "block": "minecraft:gravel"
      },
      {
        "char": "(",
        "block": "minecraft:oxidized_copper_grate"
      },
      {
        "char": ")",
        "block": "tfmg:asphalt"
      },
      {
        "char": "*",
        "block": "the_wasteland_reworked:rusted_barrel"
      },
      {
        "char": "+",
        "block": "wastelands:scrap_pile"
      }
    ]
  }
}
