{
  "xsize": 16,
  "zsize": 16,
  "slices": [
    [
      "))))))))))))))))",
      ")%))))%))))%))))",
      "))))))))))))))))",
      "))))))))))))))))",
      "))))))))))))))))",
      "))))))))))))))))",
      "))))))))))))))))",
      "))))))))))))))))",
      "))))%%$)))))))))",
      "))%%$)))))))))))",
      "%%$)))))))))))))",
      "$)))))))))))))))",
      ")))))))))))))))%",
      ")))))))))))))%%$",
      ")))))))))))%%$))",
      ")))))))))%%$))))"
    ],
    [
      "                ",
      "                ",
      "                ",
      "                ",
      "                ",
      "                ",
      "                ",
      "+++++++++%%%%%%%",
      "+++++++++%%%%%%%",
      "+++++++++%%%%%%%",
      "''''''++'%%%%%%%",
      "''''''++'%%%%%%%",
      "''''''++'%%%%%%%",
      "'&&&''++'%%%%%%%",
      "'&&&''++'%%%%%%%",
      "'&&&''++'%%%%%%%"
    ],
    [
      "                ",
      "                ",
      "                ",
      "                ",
      "                ",
      "                ",
      "                ",
      "      ** %%%%%%%",
      "         %%%%%%%",
      "         %%%%%%%",
      "         %%%%%%%",
      "         %%%%%%%",
      "         %%%%%%%",
      " ( (     %%%%%%%",
      " ( (     %%%%%%%",
      " ( (     %%%%%%%"
    ],
    [
      "                ",
      "                ",
      "                ",
      "                ",
      "                ",
      "                ",
      "                ",
      "      ** %%%%%%%",
      "         %%%%%%%",
      "         %%%%%%%",
      "         %%%%%%%",
      "         %%%%%%%",
      "         %%%%%%%",
      " ( (     %%%%%%%",
      " ( (     %%%%%%%",
      " ( (     %%%%%%%"
    ],
    [
      "                ",
      "                ",
      "                ",
      "                ",
      "                ",
      "                ",
      "                ",
      "      ** %%%%%%%",
      "         %%%%%%%",
      "         %%%%%%%",
      "         %%%%%%%",
      "         %%%%%%%",
      "         %%%%%%%",
      "         %%%%%%%",
      "         %%%%%%%",
      "         %%%%%%%"
    ],
    [
      "                ",
      "                ",
      "                ",
      "                ",
      "                ",
      "                ",
      "                ",
      "      **       *",
      "               !",
      "               !",
      "               !",
      "               !",
      "               !",
      "               !",
      "               !",
      "               !"
    ]
  ],
  "palette": {
    "palette": [
      {
        "char": "!",
        "block": "minecraft:bricks"
      },
      {
        "char": "$",
        "block": "minecraft:coarse_dirt"
      },
      {
        "char": "%",
        "block": "minecraft:gravel"
      },
      {
        "char": "&",
        "block": "minecraft:polished_blackstone"
      },
      {
        "char": "'",
        "block": "minecraft:smooth_stone"
      },
      {
        "char": "(",
        "block": "minecraft:yellow_concrete"
      },
      {
        "char": ")",
        "block": "tfmg:asphalt"
      },
      {
        "char": "*",
        "block": "tfmg:cinder_block"
      },
      {
        "char": "+",
        "block": "tfmg:factory_floor"
      }
    ]
  }
}
