{
  "xsize": 16,
  "zsize": 16,
  "slices": [
    [
      "!!!!!!          ",
      "                ",
      "                ",
      "                ",
      "$$$$$$          ",
      "$$$$$$          ",
      "$$$$$$          ",
      "$$$$$$          ",
      "$$$$$$          ",
      "$$$$$$          ",
      "                ",
      "                ",
      "                ",
      "                ",
      "                ",
      "                "
    ],
    [
      "!!!!!!          ",
      "                ",
      "                ",
      "                ",
      "$$$$$$          ",
      "$$$$$$          ",
      "$$$$$$          ",
      "$$$$$$          ",
      "$$$$$$          ",
      "$$$$$$          ",
      "                ",
      "                ",
      "                ",
      "                ",
      "                ",
      "                "
    ],
    [
      "%%%%%%%         ",
      "%%%%%%%         ",
      "                ",
      "                ",
      "$$$$$$          ",
      "$$$$$$          ",
      "$$$$$$          ",
      "$$$$$$          ",
      "$$$$$$          ",
      "$$$$$$          ",
      "                ",
      "                ",
      "                ",
      "                ",
      "                ",
      "                "
    ]
  ],
  "palette": {
    "palette": [
      {
        "char": "!",
        "block": "create:framed_glass"
      },
      {
        "char": "$",
        "block": "immersiveengineering:sheetmetal_steel"
      },
      {
        "char": "%",
        "block": "minecraft:smooth_stone_slab[type=bottom,waterlogged=false]"
      }
    ]
  }
}
