{
  "xsize": 16,
  "zsize": 16,
  "slices": [
    [
      ".......''&......",
      ".....''&........",
      "...''&..........",
      ".''&............",
      "'&..............",
      "................",
      "..............''",
      "............''&.",
      "..........''&...",
      "........''&.....",
      "......''&.......",
      "....''&.........",
      "..''&...........",
      "''&.............",
      "&...............",
      ".&....&....&...'"
    ],
    [
      "+***++00+'''''''",
      "+***++00+'''''''",
      "+***++00++***++0",
      "+***++00++***++0",
      "+***++00++***++0",
      "+***++00++***++0",
      "++++++00+++++++0",
      "++++++00+++++++0",
      "++++++00+++++++0",
      "0000000000000000",
      "0000000000000000",
      "0000000000000000",
      "0000000000000000",
      "0000000000000000",
      "                ",
      "                "
    ],
    [
      " - -     '''''''",
      " - -     '''''''",
      " - -      - -  %",
      " - -      - -  %",
      " - -      - -  %",
      " - -      - -  %",
      "               %",
      "!   $ 1  !   $ %",
      "               %",
      " ,             (",
      "               %",
      "               %",
      "               %",
      "////////////////",
      "                ",
      "                "
    ],
    [
      " - -     '''''''",
      " - -     '''''''",
      " - -      - -  %",
      " - -      - -  %",
      " - -      - -  %",
      " - -      - -  %",
      "               %",
      "               %",
      "               %",
      "               )",
      "               %",
      "               %",
      "               %",
      "////////////////",
      "                ",
      "                "
    ],
    [
      "         '''''''",
      "         '''''''",
      "               %",
      "               %",
      "               %",
      "               %",
      "               %",
      "               %",
      "               %",
      "               %",
      "               %",
      "               %",
      "               %",
      "////////////////",
      "                ",
      "                "
    ],
    [
      "               %",
      "               %",
      "           /   %",
      "               %",
      "               %",
      "               %",
      "               %",
      "               %",
      "               %",
      "               %",
      "               %",
      "               %",
      "               %",
      "////////////////",
      "                ",
      "                "
    ]
  ],
  "palette": {
    "palette": [
      {
        "char": "!",
        "block": "immersiveengineering:metal_barrel"
      },
      {
        "char": "$",
        "block": "minecraft:anvil"
      },
      {
        "char": "%",
        "block": "minecraft:bricks"
      },
      {
        "char": "&",
        "block": "minecraft:coarse_dirt"
      },
      {
        "char": "'",
        "block": "minecraft:gravel"
      },
      {
        "char": "(",
        "block": "minecraft:iron_door[facing=west,half=lower,hinge=left,open=false,powered=false]"
      },
      {
        "char": ")",
        "block": "minecraft:iron_door[facing=west,half=upper,hinge=left,open=false,powered=false]"
      },
      {
        "char": "*",
        "block": "minecraft:polished_blackstone"
      },
      {
        "char": "+",
        "block": "minecraft:smooth_stone"
      },
      {
        "char": ",",
        "block": "minecraft:spawner",
        "tag": {
          "id": "minecraft:mob_spawner",
          "Delay": 200,
          "MinSpawnDelay": 240,
          "MaxSpawnDelay": 720,
          "SpawnCount": 2,
          "MaxNearbyEntities": 5,
          "RequiredPlayerRange": 14,
          "SpawnRange": 4,
          "SpawnData": {
            "entity": {
              "id": "the_wasteland_reworked:ghoul"
            }
          },
          "SpawnPotentials": [
            {
              "weight": 1,
              "data": {
                "entity": {
                  "id": "the_wasteland_reworked:ghoul"
                }
              }
            }
          ]
        }
      },
      {
        "char": "-",
        "block": "minecraft:yellow_concrete"
      },
      {
        "char": ".",
        "block": "tfmg:asphalt"
      },
      {
        "char": "/",
        "block": "tfmg:cinder_block"
      },
      {
        "char": "0",
        "block": "tfmg:factory_floor"
      },
      {
        "char": "1",
        "block": "wastelands:scrap_pile"
      }
    ]
  }
}
