{
  "xsize": 16,
  "zsize": 16,
  "slices": [
    [
      "--------        ",
      "--------        ",
      "------''        ",
      "----''&-        ",
      "--''&---        ",
      "''&----'        ",
      "&-------        ",
      "--------        ",
      "--------        ",
      "--------        ",
      "--------        ",
      "-------'        ",
      "-----''&        ",
      "---''&--        ",
      "-''&----        ",
      "&&---&--        "
    ],
    [
      "'''''''         ",
      "'''''''         ",
      "/////           ",
      "/////           ",
      "/////           ",
      "/////           ",
      "/////           ",
      "/////           ",
      "/////           ",
      "/////           ",
      "/////           ",
      "/////           ",
      "/////           ",
      "/////           ",
      "                ",
      "                "
    ],
    [
      "'''''''         ",
      "'''''''         ",
      "    .           ",
      "  ,(.           ",
      "    .           ",
      "$*$$.           ",
      "    .           ",
      " ))).           ",
      "    .           ",
      " )%).           ",
      "    .           ",
      " ))).           ",
      "    .           ",
      ".....           ",
      "                ",
      "                "
    ],
    [
      "'''''''         ",
      "'''''''         ",
      "    .           ",
      "    .           ",
      "    .           ",
      "$+$$.           ",
      "    .           ",
      " ))).           ",
      "    .           ",
      " ))).           ",
      "    .           ",
      " ))).           ",
      "    .           ",
      ".....           ",
      "                ",
      "                "
    ],
    [
      "'''''''         ",
      "'''''''         ",
      "    !           ",
      "    !           ",
      "    .           ",
      "$$$$.           ",
      "    .           ",
      " ))).           ",
      "    .           ",
      " ))).           ",
      "    !           ",
      " )))!           ",
      "    .           ",
      ".....           ",
      "                ",
      "                "
    ],
    [
      "    .           ",
      "    .           ",
      "    !           ",
      "    !           ",
      "    .           ",
      "$$$$.           ",
      "    .           ",
      "    .           ",
      "    .           ",
      "    .           ",
      "    !           ",
      "    !           ",
      "    .           ",
      ".....           ",
      "                ",
      "                "
    ]
  ],
  "palette": {
    "palette": [
      {
        "char": "!",
        "block": "create:framed_glass"
      },
      {
        "char": "$",
        "block": "minecraft:bricks"
      },
      {
        "char": "%",
        "block": "minecraft:chest[facing=north,type=single,waterlogged=false]",
        "tag": {
          "id": "minecraft:chest",
          "LootTable": "infinite_domain:chests/wasteland_industrial"
        }
      },
      {
        "char": "&",
        "block": "minecraft:coarse_dirt"
      },
      {
        "char": "'",
        "block": "minecraft:gravel"
      },
      {
        "char": "(",
        "block": "minecraft:quartz_stairs[facing=west,half=bottom,shape=straight,waterlogged=false]"
      },
      {
        "char": ")",
        "block": "minecraft:scaffolding"
      },
      {
        "char": "*",
        "block": "minecraft:spruce_door[facing=south,half=lower,hinge=left,open=false,powered=false]"
      },
      {
        "char": "+",
        "block": "minecraft:spruce_door[facing=south,half=upper,hinge=left,open=false,powered=false]"
      },
      {
        "char": ",",
        "block": "kubejs:ruined_cauldron"
      },
      {
        "char": "-",
        "block": "tfmg:asphalt"
      },
      {
        "char": ".",
        "block": "tfmg:cinder_block"
      },
      {
        "char": "/",
        "block": "tfmg:factory_floor"
      }
    ]
  }
}
