{
  "xsize": 16,
  "zsize": 16,
  "slices": [
    [
      "     !       %%%",
      "     !       %%%",
      "     !       %%%",
      "     !       %%%",
      "     !       %%%",
      "     !       %%%",
      "     !       %%%",
      "     !       %%%",
      "     !          ",
      "     !          ",
      "     !          ",
      "     !!!!!!!!!!!",
      "                ",
      "                ",
      "                ",
      "                "
    ],
    [
      "     $$$$$$$$)  ",
      "     $$$$$$$$)  ",
      "     $$$$$$$$)  ",
      "     $$$$$$$$)  ",
      "     $$$$$$$$)  ",
      "     $$$$$$$$)  ",
      "     $$$$$$$$)  ",
      "     $$$$$$$$)))",
      "     $$$$$$$$$$$",
      "     $$$$$$$$$$$",
      "     $$$$$$$$$$$",
      "     $$$$$$$$$$$",
      "                ",
      "                ",
      "                ",
      "                "
    ],
    [
      "             )  ",
      "             )  ",
      "             )  ",
      "             )  ",
      "             )  ",
      "             )  ",
      "             )  ",
      "             )))",
      "                ",
      "                ",
      "                ",
      "                ",
      "                ",
      "                ",
      "                ",
      "                "
    ],
    [
      "             )  ",
      "             )  ",
      "             )  ",
      "             )  ",
      "             )  ",
      "             )  ",
      "             )  ",
      "             )))",
      "                ",
      "                ",
      "                ",
      "                ",
      "                ",
      "                ",
      "                ",
      "                "
    ],
    [
      "             )&&",
      "             )%%",
      "             )%%",
      "             )%(",
      "             )%'",
      "             )%%",
      "             )%%",
      "             )))",
      "                ",
      "                ",
      "                ",
      "                ",
      "                ",
      "                ",
      "                ",
      "                "
    ],
    [
      "             )&&",
      "             )  ",
      "             )  ",
      "             )  ",
      "             )  ",
      "             )  ",
      "             )  ",
      "             )))",
      "                ",
      "                ",
      "                ",
      "                ",
      "                ",
      "                ",
      "                ",
      "                "
    ]
  ],
  "palette": {
    "palette": [
      {
        "char": "!",
        "block": "minecraft:smooth_quartz"
      },
      {
        "char": "$",
        "block": "minecraft:smooth_stone"
      },
      {
        "char": "%",
        "block": "minecraft:spruce_planks"
      },
      {
        "char": "&",
        "block": "minecraft:stripped_spruce_wood"
      },
      {
        "char": "'",
        "block": "minecraft:white_bed[facing=north,occupied=false,part=foot]"
      },
      {
        "char": "(",
        "block": "minecraft:white_bed[facing=north,occupied=false,part=head]"
      },
      {
        "char": ")",
        "block": "minecraft:white_concrete"
      }
    ]
  }
}
