{
  "xsize": 16,
  "zsize": 16,
  "slices": [
    [
      "             !  ",
      "             !  ",
      "             !  ",
      "             !  ",
      "             !  ",
      "             !  ",
      "             !  ",
      "             !  ",
      "             !  ",
      "             !  ",
      "             !  ",
      "             !  ",
      "             !  ",
      "             !  ",
      "             !  ",
      "             !  "
    ],
    [
      "             !  ",
      "             !  ",
      "             !  ",
      "             !  ",
      "             !  ",
      "             !  ",
      "             !  ",
      "             !  ",
      "             !  ",
      "             !  ",
      "             !  ",
      "             !  ",
      "             !  ",
      "             !  ",
      "             !  ",
      "             !  "
    ],
    [
      "$$$$$$$$$$$$$!  ",
      "$$$$$$$$$$$$$!  ",
      "$$$$$$$$$$$$$!  ",
      "$$$$$$$$$$$$$!  ",
      "$$$$$$$$$$$$$!  ",
      "$$$$$$$$$$$$$!  ",
      "$$$$$$$$$$$$$!  ",
      "$$$$$$$$$$$$$!  ",
      "$$$$$$$$$$$$$!  ",
      "$$$$$$$$$$$$$!  ",
      "$$$$$$$$$$$$$!  ",
      "$$$$$$$$$$$$$!  ",
      "$$$$$$$$$$$$$!  ",
      "$$$$$$$$$$$$$!  ",
      "$$$$$$$$$$$$$!  ",
      "$$$$$$$$$$$$$!  "
    ],
    [
      "             !  ",
      "             !  ",
      "             !  ",
      "             !  ",
      "             !  ",
      "             !  ",
      "             !  ",
      "             !  ",
      "             !  ",
      "             !  ",
      "             !  ",
      "             !  ",
      "             !  ",
      "             !  ",
      "             !  ",
      "             !  "
    ],
    [
      "             !  ",
      "             !  ",
      "             !  ",
      "             !  ",
      "             !  ",
      "             !  ",
      "             !  ",
      "             !  ",
      "             !  ",
      "             !  ",
      "             !  ",
      "             !  ",
      "             !  ",
      "             !  ",
      "             !  ",
      "             !  "
    ],
    [
      "             !  ",
      "             !  ",
      "             !  ",
      "             !  ",
      "             !  ",
      "             !  ",
      "             !  ",
      "             !  ",
      "             !  ",
      "             !  ",
      "             !  ",
      "             !  ",
      "             !  ",
      "             !  ",
      "             !  ",
      "             !  "
    ]
  ],
  "palette": {
    "palette": [
      {
        "char": "!",
        "block": "minecraft:smooth_quartz"
      },
      {
        "char": "$",
        "block": "minecraft:spruce_planks"
      }
    ]
  }
}
