{
  "xsize": 16,
  "zsize": 16,
  "slices": [
    [
      ",,,,,,,,,,,,    ",
      ",,,,,,,,,,,(    ",
      ",,,,,,,,,((%    ",
      ",,,,,,,((%,,    ",
      ",,,,,((%,,,,    ",
      ",,,((%,,,,,(    ",
      ",((%,,,,,,,,    ",
      "(%,,,,,,,,,,    ",
      ",,,,,,,,,,,,    ",
      ",,,,,,,,,,,,    ",
      ",,,,,,,,,,,,    ",
      ",,,,,,,,,,((    ",
      ",,,,,,,,((%,    ",
      ",,,,,,((%,,,    ",
      ",,,,((%,,,,,    ",
      ",,((%,,,,,,,    "
    ],
    [
      "                ",
      "    *           ",
      "                ",
      "                ",
      "                ",
      "%%%%%%%%%%      ",
      "%%%%%%%%%%      ",
      "%%%%%%%%%%      ",
      "%%%%%%%%%%      ",
      "%%%%%%%%%%      ",
      "%%%%%%%%%%      ",
      "%%%%%%%%%%      ",
      "%%%%%%%%%%      ",
      "%%%%%%%%%%      ",
      "%%%%%%%%%%      ",
      "%%%%%%%%%%      "
    ],
    [
      "                ",
      "    *           ",
      "                ",
      "                ",
      "                ",
      "+$$$$+$$$+      ",
      "         $      ",
      "         $      ",
      " &   &   $      ",
      " &   &   $      ",
      " &   &   $      ",
      " &   &   +      ",
      " &   &   $      ",
      " &   &   $      ",
      " &   &   $      ",
      " &   &   $      "
    ],
    [
      "                ",
      "    *           ",
      "                ",
      "                ",
      "                ",
      "+!!!!+!!!+      ",
      "         !      ",
      "         !      ",
      "         !      ",
      " '   '   !      ",
      "         !      ",
      "         +      ",
      "         !      ",
      " '   '   !      ",
      "         !      ",
      "         !      "
    ],
    [
      "   )))          ",
      "   )))          ",
      "   )))          ",
      "                ",
      "                ",
      "+!!!!+!!!+      ",
      "         !      ",
      "         !      ",
      "         !      ",
      "         !      ",
      "         !      ",
      "         +      ",
      "         !      ",
      "         !      ",
      "         !      ",
      "         !      "
    ],
    [
      "   )))          ",
      "   )))          ",
      "   )))          ",
      "                ",
      "                ",
      "+!!!!+!!!+      ",
      "         !      ",
      "         !      ",
      "         !      ",
      "         !      ",
      "         !      ",
      "         +      ",
      "         !      ",
      "         !      ",
      "         !      ",
      "         !      "
    ]
  ],
  "palette": {
    "palette": [
      {
        "char": "!",
        "block": "create:framed_glass"
      },
      {
        "char": "$",
        "block": "minecraft:bricks"
      },
      {
        "char": "%",
        "block": "minecraft:coarse_dirt"
      },
      {
        "char": "&",
        "block": "minecraft:farmland[moisture=7]"
      },
      {
        "char": "'",
        "block": "minecraft:flower_pot"
      },
      {
        "char": "(",
        "block": "minecraft:gravel"
      },
      {
        "char": ")",
        "block": "minecraft:spruce_leaves[distance=1,persistent=true]"
      },
      {
        "char": "*",
        "block": "minecraft:spruce_log[axis=y]"
      },
      {
        "char": "+",
        "block": "minecraft:stripped_dark_oak_log[axis=y]"
      },
      {
        "char": ",",
        "block": "tfmg:asphalt"
      }
    ]
  }
}
