{
  "xsize": 16,
  "zsize": 16,
  "slices": [
    [
      " )))$$!)))))))))",
      " )$$!)))))))))))",
      " $!)))))))))))))",
      " )))))))))))))))",
      " ))))))))))))))$",
      " !)))))))))))$$!",
      " ))))))))))$$!))",
      " ))))))))$$!))))",
      " ))))))$$!))))))",
      " ))))$$!))))))))",
      " ))$$!))))))))))",
      " !$!))))))))))))",
      " !))))))))))))))",
      " )))))))))))))))",
      " )))))))))))))$$",
      " )))))))))))$$!)"
    ],
    [
      "     &&&&&&&&&&&",
      "     &&&&&&&&&&&",
      "     &&&((((((((",
      "     &&&((((((((",
      "     &&&((((((((",
      "     &&&((((((((",
      "     &&&((((((((",
      "     &&&((((((((",
      "     &&&((((((((",
      "     &&&((((((((",
      "     &&&((((((((",
      "     &&&((((((((",
      "     &&&&&&&&&&&",
      "     &&&&&&&&&&&",
      "     &&&&&&&&&&&",
      "     &&&&&&&&&&&"
    ],
    [
      "     '          ",
      "     ' %%%%%%%%%",
      "     ' %%%%%%%%%",
      "     ' %%%%%%%%%",
      "     ' %%%%%%%%%",
      "     ' %%%%%%%%%",
      "     ' %%%%%%%%%",
      "     ' %%%%%%%%%",
      "     ' %%%%%%%%%",
      "     ' %%%%%%%%%",
      "     ' %%%%%%%%%",
      "     ' %%%%%%%%%",
      "     ' %%%%%%%%%",
      "     '          ",
      "     '          ",
      "     '          "
    ],
    [
      "     '          ",
      "     '          ",
      "     '          ",
      "     '          ",
      "     '          ",
      "     '          ",
      "     '          ",
      "     '          ",
      "     '          ",
      "     '          ",
      "     '          ",
      "     '          ",
      "     '          ",
      "     '          ",
      "     '          ",
      "     '          "
    ],
    [
      "     '          ",
      "     '          ",
      "     '          ",
      "     '          ",
      "     '          ",
      "     '          ",
      "     '          ",
      "     '          ",
      "     '          ",
      "     '          ",
      "     '          ",
      "     '          ",
      "     '          ",
      "     '          ",
      "     '          ",
      "     '          "
    ],
    [
      "     '          ",
      "     '          ",
      "     '          ",
      "     '          ",
      "     '          ",
      "     '          ",
      "     '          ",
      "     '          ",
      "     '          ",
      "     '          ",
      "     '          ",
      "     '          ",
      "     '          ",
      "     '          ",
      "     '          ",
      "     '          "
    ]
  ],
  "palette": {
    "palette": [
      {
        "char": "!",
        "block": "minecraft:coarse_dirt"
      },
      {
        "char": "$",
        "block": "minecraft:gravel"
      },
      {
        "char": "%",
        "block": "minecraft:light_blue_concrete"
      },
      {
        "char": "&",
        "block": "minecraft:polished_andesite"
      },
      {
        "char": "'",
        "block": "minecraft:smooth_quartz"
      },
      {
        "char": "(",
        "block": "minecraft:water"
      },
      {
        "char": ")",
        "block": "tfmg:asphalt"
      }
    ]
  }
}
