{
  "xsize": 16,
  "zsize": 16,
  "slices": [
    [
      ".......))%......",
      ".....))%........",
      "...))%..........",
      ".))%............",
      ")%..............",
      "................",
      "..............))",
      "............))%.",
      "..........))%...",
      "........))%.....",
      "......))%.......",
      "....))%.........",
      "..))%...........",
      "))%.............",
      "%...............",
      "...............)"
    ],
    [
      "    000000000000",
      "+   00+00000+000",
      "    000000000000",
      "    000000000000",
      "    000000000000",
      "%%   %%%%%%%%%%%",
      "%%   %%%%%%%%%%%",
      "%%   %%%%%%%%%%%",
      "%%   %%%%%%%%%%%",
      "%%   %%%%%%%%%%%",
      "%%   %%%%%%%%%%%",
      "%%   %%%%%%%%%%%",
      "%%   %%%%%%%%%%%",
      "%%   %%%%%%%%%%%",
      "%%   %%%%%%%%%%%",
      "%%   %%%%%%%%%%%"
    ],
    [
      "    $          /",
      "+   $ +     +  /",
      "    $          /",
      "    $          /",
      "    $$$$$$$$$$$$",
      "$-   -$$$$-$$$$-",
      " $   $          ",
      " $   $          ",
      " $   $,,,,,,,,,,",
      " $   $,,,,,,,,,,",
      " $   $,,,,,,,,,,",
      " -   -,,,,,,,,,,",
      " $   $ '   '   '",
      " $   $ '   '   '",
      " $   $ '   '   '",
      " $   $ '   '   '"
    ],
    [
      "    $          /",
      "+   $ +     +  /",
      "    $          /",
      "    $          /",
      "    $$$$$$$$$$$$",
      "!-   -!!!!-!!!!-",
      " !   !          ",
      " !   !          ",
      " !   !,,,,,,,,,,",
      " !   !,,&,,,,&,,",
      " !   !,,,,,,,,,,",
      " -   -,,,,,,,,,,",
      " !   !          ",
      " !   ! (   (   (",
      " !   !          ",
      " !   !          "
    ],
    [
      "**  $***   *** /",
      "**  $***   *** /",
      "**  $***   *** /",
      "    $          /",
      "    $$$$$$$$$$$$",
      "!-   -!!!!-!!!!-",
      " !   !          ",
      " !   !          ",
      " !   !          ",
      " !   !          ",
      " !   !          ",
      " -   -          ",
      " !   !          ",
      " !   !          ",
      " !   !          ",
      " !   !          "
    ],
    [
      "**  $***   *** /",
      "**  $***   *** /",
      "**  $***   *** /",
      "    $          /",
      "    $$$$$$$$$$$$",
      "!-   -!!!!-!!!!-",
      " !   !          ",
      " !   !          ",
      " !   !          ",
      " !   !          ",
      " !   !          ",
      " -   -          ",
      " !   !          ",
      " !   !          ",
      " !   !          ",
      " !   !          "
    ]
  ],
  "palette": {
    "palette": [
      {
        "char": "!",
        "block": "create:framed_glass"
      },
      {
        "char": "$",
        "block": "minecraft:bricks"
      },
      {
        "char": "%",
        "block": "minecraft:coarse_dirt"
      },
      {
        "char": "&",
        "block": "minecraft:composter[level=5]"
      },
      {
        "char": "'",
        "block": "minecraft:farmland[moisture=7]"
      },
      {
        "char": "(",
        "block": "minecraft:flower_pot"
      },
      {
        "char": ")",
        "block": "minecraft:gravel"
      },
      {
        "char": "*",
        "block": "minecraft:spruce_leaves[distance=1,persistent=true]"
      },
      {
        "char": "+",
        "block": "minecraft:spruce_log[axis=y]"
      },
      {
        "char": ",",
        "block": "minecraft:spruce_planks"
      },
      {
        "char": "-",
        "block": "minecraft:stripped_dark_oak_log[axis=y]"
      },
      {
        "char": ".",
        "block": "tfmg:asphalt"
      },
      {
        "char": "/",
        "block": "tfmg:cinder_block"
      },
      {
        "char": "0",
        "block": "tfmg:factory_floor"
      }
    ]
  }
}
