{
  "xsize": 16,
  "zsize": 16,
  "slices": [
    [
      "++++++++++++++++",
      "++++++++++++++&&",
      "++++++++++++&&%+",
      "++++++++++&&%+++",
      "++++++++&&%+++++",
      "++++++&&%+++++++",
      "++++&&%+++++++++",
      "++&&%+++++++++++",
      "&&%+++++++++++++",
      "%+++++++++++++++",
      "+++++++++++++++&",
      "+++++++++++++&&%",
      "+++++++++++&&%++",
      "+++++++++&&%++++",
      "+++++++&&%++++++",
      "+++++&&%++++++++"
    ],
    [
      "                ",
      "                ",
      "                ",
      "                ",
      "                ",
      "                ",
      "  ,,,,,,,,,,,,,,",
      "  ,,,,,,,,,,,,,,",
      "  ,,,,,,,,,,,,,,",
      "  ,,,,,,,,,,,,,,",
      "  ,,,,,,,,,,,,,,",
      "  ,,,,,,,,,,,,,,",
      "  ,,,,,,,,,,,,,,",
      "  ,,,,,,,,,,,,,,",
      "  ,,,,,,,,,,,,,,",
      "  ,,,,,,,,,,,,,,"
    ],
    [
      "                ",
      "                ",
      "                ",
      "                ",
      "                ",
      "                ",
      "  $$$$$$'$$$$$$$",
      "  $             ",
      "  $             ",
      "  $             ",
      "  $ ))        - ",
      "  $ *           ",
      "  $             ",
      "  $             ",
      "  $             ",
      "  $             "
    ],
    [
      "                ",
      "                ",
      "                ",
      "                ",
      "                ",
      "                ",
      "  $$$$$$($$$$$$$",
      "  $             ",
      "  $             ",
      "  $             ",
      "  $             ",
      "  $             ",
      "  $             ",
      "  $             ",
      "  $             ",
      "  $             "
    ],
    [
      "                ",
      "                ",
      "                ",
      "                ",
      "                ",
      "                ",
      "  $$$$$$$$$$$$$$",
      "  $             ",
      "  $             ",
      "  $             ",
      "  $             ",
      "  $             ",
      "  $             ",
      "  $             ",
      "  $             ",
      "  $             "
    ],
    [
      "                ",
      "                ",
      "                ",
      "                ",
      "                ",
      "                ",
      "  $$$$$$$$$$$$$$",
      "  $             ",
      "  $             ",
      "  $             ",
      "  $             ",
      "  $             ",
      "  $             ",
      "  !             ",
      "  !             ",
      "  $             "
    ]
  ],
  "palette": {
    "palette": [
      {
        "char": "!",
        "block": "create:framed_glass"
      },
      {
        "char": "$",
        "block": "minecraft:bricks"
      },
      {
        "char": "%",
        "block": "minecraft:coarse_dirt"
      },
      {
        "char": "&",
        "block": "minecraft:gravel"
      },
      {
        "char": "'",
        "block": "minecraft:iron_door[facing=north,half=lower,hinge=left,open=false,powered=false]"
      },
      {
        "char": "(",
        "block": "minecraft:iron_door[facing=north,half=upper,hinge=left,open=false,powered=false]"
      },
      {
        "char": ")",
        "block": "minecraft:spruce_slab[type=bottom,waterlogged=false]"
      },
      {
        "char": "*",
        "block": "minecraft:spruce_stairs[facing=north,half=bottom,shape=straight,waterlogged=false]"
      },
      {
        "char": "+",
        "block": "tfmg:asphalt"
      },
      {
        "char": ",",
        "block": "tfmg:factory_floor"
      },
      {
        "char": "-",
        "block": "the_wasteland_reworked:radio"
      }
    ]
  }
}
