{
  "xsize": 16,
  "zsize": 16,
  "slices": [
    [
      "                ",
      "                ",
      "                ",
      "                ",
      "                ",
      "                ",
      "                ",
      "!!!!!!!!!!!!!!  ",
      "             !  ",
      "             !  ",
      "             !  ",
      "             !  ",
      "             !  ",
      "%%%%%%%%     !  ",
      "%%%%%%%%     !  ",
      "%%%%%%%%     !  "
    ],
    [
      "                ",
      "                ",
      "                ",
      "                ",
      "                ",
      "                ",
      "                ",
      "$$$$$$$$$$$$$$  ",
      "$$$$$$$$$$$$$$  ",
      "$$$$$$$$$$$$$$  ",
      "$$$$$$$$$$$$$$  ",
      "$$$$$$$$$$$$$$  ",
      "$$$$$$$$$$$$$$  ",
      "&&&&&&&&$$$$$$  ",
      "       &$$$$$$  ",
      "       &$$$$$$  "
    ],
    [
      "                ",
      "                ",
      "                ",
      "                ",
      "                ",
      "                ",
      "                ",
      "                ",
      "                ",
      "                ",
      "                ",
      "                ",
      "                ",
      "&&&&&&&&        ",
      "&&&&&&&&        ",
      "&&&&&&&&        "
    ],
    [
      "                ",
      "                ",
      "                ",
      "                ",
      "                ",
      "                ",
      "                ",
      "                ",
      "                ",
      "                ",
      "                ",
      "                ",
      "                ",
      "&&&&&&&&        ",
      "&&&&&&&&        ",
      "&&&&&&&&        "
    ],
    [
      "                ",
      "                ",
      "                ",
      "                ",
      "                ",
      "                ",
      "                ",
      "                ",
      "                ",
      "                ",
      "                ",
      "                ",
      "                ",
      "&&&&&&&&        ",
      "&&&&&&&&        ",
      "&&&&&&&&        "
    ],
    [
      "                ",
      "                ",
      "                ",
      "                ",
      "                ",
      "                ",
      "                ",
      "                ",
      "                ",
      "                ",
      "                ",
      "                ",
      "                ",
      "&&&&&&&&        ",
      "       &        ",
      "     ' &        "
    ]
  ],
  "palette": {
    "palette": [
      {
        "char": "!",
        "block": "minecraft:smooth_quartz"
      },
      {
        "char": "$",
        "block": "minecraft:smooth_stone"
      },
      {
        "char": "%",
        "block": "minecraft:spruce_planks"
      },
      {
        "char": "&",
        "block": "minecraft:white_concrete"
      },
      {
        "char": "'",
        "block": "supplementaries:item_shelf"
      }
    ]
  }
}
