{
  "xsize": 16,
  "zsize": 16,
  "slices": [
    [
      "     ...........",
      "))....)....)....",
      "................",
      "................",
      "................",
      "................",
      "................",
      "......))$.......",
      "....))$.........",
      "..))$...........",
      "))$.............",
      "$...............",
      "...............)",
      ".............))$",
      "...........))$..",
      ".........))$...."
    ],
    [
      "                ",
      "                ",
      "                ",
      "                ",
      "                ",
      "                ",
      "                ",
      "    000000000000",
      "    000000000000",
      "    000000000000",
      "    000000000000",
      "    000000000000",
      "    000000000000",
      "    000000000000",
      "    000000000000",
      "    000000000000"
    ],
    [
      "                ",
      "                ",
      "                ",
      "                ",
      "                ",
      "                ",
      "                ",
      "    !!!!!!!!!%&!",
      "    !          /",
      "    !          /",
      "    ! ,,  1    /",
      "    ! -        /",
      "    !          /",
      "    !          *",
      "    !          /",
      "    !          /"
    ],
    [
      "                ",
      "                ",
      "                ",
      "                ",
      "                ",
      "                ",
      "                ",
      "    !!!!!!!!!'(!",
      "    !          /",
      "    !          /",
      "    !          /",
      "    !          /",
      "    !          /",
      "    !          +",
      "    !          /",
      "    !          /"
    ],
    [
      "                ",
      "                ",
      "                ",
      "                ",
      "                ",
      "                ",
      "                ",
      "    !!!!!!!!!!!!",
      "    !          /",
      "    !          /",
      "    !          /",
      "    !          /",
      "    !          /",
      "    !          /",
      "    !          /",
      "    !          /"
    ],
    [
      "                ",
      "                ",
      "                ",
      "                ",
      "                ",
      "                ",
      "                ",
      "    !!!!!!!!!!!!",
      "    !          /",
      "    !          /",
      "    !          /",
      "    !          /",
      "    !          /",
      "    !          /",
      "    !          /",
      "    !          /"
    ]
  ],
  "palette": {
    "palette": [
      {
        "char": "!",
        "block": "minecraft:bricks"
      },
      {
        "char": "$",
        "block": "minecraft:coarse_dirt"
      },
      {
        "char": "%",
        "block": "minecraft:dark_oak_door[facing=north,half=lower,hinge=left,open=false,powered=false]"
      },
      {
        "char": "&",
        "block": "minecraft:dark_oak_door[facing=north,half=lower,hinge=right,open=false,powered=false]"
      },
      {
        "char": "'",
        "block": "minecraft:dark_oak_door[facing=north,half=upper,hinge=left,open=false,powered=false]"
      },
      {
        "char": "(",
        "block": "minecraft:dark_oak_door[facing=north,half=upper,hinge=right,open=false,powered=false]"
      },
      {
        "char": ")",
        "block": "minecraft:gravel"
      },
      {
        "char": "*",
        "block": "minecraft:spruce_door[facing=east,half=lower,hinge=left,open=false,powered=false]"
      },
      {
        "char": "+",
        "block": "minecraft:spruce_door[facing=east,half=upper,hinge=left,open=false,powered=false]"
      },
      {
        "char": ",",
        "block": "minecraft:spruce_slab[type=bottom,waterlogged=false]"
      },
      {
        "char": "-",
        "block": "minecraft:spruce_stairs[facing=north,half=bottom,shape=straight,waterlogged=false]"
      },
      {
        "char": ".",
        "block": "tfmg:asphalt"
      },
      {
        "char": "/",
        "block": "tfmg:cinder_block"
      },
      {
        "char": "0",
        "block": "tfmg:factory_floor"
      },
      {
        "char": "1",
        "block": "the_wasteland_reworked:radio"
      }
    ]
  }
}
