{
  "xsize": 16,
  "zsize": 16,
  "slices": [
    [
      "/////////////((%",
      "///////////((%//",
      "/////////((%////",
      "///////((%//////",
      "/////((%////////",
      "///((%//////////",
      "/((%////////////",
      "(%//////////////",
      "////////////////",
      "//////////////((",
      "////////////((%/",
      "//////////((%///",
      "////////((%/////",
      "//////((%///////",
      "////((%/////////",
      "/%((%/%////%////"
    ],
    [
      "%%   %%%%%%%%%%%",
      "%%   %%%%%%%%%%%",
      "%%   %%%%%%%%%%%",
      "%%   %%%%%%%%%%%",
      "%%   %%%%%%%%%%%",
      "%%   %%%%%%%%%%%",
      "%%   %%%%%%%%%%%",
      "%%   %%%%%%%%%%%",
      "%%   %%%%%%%%%%%",
      "%%   %%%%%%%%%%%",
      "%%   %%%%%%%%%%%",
      "%%   %%%%%%%%%%%",
      "%%   %%%%%%%%%%%",
      "%%   %%%%%%%%%%%",
      "                ",
      "                "
    ],
    [
      " $   $ &   &   &",
      " .   . &   &   &",
      " $   $ &   & - &",
      " $   $ &   &   &",
      " $   $ &   &   &",
      " $   $ &   &   &",
      " $   $ &   &   &",
      " .   . &   &   &",
      " $   $ &   &   &",
      " $   $ &   &   &",
      " $   $ &   &   &",
      " $   $          ",
      " $   $          ",
      "$.   .$$$$.$)*$.",
      "                ",
      "                "
    ],
    [
      " !   !          ",
      " .   . '   '   '",
      " !   !          ",
      " !   !          ",
      " !   !          ",
      " !   ! '   '   '",
      " !   !          ",
      " .   .          ",
      " !   !          ",
      " !   ! '   '   '",
      " !   !          ",
      " !   !          ",
      " !   !          ",
      "!.   .!!!!.!+,!.",
      "                ",
      "                "
    ],
    [
      " !   !          ",
      " .   .          ",
      " !   !          ",
      " !   !          ",
      " !   !          ",
      " !   !          ",
      " !   !          ",
      " .   .          ",
      " !   !          ",
      " !   !          ",
      " !   !          ",
      " !   !          ",
      " !   !          ",
      "!.   .!!!!.!!!!.",
      "                ",
      "                "
    ],
    [
      " !   !          ",
      " .   .          ",
      " !   !          ",
      " !   !          ",
      " !   !          ",
      " !   !          ",
      " !   !          ",
      " .   .          ",
      " !   !          ",
      " !   !          ",
      " !   !          ",
      " !   !          ",
      " !   !          ",
      "!.   .!!!!.!!!!.",
      "                ",
      "                "
    ]
  ],
  "palette": {
    "palette": [
      {
        "char": "!",
        "block": "create:framed_glass"
      },
      {
        "char": "$",
        "block": "minecraft:bricks"
      },
      {
        "char": "%",
        "block": "minecraft:coarse_dirt"
      },
      {
        "char": "&",
        "block": "minecraft:farmland[moisture=7]"
      },
      {
        "char": "'",
        "block": "minecraft:flower_pot"
      },
      {
        "char": "(",
        "block": "minecraft:gravel"
      },
      {
        "char": ")",
        "block": "minecraft:iron_door[facing=south,half=lower,hinge=left,open=false,powered=false]"
      },
      {
        "char": "*",
        "block": "minecraft:iron_door[facing=south,half=lower,hinge=right,open=false,powered=false]"
      },
      {
        "char": "+",
        "block": "minecraft:iron_door[facing=south,half=upper,hinge=left,open=false,powered=false]"
      },
      {
        "char": ",",
        "block": "minecraft:iron_door[facing=south,half=upper,hinge=right,open=false,powered=false]"
      },
      {
        "char": "-",
        "block": "minecraft:spawner",
        "tag": {
          "id": "minecraft:mob_spawner",
          "Delay": 200,
          "MinSpawnDelay": 240,
          "MaxSpawnDelay": 720,
          "SpawnCount": 2,
          "MaxNearbyEntities": 6,
          "RequiredPlayerRange": 14,
          "SpawnRange": 4,
          "SpawnData": {
            "entity": {
              "id": "minecraft:zombie"
            }
          },
          "SpawnPotentials": [
            {
              "weight": 1,
              "data": {
                "entity": {
                  "id": "minecraft:zombie"
                }
              }
            }
          ]
        }
      },
      {
        "char": ".",
        "block": "minecraft:stripped_dark_oak_log[axis=y]"
      },
      {
        "char": "/",
        "block": "tfmg:asphalt"
      }
    ]
  }
}
