{
  "xsize": 16,
  "zsize": 16,
  "slices": [
    [
      "))))))))))))))))",
      "))))))))))))))$$",
      "))))))))))))$$!)",
      "))))))))))$$!)))",
      "))))))))$$!)))))",
      "))))))$$!)))))))",
      "))))$$!)))))))))",
      "))$$!)))))))))))",
      "$$!)))))))))))))",
      "!)))))))))))))))",
      ")))))))))))))))$",
      ")))))))))))))$$!",
      ")))))))))))$$!))",
      ")))))))))$$!))))",
      ")))))))$$!))))))",
      "!))))!$!))!))))!"
    ],
    [
      "$$$$$$$$$$$$$$$$",
      "$$$$$$$$$$$$$$$$",
      "%%%%%%%%%%%%%%  ",
      "%%%%%%%%%%%%%%  ",
      "%%%%%%%%%%%%%%  ",
      "%%%%%%%%%%%%%%  ",
      "%%%%%%%%%%%%%%  ",
      "%%%%%%%%%%%%%%  ",
      "%%%%%%%%%%%%%%  ",
      "%%%%%%%%%%%%%%  ",
      "%%%%%%%%%%%%%%  ",
      "%%%%%%%%%%%%%%  ",
      "                ",
      "                ",
      "                ",
      "                "
    ],
    [
      "$$$$$$$$$$$$$$$$",
      "$$$$$$$$$$$$$$$$",
      "  '''''''''' (  ",
      "  '''''''''' (  ",
      "  '''''''''' (  ",
      "  '''''''''' (  ",
      "  '''''''''' (  ",
      "  '''''''''' (  ",
      "             (  ",
      "             (  ",
      "             (  ",
      "((((((((((((((  ",
      "                ",
      "                ",
      "                ",
      "                "
    ],
    [
      "$$$$$$$$$$$$$$$$",
      "$$$$$$$$$$$$$$$$",
      "  '''''''''' (  ",
      "  '''''''''' (  ",
      "  '''''''''' (  ",
      "  '''''''''' (  ",
      "  '''''''''' (  ",
      "  '''''''''' (  ",
      "             (  ",
      "             (  ",
      "             (  ",
      "((((((((((((((  ",
      "                ",
      "                ",
      "                ",
      "                "
    ],
    [
      "$$$$$$$$$$$$$$$$",
      "$$$$$$$$$$$$$$$$",
      " &'''''''''' (  ",
      "  '''''''''' (  ",
      "  '''''''''' (  ",
      "  '''''''''' (  ",
      "  '''''''''' (  ",
      "  '''''''''' (  ",
      "             (  ",
      "             (  ",
      "             (  ",
      "((((((((((((((  ",
      "                ",
      "                ",
      "                ",
      "                "
    ],
    [
      "$$$$$$$$$$$$$$$$",
      "$$$$$$$$$$$$$$$$",
      "  '''''''''' (  ",
      " &'''''''''' (  ",
      "  '''''''''' (  ",
      "  '''''''''' (  ",
      "  '''''''''' (  ",
      "  '''''''''' (  ",
      "             (  ",
      "             (  ",
      "             (  ",
      "((((((((((((((  ",
      "                ",
      "                ",
      "                ",
      "                "
    ]
  ],
  "palette": {
    "palette": [
      {
        "char": "!",
        "block": "minecraft:coarse_dirt"
      },
      {
        "char": "$",
        "block": "minecraft:gravel"
      },
      {
        "char": "%",
        "block": "minecraft:polished_andesite"
      },
      {
        "char": "&",
        "block": "minecraft:quartz_stairs[facing=south,half=bottom,shape=straight,waterlogged=false]"
      },
      {
        "char": "'",
        "block": "minecraft:scaffolding"
      },
      {
        "char": "(",
        "block": "minecraft:smooth_quartz"
      },
      {
        "char": ")",
        "block": "tfmg:asphalt"
      }
    ]
  }
}
