{
  "xsize": 16,
  "zsize": 16,
  "slices": [
    [
      " 111111111111111",
      ",,1111,1111,1111",
      "1111111111111111",
      "1111111111111111",
      "1111111111111111",
      "1111111111111111",
      "1111111111111111",
      "111111,,!1111111",
      "1111,,!111111111",
      "11,,!11111111111",
      ",,!1111111111111",
      "!111111111111111",
      "111111111111111,",
      "1111111111111,,!",
      "11111111111,,!11",
      "111111111,,!1111"
    ],
    [
      "                ",
      "                ",
      "                ",
      "                ",
      "  --------------",
      "  --------------",
      "  --------------",
      "----------------",
      "-------------,,,",
      "-------------,,,",
      "-------------,,,",
      "-------------,,,",
      "-------------,,,",
      "-------------,,,",
      "-------------,,,",
      "-------------,,,"
    ],
    [
      "                ",
      "                ",
      "                ",
      "                ",
      "  ......$%......",
      "  .             ",
      "  .             ",
      "...             ",
      "  .          ,,,",
      "  ......()...,,,",
      "             ,,,",
      "             ,,,",
      "  //         ,,,",
      "  0          ,,,",
      "             ,,,",
      "             ,,,"
    ],
    [
      "                ",
      "                ",
      "                ",
      "                ",
      "  ......&'......",
      "  .             ",
      "  .             ",
      "...             ",
      "  .          ,,,",
      "  ......*+...,,,",
      "             ,,,",
      "             ,,,",
      "             ,,,",
      "             ,,,",
      "             ,,,",
      "             ,,,"
    ],
    [
      "                ",
      "                ",
      "                ",
      "                ",
      "  ..............",
      "  .             ",
      "  .             ",
      "...             ",
      "  .          ,,,",
      "  ...........,,,",
      "             ,,,",
      "             ,,,",
      "             ,,,",
      "             ,,,",
      "             ,,,",
      "             ,,,"
    ],
    [
      "                ",
      "                ",
      "                ",
      "                ",
      "  ..............",
      "  .             ",
      "  .             ",
      "...             ",
      "  .          ,,,",
      "  ...........,,,",
      "             ,,,",
      "             ,,,",
      "             ,,,",
      "             ,,,",
      "             ,,,",
      "             ,,,"
    ]
  ],
  "palette": {
    "palette": [
      {
        "char": "!",
        "block": "minecraft:coarse_dirt"
      },
      {
        "char": "$",
        "block": "minecraft:dark_oak_door[facing=north,half=lower,hinge=left,open=false,powered=false]"
      },
      {
        "char": "%",
        "block": "minecraft:dark_oak_door[facing=north,half=lower,hinge=right,open=false,powered=false]"
      },
      {
        "char": "&",
        "block": "minecraft:dark_oak_door[facing=north,half=upper,hinge=left,open=false,powered=false]"
      },
      {
        "char": "'",
        "block": "minecraft:dark_oak_door[facing=north,half=upper,hinge=right,open=false,powered=false]"
      },
      {
        "char": "(",
        "block": "minecraft:dark_oak_door[facing=south,half=lower,hinge=left,open=false,powered=false]"
      },
      {
        "char": ")",
        "block": "minecraft:dark_oak_door[facing=south,half=lower,hinge=right,open=false,powered=false]"
      },
      {
        "char": "*",
        "block": "minecraft:dark_oak_door[facing=south,half=upper,hinge=left,open=false,powered=false]"
      },
      {
        "char": "+",
        "block": "minecraft:dark_oak_door[facing=south,half=upper,hinge=right,open=false,powered=false]"
      },
      {
        "char": ",",
        "block": "minecraft:gravel"
      },
      {
        "char": "-",
        "block": "minecraft:polished_andesite"
      },
      {
        "char": ".",
        "block": "minecraft:smooth_quartz"
      },
      {
        "char": "/",
        "block": "minecraft:spruce_slab[type=bottom,waterlogged=false]"
      },
      {
        "char": "0",
        "block": "minecraft:spruce_stairs[facing=north,half=bottom,shape=straight,waterlogged=false]"
      },
      {
        "char": "1",
        "block": "tfmg:asphalt"
      }
    ]
  }
}
