{
  "xsize": 16,
  "zsize": 16,
  "slices": [
    [
      " %%%   %%%   %%%",
      " %%%   %%%   %%%",
      " %%%   %%%   %%%",
      "        $       ",
      "$$$$$$$$$       ",
      "!!!!&!!&   &!!!!",
      "       !   !    ",
      "       !   !    ",
      "       !   !    ",
      "       !   !    ",
      "       !   !    ",
      "       &   &    ",
      "       !   !    ",
      "       !   !    ",
      "       !   !    ",
      "       !   !    "
    ],
    [
      "        $       ",
      "        $       ",
      "                ",
      "                ",
      "$$$$$$$$        ",
      "!!!!&!!&        ",
      "       !        ",
      "       !        ",
      "       !        ",
      "       !        ",
      "       !        ",
      "       &        ",
      "       !        ",
      "       !        ",
      "       !        ",
      "       !        "
    ],
    [
      "        $       ",
      "        $       ",
      "                ",
      "                ",
      "$$$$$$$$        ",
      "!!!!&!!&        ",
      "       !        ",
      "       !        ",
      "       !        ",
      "       !        ",
      "       !        ",
      "       &        ",
      "       !        ",
      "       !        ",
      "       !        ",
      "       !        "
    ],
    [
      "        $       ",
      "        $       ",
      "                ",
      "                ",
      "$$$$$$$$        ",
      "!!!!&!!&        ",
      "       !        ",
      "       !        ",
      "       !        ",
      "       !        ",
      "       !        ",
      "       &        ",
      "       !        ",
      "       !        ",
      "       !        ",
      "       !        "
    ],
    [
      "        $       ",
      "        $       ",
      "                ",
      "                ",
      "$$$$$$$$        ",
      "!!!!!!!!        ",
      "       !        ",
      "       !        ",
      "       !        ",
      "       !        ",
      "       !        ",
      "       !        ",
      "       !        ",
      "       !        ",
      "       !        ",
      "       !        "
    ],
    [
      "        $       ",
      "        $       ",
      "                ",
      "                ",
      "$$$$$$$$        ",
      "!!!!!!!         ",
      "      !         ",
      "      !         ",
      "      !         ",
      "      !         ",
      "      !         ",
      "      !         ",
      "      !         ",
      "      !         ",
      "      !         ",
      "      !         "
    ]
  ],
  "palette": {
    "palette": [
      {
        "char": "!",
        "block": "create:framed_glass"
      },
      {
        "char": "$",
        "block": "minecraft:bricks"
      },
      {
        "char": "%",
        "block": "minecraft:spruce_leaves[distance=1,persistent=true]"
      },
      {
        "char": "&",
        "block": "minecraft:stripped_dark_oak_log[axis=y]"
      }
    ]
  }
}
