{
  "xsize": 16,
  "zsize": 16,
  "slices": [
    [
      "                ",
      "                ",
      "                ",
      "++++++++++ +++++",
      "  +            +",
      "  +            +",
      "  +            +",
      "  +            +",
      "  +            +",
      "  +            +",
      "                ",
      "                ",
      "                ",
      "                ",
      "                ",
      "                "
    ],
    [
      "                ",
      "                ",
      "                ",
      "++++++++++ +++++",
      "  +            +",
      "  +            +",
      "  +            +",
      "  +            +",
      "  +            +",
      "  +            +",
      "                ",
      "                ",
      "                ",
      "                ",
      "                ",
      "                "
    ],
    [
      "                ",
      "                ",
      "                ",
      "                ",
      "                ",
      "                ",
      "                ",
      "                ",
      "                ",
      "                ",
      "                ",
      "                ",
      "                ",
      "                ",
      "                ",
      "                "
    ],
    [
      "                ",
      "                ",
      "                ",
      "                ",
      "                ",
      "                ",
      "                ",
      "                ",
      "                ",
      "                ",
      "                ",
      "                ",
      "                ",
      "                ",
      "                ",
      "                "
    ],
    [
      "                ",
      "                ",
      "                ",
      "                ",
      "                ",
      "                ",
      "                ",
      "                ",
      "                ",
      "                ",
      "                ",
      "                ",
      "                ",
      "                ",
      "                ",
      "                "
    ],
    [
      "))).&),)))      ",
      "))))))))))      ",
      "*)))))))))      ",
      "+++++++(++      ",
      "))+)))))))      ",
      "))+)))))))      ",
      "))')))))))      ",
      "))+-)%))))      ",
      "))+)))))!)      ",
      "))+)))))))      ",
      "))))))))))      ",
      "))))))))))      ",
      "$$))!!!!!)      ",
      "))).&),)))      ",
      "))))))))))      ",
      "*)))))))))      "
    ]
  ],
  "palette": {
    "palette": [
      {
        "char": "!",
        "block": "minecraft:barrel[facing=up,open=false]"
      },
      {
        "char": "$",
        "block": "minecraft:dark_oak_stairs[facing=south,half=bottom,shape=straight,waterlogged=false]"
      },
      {
        "char": "%",
        "block": "minecraft:quartz_stairs[facing=north,half=bottom,shape=straight,waterlogged=false]"
      },
      {
        "char": "&",
        "block": "minecraft:smoker[facing=north,lit=false]"
      },
      {
        "char": "'",
        "block": "minecraft:spruce_door[facing=east,half=lower,hinge=left,open=false,powered=false]"
      },
      {
        "char": "(",
        "block": "minecraft:spruce_door[facing=south,half=lower,hinge=left,open=false,powered=false]"
      },
      {
        "char": ")",
        "block": "minecraft:spruce_planks"
      },
      {
        "char": "*",
        "block": "minecraft:spruce_slab[type=bottom,waterlogged=false]"
      },
      {
        "char": "+",
        "block": "minecraft:stripped_spruce_wood"
      },
      {
        "char": ",",
        "block": "minecraft:water_cauldron[level=1]"
      },
      {
        "char": "-",
        "block": "minecraft:water_cauldron[level=2]"
      },
      {
        "char": ".",
        "block": "the_wasteland_reworked:radio"
      }
    ]
  }
}
