{
  "xsize": 16,
  "zsize": 16,
  "slices": [
    [
      ",,,,,,,,     '  ",
      ",,,,,,,,     '  ",
      ",,,,,,,,     '  ",
      ",,,,,,,,     '  ",
      ",,,,,,,,     '  ",
      ",,,,,,,,     '  ",
      ",,,,,,,,     '  ",
      ",,,,,,,,     '  ",
      ",,,,,,,,     '  ",
      ",,,,,,,,     '  ",
      ",,,,,,,,     '  ",
      ",,,,,,,,     '  ",
      ",,,,,,,,     '  ",
      ",,,,,,,,     '  ",
      ",,,,,,,,     '  ",
      ",,,,,,,,     '  "
    ],
    [
      "       0))))))  ",
      "       0))))))  ",
      "       0))))))  ",
      "       0))))))  ",
      "       0))))))  ",
      "       0))))))  ",
      "       0))))))  ",
      "       0))))))  ",
      "       0))))))  ",
      "       0))))))  ",
      "       0))))))  ",
      "       0))))))  ",
      "       0))))))  ",
      "       0))))))  ",
      "       0))))))  ",
      "       0))))))  "
    ],
    [
      "00000000        ",
      "00000000        ",
      "00000000        ",
      "00000000        ",
      "00000000        ",
      "00000000        ",
      "00000000        ",
      "       0        ",
      "       0        ",
      "       0        ",
      "       0        ",
      "       0        ",
      "       0        ",
      "       0        ",
      "       0        ",
      "       0        "
    ],
    [
      "00000000        ",
      "00000000        ",
      "00000000        ",
      "00000000        ",
      "00000000        ",
      "00000000        ",
      "00000000        ",
      "       0        ",
      "       0        ",
      "       0        ",
      "       0        ",
      "       0        ",
      "       0        ",
      "       0        ",
      "       0        ",
      "       0        "
    ],
    [
      "00000000        ",
      "00000000        ",
      "00000000        ",
      "0000*000        ",
      "00000000        ",
      "00000000        ",
      "00000000        ",
      "/,%,,,,0        ",
      ",,,,,!,0        ",
      ",,,,,,,0        ",
      ",,,,,,,0        ",
      ",,,,,,((((      ",
      ",!!!!!((((      ",
      "2&,.,,((((      ",
      ",,,,,,((((      ",
      ",,,,,,((((      "
    ],
    [
      "1      0        ",
      "       0        ",
      "       0        ",
      "----+--0        ",
      "       0        ",
      "       0        ",
      "       0        ",
      "       0        ",
      "  $    0        ",
      "       0        ",
      "       0        ",
      "       0        ",
      "     1 0        ",
      "1      0        ",
      "       0        ",
      "       0        "
    ]
  ],
  "palette": {
    "palette": [
      {
        "char": "!",
        "block": "minecraft:barrel[facing=up,open=false]"
      },
      {
        "char": "$",
        "block": "minecraft:lever[face=wall,facing=south,powered=false]"
      },
      {
        "char": "%",
        "block": "minecraft:quartz_stairs[facing=north,half=bottom,shape=straight,waterlogged=false]"
      },
      {
        "char": "&",
        "block": "minecraft:smoker[facing=north,lit=false]"
      },
      {
        "char": "'",
        "block": "minecraft:smooth_quartz"
      },
      {
        "char": "(",
        "block": "minecraft:smooth_quartz_slab[type=bottom,waterlogged=false]"
      },
      {
        "char": ")",
        "block": "minecraft:smooth_stone"
      },
      {
        "char": "*",
        "block": "minecraft:spruce_door[facing=south,half=lower,hinge=left,open=false,powered=false]"
      },
      {
        "char": "+",
        "block": "minecraft:spruce_door[facing=south,half=upper,hinge=left,open=false,powered=false]"
      },
      {
        "char": ",",
        "block": "minecraft:spruce_planks"
      },
      {
        "char": "-",
        "block": "minecraft:stripped_spruce_wood"
      },
      {
        "char": ".",
        "block": "minecraft:water_cauldron[level=1]"
      },
      {
        "char": "/",
        "block": "minecraft:water_cauldron[level=2]"
      },
      {
        "char": "0",
        "block": "minecraft:white_concrete"
      },
      {
        "char": "1",
        "block": "supplementaries:item_shelf"
      },
      {
        "char": "2",
        "block": "the_wasteland_reworked:radio"
      }
    ]
  }
}
