{
  "xsize": 16,
  "zsize": 16,
  "slices": [
    [
      "&'''''''''''''''",
      "&'''''''''''''''",
      "&'''''''''''''''",
      "&'''''''''''''''",
      "&&&&&&&&&&&&&&&&",
      "&&&&&&&&&&&&&&&&",
      "&&&&&&&&&&&&$$$$",
      "''''''''''''$$$$",
      "            $$$$",
      "            $$$$",
      "                ",
      "                ",
      "                ",
      "                ",
      "                ",
      "                "
    ],
    [
      " '              ",
      " '              ",
      " '              ",
      " '''''''''''''''",
      "                ",
      "                ",
      "                ",
      "''''''''''''''''",
      "                ",
      "                ",
      "                ",
      "                ",
      "                ",
      "                ",
      "                ",
      "                "
    ],
    [
      " '              ",
      " '              ",
      " '              ",
      " '''''''''''''''",
      "                ",
      "                ",
      "                ",
      "!!''''!!''''''!!",
      "                ",
      "                ",
      "                ",
      "                ",
      "                ",
      "                ",
      "                ",
      "                "
    ],
    [
      " '              ",
      " '              ",
      " '              ",
      " '''''''''''''''",
      "                ",
      "                ",
      "                ",
      "!!''''!!''''''!!",
      "                ",
      "                ",
      "                ",
      "                ",
      "                ",
      "                ",
      "                ",
      "                "
    ],
    [
      "%''!!!!!!!!!!!!!",
      "%'''''''''''''''",
      "%'''''''''''''''",
      "%'''''''''''''''",
      "%%%%%%%%%%%%%%%%",
      "%%%%%%%%%%%%%%%%",
      "%%%%%%%%%%%%%%%%",
      "%%%%%%%%%%%%%%%%",
      "                ",
      "                ",
      "                ",
      "                ",
      "                ",
      "                ",
      "                ",
      "                "
    ],
    [
      "   !!!!!!!!!!!!!",
      "                ",
      "                ",
      "                ",
      "                ",
      "                ",
      "                ",
      "                ",
      "                ",
      "                ",
      "                ",
      "                ",
      "                ",
      "                ",
      "                ",
      "                "
    ]
  ],
  "palette": {
    "palette": [
      {
        "char": "!",
        "block": "create:framed_glass"
      },
      {
        "char": "$",
        "block": "minecraft:smooth_quartz_slab[type=bottom,waterlogged=false]"
      },
      {
        "char": "%",
        "block": "minecraft:smooth_stone"
      },
      {
        "char": "&",
        "block": "minecraft:spruce_planks"
      },
      {
        "char": "'",
        "block": "minecraft:white_concrete"
      }
    ]
  }
}
