{
  "xsize": 16,
  "zsize": 16,
  "slices": [
    [
      "++++++++++++++++",
      "++++++++++++++((",
      "++++++++++++((%+",
      "++++++++++((%+++",
      "++++++++((%+++++",
      "++++++((%+++++++",
      "++++((%+++++++++",
      "++((%+++++++++++",
      "((%+++++++++++++",
      "%+++++++++++++++",
      "+++++++++++++++(",
      "+++++++++++++((%",
      "+++++++++++((%++",
      "+++++++++((%++++",
      "+++++++((%++++++",
      "%++++%(%++%++++%"
    ],
    [
      "%%%%%%%%   %%%%%",
      "%%%%%%%%   %%%%%",
      "%%%%%%%%   %%%%%",
      "%%%%%%%%   %%%%%",
      "%%%%%%%%   %%%%%",
      "%%%%%%%%   %%%%%",
      "%%%%%%%%   %%%%%",
      "%%%%%%%%   %%%%%",
      "%%%%%%%%   %%%%%",
      "%%%%%%%%   %%%%%",
      "%%%%%%%%   %%%%%",
      "%%%%%%%%   %%%%%",
      "%%%%%%%%   %%%%%",
      "%%%%%%%%   %%%%%",
      "                ",
      "                "
    ],
    [
      "   &   $   $ &  ",
      "   &   )   ) &  ",
      "   &   $   $ &  ",
      "   &   $   $ &  ",
      "   &   $   $ &  ",
      "   &   $   $ &  ",
      "   &   $   $ &  ",
      "   &   )   ) &  ",
      "   &   $   $ &  ",
      "   &   $   $ &  ",
      "   &   $   $ ***",
      "       $   $ ***",
      "       $   $ ***",
      "$$$$)$$)   )$$$$",
      "                ",
      "                "
    ],
    [
      "       !   !    ",
      "   '   )   ) '  ",
      "       !   !    ",
      "       !   !    ",
      "       !   !    ",
      "   '   !   ! '  ",
      "       !   !    ",
      "       )   )    ",
      "       !   !    ",
      "   '   !   ! '  ",
      "       !   !    ",
      "       !   !    ",
      "       !   !    ",
      "!!!!)!!)   )!!!!",
      "                ",
      "                "
    ],
    [
      "       !   !    ",
      "       )   )    ",
      "       !   !    ",
      "       !   !    ",
      "       !   !    ",
      "       !   !    ",
      "       !   !    ",
      "       )   )    ",
      "       !   !    ",
      "       !   !    ",
      "       !   !    ",
      "       !   !    ",
      "       !   !    ",
      "!!!!)!!)   )!!!!",
      "                ",
      "                "
    ],
    [
      "       !   !    ",
      "       )   )    ",
      "       !   !    ",
      "       !   !    ",
      "       !   !    ",
      "       !   !    ",
      "       !   !    ",
      "       )   )    ",
      "       !   !    ",
      "       !   !    ",
      "       !   !    ",
      "       !   !    ",
      "       !   !    ",
      "!!!!)!!)   )!!!!",
      "                ",
      "                "
    ]
  ],
  "palette": {
    "palette": [
      {
        "char": "!",
        "block": "create:framed_glass"
      },
      {
        "char": "$",
        "block": "minecraft:bricks"
      },
      {
        "char": "%",
        "block": "minecraft:coarse_dirt"
      },
      {
        "char": "&",
        "block": "minecraft:farmland[moisture=7]"
      },
      {
        "char": "'",
        "block": "minecraft:flower_pot"
      },
      {
        "char": "(",
        "block": "minecraft:gravel"
      },
      {
        "char": ")",
        "block": "minecraft:stripped_dark_oak_log[axis=y]"
      },
      {
        "char": "*",
        "block": "minecraft:water_cauldron[level=3]"
      },
      {
        "char": "+",
        "block": "tfmg:asphalt"
      }
    ]
  }
}
