{
  "xsize": 16,
  "zsize": 16,
  "slices": [
    [
      "    &      (    ",
      "    &      (    ",
      "    &      !    ",
      "    &      !    ",
      "    &      (    ",
      "    &      (    ",
      "((((((((((((    ",
      "                ",
      "   %        %   ",
      "                ",
      "                ",
      "                ",
      "                ",
      "                ",
      "                ",
      "                "
    ],
    [
      "    &      (    ",
      "    &      (    ",
      "    &      !    ",
      "    &      !    ",
      "    &      (    ",
      "    &      (    ",
      "((((((((((((    ",
      "                ",
      "   %        %   ",
      "                ",
      "                ",
      "                ",
      "                ",
      "                ",
      "                ",
      "                "
    ],
    [
      "           (    ",
      "           (    ",
      "           (    ",
      "           (    ",
      "           (    ",
      "           (    ",
      "((((((((((((    ",
      "                ",
      "                ",
      "                ",
      "                ",
      "                ",
      "                ",
      "                ",
      "                ",
      "                "
    ],
    [
      "           (    ",
      "           (    ",
      "         $ (    ",
      "           (    ",
      "           (    ",
      "           (    ",
      "((((((((((((    ",
      "                ",
      "                ",
      "                ",
      "                ",
      "                ",
      "                ",
      "                ",
      "                ",
      "                "
    ],
    [
      "''''''''''''    ",
      "''''''''''''    ",
      "'''''''''$''    ",
      "''''''''''''    ",
      "''''''''''''    ",
      "''''''''''''    ",
      "''''''''''''    ",
      "                ",
      "                ",
      "                ",
      "                ",
      "                ",
      "                ",
      "                ",
      "                ",
      "                "
    ],
    [
      "!!!!!!!!!       ",
      "!!!!!!!!!       ",
      "!!!!!!!!!$      ",
      "                ",
      "                ",
      "                ",
      "                ",
      "                ",
      "                ",
      "                ",
      "                ",
      "                ",
      "                ",
      "                ",
      "                ",
      "                "
    ]
  ],
  "palette": {
    "palette": [
      {
        "char": "!",
        "block": "create:framed_glass"
      },
      {
        "char": "$",
        "block": "minecraft:bricks"
      },
      {
        "char": "%",
        "block": "minecraft:stripped_spruce_log[axis=y]"
      },
      {
        "char": "&",
        "block": "minecraft:stripped_spruce_wood"
      },
      {
        "char": "'",
        "block": "minecraft:weathered_cut_copper"
      },
      {
        "char": "(",
        "block": "the_wasteland_reworked:decayed_planks"
      }
    ]
  }
}
