{
  "xsize": 16,
  "zsize": 16,
  "slices": [
    [
      ".....           ",
      ".%....%....%..  ",
      "..............  ",
      ".............%  ",
      "............%%  ",
      "..........%%$.  ",
      "........%%$...  ",
      "......%%$.....  ",
      "....%%$.......  ",
      "..%%$........%  ",
      "%%$...........  ",
      "$.............  ",
      "..............  ",
      ".............%  ",
      "...........%%$  ",
      ".........%%$.%  "
    ],
    [
      "                ",
      "                ",
      "                ",
      "                ",
      "                ",
      "                ",
      "'''''''''''     ",
      "'''''''''''     ",
      "'''''''''''     ",
      "'''''''''''     ",
      "'''''''''''     ",
      "'''''''''''     ",
      "'''''''''''     ",
      "'''''''''''     ",
      "'''''''''''     ",
      "'''''''''''     "
    ],
    [
      "                ",
      "                ",
      "                ",
      "                ",
      "                ",
      "                ",
      "   &&&&&&&&     ",
      "  -       &     ",
      "  -       &     ",
      "  -       &     ",
      "( -       &     ",
      "  -       &     ",
      "  )       &     ",
      "  -       &     ",
      "  ----+---&     ",
      "  -       &     "
    ],
    [
      "                ",
      "                ",
      "                ",
      "                ",
      "                ",
      "                ",
      "   &&&&&&&&     ",
      "  -       &     ",
      "  -       &     ",
      "  -       &     ",
      "  -       &     ",
      "( -       &     ",
      "  *       &     ",
      "  -       &     ",
      "  ----,---&     ",
      "  -       &     "
    ],
    [
      "                ",
      "                ",
      "                ",
      "                ",
      "                ",
      "                ",
      "   &&&!!&&&     ",
      "  -       &     ",
      "  -       &     ",
      "  -       &     ",
      "  -       &     ",
      "  -       &     ",
      "( -       &     ",
      "  -       &     ",
      "  --------&     ",
      "  -       &     "
    ],
    [
      "                ",
      "                ",
      "                ",
      "                ",
      "                ",
      "                ",
      "   &&&!!&&&     ",
      "  -       &     ",
      "  -       &     ",
      "  -       &     ",
      "  -       &     ",
      "  -       &     ",
      "  -       &     ",
      "( -       &     ",
      "  --------&     ",
      "  -       &     "
    ]
  ],
  "palette": {
    "palette": [
      {
        "char": "!",
        "block": "create:framed_glass"
      },
      {
        "char": "$",
        "block": "minecraft:coarse_dirt"
      },
      {
        "char": "%",
        "block": "minecraft:gravel"
      },
      {
        "char": "&",
        "block": "minecraft:mud_bricks"
      },
      {
        "char": "'",
        "block": "minecraft:oak_planks"
      },
      {
        "char": "(",
        "block": "minecraft:oak_stairs[facing=south,half=bottom,shape=straight,waterlogged=false]"
      },
      {
        "char": ")",
        "block": "minecraft:spruce_door[facing=east,half=lower,hinge=left,open=false,powered=false]"
      },
      {
        "char": "*",
        "block": "minecraft:spruce_door[facing=east,half=upper,hinge=left,open=false,powered=false]"
      },
      {
        "char": "+",
        "block": "minecraft:spruce_door[facing=south,half=lower,hinge=left,open=false,powered=false]"
      },
      {
        "char": ",",
        "block": "minecraft:spruce_door[facing=south,half=upper,hinge=left,open=false,powered=false]"
      },
      {
        "char": "-",
        "block": "minecraft:stripped_dark_oak_wood"
      },
      {
        "char": ".",
        "block": "tfmg:asphalt"
      }
    ]
  }
}
