{
  "xsize": 16,
  "zsize": 16,
  "slices": [
    [
      "                ",
      "                ",
      "                ",
      "                ",
      "                ",
      "                ",
      "   &&&&&&&&     ",
      "          &     ",
      "          &     ",
      "          &     ",
      "          &     ",
      "          &     ",
      "          &     ",
      "          &     ",
      "(         &     ",
      "          &     "
    ],
    [
      "                ",
      "                ",
      "                ",
      "                ",
      "                ",
      "                ",
      "&&&&&&&&&&&     ",
      "          &     ",
      "          &     ",
      "          &     ",
      "          &     ",
      "          &     ",
      "          &     ",
      "          &     ",
      "          &     ",
      "(         &     "
    ],
    [
      "                ",
      "                ",
      "                ",
      "                ",
      "                ",
      "                ",
      "&&&&&&&&&&&     ",
      "          &     ",
      "          &     ",
      "          &     ",
      "          &     ",
      "          &     ",
      "          &     ",
      "          &     ",
      "          &     ",
      "          &     "
    ],
    [
      "                ",
      "                ",
      "                ",
      "                ",
      "                ",
      "'''''''''''''   ",
      "'',''''''''''   ",
      "'''''''''''''   ",
      "'''''''''''''   ",
      "''''''''''''    ",
      "''''''''''''    ",
      "''''''''''''    ",
      "''''''''''''    ",
      "''''''''''''    ",
      "''''''''''''    ",
      " '''''''''''    "
    ],
    [
      "                ",
      "                ",
      "                ",
      "                ",
      "                ",
      "                ",
      "%%,%%%%%%%%     ",
      "%%%%%%%%%%%     ",
      "000000000000    ",
      "    -      0    ",
      "!!!!-$$$   0    ",
      " .  -    1 0    ",
      "    -      0    ",
      "    - +    0    ",
      "    -      0    ",
      "---)-------0    "
    ],
    [
      "                ",
      "                ",
      "                ",
      "                ",
      "                ",
      "                ",
      "  ,             ",
      "                ",
      "000000000000    ",
      "    -      0    ",
      "   /-      0    ",
      "    -    / 0    ",
      "    -      0    ",
      "    -      0    ",
      "    -      0    ",
      "---*-------0    "
    ]
  ],
  "palette": {
    "palette": [
      {
        "char": "!",
        "block": "minecraft:barrel[facing=up,open=false]"
      },
      {
        "char": "$",
        "block": "minecraft:dark_oak_stairs[facing=south,half=bottom,shape=straight,waterlogged=false]"
      },
      {
        "char": "%",
        "block": "minecraft:dark_prismarine"
      },
      {
        "char": "&",
        "block": "minecraft:mud_bricks"
      },
      {
        "char": "'",
        "block": "minecraft:oak_planks"
      },
      {
        "char": "(",
        "block": "minecraft:oak_stairs[facing=south,half=bottom,shape=straight,waterlogged=false]"
      },
      {
        "char": ")",
        "block": "minecraft:spruce_door[facing=south,half=lower,hinge=left,open=false,powered=false]"
      },
      {
        "char": "*",
        "block": "minecraft:spruce_door[facing=south,half=upper,hinge=left,open=false,powered=false]"
      },
      {
        "char": "+",
        "block": "minecraft:spruce_slab[type=bottom,waterlogged=false]"
      },
      {
        "char": ",",
        "block": "minecraft:stripped_spruce_log[axis=y]"
      },
      {
        "char": "-",
        "block": "minecraft:stripped_spruce_wood"
      },
      {
        "char": ".",
        "block": "kubejs:ruined_cauldron"
      },
      {
        "char": "/",
        "block": "supplementaries:item_shelf"
      },
      {
        "char": "0",
        "block": "the_wasteland_reworked:decayed_planks"
      },
      {
        "char": "1",
        "block": "the_wasteland_reworked:radio"
      }
    ]
  }
}
