{
  "xsize": 16,
  "zsize": 16,
  "slices": [
    [
      "+++++++%%!++++  ",
      "+++++%%!++++++  ",
      "+++%%!++++++++  ",
      "+%%!++++++++++  ",
      "%!++++++++++++  ",
      "+++++++++++++%  ",
      "++++++++++++++  ",
      "++++++++++++%%  ",
      "++++++++++%%!+  ",
      "+!++++!+%%!!++  ",
      "                ",
      "                ",
      "                ",
      "                ",
      "                ",
      "                "
    ],
    [
      "'''''''''''     ",
      "'''''''''''     ",
      "''''''%%%%%%%%% ",
      "''''''%%%%%%%%% ",
      "''''''%%%%%%%%% ",
      "''''''%%%%%%%%% ",
      "''''''%%%%%%%%% ",
      "''''''%%%%%%%%% ",
      "      %%%%%%%%% ",
      "      %%%%%%%%% ",
      "      %%%%%%%%% ",
      "                ",
      "                ",
      "                ",
      "                ",
      "                "
    ],
    [
      "  ) $$$   &     ",
      "  )     , &     ",
      "  )   %%%%%%%%% ",
      "  )  (%%%%%%%%% ",
      "  )   %%%%%%%%% ",
      "  )   %%%%%%%%% ",
      "  )   %%%%%%%%% ",
      "&&&&&&%%%%%%%%% ",
      "      %%%%%%%%% ",
      "      %%%%%%%%% ",
      "      %%%%%%%%% ",
      "                ",
      "                ",
      "                ",
      "                ",
      "                "
    ],
    [
      "  )       &     ",
      "  )     * &     ",
      "  )   %%%%%%%%% ",
      "  )   %%%%%%%%% ",
      "  )   %%%%%%%%% ",
      "  )   %%%%%%%%% ",
      "  )   %%%%%%%%% ",
      "&&&&&&%%%%%%%%% ",
      "      %%%%%%%%% ",
      "      %%%%%%%%% ",
      "      %%%%%%%%% ",
      "                ",
      "                ",
      "                ",
      "                ",
      "                "
    ],
    [
      "  )       &     ",
      "  )       &     ",
      "  )   %%%%%%%%% ",
      "  )   %%%%%%%%% ",
      "  )   %%%%%%%%% ",
      "  )   %%%%%%%%% ",
      "  )   %%%%%%%%% ",
      "&&&&&&%%%%%%%%% ",
      "      %%%%%%%%% ",
      "      %%%%%%%%% ",
      "      %%%%%%%%% ",
      "                ",
      "                ",
      "                ",
      "                ",
      "                "
    ],
    [
      "  )       &     ",
      "  )       &     ",
      "  )       &     ",
      "  )       &     ",
      "  )       &     ",
      "  )       &     ",
      "  )       &     ",
      "&&&&&&&&&&&     ",
      "                ",
      "                ",
      "                ",
      "                ",
      "                ",
      "                ",
      "                ",
      "                "
    ]
  ],
  "palette": {
    "palette": [
      {
        "char": "!",
        "block": "minecraft:coarse_dirt"
      },
      {
        "char": "$",
        "block": "minecraft:dark_oak_stairs[facing=south,half=bottom,shape=straight,waterlogged=false]"
      },
      {
        "char": "%",
        "block": "minecraft:gravel"
      },
      {
        "char": "&",
        "block": "minecraft:mud_bricks"
      },
      {
        "char": "'",
        "block": "minecraft:oak_planks"
      },
      {
        "char": "(",
        "block": "minecraft:spruce_slab[type=bottom,waterlogged=false]"
      },
      {
        "char": ")",
        "block": "minecraft:stripped_dark_oak_wood"
      },
      {
        "char": "*",
        "block": "supplementaries:item_shelf"
      },
      {
        "char": "+",
        "block": "tfmg:asphalt"
      },
      {
        "char": ",",
        "block": "the_wasteland_reworked:radio"
      }
    ]
  }
}
