{
  "xsize": 16,
  "zsize": 16,
  "slices": [
    [
      " ***%%$*********",
      " *%%$***********",
      " %$*************",
      " ***************",
      " **************%",
      " $***********%%$",
      " **********%%$**",
      " ********%%$****",
      " ******%%$******",
      " *$**%%$****$***",
      "                ",
      "                ",
      "                ",
      "                ",
      "                ",
      "                "
    ],
    [
      "    ''''''''''''",
      "    ''''''''''''",
      "    ''''''''''''",
      "    ''''''''''''",
      "    ''''''''''''",
      "    ''''''''''''",
      "    ''''''''''''",
      "    ''''''''''''",
      "                ",
      "                ",
      "                ",
      "                ",
      "                ",
      "                ",
      "                ",
      "                "
    ],
    [
      "    &           ",
      "    &           ",
      "    & ! ()      ",
      "    &           ",
      "    &           ",
      "    &           ",
      "    &           ",
      "    &&&&&&&&&&&&",
      "                ",
      "                ",
      "                ",
      "                ",
      "                ",
      "                ",
      "                ",
      "                "
    ],
    [
      "    &           ",
      "    &           ",
      "    &           ",
      "    &           ",
      "    &           ",
      "    &           ",
      "    &           ",
      "    &&&&&&&&&&&&",
      "                ",
      "                ",
      "                ",
      "                ",
      "                ",
      "                ",
      "                ",
      "                "
    ],
    [
      "    &           ",
      "    &           ",
      "    &           ",
      "    &           ",
      "    &           ",
      "    &           ",
      "    &           ",
      "    &&&&&&&&&&&&",
      "                ",
      "                ",
      "                ",
      "                ",
      "                ",
      "                ",
      "                ",
      "                "
    ],
    [
      "    &           ",
      "    &           ",
      "    &           ",
      "    &           ",
      "    &           ",
      "    &           ",
      "    &           ",
      "    &&&&&&&&&&&&",
      "                ",
      "                ",
      "                ",
      "                ",
      "                ",
      "                ",
      "                ",
      "                "
    ]
  ],
  "palette": {
    "palette": [
      {
        "char": "!",
        "block": "kubejs:ruined_blast_furnace[facing=south]"
      },
      {
        "char": "$",
        "block": "minecraft:coarse_dirt"
      },
      {
        "char": "%",
        "block": "minecraft:gravel"
      },
      {
        "char": "&",
        "block": "minecraft:mud_bricks"
      },
      {
        "char": "'",
        "block": "minecraft:oak_planks"
      },
      {
        "char": "(",
        "block": "minecraft:spawner",
        "tag": {
          "id": "minecraft:mob_spawner",
          "Delay": 200,
          "MinSpawnDelay": 240,
          "MaxSpawnDelay": 720,
          "SpawnCount": 1,
          "MaxNearbyEntities": 4,
          "RequiredPlayerRange": 14,
          "SpawnRange": 4,
          "SpawnData": {
            "entity": {
              "id": "minecraft:zombie"
            }
          },
          "SpawnPotentials": [
            {
              "weight": 1,
              "data": {
                "entity": {
                  "id": "minecraft:zombie"
                }
              }
            }
          ]
        }
      },
      {
        "char": ")",
        "block": "kubejs:ruined_cauldron"
      },
      {
        "char": "*",
        "block": "tfmg:asphalt"
      }
    ]
  }
}
