{
  "xsize": 16,
  "zsize": 16,
  "slices": [
    [
      "          (     ",
      "          (     ",
      "          (     ",
      "          (     ",
      "          (     ",
      "          (     ",
      "          (     ",
      "(((((((((((     ",
      "                ",
      "                ",
      "                ",
      "                ",
      "                ",
      "                ",
      "                ",
      "                "
    ],
    [
      "          (     ",
      "          (     ",
      "          (     ",
      "          (     ",
      "          (     ",
      "          (     ",
      "          (     ",
      "(((((((((((     ",
      "                ",
      "                ",
      "                ",
      "                ",
      "                ",
      "                ",
      "                ",
      "                "
    ],
    [
      "*         (     ",
      "          (     ",
      "          (     ",
      "          (     ",
      "          (     ",
      "          (     ",
      "          (     ",
      "(((((((((((     ",
      "                ",
      "                ",
      "                ",
      "                ",
      "                ",
      "                ",
      "                ",
      "                "
    ],
    [
      " )))))))))))    ",
      "))))))))))))    ",
      "))))))))))))    ",
      "))))))))))))    ",
      "))))))))))))    ",
      "))))))))))))    ",
      ")))))))))))))   ",
      "((())))))))))   ",
      "   .)))))))).   ",
      "   ))))))))))   ",
      "                ",
      "                ",
      "                ",
      "                ",
      "                ",
      "                "
    ],
    [
      "    /      1    ",
      "    ,      1    ",
      "  0 + &    1    ",
      "    / %    1    ",
      "    /   !  1    ",
      "    /      1    ",
      "111111111111    ",
      "$$$$$$$$$$$     ",
      "   .        .   ",
      "                ",
      "                ",
      "                ",
      "                ",
      "                ",
      "                ",
      "                "
    ],
    [
      "    /      1    ",
      "    -      1    ",
      "    /      1    ",
      "    '      1    ",
      "    /      1    ",
      "    /      1    ",
      "111111111111    ",
      "                ",
      "   .        .   ",
      "                ",
      "                ",
      "                ",
      "                ",
      "                ",
      "                ",
      "                "
    ]
  ],
  "palette": {
    "palette": [
      {
        "char": "!",
        "block": "minecraft:chest[facing=north,type=single,waterlogged=false]",
        "tag": {
          "id": "minecraft:chest",
          "LootTable": "infinite_domain:chests/wasteland_home"
        }
      },
      {
        "char": "$",
        "block": "minecraft:dark_prismarine"
      },
      {
        "char": "%",
        "block": "minecraft:gray_bed[facing=north,occupied=false,part=foot]"
      },
      {
        "char": "&",
        "block": "minecraft:gray_bed[facing=north,occupied=false,part=head]"
      },
      {
        "char": "'",
        "block": "minecraft:lever[face=wall,facing=south,powered=false]"
      },
      {
        "char": "(",
        "block": "minecraft:mud_bricks"
      },
      {
        "char": ")",
        "block": "minecraft:oak_planks"
      },
      {
        "char": "*",
        "block": "minecraft:oak_stairs[facing=south,half=bottom,shape=straight,waterlogged=false]"
      },
      {
        "char": "+",
        "block": "minecraft:quartz_stairs[facing=north,half=bottom,shape=straight,waterlogged=false]"
      },
      {
        "char": ",",
        "block": "minecraft:spruce_door[facing=east,half=lower,hinge=left,open=false,powered=false]"
      },
      {
        "char": "-",
        "block": "minecraft:spruce_door[facing=east,half=upper,hinge=left,open=false,powered=false]"
      },
      {
        "char": ".",
        "block": "minecraft:stripped_spruce_log[axis=y]"
      },
      {
        "char": "/",
        "block": "minecraft:stripped_spruce_wood"
      },
      {
        "char": "0",
        "block": "kubejs:ruined_cauldron"
      },
      {
        "char": "1",
        "block": "the_wasteland_reworked:decayed_planks"
      }
    ]
  }
}
