{
  "xsize": 16,
  "zsize": 16,
  "slices": [
    [
      "   '&&'&........",
      "   &&'&&........",
      "   &'&&'........",
      "   '&&'&........",
      "   &&'&&........",
      "   &'&&'........",
      "   '&&'&........",
      "   &&'&&........",
      "   &'&&'........",
      "   '&&'&........",
      "   &&'&&........",
      "   &'&&'........",
      "   '&&'&        ",
      "   &&'&&        ",
      "   &'&&'........",
      "   '&&'&........"
    ],
    [
      ",,,'&&'&!       ",
      ",,,&&'&&!       ",
      ",,,&'&&'        ",
      ",,,'&&&&&&&&    ",
      ",,,&&'&&&&&&    ",
      ",,,&'&&&&&&&    ",
      ",,,'&&&&&&&&    ",
      ",,,&&'&&        ",
      ",,,&'&&'! $     ",
      ",,,'&&'&!       ",
      ",,,&&'&&!       ",
      ",,,&'&&'!!!!!!!!",
      ",,,'&&'&        ",
      ",,,&&'&&        ",
      ",,,&'&&'!!!!!!!!",
      ",,,'&&'&!       "
    ],
    [
      "    &&'&!       ",
      "&&&&&'&&!       ",
      "&&&& &&'        ",
      "&&&&&&&&&&&&    ",
      "&&&&&'&&&&&&    ",
      "&&&&'&&&&&&&    ",
      "&&&&&&&&&&&&    ",
      "&&&&&'&&        ",
      "    '&&'!       ",
      "    &&'&!       ",
      "    &'&&!       ",
      "     &&'!!!!!!!!",
      "    &&'&        ",
      "    &'&&        ",
      "    '&&'!!!!!!!!",
      "    &&'&!       "
    ],
    [
      "     &'&!       ",
      "     '&&!       ",
      "     &&'        ",
      "     &'&        ",
      "     '&&        ",
      "     &&'        ",
      "     &'&        ",
      "      &&        ",
      "     &&'!       ",
      "     &'&!       ",
      "     '&&!       ",
      "     &&'!!!!!!!!",
      "     &'&        ",
      "     '&&        ",
      "     &&'!!!!!!!!",
      "     &'&!       "
    ],
    [
      "      '&))))))))",
      "      &&))))))))",
      "      &'))))))))",
      "       &))))))))",
      "      &&))))))))",
      "      &'))))))))",
      "      '&))))))))",
      "      &&))))))))",
      "      & ))))))))",
      "      '&))))))))",
      "      &&))))))))",
      "      &'))))))))",
      "       &++++++++",
      "      &&++++++++",
      "      &'........",
      "      '&........"
    ],
    [
      "        (      /",
      "        (      /",
      "        (      /",
      "        (      /",
      "        ( %% *%/",
      "        (      /",
      "        (      /",
      "        (      /",
      "        (      /",
      "        (       ",
      "        (       ",
      "        ((((((((",
      "        (     ( ",
      "        -     - ",
      "        --------",
      "        -       "
    ]
  ],
  "palette": {
    "palette": [
      {
        "char": "!",
        "block": "immersiveengineering:concrete_reinforced"
      },
      {
        "char": "$",
        "block": "immersiveengineering:metal_barrel"
      },
      {
        "char": "%",
        "block": "minecraft:bookshelf"
      },
      {
        "char": "&",
        "block": "minecraft:coarse_dirt"
      },
      {
        "char": "'",
        "block": "minecraft:gravel"
      },
      {
        "char": "(",
        "block": "minecraft:light_gray_concrete"
      },
      {
        "char": ")",
        "block": "minecraft:polished_andesite"
      },
      {
        "char": "*",
        "block": "minecraft:spawner",
        "tag": {
          "id": "minecraft:mob_spawner",
          "Delay": 200,
          "MinSpawnDelay": 240,
          "MaxSpawnDelay": 720,
          "SpawnCount": 2,
          "MaxNearbyEntities": 7,
          "RequiredPlayerRange": 14,
          "SpawnRange": 4,
          "SpawnData": {
            "entity": {
              "id": "the_wasteland_reworked:ghoul"
            }
          },
          "SpawnPotentials": [
            {
              "weight": 1,
              "data": {
                "entity": {
                  "id": "the_wasteland_reworked:ghoul"
                }
              }
            }
          ]
        }
      },
      {
        "char": "+",
        "block": "minecraft:stone_bricks"
      },
      {
        "char": ",",
        "block": "tfmg:asphalt"
      },
      {
        "char": "-",
        "block": "tfmg:cinder_block"
      },
      {
        "char": ".",
        "block": "tfmg:factory_floor"
      },
      {
        "char": "/",
        "block": "zvhouses:stone_brick_countertop"
      }
    ]
  }
}
