{
  "xsize": 16,
  "zsize": 16,
  "slices": [
    [
      "  00000000000000",
      "  00000000000000",
      "  00000000000000",
      "  00000000000000",
      "  00000000000000",
      "  00000000000000",
      "  00000000000000",
      "  00000000000000",
      "  00000000000000",
      "  00000000000000",
      "                ",
      "                ",
      "  00000000000000",
      "  00000000000000",
      "  00000000000000",
      "  00000000000000"
    ],
    [
      "  !             ",
      "  !             ",
      "  !             ",
      "  !             ",
      "  !            $",
      "  !            $",
      "  ! %          $",
      "  !             ",
      "  !             ",
      "  !!!!!!!!!!!!!!",
      "                ",
      "                ",
      "  !!!!!!!!!!!!!!",
      "  !             ",
      "  !             ",
      "  !  +$$        "
    ],
    [
      "  !             ",
      "  !             ",
      "  !             ",
      "  !             ",
      "  !            $",
      "  !            $",
      "  !            $",
      "  !             ",
      "  !             ",
      "  !!!!!!!!!!!!!!",
      "                ",
      "                ",
      "  !!!!!!!!!!!!!!",
      "  !             ",
      "  !             ",
      "  !   $$        "
    ],
    [
      "  !             ",
      "  !             ",
      "  !             ",
      "  !             ",
      "  !             ",
      "  !             ",
      "  !             ",
      "  !             ",
      "  !             ",
      "  !!!!!!!!!!!!!!",
      "                ",
      "                ",
      "  !!!!!!!!!!!!!!",
      "  !             ",
      "  !             ",
      "  !             "
    ],
    [
      "..((((((((((((((",
      "..((((((((((((((",
      "..((((((((((((((",
      "/.((((((((((((((",
      "..((((((((((((((",
      "..((((((((((((((",
      "..((((((((((((((",
      "..((((((((((((((",
      "..((((((((((((((",
      "..((((((((((((((",
      "................",
      "................",
      "..--------------",
      "..--------------",
      "..--------------",
      "..--------------"
    ],
    [
      "  &         &1  ",
      "  ,  $$$$$$ &1  ",
      "  &  $$$$$$ &1 )",
      "/ &  $$$$$$ &1  ",
      "  &  $$$$$$ &1  ",
      "  &  $$$$$$ &1  ",
      "  &  $$$$$$ &1  ",
      "  &         &   ",
      "  &         &   ",
      "  &&&&&&&&&&&&&&",
      "  &     &     & ",
      "  '     '     ' ",
      "  ''''''''''''''",
      "  '         '   ",
      "  '         '   ",
      "  '  *      '   "
    ]
  ],
  "palette": {
    "palette": [
      {
        "char": "!",
        "block": "immersiveengineering:concrete_reinforced"
      },
      {
        "char": "$",
        "block": "immersiveengineering:crate"
      },
      {
        "char": "%",
        "block": "immersiveengineering:metal_barrel"
      },
      {
        "char": "&",
        "block": "minecraft:bricks"
      },
      {
        "char": "'",
        "block": "minecraft:mud_bricks"
      },
      {
        "char": "(",
        "block": "minecraft:oak_planks"
      },
      {
        "char": ")",
        "block": "minecraft:oak_stairs[facing=east,half=bottom,shape=straight,waterlogged=false]"
      },
      {
        "char": "*",
        "block": "minecraft:oak_stairs[facing=south,half=bottom,shape=straight,waterlogged=false]"
      },
      {
        "char": "+",
        "block": "minecraft:polished_andesite_stairs[facing=south,half=bottom,shape=straight,waterlogged=false]"
      },
      {
        "char": ",",
        "block": "minecraft:spruce_door[facing=west,half=lower,hinge=left,open=false,powered=false]"
      },
      {
        "char": "-",
        "block": "minecraft:spruce_planks"
      },
      {
        "char": ".",
        "block": "minecraft:stone_bricks"
      },
      {
        "char": "/",
        "block": "minecraft:stripped_dark_oak_log[axis=y]"
      },
      {
        "char": "0",
        "block": "tfmg:factory_floor"
      },
      {
        "char": "1",
        "block": "zvhouses:spruce_countertop"
      }
    ]
  }
}
