{
  "xsize": 16,
  "zsize": 16,
  "slices": [
    [
      "                ",
      "             %%%",
      "        $    % %",
      "        $    % %",
      "        $    & &",
      "        $    & &",
      "        $    & &",
      "        $    & &",
      "        $    & &",
      "       ($&&&&&&&",
      "       ($&&&&&&&",
      "       ($&&&&&&&",
      "       ($&&&&&&&",
      "       ($&&&&&&&",
      "       ($&&&&&&&",
      "       ($&&&&&&&"
    ],
    [
      "                ",
      "             +  ",
      "        $       ",
      "        $    $ $",
      "        $       ",
      "        $       ",
      "        $       ",
      "        $       ",
      "        $       ",
      "        $  '  , ",
      "        $     ) ",
      "        $     , ",
      "        $     , ",
      "        $     , ",
      "        $     , ",
      "        $,,,,,,,"
    ],
    [
      "                ",
      "                ",
      "        $       ",
      "        $    $ $",
      "        $       ",
      "        $       ",
      "        !       ",
      "        !       ",
      "        $       ",
      "        $       ",
      "        $     * ",
      "        $     , ",
      "        !     , ",
      "        !     , ",
      "        $     , ",
      "        $,,,,,,,"
    ],
    [
      "                ",
      "                ",
      "        $       ",
      "        $    $ $",
      "        $       ",
      "        $       ",
      "        !       ",
      "        !       ",
      "        $       ",
      "        $       ",
      "        $     , ",
      "        $     , ",
      "        !     , ",
      "        !     , ",
      "        $     , ",
      "        $,,,,,,,"
    ],
    [
      "                ",
      "                ",
      "        $    ( (",
      "        $    $ $",
      "        $       ",
      "        $       ",
      "        $       ",
      "        $       ",
      "        $       ",
      "        $       ",
      "        $     , ",
      "        $     , ",
      "        $     , ",
      "        $     , ",
      "        $     , ",
      "        $,,,,,,,"
    ],
    [
      "                ",
      "                ",
      "        $       ",
      "        $    $ $",
      "        $       ",
      "        $       ",
      "        $       ",
      "        $       ",
      "        $       ",
      "        $       ",
      "        $       ",
      "        $       ",
      "        $       ",
      "        $       ",
      "        $       ",
      "        $,,,,,,,"
    ]
  ],
  "palette": {
    "palette": [
      {
        "char": "!",
        "block": "create:framed_glass"
      },
      {
        "char": "$",
        "block": "minecraft:light_gray_concrete"
      },
      {
        "char": "%",
        "block": "minecraft:oak_slab[type=top,waterlogged=false]"
      },
      {
        "char": "&",
        "block": "minecraft:polished_andesite"
      },
      {
        "char": "'",
        "block": "minecraft:smoker[facing=north,lit=false]"
      },
      {
        "char": "(",
        "block": "minecraft:smooth_stone_slab[type=top,waterlogged=false]"
      },
      {
        "char": ")",
        "block": "minecraft:spruce_door[facing=east,half=lower,hinge=left,open=false,powered=false]"
      },
      {
        "char": "*",
        "block": "minecraft:spruce_door[facing=east,half=upper,hinge=left,open=false,powered=false]"
      },
      {
        "char": "+",
        "block": "minecraft:stripped_oak_log[axis=y]"
      },
      {
        "char": ",",
        "block": "minecraft:stripped_spruce_wood"
      }
    ]
  }
}
