{
  "xsize": 16,
  "zsize": 16,
  "slices": [
    [
      "        $       ",
      "        $       ",
      "        $       ",
      "        $       ",
      "        $       ",
      "        $       ",
      "        $       ",
      "        $       ",
      "        $       ",
      "        $       ",
      "        $       ",
      "        $$$$$$$$",
      "        $     $ ",
      "        -     - ",
      "        --------",
      "        -       "
    ],
    [
      "       ($&&&&&&&",
      "       ($&&&&&&&",
      "       ($&&&&&&&",
      "       ($&&&&&&&",
      "       ($&&&&&&&",
      "       ($&&&&&&&",
      "       ($&&&&&&&",
      "       ($&&&&&&&",
      "       ($&&&&&&&",
      "       ($&&&&&&&",
      "       ($&&&&&&&",
      "       ($$$$$$$$",
      "        $     $ ",
      "                ",
      "        ,,,,,,,,",
      "        ,,,,,,,,"
    ],
    [
      "        $     + ",
      "        $     + ",
      "        $     + ",
      "        $  %  + ",
      "        $     ) ",
      "        $  '  + ",
      "        $     + ",
      "        $     + ",
      "        $     + ",
      "        $     + ",
      "        $     + ",
      "        $$$$$$$$",
      "        $     $ ",
      "                ",
      "        --------",
      "                "
    ],
    [
      "        $     + ",
      "        $     + ",
      "        !     + ",
      "        !     + ",
      "        $     * ",
      "        $     + ",
      "        $     + ",
      "        $     + ",
      "        !     + ",
      "        !     + ",
      "        $     + ",
      "        $$$!!$$$",
      "        $     $ ",
      "                ",
      "                ",
      "                "
    ],
    [
      "        $     + ",
      "        $     + ",
      "        !     + ",
      "        !     + ",
      "        $     + ",
      "        $     + ",
      "        $     + ",
      "        $     + ",
      "        !     + ",
      "        !     + ",
      "        $     + ",
      "        $$$!!$$$",
      "        $     $ ",
      "                ",
      "                ",
      "                "
    ],
    [
      "        $     + ",
      "        $     + ",
      "        $     + ",
      "        $     + ",
      "        $     + ",
      "        $     + ",
      "        $     + ",
      "        $     + ",
      "        $     + ",
      "        $     + ",
      "        $     + ",
      "        $$$$$$$$",
      "        $ (((($(",
      "                ",
      "                ",
      "                "
    ]
  ],
  "palette": {
    "palette": [
      {
        "char": "!",
        "block": "create:framed_glass"
      },
      {
        "char": "$",
        "block": "minecraft:light_gray_concrete"
      },
      {
        "char": "%",
        "block": "minecraft:oak_stairs[facing=south,half=bottom,shape=straight,waterlogged=false]"
      },
      {
        "char": "&",
        "block": "minecraft:polished_andesite"
      },
      {
        "char": "'",
        "block": "kubejs:ruined_smoker[facing=north]"
      },
      {
        "char": "(",
        "block": "minecraft:smooth_stone_slab[type=top,waterlogged=false]"
      },
      {
        "char": ")",
        "block": "minecraft:spruce_door[facing=east,half=lower,hinge=left,open=false,powered=false]"
      },
      {
        "char": "*",
        "block": "minecraft:spruce_door[facing=east,half=upper,hinge=left,open=false,powered=false]"
      },
      {
        "char": "+",
        "block": "minecraft:stripped_spruce_wood"
      },
      {
        "char": ",",
        "block": "minecraft:weathered_cut_copper"
      },
      {
        "char": "-",
        "block": "tfmg:cinder_block"
      }
    ]
  }
}
