{
  "xsize": 16,
  "zsize": 16,
  "slices": [
    [
      "(((((((((((     ",
      "(((((((((((     ",
      "(((((((((((     ",
      "(((((((((((     ",
      "(((((((((((     ",
      "                ",
      "                ",
      "                ",
      "                ",
      "                ",
      "                ",
      "                ",
      "                ",
      "                ",
      "                ",
      "                "
    ],
    [
      "     $$$  !     ",
      "     $$$  !     ",
      "          !     ",
      "          !     ",
      "!!!!!!!!!!!     ",
      "                ",
      "                ",
      "                ",
      "                ",
      "                ",
      "                ",
      "                ",
      "                ",
      "                ",
      "                ",
      "                "
    ],
    [
      "     $$$  !     ",
      "     $$$  !     ",
      "          !     ",
      "          !     ",
      "!!!!!!!!!!!     ",
      "                ",
      "                ",
      "                ",
      "                ",
      "                ",
      "                ",
      "                ",
      "                ",
      "                ",
      "                ",
      "                "
    ],
    [
      "          !     ",
      "          !     ",
      "          !     ",
      "          !     ",
      "!!!!!!!!!!!     ",
      "                ",
      "                ",
      "                ",
      "                ",
      "                ",
      "                ",
      "                ",
      "                ",
      "                ",
      "                ",
      "                "
    ],
    [
      "(((((((((((&&   ",
      "(((((((((((&&   ",
      "(((((((((((&&   ",
      "(((((((((((&&   ",
      "(((((((((((&&   ",
      "&&&&&&&&&&&&&   ",
      "&&&&&&&&&&&&&   ",
      "                ",
      "                ",
      "                ",
      "                ",
      "                ",
      "                ",
      "                ",
      "                ",
      "                "
    ],
    [
      "' %%%%%%% '     ",
      "' %%%%%%% '     ",
      "'         '     ",
      "'         '     ",
      "'''''''''''     ",
      "    '     '     ",
      "                ",
      "                ",
      "                ",
      "                ",
      "                ",
      "                ",
      "                ",
      "                ",
      "                ",
      "                "
    ]
  ],
  "palette": {
    "palette": [
      {
        "char": "!",
        "block": "immersiveengineering:concrete_reinforced"
      },
      {
        "char": "$",
        "block": "immersiveengineering:crate"
      },
      {
        "char": "%",
        "block": "immersiveengineering:sheetmetal_steel"
      },
      {
        "char": "&",
        "block": "minecraft:stone_bricks"
      },
      {
        "char": "'",
        "block": "tfmg:cinder_block"
      },
      {
        "char": "(",
        "block": "tfmg:factory_floor"
      }
    ]
  }
}
