{
  "xsize": 16,
  "zsize": 16,
  "slices": [
    [
      "((((((((((((((((",
      "((((((((((((((((",
      "((((((((((((((((",
      "((((((((((((((((",
      "((((((((((((((((",
      "((((((((((((((((",
      "((((((((((((((((",
      "((((((((((((((((",
      "((((((((((((((((",
      "((((((((((((((((",
      "((((((((((((((((",
      "((((((((((((((((",
      "((((((((((((((((",
      "((((((((((((((((",
      "((((%%((((((((((",
      "((%%$((((((((((("
    ],
    [
      "&               ",
      "&               ",
      "&               ",
      "&               ",
      "&               ",
      "&               ",
      "&               ",
      "&               ",
      "&               ",
      "&               ",
      "&               ",
      "!               ",
      "!               ",
      "!               ",
      "''''''''''''''''",
      "''''''''''''''''"
    ],
    [
      ")               ",
      ")               ",
      ")               ",
      ")               ",
      ")               ",
      ")               ",
      ")               ",
      ")               ",
      ")               ",
      ")               ",
      ")               ",
      "!               ",
      "!               ",
      "!               ",
      "''''''''''''''''",
      "''''''''''''''''"
    ],
    [
      ")               ",
      ")               ",
      ")               ",
      ")               ",
      ")               ",
      ")               ",
      ")               ",
      ")               ",
      ")               ",
      ")               ",
      ")               ",
      "!               ",
      "!               ",
      "!               ",
      "''''''''''''''''",
      "''''''''''''''''"
    ],
    [
      ")               ",
      ")               ",
      ")               ",
      ")               ",
      ")               ",
      ")               ",
      ")               ",
      ")               ",
      ")               ",
      ")               ",
      ")               ",
      "!               ",
      "!               ",
      "!               ",
      "''''''''''''''''",
      "''''''''''''''''"
    ],
    [
      ")               ",
      ")               ",
      ")               ",
      ")               ",
      ")               ",
      ")               ",
      ")               ",
      ")               ",
      ")               ",
      ")               ",
      ")               ",
      "!               ",
      "!               ",
      "!               ",
      "''''''''''''''''",
      "''''''''''''''''"
    ]
  ],
  "palette": {
    "palette": [
      {
        "char": "!",
        "block": "immersiveengineering:concrete_reinforced"
      },
      {
        "char": "$",
        "block": "minecraft:coarse_dirt"
      },
      {
        "char": "%",
        "block": "minecraft:gravel"
      },
      {
        "char": "&",
        "block": "minecraft:smooth_stone"
      },
      {
        "char": "'",
        "block": "minecraft:stone_bricks"
      },
      {
        "char": "(",
        "block": "tfmg:asphalt"
      },
      {
        "char": ")",
        "block": "tfmg:cinder_block"
      }
    ]
  }
}
