{
  "xsize": 16,
  "zsize": 16,
  "slices": [
    [
      "&&& !           ",
      "    !           ",
      "    %           ",
      "    !           ",
      "    !           ",
      "    !           ",
      "&&& !           ",
      "    %           ",
      "    $           ",
      "    %           ",
      "    !           ",
      "    !           ",
      "&&& !           ",
      "    !           ",
      "    %           ",
      "    !           "
    ],
    [
      "    !           ",
      "    !           ",
      "    %           ",
      "    !           ",
      "    !           ",
      "    !           ",
      "    !           ",
      "    %           ",
      "                ",
      "    %           ",
      "    !           ",
      "    !           ",
      "    !           ",
      "    !           ",
      "    %           ",
      "    !           "
    ],
    [
      "    !           ",
      "    !           ",
      "    %           ",
      "    !           ",
      "    !           ",
      "    !           ",
      "    !           ",
      "    %           ",
      "    %           ",
      "    %           ",
      "    !           ",
      "    !           ",
      "    !           ",
      "    !           ",
      "    %           ",
      "    !           "
    ],
    [
      "    %''''       ",
      "    %''''       ",
      "    %''''       ",
      "    %''''       ",
      "    %''''       ",
      "    %''''       ",
      "    %''''       ",
      "    %''''       ",
      "    %''''       ",
      "    %''''       ",
      "    %''''       ",
      "    %''''       ",
      "    %''''       ",
      "    %''''       ",
      "    %''''       ",
      "    %''''       "
    ],
    [
      "    %           ",
      "    %           ",
      "    %           ",
      "    %           ",
      "    %           ",
      "    %           ",
      "    %           ",
      "    %           ",
      "    %           ",
      "    %           ",
      "    %           ",
      "    %           ",
      "    %           ",
      "    %           ",
      "    %           ",
      "    %           "
    ],
    [
      "((((%'          ",
      "((((%'          ",
      "((((%'          ",
      "((((%'          ",
      "((((%'          ",
      "((((%'          ",
      "((((%'          ",
      "((((%'          ",
      "((((%'          ",
      "((((%'          ",
      "((((%'          ",
      "((((%'          ",
      "((((%'          ",
      "((((%'          ",
      "((((%'          ",
      "((((%'          "
    ]
  ],
  "palette": {
    "palette": [
      {
        "char": "!",
        "block": "create:framed_glass"
      },
      {
        "char": "$",
        "block": "minecraft:dark_oak_door[facing=east,half=upper,hinge=left,open=false,powered=false]"
      },
      {
        "char": "%",
        "block": "minecraft:mud_bricks"
      },
      {
        "char": "&",
        "block": "minecraft:scaffolding"
      },
      {
        "char": "'",
        "block": "minecraft:smooth_stone_slab[type=top,waterlogged=false]"
      },
      {
        "char": "(",
        "block": "minecraft:spruce_planks"
      }
    ]
  }
}
