{
  "xsize": 16,
  "zsize": 16,
  "slices": [
    [
      "        --------",
      "        --------",
      "        --------",
      "        --------",
      "        --------",
      "        --------",
      "        --------",
      "        --------",
      "        --------",
      "        --------",
      "        --------",
      "        --------",
      "                ",
      "                ",
      "        --------",
      "        --------"
    ],
    [
      "        !       ",
      "        !       ",
      "        !       ",
      "        !       ",
      "        !       ",
      "        !       ",
      "        !       ",
      "        !       ",
      "        ! $     ",
      "        !       ",
      "        !       ",
      "        !!!!!!!!",
      "                ",
      "                ",
      "        !!!!!!!!",
      "        !       "
    ],
    [
      "        !       ",
      "        !       ",
      "        !       ",
      "        !       ",
      "        !       ",
      "        !       ",
      "        !       ",
      "        !       ",
      "        !       ",
      "        !       ",
      "        !       ",
      "        !!!!!!!!",
      "                ",
      "                ",
      "        !!!!!!!!",
      "        !       "
    ],
    [
      "        !       ",
      "        !       ",
      "        !       ",
      "        !       ",
      "        !       ",
      "        !       ",
      "        !       ",
      "        !       ",
      "        !       ",
      "        !       ",
      "        !       ",
      "        !!!!!!!!",
      "                ",
      "                ",
      "        !!!!!!!!",
      "        !       "
    ],
    [
      "+++(((((''''''''",
      "+++(((((''''''''",
      "+++(((((''''''''",
      "+++(((((''''''''",
      "+++(((((''''''''",
      "+++(((((''''''''",
      "+++(((((''''''''",
      "+++(((((''''''''",
      "+++(((((''''''''",
      "+++((*((''''''''",
      "+++(((((''''''''",
      "+++(((((''''''''",
      "+++((((())))))))",
      "+++((((())))))))",
      "+++(((((--------",
      "+++(((((--------"
    ],
    [
      "        &      .",
      "        &      .",
      "        &      .",
      "        &      .",
      "        & %% %%.",
      "        &      .",
      "        &      .",
      "        &      .",
      "        &      .",
      "     *  &       ",
      "        &       ",
      "        &&&&&&&&",
      "        &     & ",
      "        ,     , ",
      "        ,,,,,,,,",
      "        ,       "
    ]
  ],
  "palette": {
    "palette": [
      {
        "char": "!",
        "block": "immersiveengineering:concrete_reinforced"
      },
      {
        "char": "$",
        "block": "immersiveengineering:metal_barrel"
      },
      {
        "char": "%",
        "block": "minecraft:bookshelf"
      },
      {
        "char": "&",
        "block": "minecraft:light_gray_concrete"
      },
      {
        "char": "'",
        "block": "minecraft:polished_andesite"
      },
      {
        "char": "(",
        "block": "minecraft:smooth_stone"
      },
      {
        "char": ")",
        "block": "minecraft:stone_bricks"
      },
      {
        "char": "*",
        "block": "minecraft:stripped_dark_oak_log[axis=y]"
      },
      {
        "char": "+",
        "block": "tfmg:asphalt"
      },
      {
        "char": ",",
        "block": "tfmg:cinder_block"
      },
      {
        "char": "-",
        "block": "tfmg:factory_floor"
      },
      {
        "char": ".",
        "block": "zvhouses:stone_brick_countertop"
      }
    ]
  }
}
