{
  "xsize": 16,
  "zsize": 16,
  "slices": [
    [
      "                ",
      "                ",
      "                ",
      "        --------",
      "        --------",
      "        --------",
      "        --------",
      "        --------",
      "        --------",
      "        --------",
      "        --------",
      "        --------",
      "        --------",
      "        --------",
      "        --------",
      "        --------"
    ],
    [
      "                ",
      "                ",
      "                ",
      "        !!!!!!!!",
      "        !       ",
      "        !       ",
      "        !  $$$  ",
      "        !  $$$  ",
      "        !  $$$  ",
      "        !       ",
      "        !       ",
      "        !       ",
      "        !       ",
      "        !       ",
      "        !       ",
      "        !!!!!!!!"
    ],
    [
      "                ",
      "                ",
      "                ",
      "        !!!!!!!!",
      "        !       ",
      "        !       ",
      "        !  $$$  ",
      "        !  $$$  ",
      "        !  $$$  ",
      "        !       ",
      "        !       ",
      "        !       ",
      "        !       ",
      "        !       ",
      "        !       ",
      "        !!!!!!!!"
    ],
    [
      "                ",
      "                ",
      "                ",
      "        !!!!!!!!",
      "        !       ",
      "        !       ",
      "        !       ",
      "        !       ",
      "        !       ",
      "        !       ",
      "        !       ",
      "        !       ",
      "        !       ",
      "        !       ",
      "        !       ",
      "        !!!!!!!!"
    ],
    [
      ",,,)))))********",
      ",,,)))))********",
      ",,,)))))********",
      ",,,)))))((((((((",
      ",,,)))))((((((((",
      ",,,))+))((((((((",
      ",,,)))))((((((((",
      ",,,)))))((((((((",
      ",,,)))))((((((((",
      ",,,)))))((((((((",
      ",,,)))))((((((((",
      ",,,)))))((((((((",
      ",,,)))))((((((((",
      ",,,)))))((((((((",
      ",,,)))))((((((((",
      ",,,)))))(!!!!!!!"
    ],
    [
      "                ",
      "                ",
      "        '     ' ",
      "        ''''''''",
      "        '       ",
      "     +  '       ",
      "        '      .",
      "        '      .",
      "        ' %% %%.",
      "        '      .",
      "        '      .",
      "        '      .",
      "        '       ",
      "        '      .",
      "        ' %% %%.",
      "        &      ."
    ]
  ],
  "palette": {
    "palette": [
      {
        "char": "!",
        "block": "immersiveengineering:concrete_reinforced"
      },
      {
        "char": "$",
        "block": "immersiveengineering:crate"
      },
      {
        "char": "%",
        "block": "minecraft:bookshelf"
      },
      {
        "char": "&",
        "block": "minecraft:dark_oak_door[facing=west,half=lower,hinge=left,open=false,powered=false]"
      },
      {
        "char": "'",
        "block": "minecraft:light_gray_concrete"
      },
      {
        "char": "(",
        "block": "minecraft:polished_andesite"
      },
      {
        "char": ")",
        "block": "minecraft:smooth_stone"
      },
      {
        "char": "*",
        "block": "minecraft:stone_bricks"
      },
      {
        "char": "+",
        "block": "minecraft:stripped_dark_oak_log[axis=y]"
      },
      {
        "char": ",",
        "block": "tfmg:asphalt"
      },
      {
        "char": "-",
        "block": "tfmg:factory_floor"
      },
      {
        "char": ".",
        "block": "zvhouses:stone_brick_countertop"
      }
    ]
  }
}
