{
  "xsize": 16,
  "zsize": 16,
  "slices": [
    [
      "00000000000     ",
      "00000000000     ",
      "00000000000     ",
      "00000000000     ",
      "00000000000     ",
      "00000000000     ",
      "00000000000     ",
      "00000000000     ",
      "00000000000     ",
      "00000000000     ",
      "00000000000     ",
      "00000000000     ",
      "00000000000     ",
      "00000000000     ",
      "00000000000     ",
      "00000000000     "
    ],
    [
      "          !     ",
      "       )  !     ",
      "          !     ",
      "          !     ",
      "          !     ",
      "          !     ",
      "          !     ",
      "          !     ",
      "          !     ",
      "!!!!!!!+!!!     ",
      "          !     ",
      "          !     ",
      "          !     ",
      "      '   !     ",
      "          !     ",
      "     $$$  !     "
    ],
    [
      "          !     ",
      "          !     ",
      "       )  !     ",
      "          !     ",
      "          !     ",
      "          !     ",
      "          !     ",
      "          !     ",
      "          !     ",
      "!!!!!!!,!!!     ",
      "          !     ",
      "          !     ",
      "          !     ",
      "          !     ",
      "          !     ",
      "     $$$  !     "
    ],
    [
      "          !     ",
      "          !     ",
      "          !     ",
      "       )  !     ",
      "          !     ",
      "          !     ",
      "          !     ",
      "          !     ",
      "          !     ",
      "!!!!!!!!!!!     ",
      "          !     ",
      "          !     ",
      "          !     ",
      "          !     ",
      "          !     ",
      "          !     "
    ],
    [
      "00000000000--   ",
      "00000000000--   ",
      "0000000 000--   ",
      "0000000 000--   ",
      "0000000)000--   ",
      "00000000000--   ",
      "00000000000-.   ",
      "00000000000--   ",
      "00000000000--   ",
      "!!!!!!!!!!0--   ",
      "00000000000--   ",
      "00000000000--   ",
      "00000000000--   ",
      "00000000000--   ",
      "00000000000-.   ",
      "00000000000--   "
    ],
    [
      "/         /     ",
      "/      (  /     ",
      "/ &&&&    /     ",
      "/ &&&&    /     ",
      "/ &&&&    /     ",
      "/ &&&&    /     ",
      "* &&&&    / .   ",
      "/ &&&&    /     ",
      "/         /     ",
      "/////+/////     ",
      "/         /     ",
      "/         /     ",
      "/ %%%%%%% *     ",
      "/ %%%%%%% /     ",
      "/ %%%%%%% / .   ",
      "/ %%%%'%% /     "
    ]
  ],
  "palette": {
    "palette": [
      {
        "char": "!",
        "block": "immersiveengineering:concrete_reinforced"
      },
      {
        "char": "$",
        "block": "immersiveengineering:crate"
      },
      {
        "char": "%",
        "block": "immersiveengineering:sheetmetal_steel"
      },
      {
        "char": "&",
        "block": "minecraft:bookshelf"
      },
      {
        "char": "'",
        "block": "minecraft:chest[facing=west,type=single,waterlogged=false]",
        "tag": {
          "id": "minecraft:chest",
          "LootTable": "infinite_domain:chests/wasteland_office"
        }
      },
      {
        "char": "(",
        "block": "minecraft:oak_stairs[facing=south,half=bottom,shape=straight,waterlogged=false]"
      },
      {
        "char": ")",
        "block": "minecraft:polished_andesite_stairs[facing=south,half=bottom,shape=straight,waterlogged=false]"
      },
      {
        "char": "*",
        "block": "minecraft:spruce_door[facing=east,half=lower,hinge=left,open=false,powered=false]"
      },
      {
        "char": "+",
        "block": "minecraft:spruce_door[facing=south,half=lower,hinge=left,open=false,powered=false]"
      },
      {
        "char": ",",
        "block": "minecraft:spruce_door[facing=south,half=upper,hinge=left,open=false,powered=false]"
      },
      {
        "char": "-",
        "block": "minecraft:stone_bricks"
      },
      {
        "char": ".",
        "block": "minecraft:stripped_dark_oak_log[axis=y]"
      },
      {
        "char": "/",
        "block": "tfmg:cinder_block"
      },
      {
        "char": "0",
        "block": "tfmg:factory_floor"
      }
    ]
  }
}
