{
  "xsize": 16,
  "zsize": 16,
  "slices": [
    [
      "   %%'%%,,,,,,,,",
      "   %'%%',,,,,,,,",
      "   '%%'%,,,,,,,,",
      "   %%'%%,,,,,,,,",
      "   %'%%',,,,,,,,",
      "   '%%'%,,,,,,,,",
      "   %%'%%,,,,,,,,",
      "   %'%%',,,,,,,,",
      "   '%%'%,,,,,,,,",
      "   %%'%%,,,,,,,,",
      "   %'%%',,,,,,,,",
      "   '%%'%,,,,,,,,",
      "   %%'%%,,,,,,,,",
      "   %'%%',,,,,,,,",
      "   '%%'%,,,,,,,,",
      "   %%'%%,,,,,,,,"
    ],
    [
      "***%%'%%!       ",
      "***%'%%'!  $$$  ",
      "***'%%'%!  $$$  ",
      "***%%'%%!  $$$  ",
      "***%'%%'        ",
      "***'%%%%%%%%    ",
      "***%%'%%%%%%    ",
      "***%'%%%%%%%    ",
      "***'%%%%%%%%    ",
      "***%%'%% !!!!!!!",
      "***%'%%'!       ",
      "***'%%'%!       ",
      "***%%'%%!       ",
      "***%'%%'!       ",
      "***'%%'%!       ",
      "***%%'%%''''    "
    ],
    [
      "    %'%%!       ",
      "    '%%'!  $$$  ",
      "    %%'%!  $$$  ",
      "    %'%%!  $$$  ",
      "     %%'        ",
      "    %%%%%%%%    ",
      "%%%%%'%%%%%%    ",
      "%%%%%%%%%%%%    ",
      "%%%%%%%%%%%%    ",
      "%%%%%'%% !!!!!!!",
      "%%%%%%%'!       ",
      "%%%%%%'%!       ",
      "%%%%%'%%!       ",
      "%%%%%%%'!       ",
      "%%%%%%'%!       ",
      "    %'%%''''    "
    ],
    [
      "      %%!       ",
      "     %%'!       ",
      "     %'%!       ",
      "     '%%!       ",
      "     %%'        ",
      "     %'%        ",
      "     '%%        ",
      "     %%'        ",
      "     %'%        ",
      "      %% !!!!!!!",
      "     %%'!       ",
      "     %'%!       ",
      "     '%%!       ",
      "     %%'!       ",
      "     %'%!       ",
      "     '%%''''    "
    ],
    [
      "      %%,,,,,,,,",
      "      % ,,,,,,,,",
      "      '%,,,,,,,,",
      "      %%,,,,,,,,",
      "      %',,,,,,,,",
      "       %,,,,,,,,",
      "      %%,,,,,,,,",
      "      %',,,,,,,,",
      "      '%,,,,,,,,",
      "      %%,!!!!!!!",
      "      % ,,,,,,,,",
      "      '%,,,,,,,,",
      "      %%,,,,,,,,",
      "      %',,,,,,,,",
      "       %,,,,,,,,",
      "      %%'''',,,,"
    ],
    [
      "        +       ",
      "        +       ",
      "        + ------",
      "        +       ",
      "        +       ",
      "        +       ",
      "        +  )    ",
      "        +  ((   ",
      "        +       ",
      "        &       ",
      "        +       ",
      "        +  )    ",
      "        +  ((   ",
      "        +       ",
      "        +       ",
      "        ''''    "
    ]
  ],
  "palette": {
    "palette": [
      {
        "char": "!",
        "block": "immersiveengineering:concrete_reinforced"
      },
      {
        "char": "$",
        "block": "immersiveengineering:crate"
      },
      {
        "char": "%",
        "block": "minecraft:coarse_dirt"
      },
      {
        "char": "&",
        "block": "minecraft:dark_oak_door[facing=west,half=lower,hinge=left,open=false,powered=false]"
      },
      {
        "char": "'",
        "block": "minecraft:gravel"
      },
      {
        "char": "(",
        "block": "minecraft:spruce_slab[type=bottom,waterlogged=false]"
      },
      {
        "char": ")",
        "block": "minecraft:spruce_stairs[facing=south,half=bottom,shape=straight,waterlogged=false]"
      },
      {
        "char": "*",
        "block": "tfmg:asphalt"
      },
      {
        "char": "+",
        "block": "tfmg:cinder_block"
      },
      {
        "char": ",",
        "block": "tfmg:factory_floor"
      },
      {
        "char": "-",
        "block": "zvhouses:stone_brick_countertop"
      }
    ]
  }
}
