{
  "xsize": 16,
  "zsize": 16,
  "slices": [
    [
      "/////           ",
      "/////           ",
      "/////           ",
      "/////           ",
      "/////           ",
      "/////           ",
      "/////           ",
      "/////           ",
      "/////           ",
      "/////           ",
      "                ",
      "                ",
      "/////           ",
      "/////           ",
      "/////           ",
      "/////           "
    ],
    [
      "    !           ",
      "    !           ",
      "    !           ",
      "    !           ",
      "$$  !           ",
      "$$  !           ",
      "$$  !           ",
      "    !           ",
      "    !           ",
      "!!!!!           ",
      "                ",
      "                ",
      "!!!!!           ",
      "    !           ",
      "    !           ",
      "    !           "
    ],
    [
      "    !           ",
      "    !           ",
      "    !           ",
      "    !           ",
      "$$  !           ",
      "$$  !           ",
      "$$  !           ",
      "    !           ",
      "    !           ",
      "!!!!!           ",
      "                ",
      "                ",
      "!!!!!           ",
      "    !           ",
      "    !           ",
      "    !           "
    ],
    [
      "    !           ",
      "    !           ",
      "    !           ",
      "    !           ",
      "    !           ",
      "    !           ",
      "    !           ",
      "    !           ",
      "    !           ",
      "!!!!!           ",
      "                ",
      "                ",
      "!!!!!           ",
      "    !           ",
      "    !           ",
      "    !           "
    ],
    [
      "''''')))))......",
      "''''')))))......",
      "''''')))))......",
      "''''')))))......",
      "''''')))))......",
      "''''')))))......",
      "''''')))))......",
      "''''')),))......",
      "''''')))))......",
      "''''')))))......",
      "+++++)))))......",
      "+++++)))))......",
      "*****)))))......",
      "*****)))))......",
      "*****)),))......",
      "*****)))))......"
    ],
    [
      "    %           ",
      "    %           ",
      "    %           ",
      "    %           ",
      "    %         - ",
      "    %           ",
      " (  %           ",
      "    %  ,        ",
      "    %           ",
      "%%%%%           ",
      "    %         - ",
      "    &           ",
      "&&&&&           ",
      "    &           ",
      "    &  ,        ",
      "    &           "
    ]
  ],
  "palette": {
    "palette": [
      {
        "char": "!",
        "block": "immersiveengineering:concrete_reinforced"
      },
      {
        "char": "$",
        "block": "immersiveengineering:crate"
      },
      {
        "char": "%",
        "block": "minecraft:bricks"
      },
      {
        "char": "&",
        "block": "minecraft:mud_bricks"
      },
      {
        "char": "'",
        "block": "minecraft:oak_planks"
      },
      {
        "char": "(",
        "block": "minecraft:oak_stairs[facing=east,half=bottom,shape=straight,waterlogged=false]"
      },
      {
        "char": ")",
        "block": "minecraft:smooth_stone"
      },
      {
        "char": "*",
        "block": "minecraft:spruce_planks"
      },
      {
        "char": "+",
        "block": "minecraft:stone_bricks"
      },
      {
        "char": ",",
        "block": "minecraft:stripped_dark_oak_log[axis=y]"
      },
      {
        "char": "-",
        "block": "minecraft:yellow_concrete"
      },
      {
        "char": ".",
        "block": "tfmg:asphalt"
      },
      {
        "char": "/",
        "block": "tfmg:factory_floor"
      }
    ]
  }
}
