{
  "xsize": 16,
  "zsize": 16,
  "slices": [
    [
      "                ",
      "                ",
      "                ",
      "-----           ",
      "-----           ",
      "-----           ",
      "-----           ",
      "-----           ",
      "-----           ",
      "-----           ",
      "-----           ",
      "-----           ",
      "-----           ",
      "-----           ",
      "-----           ",
      "-----           "
    ],
    [
      "                ",
      "                ",
      "                ",
      "!!!!!           ",
      "    !           ",
      "    !           ",
      "    !           ",
      "    !           ",
      "    !           ",
      "    !           ",
      "    !           ",
      "    !           ",
      "    !           ",
      "    !           ",
      "!!!!!           ",
      "    !           "
    ],
    [
      "                ",
      "                ",
      "                ",
      "!!!!!           ",
      "    !           ",
      "    !           ",
      "    !           ",
      "    !           ",
      "    !           ",
      "    !           ",
      "    !           ",
      "    !           ",
      "    !           ",
      "    !           ",
      "!!!!!           ",
      "    !           "
    ],
    [
      "                ",
      "                ",
      "                ",
      "!!!!!           ",
      "    !           ",
      "    !           ",
      "    !           ",
      "    !           ",
      "    !           ",
      "    !           ",
      "    !           ",
      "    !           ",
      "    !           ",
      "    !           ",
      "!!!!!           ",
      "    !           "
    ],
    [
      ")))))(((((,,,,,,",
      ")))))(((((,,,,,,",
      ")))))(((((,,,,,,",
      "&&&&&(((((,,,,,,",
      "&&&&&(((((,,,,,,",
      "&&&&&((*((,,,,,,",
      "&&&&&(((((,,,,,,",
      "&&&&&(((((,,,,,,",
      "&&&&&(((((,,,,,,",
      "&&&&&(((((,,,,,,",
      "&&&&&(((((,,,,,,",
      "&&&&&(((((,,,,,,",
      "&&&&&(((((,,,,,,",
      "&&&&&(((((,,,,,,",
      "!!!!&(((((,,,,,,",
      "&&&&&(((((,,,,,,"
    ],
    [
      "                ",
      "                ",
      "    $         + ",
      "$$$$$           ",
      "    $           ",
      "    $  *        ",
      "    $           ",
      "    $           ",
      "    $         + ",
      "    $           ",
      "    $           ",
      " '  $           ",
      "    $           ",
      "    $           ",
      "    %         + ",
      "    $           "
    ]
  ],
  "palette": {
    "palette": [
      {
        "char": "!",
        "block": "immersiveengineering:concrete_reinforced"
      },
      {
        "char": "$",
        "block": "minecraft:bricks"
      },
      {
        "char": "%",
        "block": "minecraft:dark_oak_door[facing=east,half=lower,hinge=left,open=false,powered=false]"
      },
      {
        "char": "&",
        "block": "minecraft:oak_planks"
      },
      {
        "char": "'",
        "block": "minecraft:oak_stairs[facing=east,half=bottom,shape=straight,waterlogged=false]"
      },
      {
        "char": "(",
        "block": "minecraft:smooth_stone"
      },
      {
        "char": ")",
        "block": "minecraft:stone_bricks"
      },
      {
        "char": "*",
        "block": "minecraft:stripped_dark_oak_log[axis=y]"
      },
      {
        "char": "+",
        "block": "minecraft:yellow_concrete"
      },
      {
        "char": ",",
        "block": "tfmg:asphalt"
      },
      {
        "char": "-",
        "block": "tfmg:factory_floor"
      }
    ]
  }
}
