{
  "xsize": 16,
  "zsize": 16,
  "slices": [
    [
      "                ",
      "                ",
      "                ",
      "...........     ",
      "...........     ",
      "...........     ",
      "...........     ",
      "...........     ",
      "...........     ",
      "...........     ",
      "...........     ",
      "...........     ",
      "...........     ",
      "...........     ",
      "...........     ",
      "...........     "
    ],
    [
      "                ",
      "                ",
      "                ",
      "!!!!!!!!!!!     ",
      "          !     ",
      "          !     ",
      "       (  !     ",
      "          !     ",
      "          !     ",
      "          !     ",
      "          !     ",
      "          !     ",
      "          !     ",
      "          !     ",
      "          !     ",
      "!!!!!!!*!!!     "
    ],
    [
      "                ",
      "                ",
      "                ",
      "!!!!!!!!!!!     ",
      "          !     ",
      "          !     ",
      "          !     ",
      "       (  !     ",
      "          !     ",
      "          !     ",
      "          !     ",
      "          !     ",
      "          !     ",
      "          !     ",
      "          !     ",
      "!!!!!!!+!!!     "
    ],
    [
      "                ",
      "                ",
      "                ",
      "!!!!!!!!!!!     ",
      "          !     ",
      "          !     ",
      "          !     ",
      "          !     ",
      "       (  !     ",
      "          !     ",
      "          !     ",
      "          !     ",
      "          !     ",
      "          !     ",
      "          !     ",
      "!!!!!!!!!!!     "
    ],
    [
      ",,,,,,,,,,,,,   ",
      ",,,,,,,,,,,,,   ",
      ",,,,,,,,,,,,,   ",
      "''''''''''',,   ",
      "''''''''''',,   ",
      "''''''''''',,   ",
      "''''''''''',,   ",
      "''''''' ''',,   ",
      "''''''' ''',,   ",
      "'''''''(''',,   ",
      "''''''''''',,   ",
      "''''''''''',,   ",
      "''''''''''',-   ",
      "''''''''''',,   ",
      "''''''''''',,   ",
      "!!!!!!!!!!',,   "
    ],
    [
      "                ",
      "                ",
      "    %     %     ",
      "%%%%%%%%%%%     ",
      "%         %     ",
      "%         %     ",
      "%      &  %     ",
      "%         %     ",
      "%         %     ",
      "%  $      %     ",
      "%         %     ",
      "%         %     ",
      ")         % -   ",
      "%         %     ",
      "%         %     ",
      "%%%%%*%%%%%     "
    ]
  ],
  "palette": {
    "palette": [
      {
        "char": "!",
        "block": "immersiveengineering:concrete_reinforced"
      },
      {
        "char": "$",
        "block": "minecraft:brewing_stand"
      },
      {
        "char": "%",
        "block": "minecraft:light_gray_concrete"
      },
      {
        "char": "&",
        "block": "minecraft:oak_stairs[facing=south,half=bottom,shape=straight,waterlogged=false]"
      },
      {
        "char": "'",
        "block": "minecraft:polished_andesite"
      },
      {
        "char": "(",
        "block": "minecraft:polished_andesite_stairs[facing=south,half=bottom,shape=straight,waterlogged=false]"
      },
      {
        "char": ")",
        "block": "minecraft:spruce_door[facing=east,half=lower,hinge=left,open=false,powered=false]"
      },
      {
        "char": "*",
        "block": "minecraft:spruce_door[facing=south,half=lower,hinge=left,open=false,powered=false]"
      },
      {
        "char": "+",
        "block": "minecraft:spruce_door[facing=south,half=upper,hinge=left,open=false,powered=false]"
      },
      {
        "char": ",",
        "block": "minecraft:stone_bricks"
      },
      {
        "char": "-",
        "block": "minecraft:stripped_dark_oak_log[axis=y]"
      },
      {
        "char": ".",
        "block": "tfmg:factory_floor"
      }
    ]
  }
}
