{
  "xsize": 16,
  "zsize": 16,
  "slices": [
    [
      "****************",
      "****************",
      "****************",
      "****************",
      "****************",
      "****************",
      "****************",
      "****************",
      "****************",
      "****************",
      "****************",
      "****************",
      "****************",
      "****************",
      " %%$************",
      " $**************"
    ],
    [
      "   '''''''''''''",
      "   '''''''''''''",
      "   '''''''''''''",
      "   '''''''''''''",
      "   '''''''''''''",
      "   '''''''''''''",
      "   '''''''''''''",
      "   '''''''''''''",
      "   '''''''''''''",
      "   '''''''''''''",
      "   '''''''''''''",
      "             !!!",
      "             !!!",
      "             !!!",
      "))))))))))))))))",
      "))))))))))))))))"
    ],
    [
      "   +         ,  ",
      "   +            ",
      "   +            ",
      "   + &&&&&&&&&  ",
      "   + &&&&(&&&&  ",
      "   + &&&&&&&&&  ",
      "   + &&&&&&&&&  ",
      "   + &&&&&&&&&  ",
      "   + &&&&&&&&&  ",
      "   +            ",
      "   +++++++++++++",
      "             !!!",
      "             !!!",
      "             !!!",
      "))))))))))))))))",
      "))))))))))))))))"
    ],
    [
      "   +            ",
      "   +            ",
      "   +            ",
      "   + &&&&&&&&&  ",
      "   + &&&&&&&&&  ",
      "   + &&&&&&&&&  ",
      "   + &&&&&&&&&  ",
      "   + &&&&&&&&&  ",
      "   + &&&&&&&&&  ",
      "   +            ",
      "   +++++++++++++",
      "             !!!",
      "             !!!",
      "             !!!",
      "))))))))))))))))",
      "))))))))))))))))"
    ],
    [
      "   +            ",
      "   +            ",
      "   +            ",
      "   + &&&&&&&&&  ",
      "   + &&&&&&&&&  ",
      "   + &&&&&&&&&  ",
      "   + &&&&&&&&&  ",
      "   + &&&&&&&&&  ",
      "   + &&&&&&&&&  ",
      "   +            ",
      "   +++++++++++++",
      "             !!!",
      "             !!!",
      "             !!!",
      "))))))))))))))))",
      "))))))))))))))))"
    ],
    [
      "   +            ",
      "   +            ",
      "   +            ",
      "   + &&&&&&&&&  ",
      "   + &&&&&&&&&  ",
      "   + &&&&&&&&&  ",
      "   + &&&&&&&&&  ",
      "   + &&&&&&&&&  ",
      "   + &&&&&&&&&  ",
      "   +            ",
      "   +++++++++++++",
      "             !!!",
      "             !!!",
      "             !!!",
      "))))))))))))))))",
      "))))))))))))))))"
    ]
  ],
  "palette": {
    "palette": [
      {
        "char": "!",
        "block": "immersiveengineering:concrete_reinforced"
      },
      {
        "char": "$",
        "block": "minecraft:coarse_dirt"
      },
      {
        "char": "%",
        "block": "minecraft:gravel"
      },
      {
        "char": "&",
        "block": "minecraft:scaffolding"
      },
      {
        "char": "'",
        "block": "minecraft:smooth_stone"
      },
      {
        "char": "(",
        "block": "minecraft:spawner",
        "tag": {
          "id": "minecraft:mob_spawner",
          "Delay": 200,
          "MinSpawnDelay": 240,
          "MaxSpawnDelay": 720,
          "SpawnCount": 2,
          "MaxNearbyEntities": 6,
          "RequiredPlayerRange": 14,
          "SpawnRange": 4,
          "SpawnData": {
            "entity": {
              "id": "minecraft:zombie"
            }
          },
          "SpawnPotentials": [
            {
              "weight": 1,
              "data": {
                "entity": {
                  "id": "minecraft:zombie"
                }
              }
            }
          ]
        }
      },
      {
        "char": ")",
        "block": "minecraft:stone_bricks"
      },
      {
        "char": "*",
        "block": "tfmg:asphalt"
      },
      {
        "char": "+",
        "block": "tfmg:cinder_block"
      },
      {
        "char": ",",
        "block": "the_wasteland_reworked:radio"
      }
    ]
  }
}
