{
  "xsize": 16,
  "zsize": 16,
  "slices": [
    [
      "  %         %   ",
      "  )  $$$$$$ %   ",
      "  %  $$$$$$ %   ",
      "+ %  $$$$$$ %   ",
      "  !  $$$$$$ %   ",
      "  !  $$$$$$ %   ",
      "  %  $$$$$$ %   ",
      "  %         %   ",
      "  %         %   ",
      "  %%%!!%%%!!%%% ",
      "  %     %     % ",
      "  &     &     & ",
      "  &&&!!&&&!!&&&!",
      "  &         &   ",
      "  &         &   ",
      "  &         &   "
    ],
    [
      "  %         %   ",
      "     $$$$$$ %   ",
      "  %  $$$$$$ %   ",
      "+ %  $$$$$$ %   ",
      "  !  $$$$$$ %   ",
      "  !  $$$$$$ %   ",
      "  %  $$$$$$ %   ",
      "  %         %   ",
      "  %         %   ",
      "  %%%!!%%%!!%% !",
      "  %     %       ",
      "  &     &     & ",
      "  &&&!!&&&!!&&&!",
      "  &         &   ",
      "  &         &   ",
      "  &         &   "
    ],
    [
      "  %         %   ",
      "  %         %   ",
      "  %         %   ",
      "+ %         %   ",
      "  !         %   ",
      "  !         %   ",
      "  %         %   ",
      "  %         %   ",
      "  %         %   ",
      "  %%%%%%%%%%%%  ",
      "  % ((((%((((   ",
      "  & ((((&(((( &(",
      "  &&&&&&&&&&&&&&",
      "  &         &   ",
      "  &         &   ",
      "  &         &   "
    ],
    [
      ",,,             ",
      ",,,             ",
      ",,,             ",
      ",,,             ",
      "  %             ",
      "  %             ",
      "  %             ",
      "  %             ",
      "  %             ",
      "  %%%%%%%%%%%%  ",
      "  %     %       ",
      "  &     &     & ",
      "  &&&&&&&&&&&&&&",
      "  &             ",
      "  &             ",
      "  &             "
    ],
    [
      "  %             ",
      "  %             ",
      "  %             ",
      "  %             ",
      "  %             ",
      "  %             ",
      "  %             ",
      "  %             ",
      "  %             ",
      "  %%%%%%%%%%%%% ",
      "  %     %     % ",
      "  &     &     & ",
      "  &&&&&&&&&&&&&&",
      "  &             ",
      "  &             ",
      "  &             "
    ],
    [
      "  %'''''''''''''",
      "  %'''''''''''''",
      "  %'''''''''''''",
      "  %'''''''''''''",
      "  %'''''''''''''",
      "  %'''''''''''''",
      "  %'''''''''''''",
      "  %''''''''''' '",
      "  %''''''''''' '",
      "  %%%%%%%%%%%% %",
      "  %     %       ",
      "  &     &     & ",
      "  &&&&&&&&&&&&&&",
      "  &*************",
      "  &*************",
      "  &*************"
    ]
  ],
  "palette": {
    "palette": [
      {
        "char": "!",
        "block": "create:framed_glass"
      },
      {
        "char": "$",
        "block": "immersiveengineering:crate"
      },
      {
        "char": "%",
        "block": "minecraft:bricks"
      },
      {
        "char": "&",
        "block": "minecraft:mud_bricks"
      },
      {
        "char": "'",
        "block": "minecraft:oak_planks"
      },
      {
        "char": "(",
        "block": "minecraft:smooth_stone_slab[type=top,waterlogged=false]"
      },
      {
        "char": ")",
        "block": "minecraft:spruce_door[facing=west,half=upper,hinge=left,open=false,powered=false]"
      },
      {
        "char": "*",
        "block": "minecraft:spruce_planks"
      },
      {
        "char": "+",
        "block": "minecraft:stripped_dark_oak_log[axis=y]"
      },
      {
        "char": ",",
        "block": "minecraft:weathered_cut_copper"
      }
    ]
  }
}
