{
  "xsize": 16,
  "zsize": 16,
  "slices": [
    [
      "                ",
      "                ",
      "    $     $     ",
      "$$$$$$$$$$$     ",
      "     '    $     ",
      "     '    $     ",
      "     '    $     ",
      "     '    $     ",
      "     '    $     ",
      "     '    $     ",
      "     '    $     ",
      "     '    $     ",
      "     '    $     ",
      "     '    $     ",
      "     '    $     ",
      "''''''    $     "
    ],
    [
      "                ",
      "                ",
      "    $     $     ",
      "$$$$$$$$$$$     ",
      "          $     ",
      "          $     ",
      "          $     ",
      "          $     ",
      "          $     ",
      "          $     ",
      "          $     ",
      "          $     ",
      "          $     ",
      "          $     ",
      "          $     ",
      "          $     "
    ],
    [
      "                ",
      "                ",
      "                ",
      "&&&&&&&&&&&     ",
      "&&&&&&&&&&&     ",
      "&&&&&&&&&&&     ",
      "&&&&&&&&&&&     ",
      "&&!!&!!&&&&     ",
      "&&!!&!!&&&&     ",
      "&&!!&!!&&&&     ",
      "&&!!&!!&&&&     ",
      "&&!!&!!&&&&     ",
      "&&!!%!!%&&&     ",
      "&&%%%%%%&&&     ",
      "&&%%%%%%&&&     ",
      "&&%%%%%%&&&     "
    ],
    [
      "                ",
      "                ",
      "                ",
      "$$$$$$$$$$$     ",
      "                ",
      "                ",
      "                ",
      "                ",
      "                ",
      "                ",
      "                ",
      "                ",
      "  $$$$$$        ",
      "  $    $        ",
      "  $    $        ",
      "  $    $        "
    ],
    [
      "                ",
      "                ",
      "                ",
      "                ",
      "                ",
      "                ",
      "                ",
      "                ",
      "                ",
      "                ",
      "                ",
      "                ",
      "  $$$$$$        ",
      "  $    $        ",
      "  $    $        ",
      "  $    $        "
    ],
    [
      "                ",
      "                ",
      "                ",
      "                ",
      "                ",
      "                ",
      "                ",
      "                ",
      "                ",
      "                ",
      "                ",
      "                ",
      "  &&&&&&        ",
      "  &&&&&&        ",
      "  &&&&&&        ",
      "  &&&&&&        "
    ]
  ],
  "palette": {
    "palette": [
      {
        "char": "!",
        "block": "create:framed_glass"
      },
      {
        "char": "$",
        "block": "minecraft:light_gray_concrete"
      },
      {
        "char": "%",
        "block": "minecraft:polished_andesite"
      },
      {
        "char": "&",
        "block": "minecraft:smooth_stone"
      },
      {
        "char": "'",
        "block": "minecraft:stripped_spruce_wood"
      }
    ]
  }
}
