{
  "xsize": 16,
  "zsize": 16,
  "slices": [
    [
      "  !  $$$$$$ %   ",
      "  %  $$$$$$ %   ",
      "  %         %   ",
      "  %         %   ",
      "  %%%!!%%%!!%%%!",
      "  %     %     % ",
      "                ",
      "                ",
      "                ",
      "                ",
      "                ",
      "                ",
      "                ",
      "                ",
      "                ",
      "                "
    ],
    [
      "  !  $$$$$$ %   ",
      "  %  $$$$$$ %   ",
      "  %         %   ",
      "  %         %   ",
      "  %%%!!%%%!!%%%!",
      "  %     %     % ",
      "                ",
      "                ",
      "                ",
      "                ",
      "                ",
      "                ",
      "                ",
      "                ",
      "                ",
      "                "
    ],
    [
      "  !         %   ",
      "  %         %   ",
      "  %         %   ",
      "  %         %   ",
      "  %%%%%%%%%%%%%%",
      "  % &&&&%&&&& %&",
      "                ",
      "                ",
      "                ",
      "                ",
      "                ",
      "                ",
      "                ",
      "                ",
      "                ",
      "                "
    ],
    [
      "  %             ",
      "  %             ",
      "  %             ",
      "  %             ",
      "  %%%%%%%%%%%%%%",
      "  %     %     % ",
      "                ",
      "                ",
      "                ",
      "                ",
      "                ",
      "                ",
      "                ",
      "                ",
      "                ",
      "                "
    ],
    [
      "  %             ",
      "  %             ",
      "  %             ",
      "  %             ",
      "  %%%%%%%%%%%%%%",
      "  %     %     % ",
      "                ",
      "                ",
      "                ",
      "                ",
      "                ",
      "                ",
      "                ",
      "                ",
      "                ",
      "                "
    ],
    [
      "  %'''''''''''''",
      "  %'''''''''''''",
      "  %'''''''''''''",
      "  %'''''''''''''",
      "  %%%%%%%%%%%%%%",
      "  %     %     % ",
      "                ",
      "                ",
      "                ",
      "                ",
      "                ",
      "                ",
      "                ",
      "                ",
      "                ",
      "                "
    ]
  ],
  "palette": {
    "palette": [
      {
        "char": "!",
        "block": "create:framed_glass"
      },
      {
        "char": "$",
        "block": "immersiveengineering:crate"
      },
      {
        "char": "%",
        "block": "minecraft:mud_bricks"
      },
      {
        "char": "&",
        "block": "minecraft:smooth_stone_slab[type=top,waterlogged=false]"
      },
      {
        "char": "'",
        "block": "minecraft:spruce_planks"
      }
    ]
  }
}
