{
  "xsize": 16,
  "zsize": 16,
  "slices": [
    [
      "                ",
      ")))))           ",
      ")))))     (     ",
      ")))))((((((     ",
      "++++++++++(     ",
      "++++++++++(     ",
      "++++++++++(     ",
      "++++++++++(     ",
      "++++++++++(     ",
      "++++++++++(     ",
      "+++++++ ++(     ",
      "+++++++ ++(     ",
      "++++++++++(     ",
      "++++++++++(     ",
      "++++++++++(     ",
      "++++++++++(     "
    ],
    [
      "                ",
      "    .           ",
      "    (     (     ",
      "(((((((((((     ",
      "     /    (     ",
      "     /    (     ",
      "     / *  (     ",
      "     /    (     ",
      "     &    (     ",
      "     /    (     ",
      "  %  /    (     ",
      "  $  /    (     ",
      " 0   /    (     ",
      "     /    (     ",
      "  -  /    (     ",
      "//////    (     "
    ],
    [
      "                ",
      "                ",
      "    (     (     ",
      "!!(((!!((((     ",
      "     /    (     ",
      "     /    (     ",
      "     /    !     ",
      "     / *  !     ",
      "     '    (     ",
      "     /    (     ",
      "     /    (     ",
      "     /    (     ",
      "     /    !     ",
      "     /    !     ",
      "     /    (     ",
      "//////    (     "
    ],
    [
      "                ",
      "                ",
      "    (     (     ",
      "!!(((!!((((     ",
      "     /    (     ",
      "     /    (     ",
      "     /    !     ",
      "     /    !     ",
      "     / *  (     ",
      "     /    (     ",
      "     /    (     ",
      "     /    (     ",
      "     /    !     ",
      "     /    !     ",
      "     /    (     ",
      "//////    (     "
    ],
    [
      "                ",
      "                ",
      ",,, (,,,  (     ",
      "(((((((((((     ",
      "     /    (     ",
      "     /    (     ",
      "     /    (     ",
      "     /    (     ",
      "     /    (     ",
      "     / *  (     ",
      "     /    (     ",
      "     /    (     ",
      "     /    (     ",
      "     /    (     ",
      "     /    (     ",
      "//////    (     "
    ],
    [
      "                ",
      "                ",
      "    (     (     ",
      "(((((((((((     ",
      "     /    (     ",
      "     /    (     ",
      "     /    (     ",
      "     /    (     ",
      "     /    (     ",
      "     /    (     ",
      "     / *  (     ",
      "     /    (     ",
      "     /    (     ",
      "     /    (     ",
      "     /    (     ",
      "//////    (     "
    ]
  ],
  "palette": {
    "palette": [
      {
        "char": "!",
        "block": "create:framed_glass"
      },
      {
        "char": "$",
        "block": "minecraft:brown_bed[facing=north,occupied=false,part=foot]"
      },
      {
        "char": "%",
        "block": "minecraft:brown_bed[facing=north,occupied=false,part=head]"
      },
      {
        "char": "&",
        "block": "minecraft:dark_oak_door[facing=west,half=lower,hinge=left,open=false,powered=false]"
      },
      {
        "char": "'",
        "block": "minecraft:dark_oak_door[facing=west,half=upper,hinge=left,open=false,powered=false]"
      },
      {
        "char": "(",
        "block": "minecraft:light_gray_concrete"
      },
      {
        "char": ")",
        "block": "minecraft:oak_slab[type=top,waterlogged=false]"
      },
      {
        "char": "*",
        "block": "minecraft:oak_stairs[facing=south,half=bottom,shape=straight,waterlogged=false]"
      },
      {
        "char": "+",
        "block": "minecraft:polished_andesite"
      },
      {
        "char": ",",
        "block": "minecraft:smooth_stone_slab[type=top,waterlogged=false]"
      },
      {
        "char": "-",
        "block": "minecraft:spawner",
        "tag": {
          "id": "minecraft:mob_spawner",
          "Delay": 200,
          "MinSpawnDelay": 240,
          "MaxSpawnDelay": 720,
          "SpawnCount": 2,
          "MaxNearbyEntities": 7,
          "RequiredPlayerRange": 14,
          "SpawnRange": 4,
          "SpawnData": {
            "entity": {
              "id": "the_wasteland_reworked:ghoul"
            }
          },
          "SpawnPotentials": [
            {
              "weight": 1,
              "data": {
                "entity": {
                  "id": "the_wasteland_reworked:ghoul"
                }
              }
            }
          ]
        }
      },
      {
        "char": ".",
        "block": "minecraft:stripped_oak_log[axis=y]"
      },
      {
        "char": "/",
        "block": "minecraft:stripped_spruce_wood"
      },
      {
        "char": "0",
        "block": "minecraft:water_cauldron[level=3]"
      }
    ]
  }
}
