{
  "xsize": 16,
  "zsize": 16,
  "slices": [
    [
      "                ",
      "       ******** ",
      "  $    ******** ",
      "  $$$$$********$",
      "  $)))))))))))))",
      "  $)))))))))))))",
      "  $)))))))))))))",
      "  $)))))))))))))",
      "  $)))))))))))))",
      "  $)))))))))))))",
      "  $)) ))))))))))",
      "  $)) ))))))))))",
      "  $)))))))))))))",
      "  $)))))))))))))",
      "  $)))))))))))))",
      "  $)))))))))))))"
    ],
    [
      "                ",
      "       .      . ",
      "  $     $     $ ",
      "  $$$$$$$$$$$$$$",
      "  $    /      / ",
      "  $    /      / ",
      "  $    /      / ",
      "  $    /      / ",
      "  $    '      / ",
      "  $    /  &   / ",
      "  $    /  %   , ",
      "  $    /      / ",
      "  $    /   0  / ",
      "  $    /      / ",
      "  $    /////////",
      "  $    /      / "
    ],
    [
      "                ",
      "                ",
      "  $     $     $ ",
      "  $$$!!$$$!!$$$!",
      "  $    /      / ",
      "  $    /      / ",
      "  !    /      / ",
      "  !    /      / ",
      "  $    (      / ",
      "  $    /      / ",
      "  $    /      - ",
      "  $    /      / ",
      "  !    /      / ",
      "  !    /      / ",
      "  $    /////////",
      "  $    /      / "
    ],
    [
      "                ",
      "                ",
      "  $     $     $ ",
      "  $$$!!$$$!!$$$!",
      "  $    /      / ",
      "  $    /      / ",
      "  !    /      / ",
      "  !    /      / ",
      "  $    /      / ",
      "  $    /      / ",
      "  $    /      / ",
      "  $    /      / ",
      "  !    /      / ",
      "  !    /      / ",
      "  $    /////////",
      "  $    /      / "
    ],
    [
      "                ",
      "                ",
      "  $ ++++$++++ $+",
      "  $$$$$$$$$$$$$$",
      "  $    /      / ",
      "  $    /      / ",
      "  $    /      / ",
      "  $    /      / ",
      "  $    /      / ",
      "  $    /      / ",
      "  $    /      / ",
      "  $    /      / ",
      "  $    /      / ",
      "  $    /      / ",
      "  $    /////////",
      "  $    /      / "
    ],
    [
      "                ",
      "                ",
      "  $     $     $ ",
      "  $$$$$$$$$$$$$$",
      "  $    /        ",
      "  $    /        ",
      "  $    /        ",
      "  $    /        ",
      "  $    /        ",
      "  $    /        ",
      "  $    /        ",
      "  $    /        ",
      "  $    /        ",
      "  $    /        ",
      "  $    /////////",
      "  $    /        "
    ]
  ],
  "palette": {
    "palette": [
      {
        "char": "!",
        "block": "create:framed_glass"
      },
      {
        "char": "$",
        "block": "minecraft:bricks"
      },
      {
        "char": "%",
        "block": "minecraft:brown_bed[facing=north,occupied=false,part=foot]"
      },
      {
        "char": "&",
        "block": "minecraft:brown_bed[facing=north,occupied=false,part=head]"
      },
      {
        "char": "'",
        "block": "minecraft:dark_oak_door[facing=east,half=lower,hinge=left,open=false,powered=false]"
      },
      {
        "char": "(",
        "block": "minecraft:dark_oak_door[facing=east,half=upper,hinge=left,open=false,powered=false]"
      },
      {
        "char": ")",
        "block": "minecraft:oak_planks"
      },
      {
        "char": "*",
        "block": "minecraft:oak_slab[type=top,waterlogged=false]"
      },
      {
        "char": "+",
        "block": "minecraft:smooth_stone_slab[type=top,waterlogged=false]"
      },
      {
        "char": ",",
        "block": "minecraft:spruce_door[facing=east,half=lower,hinge=left,open=false,powered=false]"
      },
      {
        "char": "-",
        "block": "minecraft:spruce_door[facing=east,half=upper,hinge=left,open=false,powered=false]"
      },
      {
        "char": ".",
        "block": "minecraft:stripped_oak_log[axis=y]"
      },
      {
        "char": "/",
        "block": "minecraft:stripped_spruce_wood"
      },
      {
        "char": "0",
        "block": "kubejs:ruined_cauldron"
      }
    ]
  }
}
