{
  "xsize": 16,
  "zsize": 16,
  "slices": [
    [
      "                ",
      "                ",
      "        &     & ",
      "        &&&!!&&&",
      "        &       ",
      "     )  !       ",
      "        !       ",
      "        !       ",
      "        ! $$ $$ ",
      "        &       ",
      "        !       ",
      "        !       ",
      "        !       ",
      "        !       ",
      "        & $$ $$ ",
      "        %       "
    ],
    [
      "                ",
      "                ",
      "        &     & ",
      "        &&&!!&&&",
      "        &       ",
      "     )  !       ",
      "        !       ",
      "        !       ",
      "        ! $$ $$ ",
      "        &       ",
      "        !       ",
      "        !       ",
      "        !       ",
      "        !       ",
      "        & $$ $$ ",
      "                "
    ],
    [
      "                ",
      "                ",
      "        & ((((&(",
      "        &&&&&&&&",
      "        &       ",
      "     )  !       ",
      "        !       ",
      "        !       ",
      "        !       ",
      "        &       ",
      "        !       ",
      "        !       ",
      "        !       ",
      "        !       ",
      "        &       ",
      "        &       "
    ],
    [
      "                ",
      "                ",
      "        &     & ",
      "        &&&&&&&&",
      "    ((((&       ",
      "    ((((&       ",
      "    ((((&       ",
      "    ((((&       ",
      "    ((((&       ",
      "    ((((&       ",
      "    ((((&       ",
      "    ((((&       ",
      "    ((((&       ",
      "    ((((&       ",
      "    ((((&       ",
      "    ((((&       "
    ],
    [
      "                ",
      "                ",
      "        &     & ",
      "        &&&&&&&&",
      "        &       ",
      "        &       ",
      "        &       ",
      "        &       ",
      "        &       ",
      "        &       ",
      "        &       ",
      "        &       ",
      "        &       ",
      "        &       ",
      "        &       ",
      "        &       "
    ],
    [
      "                ",
      "                ",
      "        &     & ",
      "       (&&&&&&&&",
      "       (&'''''''",
      "       (&'''''''",
      "       (&'''''''",
      "       (&'''''''",
      "       (&'''''''",
      "       (&'''''''",
      "       (&'''''''",
      "       (&'''''''",
      "       (&'''''''",
      "       (&'''''''",
      "       (&'''''''",
      "       (&'''''''"
    ]
  ],
  "palette": {
    "palette": [
      {
        "char": "!",
        "block": "create:framed_glass"
      },
      {
        "char": "$",
        "block": "minecraft:bookshelf"
      },
      {
        "char": "%",
        "block": "minecraft:dark_oak_door[facing=west,half=upper,hinge=left,open=false,powered=false]"
      },
      {
        "char": "&",
        "block": "minecraft:light_gray_concrete"
      },
      {
        "char": "'",
        "block": "minecraft:polished_andesite"
      },
      {
        "char": "(",
        "block": "minecraft:smooth_stone_slab[type=top,waterlogged=false]"
      },
      {
        "char": ")",
        "block": "minecraft:stripped_dark_oak_log[axis=y]"
      }
    ]
  }
}
