{
  "xsize": 16,
  "zsize": 16,
  "slices": [
    [
      "  11111111111111",
      "  11111111111111",
      "  11111111111111",
      "  11111111111111",
      "  11111111111111",
      "  11111111111111",
      "  11111111111111",
      "  11111111111111",
      "  11111111111111",
      "  11111111111111",
      "                ",
      "                ",
      "  11111111111111",
      "  11111111111111",
      "  11111111111111",
      "  11111111111111"
    ],
    [
      "  !             ",
      "  !             ",
      "  !             ",
      "  !             ",
      "  !   '        $",
      "  !            $",
      "  ! %          $",
      "  !             ",
      "  !             ",
      "  !!!!!!!!!!!!((",
      "              ((",
      "              ((",
      "  !!!!!!!!!!!!((",
      "  !             ",
      "  !             ",
      "  !  ,$$        "
    ],
    [
      "  !             ",
      "  !             ",
      "  !             ",
      "  !             ",
      "  !            $",
      "  !            $",
      "  !            $",
      "  !             ",
      "  !             ",
      "  !!!!!!!!!!!!((",
      "              ((",
      "              ((",
      "  !!!!!!!!!!!!((",
      "  !             ",
      "  !             ",
      "  !   $$        "
    ],
    [
      "  !             ",
      "  !             ",
      "  !             ",
      "  !             ",
      "  !             ",
      "  !             ",
      "  !             ",
      "  !             ",
      "  !             ",
      "  !!!!!!!!!!!!((",
      "              ((",
      "              ((",
      "  !!!!!!!!!!!!((",
      "  !             ",
      "  !             ",
      "  !             "
    ],
    [
      "//))))))))))))))",
      "//))))))))))))))",
      "//))))))))))))))",
      "0/))))))))))))))",
      "//))))))))))))))",
      "//))))))))))))))",
      "//))))))))))))))",
      "//))))))))))))  ",
      "//))))))))))))  ",
      "//))))))))))))  ",
      "////////////// 2",
      "////////////////",
      "//..............",
      "//..............",
      "//..............",
      "//.............."
    ],
    [
      "  &         &3  ",
      "  -  $$$$$$ &3  ",
      "  &  $$$$$$ &3 *",
      "0 &  $$$$$$ &3  ",
      "  &  $$$$$$ &3  ",
      "  &  $$$$$$ &3  ",
      "  &  $$$$$$ &3  ",
      "  &         &   ",
      "  &         &   ",
      "  &&&&&&&&&&&&  ",
      "  &     &       ",
      "  (     (     ( ",
      "  ((((((((((((((",
      "  (         (   ",
      "  (         (   ",
      "  (  +      (   "
    ]
  ],
  "palette": {
    "palette": [
      {
        "char": "!",
        "block": "immersiveengineering:concrete_reinforced"
      },
      {
        "char": "$",
        "block": "immersiveengineering:crate"
      },
      {
        "char": "%",
        "block": "immersiveengineering:metal_barrel"
      },
      {
        "char": "&",
        "block": "minecraft:bricks"
      },
      {
        "char": "'",
        "block": "minecraft:chest[facing=east,type=single,waterlogged=false]",
        "tag": {
          "id": "minecraft:chest",
          "LootTable": "infinite_domain:chests/wasteland_industrial"
        }
      },
      {
        "char": "(",
        "block": "minecraft:mud_bricks"
      },
      {
        "char": ")",
        "block": "minecraft:oak_planks"
      },
      {
        "char": "*",
        "block": "minecraft:oak_stairs[facing=east,half=bottom,shape=straight,waterlogged=false]"
      },
      {
        "char": "+",
        "block": "minecraft:oak_stairs[facing=south,half=bottom,shape=straight,waterlogged=false]"
      },
      {
        "char": ",",
        "block": "minecraft:polished_andesite_stairs[facing=south,half=bottom,shape=straight,waterlogged=false]"
      },
      {
        "char": "-",
        "block": "minecraft:spruce_door[facing=west,half=lower,hinge=left,open=false,powered=false]"
      },
      {
        "char": ".",
        "block": "minecraft:spruce_planks"
      },
      {
        "char": "/",
        "block": "minecraft:stone_bricks"
      },
      {
        "char": "0",
        "block": "minecraft:stripped_dark_oak_log[axis=y]"
      },
      {
        "char": "1",
        "block": "tfmg:factory_floor"
      },
      {
        "char": "2",
        "block": "wastelands:scrap_pile"
      },
      {
        "char": "3",
        "block": "zvhouses:spruce_countertop"
      }
    ]
  }
}
