{
  "xsize": 16,
  "zsize": 16,
  "slices": [
    [
      ",,,,,           ",
      ",,,,,           ",
      ",,,,,           ",
      ",,,,,           ",
      ",,,,,           ",
      ",,,,,           ",
      ",,,,,           ",
      ",,,,,           ",
      ",,,,,           ",
      ",,,,,           ",
      ",,,,,           ",
      ",,,,,           ",
      ",,,,,           ",
      ",,,,,           ",
      ",,,,,           ",
      ",,,,,           "
    ],
    [
      "    !           ",
      "    !           ",
      "    !           ",
      "    !           ",
      "    !           ",
      "    !           ",
      "    !           ",
      "    !           ",
      "!!!!!           ",
      "    !           ",
      "    !           ",
      "    !           ",
      "    !           ",
      "    !           ",
      "    !           ",
      "$$  !           "
    ],
    [
      "    !           ",
      "    !           ",
      "    !           ",
      "    !           ",
      "    !           ",
      "    !           ",
      "    !           ",
      "    !           ",
      "!!!!!           ",
      "    !           ",
      "    !           ",
      "    !           ",
      "    !           ",
      "    !           ",
      "    !           ",
      "$$  !           "
    ],
    [
      "    !           ",
      "    !           ",
      "    !           ",
      "    !           ",
      "    !           ",
      "    !           ",
      "    !           ",
      "    !           ",
      "!!!!!           ",
      "    !           ",
      "    !           ",
      "    !           ",
      "    !           ",
      "    !           ",
      "    !           ",
      "    !           "
    ],
    [
      ")))))(((((++++++",
      ")))))(((((++++++",
      ")))))(((((++++++",
      ")))))(((((++++++",
      ")))))(((((++++++",
      ")))))(((((++++++",
      ")))))(((((++++++",
      ")))))(((((++++++",
      "!!!!)(((((++++++",
      ")))))(((((++++++",
      ")))))(((((++++++",
      ")))))(((((++++++",
      ")))))(((((++++++",
      ")))))(((((++++++",
      ")))))(((((++++++",
      ")))))(((((++++++"
    ],
    [
      "''' &         * ",
      "    &           ",
      "    &           ",
      "    &           ",
      "    &           ",
      "    &           ",
      "''' &         * ",
      "    &           ",
      "    %           ",
      "    &           ",
      "    &           ",
      "    &           ",
      "''' &         * ",
      "    &           ",
      "    &           ",
      "    &           "
    ]
  ],
  "palette": {
    "palette": [
      {
        "char": "!",
        "block": "immersiveengineering:concrete_reinforced"
      },
      {
        "char": "$",
        "block": "immersiveengineering:crate"
      },
      {
        "char": "%",
        "block": "minecraft:dark_oak_door[facing=east,half=lower,hinge=left,open=false,powered=false]"
      },
      {
        "char": "&",
        "block": "minecraft:mud_bricks"
      },
      {
        "char": "'",
        "block": "minecraft:scaffolding"
      },
      {
        "char": "(",
        "block": "minecraft:smooth_stone"
      },
      {
        "char": ")",
        "block": "minecraft:spruce_planks"
      },
      {
        "char": "*",
        "block": "minecraft:yellow_concrete"
      },
      {
        "char": "+",
        "block": "tfmg:asphalt"
      },
      {
        "char": ",",
        "block": "tfmg:factory_floor"
      }
    ]
  }
}
