{
  "xsize": 16,
  "zsize": 16,
  "slices": [
    [
      "  %  &      % ''",
      "  !         %   ",
      "  !         %   ",
      "  %         %   ",
      "  %         %   ",
      ", %         (   ",
      "  %         % ''",
      "  %         %   ",
      "  %%%%%)%%%%%   ",
      "  %         %   ",
      "  %         %   ",
      "  *  $$$$$$ %   ",
      "  %  $$$$$$ % ''",
      ", %  $$$$$$ %   ",
      "  %  $$$$$$ %   ",
      "  !  $$$$$$ %   "
    ],
    [
      "  %         %   ",
      "  !  &      %   ",
      "  !         %   ",
      "  %         %   ",
      "  %         %   ",
      ", %         %   ",
      "  %         %   ",
      "  %         %   ",
      "  %%%%%%%%%%%   ",
      "  %         %   ",
      "  %         %   ",
      "     $$$$$$ %   ",
      "  %  $$$$$$ %   ",
      ", %  $$$$$$ %   ",
      "  %  $$$$$$ %   ",
      "  !  $$$$$$ %   "
    ],
    [
      "  %         %   ",
      "  !         %   ",
      "  !  &      %   ",
      "  %         %   ",
      "  %         %   ",
      ", %         %   ",
      "  %         %   ",
      "  %         %   ",
      "  %%%%%%%%%%%   ",
      "  %         %   ",
      "  %         %   ",
      "  %         %   ",
      "  %         %   ",
      ", %         %   ",
      "  %         %   ",
      "  !         %   "
    ],
    [
      "  %             ",
      "  %             ",
      "  %             ",
      "  %  &          ",
      "  %             ",
      "---             ",
      "---             ",
      "---             ",
      "---             ",
      "---             ",
      "---             ",
      "---             ",
      "---             ",
      "---             ",
      "  %             ",
      "  %             "
    ],
    [
      "  %             ",
      "  %             ",
      "  %             ",
      "  %             ",
      "  %  &          ",
      "  %             ",
      "  %             ",
      "  %             ",
      "  %             ",
      "  %             ",
      "  %             ",
      "  %             ",
      "  %             ",
      "  %             ",
      "  %             ",
      "  %             "
    ],
    [
      "  %+++++++++++++",
      "  %+++++++++++++",
      "  %+++++++++++++",
      "  %++ ++++++++++",
      "  %++ ++++++++++",
      "  %+++++++++++++",
      "  %+++++++++++++",
      "  %+++++++++++++",
      "  %+++++++++++++",
      "  %+++++++++++++",
      "  %+++++++++++++",
      "  %+++++++++++++",
      "  %+++++++++++++",
      "  %+++++++++++++",
      "  %+++++++++++++",
      "  %+++++++++++++"
    ]
  ],
  "palette": {
    "palette": [
      {
        "char": "!",
        "block": "create:framed_glass"
      },
      {
        "char": "$",
        "block": "immersiveengineering:crate"
      },
      {
        "char": "%",
        "block": "minecraft:mud_bricks"
      },
      {
        "char": "&",
        "block": "minecraft:oak_stairs[facing=south,half=bottom,shape=straight,waterlogged=false]"
      },
      {
        "char": "'",
        "block": "minecraft:scaffolding"
      },
      {
        "char": "(",
        "block": "minecraft:spruce_door[facing=east,half=upper,hinge=left,open=false,powered=false]"
      },
      {
        "char": ")",
        "block": "minecraft:spruce_door[facing=south,half=upper,hinge=left,open=false,powered=false]"
      },
      {
        "char": "*",
        "block": "minecraft:spruce_door[facing=west,half=upper,hinge=left,open=false,powered=false]"
      },
      {
        "char": "+",
        "block": "minecraft:spruce_planks"
      },
      {
        "char": ",",
        "block": "minecraft:stripped_dark_oak_log[axis=y]"
      },
      {
        "char": "-",
        "block": "minecraft:weathered_cut_copper"
      }
    ]
  }
}
