{
  "xsize": 16,
  "zsize": 16,
  "slices": [
    [
      ",,,,,,,,,,+     ",
      ",,,,,,,,,,+     ",
      ",,,,,,,,,,+     ",
      ",,,,,,,,,,+     ",
      ",,,,,,,,,,+     ",
      ",,,,,,, ,,+     ",
      ",,,,,,, ,,+     ",
      ",,,,,,,,,,+     ",
      ",,,,,,,,,,+     ",
      ",,,,,,,,,,+     ",
      ",,,,,,,,,,+     ",
      ",,,,,,,,,,+     ",
      ",,,,,,,,,,+     ",
      ",,,,,,,,,,+     ",
      ",,,,,,,,,,+     ",
      ",,,,,,,,,,+     "
    ],
    [
      "     *    +     ",
      "     *    +     ",
      "     *    +     ",
      "  )  &    +     ",
      "  (( *    +     ",
      "%    *    +     ",
      "     *    +     ",
      "  $  *    +     ",
      "  $  *    +     ",
      "******    +     ",
      "     *    +     ",
      "     *    +     ",
      "     *    +     ",
      "     *    +     ",
      "  )  *    +     ",
      "  $( &    +     "
    ],
    [
      "     *    +     ",
      "     *    !     ",
      "     *    !     ",
      "     '    +     ",
      "     *    +     ",
      "     *    +     ",
      "     *    +     ",
      "  $  *    !     ",
      "  $  *    !     ",
      "******    +     ",
      "     *    +     ",
      "     *    !     ",
      "     *    !     ",
      "     *    +     ",
      "     *    +     ",
      "  $  '    +     "
    ],
    [
      "     *    +     ",
      "     *    !     ",
      "     *    !     ",
      "     *    +     ",
      "     *    +     ",
      "     *    +     ",
      "     *    +     ",
      "  $  *    !     ",
      "  $  *    !     ",
      "******    +     ",
      "     *    +     ",
      "     *    !     ",
      "     *    !     ",
      "     *    +     ",
      "     *    +     ",
      "  $  *    +     "
    ],
    [
      "     *    +     ",
      "     *    +     ",
      "     *    +     ",
      "     *    +     ",
      "     *    +     ",
      "     *    +     ",
      "     *    +     ",
      "     *    +     ",
      "     *    +     ",
      "******    +     ",
      "     *    +     ",
      "     *    +     ",
      "     *    +     ",
      "     *    +     ",
      "     *    +     ",
      "     *    +     "
    ],
    [
      "     *    +     ",
      "     *    +     ",
      "     *    +     ",
      "     *    +     ",
      "     *    +     ",
      "     *    +     ",
      "     *    +     ",
      "     *    +     ",
      "     *    +     ",
      "******    +     ",
      "     *    +     ",
      "     *    +     ",
      "     *    +     ",
      "     *    +     ",
      "     *    +     ",
      "     *    +     "
    ]
  ],
  "palette": {
    "palette": [
      {
        "char": "!",
        "block": "create:framed_glass"
      },
      {
        "char": "$",
        "block": "minecraft:bookshelf"
      },
      {
        "char": "%",
        "block": "kubejs:ruined_cartography_table"
      },
      {
        "char": "&",
        "block": "minecraft:dark_oak_door[facing=west,half=lower,hinge=left,open=false,powered=false]"
      },
      {
        "char": "'",
        "block": "minecraft:dark_oak_door[facing=west,half=upper,hinge=left,open=false,powered=false]"
      },
      {
        "char": "(",
        "block": "minecraft:spruce_slab[type=bottom,waterlogged=false]"
      },
      {
        "char": ")",
        "block": "minecraft:spruce_stairs[facing=south,half=bottom,shape=straight,waterlogged=false]"
      },
      {
        "char": "*",
        "block": "minecraft:stripped_spruce_wood"
      },
      {
        "char": "+",
        "block": "tfmg:cinder_block"
      },
      {
        "char": ",",
        "block": "tfmg:factory_floor"
      }
    ]
  }
}
