{
  "xsize": 16,
  "zsize": 16,
  "slices": [
    [
      "  $*************",
      "  $*************",
      "  $*************",
      "  $*************",
      "  $*************",
      "  $************ ",
      "  $************ ",
      "  $************ ",
      "  $************ ",
      "  $$$$$$$$$$$$$ ",
      "  $     $     $ ",
      "  )     )     ) ",
      "  ))))))))))))))",
      "  )/////////////",
      "  )/////////////",
      "  )/////////////"
    ],
    [
      "  $    0      0 ",
      "  $    0      0 ",
      "  $    0      - ",
      "  $    0      0 ",
      "  $    '  &1  0 ",
      "  $    0  %     ",
      "  $    0        ",
      "  $    0        ",
      "  $    0        ",
      "  $$$$$$$$$$$$ $",
      "  $     $       ",
      "  )     )     ) ",
      "  ))))))))))))))",
      "  )    0      0 ",
      "  )    0      0 ",
      "  )  + 0      0 "
    ],
    [
      "  !    0      0 ",
      "  !    0      0 ",
      "  $    0      . ",
      "  $    0      0 ",
      "  $    (        ",
      "  $    0        ",
      "  !    0        ",
      "  !    0        ",
      "  $    0        ",
      "  $$$!!$$$!!$$  ",
      "  $     $       ",
      "  )     )     ) ",
      "  )))!!)))!!)))!",
      "  )    0      0 ",
      "  )    0      0 ",
      "  !    0      0 "
    ],
    [
      "  !    0      0 ",
      "  !    0      0 ",
      "  $    0      0 ",
      "  $    0      0 ",
      "  $    0        ",
      "  $    0        ",
      "  !    0        ",
      "  !    0        ",
      "  $    0        ",
      "  $$$!!$$$!!$$  ",
      "  $     $       ",
      "  )     )     ) ",
      "  )))!!)))!!)))!",
      "  )    0      0 ",
      "  )    0      0 ",
      "  !    0      0 "
    ],
    [
      "  $    0      0 ",
      "  $    0      0 ",
      "  $    0      0 ",
      "  $    0      0 ",
      "  $    0      0 ",
      "  $    0      0 ",
      "  $    0      0 ",
      "  $    0      0 ",
      "  $    0      0 ",
      "  $$$$$$$$$$$$$ ",
      "  $ ,,,,$,,,, $ ",
      "  ) ,,,,),,,, ),",
      "  ))))))))))))))",
      "  )    0      0 ",
      "  )    0      0 ",
      "  )    0      0 "
    ],
    [
      "  $    0        ",
      "  $    0        ",
      "  $    0        ",
      "  $    0        ",
      "  $    0        ",
      "  $    0        ",
      "  $    0        ",
      "  $    0        ",
      "  $    0        ",
      "  $$$$$$$$$$$$$$",
      "  $     $     $ ",
      "  )     )     ) ",
      "  ))))))))))))))",
      "  )    0        ",
      "  )    0        ",
      "  )    0        "
    ]
  ],
  "palette": {
    "palette": [
      {
        "char": "!",
        "block": "create:framed_glass"
      },
      {
        "char": "$",
        "block": "minecraft:bricks"
      },
      {
        "char": "%",
        "block": "minecraft:brown_bed[facing=north,occupied=false,part=foot]"
      },
      {
        "char": "&",
        "block": "minecraft:brown_bed[facing=north,occupied=false,part=head]"
      },
      {
        "char": "'",
        "block": "minecraft:dark_oak_door[facing=east,half=lower,hinge=left,open=false,powered=false]"
      },
      {
        "char": "(",
        "block": "minecraft:dark_oak_door[facing=east,half=upper,hinge=left,open=false,powered=false]"
      },
      {
        "char": ")",
        "block": "minecraft:mud_bricks"
      },
      {
        "char": "*",
        "block": "minecraft:oak_planks"
      },
      {
        "char": "+",
        "block": "minecraft:oak_stairs[facing=south,half=bottom,shape=straight,waterlogged=false]"
      },
      {
        "char": ",",
        "block": "minecraft:smooth_stone_slab[type=top,waterlogged=false]"
      },
      {
        "char": "-",
        "block": "minecraft:spruce_door[facing=east,half=lower,hinge=left,open=false,powered=false]"
      },
      {
        "char": ".",
        "block": "minecraft:spruce_door[facing=east,half=upper,hinge=left,open=false,powered=false]"
      },
      {
        "char": "/",
        "block": "minecraft:spruce_planks"
      },
      {
        "char": "0",
        "block": "minecraft:stripped_spruce_wood"
      },
      {
        "char": "1",
        "block": "minecraft:water_cauldron[level=3]"
      }
    ]
  }
}
