{
  "xsize": 16,
  "zsize": 16,
  "slices": [
    [
      "  11111111111111",
      "  11111111111111",
      "  11111111111111",
      "  11111111111111",
      "  11111111111111",
      "  11111111111111",
      "  11111111111111",
      "  11111111111111",
      "  11111111111111",
      "  11111111111111",
      "  11111111111111",
      "  11111111111111",
      "  11111111111111",
      "  11111111111111",
      "  11111111111111",
      "  11111111111111"
    ],
    [
      "  !  $$$        ",
      "  !  $$$        ",
      "  !             ",
      "  !             ",
      "  !             ",
      "  !             ",
      "  !             ",
      "  !             ",
      "  !!!+!!!!!!!!!!",
      "  !             ",
      "  !             ",
      "  !             ",
      "  !             ",
      "  !             ",
      "  !             ",
      "  !            $"
    ],
    [
      "  !  '$$        ",
      "  !  $$$        ",
      "  !             ",
      "  !             ",
      "  !             ",
      "  !             ",
      "  !             ",
      "  !             ",
      "  !!!,!!!!!!!!!!",
      "  !             ",
      "  !             ",
      "  !             ",
      "  !             ",
      "  !             ",
      "  !             ",
      "  !            $"
    ],
    [
      "  !             ",
      "  !  '          ",
      "  !             ",
      "  !             ",
      "  !             ",
      "  !             ",
      "  !             ",
      "  !             ",
      "  !!!!!!!!!!!!!!",
      "  !             ",
      "  !             ",
      "  !             ",
      "  !             ",
      "  !             ",
      "  !             ",
      "  !             "
    ],
    [
      "//... ..........",
      "//... ..........",
      "//...'..........",
      "//..............",
      "//..............",
      "0/..............",
      "//..............",
      "//..............",
      "//.!!!!!!!!!!!!!",
      "//..............",
      "//..............",
      "//..............",
      "//..............",
      "0/..............",
      "//..............",
      "//.............."
    ],
    [
      "  &         & ((",
      "  &      )  &   ",
      "  &         &   ",
      "  &         &   ",
      "  &         &   ",
      "0 &      %  *   ",
      "  &         & ((",
      "  &         &   ",
      "  &&&&&+&&&&&   ",
      "  &         &   ",
      "  &         &   ",
      "  -  $$$$$$ &   ",
      "  &  $$$$$$ & ((",
      "0 &  $$$$$$ &   ",
      "  &  $$$$$$ &   ",
      "  &  $$$$$$ &   "
    ]
  ],
  "palette": {
    "palette": [
      {
        "char": "!",
        "block": "immersiveengineering:concrete_reinforced"
      },
      {
        "char": "$",
        "block": "immersiveengineering:crate"
      },
      {
        "char": "%",
        "block": "kubejs:ruined_grindstone[face=floor,facing=south]"
      },
      {
        "char": "&",
        "block": "minecraft:mud_bricks"
      },
      {
        "char": "'",
        "block": "minecraft:polished_andesite_stairs[facing=south,half=bottom,shape=straight,waterlogged=false]"
      },
      {
        "char": "(",
        "block": "minecraft:scaffolding"
      },
      {
        "char": ")",
        "block": "kubejs:ruined_smithing_table"
      },
      {
        "char": "*",
        "block": "minecraft:spruce_door[facing=east,half=lower,hinge=left,open=false,powered=false]"
      },
      {
        "char": "+",
        "block": "minecraft:spruce_door[facing=south,half=lower,hinge=left,open=false,powered=false]"
      },
      {
        "char": ",",
        "block": "minecraft:spruce_door[facing=south,half=upper,hinge=left,open=false,powered=false]"
      },
      {
        "char": "-",
        "block": "minecraft:spruce_door[facing=west,half=lower,hinge=left,open=false,powered=false]"
      },
      {
        "char": ".",
        "block": "minecraft:spruce_planks"
      },
      {
        "char": "/",
        "block": "minecraft:stone_bricks"
      },
      {
        "char": "0",
        "block": "minecraft:stripped_dark_oak_log[axis=y]"
      },
      {
        "char": "1",
        "block": "tfmg:factory_floor"
      }
    ]
  }
}
