{
  "xsize": 16,
  "zsize": 16,
  "slices": [
    [
      "     '    !     ",
      "     '    !     ",
      "     '    !     ",
      "     '    !     ",
      "     '    !     ",
      "     '    !     ",
      "     '    !     ",
      "     '    !     ",
      "     '    !     ",
      "     '    !     ",
      "     '    !     ",
      "!!!!!!!!!!!     ",
      "    !     !     ",
      "                ",
      "                ",
      "                "
    ],
    [
      "          !     ",
      "          !     ",
      "          !     ",
      "          !     ",
      "          !     ",
      "          !     ",
      "          !     ",
      "          !     ",
      "          !     ",
      "          !     ",
      "          !     ",
      "!!!!!!!!!!!     ",
      "    !     !     ",
      "                ",
      "                ",
      "                "
    ],
    [
      "&&%%%%%%&&&     ",
      "&&%%%%%%&&&     ",
      "&&%%%%%%&&&     ",
      "&&&&&&&&&&&     ",
      "&&&&&&&&&&&     ",
      "&&&&&&&&&&&     ",
      "&&&&&&&&&&&     ",
      "&&&&&&&&&&&     ",
      "&&&&&&&&&&&     ",
      "&&&&&&&&&&&     ",
      "&&&&&&&&&&&     ",
      "&&&&&&&&&&&     ",
      "                ",
      "                ",
      "                ",
      "                "
    ],
    [
      "  !    !        ",
      "  !    !        ",
      "  !!!!!!        ",
      "                ",
      "                ",
      "     (((        ",
      "     (((        ",
      "     (((        ",
      "                ",
      "                ",
      "                ",
      "!!!!!!!!!!!     ",
      "                ",
      "                ",
      "                ",
      "                "
    ],
    [
      "  !    !        ",
      "  !    !        ",
      "  !!!!!!        ",
      "                ",
      "                ",
      "     (((        ",
      "     (((        ",
      "     (((        ",
      "                ",
      "                ",
      "                ",
      "                ",
      "                ",
      "                ",
      "                ",
      "                "
    ],
    [
      "  &&&&&&        ",
      "  &&&&&&        ",
      "  &&&&&&        ",
      "                ",
      "                ",
      "                ",
      "      $         ",
      "                ",
      "                ",
      "                ",
      "                ",
      "                ",
      "                ",
      "                ",
      "                ",
      "                "
    ]
  ],
  "palette": {
    "palette": [
      {
        "char": "!",
        "block": "minecraft:light_gray_concrete"
      },
      {
        "char": "$",
        "block": "minecraft:lightning_rod[facing=up,waterlogged=false]"
      },
      {
        "char": "%",
        "block": "minecraft:polished_andesite"
      },
      {
        "char": "&",
        "block": "minecraft:smooth_stone"
      },
      {
        "char": "'",
        "block": "minecraft:stripped_spruce_wood"
      },
      {
        "char": "(",
        "block": "minecraft:weathered_copper"
      }
    ]
  }
}
