{
  "xsize": 16,
  "zsize": 16,
  "slices": [
    [
      "& $$$$$$$ !     ",
      "& $$$$$$$ &     ",
      "&         &     ",
      "&         &     ",
      "!!&&&!!&&&&     ",
      "    &     &     ",
      "                ",
      "                ",
      "                ",
      "                ",
      "                ",
      "                ",
      "                ",
      "                ",
      "                ",
      "                "
    ],
    [
      "& $$$$$$$ !     ",
      "& $$$$$$$ &     ",
      "&         &     ",
      "&         &     ",
      "!!&&&!!&&&&     ",
      "    &     &     ",
      "                ",
      "                ",
      "                ",
      "                ",
      "                ",
      "                ",
      "                ",
      "                ",
      "                ",
      "                "
    ],
    [
      "& $$$$$$$ !     ",
      "& $$$$$$$ &     ",
      "&         &     ",
      "&         &     ",
      "&&&&&&&&&&&     ",
      "%%% &%%%  &     ",
      "                ",
      "                ",
      "                ",
      "                ",
      "                ",
      "                ",
      "                ",
      "                ",
      "                ",
      "                "
    ],
    [
      "          &     ",
      "          &     ",
      "          &     ",
      "          &     ",
      "&&&&&&&&&&&     ",
      "    &     &     ",
      "                ",
      "                ",
      "                ",
      "                ",
      "                ",
      "                ",
      "                ",
      "                ",
      "                ",
      "                "
    ],
    [
      "          &     ",
      "          &     ",
      "          &     ",
      "          &     ",
      "&&&&&&&&&&&     ",
      "    &     &     ",
      "                ",
      "                ",
      "                ",
      "                ",
      "                ",
      "                ",
      "                ",
      "                ",
      "                ",
      "                "
    ],
    [
      "''''''''''&     ",
      "''''''''''&     ",
      "''''''''''&     ",
      "''''''''''&     ",
      "&&&&&&&&&&&     ",
      "    &     &     ",
      "                ",
      "                ",
      "                ",
      "                ",
      "                ",
      "                ",
      "                ",
      "                ",
      "                ",
      "                "
    ]
  ],
  "palette": {
    "palette": [
      {
        "char": "!",
        "block": "create:framed_glass"
      },
      {
        "char": "$",
        "block": "immersiveengineering:sheetmetal_steel"
      },
      {
        "char": "%",
        "block": "minecraft:smooth_stone_slab[type=top,waterlogged=false]"
      },
      {
        "char": "&",
        "block": "tfmg:cinder_block"
      },
      {
        "char": "'",
        "block": "tfmg:factory_floor"
      }
    ]
  }
}
