{
  "xsize": 16,
  "zsize": 16,
  "slices": [
    [
      "  (             ",
      "  (             ",
      "  (             ",
      "  (             ",
      "  (  )          ",
      "  (             ",
      "  (             ",
      "  (             ",
      "  (             ",
      "  (             ",
      "  (             ",
      "  (             ",
      "  (             ",
      "  (             ",
      "  (             ",
      "  (             "
    ],
    [
      "  (,,,,,,,,,,,,,",
      "  (,,,,,,,,,,,,,",
      "  (,,,,,,,,,,,,,",
      "  (,, ,,,,,,,,,,",
      "  (,, ,,,,,,,,,,",
      "  (,,,,,,,,,,,,,",
      "  (,,,,,,,,,,,,,",
      "  (,,,,,,,,,,,,,",
      "  (,,,,,,,,,,,,,",
      "  (,,,,,,,,,,,,,",
      "  (,,,,,,,,,,,,,",
      "  (,,,,,,,,,,,,,",
      "  (,,,,,,,,,,,,,",
      "  (,,,,,,,,,,,,,",
      "  (,,,,,,,,,,,,,",
      "  (,,,,,,,,,,,,,"
    ],
    [
      "  (    /      / ",
      "  (    &      / ",
      "  (    /  .   / ",
      "  (    /  --  * ",
      "  (    /    % / ",
      "  (    /  $   / ",
      "  (    /  $   / ",
      "  (    /      / ",
      "  (    /////////",
      "  (    /      / ",
      "  (    /      / ",
      "  (    /      / ",
      "  (    /      / ",
      "  (    /      * ",
      "  (    /  .   / ",
      "  (    &  $-  / "
    ],
    [
      "  !    /      / ",
      "  (    '      / ",
      "  (    /      / ",
      "  (    /      + ",
      "  (    /      / ",
      "  !    /  $   / ",
      "  !    /  $   / ",
      "  (    /      / ",
      "  (    /////////",
      "  (    /      / ",
      "  (    /      / ",
      "  !    /      / ",
      "  !    /      / ",
      "  (    /      + ",
      "  (    /      / ",
      "  (    '  $   / "
    ],
    [
      "  !    /      / ",
      "  (    /      / ",
      "  (    /      / ",
      "  (    /      / ",
      "  (    /      / ",
      "  !    /  $   / ",
      "  !    /  $   / ",
      "  (    /      / ",
      "  (    /////////",
      "  (    /      / ",
      "  (    /      / ",
      "  !    /      / ",
      "  !    /      / ",
      "  (    /      / ",
      "  (    /      / ",
      "  (    /  $   / "
    ],
    [
      "  (    /      / ",
      "  (    /      / ",
      "  (    /      / ",
      "  (    /      / ",
      "  (    /      / ",
      "  (    /      / ",
      "  (    /      / ",
      "  (    /      / ",
      "  (    /////////",
      "  (    /      / ",
      "  (    /      / ",
      "  (    /      / ",
      "  (    /      / ",
      "  (    /      / ",
      "  (    /      / ",
      "  (    /      / "
    ]
  ],
  "palette": {
    "palette": [
      {
        "char": "!",
        "block": "create:framed_glass"
      },
      {
        "char": "$",
        "block": "minecraft:bookshelf"
      },
      {
        "char": "%",
        "block": "kubejs:ruined_cartography_table"
      },
      {
        "char": "&",
        "block": "minecraft:dark_oak_door[facing=east,half=lower,hinge=left,open=false,powered=false]"
      },
      {
        "char": "'",
        "block": "minecraft:dark_oak_door[facing=east,half=upper,hinge=left,open=false,powered=false]"
      },
      {
        "char": "(",
        "block": "minecraft:mud_bricks"
      },
      {
        "char": ")",
        "block": "minecraft:oak_stairs[facing=south,half=bottom,shape=straight,waterlogged=false]"
      },
      {
        "char": "*",
        "block": "minecraft:spruce_door[facing=east,half=lower,hinge=left,open=false,powered=false]"
      },
      {
        "char": "+",
        "block": "minecraft:spruce_door[facing=east,half=upper,hinge=left,open=false,powered=false]"
      },
      {
        "char": ",",
        "block": "minecraft:spruce_planks"
      },
      {
        "char": "-",
        "block": "minecraft:spruce_slab[type=bottom,waterlogged=false]"
      },
      {
        "char": ".",
        "block": "minecraft:spruce_stairs[facing=south,half=bottom,shape=straight,waterlogged=false]"
      },
      {
        "char": "/",
        "block": "minecraft:stripped_spruce_wood"
      }
    ]
  }
}
