{
  "xsize": 16,
  "zsize": 16,
  "slices": [
    [
      "                ",
      "                ",
      "                ",
      "                ",
      "                ",
      "                ",
      "                ",
      "                ",
      "                ",
      "                ",
      "                ",
      "                ",
      "                ",
      "                ",
      "                ",
      "                "
    ],
    [
      "                ",
      "                ",
      "                ",
      "                ",
      "                ",
      "                ",
      "                ",
      "                ",
      "                ",
      "                ",
      "                ",
      "$               ",
      "$               ",
      "$               ",
      "$               ",
      "$               "
    ],
    [
      "!!!!!!!!!!!!!!  ",
      "!!!!!!!!!!!!!!  ",
      "!!!!!!!!!!!!!!  ",
      "!!!!!!!!!!!!!!  ",
      "!!!!!!!!!!!!!!  ",
      "!!!!!!!!!!!!!!  ",
      "!!!!!!!!!!!!!!  ",
      "!!!!!!!!!!!!!!  ",
      "!!!!!!!!!!!!!!  ",
      "!!!!!!!!!!!!!!  ",
      "!!!!!!!!!!!!!!  ",
      "$!!!!!!!!!!!!!  ",
      "$!!!!!!!!!!!!!  ",
      "$!!!!!!!!!!!!!  ",
      "$!!!!!!!!!!!!!  ",
      "$!!!!!!!!!!!!!  "
    ],
    [
      "  !!!!!!!!!!!!  ",
      "  !!!!!!!!!!!!  ",
      "  !!!!!!!!!!!!  ",
      "  !!!!!!!!!!!!  ",
      "  !!!!!!!!!!!!  ",
      "  !!!!!!!!!!!!  ",
      "  !!!!!!!!!!!!  ",
      "  !!!!!!!!!!!!  ",
      "  !!!!!!!!!!!!  ",
      "  !!!!!!!!!!!!  ",
      "  !!!!!!!!!!!!  ",
      "  !!!!!!!!!!!!  ",
      "  !!!!!!!!!!!!  ",
      "  !!!!!!!!!!!!  ",
      "  !!!!!!!!!!!!  ",
      "  !!!!!!!!!!!!  "
    ],
    [
      "  !!!!!!!!!!!!  ",
      "  !!!!!!!!!!!!  ",
      "  !!!!!!!!!!!!  ",
      "  !!!!!!!!!!!!  ",
      "  !!!!!!!!!!!!  ",
      "  !!!!!!!!!!!!  ",
      "  !!!!!!!!!!!!  ",
      "  !!!!!!!!!!!!  ",
      "  !!!!!!!!!!!!  ",
      "  !!!!!!!!!!!!  ",
      "  !!!!!!!!!!!!  ",
      "  !!!!!!!!!!!!  ",
      "  !!!!!!!!!!!!  ",
      "  !!!!!!!!!!!!  ",
      "  !!!!!!!!!!!!  ",
      "  !!!!!!!!!!!!  "
    ],
    [
      "  !!!!!!!!!!!!  ",
      "  !!!!!!!!!!!!  ",
      "  !!!!!!!!!!!!  ",
      "  !!!!!!!!!!!!  ",
      "  !!!!!!!!!!!!  ",
      "  !!!!!!!!!!!!  ",
      "  !!!!!!!!!!!!  ",
      "  !!!!!!!!!!!!  ",
      "  !!!!!!!!!!!!  ",
      "  !!!!!!!!!!!!  ",
      "  !!!!!!!!!!!!  ",
      "  !!!!!!!!!!!!  ",
      "  !!!!!!!!!!!!  ",
      "  !!!!!!!!!!!!  ",
      "  !!!!!!!!!!!!  ",
      "  !!!!!!!!!!!!  "
    ]
  ],
  "palette": {
    "palette": [
      {
        "char": "!",
        "block": "immersiveengineering:concrete_reinforced"
      },
      {
        "char": "$",
        "block": "tfmg:asphalt"
      }
    ]
  }
}
