{
  "xsize": 16,
  "zsize": 16,
  "slices": [
    [
      "+         +     ",
      "+         +     ",
      "+ %%%% &  +     ",
      "+ %%%%    !     ",
      "+ %%%%    !     ",
      "+ %%%%    +     ",
      "' %%%%    + )   ",
      "+ %%%%    +     ",
      "+         +     ",
      "+++++(+++++     ",
      "+         +     ",
      "+         +     ",
      "+ $$$$$$$ '     ",
      "+ $$$$$$$ +     ",
      "+ $$$$$$$ + )   ",
      "+ $$$$$$$ !     "
    ],
    [
      "+         +     ",
      "+         +     ",
      "+ %%%%    +     ",
      "+ %%%% &  !     ",
      "+ %%%%    !     ",
      "+ %%%%    +     ",
      "+ %%%%    + )   ",
      "+ %%%%    +     ",
      "+         +     ",
      "+++++++++++     ",
      "+         +     ",
      "+         +     ",
      "+ $$$$$$$       ",
      "+ $$$$$$$ +     ",
      "+ $$$$$$$ + )   ",
      "+ $$$$$$$ !     "
    ],
    [
      "+         +     ",
      "+         +     ",
      "+         +     ",
      "+         !     ",
      "+      &  !     ",
      "+         +     ",
      "+         + )   ",
      "+         +     ",
      "+         +     ",
      "+++++++++++     ",
      "+         +     ",
      "+         +     ",
      "+ $$$$$$$ +     ",
      "+ $$$$$$$ +     ",
      "+ $$$$$$$ + )   ",
      "+ $$$$$$$ !     "
    ],
    [
      "          +     ",
      "          +     ",
      "          +     ",
      "          +     ",
      "          +     ",
      "       &  +     ",
      "          ***   ",
      "          ***   ",
      "          ***   ",
      "          ***   ",
      "          ***   ",
      "          ***   ",
      "          ***   ",
      "          ***   ",
      "          ***   ",
      "          +     "
    ],
    [
      "          +     ",
      "          +     ",
      "          +     ",
      "          +     ",
      "          +     ",
      "          +     ",
      "       &  +     ",
      "          +     ",
      "          +     ",
      "          +     ",
      "          +     ",
      "          +     ",
      "          +     ",
      "          +     ",
      "          +     ",
      "          +     "
    ],
    [
      ",,,,,,,,,,+     ",
      ",,,,,,,,,,+     ",
      ",,,,,,,,,,+     ",
      ",,,,,,,,,,+     ",
      ",,,,,,,,,,+     ",
      ",,,,,,, ,,+     ",
      ",,,,,,, ,,+     ",
      ",,,,,,,,,,+     ",
      ",,,,,,,,,,+     ",
      ",,,,,,,,,,+     ",
      ",,,,,,,,,,+     ",
      ",,,,,,,,,,+     ",
      ",,,,,,,,,,+     ",
      ",,,,,,,,,,+     ",
      ",,,,,,,,,,+     ",
      ",,,,,,,,,,+     "
    ]
  ],
  "palette": {
    "palette": [
      {
        "char": "!",
        "block": "create:framed_glass"
      },
      {
        "char": "$",
        "block": "immersiveengineering:sheetmetal_steel"
      },
      {
        "char": "%",
        "block": "minecraft:bookshelf"
      },
      {
        "char": "&",
        "block": "minecraft:oak_stairs[facing=south,half=bottom,shape=straight,waterlogged=false]"
      },
      {
        "char": "'",
        "block": "minecraft:spruce_door[facing=east,half=upper,hinge=left,open=false,powered=false]"
      },
      {
        "char": "(",
        "block": "minecraft:spruce_door[facing=south,half=upper,hinge=left,open=false,powered=false]"
      },
      {
        "char": ")",
        "block": "minecraft:stripped_dark_oak_log[axis=y]"
      },
      {
        "char": "*",
        "block": "minecraft:weathered_cut_copper"
      },
      {
        "char": "+",
        "block": "tfmg:cinder_block"
      },
      {
        "char": ",",
        "block": "tfmg:factory_floor"
      }
    ]
  }
}
