{
  "xsize": 16,
  "zsize": 16,
  "slices": [
    [
      "          (     ",
      "          (     ",
      "          (     ",
      "          (     ",
      "          (     ",
      "          (     ",
      "          (     ",
      "          (     ",
      "          (     ",
      "          (     ",
      "          (     ",
      "          (     ",
      "          (     ",
      "          (     ",
      "          (     ",
      "          (     "
    ],
    [
      "'''''''''''     ",
      "'''''''''''     ",
      "''!!'!!''''     ",
      "''!!'!!''''     ",
      "''!!'!!''''     ",
      "''!!'!!''''     ",
      "''!!)!!)'''     ",
      "''!!)!!)'''     ",
      "''))))))'''     ",
      "''))))))'''     ",
      "''))))))'''     ",
      "''))))))'''     ",
      "''))))))'''     ",
      "'''''''''''     ",
      "'''''''''''     ",
      "'''''''''''     "
    ],
    [
      "                ",
      "                ",
      "                ",
      "                ",
      "                ",
      "                ",
      "  ((((((        ",
      "  (    (        ",
      "  (    (        ",
      "  (    (        ",
      "  (    (        ",
      "  (    (        ",
      "  ((((((        ",
      "                ",
      "     &&&        ",
      "     &&&        "
    ],
    [
      "                ",
      "                ",
      "                ",
      "                ",
      "                ",
      "                ",
      "  ((((((        ",
      "  (    (        ",
      "  (    (        ",
      "  (    (        ",
      "  (    (        ",
      "  (    (        ",
      "  ((((((        ",
      "                ",
      "     &&&        ",
      "     &&&        "
    ],
    [
      "                ",
      "                ",
      "                ",
      "                ",
      "                ",
      "                ",
      "  %%%%%%        ",
      "  %%%%%%        ",
      "  %%%%%%        ",
      "  %%%%%%        ",
      "  %%%%%%        ",
      "  %%%%%%        ",
      "  %%%%%%        ",
      "                ",
      "                ",
      "      $         "
    ],
    [
      "                ",
      "                ",
      "                ",
      "                ",
      "                ",
      "                ",
      "                ",
      "                ",
      "                ",
      "                ",
      "                ",
      "                ",
      "                ",
      "                ",
      "                ",
      "                "
    ]
  ],
  "palette": {
    "palette": [
      {
        "char": "!",
        "block": "create:framed_glass"
      },
      {
        "char": "$",
        "block": "minecraft:lightning_rod[facing=up,waterlogged=false]"
      },
      {
        "char": "%",
        "block": "minecraft:smooth_stone"
      },
      {
        "char": "&",
        "block": "minecraft:weathered_copper"
      },
      {
        "char": "'",
        "block": "minecraft:weathered_cut_copper"
      },
      {
        "char": "(",
        "block": "tfmg:cinder_block"
      },
      {
        "char": ")",
        "block": "tfmg:factory_floor"
      }
    ]
  }
}
