{
  "xsize": 16,
  "zsize": 16,
  "slices": [
    [
      "-----------     ",
      "-----------     ",
      "-----------     ",
      "-----------     ",
      "-----------     ",
      "-----------     ",
      "-----------     ",
      "-----------     ",
      "-----------     ",
      "-----------     ",
      "-----------     ",
      "-----------     ",
      "                ",
      "                ",
      "-----------     ",
      "-----------     "
    ],
    [
      "          !     ",
      "          !     ",
      "          !     ",
      "          !     ",
      "          !     ",
      "          !     ",
      "     $$$  !     ",
      "     $$$  !     ",
      "     $$$  !     ",
      "          !     ",
      "          !     ",
      "!!!!!!!!!!!     ",
      "                ",
      "                ",
      "!!!!!!!!!!!     ",
      "          !     "
    ],
    [
      "          !     ",
      "          !     ",
      "          !     ",
      "          !     ",
      "          !     ",
      "          !     ",
      "     $$$  !     ",
      "     $$$  !     ",
      "     $$$  !     ",
      "          !     ",
      "          !     ",
      "!!!!!!!!!!!     ",
      "                ",
      "                ",
      "!!!!!!!!!!!     ",
      "          !     "
    ],
    [
      "          !     ",
      "          !     ",
      "          !     ",
      "          !     ",
      "          !     ",
      "          !     ",
      "          !     ",
      "          !     ",
      "          !     ",
      "          !     ",
      "          !     ",
      "!!!!!!!!!!!     ",
      "                ",
      "                ",
      "!!!!!!!!!!!     ",
      "          !     "
    ],
    [
      "&&&&&&&&&&&((   ",
      "&&&&&&&&&&&((   ",
      "&&&&&&&&&&&((   ",
      "&&&&&&&&&&&((   ",
      "&&&&&&&&&&&()   ",
      "&&&&&&&&&&&((   ",
      "&&&&&&&&&&&((   ",
      "&&&&&&&&&&&((   ",
      "&&&&&&&&&&&((   ",
      "&&&&&&&&&&&((   ",
      "&&&&&&&&&&&((   ",
      "&&&&&&&&&&&((   ",
      "(((((((((((((   ",
      "(((((((((((((   ",
      "-----------((   ",
      "-----------((   "
    ],
    [
      "%         %     ",
      "%         %     ",
      "% +++++++ '     ",
      "% +++++++ %     ",
      "% +++++++ % )   ",
      "%         %     ",
      "%         %     ",
      "%         %     ",
      "%      *  %     ",
      "%         %     ",
      "%         %     ",
      "%%%%%%%%%%%     ",
      "    %     %     ",
      "    ,     ,     ",
      ",,,,,,,,,,,     ",
      ",         ,     "
    ]
  ],
  "palette": {
    "palette": [
      {
        "char": "!",
        "block": "immersiveengineering:concrete_reinforced"
      },
      {
        "char": "$",
        "block": "immersiveengineering:crate"
      },
      {
        "char": "%",
        "block": "minecraft:light_gray_concrete"
      },
      {
        "char": "&",
        "block": "minecraft:polished_andesite"
      },
      {
        "char": "'",
        "block": "minecraft:spruce_door[facing=east,half=lower,hinge=left,open=false,powered=false]"
      },
      {
        "char": "(",
        "block": "minecraft:stone_bricks"
      },
      {
        "char": ")",
        "block": "minecraft:stripped_dark_oak_log[axis=y]"
      },
      {
        "char": "*",
        "block": "minecraft:water_cauldron[level=3]"
      },
      {
        "char": "+",
        "block": "minecraft:white_concrete"
      },
      {
        "char": ",",
        "block": "tfmg:cinder_block"
      },
      {
        "char": "-",
        "block": "tfmg:factory_floor"
      }
    ]
  }
}
