{
  "xsize": 16,
  "zsize": 16,
  "slices": [
    [
      "  ))))))))))))))",
      "  ))))))))))))))",
      "  ))))))))))))))",
      "  ))))))))))))))",
      "  ))))))))))))))",
      "                ",
      "                ",
      "                ",
      "                ",
      "                ",
      "                ",
      "                ",
      "                ",
      "                ",
      "                ",
      "                "
    ],
    [
      "  !            $",
      "  ! %          $",
      "  !             ",
      "  !             ",
      "  !!!!!!!!!!!!!!",
      "                ",
      "                ",
      "                ",
      "                ",
      "                ",
      "                ",
      "                ",
      "                ",
      "                ",
      "                ",
      "                "
    ],
    [
      "  !            $",
      "  !            $",
      "  !             ",
      "  !             ",
      "  !!!!!!!!!!!!!!",
      "                ",
      "                ",
      "                ",
      "                ",
      "                ",
      "                ",
      "                ",
      "                ",
      "                ",
      "                ",
      "                "
    ],
    [
      "  !             ",
      "  !             ",
      "  !             ",
      "  !             ",
      "  !!!!!!!!!!!!!!",
      "                ",
      "                ",
      "                ",
      "                ",
      "                ",
      "                ",
      "                ",
      "                ",
      "                ",
      "                ",
      "                "
    ],
    [
      "((''''''''''''''",
      "((''''''''''''''",
      "((''''''''''''''",
      "((''''''''''''''",
      "((''''''''''''''",
      "((((((((((((((((",
      "((((((((((((((((",
      "                ",
      "                ",
      "                ",
      "                ",
      "                ",
      "                ",
      "                ",
      "                ",
      "                "
    ],
    [
      "  &  $$$$$$ &   ",
      "  &  $$$$$$ &   ",
      "  &         &   ",
      "  &         &   ",
      "  &&&&&&&&&&&&&&",
      "  &     &     & ",
      "                ",
      "                ",
      "                ",
      "                ",
      "                ",
      "                ",
      "                ",
      "                ",
      "                ",
      "                "
    ]
  ],
  "palette": {
    "palette": [
      {
        "char": "!",
        "block": "immersiveengineering:concrete_reinforced"
      },
      {
        "char": "$",
        "block": "immersiveengineering:crate"
      },
      {
        "char": "%",
        "block": "immersiveengineering:metal_barrel"
      },
      {
        "char": "&",
        "block": "minecraft:mud_bricks"
      },
      {
        "char": "'",
        "block": "minecraft:spruce_planks"
      },
      {
        "char": "(",
        "block": "minecraft:stone_bricks"
      },
      {
        "char": ")",
        "block": "tfmg:factory_floor"
      }
    ]
  }
}
