{
  "xsize": 16,
  "zsize": 16,
  "slices": [
    [
      "$$$$$$$$$       ",
      "$$$$$$$$$       ",
      "$$$$$$$$$       ",
      "$$$$$$$$$       ",
      "$$$$$$$$$       ",
      "$$$$$$$$$       ",
      "$$$$$$$$$       ",
      "$$$$$$$$$       ",
      "$$$$$$$$$       ",
      "$$$$$$$$$       ",
      "$$$$$$$$$       ",
      "$$$$$$$$$       ",
      "$$$$$$$$$       ",
      "$$$$$$$$$       ",
      "$$$$$$$$        ",
      "$$$$$$$$        "
    ],
    [
      "                ",
      "                ",
      "                ",
      "                ",
      "                ",
      "                ",
      "                ",
      "                ",
      "                ",
      "                ",
      "                ",
      "                ",
      "                ",
      "                ",
      "!!!!!!!!!       ",
      "!!!!!!!!!       "
    ],
    [
      "                ",
      "                ",
      "                ",
      "                ",
      "                ",
      "                ",
      "                ",
      "                ",
      "                ",
      "                ",
      "                ",
      "                ",
      "                ",
      "                ",
      "!!!!!!!!!       ",
      "!!!!!!!!!       "
    ],
    [
      "                ",
      "                ",
      "                ",
      "                ",
      "                ",
      "                ",
      "                ",
      "                ",
      "                ",
      "                ",
      "                ",
      "                ",
      "                ",
      "                ",
      "!!!!!!!!!       ",
      "!!!!!!!!!       "
    ],
    [
      "                ",
      "                ",
      "                ",
      "                ",
      "                ",
      "                ",
      "                ",
      "                ",
      "                ",
      "                ",
      "                ",
      "                ",
      "                ",
      "                ",
      "!!!!!!!!!       ",
      "!!!!!!!!!       "
    ],
    [
      "                ",
      "                ",
      "                ",
      "                ",
      "                ",
      "                ",
      "                ",
      "                ",
      "                ",
      "                ",
      "                ",
      "                ",
      "                ",
      "                ",
      "!!!!!!!!!       ",
      "!!!!!!!!!       "
    ]
  ],
  "palette": {
    "palette": [
      {
        "char": "!",
        "block": "minecraft:stone_bricks"
      },
      {
        "char": "$",
        "block": "tfmg:asphalt"
      }
    ]
  }
}
