{
  "xsize": 16,
  "zsize": 16,
  "slices": [
    [
      "                ",
      "                ",
      "                ",
      "                ",
      "                ",
      "                ",
      "                ",
      "                ",
      "                ",
      "                ",
      "                ",
      "                ",
      "                ",
      "                ",
      "                ",
      "                "
    ],
    [
      "                ",
      "                ",
      "                ",
      "                ",
      "                ",
      "++++++++++      ",
      "++++++++++      ",
      "++++++++++      ",
      "++++++++++      ",
      "++++++++++      ",
      "++++++++++      ",
      "++++++++++      ",
      "++++++++++      ",
      "++++++++++      ",
      "++++++++++      ",
      "++++++++++      "
    ],
    [
      "                ",
      "                ",
      "                ",
      "                ",
      "                ",
      "!!!!!!!!!!      ",
      "         !      ",
      "         !      ",
      "    % &  !      ",
      "         !      ",
      "         !      ",
      "         !      ",
      "         !      ",
      "*(*******!      ",
      "     ''''!      ",
      "  $$ ''''!      "
    ],
    [
      "                ",
      "                ",
      "                ",
      "                ",
      "                ",
      "!!!!!!!!!!      ",
      "         !      ",
      "         !      ",
      "         !      ",
      "         !      ",
      "         !      ",
      "         !      ",
      "         !      ",
      "*)*******!      ",
      "     ''''!      ",
      "  $$ ''''!      "
    ],
    [
      "                ",
      "                ",
      "                ",
      "                ",
      "                ",
      "!!!!!!!!!!      ",
      "         !      ",
      "         !      ",
      "         !      ",
      "         !      ",
      "         !      ",
      "         !      ",
      "         !      ",
      "*********!      ",
      "         !      ",
      "         !      "
    ],
    [
      "                ",
      "                ",
      "                ",
      "                ",
      "                ",
      "!!!!!!!!!!      ",
      "         !      ",
      "         !      ",
      "         !      ",
      "         !      ",
      "         !      ",
      "         !      ",
      "         !      ",
      "*********!      ",
      "         !      ",
      "         !      "
    ]
  ],
  "palette": {
    "palette": [
      {
        "char": "!",
        "block": "immersiveengineering:concrete_reinforced"
      },
      {
        "char": "$",
        "block": "immersiveengineering:crate"
      },
      {
        "char": "%",
        "block": "immersiveengineering:metal_barrel"
      },
      {
        "char": "&",
        "block": "minecraft:barrel[facing=up,open=false]"
      },
      {
        "char": "'",
        "block": "minecraft:gravel"
      },
      {
        "char": "(",
        "block": "minecraft:spruce_door[facing=south,half=lower,hinge=left,open=false,powered=false]"
      },
      {
        "char": ")",
        "block": "minecraft:spruce_door[facing=south,half=upper,hinge=left,open=false,powered=false]"
      },
      {
        "char": "*",
        "block": "tfmg:cinder_block"
      },
      {
        "char": "+",
        "block": "tfmg:factory_floor"
      }
    ]
  }
}
