{
  "xsize": 16,
  "zsize": 16,
  "slices": [
    [
      "                ",
      "                ",
      "                ",
      "                ",
      "                ",
      "                ",
      "                ",
      "                ",
      "                ",
      "                ",
      "                ",
      "                ",
      "                ",
      "                ",
      "                ",
      "                "
    ],
    [
      " 111111111111111",
      " 111111111111111",
      " 111111111111111",
      " 111111111111111",
      " 111111111111111",
      " 111111111111111",
      " 111111111111111",
      " 111111111111111",
      " 111111111111111",
      " 111111111111111",
      "                ",
      "                ",
      "                ",
      "                ",
      "                ",
      "                "
    ],
    [
      " ! (   (  % 0 $$",
      " !          )   ",
      " !          0   ",
      " !00000+00000000",
      " !          0   ",
      " ! .        0   ",
      " ! /   - &  0 ' ",
      " !          0   ",
      " !          0   ",
      " !!!!!!!!!!!!!!!",
      "                ",
      "                ",
      "                ",
      "                ",
      "                ",
      "                "
    ],
    [
      " !          0 $$",
      " !          *   ",
      " !          0   ",
      " !00000,00000000",
      " !          0   ",
      " !          0   ",
      " !          0   ",
      " !          0   ",
      " !          0   ",
      " !!!!!!!!!!!!!!!",
      "                ",
      "                ",
      "                ",
      "                ",
      "                ",
      "                "
    ],
    [
      " !          0   ",
      " !          0   ",
      " !          0   ",
      " !00000000000000",
      " !          0   ",
      " !          0   ",
      " !          0   ",
      " !          0   ",
      " !          0   ",
      " !!!!!!!!!!!!!!!",
      "                ",
      "                ",
      "                ",
      "                ",
      "                ",
      "                "
    ],
    [
      " !          0   ",
      " !          0   ",
      " !          0   ",
      " !00000000000000",
      " !          0   ",
      " !          0   ",
      " !          0   ",
      " !          0   ",
      " !          0   ",
      " !!!!!!!!!!!!!!!",
      "                ",
      "                ",
      "                ",
      "                ",
      "                ",
      "                "
    ]
  ],
  "palette": {
    "palette": [
      {
        "char": "!",
        "block": "immersiveengineering:concrete_reinforced"
      },
      {
        "char": "$",
        "block": "immersiveengineering:crate"
      },
      {
        "char": "%",
        "block": "minecraft:barrel[facing=up,open=false]"
      },
      {
        "char": "&",
        "block": "kubejs:ruined_brewing_stand"
      },
      {
        "char": "'",
        "block": "kubejs:ruined_crafting_table"
      },
      {
        "char": "(",
        "block": "minecraft:gray_bed[facing=south,occupied=false,part=head]"
      },
      {
        "char": ")",
        "block": "minecraft:spruce_door[facing=east,half=lower,hinge=left,open=false,powered=false]"
      },
      {
        "char": "*",
        "block": "minecraft:spruce_door[facing=east,half=upper,hinge=left,open=false,powered=false]"
      },
      {
        "char": "+",
        "block": "minecraft:spruce_door[facing=south,half=lower,hinge=left,open=false,powered=false]"
      },
      {
        "char": ",",
        "block": "minecraft:spruce_door[facing=south,half=upper,hinge=left,open=false,powered=false]"
      },
      {
        "char": "-",
        "block": "kubejs:ruined_cauldron"
      },
      {
        "char": ".",
        "block": "minecraft:white_bed[facing=south,occupied=false,part=foot]"
      },
      {
        "char": "/",
        "block": "minecraft:white_bed[facing=south,occupied=false,part=head]"
      },
      {
        "char": "0",
        "block": "tfmg:cinder_block"
      },
      {
        "char": "1",
        "block": "tfmg:factory_floor"
      }
    ]
  }
}
