{
  "xsize": 16,
  "zsize": 16,
  "slices": [
    [
      "                ",
      "                ",
      "                ",
      "                ",
      "                ",
      "                ",
      "                ",
      "                ",
      "                ",
      "                ",
      "                ",
      "                ",
      "                ",
      "                ",
      "                ",
      "                "
    ],
    [
      "++++++++++      ",
      "++++++++++      ",
      "++++++++++      ",
      "++++++++++      ",
      "++++++++++      ",
      "++++++++++      ",
      "++++++++++      ",
      "++++++++++      ",
      "++++++++++      ",
      "++++++++++      ",
      "                ",
      "                ",
      "                ",
      "                ",
      "                ",
      "                "
    ],
    [
      "  $$  $$ !      ",
      "         !      ",
      "         !      ",
      "*'*******!      ",
      "         !      ",
      "  ,,,,   !      ",
      "% ,,,,   !      ",
      "  ,,,, & !      ",
      "         !      ",
      "!!!!!!!!!!      ",
      "                ",
      "                ",
      "                ",
      "                ",
      "                ",
      "                "
    ],
    [
      "  $$  $$ !      ",
      "         !      ",
      "         !      ",
      "*(*******!      ",
      "         !      ",
      "         !      ",
      "     )   !      ",
      "       & !      ",
      "         !      ",
      "!!!!!!!!!!      ",
      "                ",
      "                ",
      "                ",
      "                ",
      "                ",
      "                "
    ],
    [
      "         !      ",
      "         !      ",
      "         !      ",
      "*********!      ",
      "         !      ",
      "         !      ",
      "         !      ",
      "       & !      ",
      "         !      ",
      "!!!!!!!!!!      ",
      "                ",
      "                ",
      "                ",
      "                ",
      "                ",
      "                "
    ],
    [
      "         !      ",
      "         !      ",
      "         !      ",
      "*********!      ",
      "         !      ",
      "         !      ",
      "         !      ",
      "       & !      ",
      "         !      ",
      "!!!!!!!!!!      ",
      "                ",
      "                ",
      "                ",
      "                ",
      "                ",
      "                "
    ]
  ],
  "palette": {
    "palette": [
      {
        "char": "!",
        "block": "immersiveengineering:concrete_reinforced"
      },
      {
        "char": "$",
        "block": "immersiveengineering:crate"
      },
      {
        "char": "%",
        "block": "kubejs:ruined_furnace[facing=north]"
      },
      {
        "char": "&",
        "block": "minecraft:ladder[facing=west,waterlogged=false]"
      },
      {
        "char": "'",
        "block": "minecraft:spruce_door[facing=south,half=lower,hinge=left,open=false,powered=false]"
      },
      {
        "char": "(",
        "block": "minecraft:spruce_door[facing=south,half=upper,hinge=left,open=false,powered=false]"
      },
      {
        "char": ")",
        "block": "supplementaries:item_shelf"
      },
      {
        "char": "*",
        "block": "tfmg:cinder_block"
      },
      {
        "char": "+",
        "block": "tfmg:factory_floor"
      },
      {
        "char": ",",
        "block": "zvhouses:stone_brick_countertop"
      }
    ]
  }
}
