{
  "xsize": 16,
  "zsize": 16,
  "slices": [
    [
      "                ",
      "       $$$)(  %)",
      "      $$$$$(   (",
      "      $$$$$     ",
      "      $$$$$     ",
      "       $$$      ",
      "       !$+++++++",
      "       %        ",
      "       %        ",
      "       %        ",
      "       %%%%%%%%%",
      "                ",
      "                ",
      "                ",
      "                ",
      "                "
    ],
    [
      "        ''      ",
      "            %%%(",
      "        $      (",
      "       $$$      ",
      "        $       ",
      "                ",
      "       %++++++++",
      "       %        ",
      "       %        ",
      "       %        ",
      "       %%%%%%%%%",
      "                ",
      "                ",
      "                ",
      "                ",
      "                "
    ],
    [
      "          &&&&&&",
      "            &&&&",
      "            &&&&",
      "                ",
      "                ",
      "                ",
      "       %        ",
      "       %        ",
      "       %        ",
      "       %        ",
      "       %%%%%%%%%",
      "                ",
      "                ",
      "                ",
      "                ",
      "                "
    ],
    [
      "                ",
      "            ****",
      "            ****",
      "            ****",
      "            ****",
      "            ****",
      "       *********",
      "       *********",
      "       *********",
      "       *********",
      "       *********",
      "                ",
      "                ",
      "                ",
      "                ",
      "                "
    ],
    [
      "                ",
      "                ",
      "                ",
      "                ",
      "                ",
      "                ",
      "                ",
      "                ",
      "                ",
      "                ",
      "                ",
      "                ",
      "                ",
      "                ",
      "                ",
      "                "
    ]
  ],
  "palette": {
    "palette": [
      {
        "char": "!",
        "block": "create:framed_glass"
      },
      {
        "char": "$",
        "block": "minecraft:gravel"
      },
      {
        "char": "%",
        "block": "minecraft:mud_bricks"
      },
      {
        "char": "&",
        "block": "minecraft:smooth_stone_slab[type=top,waterlogged=false]"
      },
      {
        "char": "'",
        "block": "minecraft:spruce_slab[type=top,waterlogged=false]"
      },
      {
        "char": "(",
        "block": "minecraft:stripped_dark_oak_log[axis=y]"
      },
      {
        "char": ")",
        "block": "minecraft:stripped_spruce_log[axis=y]"
      },
      {
        "char": "*",
        "block": "minecraft:weathered_cut_copper"
      },
      {
        "char": "+",
        "block": "tfmg:cinder_block"
      }
    ]
  }
}
