{
  "xsize": 16,
  "zsize": 16,
  "slices": [
    [
      "                ",
      "                ",
      "                ",
      "                ",
      "                ",
      " !!!!!!!!!!!!!!!",
      " !              ",
      " !              ",
      " !              ",
      " !              ",
      " !          ,   ",
      " !              ",
      " !              ",
      " !              ",
      " !              ",
      " !              "
    ],
    [
      "                ",
      "                ",
      "                ",
      "                ",
      "                ",
      " !!!!!!!!!!!!!!!",
      " !              ",
      " !              ",
      " !              ",
      " !          ,   ",
      " !              ",
      " !              ",
      " !              ",
      " !              ",
      " !              ",
      " !              "
    ],
    [
      "                ",
      "                ",
      "                ",
      "                ",
      "                ",
      " !!!!!!!!!!!!!!!",
      " !!!!!!!!!!!!!!!",
      " !!!!!!!!!!!!!!!",
      " !!!!!!!!!!!,!!!",
      " !!!!!!!!!!! !!!",
      " !!!!!!!!!!! !!!",
      " !!!!!!!!!!!!!!!",
      " !!!!!!!!!!!!!!!",
      " !!!!!!!!!!!!!!!",
      " !!!!!!!!!!!!!!!",
      " !!!!!!!!!!!!!!!"
    ],
    [
      "          ))))))",
      "      $+++++++++",
      "      $+++++++++",
      "      $+++++++++",
      "      $+++++++++",
      "      $+++++++++",
      "      $+++++++++",
      "      $+++++,+++",
      "      $+++++ +++",
      "      $+++++ +++",
      "      $+++++++++",
      "      $$$$$$$$$$",
      "                ",
      "                ",
      "                ",
      "                "
    ],
    [
      "        //      ",
      "      )))))0%&*0",
      "      )))))0   0",
      "      )))))     ",
      "      )))))     ",
      "      )))))     ",
      "      )))))22-22",
      "       *        ",
      "       * 3      ",
      "       *        ",
      "       *********",
      "                ",
      "                ",
      "                ",
      "                ",
      "                "
    ],
    [
      "                ",
      "      )))))0'(*1",
      "      )))))0   0",
      "      )))))     ",
      "      )))))     ",
      "      )))))     ",
      "      )))))22.22",
      "       *        ",
      "       *        ",
      "       *        ",
      "       *********",
      "                ",
      "                ",
      "                ",
      "                ",
      "                "
    ]
  ],
  "palette": {
    "palette": [
      {
        "char": "!",
        "block": "immersiveengineering:concrete_reinforced"
      },
      {
        "char": "$",
        "block": "minecraft:coarse_dirt"
      },
      {
        "char": "%",
        "block": "minecraft:dark_oak_door[facing=north,half=lower,hinge=left,open=false,powered=false]"
      },
      {
        "char": "&",
        "block": "minecraft:dark_oak_door[facing=north,half=lower,hinge=right,open=false,powered=false]"
      },
      {
        "char": "'",
        "block": "minecraft:dark_oak_door[facing=north,half=upper,hinge=left,open=false,powered=false]"
      },
      {
        "char": "(",
        "block": "minecraft:dark_oak_door[facing=north,half=upper,hinge=right,open=false,powered=false]"
      },
      {
        "char": ")",
        "block": "minecraft:gravel"
      },
      {
        "char": "*",
        "block": "minecraft:mud_bricks"
      },
      {
        "char": "+",
        "block": "minecraft:polished_andesite"
      },
      {
        "char": ",",
        "block": "minecraft:polished_andesite_stairs[facing=north,half=bottom,shape=straight,waterlogged=false]"
      },
      {
        "char": "-",
        "block": "minecraft:spruce_door[facing=south,half=lower,hinge=left,open=false,powered=false]"
      },
      {
        "char": ".",
        "block": "minecraft:spruce_door[facing=south,half=upper,hinge=left,open=false,powered=false]"
      },
      {
        "char": "/",
        "block": "minecraft:spruce_slab[type=bottom,waterlogged=false]"
      },
      {
        "char": "0",
        "block": "minecraft:stripped_dark_oak_log[axis=y]"
      },
      {
        "char": "1",
        "block": "minecraft:stripped_spruce_log[axis=y]"
      },
      {
        "char": "2",
        "block": "tfmg:cinder_block"
      },
      {
        "char": "3",
        "block": "the_wasteland_reworked:radio"
      }
    ]
  }
}
