{
  "xsize": 16,
  "zsize": 16,
  "slices": [
    [
      "                ",
      "////'''&        ",
      "///''&//        ",
      "/''&///'        ",
      "'&//////        ",
      "////////        ",
      "////////        ",
      "////////        ",
      "////////        ",
      "///////'        ",
      "//////''        ",
      "////''&/        ",
      "//''&///        ",
      "''&/////        ",
      "&///////        ",
      "///////'        "
    ],
    [
      "                ",
      "                ",
      "                ",
      "                ",
      "                ",
      "                ",
      "                ",
      "++++++          ",
      "++++++          ",
      "++++++          ",
      "++++++          ",
      "++++++          ",
      "++++++          ",
      "++++++          ",
      "++++++          ",
      "++++++          "
    ],
    [
      "                ",
      "                ",
      "                ",
      "                ",
      "                ",
      "                ",
      "                ",
      "%%%%%%          ",
      "     %          ",
      "     %          ",
      "$$$$ %          ",
      " -   %          ",
      "     %          ",
      "    ((((        ",
      "    ((((        ",
      ",,),,(((        "
    ],
    [
      "                ",
      "                ",
      "                ",
      "                ",
      "                ",
      "                ",
      "                ",
      "%%%%%%          ",
      "     %          ",
      "     %          ",
      "   . %          ",
      "     %          ",
      "     %          ",
      "     %          ",
      "     %          ",
      ",,*,,%          "
    ],
    [
      "                ",
      "                ",
      "                ",
      "                ",
      "                ",
      "                ",
      "                ",
      "%%%%%%          ",
      "     %          ",
      "     %          ",
      "     %          ",
      "     %          ",
      "     !          ",
      "     !          ",
      "     %          ",
      ",,,,,%          "
    ],
    [
      "                ",
      "                ",
      "                ",
      "                ",
      "                ",
      "                ",
      "                ",
      "%%%%%%          ",
      "     %          ",
      "     %          ",
      "     %          ",
      "     %          ",
      "     !          ",
      "     !          ",
      "     !          ",
      ",,,,,!          "
    ]
  ],
  "palette": {
    "palette": [
      {
        "char": "!",
        "block": "create:framed_glass"
      },
      {
        "char": "$",
        "block": "minecraft:barrel[facing=up,open=false]"
      },
      {
        "char": "%",
        "block": "minecraft:bricks"
      },
      {
        "char": "&",
        "block": "minecraft:coarse_dirt"
      },
      {
        "char": "'",
        "block": "minecraft:gravel"
      },
      {
        "char": "(",
        "block": "minecraft:smooth_stone_slab[type=bottom,waterlogged=false]"
      },
      {
        "char": ")",
        "block": "minecraft:spruce_door[facing=south,half=lower,hinge=left,open=false,powered=false]"
      },
      {
        "char": "*",
        "block": "minecraft:spruce_door[facing=south,half=upper,hinge=left,open=false,powered=false]"
      },
      {
        "char": "+",
        "block": "minecraft:spruce_planks"
      },
      {
        "char": ",",
        "block": "minecraft:stripped_spruce_wood"
      },
      {
        "char": "-",
        "block": "kubejs:ruined_cauldron"
      },
      {
        "char": ".",
        "block": "supplementaries:item_shelf"
      },
      {
        "char": "/",
        "block": "tfmg:asphalt"
      }
    ]
  }
}
