{
  "xsize": 16,
  "zsize": 16,
  "slices": [
    [
      "    %           ",
      "    %           ",
      "    %           ",
      "    %           ",
      "    %           ",
      "    %           ",
      "    %           ",
      "    %           ",
      "    %           ",
      "    %           ",
      "    %           ",
      "    %           ",
      "    %           ",
      "    !           ",
      "    !           ",
      "    %           "
    ],
    [
      "    %           ",
      "    %           ",
      "    %           ",
      "    %           ",
      "    %           ",
      "    %           ",
      "    %           ",
      "    %           ",
      "    %           ",
      "    %           ",
      "    %           ",
      "    %           ",
      "    %           ",
      "    %           ",
      "    %           ",
      "    %           "
    ],
    [
      "    %           ",
      "    %           ",
      "    %           ",
      "    %           ",
      "    %           ",
      "    %           ",
      "    %           ",
      "    %           ",
      "    %           ",
      "    %           ",
      "    %           ",
      "    %           ",
      "    %           ",
      "    %           ",
      "    %           ",
      "    %           "
    ],
    [
      "    %11111111111",
      "    %11111111111",
      "    %11111111111",
      "    %11111111111",
      "    %11111111111",
      "    %11111111111",
      "    %11111111111",
      "    %11111111111",
      "    %11111111111",
      "    %11111111111",
      "    %11111111111",
      "    %11111111111",
      "    %11111111111",
      "    %11111111111",
      "    %11111111111",
      "    %11111111111"
    ],
    [
      "  ,,,,   3      ",
      "    %    3      ",
      "    %    -      ",
      "    % (  3      ",
      "    % '  35 *   ",
      "    %    3     $",
      "    %    3      ",
      "    %           ",
      "    %           ",
      "    % &&&  $$$$$",
      "    %     7+ 4  ",
      "    %           ",
      "  ,,,, 2        ",
      "  ,,,,          ",
      "  ,,,333333333/3",
      "  ,,,,   3      "
    ],
    [
      "    %    3      ",
      "    %    3      ",
      "    %    .      ",
      "    %    3      ",
      "    %    3      ",
      "    %    3  )   ",
      "    %    3      ",
      "    %           ",
      "    %           ",
      "    %          6",
      "    %     6     ",
      "    %           ",
      "    %           ",
      "    %           ",
      "    %33333333303",
      "    %    3      "
    ]
  ],
  "palette": {
    "palette": [
      {
        "char": "!",
        "block": "create:framed_glass"
      },
      {
        "char": "$",
        "block": "minecraft:barrel[facing=up,open=false]"
      },
      {
        "char": "%",
        "block": "minecraft:bricks"
      },
      {
        "char": "&",
        "block": "minecraft:dark_oak_stairs[facing=south,half=bottom,shape=straight,waterlogged=false]"
      },
      {
        "char": "'",
        "block": "minecraft:gray_bed[facing=north,occupied=false,part=foot]"
      },
      {
        "char": "(",
        "block": "minecraft:gray_bed[facing=north,occupied=false,part=head]"
      },
      {
        "char": ")",
        "block": "minecraft:lever[face=wall,facing=south,powered=false]"
      },
      {
        "char": "*",
        "block": "minecraft:quartz_stairs[facing=north,half=bottom,shape=straight,waterlogged=false]"
      },
      {
        "char": "+",
        "block": "kubejs:ruined_smoker[facing=north]"
      },
      {
        "char": ",",
        "block": "minecraft:smooth_stone_slab[type=bottom,waterlogged=false]"
      },
      {
        "char": "-",
        "block": "minecraft:spruce_door[facing=east,half=lower,hinge=left,open=false,powered=false]"
      },
      {
        "char": ".",
        "block": "minecraft:spruce_door[facing=east,half=upper,hinge=left,open=false,powered=false]"
      },
      {
        "char": "/",
        "block": "minecraft:spruce_door[facing=south,half=lower,hinge=left,open=false,powered=false]"
      },
      {
        "char": "0",
        "block": "minecraft:spruce_door[facing=south,half=upper,hinge=left,open=false,powered=false]"
      },
      {
        "char": "1",
        "block": "minecraft:spruce_planks"
      },
      {
        "char": "2",
        "block": "minecraft:spruce_slab[type=bottom,waterlogged=false]"
      },
      {
        "char": "3",
        "block": "minecraft:stripped_spruce_wood"
      },
      {
        "char": "4",
        "block": "kubejs:ruined_cauldron"
      },
      {
        "char": "5",
        "block": "kubejs:ruined_cauldron"
      },
      {
        "char": "6",
        "block": "supplementaries:item_shelf"
      },
      {
        "char": "7",
        "block": "the_wasteland_reworked:radio"
      }
    ]
  }
}
