{
  "xsize": 16,
  "zsize": 16,
  "slices": [
    [
      " 333333333))(333",
      " (333333))(33333",
      " 33333))(3333333",
      " 333))(333333333",
      " 3))(33333333333",
      " )(3333333333333",
      " 333333333333333",
      " (3333333333333)",
      " 333333333333))(",
      " 3333333333))(33",
      " 33333333))(3333",
      " 333333))(333333",
      " 3333))(33333333",
      " (3))(3333333333",
      " ))(333333333333",
      " (33333333333333"
    ],
    [
      "    ////////////",
      "    ////////////",
      "    ////////////",
      "    ////////////",
      "    ////////////",
      "    ////////////",
      "    ////////////",
      "    ////////////",
      "    ////////////",
      "    ////////////",
      "    ////////////",
      "    ////////////",
      "    ////////////",
      "    ////////////",
      "    ////////////",
      "    ////////////"
    ],
    [
      "    %    1      ",
      "    % '  -      ",
      "    % &  12 +   ",
      "    %    1     $",
      "    %    1      ",
      "    %      0    ",
      "    %           ",
      "    %           ",
      "    %           ",
      "    %           ",
      "    %           ",
      "  ,,,,          ",
      "  ,,,,          ",
      "  ,,,,          ",
      "  ,,,,          ",
      "    %           "
    ],
    [
      "    %    1      ",
      "    %    .      ",
      "    %    1      ",
      "    %    1  *   ",
      "    %    1      ",
      "    %           ",
      "    %      0    ",
      "    %           ",
      "    %           ",
      "    %           ",
      "    %           ",
      "    %           ",
      "    %           ",
      "    %           ",
      "    %           ",
      "    %           "
    ],
    [
      "    %    1      ",
      "    %    1      ",
      "    %    1      ",
      "    %    1      ",
      "    %    1      ",
      "    !           ",
      "    !           ",
      "    %      0    ",
      "    %           ",
      "    %           ",
      "    %           ",
      "    %           ",
      "    %           ",
      "    !           ",
      "    !           ",
      "    %           "
    ],
    [
      "    %    1      ",
      "    %    1      ",
      "    %    1      ",
      "    %    1      ",
      "    %    1      ",
      "    !           ",
      "    !           ",
      "    %           ",
      "    %      0    ",
      "    %           ",
      "    %           ",
      "    %           ",
      "    !           ",
      "    !           ",
      "    !           ",
      "    %           "
    ]
  ],
  "palette": {
    "palette": [
      {
        "char": "!",
        "block": "create:framed_glass"
      },
      {
        "char": "$",
        "block": "minecraft:barrel[facing=up,open=false]"
      },
      {
        "char": "%",
        "block": "minecraft:bricks"
      },
      {
        "char": "&",
        "block": "minecraft:brown_bed[facing=north,occupied=false,part=foot]"
      },
      {
        "char": "'",
        "block": "minecraft:brown_bed[facing=north,occupied=false,part=head]"
      },
      {
        "char": "(",
        "block": "minecraft:coarse_dirt"
      },
      {
        "char": ")",
        "block": "minecraft:gravel"
      },
      {
        "char": "*",
        "block": "minecraft:lever[face=wall,facing=south,powered=false]"
      },
      {
        "char": "+",
        "block": "minecraft:quartz_stairs[facing=north,half=bottom,shape=straight,waterlogged=false]"
      },
      {
        "char": ",",
        "block": "minecraft:smooth_stone_slab[type=bottom,waterlogged=false]"
      },
      {
        "char": "-",
        "block": "minecraft:spruce_door[facing=east,half=lower,hinge=left,open=false,powered=false]"
      },
      {
        "char": ".",
        "block": "minecraft:spruce_door[facing=east,half=upper,hinge=left,open=false,powered=false]"
      },
      {
        "char": "/",
        "block": "minecraft:spruce_planks"
      },
      {
        "char": "0",
        "block": "minecraft:stone_brick_stairs[facing=south,half=bottom,shape=straight,waterlogged=false]"
      },
      {
        "char": "1",
        "block": "minecraft:stripped_spruce_wood"
      },
      {
        "char": "2",
        "block": "kubejs:ruined_cauldron"
      },
      {
        "char": "3",
        "block": "tfmg:asphalt"
      }
    ]
  }
}
