{
  "xsize": 16,
  "zsize": 16,
  "slices": [
    [
      "        !    &  ",
      "        !    &  ",
      "        !    &  ",
      "!!!!!!!!!    &  ",
      "       !!    &  ",
      "       !!       ",
      "       !!       ",
      "       !!   %   ",
      "       !!       ",
      "       !!       ",
      "       !!       ",
      "       !!       ",
      "       !!       ",
      "       !!       ",
      "       !!       ",
      "       !!       "
    ],
    [
      "        !    &  ",
      "        !    &  ",
      "        !    &  ",
      "!!!!!!!!!    &  ",
      "       !!    &  ",
      "       !!       ",
      "       !!       ",
      "       !!       ",
      "       !!   %   ",
      "       !!       ",
      "       !!       ",
      "       !!       ",
      "       !!       ",
      "       !!       ",
      "       !!       ",
      "       !!       "
    ],
    [
      "        !       ",
      "        !       ",
      "        !       ",
      "!!!!!!!!!       ",
      "       !!       ",
      "       !!       ",
      "       !!       ",
      "       !!       ",
      "       !!       ",
      "       !!   %   ",
      "       !!       ",
      "       !!       ",
      "       !!       ",
      "       !!       ",
      "       !!       ",
      "       !!       "
    ],
    [
      "        !       ",
      "        !       ",
      "        !       ",
      "!!!!!!!!!       ",
      "       !!       ",
      "       !!       ",
      "       !!       ",
      "       !!       ",
      "       !!       ",
      "       !!       ",
      "       !!   %   ",
      "       !!       ",
      "       !!       ",
      "       !!       ",
      "       !!       ",
      "       !!       "
    ],
    [
      "        !       ",
      "        !       ",
      "        !       ",
      "!!!!!!!!!       ",
      "       !!       ",
      "       !!       ",
      "       !!       ",
      "       !!       ",
      "       !!       ",
      "       !!       ",
      "       !!       ",
      "       !!   %   ",
      "       !!       ",
      "       !!       ",
      "       !!       ",
      "       !!       "
    ],
    [
      "        $$$$$$$$",
      "        $$$$$$$$",
      "        $$$$$$$$",
      "$$$$$$$$$$$$$$$$",
      "$$$$$$$$$$$$$$$$",
      "$$$$$$$$$$$$$$$$",
      "$$$$$$$$$$$$$$$$",
      "$$$$$$$$$$$$$$$$",
      "$$$$$$$$$$$$$$$$",
      "$$$$$$$$$$$$$$$$",
      "$$$$$$$$$$$$ $$$",
      "$$$$$$$$$$$$ $$$",
      "$$$$$$$$$$$$%$$$",
      "$$$$$$$$$$$$$$$$",
      "$$$$$$$$$$$$$$$$",
      "$$$$$$$$$$$$$$$$"
    ]
  ],
  "palette": {
    "palette": [
      {
        "char": "!",
        "block": "minecraft:bricks"
      },
      {
        "char": "$",
        "block": "minecraft:spruce_planks"
      },
      {
        "char": "%",
        "block": "minecraft:stone_brick_stairs[facing=south,half=bottom,shape=straight,waterlogged=false]"
      },
      {
        "char": "&",
        "block": "minecraft:stripped_spruce_wood"
      }
    ]
  }
}
