{
  "xsize": 16,
  "zsize": 16,
  "slices": [
    [
      "*************%%$",
      "***********%%$**",
      "*********%%$****",
      "*******%%$******",
      "*****%%$********",
      "***%%$**********",
      "*%%$************",
      "%$**************",
      "****************",
      "**************%%",
      "************%%$*",
      "**********%%$***",
      "********%%$*****",
      "******%%$*******",
      "****%%$*********",
      "**%%$***********"
    ],
    [
      "))      %%%%%%%%",
      "))              ",
      "))              ",
      "))))))))))))))))",
      "))))))))))))))))",
      "))))))))))))))))",
      "))))))))))))))))",
      "))))))))))))))))",
      "))))))))))))))))",
      "))))))))))))))))",
      "))))))))))))))))",
      "))))))))))))))))",
      "))))))))))))))))",
      "))))))))))))))))",
      "))))))))))))))))",
      "))))))))))))))))"
    ],
    [
      "&&&             ",
      "&&&             ",
      "&&&             ",
      "&&&!            ",
      "&&&             ",
      "&'&             ",
      "&&&             ",
      "&&&             ",
      "&&&             ",
      "&&&             ",
      "&&&             ",
      "&&&             ",
      "&&&             ",
      "&'&             ",
      "&&&             ",
      " !!             "
    ],
    [
      " !              ",
      " !              ",
      " !              ",
      " !!!            ",
      " !!             ",
      " (!             ",
      " !!             ",
      " !!             ",
      " !!             ",
      " !!             ",
      " !!             ",
      " !!             ",
      " !!             ",
      " (!             ",
      " !!             ",
      " !!             "
    ],
    [
      " !              ",
      " !              ",
      " !              ",
      " !!!            ",
      " !!             ",
      " !!             ",
      " !!             ",
      " !!             ",
      " !!             ",
      " !!             ",
      " !!             ",
      " !!             ",
      " !!             ",
      " !!             ",
      " !!             ",
      " !!             "
    ],
    [
      " !              ",
      " !              ",
      " !              ",
      " !!!            ",
      " !!             ",
      " !!             ",
      " !!             ",
      " !!             ",
      " !!             ",
      " !!             ",
      " !!             ",
      " !!             ",
      " !!             ",
      " !!             ",
      " !!             ",
      " !!             "
    ]
  ],
  "palette": {
    "palette": [
      {
        "char": "!",
        "block": "minecraft:bricks"
      },
      {
        "char": "$",
        "block": "minecraft:coarse_dirt"
      },
      {
        "char": "%",
        "block": "minecraft:gravel"
      },
      {
        "char": "&",
        "block": "minecraft:smooth_stone_slab[type=bottom,waterlogged=false]"
      },
      {
        "char": "'",
        "block": "minecraft:spruce_door[facing=east,half=lower,hinge=left,open=false,powered=false]"
      },
      {
        "char": "(",
        "block": "minecraft:spruce_door[facing=east,half=upper,hinge=left,open=false,powered=false]"
      },
      {
        "char": ")",
        "block": "minecraft:spruce_planks"
      },
      {
        "char": "*",
        "block": "tfmg:asphalt"
      }
    ]
  }
}
