{
  "xsize": 16,
  "zsize": 16,
  "slices": [
    [
      "                ",
      "                ",
      "                ",
      "                ",
      "                ",
      "                ",
      "                ",
      "$$$$$$          ",
      "%%%%%%%%%       ",
      "%%%%%%%%%       ",
      "%%%%%%%%%       ",
      "%%%%%%%%%       ",
      "%%%%%%%%%       ",
      "%%%%%%%%%       ",
      "%%%%%%%%%       ",
      "%%%%%%%%%       "
    ],
    [
      "                ",
      "                ",
      "                ",
      "                ",
      "                ",
      "                ",
      "                ",
      "$$$$$$          ",
      "%%%%%%%%%       ",
      "%%%%%%%%%       ",
      "%%%%%%%%%       ",
      "%%%%%%%%%       ",
      "%%%%%%%%%       ",
      "%%%%%%%%%       ",
      "%%%%%%%%%       ",
      "%%%%%%%%%       "
    ],
    [
      "                ",
      "                ",
      "                ",
      "                ",
      "                ",
      "                ",
      "                ",
      "$$$$$$          ",
      "     $          ",
      "     $          ",
      "     $          ",
      "     $          ",
      "     $          ",
      "     $          ",
      "     $          ",
      "     $          "
    ],
    [
      "                ",
      "                ",
      "                ",
      "                ",
      "                ",
      "                ",
      "                ",
      "$$$$$$          ",
      ")))))$          ",
      ")))))$          ",
      ")))))$          ",
      ")))))$          ",
      ")))))$          ",
      ")))))$          ",
      ")))))$          ",
      ")))))$          "
    ],
    [
      "                ",
      "                ",
      "                ",
      "                ",
      "                ",
      "                ",
      "                ",
      "$$$$$$          ",
      "     $          ",
      "     $          ",
      "!!!! $          ",
      " +   $          ",
      "     $          ",
      "    &&&&        ",
      "    &&&&        ",
      "**'**&&&        "
    ],
    [
      "                ",
      "                ",
      "                ",
      "                ",
      "                ",
      "                ",
      "                ",
      "$$$$$$          ",
      "     $          ",
      "     $          ",
      "   , $          ",
      "     $          ",
      "     $          ",
      "     $          ",
      "     $          ",
      "**(**$          "
    ]
  ],
  "palette": {
    "palette": [
      {
        "char": "!",
        "block": "minecraft:barrel[facing=up,open=false]"
      },
      {
        "char": "$",
        "block": "minecraft:bricks"
      },
      {
        "char": "%",
        "block": "minecraft:gravel"
      },
      {
        "char": "&",
        "block": "minecraft:smooth_stone_slab[type=bottom,waterlogged=false]"
      },
      {
        "char": "'",
        "block": "minecraft:spruce_door[facing=south,half=lower,hinge=left,open=false,powered=false]"
      },
      {
        "char": "(",
        "block": "minecraft:spruce_door[facing=south,half=upper,hinge=left,open=false,powered=false]"
      },
      {
        "char": ")",
        "block": "minecraft:spruce_planks"
      },
      {
        "char": "*",
        "block": "minecraft:stripped_spruce_wood"
      },
      {
        "char": "+",
        "block": "minecraft:water_cauldron[level=1]"
      },
      {
        "char": ",",
        "block": "supplementaries:item_shelf"
      }
    ]
  }
}
