{
  "xsize": 16,
  "zsize": 16,
  "slices": [
    [
      "11111111        ",
      "11111111        ",
      "11111111        ",
      "1111111'        ",
      "11111''&        ",
      "111''&1'        ",
      "1''&1111        ",
      "'&111111        ",
      "11111111        ",
      "11111111        ",
      "11111111        ",
      "1111111'        ",
      "11111111        ",
      "111111''        ",
      "1111''&1        ",
      "11''&111        "
    ],
    [
      "------          ",
      "------          ",
      "------          ",
      "------          ",
      "------          ",
      "------          ",
      "------          ",
      "------          ",
      "------          ",
      "------          ",
      "------          ",
      "------          ",
      "------          ",
      "------          ",
      "------          ",
      "------          "
    ],
    [
      "    ****        ",
      "     %          ",
      "     %          ",
      "     %          ",
      ")    %          ",
      "   $ %          ",
      "     %          ",
      "     %          ",
      "     %          ",
      "$$$$ %          ",
      " /   %          ",
      "     %          ",
      "    ****        ",
      "    ****        ",
      "..+..***        ",
      "    ****        "
    ],
    [
      "     %          ",
      "     %          ",
      "     %          ",
      "     %          ",
      "     %          ",
      "(    %          ",
      "     %          ",
      "     %          ",
      "     %          ",
      "   0 %          ",
      "     %          ",
      "     %          ",
      "     %          ",
      "     %          ",
      "..,..%          ",
      "     %          "
    ],
    [
      "     %          ",
      "     %          ",
      "     %          ",
      "     %          ",
      "     %          ",
      "     %          ",
      "     %          ",
      "     !          ",
      "     !          ",
      "     %          ",
      "     %          ",
      "     %          ",
      "     %          ",
      "     %          ",
      ".....%          ",
      "     %          "
    ],
    [
      "     %          ",
      "     %          ",
      "     %          ",
      "     %          ",
      "     %          ",
      "     %          ",
      "     %          ",
      "     !          ",
      "     !          ",
      "     %          ",
      "     %          ",
      "     %          ",
      "     %          ",
      "     !          ",
      ".....!          ",
      "     %          "
    ]
  ],
  "palette": {
    "palette": [
      {
        "char": "!",
        "block": "create:framed_glass"
      },
      {
        "char": "$",
        "block": "minecraft:barrel[facing=up,open=false]"
      },
      {
        "char": "%",
        "block": "minecraft:bricks"
      },
      {
        "char": "&",
        "block": "minecraft:coarse_dirt"
      },
      {
        "char": "'",
        "block": "minecraft:gravel"
      },
      {
        "char": "(",
        "block": "minecraft:lever[face=wall,facing=south,powered=false]"
      },
      {
        "char": ")",
        "block": "minecraft:quartz_stairs[facing=north,half=bottom,shape=straight,waterlogged=false]"
      },
      {
        "char": "*",
        "block": "minecraft:smooth_stone_slab[type=bottom,waterlogged=false]"
      },
      {
        "char": "+",
        "block": "minecraft:spruce_door[facing=south,half=lower,hinge=left,open=false,powered=false]"
      },
      {
        "char": ",",
        "block": "minecraft:spruce_door[facing=south,half=upper,hinge=left,open=false,powered=false]"
      },
      {
        "char": "-",
        "block": "minecraft:spruce_planks"
      },
      {
        "char": ".",
        "block": "minecraft:stripped_spruce_wood"
      },
      {
        "char": "/",
        "block": "kubejs:ruined_cauldron"
      },
      {
        "char": "0",
        "block": "supplementaries:item_shelf"
      },
      {
        "char": "1",
        "block": "tfmg:asphalt"
      }
    ]
  }
}
