{
  "xsize": 16,
  "zsize": 16,
  "slices": [
    [
      "''&,,,,,        ",
      "&,,,,,,'        ",
      ",,,,,,,,        ",
      ",,,,,,,,        ",
      ",,,,,,,,        ",
      ",,,,,,,,        ",
      ",,,,,,,'        ",
      ",,,,,'''        ",
      ",,,''&,,        ",
      ",''&,,,,        ",
      "'&,,,,,,        ",
      ",,,,,,,,        ",
      ",,,,,,,,        ",
      ",,,,,,,'        ",
      ",,,,,,,,        ",
      ",,,,,,,,        "
    ],
    [
      "++++++          ",
      "++++++          ",
      "++++++          ",
      "++++++          ",
      "++++++          ",
      "++++++          ",
      "++++++          ",
      "++++++          ",
      "++++++          ",
      "++++++          ",
      "++++++          ",
      "++++++          ",
      "++++++          ",
      "++++++          ",
      "++++++          ",
      "++++++          "
    ],
    [
      "     %          ",
      "     %          ",
      ")    %          ",
      "   $ %          ",
      "     %          ",
      "     %          ",
      "     %          ",
      "     %          ",
      "     %          ",
      "     %          ",
      "     %          ",
      "    ****        ",
      "    ****        ",
      "    ****        ",
      "    ****        ",
      "     %          "
    ],
    [
      "     %          ",
      "     %          ",
      "     %          ",
      "(    %          ",
      "     %          ",
      "     %          ",
      "     %          ",
      "     %          ",
      "     %          ",
      "     %          ",
      "     %          ",
      "     %          ",
      "     %          ",
      "     %          ",
      "     %          ",
      "     %          "
    ],
    [
      "     %          ",
      "     %          ",
      "     %          ",
      "     %          ",
      "     %          ",
      "     !          ",
      "     !          ",
      "     %          ",
      "     %          ",
      "     %          ",
      "     %          ",
      "     %          ",
      "     %          ",
      "     !          ",
      "     !          ",
      "     %          "
    ],
    [
      "     %          ",
      "     %          ",
      "     %          ",
      "     %          ",
      "     %          ",
      "     !          ",
      "     !          ",
      "     %          ",
      "     %          ",
      "     %          ",
      "     %          ",
      "     %          ",
      "     !          ",
      "     !          ",
      "     !          ",
      "     %          "
    ]
  ],
  "palette": {
    "palette": [
      {
        "char": "!",
        "block": "create:framed_glass"
      },
      {
        "char": "$",
        "block": "minecraft:barrel[facing=up,open=false]"
      },
      {
        "char": "%",
        "block": "minecraft:bricks"
      },
      {
        "char": "&",
        "block": "minecraft:coarse_dirt"
      },
      {
        "char": "'",
        "block": "minecraft:gravel"
      },
      {
        "char": "(",
        "block": "minecraft:lever[face=wall,facing=south,powered=false]"
      },
      {
        "char": ")",
        "block": "minecraft:quartz_stairs[facing=north,half=bottom,shape=straight,waterlogged=false]"
      },
      {
        "char": "*",
        "block": "minecraft:smooth_stone_slab[type=bottom,waterlogged=false]"
      },
      {
        "char": "+",
        "block": "minecraft:spruce_planks"
      },
      {
        "char": ",",
        "block": "tfmg:asphalt"
      }
    ]
  }
}
