{
  "xsize": 16,
  "zsize": 16,
  "slices": [
    [
      "++++++++++&&%+++",
      "++++++++&&%+++++",
      "++++++&&%+++++++",
      "++++&&%+++++++++",
      "++&&%+++++++++++",
      "&&%+++++++++++++",
      "%+++++++++++++++",
      "+++++++++++++++&",
      "+++++++++++++&&%",
      "+++++++++++&&%++",
      "+++++++++&&%++++",
      "+++++++&&%++++++",
      "+++++&&%++++++++",
      "+++&&%++++++++++",
      "+&&%++++++++++++",
      "&%++++++++++++++"
    ],
    [
      "        &&&&&&&&",
      "        &&&&&&&&",
      "%%%     &&&&&&&&",
      "%%%     &&&&&&&&",
      "%%%     &&&&&&&&",
      "%%%     &&&&&&&&",
      "%%%     &&&&&&&&",
      "        &&&&&&&&",
      "        &&&&&&&&",
      "        &&&&&&&&",
      "        &&&&&&&&",
      "&&      ((((((((",
      "&&      ((((((((",
      "&&      ((((((((",
      "&&      ((((((((",
      "&&      (((((((("
    ],
    [
      "       '&&&&&&&&",
      "       '&&&&&&&&",
      "       '&&&&&&&&",
      "       '&&&&&&&&",
      "$      '&&&&&&&&",
      "       '&&&&&&&&",
      "       '&&&&&&&&",
      "       '&&&&&&&&",
      "       '&&&&&&&&",
      "       '&&&&&&&&",
      "       '&&&&&&&&",
      "       '''      ",
      "       ''' )    ",
      "       '''      ",
      "       ''*******",
      "       '''   *  "
    ],
    [
      "        &&&&&&&&",
      "        &&&&&&&&",
      "        &&&&&&&&",
      "        &&&&&&&&",
      "        &&&&&&&&",
      "        &&&&&&&&",
      "        &&&&&&&&",
      "        &&&&&&&&",
      "        &&&&&&&&",
      "        &&&&&&&&",
      "        &&&&&&&&",
      "        !       ",
      "        !       ",
      "        !       ",
      "        !*******",
      "        !    *  "
    ],
    [
      "        &&&&&&&&",
      "        &&&&&&&&",
      "        &&&&&&&&",
      "        &&&&&&&&",
      "        &&&&&&&&",
      "        &&&&&&&&",
      "        &&&&&&&&",
      "        &&&&&&&&",
      "        &&&&&&&&",
      "        &&&&&&&&",
      "        &&&&&&&&",
      "        !       ",
      "        !       ",
      "        !       ",
      "        !*******",
      "        !    *  "
    ],
    [
      "        &&&&&&&&",
      "        &&&&&&&&",
      "        &&&&&&&&",
      "        &&&&&&&&",
      "        &&&&&&&&",
      "        &&&&&&&&",
      "        &&&&&&&&",
      "        &&&&&&&&",
      "        &&&&&&&&",
      "        &&&&&&&&",
      "        &&&&&&&&",
      "        !       ",
      "        !       ",
      "        !       ",
      "        !*******",
      "        !    *  "
    ]
  ],
  "palette": {
    "palette": [
      {
        "char": "!",
        "block": "minecraft:bricks"
      },
      {
        "char": "$",
        "block": "minecraft:cauldron"
      },
      {
        "char": "%",
        "block": "minecraft:coarse_dirt"
      },
      {
        "char": "&",
        "block": "minecraft:gravel"
      },
      {
        "char": "'",
        "block": "minecraft:smooth_stone_slab[type=bottom,waterlogged=false]"
      },
      {
        "char": "(",
        "block": "minecraft:spruce_planks"
      },
      {
        "char": ")",
        "block": "minecraft:spruce_slab[type=bottom,waterlogged=false]"
      },
      {
        "char": "*",
        "block": "minecraft:stripped_spruce_wood"
      },
      {
        "char": "+",
        "block": "tfmg:asphalt"
      }
    ]
  }
}
