{
  "xsize": 16,
  "zsize": 16,
  "slices": [
    [
      "        &&&&&&&&",
      "        &&&&&&&&",
      "        &&&&&&&&",
      "        &&&&&&&&",
      "        &&&&&&&&",
      "        &&&&&&&&",
      "        &&&&&&&&",
      "        &&&&&&&&",
      "        &&&&&&&&",
      "        &&&&&&&&",
      "        &&&&&&&&",
      "        $       ",
      "        $       ",
      "        $       ",
      "        $       ",
      "        $       "
    ],
    [
      "        &&&&&&&&",
      "        &&&&&&&&",
      "        &&&&&&&&",
      "        &&&&&&&&",
      "        &&&&&&&&",
      "        &&&&&&&&",
      "        &&&&&&&&",
      "        &&&&&&&&",
      "        &&&&&&&&",
      "        &&&&&&&&",
      "        &&&&&&&&",
      "        $       ",
      "        $       ",
      "        $       ",
      "        $       ",
      "        $       "
    ],
    [
      "        $       ",
      "        $       ",
      "        $       ",
      "        $       ",
      "        $       ",
      "        $       ",
      "        $       ",
      "        $       ",
      "        $       ",
      "        $       ",
      "        $       ",
      "        $       ",
      "        $       ",
      "        $       ",
      "        $       ",
      "        $       "
    ],
    [
      "        ////////",
      "        ////////",
      "        ////////",
      "        ////////",
      "        ////////",
      "        ////////",
      "        ////////",
      "        ////////",
      "        ////////",
      "        ////////",
      "        ////////",
      "        ////////",
      "        ////////",
      "        ////////",
      "        ////////",
      "        ////////"
    ],
    [
      "       ***   1  ",
      "       ***   1  ",
      "       ***   +  ",
      "       ***(  1  ",
      "       ***'  12 ",
      "       ***   1  ",
      "     $ ***   1  ",
      "       *-*      ",
      "       ***      ",
      "       ***%%%  !",
      "       ***    4)",
      "       ***      ",
      "       *** 0    ",
      "       ***      ",
      "       **1111111",
      "       ***   1  "
    ],
    [
      "        $    1  ",
      "        $    1  ",
      "        $    ,  ",
      "        $    1  ",
      "        $    1  ",
      "        $    1  ",
      "        $    1  ",
      "        .       ",
      "        $       ",
      "        $       ",
      "        $     3 ",
      "        $       ",
      "        $       ",
      "        $       ",
      "        $1111111",
      "        $    1  "
    ]
  ],
  "palette": {
    "palette": [
      {
        "char": "!",
        "block": "minecraft:barrel[facing=up,open=false]"
      },
      {
        "char": "$",
        "block": "minecraft:bricks"
      },
      {
        "char": "%",
        "block": "minecraft:dark_oak_stairs[facing=south,half=bottom,shape=straight,waterlogged=false]"
      },
      {
        "char": "&",
        "block": "minecraft:gravel"
      },
      {
        "char": "'",
        "block": "minecraft:gray_bed[facing=north,occupied=false,part=foot]"
      },
      {
        "char": "(",
        "block": "minecraft:gray_bed[facing=north,occupied=false,part=head]"
      },
      {
        "char": ")",
        "block": "kubejs:ruined_smoker[facing=north]"
      },
      {
        "char": "*",
        "block": "minecraft:smooth_stone_slab[type=bottom,waterlogged=false]"
      },
      {
        "char": "+",
        "block": "minecraft:spruce_door[facing=east,half=lower,hinge=left,open=false,powered=false]"
      },
      {
        "char": ",",
        "block": "minecraft:spruce_door[facing=east,half=upper,hinge=left,open=false,powered=false]"
      },
      {
        "char": "-",
        "block": "minecraft:spruce_door[facing=west,half=lower,hinge=left,open=false,powered=false]"
      },
      {
        "char": ".",
        "block": "minecraft:spruce_door[facing=west,half=upper,hinge=left,open=false,powered=false]"
      },
      {
        "char": "/",
        "block": "minecraft:spruce_planks"
      },
      {
        "char": "0",
        "block": "minecraft:spruce_slab[type=bottom,waterlogged=false]"
      },
      {
        "char": "1",
        "block": "minecraft:stripped_spruce_wood"
      },
      {
        "char": "2",
        "block": "kubejs:ruined_cauldron"
      },
      {
        "char": "3",
        "block": "supplementaries:item_shelf"
      },
      {
        "char": "4",
        "block": "the_wasteland_reworked:radio"
      }
    ]
  }
}
