{
  "xsize": 16,
  "zsize": 16,
  "slices": [
    [
      "        !       ",
      "        !       ",
      "        !       ",
      "     !!!!       ",
      "       !!       ",
      "       !!       ",
      "       !!       ",
      "       !!       ",
      "       !!       ",
      "       !!   ,   ",
      "       !!       ",
      "       !!       ",
      "       !!       ",
      "       !!       ",
      "       !!       ",
      "       !!       "
    ],
    [
      "        !       ",
      "        !       ",
      "        !       ",
      "     !!!!       ",
      "       !!       ",
      "       !!       ",
      "       !!       ",
      "       !!       ",
      "       !!       ",
      "       !!       ",
      "       !!   ,   ",
      "       !!       ",
      "       !!       ",
      "       !!       ",
      "       !!       ",
      "       !!       "
    ],
    [
      "        !       ",
      "        !       ",
      "        !       ",
      "     !!!!       ",
      "       !!       ",
      "       !!       ",
      "       !!       ",
      "       !!       ",
      "       !!       ",
      "       !!       ",
      "       !!       ",
      "       !!   ,   ",
      "       !!       ",
      "       !!       ",
      "       !!       ",
      "       !!       "
    ],
    [
      "        ++++++++",
      "        ++++++++",
      "        ++++++++",
      "++++++++++++++++",
      "++++++++++++++++",
      "++++++++++++++++",
      "++++++++++++++++",
      "++++++++++++++++",
      "++++++++++++++++",
      "++++++++++++++++",
      "++++++++++++ +++",
      "++++++++++++ +++",
      "++++++++++++,+++",
      "++++++++++++++++",
      "++++++++++++++++",
      "++++++++++++++++"
    ],
    [
      "       &&&   -  ",
      "       &&&%  '  ",
      "       &&&$  -. ",
      "!!!!!!!&&&   -  ",
      "       &&&   -  ",
      "       &)&  ,   ",
      "       &&&      ",
      "       &&&      ",
      "       &&&      ",
      "       &&&      ",
      "       &&&      ",
      "       &&&      ",
      "       &&&      ",
      "       &)&      ",
      "       &&&      ",
      "       !!       "
    ],
    [
      "        !    -  ",
      "        !    (  ",
      "        !    -  ",
      "!!!!!!!!!    -  ",
      "       !!    -  ",
      "       !*       ",
      "       !!   ,   ",
      "       !!       ",
      "       !!       ",
      "       !!       ",
      "       !!       ",
      "       !!       ",
      "       !!       ",
      "       !*       ",
      "       !!       ",
      "       !!       "
    ]
  ],
  "palette": {
    "palette": [
      {
        "char": "!",
        "block": "minecraft:bricks"
      },
      {
        "char": "$",
        "block": "minecraft:brown_bed[facing=north,occupied=false,part=foot]"
      },
      {
        "char": "%",
        "block": "minecraft:brown_bed[facing=north,occupied=false,part=head]"
      },
      {
        "char": "&",
        "block": "minecraft:smooth_stone_slab[type=bottom,waterlogged=false]"
      },
      {
        "char": "'",
        "block": "minecraft:spruce_door[facing=east,half=lower,hinge=left,open=false,powered=false]"
      },
      {
        "char": "(",
        "block": "minecraft:spruce_door[facing=east,half=upper,hinge=left,open=false,powered=false]"
      },
      {
        "char": ")",
        "block": "minecraft:spruce_door[facing=west,half=lower,hinge=left,open=false,powered=false]"
      },
      {
        "char": "*",
        "block": "minecraft:spruce_door[facing=west,half=upper,hinge=left,open=false,powered=false]"
      },
      {
        "char": "+",
        "block": "minecraft:spruce_planks"
      },
      {
        "char": ",",
        "block": "minecraft:stone_brick_stairs[facing=south,half=bottom,shape=straight,waterlogged=false]"
      },
      {
        "char": "-",
        "block": "minecraft:stripped_spruce_wood"
      },
      {
        "char": ".",
        "block": "kubejs:ruined_cauldron"
      }
    ]
  }
}
