{
  "xsize": 16,
  "zsize": 16,
  "slices": [
    [
      "6666666666((&666",
      "66666666((&66666",
      "666666((&6666666",
      "6666((&666666666",
      "66((&66666666666",
      "((&6666666666666",
      "&666666666666666",
      "666666666666666(",
      "6666666666666((&",
      "66666666666((&66",
      "666666666((&6666",
      "6666666((&666666",
      "66666((&66666666",
      "666((&6666666666",
      "6((&666666666666",
      "(&66666666666666"
    ],
    [
      "        11111111",
      "        11111111",
      "&&&     11111111",
      "&&&     11111111",
      "&&&     11111111",
      "&&&     11111111",
      "&&&     11111111",
      "        11111111",
      "        11111111",
      "        11111111",
      "        11111111",
      "((      11111111",
      "((      11111111",
      "((      11111111",
      "((      11111111",
      "((      11111111"
    ],
    [
      "       ,,,   3  ",
      "       ,,,   3  ",
      "       ,,,   -  ",
      "       ,,,*  3  ",
      "%      ,,,)  34 ",
      "       ,,,   3  ",
      "       ,,,   3  ",
      "       ,/,      ",
      "       ,,,      ",
      "       ,,,'''  !",
      "       ,,,    7+",
      "       ,,,      ",
      "       ,,, 2    ",
      "       ,,,      ",
      "       ,,3333333",
      "       ,,,   3  "
    ],
    [
      "        $    3  ",
      "        $    3  ",
      "        $    .  ",
      "        $    3  ",
      "        $    3  ",
      "        $    3  ",
      "        $    3  ",
      "        0       ",
      "        $       ",
      "        $       ",
      "        $     5 ",
      "        $       ",
      "        $       ",
      "        $       ",
      "        $3333333",
      "        $    3  "
    ],
    [
      "        $    3  ",
      "        $    3  ",
      "        $    3  ",
      "        $    3  ",
      "        $    3  ",
      "        $    3  ",
      "        $    3  ",
      "        $       ",
      "        $       ",
      "        $       ",
      "        $       ",
      "        $       ",
      "        $       ",
      "        $       ",
      "        $3333333",
      "        $    3  "
    ],
    [
      "        $    3  ",
      "        $    3  ",
      "        $    3  ",
      "        $    3  ",
      "        $    3  ",
      "        $    3  ",
      "        $    3  ",
      "        $       ",
      "        $       ",
      "        $       ",
      "        $       ",
      "        $       ",
      "        $       ",
      "        $       ",
      "        $3333333",
      "        $    3  "
    ]
  ],
  "palette": {
    "palette": [
      {
        "char": "!",
        "block": "minecraft:barrel[facing=up,open=false]"
      },
      {
        "char": "$",
        "block": "minecraft:bricks"
      },
      {
        "char": "%",
        "block": "minecraft:cauldron"
      },
      {
        "char": "&",
        "block": "minecraft:coarse_dirt"
      },
      {
        "char": "'",
        "block": "minecraft:dark_oak_stairs[facing=south,half=bottom,shape=straight,waterlogged=false]"
      },
      {
        "char": "(",
        "block": "minecraft:gravel"
      },
      {
        "char": ")",
        "block": "minecraft:gray_bed[facing=north,occupied=false,part=foot]"
      },
      {
        "char": "*",
        "block": "minecraft:gray_bed[facing=north,occupied=false,part=head]"
      },
      {
        "char": "+",
        "block": "minecraft:smoker[facing=north,lit=false]"
      },
      {
        "char": ",",
        "block": "minecraft:smooth_stone_slab[type=bottom,waterlogged=false]"
      },
      {
        "char": "-",
        "block": "minecraft:spruce_door[facing=east,half=lower,hinge=left,open=false,powered=false]"
      },
      {
        "char": ".",
        "block": "minecraft:spruce_door[facing=east,half=upper,hinge=left,open=false,powered=false]"
      },
      {
        "char": "/",
        "block": "minecraft:spruce_door[facing=west,half=lower,hinge=left,open=false,powered=false]"
      },
      {
        "char": "0",
        "block": "minecraft:spruce_door[facing=west,half=upper,hinge=left,open=false,powered=false]"
      },
      {
        "char": "1",
        "block": "minecraft:spruce_planks"
      },
      {
        "char": "2",
        "block": "minecraft:spruce_slab[type=bottom,waterlogged=false]"
      },
      {
        "char": "3",
        "block": "minecraft:stripped_spruce_wood"
      },
      {
        "char": "4",
        "block": "minecraft:water_cauldron[level=2]"
      },
      {
        "char": "5",
        "block": "supplementaries:item_shelf"
      },
      {
        "char": "6",
        "block": "tfmg:asphalt"
      },
      {
        "char": "7",
        "block": "the_wasteland_reworked:radio"
      }
    ]
  }
}
