{
  "xsize": 16,
  "zsize": 16,
  "slices": [
    [
      "                ",
      " 2(2222(2222(22(",
      " 222222222222((&",
      " &222222222((&22",
      " 22222222((&2222",
      " 222222((&222222",
      " 2222((&22222222",
      " 22((&2222222222",
      " ((&222222222222",
      " &22222222222222",
      " 222222222222222",
      " 2222222222222((",
      " 22222222222((&2",
      " 222222222((&222",
      " 2222222((&22222",
      " &2222((&2222222"
    ],
    [
      "                ",
      "                ",
      "                ",
      "                ",
      "                ",
      "                ",
      "                ",
      "    ------------",
      "    ------------",
      "    ------------",
      "    ------------",
      "    ------------",
      "    ------------",
      "    ------------",
      "    ------------",
      "    ------------"
    ],
    [
      "                ",
      "                ",
      "                ",
      "                ",
      "                ",
      "                ",
      "                ",
      "    %%%%%%%%%%%%",
      "    %           ",
      "    %           ",
      "    % '''  $$$$$",
      "    %     3) 0  ",
      "    %           ",
      "  **** .        ",
      "  ****          ",
      "  ***/////////+/"
    ],
    [
      "                ",
      "                ",
      "                ",
      "                ",
      "                ",
      "                ",
      "                ",
      "    %%%%%%%%%%%%",
      "    %           ",
      "    %           ",
      "    %          1",
      "    %     1     ",
      "    %           ",
      "    %           ",
      "    %           ",
      "    %/////////,/"
    ],
    [
      "                ",
      "                ",
      "                ",
      "                ",
      "                ",
      "                ",
      "                ",
      "    %%%%%%%%%%%%",
      "    %           ",
      "    %           ",
      "    %           ",
      "    %           ",
      "    !           ",
      "    !           ",
      "    %           ",
      "    %///////////"
    ],
    [
      "                ",
      "                ",
      "                ",
      "                ",
      "                ",
      "                ",
      "                ",
      "    %%%%%%%%%%%%",
      "    %           ",
      "    %           ",
      "    %           ",
      "    %           ",
      "    !           ",
      "    !           ",
      "    !           ",
      "    !///////////"
    ]
  ],
  "palette": {
    "palette": [
      {
        "char": "!",
        "block": "create:framed_glass"
      },
      {
        "char": "$",
        "block": "minecraft:barrel[facing=up,open=false]"
      },
      {
        "char": "%",
        "block": "minecraft:bricks"
      },
      {
        "char": "&",
        "block": "minecraft:coarse_dirt"
      },
      {
        "char": "'",
        "block": "minecraft:dark_oak_stairs[facing=south,half=bottom,shape=straight,waterlogged=false]"
      },
      {
        "char": "(",
        "block": "minecraft:gravel"
      },
      {
        "char": ")",
        "block": "minecraft:smoker[facing=north,lit=false]"
      },
      {
        "char": "*",
        "block": "minecraft:smooth_stone_slab[type=bottom,waterlogged=false]"
      },
      {
        "char": "+",
        "block": "minecraft:spruce_door[facing=south,half=lower,hinge=left,open=false,powered=false]"
      },
      {
        "char": ",",
        "block": "minecraft:spruce_door[facing=south,half=upper,hinge=left,open=false,powered=false]"
      },
      {
        "char": "-",
        "block": "minecraft:spruce_planks"
      },
      {
        "char": ".",
        "block": "minecraft:spruce_slab[type=bottom,waterlogged=false]"
      },
      {
        "char": "/",
        "block": "minecraft:stripped_spruce_wood"
      },
      {
        "char": "0",
        "block": "minecraft:water_cauldron[level=1]"
      },
      {
        "char": "1",
        "block": "supplementaries:item_shelf"
      },
      {
        "char": "2",
        "block": "tfmg:asphalt"
      },
      {
        "char": "3",
        "block": "the_wasteland_reworked:radio"
      }
    ]
  }
}
