{
  "xsize": 16,
  "zsize": 16,
  "slices": [
    [
      "1111111111111111",
      "11111111111111''",
      "111111111111''&1",
      "1111111111''&111",
      "11111111''&11111",
      "111111''&1111111",
      "1111''&111111111",
      "11''&11111111111",
      "''&1111111111111",
      "&111111111111111",
      "111111111111111'",
      "1111111111111''&",
      "11111111111''&11",
      "111111111''&1111",
      "1111111''&111111",
      "11111''&11111111"
    ],
    [
      "''      --------",
      "        --------",
      "        --------",
      "----------------",
      "----------------",
      "----------------",
      "----------------",
      "----------------",
      "----------------",
      "----------------",
      "----------------",
      "----------------",
      "----------------",
      "----------------",
      "----------------",
      "----------------"
    ],
    [
      "       (((   /  ",
      "       (((%  )  ",
      "       ((($  /0 ",
      "     !!(((   /  ",
      "       (((   /  ",
      "       (+(  .   ",
      "       (((      ",
      "       (((      ",
      "       (((      ",
      "       (((      ",
      "       (((      ",
      "       (((      ",
      "       (((      ",
      "       (+(      ",
      "       (((      ",
      "       !!       "
    ],
    [
      "        !    /  ",
      "        !    *  ",
      "        !    /  ",
      "     !!!!    /  ",
      "       !!    /  ",
      "       !,       ",
      "       !!   .   ",
      "       !!       ",
      "       !!       ",
      "       !!       ",
      "       !!       ",
      "       !!       ",
      "       !!       ",
      "       !,       ",
      "       !!       ",
      "       !!       "
    ],
    [
      "        !    /  ",
      "        !    /  ",
      "        !    /  ",
      "     !!!!    /  ",
      "       !!    /  ",
      "       !!       ",
      "       !!       ",
      "       !!   .   ",
      "       !!       ",
      "       !!       ",
      "       !!       ",
      "       !!       ",
      "       !!       ",
      "       !!       ",
      "       !!       ",
      "       !!       "
    ],
    [
      "        !    /  ",
      "        !    /  ",
      "        !    /  ",
      "     !!!!    /  ",
      "       !!    /  ",
      "       !!       ",
      "       !!       ",
      "       !!       ",
      "       !!   .   ",
      "       !!       ",
      "       !!       ",
      "       !!       ",
      "       !!       ",
      "       !!       ",
      "       !!       ",
      "       !!       "
    ]
  ],
  "palette": {
    "palette": [
      {
        "char": "!",
        "block": "minecraft:bricks"
      },
      {
        "char": "$",
        "block": "minecraft:brown_bed[facing=north,occupied=false,part=foot]"
      },
      {
        "char": "%",
        "block": "minecraft:brown_bed[facing=north,occupied=false,part=head]"
      },
      {
        "char": "&",
        "block": "minecraft:coarse_dirt"
      },
      {
        "char": "'",
        "block": "minecraft:gravel"
      },
      {
        "char": "(",
        "block": "minecraft:smooth_stone_slab[type=bottom,waterlogged=false]"
      },
      {
        "char": ")",
        "block": "minecraft:spruce_door[facing=east,half=lower,hinge=left,open=false,powered=false]"
      },
      {
        "char": "*",
        "block": "minecraft:spruce_door[facing=east,half=upper,hinge=left,open=false,powered=false]"
      },
      {
        "char": "+",
        "block": "minecraft:spruce_door[facing=west,half=lower,hinge=left,open=false,powered=false]"
      },
      {
        "char": ",",
        "block": "minecraft:spruce_door[facing=west,half=upper,hinge=left,open=false,powered=false]"
      },
      {
        "char": "-",
        "block": "minecraft:spruce_planks"
      },
      {
        "char": ".",
        "block": "minecraft:stone_brick_stairs[facing=south,half=bottom,shape=straight,waterlogged=false]"
      },
      {
        "char": "/",
        "block": "minecraft:stripped_spruce_wood"
      },
      {
        "char": "0",
        "block": "minecraft:water_cauldron[level=2]"
      },
      {
        "char": "1",
        "block": "tfmg:asphalt"
      }
    ]
  }
}
