{
  "xsize": 16,
  "zsize": 16,
  "slices": [
    [
      "                ",
      "                ",
      "                ",
      "                ",
      "                ",
      "                ",
      "                ",
      "        $$$$$$$$",
      "        &&&&&&&&",
      "        &&&&&&&&",
      "        &&&&&&&&",
      "        &&&&&&&&",
      "        &&&&&&&&",
      "        &&&&&&&&",
      "        &&&&&&&&",
      "        &&&&&&&&"
    ],
    [
      "                ",
      "                ",
      "                ",
      "                ",
      "                ",
      "                ",
      "                ",
      "        $$$$$$$$",
      "        &&&&&&&&",
      "        &&&&&&&&",
      "        &&&&&&&&",
      "        &&&&&&&&",
      "        &&&&&&&&",
      "        &&&&&&&&",
      "        &&&&&&&&",
      "        &&&&&&&&"
    ],
    [
      "                ",
      "                ",
      "                ",
      "                ",
      "                ",
      "                ",
      "                ",
      "        $$$$$$$$",
      "        $       ",
      "        $       ",
      "        $       ",
      "        $       ",
      "        $       ",
      "        $       ",
      "        $       ",
      "        $       "
    ],
    [
      "                ",
      "                ",
      "                ",
      "                ",
      "                ",
      "                ",
      "                ",
      "        $$$$$$$$",
      "        ++++++++",
      "        ++++++++",
      "        ++++++++",
      "        ++++++++",
      "        ++++++++",
      "        ++++++++",
      "        ++++++++",
      "        ++++++++"
    ],
    [
      "                ",
      "                ",
      "                ",
      "                ",
      "                ",
      "                ",
      "                ",
      "        $$$$$$$$",
      "        $       ",
      "        $       ",
      "       (((%%%  !",
      "       (((    /'",
      "       ()(      ",
      "       ((( ,    ",
      "       (((      ",
      "       ((-------"
    ],
    [
      "                ",
      "                ",
      "                ",
      "                ",
      "                ",
      "                ",
      "                ",
      "        $$$$$$$$",
      "        $       ",
      "        $       ",
      "        $       ",
      "        $     . ",
      "        *       ",
      "        $       ",
      "        $       ",
      "        $-------"
    ]
  ],
  "palette": {
    "palette": [
      {
        "char": "!",
        "block": "minecraft:barrel[facing=up,open=false]"
      },
      {
        "char": "$",
        "block": "minecraft:bricks"
      },
      {
        "char": "%",
        "block": "minecraft:dark_oak_stairs[facing=south,half=bottom,shape=straight,waterlogged=false]"
      },
      {
        "char": "&",
        "block": "minecraft:gravel"
      },
      {
        "char": "'",
        "block": "kubejs:ruined_smoker[facing=north]"
      },
      {
        "char": "(",
        "block": "minecraft:smooth_stone_slab[type=bottom,waterlogged=false]"
      },
      {
        "char": ")",
        "block": "minecraft:spruce_door[facing=west,half=lower,hinge=left,open=false,powered=false]"
      },
      {
        "char": "*",
        "block": "minecraft:spruce_door[facing=west,half=upper,hinge=left,open=false,powered=false]"
      },
      {
        "char": "+",
        "block": "minecraft:spruce_planks"
      },
      {
        "char": ",",
        "block": "minecraft:spruce_slab[type=bottom,waterlogged=false]"
      },
      {
        "char": "-",
        "block": "minecraft:stripped_spruce_wood"
      },
      {
        "char": ".",
        "block": "supplementaries:item_shelf"
      },
      {
        "char": "/",
        "block": "the_wasteland_reworked:radio"
      }
    ]
  }
}
