{
  "xsize": 16,
  "zsize": 16,
  "slices": [
    [
      "  ,,,,   2      ",
      "    %    2      ",
      "    %    -      ",
      "    % (  2      ",
      "    % '  24 *   ",
      "    %    2     $",
      "    %    2      ",
      "    %           ",
      "    %           ",
      "    % &&&  $$$$$",
      "    %     6+ 3  ",
      "    %           ",
      "  ,,,, 1        ",
      "  ,,,,          ",
      "  ,,,222222222/2",
      "  ,,,,   2      "
    ],
    [
      "    %    2      ",
      "    %    2      ",
      "    %    .      ",
      "    %    2      ",
      "    %    2      ",
      "    %    2  )   ",
      "    %    2      ",
      "    %           ",
      "    %           ",
      "    %          5",
      "    %     5     ",
      "    %           ",
      "    %           ",
      "    %           ",
      "    %22222222202",
      "    %    2      "
    ],
    [
      "    %    2      ",
      "    %    2      ",
      "    %    2      ",
      "    %    2      ",
      "    %    2      ",
      "    %    2      ",
      "    %    2      ",
      "    !           ",
      "    !           ",
      "    %           ",
      "    %           ",
      "    %           ",
      "    %           ",
      "    %           ",
      "    %22222222222",
      "    %    2      "
    ],
    [
      "    %    2      ",
      "    %    2      ",
      "    %    2      ",
      "    %    2      ",
      "    %    2      ",
      "    %    2      ",
      "    %    2      ",
      "    !           ",
      "    !           ",
      "    %           ",
      "    %           ",
      "    %           ",
      "    %           ",
      "    !           ",
      "    !22222222222",
      "    %    2      "
    ],
    [
      "    %           ",
      "    %           ",
      "    %           ",
      "    %           ",
      "    %           ",
      "    %           ",
      "    %           ",
      "    %           ",
      "    %           ",
      "    %           ",
      "    %           ",
      "    %           ",
      "    %           ",
      "    !           ",
      "    !           ",
      "    %           "
    ],
    [
      "    %           ",
      "    %           ",
      "    %           ",
      "    %           ",
      "    %           ",
      "    %           ",
      "    %           ",
      "    %           ",
      "    %           ",
      "    %           ",
      "    %           ",
      "    %           ",
      "    %           ",
      "    %           ",
      "    %           ",
      "    %           "
    ]
  ],
  "palette": {
    "palette": [
      {
        "char": "!",
        "block": "create:framed_glass"
      },
      {
        "char": "$",
        "block": "minecraft:barrel[facing=up,open=false]"
      },
      {
        "char": "%",
        "block": "minecraft:bricks"
      },
      {
        "char": "&",
        "block": "minecraft:dark_oak_stairs[facing=south,half=bottom,shape=straight,waterlogged=false]"
      },
      {
        "char": "'",
        "block": "minecraft:gray_bed[facing=north,occupied=false,part=foot]"
      },
      {
        "char": "(",
        "block": "minecraft:gray_bed[facing=north,occupied=false,part=head]"
      },
      {
        "char": ")",
        "block": "minecraft:lever[face=wall,facing=south,powered=false]"
      },
      {
        "char": "*",
        "block": "minecraft:quartz_stairs[facing=north,half=bottom,shape=straight,waterlogged=false]"
      },
      {
        "char": "+",
        "block": "kubejs:ruined_smoker[facing=north]"
      },
      {
        "char": ",",
        "block": "minecraft:smooth_stone_slab[type=bottom,waterlogged=false]"
      },
      {
        "char": "-",
        "block": "minecraft:spruce_door[facing=east,half=lower,hinge=left,open=false,powered=false]"
      },
      {
        "char": ".",
        "block": "minecraft:spruce_door[facing=east,half=upper,hinge=left,open=false,powered=false]"
      },
      {
        "char": "/",
        "block": "minecraft:spruce_door[facing=south,half=lower,hinge=left,open=false,powered=false]"
      },
      {
        "char": "0",
        "block": "minecraft:spruce_door[facing=south,half=upper,hinge=left,open=false,powered=false]"
      },
      {
        "char": "1",
        "block": "minecraft:spruce_slab[type=bottom,waterlogged=false]"
      },
      {
        "char": "2",
        "block": "minecraft:stripped_spruce_wood"
      },
      {
        "char": "3",
        "block": "kubejs:ruined_cauldron"
      },
      {
        "char": "4",
        "block": "kubejs:ruined_cauldron"
      },
      {
        "char": "5",
        "block": "supplementaries:item_shelf"
      },
      {
        "char": "6",
        "block": "the_wasteland_reworked:radio"
      }
    ]
  }
}
