{
  "xsize": 16,
  "zsize": 16,
  "slices": [
    [
      "       )))   /  ",
      "       )))   /  ",
      "       )))   *  ",
      "       )))'  /  ",
      "       )))&  /0 ",
      "       )))   /  ",
      "       )))   /  ",
      "       ),)      ",
      "       )))      ",
      "       )))%%%  !",
      "       )))    2(",
      "       )))      ",
      "       ))) .    ",
      "       )))      ",
      "       ))///////",
      "       )))   /  "
    ],
    [
      "        $    /  ",
      "        $    /  ",
      "        $    +  ",
      "        $    /  ",
      "        $    /  ",
      "        $    /  ",
      "        $    /  ",
      "        -       ",
      "        $       ",
      "        $       ",
      "        $     1 ",
      "        $       ",
      "        $       ",
      "        $       ",
      "        $///////",
      "        $    /  "
    ],
    [
      "        $    /  ",
      "        $    /  ",
      "        $    /  ",
      "        $    /  ",
      "        $    /  ",
      "        $    /  ",
      "        $    /  ",
      "        $       ",
      "        $       ",
      "        $       ",
      "        $       ",
      "        $       ",
      "        $       ",
      "        $       ",
      "        $///////",
      "        $    /  "
    ],
    [
      "        $    /  ",
      "        $    /  ",
      "        $    /  ",
      "        $    /  ",
      "        $    /  ",
      "        $    /  ",
      "        $    /  ",
      "        $       ",
      "        $       ",
      "        $       ",
      "        $       ",
      "        $       ",
      "        $       ",
      "        $       ",
      "        $///////",
      "        $    /  "
    ],
    [
      "        $       ",
      "        $       ",
      "        $       ",
      "        $       ",
      "        $       ",
      "        $       ",
      "        $       ",
      "        $       ",
      "        $       ",
      "        $       ",
      "        $       ",
      "        $       ",
      "        $       ",
      "        $       ",
      "        $       ",
      "        $       "
    ],
    [
      "        $       ",
      "        $       ",
      "        $       ",
      "        $       ",
      "        $       ",
      "        $       ",
      "        $       ",
      "        $       ",
      "        $       ",
      "        $       ",
      "        $       ",
      "        $       ",
      "        $       ",
      "        $       ",
      "        $       ",
      "        $       "
    ]
  ],
  "palette": {
    "palette": [
      {
        "char": "!",
        "block": "minecraft:barrel[facing=up,open=false]"
      },
      {
        "char": "$",
        "block": "minecraft:bricks"
      },
      {
        "char": "%",
        "block": "minecraft:dark_oak_stairs[facing=south,half=bottom,shape=straight,waterlogged=false]"
      },
      {
        "char": "&",
        "block": "minecraft:gray_bed[facing=north,occupied=false,part=foot]"
      },
      {
        "char": "'",
        "block": "minecraft:gray_bed[facing=north,occupied=false,part=head]"
      },
      {
        "char": "(",
        "block": "kubejs:ruined_smoker[facing=north]"
      },
      {
        "char": ")",
        "block": "minecraft:smooth_stone_slab[type=bottom,waterlogged=false]"
      },
      {
        "char": "*",
        "block": "minecraft:spruce_door[facing=east,half=lower,hinge=left,open=false,powered=false]"
      },
      {
        "char": "+",
        "block": "minecraft:spruce_door[facing=east,half=upper,hinge=left,open=false,powered=false]"
      },
      {
        "char": ",",
        "block": "minecraft:spruce_door[facing=west,half=lower,hinge=left,open=false,powered=false]"
      },
      {
        "char": "-",
        "block": "minecraft:spruce_door[facing=west,half=upper,hinge=left,open=false,powered=false]"
      },
      {
        "char": ".",
        "block": "minecraft:spruce_slab[type=bottom,waterlogged=false]"
      },
      {
        "char": "/",
        "block": "minecraft:stripped_spruce_wood"
      },
      {
        "char": "0",
        "block": "kubejs:ruined_cauldron"
      },
      {
        "char": "1",
        "block": "supplementaries:item_shelf"
      },
      {
        "char": "2",
        "block": "the_wasteland_reworked:radio"
      }
    ]
  }
}
