{
  "xsize": 16,
  "zsize": 16,
  "slices": [
    [
      "    +       $$  ",
      "    +       $$  ",
      "    +       $$  ",
      "    +       $$  ",
      "    +       !$  ",
      "    +       !$  ",
      "    +       $$  ",
      "    +       $$  ",
      "    +       $$  ",
      "    +       $$  ",
      "    +       $$  ",
      "    +       !$  ",
      "    +       !$  ",
      "    +       $$  ",
      "    +       $$  ",
      "    +       $$  "
    ],
    [
      "    +       $$  ",
      "    +       $$  ",
      "    +       $$  ",
      "    +       $$  ",
      "    +       $$  ",
      "    +       $$  ",
      "    +       $$  ",
      "    +       $$  ",
      "    +       $$  ",
      "    +       $$  ",
      "    +       $$  ",
      "    +       $$  ",
      "    +       $$  ",
      "    +       $$  ",
      "    +       $$  ",
      "    +       $$  "
    ],
    [
      "            $$  ",
      "            $$  ",
      "            $$  ",
      "            $$  ",
      "            $$  ",
      "            $$  ",
      "            $$  ",
      "            $$  ",
      "            $$  ",
      "            $$  ",
      "            $$  ",
      "            $$  ",
      "            $$  ",
      "            $$  ",
      "            $$  ",
      "            $$  "
    ],
    [
      "            $$  ",
      "            $$  ",
      "            $$  ",
      "            $$  ",
      "            $$  ",
      "            $$  ",
      "            $$  ",
      "            $$  ",
      "            $$  ",
      "            $$  ",
      "            $$  ",
      "            $$  ",
      "            $$  ",
      "            $$  ",
      "            $$  ",
      "            $$  "
    ],
    [
      "&&&&&&&&&&&&$$  ",
      "&&&&&&&&&&&&$$  ",
      "&&&&&&&&&&&&$$  ",
      "&&&&&&&&&&&&$$  ",
      "&&&&&&&&&&&&$$  ",
      "&&&&&&&&&&&&$$  ",
      "&&&&&&&&&&&&$$  ",
      "&&&&&&&&&&&&$$  ",
      "&&&&&&&&&&&&$$  ",
      "&&&&&&&&&&&&$$  ",
      "&&&&&&&&&&&&$$  ",
      "&&&&&&&&&&&&$$  ",
      "&&&&&&&&&&&&$$  ",
      "&&&&&&&&&&&&$$  ",
      "&&&&&&&&&&&&$$  ",
      "&&&&&&&&&&&&$$  "
    ],
    [
      "    +       $$  ",
      "    +       $$  ",
      "    +       $$  ",
      "    +       $$  ",
      "    +       $$  ",
      "    +       $$  ",
      "    +       $$  ",
      "    +       $$  ",
      "    + ))    $$  ",
      " '  + *     $$  ",
      "    +       $$  ",
      "    +       $$  ",
      "    +       $$  ",
      "    (       $$  ",
      "    +       $$  ",
      "    +  %    $$  "
    ]
  ],
  "palette": {
    "palette": [
      {
        "char": "!",
        "block": "create:framed_glass"
      },
      {
        "char": "$",
        "block": "immersiveengineering:concrete_reinforced"
      },
      {
        "char": "%",
        "block": "minecraft:barrel[facing=up,open=false]"
      },
      {
        "char": "&",
        "block": "minecraft:smooth_stone"
      },
      {
        "char": "'",
        "block": "minecraft:spawner",
        "tag": {
          "id": "minecraft:mob_spawner",
          "Delay": 200,
          "MinSpawnDelay": 240,
          "MaxSpawnDelay": 720,
          "SpawnCount": 2,
          "MaxNearbyEntities": 7,
          "RequiredPlayerRange": 14,
          "SpawnRange": 4,
          "SpawnData": {
            "entity": {
              "id": "the_wasteland_reworked:ghoul"
            }
          },
          "SpawnPotentials": [
            {
              "weight": 1,
              "data": {
                "entity": {
                  "id": "the_wasteland_reworked:ghoul"
                }
              }
            }
          ]
        }
      },
      {
        "char": "(",
        "block": "minecraft:spruce_door[facing=east,half=lower,hinge=left,open=false,powered=false]"
      },
      {
        "char": ")",
        "block": "minecraft:spruce_slab[type=bottom,waterlogged=false]"
      },
      {
        "char": "*",
        "block": "minecraft:spruce_stairs[facing=north,half=bottom,shape=straight,waterlogged=false]"
      },
      {
        "char": "+",
        "block": "tfmg:cinder_block"
      }
    ]
  }
}
