{
  "xsize": 16,
  "zsize": 16,
  "slices": [
    [
      "3333333333333333",
      "3333333333333333",
      "3333333333333333",
      "3333333333333333",
      "3333333333333333",
      "3333333333))$333",
      "33333333))$33333",
      "333333))$3333333",
      "3333))$333333333",
      "33))$33333333333",
      "))$3333333333333",
      "$333333333333333",
      "333333333333333)",
      "3333333333333))$",
      "33333333333))$33",
      "333333333))$3333"
    ],
    [
      "                ",
      "                ",
      "    2     2     ",
      "     ,          ",
      "                ",
      "                ",
      "++++++++++++++++",
      "++++++++++++++++",
      "++++++++++++++++",
      "++++++++++++++++",
      "+++++++++++++   ",
      "+++++++++++++   ",
      "+++++++++++++   ",
      "+++++++++++++   ",
      "++++++++)))++   ",
      "++++++++)))++   "
    ],
    [
      "                ",
      "                ",
      "                ",
      "     ,          ",
      "                ",
      "                ",
      "%&**************",
      "               *",
      "               *",
      "     //        *",
      "     0          ",
      "                ",
      "                ",
      "4444-444444-4   ",
      "        )))     ",
      "        )))     "
    ],
    [
      "                ",
      "                ",
      "                ",
      "     ,          ",
      "                ",
      "      ///   /// ",
      "'(**************",
      "               *",
      "               *",
      "         5     *",
      "                ",
      "                ",
      "                ",
      "4444.444444.4   ",
      "        )))     ",
      "        )))     "
    ],
    [
      "                ",
      "                ",
      "                ",
      "     ,          ",
      "                ",
      "                ",
      "1****1!!!1*1!!!1",
      "               *",
      "               *",
      "               *",
      "                ",
      "                ",
      "                ",
      "4444444444444   ",
      "        )))     ",
      "        )))     "
    ],
    [
      "                ",
      "                ",
      "                ",
      "     ,          ",
      "                ",
      "                ",
      "1****1!!!1*1!!!1",
      "               *",
      "               *",
      "               *",
      "                ",
      "                ",
      "                ",
      "4444444444444   ",
      "        )))     ",
      "        )))     "
    ]
  ],
  "palette": {
    "palette": [
      {
        "char": "!",
        "block": "create:framed_glass"
      },
      {
        "char": "$",
        "block": "minecraft:coarse_dirt"
      },
      {
        "char": "%",
        "block": "minecraft:dark_oak_door[facing=north,half=lower,hinge=left,open=false,powered=false]"
      },
      {
        "char": "&",
        "block": "minecraft:dark_oak_door[facing=north,half=lower,hinge=right,open=false,powered=false]"
      },
      {
        "char": "'",
        "block": "minecraft:dark_oak_door[facing=north,half=upper,hinge=left,open=false,powered=false]"
      },
      {
        "char": "(",
        "block": "minecraft:dark_oak_door[facing=north,half=upper,hinge=right,open=false,powered=false]"
      },
      {
        "char": ")",
        "block": "minecraft:gravel"
      },
      {
        "char": "*",
        "block": "minecraft:mud_bricks"
      },
      {
        "char": "+",
        "block": "minecraft:polished_andesite"
      },
      {
        "char": ",",
        "block": "minecraft:polished_deepslate"
      },
      {
        "char": "-",
        "block": "minecraft:spruce_door[facing=south,half=lower,hinge=left,open=false,powered=false]"
      },
      {
        "char": ".",
        "block": "minecraft:spruce_door[facing=south,half=upper,hinge=left,open=false,powered=false]"
      },
      {
        "char": "/",
        "block": "minecraft:spruce_slab[type=bottom,waterlogged=false]"
      },
      {
        "char": "0",
        "block": "minecraft:spruce_stairs[facing=north,half=bottom,shape=straight,waterlogged=false]"
      },
      {
        "char": "1",
        "block": "minecraft:stripped_spruce_log[axis=y]"
      },
      {
        "char": "2",
        "block": "minecraft:white_concrete"
      },
      {
        "char": "3",
        "block": "tfmg:asphalt"
      },
      {
        "char": "4",
        "block": "tfmg:cinder_block"
      },
      {
        "char": "5",
        "block": "the_wasteland_reworked:radio"
      }
    ]
  }
}
