{
  "xsize": 16,
  "zsize": 16,
  "slices": [
    [
      "/////////////**%",
      "///////////**%//",
      "/////////**%////",
      "///////**%//////",
      "/////**%////////",
      "///**%//////////",
      "/**%////////////",
      "*%//////////////",
      "////////////////",
      "//////////////**",
      "////////////**%/",
      "//////////**%///",
      "////////**%/////",
      "//////**%///////",
      "////**%/////////",
      "//**%///////////"
    ],
    [
      ",,,,,,,,,,,,,   ",
      ",,,,,,,,,,,,,   ",
      ",,,,,,,,,,,,,   ",
      ",,,,,,,,,,,,, **",
      ",,,,,,,,,,,,, **",
      ",,,,,,,,,,,,, **",
      ",,,,,,,,,,,,,   ",
      ",,,,,,,,,,,,,   ",
      ",,,,,,,,,,,,,   ",
      ",,,,,,,,,,,,,   ",
      ",,,,,,,,,,,,,   ",
      ",,,,,,,,,,,,,   ",
      ",,,,,,,,,,,,,   ",
      ",,,,,,,,,,,,,   ",
      ",,,,,,,,,,,,,   ",
      "                "
    ],
    [
      "      0 !!!!!   ",
      "      0 !!!!!   ",
      "      0 !!!!!   ",
      "      0       **",
      "      -       **",
      "      0       **",
      "      0         ",
      "      0         ",
      "      0         ",
      "      0         ",
      "      0    $    ",
      "      0         ",
      "      0         ",
      "      0         ",
      "++++++++++&'+   ",
      "                "
    ],
    [
      "      0 !!!!!   ",
      "      0 !!!!!   ",
      "      0 !!!!!   ",
      "      0       **",
      "      .       **",
      "      0       **",
      "      0         ",
      "      0         ",
      "      0         ",
      "      0         ",
      "      0         ",
      "      0         ",
      "      0         ",
      "      0         ",
      "++++++++++()+   ",
      "                "
    ],
    [
      "      0 !!!!!   ",
      "      0 !!!!!   ",
      "      0 !!!!!   ",
      "      0       **",
      "      0       **",
      "      0       **",
      "      0         ",
      "      0         ",
      "      0         ",
      "      0         ",
      "      0         ",
      "      0         ",
      "      0         ",
      "      0         ",
      "+++++++++++++   ",
      "                "
    ],
    [
      "      0         ",
      "      0         ",
      "      0         ",
      "      0       **",
      "      0       **",
      "      0       **",
      "      0         ",
      "      0         ",
      "      0         ",
      "      0         ",
      "      0         ",
      "      0         ",
      "      0         ",
      "      0         ",
      "+++++++++++++   ",
      "                "
    ]
  ],
  "palette": {
    "palette": [
      {
        "char": "!",
        "block": "immersiveengineering:sheetmetal_steel"
      },
      {
        "char": "$",
        "block": "minecraft:chest[facing=north,type=single,waterlogged=false]",
        "tag": {
          "id": "minecraft:chest",
          "LootTable": "infinite_domain:chests/wasteland_office"
        }
      },
      {
        "char": "%",
        "block": "minecraft:coarse_dirt"
      },
      {
        "char": "&",
        "block": "minecraft:dark_oak_door[facing=south,half=lower,hinge=left,open=false,powered=false]"
      },
      {
        "char": "'",
        "block": "minecraft:dark_oak_door[facing=south,half=lower,hinge=right,open=false,powered=false]"
      },
      {
        "char": "(",
        "block": "minecraft:dark_oak_door[facing=south,half=upper,hinge=left,open=false,powered=false]"
      },
      {
        "char": ")",
        "block": "minecraft:dark_oak_door[facing=south,half=upper,hinge=right,open=false,powered=false]"
      },
      {
        "char": "*",
        "block": "minecraft:gravel"
      },
      {
        "char": "+",
        "block": "minecraft:mud_bricks"
      },
      {
        "char": ",",
        "block": "minecraft:polished_andesite"
      },
      {
        "char": "-",
        "block": "minecraft:spruce_door[facing=east,half=lower,hinge=left,open=false,powered=false]"
      },
      {
        "char": ".",
        "block": "minecraft:spruce_door[facing=east,half=upper,hinge=left,open=false,powered=false]"
      },
      {
        "char": "/",
        "block": "tfmg:asphalt"
      },
      {
        "char": "0",
        "block": "tfmg:cinder_block"
      }
    ]
  }
}
