{
  "xsize": 16,
  "zsize": 16,
  "slices": [
    [
      "       $      * ",
      "       $      * ",
      "       $      * ",
      "       $      * ",
      "       !      * ",
      "       !      * ",
      "       $      * ",
      "       $      * ",
      "       $      * ",
      "       $      * ",
      "       $      * ",
      "       !      * ",
      "       !      * ",
      "       $      * ",
      "       $      * ",
      "       $      * "
    ],
    [
      "       $      * ",
      "       $      * ",
      "       $      * ",
      "       $      * ",
      "       $      * ",
      "       $      * ",
      "       $      * ",
      "       $      * ",
      "       $      * ",
      "       $      * ",
      "       $      * ",
      "       $      * ",
      "       $      * ",
      "       $      * ",
      "       $      * ",
      "       $      * "
    ],
    [
      "       $        ",
      "       $        ",
      "       $        ",
      "       $        ",
      "       $        ",
      "       $        ",
      "       $        ",
      "       $        ",
      "       $        ",
      "       $        ",
      "       $        ",
      "       $        ",
      "       $        ",
      "       $        ",
      "       $        ",
      "       $        "
    ],
    [
      "       $        ",
      "       $        ",
      "       $        ",
      "       $        ",
      "       $        ",
      "       $        ",
      "       $        ",
      "       $        ",
      "       $        ",
      "       $        ",
      "       $        ",
      "       $        ",
      "       $        ",
      "       $        ",
      "       $        ",
      "       $        "
    ],
    [
      "       $''''''''",
      "       $''''''''",
      "       $''''''''",
      "       $''''''''",
      "       $''''''''",
      "       $''''''''",
      "       $''''''''",
      "       $''''''''",
      "       $''''''''",
      "       $''''''''",
      "       $''''''''",
      "       $''''''''",
      "       $''''''''",
      "       $''''''''",
      "       $''''''''",
      "       $''''''''"
    ],
    [
      "       $      * ",
      "       $      * ",
      "       $      * ",
      "       $      * ",
      "       $      * ",
      "       $      * ",
      "       $      * ",
      "       $      * ",
      "       $ ((   * ",
      "       $ )    * ",
      "       $      * ",
      "       $      * ",
      "       $      * ",
      "       $   &  * ",
      "       $      * ",
      "       $   %  * "
    ]
  ],
  "palette": {
    "palette": [
      {
        "char": "!",
        "block": "create:framed_glass"
      },
      {
        "char": "$",
        "block": "immersiveengineering:concrete_reinforced"
      },
      {
        "char": "%",
        "block": "kubejs:ruined_cartography_table"
      },
      {
        "char": "&",
        "block": "minecraft:chest[facing=east,type=single,waterlogged=false]",
        "tag": {
          "id": "minecraft:chest",
          "LootTable": "infinite_domain:chests/wasteland_office"
        }
      },
      {
        "char": "'",
        "block": "minecraft:smooth_stone"
      },
      {
        "char": "(",
        "block": "minecraft:spruce_slab[type=bottom,waterlogged=false]"
      },
      {
        "char": ")",
        "block": "minecraft:spruce_stairs[facing=north,half=bottom,shape=straight,waterlogged=false]"
      },
      {
        "char": "*",
        "block": "tfmg:cinder_block"
      }
    ]
  }
}
