{
  "xsize": 16,
  "zsize": 16,
  "slices": [
    [
      "                ",
      "                ",
      "                ",
      "                ",
      "                ",
      "                ",
      "                ",
      "                ",
      "                ",
      "       $$$$$$$$$",
      "       $        ",
      "       $        ",
      "       $        ",
      "       $        ",
      "       $        ",
      "       $        "
    ],
    [
      "                ",
      "                ",
      "                ",
      "                ",
      "                ",
      "                ",
      "                ",
      "                ",
      "                ",
      "       $$$$$$$$$",
      "       $&&&&&&&&",
      "       $&&&&&&&&",
      "       $&&&&&&&&",
      "       $&&&&&&&&",
      "       $&&&&&&&&",
      "       $&&&&&&&&"
    ],
    [
      "                ",
      "                ",
      "                ",
      "                ",
      "                ",
      "                ",
      "                ",
      "                ",
      "         ''  '' ",
      "       $$$$$$$$$",
      "       $      + ",
      "       $      + ",
      "       $ '%%%%%%",
      "       $ )%%%%%%",
      "       $  %%%%%%",
      "       $  %%%%%%"
    ],
    [
      "                ",
      "                ",
      "                ",
      "                ",
      "                ",
      "                ",
      "                ",
      "                ",
      "                ",
      "       $*!!**!!*",
      "       $      + ",
      "       $      + ",
      "       $  &&&&&&",
      "       !  &     ",
      "       !  &     ",
      "       $  &     "
    ],
    [
      "                ",
      "                ",
      "                ",
      "                ",
      "                ",
      "                ",
      "                ",
      "                ",
      "                ",
      "       $*!!**!!*",
      "       $      + ",
      "       $      + ",
      "       $  &&&&&&",
      "       !  &     ",
      "       !  &     ",
      "       $  &     "
    ],
    [
      "                ",
      "                ",
      "                ",
      "                ",
      "                ",
      "                ",
      "                ",
      "                ",
      "         ((  (( ",
      "       $$$$$$$$$",
      "       $      + ",
      "       $      + ",
      "       $  &&&&&&",
      "       $  &     ",
      "       $  &     ",
      "       $  &     "
    ]
  ],
  "palette": {
    "palette": [
      {
        "char": "!",
        "block": "create:framed_glass"
      },
      {
        "char": "$",
        "block": "immersiveengineering:concrete_reinforced"
      },
      {
        "char": "%",
        "block": "minecraft:polished_andesite"
      },
      {
        "char": "&",
        "block": "minecraft:smooth_stone"
      },
      {
        "char": "'",
        "block": "minecraft:spruce_slab[type=bottom,waterlogged=false]"
      },
      {
        "char": "(",
        "block": "minecraft:spruce_slab[type=top,waterlogged=false]"
      },
      {
        "char": ")",
        "block": "minecraft:spruce_stairs[facing=north,half=bottom,shape=straight,waterlogged=false]"
      },
      {
        "char": "*",
        "block": "minecraft:stripped_spruce_log[axis=y]"
      },
      {
        "char": "+",
        "block": "tfmg:cinder_block"
      }
    ]
  }
}
