{
  "xsize": 16,
  "zsize": 16,
  "slices": [
    [
      "                ",
      "                ",
      "                ",
      "              ((",
      "              ((",
      "              ((",
      "                ",
      "                ",
      "                ",
      "                ",
      "                ",
      "                ",
      "                ",
      "                ",
      "*************   ",
      "                "
    ],
    [
      "                ",
      "                ",
      "                ",
      "              ((",
      "              ((",
      "              ((",
      "                ",
      "                ",
      "                ",
      "                ",
      "                ",
      "                ",
      "                ",
      "                ",
      "*************   ",
      "                "
    ],
    [
      "                ",
      "                ",
      "                ",
      "                ",
      "               $",
      "                ",
      "                ",
      "                ",
      "                ",
      "                ",
      "                ",
      "                ",
      "                ",
      "                ",
      "*************   ",
      "                "
    ],
    [
      ",,,,,,,,,,,,,,,,",
      ",,,,,,,,,,,,,,,,",
      ",,,,,,,,,,,,,,,,",
      ",,,,,,,,,,,,,   ",
      ",,,,,,,,,,,,,   ",
      ",,,,,,,,,,,,,   ",
      ",,,,,,,,,,,,,   ",
      ",,,,,,,,,, ,,   ",
      ",,,,,,,,,,,,,   ",
      ",,,,,,,,,,,,,   ",
      ",,,,,,,,,,,,,   ",
      ",,,,,,,,,,,,,   ",
      ",,,,,,,,,,,,,   ",
      ",,,,,,,,,,,,,   ",
      ",,,,,,,,,,,,,   ",
      "                "
    ],
    [
      "    /       $$  ",
      "    /       $$  ",
      "/-//////-///$$  ",
      "    /       $   ",
      "    /       $   ",
      "    /  %    $   ",
      "    /    +++$   ",
      "    /    &)+$   ",
      "    /    +++$   ",
      "    /       $   ",
      "$$$$$$$$$$$$$   ",
      "                ",
      "                ",
      "                ",
      "                ",
      "                "
    ],
    [
      "    /       $$  ",
      "    /       $$  ",
      "/.//////.///!$  ",
      "    /       !   ",
      "    /       $   ",
      "    /       $   ",
      "    /    +++$   ",
      "    /    ')+$   ",
      "    /    +++$   ",
      "    /       $   ",
      "$$$$$$$$$$$$$   ",
      "                ",
      "                ",
      "                ",
      "                ",
      "                "
    ]
  ],
  "palette": {
    "palette": [
      {
        "char": "!",
        "block": "create:framed_glass"
      },
      {
        "char": "$",
        "block": "immersiveengineering:concrete_reinforced"
      },
      {
        "char": "%",
        "block": "minecraft:bookshelf"
      },
      {
        "char": "&",
        "block": "minecraft:dark_oak_door[facing=west,half=lower,hinge=left,open=false,powered=false]"
      },
      {
        "char": "'",
        "block": "minecraft:dark_oak_door[facing=west,half=upper,hinge=left,open=false,powered=false]"
      },
      {
        "char": "(",
        "block": "minecraft:gravel"
      },
      {
        "char": ")",
        "block": "minecraft:ladder[facing=south,waterlogged=false]"
      },
      {
        "char": "*",
        "block": "minecraft:mud_bricks"
      },
      {
        "char": "+",
        "block": "minecraft:polished_deepslate"
      },
      {
        "char": ",",
        "block": "minecraft:smooth_stone"
      },
      {
        "char": "-",
        "block": "minecraft:spruce_door[facing=south,half=lower,hinge=left,open=false,powered=false]"
      },
      {
        "char": ".",
        "block": "minecraft:spruce_door[facing=south,half=upper,hinge=left,open=false,powered=false]"
      },
      {
        "char": "/",
        "block": "tfmg:cinder_block"
      }
    ]
  }
}
