{
  "xsize": 16,
  "zsize": 16,
  "slices": [
    [
      "            $   ",
      "            $   ",
      "            $   ",
      "            $   ",
      "            $   ",
      "            $   ",
      "            $   ",
      "            $   ",
      "            $   ",
      "            $   ",
      "            $   ",
      "            $   ",
      "            $   ",
      "            $   ",
      "            $   ",
      "            $   "
    ],
    [
      "************$   ",
      "************$   ",
      "************$   ",
      "************$   ",
      "************$   ",
      "************$   ",
      "************$   ",
      "************$   ",
      "************$   ",
      "************$   ",
      "************$   ",
      "************$   ",
      "************$   ",
      "************$   ",
      "************$   ",
      "************$   "
    ],
    [
      "))))))))))  $   ",
      "))))))))))  $   ",
      "))))))))))  $   ",
      "))))))))))  $   ",
      "))))))))))  $   ",
      "))))))))))  $   ",
      "))))))))))  $   ",
      "))))))))))  $   ",
      "))))))))))  $   ",
      "))))))))))  $   ",
      "))))))))))  $   ",
      "))))))))))  $   ",
      "))))))))))  $   ",
      "))))))))))  $   ",
      "))))))))))  $   ",
      "    -  &    $   "
    ],
    [
      "  - %%%% *  $   ",
      "  - %%%% *  $   ",
      "  - %%%% *  $   ",
      "  - %%%% *  $   ",
      "  - %%%% *  !   ",
      "  -      *  !   ",
      "  +      *  $   ",
      "  -      *  $   ",
      "  -      *  $   ",
      "  -      *  $   ",
      "  -      *  $   ",
      "  -      *  !   ",
      "  -      *  !   ",
      "  -      *  $   ",
      "*'********  $   ",
      "    -       $   "
    ],
    [
      "  - %%%% *  $   ",
      "  - %%%% *  $   ",
      "  - %%%% *  $   ",
      "  - %%%% *  $   ",
      "  - %%%% *  !   ",
      "  -      *  !   ",
      "  ,      *  $   ",
      "  -      *  $   ",
      "  -      *  $   ",
      "  -      *  $   ",
      "  -      *  $   ",
      "  -      *  !   ",
      "  -      *  !   ",
      "  -      *  $   ",
      "*(********  $   ",
      "    -       $   "
    ],
    [
      "  - %%%% *  $   ",
      "  - %%%% *  $   ",
      "  - %%%% *  $   ",
      "  - %%%% *  $   ",
      "  - %%%% *  $   ",
      "  -      *  $   ",
      "  -      *  $   ",
      "  -      *  $   ",
      "  -      *  $   ",
      "  -      *  $   ",
      "  -      *  $   ",
      "  -      *  $   ",
      "  -      *  $   ",
      "  -      *  $   ",
      "**********  $   ",
      "    -       $   "
    ]
  ],
  "palette": {
    "palette": [
      {
        "char": "!",
        "block": "create:framed_glass"
      },
      {
        "char": "$",
        "block": "immersiveengineering:concrete_reinforced"
      },
      {
        "char": "%",
        "block": "immersiveengineering:sheetmetal_steel"
      },
      {
        "char": "&",
        "block": "minecraft:barrel[facing=up,open=false]"
      },
      {
        "char": "'",
        "block": "minecraft:dark_oak_door[facing=south,half=lower,hinge=left,open=false,powered=false]"
      },
      {
        "char": "(",
        "block": "minecraft:dark_oak_door[facing=south,half=upper,hinge=left,open=false,powered=false]"
      },
      {
        "char": ")",
        "block": "minecraft:polished_andesite"
      },
      {
        "char": "*",
        "block": "minecraft:smooth_stone"
      },
      {
        "char": "+",
        "block": "minecraft:spruce_door[facing=east,half=lower,hinge=left,open=false,powered=false]"
      },
      {
        "char": ",",
        "block": "minecraft:spruce_door[facing=east,half=upper,hinge=left,open=false,powered=false]"
      },
      {
        "char": "-",
        "block": "tfmg:cinder_block"
      }
    ]
  }
}
