{
  "xsize": 16,
  "zsize": 16,
  "slices": [
    [
      "(((((((((((((   ",
      "(((((((((((((   ",
      "(((((((((((((   ",
      "(((((((((((((   ",
      "(((((&(((((((   ",
      "(((&&%(((((((   ",
      "(&&%(((((((((   ",
      "&%(((((((((((   ",
      "(((((((((((((   ",
      "(((((((((((((   ",
      "(((((((((((((   ",
      "(((((((((((((   ",
      "(((((((((((((   ",
      "(((((((((((((   ",
      "((((&&(((((((   ",
      "((&&%((((((((   "
    ],
    [
      "                ",
      "                ",
      "                ",
      "                ",
      "                ",
      "                ",
      "                ",
      "                ",
      "                ",
      "                ",
      "                ",
      "                ",
      "                ",
      "                ",
      "                ",
      "                "
    ],
    [
      "                ",
      "                ",
      "                ",
      "                ",
      "                ",
      "                ",
      "                ",
      "                ",
      "                ",
      "                ",
      "                ",
      "                ",
      "                ",
      "                ",
      "                ",
      "                "
    ],
    [
      "   ''''''''''   ",
      "   ''''''''''   ",
      "   ''''''''''   ",
      "   ''''''''''   ",
      "   ''''''''''   ",
      "   ''''''''''   ",
      "   ''''''''''   ",
      "   ''''''''''   ",
      "   ''''''''''   ",
      "   ''''''''''   ",
      "   ''$'''''''   ",
      "   ''''''''''   ",
      "   ''''''''''   ",
      "   ''''''''''   ",
      "       ''''''   ",
      "       ''''''   "
    ],
    [
      "   !   '    !   ",
      "   !   '    !   ",
      "   !   '    !   ",
      "   !   '    !   ",
      "   !   '    !   ",
      "   !   '    !   ",
      "   !   '    !   ",
      "   !   '    !   ",
      "   !   '    !   ",
      "   !   '    !   ",
      "   !   '    !   ",
      "   !   '    !   ",
      "   !   '    !   ",
      "   !   '    !   ",
      "       '    !   ",
      "       '    !   "
    ],
    [
      "   !   '    !   ",
      "   !   '    !   ",
      "   !   '    !   ",
      "   !   '    !   ",
      "   !   '    !   ",
      "   !   '    !   ",
      "   !   '    !   ",
      "   !   '    !   ",
      "   !   '    !   ",
      "   !   '    !   ",
      "   !   '    !   ",
      "   !   '    !   ",
      "   !   '    !   ",
      "   !   '    !   ",
      "       '    !   ",
      "       '    !   "
    ]
  ],
  "palette": {
    "palette": [
      {
        "char": "!",
        "block": "immersiveengineering:concrete_reinforced"
      },
      {
        "char": "$",
        "block": "minecraft:chest[facing=west,type=single,waterlogged=false]",
        "tag": {
          "id": "minecraft:chest",
          "LootTable": "infinite_domain:chests/wasteland_data"
        }
      },
      {
        "char": "%",
        "block": "minecraft:coarse_dirt"
      },
      {
        "char": "&",
        "block": "minecraft:gravel"
      },
      {
        "char": "'",
        "block": "minecraft:smooth_stone"
      },
      {
        "char": "(",
        "block": "tfmg:asphalt"
      }
    ]
  }
}
