{
  "xsize": 16,
  "zsize": 16,
  "slices": [
    [
      "////////////////",
      "////////////////",
      "////////////////",
      "////////////////",
      "////////////////",
      "///////%%$//////",
      "/////%%$////////",
      "///%%$//////////",
      "/%%$////////////",
      "%$//////////////",
      "////////////////",
      "//////////////%%",
      "////////////%%$/",
      "//////////%%$///",
      "////////%%$/////",
      "//////%%$///////"
    ],
    [
      "                ",
      "                ",
      "  .     .     . ",
      "            (   ",
      "                ",
      "                ",
      "    ''''''''''''",
      "    ''''''''''''",
      "    ''''''''''''",
      "    ''''''''''''",
      "    ''''''''''''",
      "    ''''''''''''",
      "    ''''''''''''",
      "    ''''''''''''",
      "    ''''''''''''",
      "    ''''''''''''"
    ],
    [
      "                ",
      "                ",
      "                ",
      "            (   ",
      "                ",
      "                ",
      "    &&&&&&&&&&&&",
      "    &           ",
      "    &           ",
      "    &  ++       ",
      "    &  ,        ",
      "    &           ",
      "    &           ",
      "    &0000000)000",
      "    &          0",
      "    &          0"
    ],
    [
      "                ",
      "                ",
      "                ",
      "            (   ",
      "                ",
      "       +++   +++",
      "    &&&&&&&&&&&&",
      "    &           ",
      "    &           ",
      "    &           ",
      "    &           ",
      "    &           ",
      "    &           ",
      "    &0000000*000",
      "    &          0",
      "    &          0"
    ],
    [
      "                ",
      "                ",
      "                ",
      "            (   ",
      "                ",
      "                ",
      "    &&-!!!-&-!!!",
      "    &           ",
      "    &           ",
      "    &           ",
      "    &           ",
      "    &           ",
      "    &           ",
      "    &00000000000",
      "    &          0",
      "    &          0"
    ],
    [
      "                ",
      "                ",
      "                ",
      "            (   ",
      "                ",
      "                ",
      "    &&-!!!-&-!!!",
      "    &           ",
      "    &           ",
      "    &           ",
      "    &           ",
      "    &           ",
      "    &           ",
      "    &00000000000",
      "    &          0",
      "    &          0"
    ]
  ],
  "palette": {
    "palette": [
      {
        "char": "!",
        "block": "create:framed_glass"
      },
      {
        "char": "$",
        "block": "minecraft:coarse_dirt"
      },
      {
        "char": "%",
        "block": "minecraft:gravel"
      },
      {
        "char": "&",
        "block": "minecraft:mud_bricks"
      },
      {
        "char": "'",
        "block": "minecraft:polished_andesite"
      },
      {
        "char": "(",
        "block": "minecraft:polished_deepslate"
      },
      {
        "char": ")",
        "block": "minecraft:spruce_door[facing=south,half=lower,hinge=left,open=false,powered=false]"
      },
      {
        "char": "*",
        "block": "minecraft:spruce_door[facing=south,half=upper,hinge=left,open=false,powered=false]"
      },
      {
        "char": "+",
        "block": "minecraft:spruce_slab[type=bottom,waterlogged=false]"
      },
      {
        "char": ",",
        "block": "minecraft:spruce_stairs[facing=north,half=bottom,shape=straight,waterlogged=false]"
      },
      {
        "char": "-",
        "block": "minecraft:stripped_spruce_log[axis=y]"
      },
      {
        "char": ".",
        "block": "minecraft:white_concrete"
      },
      {
        "char": "/",
        "block": "tfmg:asphalt"
      },
      {
        "char": "0",
        "block": "tfmg:cinder_block"
      }
    ]
  }
}
