{
  "xsize": 16,
  "zsize": 16,
  "slices": [
    [
      ",,,,,,,&&%,,,,,,",
      ",,,,,&&%,,,,,,,,",
      ",,,&&%,,,,,,,,,,",
      ",&&%,,,,,,,,,,,,",
      "&%,,,,,,,,,,,,,,",
      ",,,,,,,,,,,,,,,,",
      ",,,,,,,,,,,,,,&&",
      ",,,,,,,,,,,,&&%,",
      ",,,,,,,,,,&&%,,,",
      ",,,,,,,,&&%,,,,,",
      ",,,,,,&&%,,,,,,,",
      ",,,,&&%,,,,,,,,,",
      ",,&&%,,,,,,,,,,,",
      "&&%,,,,,,,,,,,,,",
      "%,,,,,,,,,,,,,,,",
      ",,,,,,,,,,,,,,,&"
    ],
    [
      "((((((((((((((((",
      "((((((((((((((((",
      "((((((((((((((((",
      "((((((((((((((((",
      "((((((((((((((((",
      "((((((((((((((((",
      "((((((((((((((((",
      "((((((((((((((((",
      "((((((((((((((((",
      "((((((((((((((((",
      "((((((((((((((((",
      "((((((((((((((((",
      "((((((((((((((((",
      "((((((((((((((((",
      "((((((((((((((((",
      "(((((((((((((((("
    ],
    [
      "       !!!!!!  '",
      "  )    !!!!!!  '",
      "       !!!!!!  '",
      "       !!!!!!  '",
      "               '",
      "               '",
      "               '",
      "               '",
      "               '",
      "               '",
      "               '",
      "--*-------*----'",
      "      -        '",
      "      -        '",
      "      -        '",
      "      - $$$$$$ '"
    ],
    [
      "       !!!!!!  '",
      "       !!!!!!  '",
      "       !!!!!!  '",
      "       !!!!!!  '",
      "               '",
      "               '",
      "               '",
      "               '",
      "               '",
      "               '",
      "               '",
      "--+-------+----'",
      "      -        '",
      "      -        '",
      "      -        '",
      "      - $$$$$$ '"
    ],
    [
      "               '",
      "               '",
      "               '",
      "               '",
      "               '",
      "               '",
      "               '",
      "               '",
      "               '",
      "               '",
      "               '",
      "---------------'",
      "      -        '",
      "      -        '",
      "      -        '",
      "      - $$$$$$ '"
    ],
    [
      "               '",
      "               '",
      "               '",
      "               '",
      "               '",
      "               '",
      "               '",
      "               '",
      "               '",
      "               '",
      "               '",
      "---------------'",
      "      -        '",
      "      -        '",
      "      -        '",
      "      -        '"
    ]
  ],
  "palette": {
    "palette": [
      {
        "char": "!",
        "block": "immersiveengineering:crate"
      },
      {
        "char": "$",
        "block": "immersiveengineering:sheetmetal_steel"
      },
      {
        "char": "%",
        "block": "minecraft:coarse_dirt"
      },
      {
        "char": "&",
        "block": "minecraft:gravel"
      },
      {
        "char": "'",
        "block": "minecraft:mud_bricks"
      },
      {
        "char": "(",
        "block": "minecraft:polished_andesite"
      },
      {
        "char": ")",
        "block": "kubejs:ruined_smoker[facing=south]"
      },
      {
        "char": "*",
        "block": "minecraft:spruce_door[facing=south,half=lower,hinge=left,open=false,powered=false]"
      },
      {
        "char": "+",
        "block": "minecraft:spruce_door[facing=south,half=upper,hinge=left,open=false,powered=false]"
      },
      {
        "char": ",",
        "block": "tfmg:asphalt"
      },
      {
        "char": "-",
        "block": "tfmg:cinder_block"
      }
    ]
  }
}
