{
  "xsize": 16,
  "zsize": 16,
  "slices": [
    [
      "  ) $$$$ '  !   ",
      "  ) $$$$ '  !   ",
      "  ) $$$$ '  !   ",
      "  ) $$$$ '  !   ",
      "  ) $$$$ '  !   ",
      "  )      '  !   ",
      "  )      '  !   ",
      "  )      '  !   ",
      "  )      '  !   ",
      "  )      '  !   ",
      "  )      '  !   ",
      "  )      '  !   ",
      "  )      '  !   ",
      "  )      '  !   ",
      "''''''''''  !   ",
      "            !   "
    ],
    [
      "         '%%%   ",
      "         '%%%   ",
      "         '%%%   ",
      "         '%%%   ",
      "         '%%%   ",
      "         '%%%   ",
      "         '%%%   ",
      "         '%%%   ",
      "         '%%%   ",
      "         '%%%   ",
      "         '%%%   ",
      "         '%%%   ",
      "         '%%%   ",
      "         '%%%   ",
      "''''''''''%%%   ",
      "%%%%%%%%%%%%%   "
    ],
    [
      "((((((((((      ",
      "(((((((&&(      ",
      "(((((((&&(      ",
      "(((((((&&(      ",
      "(((((((&&(      ",
      "(((((((&&(      ",
      "(((((((&&(      ",
      "((((((((((      ",
      "((((((((((      ",
      "((((((((((      ",
      "((((((((((      ",
      "((((((((((      ",
      "((((((((((      ",
      "((((((((((      ",
      "((((((((((      ",
      "                "
    ]
  ],
  "palette": {
    "palette": [
      {
        "char": "!",
        "block": "immersiveengineering:concrete_reinforced"
      },
      {
        "char": "$",
        "block": "immersiveengineering:sheetmetal_steel"
      },
      {
        "char": "%",
        "block": "minecraft:light_gray_concrete"
      },
      {
        "char": "&",
        "block": "minecraft:oxidized_copper"
      },
      {
        "char": "'",
        "block": "minecraft:smooth_stone"
      },
      {
        "char": "(",
        "block": "minecraft:weathered_cut_copper"
      },
      {
        "char": ")",
        "block": "tfmg:cinder_block"
      }
    ]
  }
}
