{
  "xsize": 16,
  "zsize": 16,
  "slices": [
    [
      "       !        ",
      "       !        ",
      "       !        ",
      "       !        ",
      "       !        ",
      "       !        ",
      "       !&&&     ",
      "       !&$&     ",
      "       !&&&     ",
      "       !        ",
      "       !!!!!!!!!",
      "                ",
      "                ",
      "                ",
      "                ",
      "                "
    ],
    [
      "       %%%%%%%%%",
      "       %%%%%%%%%",
      "       %%%%%%%%%",
      "       %%%%%%%%%",
      "       %%%%%%%%%",
      "       %%%%%%%%%",
      "       %%%%%%%%%",
      "       %%%%%%%%%",
      "       %%%%%%%%%",
      "       %%%%%%%%%",
      "       %%%%%%%%%",
      "                ",
      "                ",
      "                ",
      "                ",
      "                "
    ],
    [
      "                ",
      "                ",
      "                ",
      "                ",
      "                ",
      "                ",
      "                ",
      "                ",
      "                ",
      "                ",
      "                ",
      "                ",
      "                ",
      "                ",
      "                ",
      "                "
    ]
  ],
  "palette": {
    "palette": [
      {
        "char": "!",
        "block": "immersiveengineering:concrete_reinforced"
      },
      {
        "char": "$",
        "block": "minecraft:ladder[facing=south,waterlogged=false]"
      },
      {
        "char": "%",
        "block": "minecraft:light_gray_concrete"
      },
      {
        "char": "&",
        "block": "minecraft:polished_deepslate"
      }
    ]
  }
}
