{
  "xsize": 16,
  "zsize": 16,
  "slices": [
    [
      "               &",
      "               &",
      "               &",
      "               &",
      "               &",
      "               &",
      "               &",
      "               &",
      "               &",
      "               &",
      "               &",
      "               &",
      "               &",
      "               &",
      "               &",
      "               &"
    ],
    [
      "               &",
      "               &",
      "               &",
      "               &",
      "               &",
      "               &",
      "               &",
      "               &",
      "               &",
      "               &",
      "               &",
      "               &",
      "               &",
      "               &",
      "               &",
      "               &"
    ],
    [
      "               &",
      "               &",
      "               &",
      "               &",
      "               &",
      "               &",
      "               &",
      "               &",
      "               &",
      "               &",
      "               &",
      "               &",
      "               &",
      "               &",
      "               &",
      "               &"
    ],
    [
      "''''''''''''''''",
      "''''''''''''''''",
      "''''''''''''''''",
      "''''''''''''''''",
      "''''''''''''''''",
      "''''''''''''''''",
      "''''''''''''''''",
      "''''''''''''''''",
      "''''''''''''''''",
      "''''''''''''''''",
      "''''''''''''''''",
      "''''''''''''''''",
      "''''''''''''''''",
      "''''''''''''''''",
      "''''''''''''''''",
      "''''''''''''''''"
    ],
    [
      "    ,       $   ",
      "    ,       $   ",
      "    ,       $   ",
      "    ,       $   ",
      "    ,       $   ",
      "    ,       $   ",
      "    ,       $   ",
      "    ,       $   ",
      "    , **    $   ",
      "    , +     $   ",
      "    ,       $   ",
      "    ,       $   ",
      "    ,       $   ",
      "    (       $   ",
      "    ,       $   ",
      "    ,  %    $   "
    ],
    [
      "    ,       $   ",
      "    ,       $   ",
      "    ,       $   ",
      "    ,       $   ",
      "    ,       !   ",
      "    ,       !   ",
      "    ,       $   ",
      "    ,       $   ",
      "    ,       $   ",
      "    ,       $   ",
      "    ,       $   ",
      "    ,       !   ",
      "    ,       !   ",
      "    )       $   ",
      "    ,       $   ",
      "    ,       $   "
    ]
  ],
  "palette": {
    "palette": [
      {
        "char": "!",
        "block": "create:framed_glass"
      },
      {
        "char": "$",
        "block": "immersiveengineering:concrete_reinforced"
      },
      {
        "char": "%",
        "block": "minecraft:barrel[facing=up,open=false]"
      },
      {
        "char": "&",
        "block": "minecraft:mud_bricks"
      },
      {
        "char": "'",
        "block": "minecraft:smooth_stone"
      },
      {
        "char": "(",
        "block": "minecraft:spruce_door[facing=east,half=lower,hinge=left,open=false,powered=false]"
      },
      {
        "char": ")",
        "block": "minecraft:spruce_door[facing=east,half=upper,hinge=left,open=false,powered=false]"
      },
      {
        "char": "*",
        "block": "minecraft:spruce_slab[type=bottom,waterlogged=false]"
      },
      {
        "char": "+",
        "block": "minecraft:spruce_stairs[facing=north,half=bottom,shape=straight,waterlogged=false]"
      },
      {
        "char": ",",
        "block": "tfmg:cinder_block"
      }
    ]
  }
}
