{
  "xsize": 16,
  "zsize": 16,
  "slices": [
    [
      "1111111111111,,%",
      "11111111111,,%11",
      "111111111,,%1111",
      "1111111,,%111111",
      "11111,,%11111111",
      "111,,%1111111111",
      "1,,%111111111111",
      ",%11111111111111",
      "1111111111111111",
      "11111111111111,,",
      "111111111111,,%1",
      "1111111111,,%111",
      "11111111,,%11111",
      "111111,,%1111111",
      "1111,,%111111111",
      "11,,%11111111111"
    ],
    [
      "................",
      "................",
      "................",
      "................",
      "................",
      "................",
      "................",
      "................",
      "................",
      "................",
      "................",
      "................",
      "................",
      "................",
      "................",
      "                "
    ],
    [
      "      2 !!!!!! -",
      "      2 !!!!!! -",
      "      2 !!!!!! -",
      "      2        -",
      "      /        -",
      "      2        -",
      "      2        -",
      "      2        &",
      "      2        -",
      "      2        -",
      "      2    $   -",
      "      2        -",
      "      2        -",
      "      2        -",
      "----------()----",
      "                "
    ],
    [
      "      2 !!!!!! -",
      "      2 !!!!!! -",
      "      2 !!!!!! -",
      "      2        -",
      "      0        -",
      "      2        -",
      "      2        -",
      "      2        '",
      "      2        -",
      "      2        -",
      "      2        -",
      "      2        -",
      "      2        -",
      "      2        -",
      "----------*+----",
      "                "
    ],
    [
      "      2 !!!!!! -",
      "      2 !!!!!! -",
      "      2 !!!!!! -",
      "      2        -",
      "      2        -",
      "      2        -",
      "      2        -",
      "      2        -",
      "      2        -",
      "      2        -",
      "      2        -",
      "      2        -",
      "      2        -",
      "      2        -",
      "----------------",
      "                "
    ],
    [
      "      2        -",
      "      2        -",
      "      2        -",
      "      2        -",
      "      2        -",
      "      2        -",
      "      2        -",
      "      2        -",
      "      2        -",
      "      2        -",
      "      2        -",
      "      2        -",
      "      2        -",
      "      2        -",
      "----------------",
      "                "
    ]
  ],
  "palette": {
    "palette": [
      {
        "char": "!",
        "block": "immersiveengineering:sheetmetal_steel"
      },
      {
        "char": "$",
        "block": "minecraft:chest[facing=north,type=single,waterlogged=false]",
        "tag": {
          "id": "minecraft:chest",
          "LootTable": "infinite_domain:chests/wasteland_office"
        }
      },
      {
        "char": "%",
        "block": "minecraft:coarse_dirt"
      },
      {
        "char": "&",
        "block": "minecraft:dark_oak_door[facing=east,half=lower,hinge=left,open=false,powered=false]"
      },
      {
        "char": "'",
        "block": "minecraft:dark_oak_door[facing=east,half=upper,hinge=left,open=false,powered=false]"
      },
      {
        "char": "(",
        "block": "minecraft:dark_oak_door[facing=south,half=lower,hinge=left,open=false,powered=false]"
      },
      {
        "char": ")",
        "block": "minecraft:dark_oak_door[facing=south,half=lower,hinge=right,open=false,powered=false]"
      },
      {
        "char": "*",
        "block": "minecraft:dark_oak_door[facing=south,half=upper,hinge=left,open=false,powered=false]"
      },
      {
        "char": "+",
        "block": "minecraft:dark_oak_door[facing=south,half=upper,hinge=right,open=false,powered=false]"
      },
      {
        "char": ",",
        "block": "minecraft:gravel"
      },
      {
        "char": "-",
        "block": "minecraft:mud_bricks"
      },
      {
        "char": ".",
        "block": "minecraft:polished_andesite"
      },
      {
        "char": "/",
        "block": "minecraft:spruce_door[facing=east,half=lower,hinge=left,open=false,powered=false]"
      },
      {
        "char": "0",
        "block": "minecraft:spruce_door[facing=east,half=upper,hinge=left,open=false,powered=false]"
      },
      {
        "char": "1",
        "block": "tfmg:asphalt"
      },
      {
        "char": "2",
        "block": "tfmg:cinder_block"
      }
    ]
  }
}
