{
  "xsize": 16,
  "zsize": 16,
  "slices": [
    [
      "--------$$$$!---",
      "--------$$$-----",
      "------!!!!!!!!!!",
      "----$$!!!!!!!!!!",
      "--$$!-!!!!!!!!!!",
      "$$!---!!!!!!!!!!",
      "!-----!!!!!!!!!!",
      "------!!!!!!!!!!",
      "------!!!!!!!!!!",
      "------!!!!!!!!!!",
      "------!!!!!!!!!!",
      "-------$$!------",
      "-----$$!--------",
      "---$$!----------",
      "-$$!------------",
      "$!--------------"
    ],
    [
      "   *            ",
      "   * ++++++&'+++",
      "   * +          ",
      "   * +          ",
      "   * +          ",
      "   * +          ",
      "   * +          ",
      "   * +          ",
      "    *+ %%%     ,",
      "     + %%%      ",
      "     +*         ",
      "     +++++++++++",
      "        *       ",
      "         *******",
      "                ",
      "                "
    ],
    [
      "   *            ",
      "   * ++++++()+++",
      "   * +          ",
      "   * +          ",
      "   * +          ",
      "   * +          ",
      "   * +          ",
      "   * +          ",
      "    *+          ",
      "     +          ",
      "     +*         ",
      "     +++++++++++",
      "        *       ",
      "         *******",
      "                ",
      "                "
    ],
    [
      "   *            ",
      "   *            ",
      "   *            ",
      "   *            ",
      "   *            ",
      "   *            ",
      "   *            ",
      "   *            ",
      "    *           ",
      "     *          ",
      "      *         ",
      "       *        ",
      "        *       ",
      "         *******",
      "                ",
      "                "
    ],
    [
      "   *            ",
      "   *            ",
      "   *            ",
      "   *            ",
      "   *            ",
      "   *            ",
      "   *            ",
      "   *            ",
      "    *           ",
      "     *          ",
      "      *         ",
      "       *        ",
      "        *       ",
      "         *******",
      "                ",
      "                "
    ],
    [
      "   *            ",
      "   *            ",
      "   *            ",
      "   *            ",
      "   *            ",
      "   *            ",
      "   *            ",
      "   *            ",
      "    *           ",
      "     *          ",
      "      *         ",
      "       *        ",
      "        *       ",
      "         *******",
      "                ",
      "                "
    ]
  ],
  "palette": {
    "palette": [
      {
        "char": "!",
        "block": "minecraft:coarse_dirt"
      },
      {
        "char": "$",
        "block": "minecraft:gravel"
      },
      {
        "char": "%",
        "block": "minecraft:hay_block"
      },
      {
        "char": "&",
        "block": "minecraft:oak_door[facing=north,half=lower,hinge=left,open=false,powered=false]"
      },
      {
        "char": "'",
        "block": "minecraft:oak_door[facing=north,half=lower,hinge=right,open=false,powered=false]"
      },
      {
        "char": "(",
        "block": "minecraft:oak_door[facing=north,half=upper,hinge=left,open=false,powered=false]"
      },
      {
        "char": ")",
        "block": "minecraft:oak_door[facing=north,half=upper,hinge=right,open=false,powered=false]"
      },
      {
        "char": "*",
        "block": "minecraft:stripped_dark_oak_log[axis=y]"
      },
      {
        "char": "+",
        "block": "minecraft:stripped_oak_log[axis=y]"
      },
      {
        "char": ",",
        "block": "kubejs:ruined_cauldron"
      },
      {
        "char": "-",
        "block": "tfmg:asphalt"
      }
    ]
  }
}
