{
  "xsize": 16,
  "zsize": 16,
  "slices": [
    [
      "$+++++++++++++++",
      "+++++++++++++++&",
      "+++++++++++++&&$",
      "+++++++++++&&$++",
      "+++++++++&&$++++",
      "+++++++&&$++++++",
      "+++++&&$++++++++",
      "+++&&$++++++++++",
      "+&&$++++++++++++",
      "&$+++++++++++++&",
      "+++++++++++++&&&",
      "++++++++++++&&&&",
      "+++++++++++&&&$+",
      "++++++++++&&&+++",
      "++++++++&&&&++++",
      "++++++&&$&&+++++"
    ],
    [
      "                ",
      "                ",
      "               %",
      "         ))))))%",
      "        )      %",
      "       )       %",
      "      )        %",
      "     )         %",
      "    )          %",
      "   )           %",
      "   )            ",
      "   ) $$$$$$$$   ",
      "   ) $$$$$$$$   ",
      "   ) $$$$$$$$   ",
      "   ) $$$$$$$$   ",
      "   ) $$$$$$$$   "
    ],
    [
      "                ",
      "                ",
      "               )",
      "         ))))))%",
      "        )      %",
      "       )       %",
      "      )        %",
      "     )         %",
      "    )          %",
      "   )           )",
      "   )            ",
      "   ) *''''''*   ",
      "   ) '          ",
      "   ) '          ",
      "   ) '    !     ",
      "   ) '  (       "
    ],
    [
      "                ",
      "                ",
      "               )",
      "         ))))))%",
      "        )      %",
      "       )       %",
      "      )        %",
      "     )         %",
      "    )          %",
      "   )           )",
      "   )            ",
      "   ) *''''''*   ",
      "   ) '          ",
      "   ) '          ",
      "   ) '          ",
      "   ) '          "
    ],
    [
      "                ",
      "                ",
      "               )",
      "         ))))))%",
      "        )      %",
      "       )       %",
      "      )        %",
      "     )         %",
      "    )          %",
      "   )           )",
      "   )            ",
      "   ) '      '   ",
      "   ) '      '   ",
      "   ) '      '   ",
      "   ) '      '   ",
      "   ) '      '   "
    ],
    [
      "                ",
      "                ",
      "               )",
      "         ))))))%",
      "        )      %",
      "       )       %",
      "      )        %",
      "     )         %",
      "    )          %",
      "   )           )",
      "   )            ",
      "   ) *'    '*   ",
      "   )  '    '    ",
      "   )  '    '    ",
      "   )  '    '    ",
      "   )  '    '    "
    ]
  ],
  "palette": {
    "palette": [
      {
        "char": "!",
        "block": "minecraft:chest[facing=east,type=single,waterlogged=false]",
        "tag": {
          "id": "minecraft:chest",
          "LootTable": "infinite_domain:chests/wasteland_market"
        }
      },
      {
        "char": "$",
        "block": "minecraft:coarse_dirt"
      },
      {
        "char": "%",
        "block": "minecraft:dark_oak_planks"
      },
      {
        "char": "&",
        "block": "minecraft:gravel"
      },
      {
        "char": "'",
        "block": "minecraft:red_wool"
      },
      {
        "char": "(",
        "block": "minecraft:smoker[facing=east,lit=false]"
      },
      {
        "char": ")",
        "block": "minecraft:stripped_dark_oak_log[axis=y]"
      },
      {
        "char": "*",
        "block": "minecraft:stripped_oak_log[axis=y]"
      },
      {
        "char": "+",
        "block": "tfmg:asphalt"
      }
    ]
  }
}
