{
  "xsize": 16,
  "zsize": 16,
  "slices": [
    [
      "//////'''/''&///",
      "///////'''&/////",
      "//////'''///////",
      "////''&/''//////",
      "'''''''/''//////",
      "'''''''/''//////",
      "'''''''/''//////",
      "////////''/////'",
      "////////'''//''&",
      "////////''/''&//",
      "////////'''&////",
      "///////'''//////",
      "/////''&''//////",
      "///''&//''//////",
      "/''&///''///////",
      "'&/////''///////"
    ],
    [
      "))  &&&&&&&& +  ",
      "))  &&&&&&&& +  ",
      "))           +  ",
      "))           +  ",
      "))           +  ",
      "))           +  ",
      "))           +  ",
      "))           +  ",
      "))  &&&&&&&& +  ",
      "))  &'''&&&& +  ",
      "))  &'''&&&& +  ",
      "))  &'''&&&& +  ",
      "))  &&&&&&&& +  ",
      "))  &&&&&&&& +  ",
      " $  &&&&&&&& +  ",
      "             +  "
    ],
    [
      "**         . +  ",
      " *  ,......, +  ",
      " *           +  ",
      " *           +  ",
      " *           +  ",
      " *           +  ",
      " *           +  ",
      "-*           +  ",
      " *  ,%%%%%%, +  ",
      " *   '''   % +  ",
      " *   '''   % +  ",
      " *   '''   % +  ",
      " *     (   % +  ",
      "**       0 % +  ",
      "    ,%%%%%%, +  ",
      "             +  "
    ],
    [
      "**         . +  ",
      " *  ,......, +  ",
      " *           +  ",
      " *           +  ",
      " *           +  ",
      " *           +  ",
      " *           +  ",
      "-*           +  ",
      " *  ,%%%%%%, +  ",
      " *         % +  ",
      " *         % +  ",
      " *    %    % +  ",
      " *         % +  ",
      "**         % +  ",
      "    ,%%%%%%, +  ",
      "             +  "
    ],
    [
      "!*  .      . +  ",
      " *  .      . +  ",
      " *           +  ",
      " !           +  ",
      " !           +  ",
      " *           +  ",
      " *           +  ",
      "-*           +  ",
      " *  %      % +  ",
      " *  %      % +  ",
      " *  %      % +  ",
      " *  %      % +  ",
      " *  %      % +  ",
      "**  %      % +  ",
      "    %      % +  ",
      "             +  "
    ],
    [
      "!*   .    .  +  ",
      " *  ,.    ., +  ",
      " *           +  ",
      " !           +  ",
      " !           +  ",
      " *           +  ",
      " *           +  ",
      "-*           +  ",
      " *        %, +  ",
      " *        %  +  ",
      " *        %  +  ",
      " *        %  +  ",
      " *        %  +  ",
      "**        %  +  ",
      "          %, +  ",
      "             +  "
    ]
  ],
  "palette": {
    "palette": [
      {
        "char": "!",
        "block": "create:framed_glass"
      },
      {
        "char": "$",
        "block": "minecraft:barrel[facing=up,open=false]"
      },
      {
        "char": "%",
        "block": "minecraft:blue_wool"
      },
      {
        "char": "&",
        "block": "minecraft:coarse_dirt"
      },
      {
        "char": "'",
        "block": "minecraft:gravel"
      },
      {
        "char": "(",
        "block": "kubejs:ruined_loom[facing=west]"
      },
      {
        "char": ")",
        "block": "minecraft:oak_planks"
      },
      {
        "char": "*",
        "block": "minecraft:spruce_planks"
      },
      {
        "char": "+",
        "block": "minecraft:stripped_dark_oak_log[axis=y]"
      },
      {
        "char": ",",
        "block": "minecraft:stripped_oak_log[axis=y]"
      },
      {
        "char": "-",
        "block": "minecraft:stripped_spruce_wood"
      },
      {
        "char": ".",
        "block": "minecraft:yellow_wool"
      },
      {
        "char": "/",
        "block": "tfmg:asphalt"
      },
      {
        "char": "0",
        "block": "wastelands:scrap_pile"
      }
    ]
  }
}
