{
  "xsize": 16,
  "zsize": 16,
  "slices": [
    [
      "////''%/'''/////",
      "//''%///''//////",
      "''%/////''//////",
      "%//////''///////",
      "///////''/''''''",
      "///////''/''''''",
      "///////''/''''''",
      "///////''''%////",
      "//////'''%//////",
      "/////''''///////",
      "///''%/''///////",
      "/''%///''///////",
      "'%/////''///////",
      "///////''///////",
      "////////''////''",
      "////////''//''%/"
    ],
    [
      "   - %%%%%%%%  *",
      "   - %%%%%%%%  *",
      "   -           *",
      "   -           *",
      "   -           *",
      "   -           *",
      "   -           *",
      "   -           *",
      "   - %%%%%%%%  *",
      "   - %%%%%%%%  *",
      "   - %%%%%%%%  *",
      "   - %%%%%%%%  *",
      "   - %%%%%%%%  *",
      "   - %%%%%%%%  *",
      "   - %%%%%%%%  &",
      "   -            "
    ],
    [
      "   - +         ,",
      "   - .++++++.  ,",
      "   -           ,",
      "   -           ,",
      "   -           ,",
      "   -           ,",
      "   -           ,",
      "   -           ,",
      "   - .((((((.  ,",
      "   - (         ,",
      "   - (         ,",
      "   - (    $    ,",
      "   - (  )      ,",
      "   - (         ,",
      "   - .((((((.   ",
      "   -            "
    ],
    [
      "   - +         ,",
      "   - .++++++.  ,",
      "   -           ,",
      "   -           ,",
      "   -           ,",
      "   -           ,",
      "   -           ,",
      "   -           ,",
      "   - .((((((.  ,",
      "   - (         ,",
      "   - (         ,",
      "   - (         ,",
      "   - (         ,",
      "   - (         ,",
      "   - .((((((.   ",
      "   -            "
    ],
    [
      "   - +      +  ,",
      "   - +      +  ,",
      "   -           ,",
      "   -           !",
      "   -           !",
      "   -           ,",
      "   -           ,",
      "   -           ,",
      "   - (      (  ,",
      "   - (      (  ,",
      "   - (      (  ,",
      "   - (      (  ,",
      "   - (      (  ,",
      "   - (      (  ,",
      "   - (      (   ",
      "   -            "
    ],
    [
      "   -  +    +   ,",
      "   - .+    +.  ,",
      "   -           ,",
      "   -           !",
      "   -           !",
      "   -           ,",
      "   -           ,",
      "   -           ,",
      "   - .(    (.  ,",
      "   -  (    (   ,",
      "   -  (    (   ,",
      "   -  (    (   ,",
      "   -  (    (   ,",
      "   -  (    (   ,",
      "   - .(    (.   ",
      "   -            "
    ]
  ],
  "palette": {
    "palette": [
      {
        "char": "!",
        "block": "create:framed_glass"
      },
      {
        "char": "$",
        "block": "minecraft:chest[facing=east,type=single,waterlogged=false]",
        "tag": {
          "id": "minecraft:chest",
          "LootTable": "infinite_domain:chests/wasteland_industrial"
        }
      },
      {
        "char": "%",
        "block": "minecraft:coarse_dirt"
      },
      {
        "char": "&",
        "block": "kubejs:ruined_composter"
      },
      {
        "char": "'",
        "block": "minecraft:gravel"
      },
      {
        "char": "(",
        "block": "minecraft:green_wool"
      },
      {
        "char": ")",
        "block": "kubejs:ruined_grindstone[face=floor,facing=east]"
      },
      {
        "char": "*",
        "block": "minecraft:oak_planks"
      },
      {
        "char": "+",
        "block": "minecraft:red_wool"
      },
      {
        "char": ",",
        "block": "minecraft:spruce_planks"
      },
      {
        "char": "-",
        "block": "minecraft:stripped_dark_oak_log[axis=y]"
      },
      {
        "char": ".",
        "block": "minecraft:stripped_oak_log[axis=y]"
      },
      {
        "char": "/",
        "block": "tfmg:asphalt"
      }
    ]
  }
}
