{
  "xsize": 16,
  "zsize": 16,
  "slices": [
    [
      "-++'------------",
      "+'--------------",
      "----------------",
      "--------------++",
      "------------++'-",
      "------------'---",
      "--------+-------",
      "---+++++++++++--",
      "++++++++++++++++",
      "++++'--+++----++",
      "++'----+++------",
      "'------+++------",
      "-------+++-----+",
      "-------+++---++'",
      "-------+++--+'--",
      "-------+++------"
    ],
    [
      "                ",
      "                ",
      "*****       ****",
      "*****       ****",
      "*****       ****",
      "*****       ****",
      "*****       ****",
      "*****       ****",
      "*****       ****",
      "*****       ****",
      "                ",
      "                ",
      "                ",
      "                ",
      "                ",
      "                "
    ],
    [
      "                ",
      "                ",
      "****,       ,***",
      "    *       *   ",
      "    *       *   ",
      " !  *       *  %",
      "  $ *       *&  ",
      "    *       *   ",
      "    *       *   ",
      "**(*,       ,*(*",
      "                ",
      "                ",
      "                ",
      "                ",
      "                ",
      "                "
    ],
    [
      "                ",
      "                ",
      "****,       ,***",
      "    *       *   ",
      "    *       *   ",
      "    *       *   ",
      "    *       *   ",
      "    *       *   ",
      "    *       *   ",
      "**)*,       ,*)*",
      "                ",
      "                ",
      "                ",
      "                ",
      "                ",
      "                "
    ],
    [
      "                ",
      "                ",
      "****,       ,***",
      "    *       *   ",
      "    *       *   ",
      "    *       *   ",
      "    *       *   ",
      "    *       *   ",
      "    *       *   ",
      "****,       ,***",
      "                ",
      "                ",
      "                ",
      "                ",
      "                ",
      "                "
    ],
    [
      "                ",
      "                ",
      "****,       ,***",
      "    *       *   ",
      "    *       *   ",
      "    *       *   ",
      "    *       *   ",
      "    *       *   ",
      "    *       *   ",
      "****,       ,***",
      "                ",
      "                ",
      "                ",
      "                ",
      "                ",
      "                "
    ]
  ],
  "palette": {
    "palette": [
      {
        "char": "!",
        "block": "minecraft:barrel[facing=up,open=false]"
      },
      {
        "char": "$",
        "block": "minecraft:bell[attachment=floor,facing=north,powered=false]"
      },
      {
        "char": "%",
        "block": "minecraft:cartography_table"
      },
      {
        "char": "&",
        "block": "minecraft:chest[facing=west,type=single,waterlogged=false]",
        "tag": {
          "id": "minecraft:chest",
          "LootTable": "infinite_domain:chests/wasteland_military"
        }
      },
      {
        "char": "'",
        "block": "minecraft:coarse_dirt"
      },
      {
        "char": "(",
        "block": "minecraft:dark_oak_door[facing=south,half=lower,hinge=left,open=false,powered=false]"
      },
      {
        "char": ")",
        "block": "minecraft:dark_oak_door[facing=south,half=upper,hinge=left,open=false,powered=false]"
      },
      {
        "char": "*",
        "block": "minecraft:dark_oak_planks"
      },
      {
        "char": "+",
        "block": "minecraft:gravel"
      },
      {
        "char": ",",
        "block": "minecraft:stripped_dark_oak_log[axis=y]"
      },
      {
        "char": "-",
        "block": "tfmg:asphalt"
      }
    ]
  }
}
