{
  "xsize": 16,
  "zsize": 16,
  "slices": [
    [
      "000000(((0(('000",
      "0000000((('00000",
      "000000(((0000000",
      "0000(('0((000000",
      "(((((((0((000000",
      "(((((((0((000000",
      "(((((((0((000000",
      "00000000((00000(",
      "00000000(((00(('",
      "00000000((0(('00",
      "00000000((('0000",
      "0000000(((000000",
      "00000(('((000000",
      "000(('00((000000",
      "0(('000((0000000",
      "('00000((0000000"
    ],
    [
      "**  '''''''' ,  ",
      "**  '''''''' ,  ",
      "**           ,  ",
      "**           ,  ",
      "**           ,  ",
      "**           ,  ",
      "**           ,  ",
      "**           ,  ",
      "**  '''''''' ,  ",
      "**  '''''''' ,  ",
      "**  '''''''' ,  ",
      "**  '''''''' ,  ",
      "**  '''''''' ,  ",
      "**  '''''''' ,  ",
      " $  '''''''' ,  ",
      "             ,  "
    ],
    [
      "++         / ,  ",
      " +  -//////- ,  ",
      " +           ,  ",
      " +           ,  ",
      " +           ,  ",
      " +           ,  ",
      " +           ,  ",
      ".+           ,  ",
      " +  -%%%%%%- ,  ",
      " +         % ,  ",
      " +         % ,  ",
      " +   &     % ,  ",
      " +     )   % ,  ",
      "++         % ,  ",
      "    -%%%%%%- ,  ",
      "             ,  "
    ],
    [
      "++         / ,  ",
      " +  -//////- ,  ",
      " +           ,  ",
      " +           ,  ",
      " +           ,  ",
      " +           ,  ",
      " +           ,  ",
      ".+           ,  ",
      " +  -%%%%%%- ,  ",
      " +         % ,  ",
      " +         % ,  ",
      " +         % ,  ",
      " +         % ,  ",
      "++         % ,  ",
      "    -%%%%%%- ,  ",
      "             ,  "
    ],
    [
      "!+  /      / ,  ",
      " +  /      / ,  ",
      " +           ,  ",
      " !           ,  ",
      " !           ,  ",
      " +           ,  ",
      " +           ,  ",
      ".+           ,  ",
      " +  %      % ,  ",
      " +  %      % ,  ",
      " +  %      % ,  ",
      " +  %      % ,  ",
      " +  %      % ,  ",
      "++  %      % ,  ",
      "    %      % ,  ",
      "             ,  "
    ],
    [
      "!+   /    /  ,  ",
      " +  -/    /- ,  ",
      " +           ,  ",
      " !           ,  ",
      " !           ,  ",
      " +           ,  ",
      " +           ,  ",
      ".+           ,  ",
      " +  -%    %- ,  ",
      " +   %    %  ,  ",
      " +   %    %  ,  ",
      " +   %    %  ,  ",
      " +   %    %  ,  ",
      "++   %    %  ,  ",
      "    -%    %- ,  ",
      "             ,  "
    ]
  ],
  "palette": {
    "palette": [
      {
        "char": "!",
        "block": "create:framed_glass"
      },
      {
        "char": "$",
        "block": "minecraft:barrel[facing=up,open=false]"
      },
      {
        "char": "%",
        "block": "minecraft:blue_wool"
      },
      {
        "char": "&",
        "block": "minecraft:chest[facing=west,type=single,waterlogged=false]",
        "tag": {
          "id": "minecraft:chest",
          "LootTable": "infinite_domain:chests/wasteland_farm"
        }
      },
      {
        "char": "'",
        "block": "minecraft:coarse_dirt"
      },
      {
        "char": "(",
        "block": "minecraft:gravel"
      },
      {
        "char": ")",
        "block": "kubejs:ruined_loom[facing=west]"
      },
      {
        "char": "*",
        "block": "minecraft:oak_planks"
      },
      {
        "char": "+",
        "block": "minecraft:spruce_planks"
      },
      {
        "char": ",",
        "block": "minecraft:stripped_dark_oak_log[axis=y]"
      },
      {
        "char": "-",
        "block": "minecraft:stripped_oak_log[axis=y]"
      },
      {
        "char": ".",
        "block": "minecraft:stripped_spruce_wood"
      },
      {
        "char": "/",
        "block": "minecraft:yellow_wool"
      },
      {
        "char": "0",
        "block": "tfmg:asphalt"
      }
    ]
  }
}
