{
  "xsize": 16,
  "zsize": 16,
  "slices": [
    [
      "++++''%+++++++++",
      "++''%+++++++++++",
      "''%+++++++++++++",
      "%+++++++++++++++",
      "+++++++++++++++'",
      "+++++++++++++''%",
      "+++++++++++''%++",
      "+++++++++''%++++",
      "'++++++''%++++++",
      "''+++''%++++++++",
      "'''''%++++++++++",
      "+''''+++++++++++",
      "'%+'''++++++++++",
      "++++'''+++++++++",
      "+++++''+++++++''",
      "++++++''++++''%+"
    ],
    [
      "                ",
      "                ",
      "&&              ",
      "&&((((((        ",
      "&&      (       ",
      "&&       (      ",
      "&&        (     ",
      "&&         (    ",
      "&&          (   ",
      "&&           (  ",
      "             (  ",
      "    %%%%%%%% (  ",
      "    %%%%%%%% (  ",
      "    %%%%%%%% (  ",
      "    %%%%%%%% (  ",
      "    %%%%%%%% (  "
    ],
    [
      "                ",
      "                ",
      "&(              ",
      " &((((((        ",
      " &      (       ",
      " &       (      ",
      " &        (     ",
      " &         (    ",
      " &          (   ",
      "&(           (  ",
      "             (  ",
      "    )******) (  ",
      "           * (  ",
      "           * (  ",
      "     $     * (  ",
      "       !   * (  "
    ],
    [
      "                ",
      "                ",
      "&(              ",
      " &((((((        ",
      " &      (       ",
      " &       (      ",
      " &        (     ",
      " &         (    ",
      " &          (   ",
      "&(           (  ",
      "             (  ",
      "    )******) (  ",
      "           * (  ",
      "           * (  ",
      "           * (  ",
      "           * (  "
    ],
    [
      "                ",
      "                ",
      "&(              ",
      " &((((((        ",
      " &      (       ",
      " &       (      ",
      " &        (     ",
      " &         (    ",
      " &          (   ",
      "&(           (  ",
      "             (  ",
      "    *      * (  ",
      "    *      * (  ",
      "    *      * (  ",
      "    *      * (  ",
      "    *      * (  "
    ],
    [
      "                ",
      "                ",
      "&(              ",
      " &((((((        ",
      " &      (       ",
      " &       (      ",
      " &        (     ",
      " &         (    ",
      " &          (   ",
      "&(           (  ",
      "             (  ",
      "    )*    *) (  ",
      "     *    *  (  ",
      "     *    *  (  ",
      "     *    *  (  ",
      "     *    *  (  "
    ]
  ],
  "palette": {
    "palette": [
      {
        "char": "!",
        "block": "minecraft:brewing_stand[has_bottle_0=false,has_bottle_1=false,has_bottle_2=false]"
      },
      {
        "char": "$",
        "block": "minecraft:chest[facing=west,type=single,waterlogged=false]",
        "tag": {
          "id": "minecraft:chest",
          "LootTable": "infinite_domain:chests/wasteland_cache"
        }
      },
      {
        "char": "%",
        "block": "minecraft:coarse_dirt"
      },
      {
        "char": "&",
        "block": "minecraft:dark_oak_planks"
      },
      {
        "char": "'",
        "block": "minecraft:gravel"
      },
      {
        "char": "(",
        "block": "minecraft:stripped_dark_oak_log[axis=y]"
      },
      {
        "char": ")",
        "block": "minecraft:stripped_oak_log[axis=y]"
      },
      {
        "char": "*",
        "block": "minecraft:yellow_wool"
      },
      {
        "char": "+",
        "block": "tfmg:asphalt"
      }
    ]
  }
}
