{
  "xsize": 16,
  "zsize": 16,
  "slices": [
    [
      ":::::::+++:::++)",
      ":::::::+++:++)::",
      ")::::::++++)::::",
      ")::::::+++::::::",
      ")::::+++++::::::",
      ")::++):+++::::::",
      ")++):::+++::::::",
      ")++::::+++::::++",
      ")+++++++++++++++",
      ")::+++++++++++++",
      ")::::::+++::++):",
      ":::::::+++++):::",
      ":::::::+++):::::",
      "::::::++):::::::",
      "::::++):::::::::",
      "::++):::::::::::"
    ],
    [
      "      59995     ",
      "77             7",
      " 7 44444444444 7",
      " 7 44444444444 7",
      " 7 44444444444 7",
      " 7 44444444444 7",
      " 7 44444444444 7",
      " 7 44444444444 7",
      " 7 44444444444 7",
      " 7 44444444444 7",
      " 7 44444444444 7",
      "77 44444444444 7",
      "                ",
      "6666666666666666",
      "                ",
      "                "
    ],
    [
      "                ",
      "77             7",
      " 7 ****01***** 7",
      " 7 *      8  * 7",
      " 7 *      8  * 7",
      " 7 *,  %  8$ * 7",
      " 7 *-  &  8  * 7",
      " 7 *      .  * 7",
      " 7 *      8  * 7",
      " 7 *'     8( * 7",
      " 7 *      8  * 7",
      "77 *********** 7",
      "                ",
      "6666666666666666",
      "                ",
      "                "
    ],
    [
      "                ",
      "                ",
      "   *!!*23**!!*  ",
      "   *      8  *  ",
      "   *      8  *  ",
      "   *      8  *  ",
      "   !      8  *  ",
      "   !      /  *  ",
      "   *      8  *  ",
      "   *      8  *  ",
      "   *      8  *  ",
      "   ***********  ",
      "                ",
      "6666666666666666",
      "                ",
      "                "
    ],
    [
      "                ",
      "                ",
      "   *!!*****!!*  ",
      "   *      8  *  ",
      "   *      8  *  ",
      "   *      8  *  ",
      "   !      8  *  ",
      "   !      8  *  ",
      "   *      8  *  ",
      "   *      8  *  ",
      "   *      8  *  ",
      "   ***********  ",
      "                ",
      "6666666666666666",
      "                ",
      "                "
    ],
    [
      "                ",
      "                ",
      "   ***********  ",
      "   *      8  *  ",
      "   *      8  *  ",
      "   *      8  *  ",
      "   *      8  *  ",
      "   *      8  *  ",
      "   *      8  *  ",
      "   *      8  *  ",
      "   *      8  *  ",
      "   ***********  ",
      "                ",
      "6666666666666666",
      "                ",
      "                "
    ]
  ],
  "palette": {
    "palette": [
      {
        "char": "!",
        "block": "create:framed_glass"
      },
      {
        "char": "$",
        "block": "minecraft:barrel[facing=up,open=false]"
      },
      {
        "char": "%",
        "block": "minecraft:brown_bed[facing=south,occupied=false,part=foot]"
      },
      {
        "char": "&",
        "block": "minecraft:brown_bed[facing=south,occupied=false,part=head]"
      },
      {
        "char": "'",
        "block": "minecraft:campfire[facing=north,lit=false,signal_fire=false,waterlogged=false]"
      },
      {
        "char": "(",
        "block": "minecraft:chest[facing=west,type=single,waterlogged=false]",
        "tag": {
          "id": "minecraft:chest",
          "LootTable": "infinite_domain:chests/wasteland_home"
        }
      },
      {
        "char": ")",
        "block": "minecraft:coarse_dirt"
      },
      {
        "char": "*",
        "block": "minecraft:dark_oak_planks"
      },
      {
        "char": "+",
        "block": "minecraft:gravel"
      },
      {
        "char": ",",
        "block": "minecraft:gray_bed[facing=south,occupied=false,part=foot]"
      },
      {
        "char": "-",
        "block": "minecraft:gray_bed[facing=south,occupied=false,part=head]"
      },
      {
        "char": ".",
        "block": "minecraft:spruce_door[facing=east,half=lower,hinge=left,open=false,powered=false]"
      },
      {
        "char": "/",
        "block": "minecraft:spruce_door[facing=east,half=upper,hinge=left,open=false,powered=false]"
      },
      {
        "char": "0",
        "block": "minecraft:spruce_door[facing=north,half=lower,hinge=left,open=false,powered=false]"
      },
      {
        "char": "1",
        "block": "minecraft:spruce_door[facing=north,half=lower,hinge=right,open=false,powered=false]"
      },
      {
        "char": "2",
        "block": "minecraft:spruce_door[facing=north,half=upper,hinge=left,open=false,powered=false]"
      },
      {
        "char": "3",
        "block": "minecraft:spruce_door[facing=north,half=upper,hinge=right,open=false,powered=false]"
      },
      {
        "char": "4",
        "block": "minecraft:spruce_planks"
      },
      {
        "char": "5",
        "block": "minecraft:stone_bricks"
      },
      {
        "char": "6",
        "block": "minecraft:stripped_dark_oak_log[axis=y]"
      },
      {
        "char": "7",
        "block": "minecraft:stripped_oak_log[axis=y]"
      },
      {
        "char": "8",
        "block": "minecraft:stripped_spruce_wood"
      },
      {
        "char": "9",
        "block": "minecraft:water[level=0]"
      },
      {
        "char": ":",
        "block": "tfmg:asphalt"
      }
    ]
  }
}
