{
  "xsize": 16,
  "zsize": 16,
  "slices": [
    [
      "                ",
      "                ",
      "   !!!!!!!!!!!  ",
      "   !         !  ",
      "   !         !  ",
      "   !         !  ",
      "   !         !  ",
      "   !         !  ",
      "   !         !  ",
      "   !         !  ",
      "   !         !  ",
      "   !!!!!!!!!!!  ",
      "                ",
      "$$$$$$$$$$$$$$$$",
      "                ",
      "                "
    ],
    [
      "                ",
      "                ",
      "   !!!!!!!!!!!  ",
      "   !         !  ",
      "   !         !  ",
      "   !         !  ",
      "   !         !  ",
      "   !         !  ",
      "   !         !  ",
      "   !         !  ",
      "   !         !  ",
      "   !!!!!!!!!!!  ",
      "                ",
      "$$$$$$$$$$$$$$$$",
      "                ",
      "                "
    ],
    [
      "                ",
      "                ",
      "   %%%%%%%%%%%  ",
      "   %%%%%%%%%%%  ",
      "   %%%%%%%%%%%  ",
      "   %%%%%%%%%%%  ",
      "   %%%%%%%%%%%  ",
      "   %%%%%%%%%%%  ",
      "   %%%%%%%%%%%  ",
      "   %%%%%%%%%%%  ",
      "   %%%%%%%%%%%  ",
      "   %%%%%%%%%%%  ",
      "                ",
      "$ $ $ $ $ $ $ $ ",
      "                ",
      "                "
    ],
    [
      "                ",
      "                ",
      "                ",
      "                ",
      "                ",
      "                ",
      "                ",
      "                ",
      "                ",
      "                ",
      "                ",
      "                ",
      "                ",
      "                ",
      "                ",
      "                "
    ],
    [
      "                ",
      "                ",
      "                ",
      "                ",
      "                ",
      "                ",
      "                ",
      "                ",
      "                ",
      "                ",
      "                ",
      "                ",
      "                ",
      "                ",
      "                ",
      "                "
    ],
    [
      "                ",
      "                ",
      "                ",
      "                ",
      "                ",
      "                ",
      "                ",
      "                ",
      "                ",
      "                ",
      "                ",
      "                ",
      "                ",
      "                ",
      "                ",
      "                "
    ]
  ],
  "palette": {
    "palette": [
      {
        "char": "!",
        "block": "minecraft:dark_oak_planks"
      },
      {
        "char": "$",
        "block": "minecraft:stripped_dark_oak_log[axis=y]"
      },
      {
        "char": "%",
        "block": "minecraft:weathered_cut_copper"
      }
    ]
  }
}
