{
  "xsize": 16,
  "zsize": 16,
  "slices": [
    [
      "4444444444444***",
      "44444444444444**",
      "444444444444**(4",
      "4444444444**(444",
      "44444444**(44444",
      "444444**(4444444",
      "4444**(444444444",
      "44**(44444444444",
      "**(4444444444444",
      "(444444444444444",
      "444444444444444*",
      "4444444444444**(",
      "44444444444**(44",
      "444444444**(4444",
      "4444444**(444444",
      "44444**(44444444"
    ],
    [
      "    /+++++++/   ",
      "    /+++++++/   ",
      "    /%+++++%/   ",
      "    /////////   ",
      "    /////////   ",
      "    /////////   ",
      "    /////////   ",
      "                ",
      "                ",
      "                ",
      "                ",
      "                ",
      "    /////////   ",
      "    /////////   ",
      "    /////////   ",
      "    /////////   "
    ],
    [
      "    3 ) 3   3   ",
      "    533333-33   ",
      "    3       3   ",
      "    3 1  $  3   ",
      "    3 2     3   ",
      "    3     ' 3   ",
      "    333333333   ",
      "                ",
      "                ",
      "                ",
      "                ",
      "                ",
      "    ,,,,,,,,,   ",
      "    ,       ,   ",
      "    , 00  & ,   ",
      "    ,       ,   "
    ],
    [
      "    3   3   3   ",
      "    333333.33   ",
      "    3       3   ",
      "    !       3   ",
      "    !       3   ",
      "    3       3   ",
      "    33!!33333   ",
      "                ",
      "                ",
      "                ",
      "                ",
      "                ",
      "    ,,!!,,,,,   ",
      "    ,       ,   ",
      "    ,       ,   ",
      "    !       ,   "
    ],
    [
      "    3   3   3   ",
      "    333333333   ",
      "    3       3   ",
      "    !       3   ",
      "    !       3   ",
      "    3       3   ",
      "    33!!33333   ",
      "                ",
      "                ",
      "                ",
      "                ",
      "                ",
      "    ,,!!,,,,,   ",
      "    ,       ,   ",
      "    ,       ,   ",
      "    !       ,   "
    ],
    [
      "    3   3   3   ",
      "    333333333   ",
      "    3       3   ",
      "    3       3   ",
      "    3       3   ",
      "    3       3   ",
      "    333333333   ",
      "                ",
      "                ",
      "                ",
      "                ",
      "                ",
      "    ,,,,,,,,,   ",
      "    ,       ,   ",
      "    ,       ,   ",
      "    ,       ,   "
    ]
  ],
  "palette": {
    "palette": [
      {
        "char": "!",
        "block": "create:framed_glass"
      },
      {
        "char": "$",
        "block": "minecraft:barrel[facing=up,open=false]"
      },
      {
        "char": "%",
        "block": "minecraft:black_concrete"
      },
      {
        "char": "&",
        "block": "minecraft:bookshelf"
      },
      {
        "char": "'",
        "block": "minecraft:chest[facing=north,type=single,waterlogged=false]",
        "tag": {
          "id": "minecraft:chest",
          "LootTable": "infinite_domain:chests/wasteland_home"
        }
      },
      {
        "char": "(",
        "block": "minecraft:coarse_dirt"
      },
      {
        "char": ")",
        "block": "minecraft:composter[level=2]"
      },
      {
        "char": "*",
        "block": "minecraft:gravel"
      },
      {
        "char": "+",
        "block": "minecraft:gray_concrete"
      },
      {
        "char": ",",
        "block": "minecraft:lime_terracotta"
      },
      {
        "char": "-",
        "block": "minecraft:spruce_door[facing=south,half=lower,hinge=left,open=false,powered=false]"
      },
      {
        "char": ".",
        "block": "minecraft:spruce_door[facing=south,half=upper,hinge=left,open=false,powered=false]"
      },
      {
        "char": "/",
        "block": "minecraft:spruce_planks"
      },
      {
        "char": "0",
        "block": "minecraft:spruce_stairs[facing=south,half=bottom,shape=straight,waterlogged=false]"
      },
      {
        "char": "1",
        "block": "minecraft:yellow_bed[facing=south,occupied=false,part=foot]"
      },
      {
        "char": "2",
        "block": "minecraft:yellow_bed[facing=south,occupied=false,part=head]"
      },
      {
        "char": "3",
        "block": "minecraft:yellow_terracotta"
      },
      {
        "char": "4",
        "block": "tfmg:asphalt"
      },
      {
        "char": "5",
        "block": "tfmg:steel_pipe"
      }
    ]
  }
}
