{
  "xsize": 16,
  "zsize": 16,
  "slices": [
    [
      "//////''$///////",
      "////''$/////////",
      "))'''''''''''''/",
      "))'''''''''''''/",
      "))'''''''''''''/",
      "))'''''''''''''/",
      "$$$$$$$$$$'''''/",
      "$$$$$$$$$$/''''/",
      "$$$$$$$$$$'''''/",
      "$$$$$$$$$$/''''/",
      "$$$$$$$$$$/''''/",
      "$$$$$$$$$$/''''/",
      "/''$////////////",
      "                ",
      "                ",
      "                "
    ],
    [
      "                ",
      "                ",
      "                ",
      "                ",
      "                ",
      "                ",
      "    &    &      ",
      "    &&-  &      ",
      " +  & &. & *  * ",
      " &, &  &+& *!!* ",
      "  &-&   && *!!* ",
      "    &    & *  * ",
      "                ",
      "                ",
      "                ",
      "                "
    ],
    [
      "                ",
      "                ",
      "                ",
      "                ",
      "    (           ",
      "                ",
      "                ",
      "                ",
      "           *  * ",
      "           *  * ",
      "           *  * ",
      "           *  * ",
      "                ",
      "                ",
      "                ",
      "                "
    ],
    [
      "                ",
      "                ",
      "                ",
      "                ",
      "                ",
      "                ",
      "                ",
      "                ",
      "           *  * ",
      "           *  * ",
      "           *  * ",
      "           *  * ",
      "                ",
      "                ",
      "                ",
      "                "
    ],
    [
      "                ",
      "                ",
      "                ",
      "                ",
      "                ",
      "                ",
      "                ",
      "                ",
      "           *  * ",
      "           *  * ",
      "           *  * ",
      "           *  * ",
      "                ",
      "                ",
      "                ",
      "                "
    ],
    [
      "                ",
      "                ",
      "                ",
      "                ",
      "                ",
      "                ",
      "                ",
      "                ",
      "           %%%% ",
      "           %%%% ",
      "           %%%% ",
      "           %%%% ",
      "                ",
      "                ",
      "                ",
      "                "
    ]
  ],
  "palette": {
    "palette": [
      {
        "char": "!",
        "block": "minecraft:barrel[facing=up,open=false]"
      },
      {
        "char": "$",
        "block": "minecraft:coarse_dirt"
      },
      {
        "char": "%",
        "block": "minecraft:dark_oak_planks"
      },
      {
        "char": "&",
        "block": "minecraft:dead_bush"
      },
      {
        "char": "'",
        "block": "minecraft:gravel"
      },
      {
        "char": "(",
        "block": "minecraft:spawner",
        "tag": {
          "id": "minecraft:mob_spawner",
          "Delay": 320,
          "MinSpawnDelay": 240,
          "MaxSpawnDelay": 720,
          "SpawnCount": 2,
          "MaxNearbyEntities": 6,
          "RequiredPlayerRange": 14,
          "SpawnRange": 4,
          "SpawnData": {
            "entity": {
              "id": "minecraft:zombie"
            }
          },
          "SpawnPotentials": [
            {
              "weight": 1,
              "data": {
                "entity": {
                  "id": "minecraft:zombie"
                }
              }
            }
          ]
        }
      },
      {
        "char": ")",
        "block": "minecraft:stone_bricks"
      },
      {
        "char": "*",
        "block": "minecraft:stripped_dark_oak_log[axis=y]"
      },
      {
        "char": "+",
        "block": "minecraft:wheat[age=1]"
      },
      {
        "char": ",",
        "block": "minecraft:wheat[age=3]"
      },
      {
        "char": "-",
        "block": "minecraft:wheat[age=5]"
      },
      {
        "char": ".",
        "block": "minecraft:wheat[age=7]"
      },
      {
        "char": "/",
        "block": "tfmg:asphalt"
      }
    ]
  }
}
