{
  "xsize": 16,
  "zsize": 16,
  "slices": [
    [
      "!!!!!!!!!!%%%%%,",
      "!!!!!!!!!!,,,,,,",
      "!!!!!!!!!!,,,,,,",
      "!!!!!!!!!!,,,%%,",
      "!!!!!!!!!!,%%!,,",
      "!!!!!!!!!!%!,,,,",
      ",,,,,,,%%!,,,,,,",
      ",,,,,%%!,,,,,,,,",
      ",,,%%!,,,,,,,,,,",
      ",%%!,,,,,,,,,,,,",
      "%!,,,,,,,,,,,,,,",
      ",,,,,,,,,,,,,,,,",
      ",,,,,,,,,,,,,,%,",
      ",,,,,,,,,,,,%%!,",
      ",,,,,,,,,,%%!,,,",
      ",,,,,,,,%%!,,,,,"
    ],
    [
      "                ",
      "  $*    $       ",
      "   $+      &    ",
      "    $(          ",
      "     $)    '    ",
      "                ",
      "                ",
      "                ",
      "                ",
      "                ",
      "                ",
      "                ",
      "                ",
      "                ",
      "                ",
      "                "
    ],
    [
      "                ",
      "                ",
      "           &    ",
      "                ",
      "                ",
      "                ",
      "                ",
      "                ",
      "                ",
      "                ",
      "                ",
      "                ",
      "                ",
      "                ",
      "                ",
      "                "
    ],
    [
      "                ",
      "                ",
      "           &    ",
      "                ",
      "                ",
      "                ",
      "                ",
      "                ",
      "                ",
      "                ",
      "                ",
      "                ",
      "                ",
      "                ",
      "                ",
      "                "
    ],
    [
      "                ",
      "                ",
      "           &    ",
      "                ",
      "                ",
      "                ",
      "                ",
      "                ",
      "                ",
      "                ",
      "                ",
      "                ",
      "                ",
      "                ",
      "                ",
      "                "
    ],
    [
      "                ",
      "                ",
      "                ",
      "                ",
      "                ",
      "                ",
      "                ",
      "                ",
      "                ",
      "                ",
      "                ",
      "                ",
      "                ",
      "                ",
      "                ",
      "                "
    ]
  ],
  "palette": {
    "palette": [
      {
        "char": "!",
        "block": "minecraft:coarse_dirt"
      },
      {
        "char": "$",
        "block": "minecraft:dead_bush"
      },
      {
        "char": "%",
        "block": "minecraft:gravel"
      },
      {
        "char": "&",
        "block": "minecraft:stripped_oak_log[axis=y]"
      },
      {
        "char": "'",
        "block": "kubejs:ruined_cauldron"
      },
      {
        "char": "(",
        "block": "minecraft:wheat[age=0]"
      },
      {
        "char": ")",
        "block": "minecraft:wheat[age=2]"
      },
      {
        "char": "*",
        "block": "minecraft:wheat[age=4]"
      },
      {
        "char": "+",
        "block": "minecraft:wheat[age=6]"
      },
      {
        "char": ",",
        "block": "tfmg:asphalt"
      }
    ]
  }
}
