{
  "xsize": 16,
  "zsize": 16,
  "slices": [
    [
      "......''$.......",
      "....''$.........",
      "(('''''''''''''.",
      "(('''''''''''''.",
      "(('''''''''''''.",
      "(('''''''''''''.",
      "$$$$$$$$$$'''''.",
      "$$$$$$$$$$.''''.",
      "$$$$$$$$$$'''''.",
      "$$$$$$$$$$.''''.",
      "$$$$$$$$$$.''''.",
      "$$$$$$$$$$.''''.",
      ".''$............",
      "                ",
      "                ",
      "                "
    ],
    [
      "                ",
      "                ",
      "                ",
      "                ",
      "                ",
      "                ",
      "                ",
      "     &,         ",
      " *    &-   )  ) ",
      " &+    &*  )!!) ",
      "  &,    &  )!!) ",
      "           )  ) ",
      "                ",
      "                ",
      "                ",
      "                "
    ],
    [
      "                ",
      "                ",
      "                ",
      "                ",
      "                ",
      "                ",
      "                ",
      "                ",
      "           )  ) ",
      "           )  ) ",
      "           )  ) ",
      "           )  ) ",
      "                ",
      "                ",
      "                ",
      "                "
    ],
    [
      "                ",
      "                ",
      "                ",
      "                ",
      "                ",
      "                ",
      "                ",
      "                ",
      "           )  ) ",
      "           )  ) ",
      "           )  ) ",
      "           )  ) ",
      "                ",
      "                ",
      "                ",
      "                "
    ],
    [
      "                ",
      "                ",
      "                ",
      "                ",
      "                ",
      "                ",
      "                ",
      "                ",
      "           )  ) ",
      "           )  ) ",
      "           )  ) ",
      "           )  ) ",
      "                ",
      "                ",
      "                ",
      "                "
    ],
    [
      "                ",
      "                ",
      "                ",
      "                ",
      "                ",
      "                ",
      "                ",
      "                ",
      "           %%%% ",
      "           %%%% ",
      "           %%%% ",
      "           %%%% ",
      "                ",
      "                ",
      "                ",
      "                "
    ]
  ],
  "palette": {
    "palette": [
      {
        "char": "!",
        "block": "minecraft:barrel[facing=up,open=false]"
      },
      {
        "char": "$",
        "block": "minecraft:coarse_dirt"
      },
      {
        "char": "%",
        "block": "minecraft:dark_oak_planks"
      },
      {
        "char": "&",
        "block": "minecraft:dead_bush"
      },
      {
        "char": "'",
        "block": "minecraft:gravel"
      },
      {
        "char": "(",
        "block": "minecraft:stone_bricks"
      },
      {
        "char": ")",
        "block": "minecraft:stripped_dark_oak_log[axis=y]"
      },
      {
        "char": "*",
        "block": "minecraft:wheat[age=1]"
      },
      {
        "char": "+",
        "block": "minecraft:wheat[age=3]"
      },
      {
        "char": ",",
        "block": "minecraft:wheat[age=5]"
      },
      {
        "char": "-",
        "block": "minecraft:wheat[age=7]"
      },
      {
        "char": ".",
        "block": "tfmg:asphalt"
      }
    ]
  }
}
