{
  "xsize": 16,
  "zsize": 16,
  "slices": [
    [
      "                ",
      "                ",
      "                ",
      "                ",
      "%%%%%%%%%%%%%%%%",
      "                ",
      "                ",
      "                ",
      "                ",
      "                ",
      "                ",
      "$$$$$$$$$$$$$$$$",
      "                ",
      "                ",
      "                ",
      "                "
    ],
    [
      "                ",
      "                ",
      "                ",
      "                ",
      "                ",
      "%%%%%%%%%%%%%%%%",
      "                ",
      "                ",
      "                ",
      "                ",
      "$$$$$$$$$$$$$$$$",
      "                ",
      "                ",
      "                ",
      "                ",
      "                "
    ],
    [
      "                ",
      "                ",
      "                ",
      "                ",
      "                ",
      "                ",
      "%%%%%%%%%%%%%%%%",
      "!!!!!!!!!!!!!!!!",
      "!!!!!!!!!!!!!!!!",
      "$$$$$$$$$$$$$$$$",
      "                ",
      "                ",
      "                ",
      "                ",
      "                ",
      "                "
    ]
  ],
  "palette": {
    "palette": [
      {
        "char": "!",
        "block": "minecraft:oxidized_copper"
      },
      {
        "char": "$",
        "block": "minecraft:weathered_cut_copper_stairs[facing=north,half=bottom,shape=straight,waterlogged=false]"
      },
      {
        "char": "%",
        "block": "minecraft:weathered_cut_copper_stairs[facing=south,half=bottom,shape=straight,waterlogged=false]"
      }
    ]
  }
}
