{
  "xsize": 16,
  "zsize": 16,
  "slices": [
    [
      "//////%/////////",
      "////////////////",
      "////////////////",
      "//./////////////",
      "///////////////&",
      "/////////////&&%",
      "///////////&&%//",
      "/////////&&%////",
      "//.////&&%//////",
      "//////&%////////",
      "////////////////",
      "////////////////",
      "////////////////",
      "//./////////////",
      "//////////////&&",
      "////////////&&%/"
    ],
    [
      "                ",
      "                ",
      "        ''''''''",
      "        ''''''''",
      "        ''''''''",
      "        ''''''''",
      "        ''''''''",
      "        ''''''''",
      "        ''''''''",
      "        ''''''''",
      "        ''''''''",
      "        ''''''''",
      "        ''''''''",
      "        ''''''''",
      "                ",
      "                "
    ],
    [
      "                ",
      "                ",
      "        00000000",
      "        0       ",
      "        0       ",
      "        0  -  $ ",
      "        0  ,,   ",
      "        (       ",
      "        )       ",
      "        0       ",
      "        0       ",
      "        0       ",
      "        0       ",
      "        00000000",
      "                ",
      "                "
    ],
    [
      "                ",
      "                ",
      "        000!!000",
      "        0       ",
      "        0       ",
      "        0       ",
      "        0       ",
      "        *       ",
      "        +       ",
      "        0       ",
      "        0       ",
      "        0       ",
      "        0       ",
      "        00000000",
      "                ",
      "                "
    ],
    [
      "                ",
      "                ",
      "        000!!000",
      "        0       ",
      "        0       ",
      "        0       ",
      "        0       ",
      "        0       ",
      "        0       ",
      "        0       ",
      "        0       ",
      "        0       ",
      "        0       ",
      "        00000000",
      "                ",
      "                "
    ],
    [
      "                ",
      "                ",
      "        00000000",
      "        0       ",
      "        0       ",
      "        0       ",
      "        0       ",
      "        0       ",
      "        0       ",
      "        0       ",
      "        0       ",
      "        0       ",
      "        0       ",
      "        00000000",
      "                ",
      "                "
    ]
  ],
  "palette": {
    "palette": [
      {
        "char": "!",
        "block": "create:framed_glass"
      },
      {
        "char": "$",
        "block": "minecraft:bell[attachment=floor,facing=north,powered=false]"
      },
      {
        "char": "%",
        "block": "minecraft:coarse_dirt"
      },
      {
        "char": "&",
        "block": "minecraft:gravel"
      },
      {
        "char": "'",
        "block": "minecraft:polished_andesite"
      },
      {
        "char": "(",
        "block": "minecraft:spruce_door[facing=west,half=lower,hinge=left,open=false,powered=false]"
      },
      {
        "char": ")",
        "block": "minecraft:spruce_door[facing=west,half=lower,hinge=right,open=false,powered=false]"
      },
      {
        "char": "*",
        "block": "minecraft:spruce_door[facing=west,half=upper,hinge=left,open=false,powered=false]"
      },
      {
        "char": "+",
        "block": "minecraft:spruce_door[facing=west,half=upper,hinge=right,open=false,powered=false]"
      },
      {
        "char": ",",
        "block": "minecraft:spruce_slab[type=bottom,waterlogged=false]"
      },
      {
        "char": "-",
        "block": "minecraft:spruce_stairs[facing=west,half=bottom,shape=straight,waterlogged=false]"
      },
      {
        "char": ".",
        "block": "minecraft:yellow_concrete"
      },
      {
        "char": "/",
        "block": "tfmg:asphalt"
      },
      {
        "char": "0",
        "block": "tfmg:cinder_block"
      }
    ]
  }
}
