{
  "xsize": 16,
  "zsize": 16,
  "slices": [
    [
      "-------%%!------",
      "-----%%!--------",
      "---%%!----------",
      "-%%!------------",
      "%!--------------",
      "----------------",
      "&&%%%%%%%%%%%%%-",
      "&&%%%%%%%%%%%%%-",
      "&&%%%%%%%%%%%%%-",
      "&&%%%%%%%%%%%%%-",
      "!!!!!!!!!!%%%%%-",
      "!!!!!!!!!!------",
      "!!!!!!!!!!------",
      "!!!!!!!!!!------",
      "!!!!!!!!!!------",
      "!!!!!!!!!!------"
    ],
    [
      "                ",
      "                ",
      "                ",
      "                ",
      "                ",
      "                ",
      "                ",
      "                ",
      "                ",
      "                ",
      "    $    $      ",
      "    $$)  $      ",
      " +  $ $* $ '    ",
      " $, $  $+$      ",
      "  $)$   $$ (    ",
      "    $    $      "
    ],
    [
      "                ",
      "                ",
      "                ",
      "                ",
      "                ",
      "                ",
      "                ",
      "                ",
      "                ",
      "                ",
      "                ",
      "                ",
      "           '    ",
      "                ",
      "                ",
      "                "
    ],
    [
      "                ",
      "                ",
      "                ",
      "                ",
      "                ",
      "                ",
      "                ",
      "                ",
      "                ",
      "                ",
      "                ",
      "                ",
      "           '    ",
      "                ",
      "                ",
      "                "
    ],
    [
      "                ",
      "                ",
      "                ",
      "                ",
      "                ",
      "                ",
      "                ",
      "                ",
      "                ",
      "                ",
      "                ",
      "                ",
      "           '    ",
      "                ",
      "                ",
      "                "
    ],
    [
      "                ",
      "                ",
      "                ",
      "                ",
      "                ",
      "                ",
      "                ",
      "                ",
      "                ",
      "                ",
      "                ",
      "                ",
      "                ",
      "                ",
      "                ",
      "                "
    ]
  ],
  "palette": {
    "palette": [
      {
        "char": "!",
        "block": "minecraft:coarse_dirt"
      },
      {
        "char": "$",
        "block": "minecraft:dead_bush"
      },
      {
        "char": "%",
        "block": "minecraft:gravel"
      },
      {
        "char": "&",
        "block": "minecraft:stone_bricks"
      },
      {
        "char": "'",
        "block": "minecraft:stripped_oak_log[axis=y]"
      },
      {
        "char": "(",
        "block": "kubejs:ruined_cauldron"
      },
      {
        "char": ")",
        "block": "minecraft:wheat[age=1]"
      },
      {
        "char": "*",
        "block": "minecraft:wheat[age=3]"
      },
      {
        "char": "+",
        "block": "minecraft:wheat[age=5]"
      },
      {
        "char": ",",
        "block": "minecraft:wheat[age=7]"
      },
      {
        "char": "-",
        "block": "tfmg:asphalt"
      }
    ]
  }
}
