{
  "xsize": 16,
  "zsize": 16,
  "slices": [
    [
      ":::,,(::::::::::",
      ":,,(::::::::::::",
      ",(:::::::::::,,7",
      ":::::::::::::,,7",
      ":::::::::::::,,7",
      "::::::::::::,,,7",
      "::::::::::,,(,,,",
      "::::::::,,(:::::",
      "::::::,,(:::::::",
      "::::,,(:::::::::",
      "::,,(:::::::::::",
      ",,(:::::::::::::",
      "(:::::::::::::::",
      "                ",
      "                ",
      "                "
    ],
    [
      "    5-------5   ",
      "    5&-----&5   ",
      "    5-------5   ",
      "    5-------5   ",
      "    5-------58  ",
      "    5-------5   ",
      "    5-------5   ",
      "    5-------5   ",
      "    5&-----&5   ",
      "    555555555   ",
      "    555555555   ",
      "    555555555   ",
      "    555555555   ",
      "                ",
      "                ",
      "                "
    ],
    [
      "    0     6 0   ",
      "    $ +*%   0   ",
      "    000000300   ",
      "    0   0   0   ",
      "    0 9 0   1   ",
      "    0   1 < 0   ",
      "    0 ) 0   0   ",
      "    ;00000300   ",
      "    0       0   ",
      "    0 .  %  0   ",
      "    0 /     0   ",
      "    0     ' 0   ",
      "    000000000   ",
      "                ",
      "                ",
      "                "
    ],
    [
      "    !       0   ",
      "    0       0   ",
      "    000000400   ",
      "    0   0   0   ",
      "    0   0   2   ",
      "    0   2   0   ",
      "    0   0   0   ",
      "    000000400   ",
      "    0       0   ",
      "    !       0   ",
      "    !       0   ",
      "    0       0   ",
      "    00!!00000   ",
      "                ",
      "                ",
      "                "
    ],
    [
      "    !       0   ",
      "    0       0   ",
      "    000000000   ",
      "    0   0   0   ",
      "    0   0   0   ",
      "    0   0   0   ",
      "    0   0   0   ",
      "    000000000   ",
      "    0       0   ",
      "    !       0   ",
      "    !       0   ",
      "    0       0   ",
      "    00!!00000   ",
      "                ",
      "                ",
      "                "
    ],
    [
      "    0       0   ",
      "    0       0   ",
      "    000000000   ",
      "    0   0   0   ",
      "    0   0   0   ",
      "    0   0   0   ",
      "    0   0   0   ",
      "    000000000   ",
      "    0       0   ",
      "    0       0   ",
      "    0       0   ",
      "    0       0   ",
      "    000000000   ",
      "                ",
      "                ",
      "                "
    ]
  ],
  "palette": {
    "palette": [
      {
        "char": "!",
        "block": "create:framed_glass"
      },
      {
        "char": "$",
        "block": "immersiveengineering:connector_lv[facing=east]"
      },
      {
        "char": "%",
        "block": "minecraft:barrel[facing=up,open=false]"
      },
      {
        "char": "&",
        "block": "minecraft:black_concrete"
      },
      {
        "char": "'",
        "block": "minecraft:chest[facing=north,type=single,waterlogged=false]",
        "tag": {
          "id": "minecraft:chest",
          "LootTable": "infinite_domain:chests/wasteland_home"
        }
      },
      {
        "char": "(",
        "block": "minecraft:coarse_dirt"
      },
      {
        "char": ")",
        "block": "minecraft:composter[level=2]"
      },
      {
        "char": "*",
        "block": "minecraft:crafting_table"
      },
      {
        "char": "+",
        "block": "minecraft:furnace[facing=north,lit=false]"
      },
      {
        "char": ",",
        "block": "minecraft:gravel"
      },
      {
        "char": "-",
        "block": "minecraft:gray_concrete"
      },
      {
        "char": ".",
        "block": "minecraft:green_bed[facing=south,occupied=false,part=foot]"
      },
      {
        "char": "/",
        "block": "minecraft:green_bed[facing=south,occupied=false,part=head]"
      },
      {
        "char": "0",
        "block": "minecraft:lime_terracotta"
      },
      {
        "char": "1",
        "block": "minecraft:spruce_door[facing=east,half=lower,hinge=left,open=false,powered=false]"
      },
      {
        "char": "2",
        "block": "minecraft:spruce_door[facing=east,half=upper,hinge=left,open=false,powered=false]"
      },
      {
        "char": "3",
        "block": "minecraft:spruce_door[facing=south,half=lower,hinge=left,open=false,powered=false]"
      },
      {
        "char": "4",
        "block": "minecraft:spruce_door[facing=south,half=upper,hinge=left,open=false,powered=false]"
      },
      {
        "char": "5",
        "block": "minecraft:spruce_planks"
      },
      {
        "char": "6",
        "block": "minecraft:spruce_slab[type=bottom,waterlogged=false]"
      },
      {
        "char": "7",
        "block": "minecraft:stone_bricks"
      },
      {
        "char": "8",
        "block": "minecraft:stone_slab[type=bottom,waterlogged=false]"
      },
      {
        "char": "9",
        "block": "minecraft:water_cauldron[level=3]"
      },
      {
        "char": ":",
        "block": "tfmg:asphalt"
      },
      {
        "char": ";",
        "block": "tfmg:steel_pipe"
      },
      {
        "char": "<",
        "block": "the_wasteland_reworked:cardboard_box"
      }
    ]
  }
}
