{
  "xsize": 16,
  "zsize": 16,
  "slices": [
    [
      "0((&000000000000",
      "(&00000000000000",
      "0000000000000000",
      "00000000000000(0",
      "000000000000((&0",
      "0000000000((&000",
      "00000000((&00000",
      "000000((&0000000",
      "0000((&000000000",
      "00((&00000000000",
      "((&0000000000000",
      "&000000000000000",
      "0000000000000000",
      "0000000000000((0",
      "00000000000((&00",
      "000000000((&0000"
    ],
    [
      "                ",
      "                ",
      "///////////     ",
      "///////////     ",
      "///((((////     ",
      "///((((////     ",
      "///((((////     ",
      "///////////     ",
      "///////////     ",
      "///////////     ",
      "///////////     ",
      "///////////     ",
      "///////////     ",
      "///////////     ",
      "                ",
      "                "
    ],
    [
      "                ",
      "                ",
      ")))))))))))     ",
      "          )     ",
      "   ((((   )     ",
      "  '((((   )     ",
      "   ((((   )     ",
      "          +     ",
      "          ,     ",
      "  *       )     ",
      "  $    %  )     ",
      "          )     ",
      "          )     ",
      ")))))))))))     ",
      "                ",
      "                "
    ],
    [
      "                ",
      "                ",
      "))!!)))))))     ",
      "          )     ",
      "          )     ",
      "          )     ",
      "          )     ",
      "          -     ",
      "          .     ",
      "          )     ",
      "          )     ",
      "          )     ",
      "          )     ",
      ")))))))))))     ",
      "                ",
      "                "
    ],
    [
      "                ",
      "                ",
      "))!!)))))))     ",
      "          )     ",
      "          )     ",
      "          )     ",
      "          )     ",
      "          )     ",
      "          )     ",
      "          )     ",
      "          )     ",
      "          )     ",
      "          )     ",
      ")))))))))))     ",
      "                ",
      "                "
    ],
    [
      "                ",
      "                ",
      ")))))))))))     ",
      "          )     ",
      "          )     ",
      "          )     ",
      "          )     ",
      "          )     ",
      "          )     ",
      "          )     ",
      "          )     ",
      "          )     ",
      "          )     ",
      ")))))))))))     ",
      "                ",
      "                "
    ]
  ],
  "palette": {
    "palette": [
      {
        "char": "!",
        "block": "create:framed_glass"
      },
      {
        "char": "$",
        "block": "immersiveengineering:metal_barrel"
      },
      {
        "char": "%",
        "block": "minecraft:chest[facing=west,type=single,waterlogged=false]",
        "tag": {
          "id": "minecraft:chest",
          "LootTable": "infinite_domain:chests/wasteland_industrial"
        }
      },
      {
        "char": "&",
        "block": "minecraft:coarse_dirt"
      },
      {
        "char": "'",
        "block": "kubejs:ruined_crafting_table"
      },
      {
        "char": "(",
        "block": "minecraft:gravel"
      },
      {
        "char": ")",
        "block": "minecraft:mud_bricks"
      },
      {
        "char": "*",
        "block": "minecraft:spawner",
        "tag": {
          "id": "minecraft:mob_spawner",
          "Delay": 200,
          "MinSpawnDelay": 240,
          "MaxSpawnDelay": 720,
          "SpawnCount": 2,
          "MaxNearbyEntities": 6,
          "RequiredPlayerRange": 14,
          "SpawnRange": 4,
          "SpawnData": {
            "entity": {
              "id": "the_wasteland_reworked:ghoul"
            }
          },
          "SpawnPotentials": [
            {
              "weight": 1,
              "data": {
                "entity": {
                  "id": "the_wasteland_reworked:ghoul"
                }
              }
            }
          ]
        }
      },
      {
        "char": "+",
        "block": "minecraft:spruce_door[facing=east,half=lower,hinge=left,open=false,powered=false]"
      },
      {
        "char": ",",
        "block": "minecraft:spruce_door[facing=east,half=lower,hinge=right,open=false,powered=false]"
      },
      {
        "char": "-",
        "block": "minecraft:spruce_door[facing=east,half=upper,hinge=left,open=false,powered=false]"
      },
      {
        "char": ".",
        "block": "minecraft:spruce_door[facing=east,half=upper,hinge=right,open=false,powered=false]"
      },
      {
        "char": "/",
        "block": "minecraft:stone_bricks"
      },
      {
        "char": "0",
        "block": "tfmg:asphalt"
      }
    ]
  }
}
