{
  "xsize": 16,
  "zsize": 16,
  "slices": [
    [
      ",,,,,,,,,''%,,,,",
      ",,,,,,,''%,,,,,,",
      ",,,,,,''''''''''",
      ",,,,,,''''''''''",
      ",,+,,,''''''''''",
      ",,,,,,''''''''''",
      ",,,,,,'''''%%%%%",
      ",,,,,,'''''%%%%%",
      ",,,,,,'''''%%%%%",
      ",,+,,,'''''%%%%%",
      ",,,,,,'''''%%%%%",
      ",,,,,,'''''%%%%%",
      ",,,,''%,,,,,,,,,",
      "                ",
      "                ",
      "                "
    ],
    [
      "                ",
      "                ",
      "                ",
      "                ",
      "        -       ",
      "                ",
      "                ",
      "             &) ",
      "       $$$    &*",
      "       $$$     &",
      "       $$$      ",
      "                ",
      "                ",
      "                ",
      "                ",
      "                "
    ],
    [
      "                ",
      "                ",
      "                ",
      "                ",
      "                ",
      "                ",
      "                ",
      "                ",
      "       $$$      ",
      "       $$$      ",
      "       $$$      ",
      "                ",
      "                ",
      "                ",
      "                ",
      "                "
    ],
    [
      "                ",
      "                ",
      "                ",
      "                ",
      "                ",
      "                ",
      "                ",
      "                ",
      "       $$$      ",
      "       $$$      ",
      "       $$$      ",
      "                ",
      "                ",
      "                ",
      "                ",
      "                "
    ],
    [
      "                ",
      "                ",
      "                ",
      "                ",
      "                ",
      "                ",
      "                ",
      "                ",
      "         (      ",
      "        !       ",
      "                ",
      "                ",
      "                ",
      "                ",
      "                ",
      "                "
    ],
    [
      "                ",
      "                ",
      "                ",
      "                ",
      "                ",
      "                ",
      "                ",
      "                ",
      "                ",
      "                ",
      "                ",
      "                ",
      "                ",
      "                ",
      "                ",
      "                "
    ]
  ],
  "palette": {
    "palette": [
      {
        "char": "!",
        "block": "immersiveengineering:connector_lv[facing=up]"
      },
      {
        "char": "$",
        "block": "immersiveengineering:sheetmetal_steel"
      },
      {
        "char": "%",
        "block": "minecraft:coarse_dirt"
      },
      {
        "char": "&",
        "block": "minecraft:dead_bush"
      },
      {
        "char": "'",
        "block": "minecraft:gravel"
      },
      {
        "char": "(",
        "block": "minecraft:stripped_oak_log[axis=y]"
      },
      {
        "char": ")",
        "block": "minecraft:wheat[age=5]"
      },
      {
        "char": "*",
        "block": "minecraft:wheat[age=7]"
      },
      {
        "char": "+",
        "block": "minecraft:yellow_concrete"
      },
      {
        "char": ",",
        "block": "tfmg:asphalt"
      },
      {
        "char": "-",
        "block": "wastelands:scrap_pile"
      }
    ]
  }
}
