{
  "xsize": 16,
  "zsize": 16,
  "slices": [
    [
      "9999999999++(999",
      "99999999++(99999",
      "999999++(9999999",
      "9999++(999999999",
      "99++(99999999999",
      "++(9999999999999",
      "(999999999999999",
      "999999999999999+",
      "9999999999999++(",
      "99999999999++(99",
      "999999999++(9999",
      "9999999++(999999",
      "99999++(99999++5",
      "999++(9999999++5",
      "9++(999999999++5",
      "+(99999999999++5"
    ],
    [
      "    222222222   ",
      "                ",
      "                ",
      "                ",
      "                ",
      "                ",
      "    222222222   ",
      "    222222222   ",
      "    222222222   ",
      "    222222222   ",
      "    2,,,,,,,2   ",
      "    2&,,,,,&2   ",
      "    2,,,,,,,2   ",
      "    2,,,,,,,2   ",
      "    2,,,,,,,26  ",
      "    2,,,,,,,2   "
    ],
    [
      "    ---------   ",
      "                ",
      "                ",
      "                ",
      "                ",
      "                ",
      "    888888888   ",
      "    8       8   ",
      "    8 44  ' 8   ",
      "    8       8   ",
      "    8     3 8   ",
      "    $ *)%   8   ",
      "    888888088   ",
      "    8   8   8   ",
      "    8 7 8   .   ",
      "    8   . : 8   "
    ],
    [
      "    --!!-----   ",
      "                ",
      "                ",
      "                ",
      "                ",
      "                ",
      "    88!!88888   ",
      "    8       8   ",
      "    8       8   ",
      "    !       8   ",
      "    !       8   ",
      "    8       8   ",
      "    888888188   ",
      "    8   8   8   ",
      "    8   8   /   ",
      "    8   /   8   "
    ],
    [
      "    --!!-----   ",
      "                ",
      "                ",
      "                ",
      "                ",
      "                ",
      "    88!!88888   ",
      "    8       8   ",
      "    8       8   ",
      "    !       8   ",
      "    !       8   ",
      "    8       8   ",
      "    888888888   ",
      "    8   8   8   ",
      "    8   8   8   ",
      "    8   8   8   "
    ],
    [
      "    ---------   ",
      "                ",
      "                ",
      "                ",
      "                ",
      "                ",
      "    888888888   ",
      "    8       8   ",
      "    8       8   ",
      "    8       8   ",
      "    8       8   ",
      "    8       8   ",
      "    888888888   ",
      "    8   8   8   ",
      "    8   8   8   ",
      "    8   8   8   "
    ]
  ],
  "palette": {
    "palette": [
      {
        "char": "!",
        "block": "create:framed_glass"
      },
      {
        "char": "$",
        "block": "immersiveengineering:connector_lv[facing=east]"
      },
      {
        "char": "%",
        "block": "minecraft:barrel[facing=up,open=false]"
      },
      {
        "char": "&",
        "block": "minecraft:black_concrete"
      },
      {
        "char": "'",
        "block": "minecraft:bookshelf"
      },
      {
        "char": "(",
        "block": "minecraft:coarse_dirt"
      },
      {
        "char": ")",
        "block": "minecraft:crafting_table"
      },
      {
        "char": "*",
        "block": "minecraft:furnace[facing=north,lit=false]"
      },
      {
        "char": "+",
        "block": "minecraft:gravel"
      },
      {
        "char": ",",
        "block": "minecraft:gray_concrete"
      },
      {
        "char": "-",
        "block": "minecraft:light_blue_terracotta"
      },
      {
        "char": ".",
        "block": "minecraft:spruce_door[facing=east,half=lower,hinge=left,open=false,powered=false]"
      },
      {
        "char": "/",
        "block": "minecraft:spruce_door[facing=east,half=upper,hinge=left,open=false,powered=false]"
      },
      {
        "char": "0",
        "block": "minecraft:spruce_door[facing=south,half=lower,hinge=left,open=false,powered=false]"
      },
      {
        "char": "1",
        "block": "minecraft:spruce_door[facing=south,half=upper,hinge=left,open=false,powered=false]"
      },
      {
        "char": "2",
        "block": "minecraft:spruce_planks"
      },
      {
        "char": "3",
        "block": "minecraft:spruce_slab[type=bottom,waterlogged=false]"
      },
      {
        "char": "4",
        "block": "minecraft:spruce_stairs[facing=south,half=bottom,shape=straight,waterlogged=false]"
      },
      {
        "char": "5",
        "block": "minecraft:stone_bricks"
      },
      {
        "char": "6",
        "block": "minecraft:stone_slab[type=bottom,waterlogged=false]"
      },
      {
        "char": "7",
        "block": "minecraft:water_cauldron[level=3]"
      },
      {
        "char": "8",
        "block": "minecraft:yellow_terracotta"
      },
      {
        "char": "9",
        "block": "tfmg:asphalt"
      },
      {
        "char": ":",
        "block": "the_wasteland_reworked:cardboard_box"
      }
    ]
  }
}
