{
  "xsize": 16,
  "zsize": 16,
  "slices": [
    [
      "@@@@@@@@@@@@@--(",
      "@@@@@@@@@@@--(@@",
      "@@@@@@@@@--(@@@@",
      "@@@@@@@--(@@@@@@",
      "@@@@@--(@@@@@@@@",
      "@@@--(@@@@@@@@@@",
      "---888--@@@@@@@@",
      "---888--@@@@@@@@",
      "---888--@@@@@@@@",
      "---888--@@@@@@--",
      "(((((---@@@@--(@",
      "(((((@@@@@--(@@@",
      "(((((@@@--(@@@@@",
      "(((((@--(@@@@@@@",
      "(((((-(@@@@@@@@@",
      "(((((@@@@@@@@@@@"
    ],
    [
      "        55555555",
      "        55555555",
      "        55555555",
      "        55555555",
      "        5.......",
      "        5%.....%",
      "        5.......",
      "        5.......",
      "       95.......",
      "        5.......",
      "        5.......",
      "   +    5.......",
      "        5%.....%",
      ";       55555555",
      "+<      55555555",
      "        55555555"
    ],
    [
      "        ????????",
      "        ?       ",
      "        ? 77  & ",
      "        ?       ",
      "        ?     6 ",
      "        ? ,*$   ",
      "        ??????1?",
      "        ?   ?   ",
      "        3 : ?   ",
      "        ?   / A ",
      "        ? ) ?   ",
      "        ??????1?",
      "        ?       ",
      "        ? =  $  ",
      "        ? >     ",
      "        ?     ' "
    ],
    [
      "        ??!!????",
      "        ?       ",
      "        ?       ",
      "        ?       ",
      "        ?       ",
      "        ?       ",
      "        ??????2?",
      "        ?   ?   ",
      "        4   ?   ",
      "        ?   0   ",
      "        ?   ?   ",
      "        ??????2?",
      "        ?       ",
      "        ?       ",
      "        ?       ",
      "        ?       "
    ],
    [
      "        ??!!????",
      "        ?       ",
      "        ?       ",
      "        ?       ",
      "        ?       ",
      "        ?       ",
      "        ????????",
      "        ?   ?   ",
      "        ?   ?   ",
      "        ?   ?   ",
      "        ?   ?   ",
      "        ????????",
      "        ?       ",
      "        ?       ",
      "        ?       ",
      "        ?       "
    ],
    [
      "        ????????",
      "        ?       ",
      "        ?       ",
      "        ?       ",
      "        ?       ",
      "        ?       ",
      "        ????????",
      "        ?   ?   ",
      "        ?   ?   ",
      "        ?   ?   ",
      "        ?   ?   ",
      "        ????????",
      "        ?       ",
      "        ?       ",
      "        ?       ",
      "        ?       "
    ]
  ],
  "palette": {
    "palette": [
      {
        "char": "!",
        "block": "create:framed_glass"
      },
      {
        "char": "$",
        "block": "minecraft:barrel[facing=up,open=false]"
      },
      {
        "char": "%",
        "block": "minecraft:black_concrete"
      },
      {
        "char": "&",
        "block": "minecraft:bookshelf"
      },
      {
        "char": "'",
        "block": "minecraft:chest[facing=north,type=single,waterlogged=false]",
        "tag": {
          "id": "minecraft:chest",
          "LootTable": "infinite_domain:chests/wasteland_home"
        }
      },
      {
        "char": "(",
        "block": "minecraft:coarse_dirt"
      },
      {
        "char": ")",
        "block": "minecraft:composter[level=2]"
      },
      {
        "char": "*",
        "block": "minecraft:crafting_table"
      },
      {
        "char": "+",
        "block": "minecraft:dead_bush"
      },
      {
        "char": ",",
        "block": "minecraft:furnace[facing=north,lit=false]"
      },
      {
        "char": "-",
        "block": "minecraft:gravel"
      },
      {
        "char": ".",
        "block": "minecraft:gray_concrete"
      },
      {
        "char": "/",
        "block": "minecraft:spruce_door[facing=east,half=lower,hinge=left,open=false,powered=false]"
      },
      {
        "char": "0",
        "block": "minecraft:spruce_door[facing=east,half=upper,hinge=left,open=false,powered=false]"
      },
      {
        "char": "1",
        "block": "minecraft:spruce_door[facing=south,half=lower,hinge=left,open=false,powered=false]"
      },
      {
        "char": "2",
        "block": "minecraft:spruce_door[facing=south,half=upper,hinge=left,open=false,powered=false]"
      },
      {
        "char": "3",
        "block": "minecraft:spruce_door[facing=west,half=lower,hinge=left,open=false,powered=false]"
      },
      {
        "char": "4",
        "block": "minecraft:spruce_door[facing=west,half=upper,hinge=left,open=false,powered=false]"
      },
      {
        "char": "5",
        "block": "minecraft:spruce_planks"
      },
      {
        "char": "6",
        "block": "minecraft:spruce_slab[type=bottom,waterlogged=false]"
      },
      {
        "char": "7",
        "block": "minecraft:spruce_stairs[facing=south,half=bottom,shape=straight,waterlogged=false]"
      },
      {
        "char": "8",
        "block": "minecraft:stone_bricks"
      },
      {
        "char": "9",
        "block": "minecraft:stone_slab[type=bottom,waterlogged=false]"
      },
      {
        "char": ":",
        "block": "minecraft:water_cauldron[level=3]"
      },
      {
        "char": ";",
        "block": "minecraft:wheat[age=5]"
      },
      {
        "char": "<",
        "block": "minecraft:wheat[age=7]"
      },
      {
        "char": "=",
        "block": "minecraft:white_bed[facing=south,occupied=false,part=foot]"
      },
      {
        "char": ">",
        "block": "minecraft:white_bed[facing=south,occupied=false,part=head]"
      },
      {
        "char": "?",
        "block": "minecraft:white_terracotta"
      },
      {
        "char": "@",
        "block": "tfmg:asphalt"
      },
      {
        "char": "A",
        "block": "the_wasteland_reworked:cardboard_box"
      }
    ]
  }
}
