{
  "xsize": 16,
  "zsize": 16,
  "slices": [
    [
      "1111111(('111111",
      "11111(('11111111",
      "111(('1111111111",
      "1(('111111111111",
      "('11111111111111",
      "1111111111111111",
      "11111111111111((",
      "111111111111(('1",
      "1111111111(('111",
      "11111111(('11111",
      "111111(('1111111",
      "1111(('111111111",
      "11(('11111111111",
      "(('1111111111111",
      "'111111111111111",
      "111111111111111("
    ],
    [
      "                ",
      "                ",
      "))))))))))))))))",
      "))))))))))))))))",
      "))))))))))))))))",
      "))))))))))))))))",
      "))))))))))))))))",
      "))))))))))))))))",
      "))))))))))))))))",
      "))))))))))))))))",
      "))))))))))))))))",
      "))))))))))))))))",
      "))))))))))))))))",
      "))))))))))))))))",
      "                ",
      "                "
    ],
    [
      "                ",
      "                ",
      "2222222222222222",
      " 2      2       ",
      " 2      2 $$$$  ",
      " 2 ..   2 $$$$  ",
      " 2 /    2    &  ",
      " *      *       ",
      " 2      2222,222",
      " 2      2       ",
      " 2   3  2  0  % ",
      " 2      2       ",
      " 2      2       ",
      "22222222,2222222",
      "                ",
      "                "
    ],
    [
      "                ",
      "                ",
      "222!!2222222!!22",
      " 2      2       ",
      " 2      2 $$$$  ",
      " 2      2 $$$$  ",
      " 2      2       ",
      " +      +       ",
      " 2      2222-222",
      " 2      2       ",
      " 2      2       ",
      " 2      2       ",
      " 2      2       ",
      "22222222-2222222",
      "                ",
      "                "
    ],
    [
      "                ",
      "                ",
      "222!!2222222!!22",
      " 2      2       ",
      " 2      2       ",
      " 2      2       ",
      " 2      2       ",
      " 2      2       ",
      " 2      22222222",
      " 2      2       ",
      " 2      2       ",
      " 2      2       ",
      " 2      2       ",
      "2222222222222222",
      "                ",
      "                "
    ],
    [
      "                ",
      "                ",
      "2222222222222222",
      " 2      2       ",
      " 2      2       ",
      " 2      2       ",
      " 2      2       ",
      " 2      2       ",
      " 2      22222222",
      " 2      2       ",
      " 2      2       ",
      " 2      2       ",
      " 2      2       ",
      "2222222222222222",
      "                ",
      "                "
    ]
  ],
  "palette": {
    "palette": [
      {
        "char": "!",
        "block": "create:framed_glass"
      },
      {
        "char": "$",
        "block": "immersiveengineering:crate"
      },
      {
        "char": "%",
        "block": "minecraft:barrel[facing=up,open=false]"
      },
      {
        "char": "&",
        "block": "minecraft:chest[facing=west,type=single,waterlogged=false]",
        "tag": {
          "id": "minecraft:chest",
          "LootTable": "infinite_domain:chests/wasteland_office"
        }
      },
      {
        "char": "'",
        "block": "minecraft:coarse_dirt"
      },
      {
        "char": "(",
        "block": "minecraft:gravel"
      },
      {
        "char": ")",
        "block": "minecraft:polished_andesite"
      },
      {
        "char": "*",
        "block": "minecraft:spruce_door[facing=east,half=lower,hinge=left,open=false,powered=false]"
      },
      {
        "char": "+",
        "block": "minecraft:spruce_door[facing=east,half=upper,hinge=left,open=false,powered=false]"
      },
      {
        "char": ",",
        "block": "minecraft:spruce_door[facing=south,half=lower,hinge=left,open=false,powered=false]"
      },
      {
        "char": "-",
        "block": "minecraft:spruce_door[facing=south,half=upper,hinge=left,open=false,powered=false]"
      },
      {
        "char": ".",
        "block": "minecraft:spruce_slab[type=bottom,waterlogged=false]"
      },
      {
        "char": "/",
        "block": "minecraft:spruce_stairs[facing=north,half=bottom,shape=straight,waterlogged=false]"
      },
      {
        "char": "0",
        "block": "minecraft:water_cauldron[level=3]"
      },
      {
        "char": "1",
        "block": "tfmg:asphalt"
      },
      {
        "char": "2",
        "block": "tfmg:cinder_block"
      },
      {
        "char": "3",
        "block": "the_wasteland_reworked:radio"
      }
    ]
  }
}
