{
  "xsize": 16,
  "zsize": 16,
  "slices": [
    [
      ">>>>>>>>>>>>,,'>",
      ">>>>>>>>>>,,'>>>",
      ",,,999,,,,'>>>>>",
      ",,,999,,'>>>>>>>",
      ",,,999,,>>>>>>>>",
      ",,,999,,>>>>>>>>",
      "''''',,,>>>>>>>>",
      "'''''>>>>>>>>>>>",
      "'''''>>>>>>>>>>,",
      "'''''>>>>>>>>,,'",
      "'''''>>>>>>,,'>>",
      "'''''>>>>,,'>>>>",
      ">>>>>>>,,'>>>>>>",
      "                ",
      "                ",
      "                "
    ],
    [
      "        7-------",
      "        7%-----%",
      "        7-------",
      "        7-------",
      "       :7-------",
      "        7-------",
      "        7-------",
      "   *    7-------",
      "        7%-----%",
      "<       77777777",
      "*=      77777777",
      "        77777777",
      "        77777777",
      "                ",
      "                ",
      "                "
    ],
    [
      "        0     8 ",
      "        0 +)$   ",
      "        00000030",
      "        0   0   ",
      "        5 ; 0   ",
      "        0   1 ? ",
      "        0 ( 0   ",
      "        00000030",
      "        0       ",
      "        0 .  $  ",
      "        0 /     ",
      "        0     & ",
      "        00000000",
      "                ",
      "                ",
      "                "
    ],
    [
      "        0       ",
      "        0       ",
      "        00000040",
      "        0   0   ",
      "        6   0   ",
      "        0   2   ",
      "        0   0   ",
      "        00000040",
      "        0       ",
      "        0       ",
      "        0       ",
      "        0       ",
      "        00!!0000",
      "                ",
      "                ",
      "                "
    ],
    [
      "        0       ",
      "        0       ",
      "        00000000",
      "        0   0   ",
      "        0   0   ",
      "        0   0   ",
      "        0   0   ",
      "        00000000",
      "        0       ",
      "        0       ",
      "        0       ",
      "        0       ",
      "        00!!0000",
      "                ",
      "                ",
      "                "
    ],
    [
      "        0       ",
      "        0       ",
      "        00000000",
      "        0   0   ",
      "        0   0   ",
      "        0   0   ",
      "        0   0   ",
      "        00000000",
      "        0       ",
      "        0       ",
      "        0       ",
      "        0       ",
      "        00000000",
      "                ",
      "                ",
      "                "
    ]
  ],
  "palette": {
    "palette": [
      {
        "char": "!",
        "block": "create:framed_glass"
      },
      {
        "char": "$",
        "block": "minecraft:barrel[facing=up,open=false]"
      },
      {
        "char": "%",
        "block": "minecraft:black_concrete"
      },
      {
        "char": "&",
        "block": "minecraft:chest[facing=north,type=single,waterlogged=false]",
        "tag": {
          "id": "minecraft:chest",
          "LootTable": "infinite_domain:chests/wasteland_home"
        }
      },
      {
        "char": "'",
        "block": "minecraft:coarse_dirt"
      },
      {
        "char": "(",
        "block": "minecraft:composter[level=2]"
      },
      {
        "char": ")",
        "block": "minecraft:crafting_table"
      },
      {
        "char": "*",
        "block": "minecraft:dead_bush"
      },
      {
        "char": "+",
        "block": "minecraft:furnace[facing=north,lit=false]"
      },
      {
        "char": ",",
        "block": "minecraft:gravel"
      },
      {
        "char": "-",
        "block": "minecraft:gray_concrete"
      },
      {
        "char": ".",
        "block": "minecraft:pink_bed[facing=south,occupied=false,part=foot]"
      },
      {
        "char": "/",
        "block": "minecraft:pink_bed[facing=south,occupied=false,part=head]"
      },
      {
        "char": "0",
        "block": "minecraft:pink_terracotta"
      },
      {
        "char": "1",
        "block": "minecraft:spruce_door[facing=east,half=lower,hinge=left,open=false,powered=false]"
      },
      {
        "char": "2",
        "block": "minecraft:spruce_door[facing=east,half=upper,hinge=left,open=false,powered=false]"
      },
      {
        "char": "3",
        "block": "minecraft:spruce_door[facing=south,half=lower,hinge=left,open=false,powered=false]"
      },
      {
        "char": "4",
        "block": "minecraft:spruce_door[facing=south,half=upper,hinge=left,open=false,powered=false]"
      },
      {
        "char": "5",
        "block": "minecraft:spruce_door[facing=west,half=lower,hinge=left,open=false,powered=false]"
      },
      {
        "char": "6",
        "block": "minecraft:spruce_door[facing=west,half=upper,hinge=left,open=false,powered=false]"
      },
      {
        "char": "7",
        "block": "minecraft:spruce_planks"
      },
      {
        "char": "8",
        "block": "minecraft:spruce_slab[type=bottom,waterlogged=false]"
      },
      {
        "char": "9",
        "block": "minecraft:stone_bricks"
      },
      {
        "char": ":",
        "block": "minecraft:stone_slab[type=bottom,waterlogged=false]"
      },
      {
        "char": ";",
        "block": "minecraft:water_cauldron[level=3]"
      },
      {
        "char": "<",
        "block": "minecraft:wheat[age=1]"
      },
      {
        "char": "=",
        "block": "minecraft:wheat[age=3]"
      },
      {
        "char": ">",
        "block": "tfmg:asphalt"
      },
      {
        "char": "?",
        "block": "the_wasteland_reworked:cardboard_box"
      }
    ]
  }
}
