{
  "xsize": 16,
  "zsize": 16,
  "slices": [
    [
      "1((&111111111111",
      "(&11111111111111",
      "1111111111111111",
      "11111111111111(1",
      "111111111111((&1",
      "1111111111((&111",
      "11111111((&11111",
      "111111((&1111111",
      "1111((&111111111",
      "11((&11111111111",
      "((&1111111111111",
      "&111111111111111",
      "1111111111111111",
      "1111111111111((1",
      "11111111111((&11",
      "111111111((&1111"
    ],
    [
      "                ",
      "                ",
      "00000000000     ",
      "00000000000     ",
      "00000000000     ",
      "00000000000     ",
      "00000000000     ",
      "00000000000     ",
      "00000000000     ",
      "00000000000     ",
      "00000000000     ",
      "00000000000     ",
      "00000000000     ",
      "00000000000     ",
      "                ",
      "                "
    ],
    [
      "                ",
      "                ",
      "***********     ",
      "          *     ",
      "          *     ",
      "  ' + )   *     ",
      "          *     ",
      "          ,     ",
      "          -     ",
      "          *     ",
      "  $    %  *     ",
      "          *     ",
      "          *     ",
      "***********     ",
      "                ",
      "                "
    ],
    [
      "                ",
      "                ",
      "**!!*******     ",
      "          *     ",
      "          *     ",
      "          *     ",
      "          *     ",
      "          .     ",
      "          /     ",
      "          *     ",
      "          *     ",
      "          *     ",
      "          *     ",
      "***********     ",
      "                ",
      "                "
    ],
    [
      "                ",
      "                ",
      "**!!*******     ",
      "          *     ",
      "          *     ",
      "          *     ",
      "          *     ",
      "          *     ",
      "          *     ",
      "          *     ",
      "          *     ",
      "          *     ",
      "          *     ",
      "***********     ",
      "                ",
      "                "
    ],
    [
      "                ",
      "                ",
      "***********     ",
      "          *     ",
      "          *     ",
      "          *     ",
      "          *     ",
      "          *     ",
      "          *     ",
      "          *     ",
      "          *     ",
      "          *     ",
      "          *     ",
      "***********     ",
      "                ",
      "                "
    ]
  ],
  "palette": {
    "palette": [
      {
        "char": "!",
        "block": "create:framed_glass"
      },
      {
        "char": "$",
        "block": "immersiveengineering:metal_barrel"
      },
      {
        "char": "%",
        "block": "minecraft:chest[facing=west,type=single,waterlogged=false]",
        "tag": {
          "id": "minecraft:chest",
          "LootTable": "infinite_domain:chests/wasteland_industrial"
        }
      },
      {
        "char": "&",
        "block": "minecraft:coarse_dirt"
      },
      {
        "char": "'",
        "block": "minecraft:crafting_table"
      },
      {
        "char": "(",
        "block": "minecraft:gravel"
      },
      {
        "char": ")",
        "block": "minecraft:grindstone[face=floor,facing=south]"
      },
      {
        "char": "*",
        "block": "minecraft:mud_bricks"
      },
      {
        "char": "+",
        "block": "minecraft:smithing_table"
      },
      {
        "char": ",",
        "block": "minecraft:spruce_door[facing=east,half=lower,hinge=left,open=false,powered=false]"
      },
      {
        "char": "-",
        "block": "minecraft:spruce_door[facing=east,half=lower,hinge=right,open=false,powered=false]"
      },
      {
        "char": ".",
        "block": "minecraft:spruce_door[facing=east,half=upper,hinge=left,open=false,powered=false]"
      },
      {
        "char": "/",
        "block": "minecraft:spruce_door[facing=east,half=upper,hinge=right,open=false,powered=false]"
      },
      {
        "char": "0",
        "block": "minecraft:stone_bricks"
      },
      {
        "char": "1",
        "block": "tfmg:asphalt"
      }
    ]
  }
}
