{
  "xsize": 16,
  "zsize": 16,
  "slices": [
    [
      "(((((+++(7777777",
      "(((((+(777777777",
      "(((((77777777777",
      "(((((77777777777",
      "(((((77777777777",
      "(((((7777777777+",
      "7777777777777++(",
      "77777777777++(77",
      "777777777++(7777",
      "7777777++(777777",
      "77777++(77777777",
      "777++(7777777777",
      "7++(777777777777",
      "+(77777777777777",
      "7777777777777777",
      "77777777777777++"
    ],
    [
      "  *     3,,,,,,,",
      "*5*     3,,,,,,,",
      " **     3%,,,,,%",
      "  *6    33333333",
      "  **    33333333",
      "  *     33333333",
      "        33333333",
      "                ",
      "                ",
      "                ",
      "                ",
      "                ",
      "        33333333",
      "        33333333",
      "        33333333",
      "        33333333"
    ],
    [
      "        / ) /   ",
      "        //////1/",
      "        /       ",
      "        / -  $  ",
      "        / .     ",
      "        /     ' ",
      "        ////////",
      "                ",
      "                ",
      "                ",
      "                ",
      "                ",
      "        00000000",
      "        0       ",
      "        0 44  & ",
      "        0       "
    ],
    [
      "        /   /   ",
      "        //////2/",
      "        /       ",
      "        /       ",
      "        /       ",
      "        /       ",
      "        //!!////",
      "                ",
      "                ",
      "                ",
      "                ",
      "                ",
      "        00!!0000",
      "        0       ",
      "        0       ",
      "        0       "
    ],
    [
      "        /   /   ",
      "        ////////",
      "        /       ",
      "        /       ",
      "        /       ",
      "        /       ",
      "        //!!////",
      "                ",
      "                ",
      "                ",
      "                ",
      "                ",
      "        00!!0000",
      "        0       ",
      "        0       ",
      "        0       "
    ],
    [
      "        /   /   ",
      "        ////////",
      "        /       ",
      "        /       ",
      "        /       ",
      "        /       ",
      "        ////////",
      "                ",
      "                ",
      "                ",
      "                ",
      "                ",
      "        00000000",
      "        0       ",
      "        0       ",
      "        0       "
    ]
  ],
  "palette": {
    "palette": [
      {
        "char": "!",
        "block": "create:framed_glass"
      },
      {
        "char": "$",
        "block": "minecraft:barrel[facing=up,open=false]"
      },
      {
        "char": "%",
        "block": "minecraft:black_concrete"
      },
      {
        "char": "&",
        "block": "minecraft:bookshelf"
      },
      {
        "char": "'",
        "block": "minecraft:chest[facing=north,type=single,waterlogged=false]",
        "tag": {
          "id": "minecraft:chest",
          "LootTable": "infinite_domain:chests/wasteland_home"
        }
      },
      {
        "char": "(",
        "block": "minecraft:coarse_dirt"
      },
      {
        "char": ")",
        "block": "kubejs:ruined_composter"
      },
      {
        "char": "*",
        "block": "minecraft:dead_bush"
      },
      {
        "char": "+",
        "block": "minecraft:gravel"
      },
      {
        "char": ",",
        "block": "minecraft:gray_concrete"
      },
      {
        "char": "-",
        "block": "minecraft:orange_bed[facing=south,occupied=false,part=foot]"
      },
      {
        "char": ".",
        "block": "minecraft:orange_bed[facing=south,occupied=false,part=head]"
      },
      {
        "char": "/",
        "block": "minecraft:orange_terracotta"
      },
      {
        "char": "0",
        "block": "minecraft:pink_terracotta"
      },
      {
        "char": "1",
        "block": "minecraft:spruce_door[facing=south,half=lower,hinge=left,open=false,powered=false]"
      },
      {
        "char": "2",
        "block": "minecraft:spruce_door[facing=south,half=upper,hinge=left,open=false,powered=false]"
      },
      {
        "char": "3",
        "block": "minecraft:spruce_planks"
      },
      {
        "char": "4",
        "block": "minecraft:spruce_stairs[facing=south,half=bottom,shape=straight,waterlogged=false]"
      },
      {
        "char": "5",
        "block": "minecraft:wheat[age=2]"
      },
      {
        "char": "6",
        "block": "minecraft:wheat[age=6]"
      },
      {
        "char": "7",
        "block": "tfmg:asphalt"
      }
    ]
  }
}
