{
  "xsize": 16,
  "zsize": 16,
  "slices": [
    [
      "   $$$00000     ",
      "   $$$00000     ",
      "      00000     ",
      "      00000     ",
      "/////////////// ",
      "/111 '(  1111// ",
      "/1          1// ",
      "/1          1// ",
      "/1 --       1// ",
      "/1 .        1// ",
      "/1          1// ",
      "/11111+111111// ",
      "/1          1// ",
      "/1       %  1// ",
      "/1          1// ",
      "/1     &    1// "
    ],
    [
      "   $$$00000     ",
      "   $$$00000     ",
      "      00000     ",
      "      00000     ",
      "/////////////// ",
      "/111 )*  1111// ",
      "/1          1// ",
      "/1          1// ",
      "/1          1// ",
      "/1          1// ",
      "/1          1// ",
      "/11111,111111// ",
      "/1          1// ",
      "/1          1// ",
      "/1          1// ",
      "/1          1// "
    ],
    [
      "   $$$00000     ",
      "   $$$00000     ",
      "      00000     ",
      "      00000     ",
      "/////////////// ",
      "/1!!     1!!1// ",
      "/1          1// ",
      "/1          1// ",
      "/1          1// ",
      "/1          1// ",
      "/1          1// ",
      "/111111111111// ",
      "/1          1// ",
      "/1          1// ",
      "/1          1// ",
      "/1          1// "
    ],
    [
      "   $$$00000     ",
      "   $$$00000     ",
      "      00000     ",
      "      00000     ",
      "/////////////// ",
      "/1!!     1!!1// ",
      "/1          1// ",
      "/1          1// ",
      "/1          1// ",
      "/1          1// ",
      "/1          1// ",
      "/111111111111// ",
      "/1          1// ",
      "/1          1// ",
      "/1          1// ",
      "/1          1// "
    ],
    [
      "                ",
      "                ",
      "                ",
      "                ",
      "/////////////// ",
      "/111111111111// ",
      "/1          1// ",
      "/1          1// ",
      "/1          1// ",
      "/1          1// ",
      "/1          1// ",
      "/1          1// ",
      "/1          1// ",
      "/1          1// ",
      "/1          1// ",
      "/1          1// "
    ],
    [
      "                ",
      "                ",
      "                ",
      "                ",
      "/////////////// ",
      "/111111111111// ",
      "/1          1// ",
      "/1          1// ",
      "/1          1// ",
      "/1          1// ",
      "/1          1// ",
      "/1          1// ",
      "/1          1// ",
      "/1          1// ",
      "/1          1// ",
      "/1          1// "
    ]
  ],
  "palette": {
    "palette": [
      {
        "char": "!",
        "block": "create:framed_glass"
      },
      {
        "char": "$",
        "block": "minecraft:blue_concrete"
      },
      {
        "char": "%",
        "block": "minecraft:chest[facing=north,type=single,waterlogged=false]",
        "tag": {
          "id": "minecraft:chest",
          "LootTable": "infinite_domain:chests/wasteland_military"
        }
      },
      {
        "char": "&",
        "block": "minecraft:spawner",
        "tag": {
          "id": "minecraft:mob_spawner",
          "Delay": 200,
          "MinSpawnDelay": 240,
          "MaxSpawnDelay": 720,
          "SpawnCount": 3,
          "MaxNearbyEntities": 9,
          "RequiredPlayerRange": 14,
          "SpawnRange": 4,
          "SpawnData": {
            "entity": {
              "id": "minecraft:pillager"
            }
          },
          "SpawnPotentials": [
            {
              "weight": 1,
              "data": {
                "entity": {
                  "id": "minecraft:pillager"
                }
              }
            }
          ]
        }
      },
      {
        "char": "'",
        "block": "minecraft:spruce_door[facing=north,half=lower,hinge=left,open=false,powered=false]"
      },
      {
        "char": "(",
        "block": "minecraft:spruce_door[facing=north,half=lower,hinge=right,open=false,powered=false]"
      },
      {
        "char": ")",
        "block": "minecraft:spruce_door[facing=north,half=upper,hinge=left,open=false,powered=false]"
      },
      {
        "char": "*",
        "block": "minecraft:spruce_door[facing=north,half=upper,hinge=right,open=false,powered=false]"
      },
      {
        "char": "+",
        "block": "minecraft:spruce_door[facing=south,half=lower,hinge=left,open=false,powered=false]"
      },
      {
        "char": ",",
        "block": "minecraft:spruce_door[facing=south,half=upper,hinge=left,open=false,powered=false]"
      },
      {
        "char": "-",
        "block": "minecraft:spruce_slab[type=bottom,waterlogged=false]"
      },
      {
        "char": ".",
        "block": "minecraft:spruce_stairs[facing=north,half=bottom,shape=straight,waterlogged=false]"
      },
      {
        "char": "/",
        "block": "minecraft:stone"
      },
      {
        "char": "0",
        "block": "minecraft:yellow_concrete"
      },
      {
        "char": "1",
        "block": "the_wasteland_reworked:cut_lead_plating"
      }
    ]
  }
}
