{
  "xsize": 16,
  "zsize": 16,
  "slices": [
    [
      "                ",
      "      $         ",
      "                ",
      "                ",
      "                ",
      "      $         ",
      "                ",
      "                ",
      "         &&&    ",
      "      $  &&&    ",
      "         &&&    ",
      "     %%%%%      ",
      "     %%%%%      ",
      "     %%%%%!!!!! ",
      "     %%%%%!!!!! ",
      "     %%%%%!!!!! "
    ],
    [
      "                ",
      "                ",
      "                ",
      "                ",
      "                ",
      "                ",
      "                ",
      "                ",
      "         &&&    ",
      "         &&&    ",
      "         &&&    ",
      "     %%%%%      ",
      "     %%%%%      ",
      "     %%%%%!!!!! ",
      "     %%%%%!!!!! ",
      "     %%%%%!!!!! "
    ],
    [
      "                ",
      "                ",
      "                ",
      "                ",
      "                ",
      "                ",
      "                ",
      "                ",
      "         &&&    ",
      "         &&&    ",
      "         &&&    ",
      "     %%%%%      ",
      "     %%%%%      ",
      "     %%%%%!!!!! ",
      "     %%%%%!!!!! ",
      "     %%%%%!!!!! "
    ],
    [
      "                ",
      "                ",
      "                ",
      "                ",
      "                ",
      "                ",
      "                ",
      "                ",
      "         &&&    ",
      "         &&&    ",
      "         &&&    ",
      "     %%%%%      ",
      "     %%%%%      ",
      "     %%%%%!!!!! ",
      "     %%%%%!!!!! ",
      "     %%%%%!!!!! "
    ],
    [
      "                ",
      "                ",
      "                ",
      "                ",
      "                ",
      "                ",
      "                ",
      "                ",
      "         &&&    ",
      "         &&&    ",
      "         &&&    ",
      "                ",
      "                ",
      "                ",
      "                ",
      "                "
    ],
    [
      "                ",
      "                ",
      "                ",
      "                ",
      "                ",
      "                ",
      "                ",
      "                ",
      "         &&&    ",
      "         &&&    ",
      "         &&&    ",
      "                ",
      "                ",
      "                ",
      "                ",
      "                "
    ]
  ],
  "palette": {
    "palette": [
      {
        "char": "!",
        "block": "minecraft:orange_concrete"
      },
      {
        "char": "$",
        "block": "minecraft:oxidized_copper_grate"
      },
      {
        "char": "%",
        "block": "minecraft:red_concrete"
      },
      {
        "char": "&",
        "block": "tfmg:steel_block"
      }
    ]
  }
}
