{
  "xsize": 16,
  "zsize": 16,
  "slices": [
    [
      "                ",
      "       $        ",
      "!             ! ",
      "!             ! ",
      "!&           &!%",
      "!             !%",
      "!             !%",
      "!             !%",
      "!             !%",
      "!             !%",
      "!             !%",
      "!&           &!%",
      "!             !%",
      "!             !%",
      "!             !%",
      "!             !%"
    ],
    [
      "                ",
      "                ",
      "!             ! ",
      "!             ! ",
      "!&           &!%",
      "!             !%",
      "!             !%",
      "!             !%",
      "!             !%",
      "!             !%",
      "!             !%",
      "!&           &!%",
      "!             !%",
      "!             !%",
      "!             !%",
      "!             !%"
    ],
    [
      "                ",
      "                ",
      "!             ! ",
      "!             ! ",
      "!&           &!%",
      "!             !%",
      "!             !%",
      "!             !%",
      "!             !%",
      "!             !%",
      "!             !%",
      "!&           &!%",
      "!             !%",
      "!             !%",
      "!             !%",
      "!             !%"
    ],
    [
      "                ",
      "                ",
      "!             ! ",
      "!             ! ",
      "!&           &!%",
      "!             !%",
      "!             !%",
      "!             !%",
      "!             !%",
      "!             !%",
      "!             !%",
      "!&           &!%",
      "!             !%",
      "!             !%",
      "!             !%",
      "!             !%"
    ],
    [
      "                ",
      "                ",
      "!             ! ",
      "!             ! ",
      "!&           &!%",
      "!             !%",
      "!             !%",
      "!             !%",
      "!             !%",
      "!             !%",
      "!             !%",
      "!&           &!%",
      "!             !%",
      "!             !%",
      "!             !%",
      "!             !%"
    ],
    [
      "                ",
      "                ",
      "!             ! ",
      "!             ! ",
      "!&           &!%",
      "!             !%",
      "!             !%",
      "!             !%",
      "!             !%",
      "!             !%",
      "!             !%",
      "!&           &!%",
      "!             !%",
      "!             !%",
      "!             !%",
      "!             !%"
    ]
  ],
  "palette": {
    "palette": [
      {
        "char": "!",
        "block": "immersiveengineering:concrete_reinforced"
      },
      {
        "char": "$",
        "block": "minecraft:oxidized_copper_grate"
      },
      {
        "char": "%",
        "block": "minecraft:stone"
      },
      {
        "char": "&",
        "block": "tfmg:steel_block"
      }
    ]
  }
}
