{
  "xsize": 16,
  "zsize": 16,
  "slices": [
    [
      "                ",
      "                ",
      "                ",
      "                ",
      "%%%%%%%%%%%%%%%%",
      "%%%%%%%%%%%%%%%%",
      "%%%%%%%%%%%%%%%%",
      "%%%%%%%%%%%%%%%%",
      "%%%%%%%%%%%%%%%%",
      "%%%%%%%%%%%%%%%%",
      "%%%%%%%%%%%%%%%%",
      "%%%%%%%%%%%%%%%%",
      "%%%%%%%%%%%%%%%%",
      "%%%%%%%%%%%%%%%%",
      "%%%%%%%%%%%%%%%%",
      "%%%%%%%%%%%%%%%%"
    ],
    [
      "                ",
      "                ",
      "                ",
      "                ",
      "%%%%%%%%%%%%%%%%",
      "%%%%%%%%%%%%%%%%",
      "%%%%%%%%%%%%%%%%",
      "%%%%%%%%%%%%%%%%",
      "%%%%%%%%%%%%%%%%",
      "%%%%%%%%%%%%%%%%",
      "%%%%%%%%%%%%%%%%",
      "%%%%%%%%%%%%%%%%",
      "%%%%%%%%%%%%%%%%",
      "%%%%%%%%%%%%%%%%",
      "%%%%%%%%%%%%%%%%",
      "%%%%%%%%%%%%%%%%"
    ],
    [
      "$$$$$$$$$$$$$$$ ",
      "$$$$$$$$$$$$$$$!",
      "$$$$$$$$$$$$$$$!",
      "$$$$$$$$$$$$$$$!",
      "$$$$$$$$$$$$$$$%",
      "$$$$$$$$$$$$$$$%",
      "$$$$$$$$$$$$$$$%",
      "$$$$$$$$$$$$$$$%",
      "$$$$$$$$$$$$$$$%",
      "%%%%%%%%%%%%%%%%",
      "%%%%%%%%%%%%%%%%",
      "%%%%%%%%%%%%%%%%",
      "%%%%%%%%%%%%%%%%",
      "%%%%%%%%%%%%%%%%",
      "%%%%%%%%%%%%%%%%",
      "%%%%%%%%%%%%%%%%"
    ],
    [
      "$$$$$$$$$$$$$$$ ",
      "$$$$$$$$$$$$$$$!",
      "$$$$$$$$$$$$$$$!",
      "$$$$$$$$$$$$$$$!",
      "$$$$$$$$$$$$$$$%",
      "$$$$$$$$$$$$$$$%",
      "$$$$$$$$$$$$$$$%",
      "$$$$$$$$$$$$$$$%",
      "$$$$$$$$$$$$$$$%",
      "%%%%%%%%%%%%%%%%",
      "%%%%%%%%%%%%%%%%",
      "%%%%%%%%%%%%%%%%",
      "%%%%%%%%%%%%%%%%",
      "%%%%%%%%%%%%%%%%",
      "%%%%%%%%%%%%%%%%",
      "%%%%%%%%%%%%%%%%"
    ],
    [
      "$$$$$$$$$$$$$$$ ",
      "$$$$$$$$$$$$$$$!",
      "$$$$$$$$$$$$$$$!",
      "$$$$$$$$$$$$$$$!",
      "$$$$$$$$$$$$$$$%",
      "$$$$$$$$$$$$$$$%",
      "$$$$$$$$$$$$$$$%",
      "$$$$$$$$$$$$$$$%",
      "$$$$$$$$$$$$$$$%",
      "%%%%%%%%%%%%%%%%",
      "%%%%%%%%%%%%%%%%",
      "%%%%%%%%%%%%%%%%",
      "%%%%%%%%%%%%%%%%",
      "%%%%%%%%%%%%%%%%",
      "%%%%%%%%%%%%%%%%",
      "%%%%%%%%%%%%%%%%"
    ],
    [
      "$$$$$$$$$$$$$$$ ",
      "$$$$$$$$$$$$$$$ ",
      "$$$$$$$$$$$$$$$ ",
      "$$$$$$$$$$$$$$$ ",
      "$$$$$$$$$$$$$$$%",
      "$$$$$$$$$$$$$$$%",
      "$$$$$$$$$$$$$$$%",
      "$$$$$$$$$$$$$$$%",
      "$$$$$$$$$$$$$$$%",
      "%%&&&&&&&&&&&&&%",
      "%%&&&&&&&&&&&&&%",
      "%%&&&&&&&&&&&&&%",
      "%%&&&&&&&&&&&&&%",
      "%%&&&&&&&&&&&&&%",
      "%%&&&&&&&&&&&&&%",
      "%%&&&&&&&&&&&&&%"
    ]
  ],
  "palette": {
    "palette": [
      {
        "char": "!",
        "block": "immersiveengineering:concrete_brick_cracked"
      },
      {
        "char": "$",
        "block": "minecraft:gravel"
      },
      {
        "char": "%",
        "block": "minecraft:stone"
      },
      {
        "char": "&",
        "block": "tfmg:factory_floor"
      }
    ]
  }
}
