{
  "xsize": 16,
  "zsize": 16,
  "slices": [
    [
      "                ",
      "                ",
      "                ",
      "                ",
      "&&&&&&&&&&&&&&&&",
      "&&&&&&&&&&&&&&&&",
      "&&&&&&&&&&&&&&&&",
      "&&&&&&&&&&&&&&&&",
      "&&&&&&&&&&&&&&&&",
      "&&&&&&&&&&&&&&&&",
      "&&&&&&&&&&&&&&&&",
      "&&&&&&&&&&&&&&&&",
      "&&&&&&&&&&&&&&&&",
      "&&&&&&&&&&&&&&&&",
      "&&&&&&&&&&&&&&&&",
      "&&&&&&&&&&&&&&&&"
    ],
    [
      "                ",
      "                ",
      "                ",
      "                ",
      "&&&&&&&&&&&&&&&&",
      "&&&&&&&&&&&&&&&&",
      "&&&&&&&&&&&&&&&&",
      "&&&&&&&&&&&&&&&&",
      "&&&&&&&&&&&&&&&&",
      "&&&&&&&&&&&&&&&&",
      "&&&&&&&&&&&&&&&&",
      "&&&&&&&&&&&&&&&&",
      "&&&&&&&&&&&&&&&&",
      "&&&&&&&&&&&&&&&&",
      "&&&&&&&&&&&&&&&&",
      "&&&&&&&&&&&&&&&&"
    ],
    [
      "     !$$$$!     ",
      "!!!!!!$$$$!!!!!!",
      "$'''''''''''''$!",
      "$'''''''''''''$!",
      "$'''''''''''''$&",
      "$'''''''''''''$&",
      "$'''''''''''''$&",
      "$'''''''''''''$&",
      "$'''''''''''''$&",
      "$'''''''''''''$&",
      "$'''''''''''''$&",
      "$'''''''''''''$&",
      "$'''''''''''''$&",
      "$'''''''''''''$&",
      "$'''''''''''''$&",
      "$'''''''''''''$&"
    ],
    [
      "     !$$$$!     ",
      "!!!!!!$$$$!!!!!!",
      "$   %     %   $!",
      "$   %     %   $!",
      "$(           ($&",
      "$   %     %   $&",
      "$   %     %   $&",
      "$   %     %   $&",
      "$   %     %   $&",
      "$   %     %   $&",
      "$   %     %   $&",
      "$(           ($&",
      "$   %     %   $&",
      "$   %     %   $&",
      "$   %     %   $&",
      "$   %     %   $&"
    ],
    [
      "     !$$$$!     ",
      "!!!!!!$$$$!!!!!!",
      "$             $!",
      "$             $!",
      "$(           ($&",
      "$             $&",
      "$             $&",
      "$             $&",
      "$             $&",
      "$             $&",
      "$             $&",
      "$(           ($&",
      "$             $&",
      "$             $&",
      "$             $&",
      "$             $&"
    ],
    [
      "      $$$$      ",
      "      $$$$      ",
      "$             $ ",
      "$             $ ",
      "$(           ($&",
      "$             $&",
      "$             $&",
      "$             $&",
      "$             $&",
      "$             $&",
      "$             $&",
      "$(           ($&",
      "$             $&",
      "$             $&",
      "$             $&",
      "$             $&"
    ]
  ],
  "palette": {
    "palette": [
      {
        "char": "!",
        "block": "immersiveengineering:concrete_brick_cracked"
      },
      {
        "char": "$",
        "block": "immersiveengineering:concrete_reinforced"
      },
      {
        "char": "%",
        "block": "minecraft:rail[shape=north_south,waterlogged=false]"
      },
      {
        "char": "&",
        "block": "minecraft:stone"
      },
      {
        "char": "'",
        "block": "tfmg:asphalt"
      },
      {
        "char": "(",
        "block": "tfmg:steel_block"
      }
    ]
  }
}
