{
  "xsize": 16,
  "zsize": 16,
  "slices": [
    [
      "$$$$$$$$$$$$$$$ ",
      "$$$$$$$$$$$$$$$ ",
      "$$$$$$$$$$$$$$$ ",
      "$$$$$$$$$$$$$$$ ",
      "$$$$$$$$$$$$$$$)",
      "$$$$$$$$$$$$$$$)",
      "$$$$$$$$$$$$$$$)",
      "$$$$$$$$$$$$$$$)",
      "$$$$$$$$$$$$$$$)",
      "))+        *  +)",
      "))+           +)",
      "))++++++'++++++)",
      "))+      +    +)",
      "))+      +    +)",
      "))+      % !  +)",
      "))+      +    +)"
    ],
    [
      "$$$$$$$$$$$$$$$ ",
      "$$$$$$$$$$$$$$$ ",
      "$$$$$$$$$$$$$$$ ",
      "$$$$$$$$$$$$$$$ ",
      "$$$$$$$$$$$$$$$)",
      "$$$$$$$$$$$$$$$)",
      "$$$$$$$$$$$$$$$)",
      "$$$$$$$$$$$$$$$)",
      "$$$$$$$$$$$$$$$)",
      "))+           +)",
      "))+        *  +)",
      "))++++++(++++++)",
      "))+      +    +)",
      "))+      +    +)",
      "))+      &    +)",
      "))+      +    +)"
    ],
    [
      "$$$$$$$$$$$$$$$ ",
      "$$$$$$$$$$$$$$$ ",
      "$$$$$$$$$$$$$$$ ",
      "$$$$$$$$$$$$$$$ ",
      "$$$$$$$$$$$$$$$)",
      "$$$$$$$$$$$$$$$)",
      "$$$$$$$$$$$$$$$)",
      "$$$$$$$$$$$$$$$)",
      "$$$$$$$$$$$$$$$)",
      "))+           +)",
      "))+           +)",
      "))+++++++++*+++)",
      "))+      +    +)",
      "))+      +    +)",
      "))+      +    +)",
      "))+      +    +)"
    ],
    [
      "$$$$$$$$$$$$$$$ ",
      "$$$$$$$$$$$$$$$ ",
      "$$$$$$$$$$$$$$$ ",
      "$$$$$$$$$$$$$$$ ",
      "$$$$$$$$$$$$$$$)",
      "$$$$$$$$$$$$$$$)",
      "$$$$$$$$$$$$$$$)",
      "$$$$$$$$$$$$$$$)",
      "$$$$$$$$$$$$$$$)",
      "))+           +)",
      "))+           +)",
      "))+++++++++ +++)",
      "))+      + *  +)",
      "))+      +    +)",
      "))+      +    +)",
      "))+      +    +)"
    ],
    [
      "$$$$$$$$$$$$$$$ ",
      "$$$$$$$$$$$$$$$ ",
      "$$$$$$$$$$$$$$$ ",
      "$$$$$$$$$$$$$$$ ",
      "$              )",
      "$              )",
      "$              )",
      "$              )",
      "$              )",
      ")              )",
      ")              )",
      ")              )",
      ")              )",
      ")              )",
      ")              )",
      ")              )"
    ],
    [
      "$$$$$$$$$$$$$$$ ",
      "$$$$$$$$$$$$$$$ ",
      "$$$$$$$$$$$$$$$ ",
      "$$$$$$$$$$$$$$$ ",
      "$              )",
      "$              )",
      "$              )",
      "$              )",
      "$              )",
      ")              )",
      ")              )",
      ")              )",
      ")              )",
      ")              )",
      ")              )",
      ")              )"
    ]
  ],
  "palette": {
    "palette": [
      {
        "char": "!",
        "block": "minecraft:chest[facing=north,type=single,waterlogged=false]",
        "tag": {
          "id": "minecraft:chest",
          "LootTable": "infinite_domain:chests/wasteland_industrial"
        }
      },
      {
        "char": "$",
        "block": "minecraft:gravel"
      },
      {
        "char": "%",
        "block": "minecraft:spruce_door[facing=east,half=lower,hinge=left,open=false,powered=false]"
      },
      {
        "char": "&",
        "block": "minecraft:spruce_door[facing=east,half=upper,hinge=left,open=false,powered=false]"
      },
      {
        "char": "'",
        "block": "minecraft:spruce_door[facing=south,half=lower,hinge=left,open=false,powered=false]"
      },
      {
        "char": "(",
        "block": "minecraft:spruce_door[facing=south,half=upper,hinge=left,open=false,powered=false]"
      },
      {
        "char": ")",
        "block": "minecraft:stone"
      },
      {
        "char": "*",
        "block": "minecraft:stone_brick_stairs[facing=south,half=bottom,shape=straight,waterlogged=false]"
      },
      {
        "char": "+",
        "block": "tfmg:cinder_block"
      }
    ]
  }
}
