{
  "xsize": 16,
  "zsize": 16,
  "slices": [
    [
      "                ",
      "                ",
      "                ",
      "                ",
      "                ",
      "                ",
      "                ",
      "                ",
      "                ",
      "                ",
      "                ",
      "                ",
      "                ",
      "                ",
      "                ",
      "                "
    ],
    [
      "                ",
      "                ",
      "                ",
      "                ",
      "                ",
      "                ",
      "                ",
      "                ",
      "                ",
      "                ",
      "                ",
      "                ",
      "                ",
      "                ",
      "                ",
      "                "
    ],
    [
      "       $$$$     ",
      "       $$$$     ",
      "  !!!!!$$$$!!   ",
      "  !!!!!$$$$!!   ",
      "  !!!!!$$$$!!   ",
      "  !!!!!$$$$!!   ",
      "  !!!!!$$$$!!   ",
      "  !!!!!$$$$!!   ",
      "  !!!!!$$$$!!   ",
      "  !!!!!$$$$!!   ",
      "  !!!!!$$$$!!   ",
      "  !!!!!$$$$!!   ",
      "  !!!!!$$$$!!   ",
      "  !!!!!$$$$!!   ",
      "  !!!!!$$$$!!   ",
      "  !!!!!$$$$!!   "
    ],
    [
      "       $$$$     ",
      "       $$$$     ",
      "  !!!!!$$$$!!   ",
      "  !!!!!$$$$!!   ",
      "  !!!!!$$$$!!   ",
      "  !!!!!$$$$!!   ",
      "  !!!!!$$$$!!   ",
      "  !!!!!$$$$!!   ",
      "  !!!!!$$$$!!   ",
      "  !!!!!$$$$!!   ",
      "  !!!!!$$$$!!   ",
      "  !!!!!$$$$!!   ",
      "  !!!!!$$$$!!   ",
      "  !!!!!$$$$!!   ",
      "  !!!!!$$$$!!   ",
      "  !!!!!$$$$!!   "
    ],
    [
      "       $$$$     ",
      "       $$$$     ",
      "  !!!!!$$$$!!   ",
      "  !!!!!$$$$!!   ",
      "  !!!!!$$$$!!   ",
      "  !!!!!$$$$!!   ",
      "  !!!!!$$$$!!   ",
      "  !!!!!$$$$!!   ",
      "  !!!!!$$$$!!   ",
      "  !!!!!$$$$!!   ",
      "  !!!!!$$$$!!   ",
      "  !!!!!$$$$!!   ",
      "  !!!!!$$$$!!   ",
      "  !!!!!$$$$!!   ",
      "  !!!!!$$$$!!   ",
      "  !!!!!$$$$!!   "
    ],
    [
      "       $$$$     ",
      "       $$$$     ",
      "       $$$$     ",
      "       $$$$     ",
      "       $$$$     ",
      "       $$$$     ",
      "       $$$$     ",
      "       $$$$     ",
      "    '''$$$$     ",
      "    '''$$$$     ",
      "   %'''%$$$     ",
      "   %%%%%$$$     ",
      "   %%%%%$$$     ",
      "   %%%%%$$$     ",
      "   %%%%%$$$     ",
      "   %%%&&&&&     "
    ]
  ],
  "palette": {
    "palette": [
      {
        "char": "!",
        "block": "immersiveengineering:concrete_brick_cracked"
      },
      {
        "char": "$",
        "block": "immersiveengineering:concrete_reinforced"
      },
      {
        "char": "%",
        "block": "minecraft:blue_concrete"
      },
      {
        "char": "&",
        "block": "minecraft:yellow_concrete"
      },
      {
        "char": "'",
        "block": "tfmg:steel_block"
      }
    ]
  }
}
