{
  "xsize": 16,
  "zsize": 16,
  "slices": [
    [
      "                ",
      "                ",
      "                ",
      "                ",
      "!!$$$$$$$$$$$$$!",
      "!!$           $!",
      "!!$           $!",
      "!!$           $!",
      "!!$           $!",
      "!!$           $!",
      "!!$           $!",
      "!!$           $!",
      "!!$           $!",
      "!!$           $!",
      "!!$           $!",
      "!!$           $!"
    ],
    [
      "                ",
      "                ",
      "                ",
      "                ",
      "!!$$$$$$$$$$$$$!",
      "!!$           $!",
      "!!$           $!",
      "!!$           $!",
      "!!$           $!",
      "!!$           $!",
      "!!$           $!",
      "!!$           $!",
      "!!$           $!",
      "!!$           $!",
      "!!$           $!",
      "!!$           $!"
    ],
    [
      "                ",
      "                ",
      "                ",
      "                ",
      "  $$$$$$$$$$$$$!",
      "  $           $!",
      "  $           $!",
      "!!$           $!",
      "!!$           $!",
      "!!$           $!",
      "!!$           $!",
      "!!$           $!",
      "!!$           $!",
      "!!$           $!",
      "!!$           $!",
      "!!$           $!"
    ],
    [
      "                ",
      "                ",
      "                ",
      "                ",
      "  %%%%%%%%%%%%%!",
      "  %%%%%%%%%%%%%!",
      "  %%%%%%%%%%%%%!",
      "  %%%%%%%%%%%%%!",
      "  %%%%%%%%%%%%%!",
      "  %%%%%%%%%%%%%!",
      "!!%%%%%%%%%%%%%!",
      "!!%%%%%%%%%%%%%!",
      "!!%%%%%%%%%%%%%!",
      "!!%%%%%%%%%%%%%!",
      "!!%%%%%%%%%%%%%!",
      "!!%%%%%%%%%%%%%!"
    ],
    [
      "                ",
      "                ",
      "                ",
      "                ",
      "      !!!!!!!!!!",
      "      !!!!!!!!!!",
      "      !!!!!!!!!!",
      "    !!!!!!!!!!!!",
      "    !!!!!!!!!!!!",
      "    !!!!!!!!!!!!",
      "  !!!!!!!!!!!!!!",
      "  !!!!!!!!!!!!!!",
      "  !!!!!!!!!!!!!!",
      "!!!!!!!!!!!!!!!!",
      "!!!!!!!!!!!!!!!!",
      "!!!!!!!!!!!!!!!!"
    ],
    [
      "                ",
      "                ",
      "                ",
      "                ",
      "        !!!!!!!!",
      "        !!!!!!!!",
      "        !!!!!!!!",
      "      !!!!!!!!!!",
      "      !!!!!!!!!!",
      "      !!!!!!!!!!",
      "    !!!!!!!!!!!!",
      "    !!!!!!!!!!!!",
      "    !!!!!!!!!!!!",
      "  !!!!!!!!!!!!!!",
      "  !!!!!!!!!!!!!!",
      "  !!!!!!!!!!!!!!"
    ]
  ],
  "palette": {
    "palette": [
      {
        "char": "!",
        "block": "minecraft:stone"
      },
      {
        "char": "$",
        "block": "tfmg:cinder_block"
      },
      {
        "char": "%",
        "block": "tfmg:steel_block"
      }
    ]
  }
}
