{
  "xsize": 16,
  "zsize": 16,
  "slices": [
    [
      " +++%%$+++++++++",
      " +%%$+++++++++++",
      " %$+++++++++++++",
      " +++++++++++++++",
      " ++++++++++++++%",
      " $+++++++++++%%$",
      " ++++++++++%%$++",
      " ++++++++%%$++++",
      " ++++++%%$++++++",
      " ++++%%$++++++++",
      " ++%%$++++++++++",
      " $%$++++++++++++",
      " $++++++++++++++",
      " +++++++++++++++",
      " +++++++++++++%%",
      " +++++++++++%%$+"
    ],
    [
      "  '''''''       ",
      "  '''''''       ",
      "  '''''''       ",
      "  '''''''       ",
      "  '''''''       ",
      "  '''''''       ",
      "  '''''''       ",
      "  '''''''       ",
      "        !!!!!   ",
      "        !!!!!   ",
      "        !!!!!   ",
      "        !!!!!   ",
      "        !!!!!   ",
      "                ",
      "                ",
      "                "
    ],
    [
      "  *     *       ",
      "  *&&&&&*       ",
      "  *&&(&&*       ",
      "  *&&&&&*       ",
      "  *&&&&&*       ",
      "  *&&&&&*       ",
      "  *     *       ",
      "  *******       ",
      "        !!!!!   ",
      "        !!!!!   ",
      "        !!!!!   ",
      "        !!!!!   ",
      "        !!!!!   ",
      "                ",
      "                ",
      "                "
    ],
    [
      "  *     *       ",
      "  *&&&&&*       ",
      "  *&&&&&*       ",
      "  *&&&&&*       ",
      "  *&&&&&*       ",
      "  *&&&&&*       ",
      "  *     *       ",
      "  *******       ",
      "                ",
      "         )))    ",
      "         )))    ",
      "         )))    ",
      "                ",
      "                ",
      "                ",
      "                "
    ],
    [
      "  *     *       ",
      "  *&&&&&*       ",
      "  *&&&&&*       ",
      "  *&&&&&*       ",
      "  *&&&&&*       ",
      "  *&&&&&*       ",
      "  *     *       ",
      "  *******       ",
      "                ",
      "         )))    ",
      "         )))    ",
      "         )))    ",
      "                ",
      "                ",
      "                ",
      "                "
    ],
    [
      "  *     *       ",
      "  *&&&&&*       ",
      "  *&&&&&*       ",
      "  *&&&&&*       ",
      "  *&&&&&*       ",
      "  *&&&&&*       ",
      "  *     *       ",
      "  *******       ",
      "                ",
      "         )))    ",
      "         )))    ",
      "         )))    ",
      "                ",
      "                ",
      "                ",
      "                "
    ]
  ],
  "palette": {
    "palette": [
      {
        "char": "!",
        "block": "immersiveengineering:concrete_reinforced"
      },
      {
        "char": "$",
        "block": "minecraft:coarse_dirt"
      },
      {
        "char": "%",
        "block": "minecraft:gravel"
      },
      {
        "char": "&",
        "block": "minecraft:scaffolding"
      },
      {
        "char": "'",
        "block": "minecraft:smooth_stone"
      },
      {
        "char": "(",
        "block": "minecraft:spawner",
        "tag": {
          "id": "minecraft:mob_spawner",
          "Delay": 200,
          "MinSpawnDelay": 240,
          "MaxSpawnDelay": 720,
          "SpawnCount": 1,
          "MaxNearbyEntities": 4,
          "RequiredPlayerRange": 14,
          "SpawnRange": 4,
          "SpawnData": {
            "entity": {
              "id": "minecraft:pillager"
            }
          },
          "SpawnPotentials": [
            {
              "weight": 1,
              "data": {
                "entity": {
                  "id": "minecraft:pillager"
                }
              }
            }
          ]
        }
      },
      {
        "char": ")",
        "block": "minecraft:stripped_dark_oak_log[axis=y]"
      },
      {
        "char": "*",
        "block": "minecraft:stripped_spruce_log"
      },
      {
        "char": "+",
        "block": "tfmg:asphalt"
      }
    ]
  }
}
