{
  "xsize": 16,
  "zsize": 16,
  "slices": [
    [
      "&&&&&&&&&&&&    ",
      "&&&&&&&&&&&$    ",
      "&&&&&&&&&&&&    ",
      "&&&&&&&&&&$$    ",
      "&&&&&&&&$$!&    ",
      "&&&&&&$$!&&&    ",
      "&&&&$$!&&&&&    ",
      "&&$$!&&&&&&$    ",
      "$$!&&&&&&&&&    ",
      "!&&&&&&&&&&&    ",
      "&&&&&&&&&&&&    ",
      "!&&&&!&&&&!&    ",
      "                ",
      "                ",
      "                ",
      "                "
    ],
    [
      " $$$$$$$$       ",
      " $$$$$$$$       ",
      " $$$$$$$$$$$$   ",
      " $$$$$$$$$$$$   ",
      " $$$$$$$$$$$$   ",
      "     $$$$$$$$   ",
      "     $$$$$$$$   ",
      "     $$$$$$$$   ",
      "     $$$$$$$$   ",
      "     $$$$$$$$   ",
      "     $$$$$$$$   ",
      "     $$$$$$$$   ",
      "                ",
      "                ",
      "                ",
      "                "
    ],
    [
      " $$$$$$$$       ",
      " $$$$$$$$       ",
      " $$$$$$$$$$$$   ",
      " $$$$$$$$$$$$   ",
      " $$$$$$$$$$$$   ",
      "     $$$$$$$$   ",
      "     $$$$$$$$   ",
      "     $$$$$$$$   ",
      "     $$$$$$$$   ",
      "     $$$$$$$$   ",
      "     $$$$$$$$   ",
      "     $$$$$$$$   ",
      "                ",
      "                ",
      "                ",
      "                "
    ],
    [
      " $$$$$$$$       ",
      " $$$$$$$$       ",
      " $$$$$$$$$$$$   ",
      " $$$$$$$$$$$$   ",
      " $$$$$$$$$$$$   ",
      "     $$$$$$$$   ",
      "     $$$$$$$$   ",
      "     $$$$$$$$   ",
      "     $$$$$$$$   ",
      "     $$$$$$$$   ",
      "     $$$$$$$$   ",
      "     $$$$$$$$   ",
      "                ",
      "                ",
      "                ",
      "                "
    ],
    [
      "                ",
      "     %%%        ",
      "     $$$$$$$$   ",
      "     $$$$$$$$   ",
      "     $$$$$$$$   ",
      "     $$$$$$$$   ",
      "     $$$$$$$$   ",
      "     $$$$$$$$   ",
      "     $$$$$$$$   ",
      "     $$$$$$$$   ",
      "     $$$$$$$$   ",
      "     $$$$$$$$   ",
      "                ",
      "                ",
      "                ",
      "                "
    ],
    [
      "                ",
      "     %%%        ",
      "     $$$$$$$$   ",
      "     $$$$$$$$   ",
      "     $$$$$$$$   ",
      "     $$$$$$$$   ",
      "     $$$$$$$$   ",
      "     $$$$$$$$   ",
      "     $$$$$$$$   ",
      "     $$$$$$$$   ",
      "     $$$$$$$$   ",
      "     $$$$$$$$   ",
      "                ",
      "                ",
      "                ",
      "                "
    ]
  ],
  "palette": {
    "palette": [
      {
        "char": "!",
        "block": "minecraft:coarse_dirt"
      },
      {
        "char": "$",
        "block": "minecraft:gravel"
      },
      {
        "char": "%",
        "block": "minecraft:polished_blackstone"
      },
      {
        "char": "&",
        "block": "tfmg:asphalt"
      }
    ]
  }
}
