{
  "xsize": 16,
  "zsize": 16,
  "slices": [
    [
      "     &          ",
      "                ",
      "                ",
      "                ",
      "                ",
      "                ",
      "                ",
      "                ",
      "                ",
      "         ***    ",
      "         ***    ",
      "         ***    ",
      "                ",
      "                ",
      "                ",
      "                "
    ],
    [
      "                ",
      "                ",
      "                ",
      "                ",
      "                ",
      "                ",
      "                ",
      "                ",
      "                ",
      "         ***    ",
      "         ***    ",
      "         ***    ",
      "                ",
      "                ",
      "                ",
      "                "
    ],
    [
      "                ",
      "                ",
      "                ",
      "                ",
      "                ",
      "                ",
      "                ",
      "                ",
      "                ",
      "         ***    ",
      "         ***    ",
      "         ***    ",
      "                ",
      "                ",
      "                ",
      "                "
    ],
    [
      ")))))))))))))   ",
      ")))))))))))))   ",
      ")))))))))))))   ",
      ")))))))))))))   ",
      ")))))))))))))   ",
      ")))))))))))))   ",
      ")))))))))))))   ",
      ")))))))))))))   ",
      ")))))))))))))   ",
      ")))))))))))))   ",
      ")))))))))))))   ",
      ")))))))))))))   ",
      ")))))))))))))   ",
      "                ",
      "                ",
      "                "
    ],
    [
      "            +   ",
      "            +   ",
      "            +   ",
      "            +   ",
      "            +   ",
      "            +   ",
      "       %    +   ",
      "       $    +   ",
      "            +   ",
      "            +   ",
      "            +   ",
      "            +   ",
      "++'++++++++++   ",
      "                ",
      "                ",
      "                "
    ],
    [
      "            +   ",
      "            !   ",
      "            !   ",
      "            +   ",
      "            !   ",
      "            !   ",
      "            +   ",
      "            !   ",
      "            !   ",
      "            +   ",
      "            +   ",
      "            +   ",
      "!!(!!+!!+!!++   ",
      "                ",
      "                ",
      "                "
    ]
  ],
  "palette": {
    "palette": [
      {
        "char": "!",
        "block": "create:framed_glass"
      },
      {
        "char": "$",
        "block": "minecraft:green_bed[facing=north,occupied=false,part=foot]"
      },
      {
        "char": "%",
        "block": "minecraft:green_bed[facing=north,occupied=false,part=head]"
      },
      {
        "char": "&",
        "block": "minecraft:oak_stairs[facing=north,half=bottom,shape=straight,waterlogged=false]"
      },
      {
        "char": "'",
        "block": "minecraft:spruce_door[facing=south,half=lower,hinge=left,open=false,powered=false]"
      },
      {
        "char": "(",
        "block": "minecraft:spruce_door[facing=south,half=upper,hinge=left,open=false,powered=false]"
      },
      {
        "char": ")",
        "block": "minecraft:spruce_planks"
      },
      {
        "char": "*",
        "block": "minecraft:stripped_dark_oak_log[axis=y]"
      },
      {
        "char": "+",
        "block": "minecraft:stripped_spruce_log"
      }
    ]
  }
}
