{
  "xsize": 16,
  "zsize": 16,
  "slices": [
    [
      "                ",
      "                ",
      "                ",
      "                ",
      "                ",
      "                ",
      "                ",
      "                ",
      "!!%!!%!!%!!%%   ",
      "            %   ",
      "            %   ",
      "            !   ",
      "            !   ",
      "            %   ",
      "            !   ",
      "            !   "
    ],
    [
      "                ",
      "                ",
      "                ",
      "                ",
      "                ",
      "                ",
      "                ",
      "                ",
      "%%%%%%%%%%%%%   ",
      "            %   ",
      "            %   ",
      "            %   ",
      "            %   ",
      "            %   ",
      "            %   ",
      "            %   "
    ],
    [
      "                ",
      "                ",
      "                ",
      "                ",
      "                ",
      "                ",
      "                ",
      "                ",
      "%%%%%%%%%%%%%   ",
      "            %   ",
      "            %   ",
      "            %   ",
      "            %   ",
      "            %   ",
      "            %   ",
      "            %   "
    ],
    [
      "                ",
      "                ",
      "                ",
      "                ",
      "                ",
      "                ",
      "                ",
      "                ",
      "$$$$$$$$$$$$$   ",
      "$$$$$$$$$$$$$   ",
      "$$$$$$$$$$$$$   ",
      "$$$$$$$$$$$$$   ",
      "$$$$$$$$$$$$$   ",
      "$$$$$$$$$$$$$   ",
      "&&&&&&&$$$$$$   ",
      "&&&&&&&$$$$$$   "
    ],
    [
      "                ",
      "                ",
      "                ",
      "                ",
      "                ",
      "                ",
      "                ",
      "                ",
      "                ",
      "                ",
      "                ",
      "                ",
      "                ",
      "                ",
      "&&&&&&&         ",
      "&&&&&&&         "
    ]
  ],
  "palette": {
    "palette": [
      {
        "char": "!",
        "block": "create:framed_glass"
      },
      {
        "char": "$",
        "block": "minecraft:dark_oak_planks"
      },
      {
        "char": "%",
        "block": "minecraft:stripped_spruce_log"
      },
      {
        "char": "&",
        "block": "minecraft:weathered_cut_copper_slab[type=bottom,waterlogged=false]"
      }
    ]
  }
}
