{
  "xsize": 16,
  "zsize": 16,
  "slices": [
    [
      "     %%%        ",
      "     %%%        ",
      "                ",
      "                ",
      "                ",
      "                ",
      "                ",
      "                ",
      "$               ",
      "$               ",
      "$               ",
      "                ",
      "                ",
      "                ",
      "                ",
      "                "
    ],
    [
      "     %%%        ",
      "     %%%        ",
      "                ",
      "                ",
      "                ",
      "                ",
      "                ",
      "                ",
      "$               ",
      "$               ",
      "$               ",
      "                ",
      "                ",
      "                ",
      "                ",
      "                "
    ],
    [
      "&&&&&&&&        ",
      "&&&&&&&&        ",
      "&&&&&&&&        ",
      "&&&&&&&&        ",
      "&&&&&&&&        ",
      "&&&&&&&&        ",
      "&&&&&&&&        ",
      "&&&&&&&&        ",
      "$&&&&&&&        ",
      "$&&&&&&&        ",
      "$&&&&&&&        ",
      "                ",
      "                ",
      "                ",
      "                ",
      "                "
    ],
    [
      "&&&&&&&&        ",
      "&&&&&&&&        ",
      "&&&&&&&&        ",
      "&&&&&&&&        ",
      "&&&&&&&&        ",
      "&&&&&&&&        ",
      "&&&&&&&&        ",
      "&&&&&&&&        ",
      "$&&&&&&&        ",
      "$&&&&&&&        ",
      "$&&&&&&&        ",
      "                ",
      "                ",
      "                ",
      "                ",
      "                "
    ],
    [
      "!!!!&&&&        ",
      "!!!!!!&&        ",
      "!!!!!!!&        ",
      "!!!!!!!!        ",
      "!!!!!!!!        ",
      "!!!!!!!!!       ",
      "!!!!!!!!!       ",
      "!!!!!!!!!       ",
      "!!!!!!!!!       ",
      "!!!!!!!!!!      ",
      "!!!!!!!!!       ",
      "                ",
      "                ",
      "                ",
      "                ",
      "                "
    ],
    [
      "!!!!&&&&        ",
      "&&&&!!&&        ",
      "&&&&&!!&        ",
      "&&&&&&!!        ",
      "&&&&&&&!        ",
      "&&&&&&&&!       ",
      "&&&&&&&&!       ",
      "&&&&&&&&!       ",
      "&&&&&&&&!       ",
      "&&&&&&&&!!      ",
      "&&&&&&&&!       ",
      "                ",
      "                ",
      "                ",
      "                ",
      "                "
    ]
  ],
  "palette": {
    "palette": [
      {
        "char": "!",
        "block": "minecraft:light_blue_concrete"
      },
      {
        "char": "$",
        "block": "minecraft:oxidized_copper"
      },
      {
        "char": "%",
        "block": "minecraft:polished_blackstone"
      },
      {
        "char": "&",
        "block": "minecraft:smooth_stone"
      }
    ]
  }
}
