{
  "xsize": 16,
  "zsize": 16,
  "slices": [
    [
      "                ",
      "                ",
      "                ",
      "                ",
      "                ",
      "     $$$$       ",
      "    !!!!!!      ",
      "    !!!!!!      ",
      "    !!!!!!      ",
      "    !!!!!!      ",
      "    !!!!!!      ",
      "                ",
      "                ",
      "                ",
      "                ",
      "                "
    ],
    [
      "                ",
      "                ",
      "                ",
      "                ",
      "                ",
      "                ",
      "    !!!!!!      ",
      "    !!!!!!      ",
      "    !!!!!!      ",
      "    !!!!!!      ",
      "    !!!!!!      ",
      "                ",
      "                ",
      "                ",
      "                ",
      "                "
    ]
  ],
  "palette": {
    "palette": [
      {
        "char": "!",
        "block": "minecraft:polished_blackstone_bricks"
      },
      {
        "char": "$",
        "block": "minecraft:yellow_concrete"
      }
    ]
  }
}
