{
  "xsize": 16,
  "zsize": 16,
  "slices": [
    [
      " +++''&+++++++++",
      " +''&+++++++++++",
      " '&+++++++++++++",
      " +++++++++++++++",
      " ++++++++++++++'",
      " &+++++++++++''&",
      " ++++++++++''&++",
      " ++++++++''&++++",
      " ++++++''&++++++",
      " ++++''&++++++++",
      " ++''&++++++++++",
      " &'&++++++++++++",
      " &++++++++++++++",
      " +++++++++++++++",
      " +++++++++++++''",
      " +++++++++++''&+"
    ],
    [
      "     ,,,,,,,,,,,",
      "     ,,,,,,,,,,,",
      "     ,,,,,,,,,,,",
      "     ,,,,,,,,,,,",
      "     ,,,,,,,,,,,",
      "     ,,,,,,,,,,,",
      "     ,,,,,,,,,,,",
      "     ,,,,,,,,,,,",
      "     ,,,,,,,,,,,",
      "     ,,,,,,,,,,,",
      "     ,,,,,,,,,,,",
      "     ,,,,,,,,,,,",
      "     ,,,,,,,,,,,",
      "     ,,,,,,,,,,,",
      "     ,,,,,,,,,,,",
      "     ,,,,,,,,,,,"
    ],
    [
      "     % ))      -",
      "     % *        ",
      "     %          ",
      "     %          ",
      "     %          ",
      "     %          ",
      "     %          ",
      "     %          ",
      "     %          ",
      "     %  $   ($  ",
      "     %          ",
      "     %          ",
      "     %          ",
      "     %          ",
      "     %          ",
      "     %%%%%%%%%%%"
    ],
    [
      "     %          ",
      "     %          ",
      "     %          ",
      "     %          ",
      "     %          ",
      "     %          ",
      "     %          ",
      "     %          ",
      "     %          ",
      "     %          ",
      "     %          ",
      "     %          ",
      "     %          ",
      "     %          ",
      "     %          ",
      "     %%%%%%%%%%%"
    ],
    [
      "     %          ",
      "     %          ",
      "     %          ",
      "     %          ",
      "     %          ",
      "     %          ",
      "     %          ",
      "     %          ",
      "     %          ",
      "     %          ",
      "     %          ",
      "     %          ",
      "     %          ",
      "     %          ",
      "     %          ",
      "     %%%%%%%%%%%"
    ],
    [
      "     %          ",
      "     %          ",
      "     %          ",
      "     !          ",
      "     !          ",
      "     %          ",
      "     %          ",
      "     %          ",
      "     %          ",
      "     %          ",
      "     %          ",
      "     %          ",
      "     %          ",
      "     %          ",
      "     %          ",
      "     %%%%%%%%%%%"
    ]
  ],
  "palette": {
    "palette": [
      {
        "char": "!",
        "block": "create:framed_glass"
      },
      {
        "char": "$",
        "block": "create:mechanical_pump[facing=south]"
      },
      {
        "char": "%",
        "block": "minecraft:bricks"
      },
      {
        "char": "&",
        "block": "minecraft:coarse_dirt"
      },
      {
        "char": "'",
        "block": "minecraft:gravel"
      },
      {
        "char": "(",
        "block": "minecraft:spawner",
        "tag": {
          "id": "minecraft:mob_spawner",
          "Delay": 200,
          "MinSpawnDelay": 240,
          "MaxSpawnDelay": 720,
          "SpawnCount": 2,
          "MaxNearbyEntities": 7,
          "RequiredPlayerRange": 14,
          "SpawnRange": 4,
          "SpawnData": {
            "entity": {
              "id": "minecraft:pillager"
            }
          },
          "SpawnPotentials": [
            {
              "weight": 1,
              "data": {
                "entity": {
                  "id": "minecraft:pillager"
                }
              }
            }
          ]
        }
      },
      {
        "char": ")",
        "block": "minecraft:spruce_slab[type=bottom,waterlogged=false]"
      },
      {
        "char": "*",
        "block": "minecraft:spruce_stairs[facing=north,half=bottom,shape=straight,waterlogged=false]"
      },
      {
        "char": "+",
        "block": "tfmg:asphalt"
      },
      {
        "char": ",",
        "block": "tfmg:factory_floor"
      },
      {
        "char": "-",
        "block": "the_wasteland_reworked:radio"
      }
    ]
  }
}
