{
  "xsize": 16,
  "zsize": 16,
  "slices": [
    [
      "  '     '   $   ",
      "  '     '       ",
      "  '     '       ",
      "  '     '       ",
      "  '     '       ",
      "  '     '       ",
      "  '     '       ",
      "  '''''''       ",
      "                ",
      "         &&&    ",
      "         &&&    ",
      "         &&&    ",
      "                ",
      "                ",
      "                ",
      "                "
    ],
    [
      "  '     '%%%    ",
      "  '     '%%%$   ",
      "  '     '%%%    ",
      "  '     '%%%    ",
      "  '     '%%%    ",
      "  '     '%%%    ",
      "  '     '%%%    ",
      "  '''''''%%%    ",
      "         %%%    ",
      "         %%%%%%%",
      "         %%%%%%%",
      "         %%%%%%%",
      "                ",
      "                ",
      "                ",
      "                "
    ],
    [
      "  !!!!!!!       ",
      "  !!!!!!!       ",
      "  !!!!!!!       ",
      "  !!!!!!!       ",
      "  !!!!!!!       ",
      "  !!!!!!!       ",
      "  !!!!!!!       ",
      "  !!!!!!!       ",
      "                ",
      "         &&&    ",
      "         &&&    ",
      "         &&&    ",
      "                ",
      "                ",
      "                ",
      "                "
    ],
    [
      "                ",
      "                ",
      "                ",
      "                ",
      "                ",
      "                ",
      "                ",
      "                ",
      "                ",
      "         &&&    ",
      "         &&&    ",
      "         &&&    ",
      "                ",
      "                ",
      "                ",
      "                "
    ],
    [
      "                ",
      "                ",
      "                ",
      "                ",
      "                ",
      "                ",
      "                ",
      "                ",
      "                ",
      "         &&&    ",
      "         &&&    ",
      "         &&&    ",
      "                ",
      "                ",
      "                ",
      "                "
    ],
    [
      "                ",
      "                ",
      "                ",
      "                ",
      "                ",
      "                ",
      "                ",
      "                ",
      "                ",
      "         &&&    ",
      "         &&&    ",
      "         &&&    ",
      "                ",
      "                ",
      "                ",
      "                "
    ]
  ],
  "palette": {
    "palette": [
      {
        "char": "!",
        "block": "minecraft:dark_oak_planks"
      },
      {
        "char": "$",
        "block": "minecraft:oak_stairs[facing=south,half=bottom,shape=straight,waterlogged=false]"
      },
      {
        "char": "%",
        "block": "minecraft:spruce_planks"
      },
      {
        "char": "&",
        "block": "minecraft:stripped_dark_oak_log[axis=y]"
      },
      {
        "char": "'",
        "block": "minecraft:stripped_spruce_log"
      }
    ]
  }
}
