{
  "xsize": 16,
  "zsize": 16,
  "slices": [
    [
      "  !      %%%    ",
      "  !      %%%    ",
      "  !             ",
      "  !             ",
      "  !             ",
      "  !             ",
      "  !             ",
      "  !             ",
      "  !           $$",
      "  !           $$",
      "  !           $$",
      "  !             ",
      "  !             ",
      "  !             ",
      "  !             ",
      "!!!             "
    ],
    [
      "  !      %%%    ",
      "  !      %%%    ",
      "  !             ",
      "  !             ",
      "  !             ",
      "  !             ",
      "  !             ",
      "  !             ",
      "  !           $$",
      "  !           $$",
      "  !           $$",
      "  !             ",
      "  !             ",
      "  !             ",
      "  !             ",
      "!!!             "
    ],
    [
      "  !      %%%    ",
      "  !      %%%    ",
      "  !             ",
      "  !             ",
      "  !             ",
      "  !             ",
      "  !             ",
      "  !             ",
      "  !           $$",
      "  !           $$",
      "  !           $$",
      "  !             ",
      "  !             ",
      "  !             ",
      "  !             ",
      "!!!             "
    ],
    [
      "  !      %%%    ",
      "  !      %%%    ",
      "  !             ",
      "  !             ",
      "  !             ",
      "  !             ",
      "  !             ",
      "  !             ",
      "  !           $$",
      "  !           $$",
      "  !           $$",
      "  !             ",
      "  !             ",
      "  !             ",
      "  !             ",
      "!!!             "
    ],
    [
      "  !      %%%    ",
      "  !      %%%    ",
      "  !             ",
      "  !             ",
      "  !             ",
      "  !             ",
      "  !             ",
      "  !             ",
      "  !           $$",
      "  !           $$",
      "  !           $$",
      "  !             ",
      "  !             ",
      "  !             ",
      "  !             ",
      "!!!             "
    ],
    [
      "&&'      %%%    ",
      "&&'      %%%    ",
      "&&'             ",
      "&&'             ",
      "&&'             ",
      "&&'             ",
      "&&'             ",
      "&&'             ",
      "&&'           $$",
      "&&'           $$",
      "&&'           $$",
      "&&'             ",
      "&&'             ",
      "&&'             ",
      "&&'             ",
      "!!'             "
    ]
  ],
  "palette": {
    "palette": [
      {
        "char": "!",
        "block": "minecraft:bricks"
      },
      {
        "char": "$",
        "block": "minecraft:oxidized_copper"
      },
      {
        "char": "%",
        "block": "minecraft:polished_blackstone"
      },
      {
        "char": "&",
        "block": "minecraft:smooth_stone"
      },
      {
        "char": "'",
        "block": "minecraft:weathered_cut_copper_stairs[facing=west,half=bottom,shape=straight,waterlogged=false]"
      }
    ]
  }
}
