{
  "xsize": 16,
  "zsize": 16,
  "slices": [
    [
      "((((((          ",
      "(&((((&((((&((((",
      "((((((((((((((((",
      "((((((((((((((&&",
      "((((((((((((&&%(",
      "((((((((((&&%(((",
      "((((((((&&%(((((",
      "((((((&&%(((((((",
      "((((((%(((((((((",
      "((&&%(((((((((((",
      "&&%(((((((((((((",
      "%(((((((((((((((",
      "(((((((((((((((&",
      "(((((((((((((&&%",
      "(((((((((((&&%((",
      "(((((((((&&%(((("
    ],
    [
      "                ",
      "                ",
      "                ",
      "                ",
      "                ",
      "                ",
      "                ",
      "                ",
      "        !!!!!   ",
      "        !!!!!   ",
      "        !!!!!   ",
      "        !!!!!   ",
      "        !!!!!   ",
      "                ",
      "            $$$$",
      "            $$$$"
    ],
    [
      "                ",
      "                ",
      "                ",
      "                ",
      "                ",
      "                ",
      "                ",
      "                ",
      "        !!!!!   ",
      "        !!!!!   ",
      "        !!!!!   ",
      "        !!!!!   ",
      "        !!!!!   ",
      "                ",
      "            $$$$",
      "            $$$$"
    ],
    [
      "                ",
      "                ",
      "                ",
      "                ",
      "                ",
      "                ",
      "                ",
      "                ",
      "                ",
      "         '''    ",
      "         '''    ",
      "         '''    ",
      "                ",
      "                ",
      "            $$$$",
      "            $$$$"
    ],
    [
      "                ",
      "                ",
      "                ",
      "                ",
      "                ",
      "                ",
      "                ",
      "                ",
      "                ",
      "         '''    ",
      "         '''    ",
      "         '''    ",
      "                ",
      "                ",
      "            $$$$",
      "            $$$$"
    ],
    [
      "                ",
      "                ",
      "                ",
      "                ",
      "                ",
      "                ",
      "                ",
      "                ",
      "                ",
      "         '''    ",
      "         '''    ",
      "         '''    ",
      "                ",
      "                ",
      "                ",
      "                "
    ]
  ],
  "palette": {
    "palette": [
      {
        "char": "!",
        "block": "immersiveengineering:concrete_reinforced"
      },
      {
        "char": "$",
        "block": "immersiveengineering:sheetmetal_steel"
      },
      {
        "char": "%",
        "block": "minecraft:coarse_dirt"
      },
      {
        "char": "&",
        "block": "minecraft:gravel"
      },
      {
        "char": "'",
        "block": "minecraft:stripped_dark_oak_log[axis=y]"
      },
      {
        "char": "(",
        "block": "tfmg:asphalt"
      }
    ]
  }
}
