{
  "xsize": 16,
  "zsize": 16,
  "slices": [
    [
      "                ",
      "                ",
      "                ",
      "                ",
      "                ",
      "                ",
      " !        !     ",
      " !        !     ",
      " !        !     ",
      " !        !     ",
      " !        !     ",
      " !        !     ",
      " !        !     ",
      " !!!!!!!!!!     ",
      "                ",
      "                "
    ],
    [
      "                ",
      "                ",
      "                ",
      "                ",
      "                ",
      "                ",
      " !        !     ",
      " !        !     ",
      " !        !     ",
      " !        !     ",
      " !        !     ",
      " !        !     ",
      " !        !     ",
      " !!!!!!!!!!     ",
      "                ",
      "                "
    ],
    [
      "$!        !     ",
      "$!        !     ",
      "$!        !     ",
      "$!        !     ",
      "$!        !     ",
      "$!        !     ",
      " !        !     ",
      " !        !     ",
      " !        !     ",
      " !        !     ",
      " !        !     ",
      " !        !     ",
      " !        !     ",
      " !!!!!!!!!!     ",
      "                ",
      "                "
    ],
    [
      " !        !     ",
      " !        !     ",
      " !        !     ",
      " !        !     ",
      " !        !     ",
      " !        !     ",
      " !        !     ",
      " !        !     ",
      " !        !     ",
      " !        !     ",
      " !        !     ",
      " !        !     ",
      " !        !     ",
      " !!!!!!!!!!     ",
      "                ",
      "                "
    ],
    [
      " %%%%%%%%%%     ",
      " %%%%%%%%%%     ",
      " %%%%%%%%%%     ",
      " %%%%%%%%%%     ",
      " %%%%%%%%%%     ",
      " %%%%%%%%%%     ",
      " %%%%%%%%%%     ",
      " %%%%%%%%%%     ",
      " %%%%%%%%%%     ",
      " %%%%%%%%%%     ",
      " %%%%%%%%%%     ",
      " %%%%%%%%%%     ",
      " %%%%%%%%%%     ",
      " %%%%%%%%%%     ",
      "                ",
      "                "
    ],
    [
      "                ",
      "                ",
      "                ",
      "                ",
      "                ",
      "                ",
      "                ",
      "                ",
      "                ",
      "                ",
      "                ",
      "                ",
      "                ",
      "                ",
      "                ",
      "                "
    ]
  ],
  "palette": {
    "palette": [
      {
        "char": "!",
        "block": "minecraft:bricks"
      },
      {
        "char": "$",
        "block": "minecraft:smooth_stone_slab[type=bottom,waterlogged=false]"
      },
      {
        "char": "%",
        "block": "minecraft:weathered_cut_copper"
      }
    ]
  }
}
