{
  "xsize": 16,
  "zsize": 16,
  "slices": [
    [
      "             ---",
      " -&----&----&---",
      " ---------------",
      " %---------&&---",
      " --------&&%----",
      " ------&&%------",
      " ----&&%--------",
      " --&&%----------",
      " &&%------------",
      " %--------------",
      " ---------------",
      " -------------&&",
      " -----------&&%-",
      " ---------&&%---",
      " -------&&%-----",
      " %----&&%-------"
    ],
    [
      "                ",
      "                ",
      "                ",
      "                ",
      "                ",
      "                ",
      "                ",
      "                ",
      "        !!!!!   ",
      "        !!!!!   ",
      "        !!!!!   ",
      "        !!!!!   ",
      "  (((((((!!!!   ",
      "  (((((((       ",
      "  (((((((       ",
      "  (((((((       "
    ],
    [
      "                ",
      "                ",
      "                ",
      "                ",
      "                ",
      "                ",
      "                ",
      "                ",
      "        !!!!!   ",
      "        !!!!!   ",
      "        !!!!!   ",
      "        !!!!!   ",
      "  ,,,),,,!!!'   ",
      "  ,     ,       ",
      "  ,    $,       ",
      "  ,     ,       "
    ],
    [
      "                ",
      "                ",
      "                ",
      "                ",
      "                ",
      "                ",
      "                ",
      "                ",
      "                ",
      "         +++    ",
      "         +++    ",
      "         +++    ",
      "  ,,,*,,,       ",
      "  ,     ,   '   ",
      "  ,     ,       ",
      "  ,     ,       "
    ],
    [
      "                ",
      "                ",
      "                ",
      "                ",
      "                ",
      "                ",
      "                ",
      "                ",
      "                ",
      "         +++    ",
      "         +++    ",
      "         +++    ",
      "  ,,,,,,,       ",
      "  ,     ,       ",
      "  ,     ,   '   ",
      "  ,     ,       "
    ],
    [
      "                ",
      "                ",
      "                ",
      "                ",
      "                ",
      "                ",
      "                ",
      "                ",
      "                ",
      "         +++    ",
      "         +++    ",
      "         +++    ",
      "  ,,,,,,,       ",
      "  ,     ,       ",
      "  ,     ,       ",
      "  ,     ,   '   "
    ]
  ],
  "palette": {
    "palette": [
      {
        "char": "!",
        "block": "immersiveengineering:concrete_reinforced"
      },
      {
        "char": "$",
        "block": "kubejs:ruined_blast_furnace[facing=west]"
      },
      {
        "char": "%",
        "block": "minecraft:coarse_dirt"
      },
      {
        "char": "&",
        "block": "minecraft:gravel"
      },
      {
        "char": "'",
        "block": "minecraft:oak_stairs[facing=south,half=bottom,shape=straight,waterlogged=false]"
      },
      {
        "char": "(",
        "block": "minecraft:smooth_stone"
      },
      {
        "char": ")",
        "block": "minecraft:spruce_door[facing=north,half=lower,hinge=left,open=false,powered=false]"
      },
      {
        "char": "*",
        "block": "minecraft:spruce_door[facing=north,half=upper,hinge=left,open=false,powered=false]"
      },
      {
        "char": "+",
        "block": "minecraft:stripped_dark_oak_log[axis=y]"
      },
      {
        "char": ",",
        "block": "minecraft:stripped_spruce_log"
      },
      {
        "char": "-",
        "block": "tfmg:asphalt"
      }
    ]
  }
}
