{
  "xsize": 16,
  "zsize": 16,
  "slices": [
    [
      "*************   ",
      "*************   ",
      "*************   ",
      "*************   ",
      "*************   ",
      "***********'*   ",
      "*************   ",
      "*************   ",
      "*************   ",
      "***********'    ",
      "*********''&    ",
      "*******''&*'    ",
      "*****''&****    ",
      "***''&******    ",
      "*''&********    ",
      "'&**********    "
    ],
    [
      " ))))))))))     ",
      " ))))))))))     ",
      " ))))))))))     ",
      " ))))))))))     ",
      " ))))))))))     ",
      " ))))))))))     ",
      " ))))))))))     ",
      " ))))))))))     ",
      " ))))))))))     ",
      " ))))))))))     ",
      " ))))))))))     ",
      " ))))))))))     ",
      " ))))))))))     ",
      " ))))))))))     ",
      "                ",
      "                "
    ],
    [
      "                ",
      "                ",
      "                ",
      "                ",
      "                ",
      "                ",
      " $        $     ",
      " $        $     ",
      " $        $     ",
      " $  ((((( $     ",
      " $ !(((%( $     ",
      " $  ((((( $     ",
      " $        $     ",
      " $$$$$$$$$$     ",
      "                ",
      "                "
    ],
    [
      "                ",
      "                ",
      "                ",
      "                ",
      "                ",
      "                ",
      " $        $     ",
      " $        $     ",
      " $        $     ",
      " $  ((((( $     ",
      " $  ((((( $     ",
      " $  ((((( $     ",
      " $        $     ",
      " $$$$$$$$$$     ",
      "                ",
      "                "
    ],
    [
      "                ",
      "                ",
      "                ",
      "                ",
      "                ",
      "                ",
      " $        $     ",
      " $        $     ",
      " $        $     ",
      " $  ((((( $     ",
      " $  ((((( $     ",
      " $  ((((( $     ",
      " $        $     ",
      " $$$$$$$$$$     ",
      "                ",
      "                "
    ],
    [
      "                ",
      "                ",
      "                ",
      "                ",
      "                ",
      "                ",
      " $        $     ",
      " $        $     ",
      " $        $     ",
      " $        $     ",
      " $        $     ",
      " $        $     ",
      " $        $     ",
      " $$$$$$$$$$     ",
      "                ",
      "                "
    ]
  ],
  "palette": {
    "palette": [
      {
        "char": "!",
        "block": "kubejs:ruined_brewing_stand"
      },
      {
        "char": "$",
        "block": "minecraft:bricks"
      },
      {
        "char": "%",
        "block": "minecraft:chest[facing=north,type=single,waterlogged=false]",
        "tag": {
          "id": "minecraft:chest",
          "LootTable": "infinite_domain:chests/wasteland_roadside"
        }
      },
      {
        "char": "&",
        "block": "minecraft:coarse_dirt"
      },
      {
        "char": "'",
        "block": "minecraft:gravel"
      },
      {
        "char": "(",
        "block": "minecraft:scaffolding"
      },
      {
        "char": ")",
        "block": "minecraft:smooth_stone"
      },
      {
        "char": "*",
        "block": "tfmg:asphalt"
      }
    ]
  }
}
