{
  "xsize": 16,
  "zsize": 16,
  "slices": [
    [
      "                ",
      "&&4444&4444&4444",
      "4444444444444444",
      "44444444444444&&",
      "444444444444&&%4",
      "4444444444&&%444",
      "44444444&&%44444",
      "444444&&%4444444",
      "4444&&%444444444",
      "44&&%44444444444",
      "&&%4444444444444",
      "%444444444444444",
      "4444444444444444",
      "4444444444444444",
      "4444444444444444",
      "4444444444444444"
    ],
    [
      "                ",
      "                ",
      "                ",
      "                ",
      "6666666666666666",
      "6666666666666666",
      "6666666666666666",
      "6666666666666666",
      "6666666666666666",
      "6666666666666666",
      "6666666666666666",
      "6666666666666666",
      "6666666666666666",
      "                ",
      "................",
      "................"
    ],
    [
      "                ",
      "                ",
      "                ",
      "                ",
      "5555555555555555",
      "     $     $    ",
      "  7  $ ----$    ",
      "2    $ ----$ 3  ",
      "     0 --/-0    ",
      "     $ ----$  , ",
      "     $ ----$    ",
      "     $     $    ",
      "5555'(5555555555",
      "                ",
      "                ",
      " +++ +++ +++ +++"
    ],
    [
      "                ",
      "                ",
      "                ",
      "                ",
      "5555555555555555",
      "     $     $    ",
      "     $ ----$    ",
      "     $ ----$    ",
      "     1 ----1    ",
      "     $ ----$    ",
      "     $ ----$    ",
      "     $     $    ",
      "5555)*5555555555",
      "                ",
      "                ",
      "                "
    ],
    [
      "                ",
      "                ",
      "                ",
      "                ",
      "5555555555555555",
      "     $     $    ",
      "     $ ----$    ",
      "     $ ----$    ",
      "     $ ----$    ",
      "     $ ----$    ",
      "     $ ----$    ",
      "     $     $    ",
      "!55!!555!!555!!5",
      "                ",
      "                ",
      "                "
    ],
    [
      "                ",
      "                ",
      "                ",
      "                ",
      "5555555555555555",
      "     $     $    ",
      "     $     $    ",
      "     $     $    ",
      "     $     $    ",
      "     $     $    ",
      "     $     $    ",
      "     $     $    ",
      "!55!!555!!555!!5",
      "                ",
      "                ",
      "                "
    ]
  ],
  "palette": {
    "palette": [
      {
        "char": "!",
        "block": "create:framed_glass"
      },
      {
        "char": "$",
        "block": "minecraft:bricks"
      },
      {
        "char": "%",
        "block": "minecraft:coarse_dirt"
      },
      {
        "char": "&",
        "block": "minecraft:gravel"
      },
      {
        "char": "'",
        "block": "minecraft:iron_door[facing=south,half=lower,hinge=left,open=false,powered=false]"
      },
      {
        "char": "(",
        "block": "minecraft:iron_door[facing=south,half=lower,hinge=right,open=false,powered=false]"
      },
      {
        "char": ")",
        "block": "minecraft:iron_door[facing=south,half=upper,hinge=left,open=false,powered=false]"
      },
      {
        "char": "*",
        "block": "minecraft:iron_door[facing=south,half=upper,hinge=right,open=false,powered=false]"
      },
      {
        "char": "+",
        "block": "minecraft:polished_blackstone"
      },
      {
        "char": ",",
        "block": "minecraft:quartz_stairs[facing=west,half=bottom,shape=straight,waterlogged=false]"
      },
      {
        "char": "-",
        "block": "minecraft:scaffolding"
      },
      {
        "char": ".",
        "block": "minecraft:smooth_stone"
      },
      {
        "char": "/",
        "block": "minecraft:spawner",
        "tag": {
          "id": "minecraft:mob_spawner",
          "Delay": 200,
          "MinSpawnDelay": 240,
          "MaxSpawnDelay": 720,
          "SpawnCount": 1,
          "MaxNearbyEntities": 4,
          "RequiredPlayerRange": 14,
          "SpawnRange": 4,
          "SpawnData": {
            "entity": {
              "id": "minecraft:pillager"
            }
          },
          "SpawnPotentials": [
            {
              "weight": 1,
              "data": {
                "entity": {
                  "id": "minecraft:pillager"
                }
              }
            }
          ]
        }
      },
      {
        "char": "0",
        "block": "minecraft:spruce_door[facing=east,half=lower,hinge=left,open=false,powered=false]"
      },
      {
        "char": "1",
        "block": "minecraft:spruce_door[facing=east,half=upper,hinge=left,open=false,powered=false]"
      },
      {
        "char": "2",
        "block": "minecraft:spruce_slab[type=bottom,waterlogged=false]"
      },
      {
        "char": "3",
        "block": "kubejs:ruined_cauldron"
      },
      {
        "char": "4",
        "block": "tfmg:asphalt"
      },
      {
        "char": "5",
        "block": "tfmg:cinder_block"
      },
      {
        "char": "6",
        "block": "tfmg:factory_floor"
      },
      {
        "char": "7",
        "block": "the_wasteland_reworked:radio"
      }
    ]
  }
}
