{
  "xsize": 16,
  "zsize": 16,
  "slices": [
    [
      " ***%%$*********",
      " *%%$***********",
      " %$*************",
      " ***************",
      " **************%",
      " $***********%%$",
      " **********%%$**",
      " ********%%$****",
      " ******%%$******",
      " ****%%$********",
      " **%%$**********",
      " $%$************",
      " $**************",
      " ***************",
      " *************%%",
      " ***********%%$*"
    ],
    [
      "  '''''''       ",
      "  '''''''       ",
      "  '''''''       ",
      "  '''''''       ",
      "  '''''''       ",
      "  '''''''       ",
      "  '''''''       ",
      "  '''''''       ",
      "        !!!!!   ",
      "        !!!!!   ",
      "        !!!!!   ",
      "        !!!!!   ",
      "        !!!!!   ",
      "                ",
      "                ",
      "                "
    ],
    [
      "  )     )       ",
      "  )&&&&&)       ",
      "  )&&&&&)       ",
      "  )&&&&&)       ",
      "  )&&&&&)       ",
      "  )&&&&&)       ",
      "  )     )       ",
      "  )))))))       ",
      "        !!!!!   ",
      "        !!!!!   ",
      "        !!!!!   ",
      "        !!!!!   ",
      "        !!!!!   ",
      "                ",
      "                ",
      "                "
    ],
    [
      "  )     )       ",
      "  )&&&&&)       ",
      "  )&&&&&)       ",
      "  )&&&&&)       ",
      "  )&&&&&)       ",
      "  )&&&&&)       ",
      "  )     )       ",
      "  )))))))       ",
      "                ",
      "         (((    ",
      "         (((    ",
      "         (((    ",
      "                ",
      "                ",
      "                ",
      "                "
    ],
    [
      "  )     )       ",
      "  )&&&&&)       ",
      "  )&&&&&)       ",
      "  )&&&&&)       ",
      "  )&&&&&)       ",
      "  )&&&&&)       ",
      "  )     )       ",
      "  )))))))       ",
      "                ",
      "         (((    ",
      "         (((    ",
      "         (((    ",
      "                ",
      "                ",
      "                ",
      "                "
    ],
    [
      "  )     )       ",
      "  )&&&&&)       ",
      "  )&&&&&)       ",
      "  )&&&&&)       ",
      "  )&&&&&)       ",
      "  )&&&&&)       ",
      "  )     )       ",
      "  )))))))       ",
      "                ",
      "         (((    ",
      "         (((    ",
      "         (((    ",
      "                ",
      "                ",
      "                ",
      "                "
    ]
  ],
  "palette": {
    "palette": [
      {
        "char": "!",
        "block": "immersiveengineering:concrete_reinforced"
      },
      {
        "char": "$",
        "block": "minecraft:coarse_dirt"
      },
      {
        "char": "%",
        "block": "minecraft:gravel"
      },
      {
        "char": "&",
        "block": "minecraft:scaffolding"
      },
      {
        "char": "'",
        "block": "minecraft:smooth_stone"
      },
      {
        "char": "(",
        "block": "minecraft:stripped_dark_oak_log[axis=y]"
      },
      {
        "char": ")",
        "block": "minecraft:stripped_spruce_log"
      },
      {
        "char": "*",
        "block": "tfmg:asphalt"
      }
    ]
  }
}
