{
  "xsize": 16,
  "zsize": 16,
  "slices": [
    [
      "////////////////",
      "//*////*////*///",
      "////////////////",
      "/%/////////////*",
      "////////////////",
      "////////////////",
      "////////////////",
      "////////////////",
      "////////////////",
      "//%////%////%///",
      "////////////////",
      "                ",
      "                ",
      "                ",
      "                ",
      "                "
    ],
    [
      "                ",
      "                ",
      "  *****         ",
      "  *****         ",
      "  *****         ",
      "  *****         ",
      "                ",
      "              0 ",
      "                ",
      "                ",
      "                ",
      "                ",
      "                ",
      "                ",
      "                ",
      "                "
    ],
    [
      "                ",
      "                ",
      "  *****    !!   ",
      "  *****'''''''  ",
      "  *****'''''''  ",
      "  *****'''''''  ",
      "   '''''''''''  ",
      "   '''''''''''  ",
      "    !!     !!   ",
      "                ",
      "                ",
      "                ",
      "                ",
      "                ",
      "                ",
      "                "
    ],
    [
      "                ",
      "                ",
      "    !!     !!   ",
      "        ''''''  ",
      "          ( ''  ",
      "          ( $'  ",
      "   -'' )  ( ''  ",
      "   '',''''''''  ",
      "    !!     !!   ",
      "                ",
      "                ",
      "                ",
      "                ",
      "                ",
      "                ",
      "                "
    ],
    [
      "                ",
      "                ",
      "                ",
      "        ''''''  ",
      "            ..  ",
      "            ..  ",
      "   ,,,      ..  ",
      "   '''''''''''  ",
      "                ",
      "                ",
      "                ",
      "                ",
      "                ",
      "                ",
      "                ",
      "                "
    ],
    [
      "                ",
      "                ",
      "                ",
      "        +++&    ",
      "        &&&&    ",
      "        &&&+    ",
      "      &&&&&&    ",
      "      &++++&    ",
      "                ",
      "                ",
      "                ",
      "                ",
      "                ",
      "                ",
      "                ",
      "                "
    ]
  ],
  "palette": {
    "palette": [
      {
        "char": "!",
        "block": "minecraft:blackstone"
      },
      {
        "char": "$",
        "block": "minecraft:chest[facing=east,type=single,waterlogged=false]",
        "tag": {
          "id": "minecraft:chest",
          "LootTable": "infinite_domain:chests/wasteland_roadside"
        }
      },
      {
        "char": "%",
        "block": "minecraft:coarse_dirt"
      },
      {
        "char": "&",
        "block": "minecraft:cyan_concrete"
      },
      {
        "char": "'",
        "block": "minecraft:cyan_terracotta"
      },
      {
        "char": "(",
        "block": "minecraft:dark_oak_stairs[facing=east,half=bottom,shape=straight,waterlogged=false]"
      },
      {
        "char": ")",
        "block": "minecraft:dark_oak_stairs[facing=west,half=bottom,shape=straight,waterlogged=false]"
      },
      {
        "char": "*",
        "block": "minecraft:gravel"
      },
      {
        "char": "+",
        "block": "minecraft:light_blue_stained_glass"
      },
      {
        "char": ",",
        "block": "minecraft:oxidized_copper"
      },
      {
        "char": "-",
        "block": "minecraft:sea_lantern"
      },
      {
        "char": ".",
        "block": "minecraft:weathered_copper"
      },
      {
        "char": "/",
        "block": "tfmg:asphalt"
      },
      {
        "char": "0",
        "block": "the_wasteland_reworked:garbage_bag"
      }
    ]
  }
}
