{
  "xsize": 16,
  "zsize": 16,
  "slices": [
    [
      "1111111111111111",
      "11,1111,1111,111",
      "1111111111111111",
      "1%1111111111111,",
      "1111111111111111",
      "1111111111111111",
      "1111111111111111",
      "1111111111111111",
      "1111111111111111",
      "11%1111%1111%111",
      "1111111111111111",
      "                ",
      "                ",
      "                ",
      "                ",
      "                "
    ],
    [
      "                ",
      "                ",
      "    !!     !!   ",
      "                ",
      "                ",
      "                ",
      "                ",
      "                ",
      "    !!     !!   ",
      "                ",
      "                ",
      "                ",
      "                ",
      "                ",
      "                ",
      "                "
    ],
    [
      "                ",
      "                ",
      "    !!     !!   ",
      "   '''''''''''  ",
      "   '''''''''''  ",
      "   '''''''''''  ",
      "   '''''''''''  ",
      "   '''''''''''  ",
      "    !!     !!   ",
      "                ",
      "                ",
      "                ",
      "                ",
      "                ",
      "                ",
      "                "
    ],
    [
      "                ",
      "                ",
      "    !!     !!   ",
      "   '''''('''''  ",
      "   /'' +  * ''  ",
      "   ''' +  * $'  ",
      "   /'' +  * ''  ",
      "   '''''''''''  ",
      "    !!     !!   ",
      "                ",
      "                ",
      "                ",
      "                ",
      "                ",
      "                ",
      "                "
    ],
    [
      "                ",
      "                ",
      "                ",
      "   ''''')'''''  ",
      "   ...      00  ",
      "   ...      00  ",
      "   ...      00  ",
      "   '''''''''''  ",
      "                ",
      "                ",
      "                ",
      "                ",
      "                ",
      "                ",
      "                ",
      "                "
    ],
    [
      "                ",
      "                ",
      "                ",
      "      &----&    ",
      "      &&&&&&    ",
      "      -&&&&-    ",
      "      &&&&&&    ",
      "      &----&    ",
      "                ",
      "                ",
      "                ",
      "                ",
      "                ",
      "                ",
      "                ",
      "                "
    ]
  ],
  "palette": {
    "palette": [
      {
        "char": "!",
        "block": "minecraft:blackstone"
      },
      {
        "char": "$",
        "block": "minecraft:chest[facing=east,type=single,waterlogged=false]",
        "tag": {
          "id": "minecraft:chest",
          "LootTable": "infinite_domain:chests/wasteland_roadside"
        }
      },
      {
        "char": "%",
        "block": "minecraft:coarse_dirt"
      },
      {
        "char": "&",
        "block": "minecraft:cyan_concrete"
      },
      {
        "char": "'",
        "block": "minecraft:cyan_terracotta"
      },
      {
        "char": "(",
        "block": "minecraft:dark_oak_door[facing=north,half=lower,hinge=left,open=false,powered=false]"
      },
      {
        "char": ")",
        "block": "minecraft:dark_oak_door[facing=north,half=upper,hinge=left,open=false,powered=false]"
      },
      {
        "char": "*",
        "block": "minecraft:dark_oak_stairs[facing=east,half=bottom,shape=straight,waterlogged=false]"
      },
      {
        "char": "+",
        "block": "minecraft:dark_oak_stairs[facing=west,half=bottom,shape=straight,waterlogged=false]"
      },
      {
        "char": ",",
        "block": "minecraft:gravel"
      },
      {
        "char": "-",
        "block": "minecraft:light_blue_stained_glass"
      },
      {
        "char": ".",
        "block": "minecraft:oxidized_copper"
      },
      {
        "char": "/",
        "block": "minecraft:sea_lantern"
      },
      {
        "char": "0",
        "block": "minecraft:weathered_copper"
      },
      {
        "char": "1",
        "block": "tfmg:asphalt"
      }
    ]
  }
}
